Workbook
Name _rng11: SIGN(ROW(#REF!))
Name base_all: [1]actual!$D$5:$AM$560
Name base_quality: '[1]rom quality'!$A:$K
Name budget_plan: [1]budget!$C$3:$O$22
Name Calendar: #N/A
Name chtYmajor: INDEX({1,2,5,10},MATCH(10^(LOG(6*[0]!valStD)-INT(LOG(6*[0]!valStD))),{1,1.2,2.2,6},1))*10^(INT(LOG(6*[0]!valStD))-1)
Name date_haul: '[1]coal trans'!$P$5:$P$1000
Name date_trf: '[1]coal trans'!$E$5:$E$1000
Name DayWeek: {1,2,3,4,5,6,7}
Name dest_trf: '[1]coal trans'!$I$5:$I$1000
Name msy_biangan: [1]actual!$B$185:$AS$311
Name nmCategory: OFFSET(#REF!,0,0,MIN(COUNTA(#REF!)-2,COUNTA(#REF!)-1),1)
Name nmValue: OFFSET([0]!nmCategory,0,1)
Name NumWeek: {0;1;2;3;4;5}
Name prod_haul: '[1]coal trans'!$U$5:$U$1000
Name psy_bunyut: [1]actual!$B$508:$AS$526
Name rom_haul: '[1]coal trans'!$T$5:$T$1000
Name shift_haul: '[1]coal trans'!$Q$5:$Q$1000
Name shift_trf: '[1]coal trans'!$F$5:$F$1000
Name source_haul: '[1]coal trans'!$R$5:$R$1000
Name source_trf: '[1]coal trans'!$H$5:$H$1000
Name todate_plan: [1]budget!$B$29:$AH$394
Name ton_haul: '[1]coal trans'!$V$5:$V$1000
Name ton_trf: '[1]coal trans'!$L$5:$L$1000
Name tsy_sb1: [1]actual!$B$327:$AS$345
Name valStD: STDEV([0]!nmValue)

Sheet weather
B2: ='[1]base ob inpit'!G2 -> 46266 | C2: Rainfall | E2: Duration | K2: Summary
C3: Prediction | D3: Actual | E3: Prediction | H3: Actual
E4: Rain | F4: Slippery | G4: Total | H4: Rain | I4: Slippery | J4: Total
A5: =+B2 -> 46266 | B5: 1 | C5: - | D5: 0 | E5: 0 | F5: 0 | G5: =E5+F5 -> 0 | H5: 0 | I5: 0 | J5: =H5+I5 -> 0 | K5: =IF(D5="",0,FIXED(D5,0)&" mm "&" / "&FIXED(J5,2)&" hr") -> 0 mm / 0.00 hr | L5: =J5/24 -> 0 | M5: =SUM(D5:D7) -> 0
A6: =+A5+1 -> 46267 | B6: 2 | C6: - | D6: 0 | E6: 0 | F6: 0 | G6: =E6+F6 -> 0 | H6: 0 | I6: 0 | J6: =H6+I6 -> 0 | K6: =IF(D6="",0,FIXED(D6,0)&" mm "&" / "&FIXED(J6,2)&" hr") -> 0 mm / 0.00 hr | L6: =J6/24 -> 0 | M6: =SUM(D6:D8) -> 3
A7: =+A6+1 -> 46268 | B7: 3 | C7: - | D7: 0 | E7: 0 | F7: 0 | G7: =E7+F7 -> 0 | H7: 0 | I7: 0 | J7: =H7+I7 -> 0 | K7: =IF(D7="",0,FIXED(D7,0)&" mm "&" / "&FIXED(J7,2)&" hr") -> 0 mm / 0.00 hr | L7: =J7/24 -> 0 | M7: =SUM(D7:D9) -> 29
A8: =+A7+1 -> 46269 | B8: 4 | C8: - | D8: 3 | E8: 0 | F8: 0 | G8: =E8+F8 -> 0 | H8: 0.66666667 | I8: 0 | J8: =H8+I8 -> 0.66666667 | K8: =IF(D8="",0,FIXED(D8,0)&" mm "&" / "&FIXED(J8,2)&" hr") -> 3 mm / 0.67 hr | L8: =J8/24 -> 0.027777778 | M8: =SUM(D8:D10) -> 30
A9: =+A8+1 -> 46270 | B9: 5 | C9: 14.713694 | D9: 26 | E9: 4.3180363 | F9: 1.850587 | G9: =E9+F9 -> 6.1686233 | H9: 1.5 | I9: 2.5833333 | J9: =H9+I9 -> 4.0833333 | K9: =IF(D9="",0,FIXED(D9,0)&" mm "&" / "&FIXED(J9,2)&" hr") -> 26 mm / 4.08 hr | L9: =J9/24 -> 0.17013889 | M9: =SUM(D9:D11) -> 37.6
A10: =+A9+1 -> 46271 | B10: 6 | C10: 53.950213 | D10: 1 | E10: 15.8328 | F10: 6.7854856 | G10: =E10+F10 -> 22.618285 | H10: 1.3666667 | I10: 0 | J10: =H10+I10 -> 1.3666667 | K10: =IF(D10="",0,FIXED(D10,0)&" mm "&" / "&FIXED(J10,2)&" hr") -> 1 mm / 1.37 hr | L10: =J10/24 -> 0.056944444 | M10: =SUM(D10:D12) -> 11.6
A11: =+A10+1 -> 46272 | B11: 7 | C11: 3.065353 | D11: 10.6 | E11: 0.8995909 | F11: 0.38553896 | G11: =E11+F11 -> 1.2851299 | H11: 2.8 | I11: 1.0833333 | J11: =H11+I11 -> 3.8833333 | K11: =IF(D11="",0,FIXED(D11,0)&" mm "&" / "&FIXED(J11,2)&" hr") -> 11 mm / 3.88 hr | L11: =J11/24 -> 0.16180556 | M11: =SUM(D11:D13) -> 10.6
A12: =+A11+1 -> 46273 | B12: 8 | C12: 8.5829884 | E12: 2.5188545 | F12: 1.0795091 | G12: =E12+F12 -> 3.5983636 | J12: =H12+I12 -> 0 | K12: =IF(D12="",0,FIXED(D12,0)&" mm "&" / "&FIXED(J12,2)&" hr") -> 0 | L12: =J12/24 -> 0 | M12: =SUM(D12:D14) -> 0
A13: =+A12+1 -> 46274 | B13: 9 | C13: 2.4522824 | E13: 0.71967272 | F13: 0.30843116 | G13: =E13+F13 -> 1.0281039 | J13: =H13+I13 -> 0 | K13: =IF(D13="",0,FIXED(D13,0)&" mm "&" / "&FIXED(J13,2)&" hr") -> 0 | L13: =J13/24 -> 0 | M13: =SUM(D13:D15) -> 0
A14: =+A13+1 -> 46275 | B14: 10 | C14: 7.3568472 | E14: 2.1590182 | F14: 0.92529349 | G14: =E14+F14 -> 3.0843116 | J14: =H14+I14 -> 0 | K14: =IF(D14="",0,FIXED(D14,0)&" mm "&" / "&FIXED(J14,2)&" hr") -> 0 | L14: =J14/24 -> 0 | M14: =SUM(D14:D16) -> 0
A15: =+A14+1 -> 46276 | B15: 11 | C15: 2.4522824 | E15: 0.71967272 | F15: 0.30843116 | G15: =E15+F15 -> 1.0281039 | J15: =H15+I15 -> 0 | K15: =IF(D15="",0,FIXED(D15,0)&" mm "&" / "&FIXED(J15,2)&" hr") -> 0 | L15: =J15/24 -> 0 | M15: =SUM(D15:D17) -> 0
A16: =+A15+1 -> 46277 | B16: 12 | C16: 4.7819507 | E16: 1.4033618 | F16: 0.60144077 | G16: =E16+F16 -> 2.0048026 | J16: =H16+I16 -> 0 | K16: =IF(D16="",0,FIXED(D16,0)&" mm "&" / "&FIXED(J16,2)&" hr") -> 0 | L16: =J16/24 -> 0 | M16: =SUM(D16:D18) -> 0
A17: =+A16+1 -> 46278 | B17: 13 | C17: - | E17: 0 | F17: 0 | G17: =E17+F17 -> 0 | J17: =H17+I17 -> 0 | K17: =IF(D17="",0,FIXED(D17,0)&" mm "&" / "&FIXED(J17,2)&" hr") -> 0 | L17: =J17/24 -> 0 | M17: =SUM(D17:D19) -> 0
A18: =+A17+1 -> 46279 | B18: 14 | C18: - | E18: 0 | F18: 0 | G18: =E18+F18 -> 0 | J18: =H18+I18 -> 0 | K18: =IF(D18="",0,FIXED(D18,0)&" mm "&" / "&FIXED(J18,2)&" hr") -> 0 | L18: =J18/24 -> 0 | M18: =SUM(D18:D20) -> 0
A19: =+A18+1 -> 46280 | B19: 15 | C19: 0.36784236 | E19: 0.10795091 | F19: 0.046264675 | G19: =E19+F19 -> 0.15421558 | J19: =H19+I19 -> 0 | K19: =IF(D19="",0,FIXED(D19,0)&" mm "&" / "&FIXED(J19,2)&" hr") -> 0 | L19: =J19/24 -> 0 | M19: =SUM(D19:D21) -> 0
A20: =+A19+1 -> 46281 | B20: 16 | C20: 22.193156 | E20: 6.5130381 | F20: 2.791302 | G20: =E20+F20 -> 9.3043401 | J20: =H20+I20 -> 0 | K20: =IF(D20="",0,FIXED(D20,0)&" mm "&" / "&FIXED(J20,2)&" hr") -> 0 | L20: =J20/24 -> 0 | M20: =SUM(D20:D22) -> 0
A21: =+A20+1 -> 46282 | B21: 17 | C21: 33.105813 | E21: 9.7155817 | F21: 4.1638207 | G21: =E21+F21 -> 13.879402 | J21: =H21+I21 -> 0 | K21: =IF(D21="",0,FIXED(D21,0)&" mm "&" / "&FIXED(J21,2)&" hr") -> 0 | L21: =J21/24 -> 0 | M21: =SUM(D21:D23) -> 0
A22: =+A21+1 -> 46283 | B22: 18 | C22: 1.8392118 | E22: 0.53975454 | F22: 0.23132337 | G22: =E22+F22 -> 0.77107791 | J22: =H22+I22 -> 0 | K22: =IF(D22="",0,FIXED(D22,0)&" mm "&" / "&FIXED(J22,2)&" hr") -> 0 | L22: =J22/24 -> 0 | M22: =SUM(D22:D24) -> 0
A23: =+A22+1 -> 46284 | B23: 19 | C23: - | E23: 0 | F23: 0 | G23: =E23+F23 -> 0 | J23: =H23+I23 -> 0 | K23: =IF(D23="",0,FIXED(D23,0)&" mm "&" / "&FIXED(J23,2)&" hr") -> 0 | L23: =J23/24 -> 0 | M23: =SUM(D23:D25) -> 0
A24: =+A23+1 -> 46285 | B24: 20 | C24: 4.9045648 | E24: 1.4393454 | F24: 0.61686233 | G24: =E24+F24 -> 2.0562078 | J24: =H24+I24 -> 0 | K24: =IF(D24="",0,FIXED(D24,0)&" mm "&" / "&FIXED(J24,2)&" hr") -> 0 | L24: =J24/24 -> 0 | M24: =SUM(D24:D26) -> 0
A25: =+A24+1 -> 46286 | B25: 21 | C25: - | E25: 0 | F25: 0 | G25: =E25+F25 -> 0 | J25: =H25+I25 -> 0 | K25: =IF(D25="",0,FIXED(D25,0)&" mm "&" / "&FIXED(J25,2)&" hr") -> 0 | L25: =J25/24 -> 0 | M25: =SUM(D25:D27) -> 0 | R25: MTD | S25: Rainfall | U25: Rain Day | V25: RS over plan
A26: =+A25+1 -> 46287 | B26: 22 | C26: 26.362036 | E26: 7.7364817 | F26: 3.315635 | G26: =E26+F26 -> 11.052117 | J26: =H26+I26 -> 0 | K26: =IF(D26="",0,FIXED(D26,0)&" mm "&" / "&FIXED(J26,2)&" hr") -> 0 | L26: =J26/24 -> 0 | M26: =SUM(D26:D28) -> 0 | S26: Prediction | T26: Actual | U26: Actual | V26: Actual
A27: =+A26+1 -> 46288 | B27: 23 | C27: - | E27: 0 | F27: 0 | G27: =E27+F27 -> 0 | J27: =H27+I27 -> 0 | K27: =IF(D27="",0,FIXED(D27,0)&" mm "&" / "&FIXED(J27,2)&" hr") -> 0 | L27: =J27/24 -> 0 | M27: =SUM(D27:D29) -> 0 | S27: =C40 -> 357.91062 | T27: =D40 -> 40.6 | U27: =COUNTIF(D5:D35,">0") -> 4 | V27: =COUNTIF(J5:J35,">6,45") -> 0
A28: =+A27+1 -> 46289 | B28: 24 | C28: 12.261412 | E28: 3.5983636 | F28: 1.5421558 | G28: =E28+F28 -> 5.1405194 | J28: =H28+I28 -> 0 | K28: =IF(D28="",0,FIXED(D28,0)&" mm "&" / "&FIXED(J28,2)&" hr") -> 0 | L28: =J28/24 -> 0 | M28: =SUM(D28:D30) -> 0
A29: =+A28+1 -> 46290 | B29: 25 | C29: - | E29: 0 | F29: 0 | G29: =E29+F29 -> 0 | J29: =H29+I29 -> 0 | K29: =IF(D29="",0,FIXED(D29,0)&" mm "&" / "&FIXED(J29,2)&" hr") -> 0 | L29: =J29/24 -> 0 | M29: =SUM(D29:D31) -> 0
A30: =+A29+1 -> 46291 | B30: 26 | C30: 76.020755 | E30: 16.8 | F30: 7.2 | G30: =E30+F30 -> 24 | J30: =H30+I30 -> 0 | K30: =IF(D30="",0,FIXED(D30,0)&" mm "&" / "&FIXED(J30,2)&" hr") -> 0 | L30: =J30/24 -> 0 | M30: =SUM(D30:D32) -> 0
A31: =+A30+1 -> 46292 | B31: 27 | C31: - | E31: 5.5098542 | F31: 2.3613661 | G31: =E31+F31 -> 7.8712203 | J31: =H31+I31 -> 0 | K31: =IF(D31="",0,FIXED(D31,0)&" mm "&" / "&FIXED(J31,2)&" hr") -> 0 | L31: =J31/24 -> 0 | M31: =SUM(D31:D33) -> 0
A32: =+A31+1 -> 46293 | B32: 28 | C32: 3.065353 | E32: 0.8995909 | F32: 0.38553896 | G32: =E32+F32 -> 1.2851299 | J32: =H32+I32 -> 0 | K32: =IF(D32="",0,FIXED(D32,0)&" mm "&" / "&FIXED(J32,2)&" hr") -> 0 | L32: =J32/24 -> 0 | M32: =SUM(D32:D34) -> 0
A33: =+A32+1 -> 46294 | B33: 29 | C33: 62.042745 | E33: 16.8 | F33: 7.2 | G33: =E33+F33 -> 24 | J33: =H33+I33 -> 0 | K33: =IF(D33="",0,FIXED(D33,0)&" mm "&" / "&FIXED(J33,2)&" hr") -> 0 | L33: =J33/24 -> 0 | M33: =SUM(D33:D35) -> 0
A34: =+A33+1 -> 46295 | B34: 30 | C34: 18.392118 | E34: 6.8052651 | F34: 2.9165422 | G34: =E34+F34 -> 9.7218073 | J34: =H34+I34 -> 0 | K34: =IF(D34="",0,FIXED(D34,0)&" mm "&" / "&FIXED(J34,2)&" hr") -> 0 | L34: =J34/24 -> 0
A35: =+A34+1 -> 46296 | B35: 31 | C35: - | E35: 0 | F35: 0 | G35: =E35+F35 -> 0 | J35: =H35+I35 -> 0 | K35: =IF(D35="",0,FIXED(D35,0)&" mm "&" / "&FIXED(J35,2)&" hr") -> 0 | L35: =J35/24 -> 0
B36: week1 | C36: =+SUMIF('[1]base coal'!$AM$6:$AM$36,weather!$B36,weather!C$5:C$35) -> 71.729261 | D36: =+SUMIF('[1]base coal'!$AM$6:$AM$36,weather!$B36,weather!D$5:D$35) -> 40.6 | E36: =+SUMIF('[1]base coal'!$AM$6:$AM$36,weather!$B36,weather!E$5:E$35) -> 21.050427 | F36: =+SUMIF('[1]base coal'!$AM$6:$AM$36,weather!$B36,weather!F$5:F$35) -> 9.0216116 | G36: =+SUMIF('[1]base coal'!$AM$6:$AM$36,weather!$B36,weather!G$5:G$35) -> 30.072039 | H36: =+SUMIF('[1]base coal'!$AM$6:$AM$36,weather!$B36,weather!H$5:H$35) -> 6.3333333 | I36: =+SUMIF('[1]base coal'!$AM$6:$AM$36,weather!$B36,weather!I$5:I$35) -> 3.6666667 | J36: =+SUMIF('[1]base coal'!$AM$6:$AM$36,weather!$B36,weather!J$5:J$35) -> 10 | K36: =IF(D36="",0,FIXED(D36,0)&" mm "&" / "&FIXED(J36,2)&" hr") -> 41 mm / 10.00 hr | N36: =31+28+31+30+31+30+31+31 -> 243
B37: week2 | C37: =+SUMIF('[1]base coal'!$AM$6:$AM$36,weather!$B37,weather!C$5:C$35) -> 25.626351 | D37: =+SUMIF('[1]base coal'!$AM$6:$AM$36,weather!$B37,weather!D$5:D$35) -> 0 | E37: =+SUMIF('[1]base coal'!$AM$6:$AM$36,weather!$B37,weather!E$5:E$35) -> 7.5205799 | F37: =+SUMIF('[1]base coal'!$AM$6:$AM$36,weather!$B37,weather!F$5:F$35) -> 3.2231057 | G37: =+SUMIF('[1]base coal'!$AM$6:$AM$36,weather!$B37,weather!G$5:G$35) -> 10.743686 | H37: =+SUMIF('[1]base coal'!$AM$6:$AM$36,weather!$B37,weather!H$5:H$35) -> 0 | I37: =+SUMIF('[1]base coal'!$AM$6:$AM$36,weather!$B37,weather!I$5:I$35) -> 0 | J37: =+SUMIF('[1]base coal'!$AM$6:$AM$36,weather!$B37,weather!J$5:J$35) -> 0 | K37: =IF(D37="",0,FIXED(D37,0)&" mm "&" / "&FIXED(J37,2)&" hr") -> 0 mm / 0.00 hr
B38: week3 | C38: =+SUMIF('[1]base coal'!$AM$6:$AM$36,weather!$B38,weather!C$5:C$35) -> 62.410587 | D38: =+SUMIF('[1]base coal'!$AM$6:$AM$36,weather!$B38,weather!D$5:D$35) -> 0 | E38: =+SUMIF('[1]base coal'!$AM$6:$AM$36,weather!$B38,weather!E$5:E$35) -> 18.315671 | F38: =+SUMIF('[1]base coal'!$AM$6:$AM$36,weather!$B38,weather!F$5:F$35) -> 7.8495731 | G38: =+SUMIF('[1]base coal'!$AM$6:$AM$36,weather!$B38,weather!G$5:G$35) -> 26.165244 | H38: =+SUMIF('[1]base coal'!$AM$6:$AM$36,weather!$B38,weather!H$5:H$35) -> 0 | I38: =+SUMIF('[1]base coal'!$AM$6:$AM$36,weather!$B38,weather!I$5:I$35) -> 0 | J38: =+SUMIF('[1]base coal'!$AM$6:$AM$36,weather!$B38,weather!J$5:J$35) -> 0 | K38: =IF(D38="",0,FIXED(D38,0)&" mm "&" / "&FIXED(J38,2)&" hr") -> 0 mm / 0.00 hr
B39: week4 | C39: =+SUMIF('[1]base coal'!$AM$6:$AM$36,weather!$B39,weather!C$5:C$35) -> 198.14442 | D39: =+SUMIF('[1]base coal'!$AM$6:$AM$36,weather!$B39,weather!D$5:D$35) -> 0 | E39: =+SUMIF('[1]base coal'!$AM$6:$AM$36,weather!$B39,weather!E$5:E$35) -> 58.149556 | F39: =+SUMIF('[1]base coal'!$AM$6:$AM$36,weather!$B39,weather!F$5:F$35) -> 24.921238 | G39: =+SUMIF('[1]base coal'!$AM$6:$AM$36,weather!$B39,weather!G$5:G$35) -> 83.070794 | H39: =+SUMIF('[1]base coal'!$AM$6:$AM$36,weather!$B39,weather!H$5:H$35) -> 0 | I39: =+SUMIF('[1]base coal'!$AM$6:$AM$36,weather!$B39,weather!I$5:I$35) -> 0 | J39: =+SUMIF('[1]base coal'!$AM$6:$AM$36,weather!$B39,weather!J$5:J$35) -> 0 | K39: =IF(D39="",0,FIXED(D39,0)&" mm "&" / "&FIXED(J39,2)&" hr") -> 0 mm / 0.00 hr | O39: =Dashboard!T34/(24*27) -> 0.036811196
B40: MTD | C40: =SUM(C5:C35) -> 357.91062 | D40: =SUM(D5:D35) -> 40.6 | E40: =SUM(E5:E35) -> 105.03623 | F40: =SUM(F5:F35) -> 45.015528 | G40: =SUM(G5:G35) -> 150.05176 | H40: =SUM(H5:H35) -> 6.3333333 | I40: =SUM(I5:I35) -> 3.6666667 | J40: =SUM(J5:J35) -> 10 | K40: =IF(D40="",0,FIXED(D40,0)&" mm "&" / "&FIXED(J40,2)&" hr") -> 41 mm / 10.00 hr | L40: =G40/24/31 -> 0.20168248
G41: =+G40/(24*31) -> 0.20168248 | J41: =+J40/(24*COUNT('Summary Sep26'!B19:B49)) -> 0.05952381 | K41: =IF(C40="",0,FIXED(C40,0)&" mm "&" / "&FIXED(G40,2)&" hr") -> 358 mm / 150.05 hr | W41: p20bk14 | AB41: p30bk14 | AG41: p30bk18 | AL41: p30bk20 | AQ41: p60bk14
...

Sheet Dashboard
A1: =+VLOOKUP($E$5,'Summary Sep26'!D19:AJ49,'Summary Sep26'!AO3+1,TRUE) -> 46272 | B1: =TEXT('Summary Sep26'!I54,"mmmm") -> September
C5: as update on | E5: ='Summary Sep26'!G54 -> 46272.44
C8: ROM Hauling | D8: Today | E8: MTD | F8: YTD
C9: Plan | D9: =VLOOKUP($E$5,todate_plan,12,TRUE) -> 23333.333 | E9: =HLOOKUP('To Date Summary'!$A$4,budget_plan,14,0)/'To Date Summary'!$A$3*'Summary Sep26'!$C$52 -> 163333.33 | F9: =VLOOKUP(E5,todate_plan,13,1) -> 5913333.3
C10: Actual | D10: =VLOOKUP($E$5,'Summary Sep26'!$D$19:$AI$50,'Summary Sep26'!W3,TRUE) -> 25248.23 | E10: =+'Summary Sep26'!W50 -> 144434.99 | F10: ='Summary Sep26'!K63 -> 5690095.6
C11: Ach. | D11: =IFERROR(D10/D9,"") -> 1.082067 | E11: =IFERROR(E10/E9,"") -> 0.88429586 | F11: =IFERROR(F10/F9,"") -> 0.96224841 | Q11: Coal Winning | R11: Today | S11: MTD | T11: YTD | U11: =U12-T12 -> 2478500
Q12: Plan | R12: =SUM(R13:R15) -> 22500 | S12: =SUM(S13:S15) -> 157500 | T12: =SUM(T13:T15) -> 5521500 | U12: 8000000
Q13: ROM LS | R13: =VLOOKUP($E$5,todate_plan,2,TRUE) -> 17166.667 | S13: =HLOOKUP('To Date Summary'!$A$4,budget_plan,11,0)/'To Date Summary'!$A$3*'Summary Sep26'!$C$52 -> 120166.67 | T13: =VLOOKUP(E5,todate_plan,3,1) -> 4112166.7
H14: Mine Stock Yard | K14: CV | L14: TS | M14: Ash | N14: IM | O14: TM | Q14: ROM HS | R14: =VLOOKUP($E$5,todate_plan,4,TRUE) -> 5333.3333 | S14: =HLOOKUP('To Date Summary'!$A$4,budget_plan,12,0)/'To Date Summary'!$A$3*'Summary Sep26'!$C$52 -> 37333.333 | T14: =VLOOKUP(E5,todate_plan,5,1) -> 1409333.3 | U14: =U12-T16 -> 2467163.3 | W14: =U14-U11 -> -11336.711
H15: Outlook | J15: =(HLOOKUP('Summary Sep26'!C52,[1]plan!$D$5:$AH$560,181,0)*1000)+(HLOOKUP('Summary Sep26'!C52,[1]plan!$D$5:$AH$560,291,0)*1000) -> 527535.58 | K15: ROM STOCK STATUS
H16: MTD | J16: =J18+J30+J24 -> 511307.74 | Q16: Actual | R16: =SUM(R17:R19) -> 22160.84 | S16: =SUM(S17:S19) -> 174095.22 | T16: =SUM(T17:T19) -> 5532836.7
H17: ="ROM Ulin "&FIXED(SUM('Stock Information'!F10,'Stock Information'!F17),0,FALSE)&" Ton" -> ROM Ulin 0 Ton | Q17: =Q13 -> ROM LS | R17: =IFERROR(HLOOKUP('Stock Information'!$C$5,base_all,14)+HLOOKUP('Stock Information'!$C$5,base_all,134),"")*1000 -> 14729.84 | S17: =([1]actual!AM18+[1]actual!AM102+[1]actual!AM150+[1]actual!AM162)*1000 -> 129902.82 | T17: =([1]actual!BJ18+[1]actual!BJ92+[1]actual!BJ150+[1]actual!BJ162)*1000 -> 4432223.8 | U17: =U14-U11 -> -11336.711 | W17: =T16/U12 -> 0.69160459
H18: Total | J18: =J19+J21 -> 0 | Q18: =Q14 -> ROM HS | R18: =IFERROR(HLOOKUP('Stock Information'!$C$5,base_all,56)+HLOOKUP('Stock Information'!$C$5,base_all,122)+HLOOKUP('Stock Information'!$C$5,base_all,140),"")*1000 -> 7431 | S18: =([1]actual!AM60+[1]actual!AM156)*1000 -> 44192.4 | T18: =([1]actual!BJ60+[1]actual!BJ156)*1000 -> 1100612.9 | U18: =U11-U14 -> 11336.711
H19: =IFERROR(J19/J18,0) -> 0 | J19: =J20 -> 0 | K19: =IFERROR(SUMPRODUCT($J$20:$J$20,K20:K20)/$J$19,"") | L19: =IFERROR(SUMPRODUCT($J$20:$J$20,L20:L20)/$J$19,"") | M19: =IFERROR(SUMPRODUCT($J$20:$J$20,M20:M20)/$J$19,"") | N19: =IFERROR(SUMPRODUCT($J$20:$J$20,N20:N20)/$J$19,"") | O19: =IFERROR(SUMPRODUCT($J$20:$J$20,O20:O20)/$J$19,"")
H20: ROM 1 | J20: =([1]actual!AP198)*1000 -> 0 | K20: =IFERROR([1]actual!AP199,"") | L20: =IFERROR([1]actual!AP200,"") | M20: =IFERROR([1]actual!AP201,"") | N20: =IFERROR([1]actual!AP202,"") | O20: =IFERROR([1]actual!AP203,"") | Q20: Ach. | R20: =IFERROR(R16/R12,"") -> 0.98492622 | S20: =IFERROR(S16/S12,"") -> 1.1053665 | T20: =IFERROR(T16/T12,"") -> 1.0020532 | W20: =SUM('Summary Sep26'!P19:P34) -> 174095.22
H21: =IFERROR(J21/J18,0) -> 0 | J21: =J22 -> 0 | K21: =IFERROR(SUMPRODUCT($J$22:$J$22,K22:K22)/$J$21,"") | L21: =IFERROR(SUMPRODUCT($J$22:$J$22,L22:L22)/$J$21,"") | M21: =IFERROR(SUMPRODUCT($J$22:$J$22,M22:M22)/$J$21,"") | N21: =IFERROR(SUMPRODUCT($J$22:$J$22,N22:N22)/$J$21,"") | O21: =IFERROR(SUMPRODUCT($J$22:$J$22,O22:O22)/$J$21,"") | Q21: =Q17 -> ROM LS | R21: =IFERROR(R17/R13,"") -> 0.85804893 | S21: =IFERROR(S17/S13,"") -> 1.0810221 | T21: =IFERROR(T17/T13,"") -> 1.0778318
C22: FC Production | D22: Today | E22: MTD | F22: YTD | H22: ROM 4 | J22: =([1]actual!AP240)*1000 -> 0 | K22: =IFERROR([1]actual!AP241,"") | L22: =IFERROR([1]actual!AP242,"") | M22: =IFERROR([1]actual!AP243,"") | N22: =IFERROR([1]actual!AP244,"") | O22: =IFERROR([1]actual!AP245,"") | Q22: =Q18 -> ROM HS | R22: =IFERROR(R18/R14,"") -> 1.3933125 | S22: =IFERROR(S18/S14,"") -> 1.183725 | T22: =IFERROR(T18/T14,"") -> 0.78094576 | W22: =SUM([1]budget!G302:G317) -> 334967.74
C23: Plan | D23: =SUM(D24:D26) -> 23333.333 | E23: =SUM(E24:E26) -> 163333.33 | F23: =SUM(F24:F26) -> 5913333.3 | H23: ="ROM Bengkirai "&FIXED(SUM('Stock Information'!F11,'Stock Information'!F12,'Stock Information'!F13,'Stock Information'!F14,'Stock Information'!F18,'Stock Information'!F19))&" Ton" -> ROM Bengkirai 511,307.74 Ton | R23: =IFERROR(R19/R15,"") | S23: =IFERROR(S19/S15,"") | T23: =IFERROR(T19/T15,"")
C24: =C49 -> HCV LS | D24: =VLOOKUP($E$5,todate_plan,8,TRUE) -> 20000 | E24: =HLOOKUP('To Date Summary'!$A$4,budget_plan,16,0)/'To Date Summary'!$A$3*'Summary Sep26'!$C$52 -> 140000 | F24: =VLOOKUP(E5,todate_plan,9,1) -> 4690000 | H24: Total | J24: =J25+J27 -> 511307.74
C25: =C50 -> HCV HS | D25: =VLOOKUP($E$5,todate_plan,10,TRUE) -> 3333.3333 | E25: =HLOOKUP('To Date Summary'!$A$4,budget_plan,17,0)/'To Date Summary'!$A$3*'Summary Sep26'!$C$52 -> 23333.333 | F25: =VLOOKUP(E5,todate_plan,11,1) -> 1223333.3 | H25: =IFERROR(J25/J24,0) -> 0.6701529 | J25: =J26 -> 342654.37 | K25: =IFERROR(SUMPRODUCT($J$26:$J$26,K26:K26)/$J$25,"") -> 6531.6306 | L25: =IFERROR(SUMPRODUCT($J$26:$J$26,L26:L26)/$J$25,"") -> 0.56643078 | M25: =IFERROR(SUMPRODUCT($J$26:$J$26,M26:M26)/$J$25,"") -> 4.2552446 | N25: =IFERROR(SUMPRODUCT($J$26:$J$26,N26:N26)/$J$25,"") -> 10.499662 | O25: =IFERROR(SUMPRODUCT($J$26:$J$26,O26:O26)/$J$25,"") -> 14.358423 | Q25: Stripping Ratio | R25: Today | S25: MTD | T25: YTD
C26: =C51 -> MCV LS | H26: ROM 1 | J26: =[1]actual!AP204*1000 -> 342654.37 | K26: =IFERROR([1]actual!AP205,"") -> 6531.6306 | L26: =IFERROR([1]actual!AP206,"") -> 0.56643078 | M26: =IFERROR([1]actual!AP207,"") -> 4.2552446 | N26: =IFERROR([1]actual!AP208,"") -> 10.499662 | O26: =IFERROR([1]actual!AP209,"") -> 14.358423 | Q26: ROM | R26: =+'Summary Sep26'!G83 -> 9.1801574 | S26: =+'Summary Sep26'!I83 -> 9.2375856 | T26: =+'Summary Sep26'!K83 -> 9.2042774
C27: Actual | D27: =SUM(D28:D30) -> 25248.23 | E27: =SUM(E28:E30) -> 144434.99 | F27: =SUM(F28:F30) -> 5690095.6 | H27: =IFERROR(J27/J24,0) -> 0.3298471 | J27: =J28 -> 168653.37 | K27: =IFERROR(SUMPRODUCT($J$28:$J$28,K28:K28)/$J$27,"") -> 6536.1741 | L27: =IFERROR(SUMPRODUCT($J$28:$J$28,L28:L28)/$J$27,"") -> 1.7362849 | M27: =IFERROR(SUMPRODUCT($J$28:$J$28,M28:M28)/$J$27,"") -> 4.6292144 | N27: =IFERROR(SUMPRODUCT($J$28:$J$28,N28:N28)/$J$27,"") -> 10.021299 | O27: =IFERROR(SUMPRODUCT($J$28:$J$28,O28:O28)/$J$27,"") -> 13.565795 | Q27: FC | R27: =+'Summary Sep26'!G84 -> 8.0575945 | S27: =+'Summary Sep26'!I84 -> 11.134556 | T27: =+'Summary Sep26'!K84 -> 8.949896
C28: =C24 -> HCV LS | D28: =+'Summary Sep26'!G67 -> 11700.3 | E28: =+'Summary Sep26'!X50 -> 21307.35 | F28: =+'Summary Sep26'!K67 -> 4113206.3 | H28: ROM 4 | J28: =[1]actual!AP246*1000 -> 168653.37 | K28: =IFERROR([1]actual!AP247,"") -> 6536.1741 | L28: =IFERROR([1]actual!AP248,"") -> 1.7362849 | M28: =IFERROR([1]actual!AP249,"") -> 4.6292144 | N28: =IFERROR([1]actual!AP250,"") -> 10.021299 | O28: =IFERROR([1]actual!AP251,"") -> 13.565795
C29: =C25 -> HCV HS | D29: =+'Summary Sep26'!G68 -> 13547.93 | E29: =+'Summary Sep26'!Y50 -> 73938.92 | F29: =+'Summary Sep26'!K68 -> 1200453.7 | H29: ="ROM SB1 "&FIXED(SUM('Stock Information'!F31,'Stock Information'!F32),0,FALSE)&" Ton " -> ROM SB1 0 Ton | Q29: Weather | S29: Today | T29: MTD | U29: YTD
C30: =C26 -> MCV LS | D30: =+'Summary Sep26'!G69 -> 0 | E30: =+'Summary Sep26'!Z50 -> 49188.72 | F30: =+'Summary Sep26'!K69 -> 376435.6 | H30: Total | J30: =J31+J33 -> 0 | Q30: Rainfall | R30: Prediction | S30: =HLOOKUP($B$1,[1]budget!$C$2:$N$25,23,0) -> 11.930354 | T30: =+S30*'Summary Sep26'!C52 -> 83.512478 | U30: =VLOOKUP(E5,todate_plan,19,1) -> 3831.5754
C31: Ach. | D31: =IFERROR(D27/D23,"") -> 1.082067 | E31: =IFERROR(E27/E23,"") -> 0.88429586 | F31: =IFERROR(F27/F23,"") -> 0.96224841 | H31: =IFERROR(J31/J30,0) -> 0 | J31: =J32 -> 0 | K31: =IFERROR(SUMPRODUCT($J$32:$J$32,K32:K32)/$J$31,"") | L31: =IFERROR(SUMPRODUCT($J$32:$J$32,L32:L32)/$J$31,"") | M31: =IFERROR(SUMPRODUCT($J$32:$J$32,M32:M32)/$J$31,"") | N31: =IFERROR(SUMPRODUCT($J$32:$J$32,N32:N32)/$J$31,"") | O31: =IFERROR(SUMPRODUCT($J$32:$J$32,O32:O32)/$J$31,"") | R31: Outlook | S31: =HLOOKUP($B$1,'[1]Rainfall Out26'!$D$1:$O$14,11,0) -> 8.4613333 | T31: =+S31*'Summary Sep26'!$C$52 -> 59.229333 | U31: =VLOOKUP(E5,'[1]Rainfall Out26'!$E$22:$I$389,3,1) -> 2970.7647
C32: =C24 -> HCV LS | D32: =IFERROR(D28/D24,"") -> 0.585015 | E32: =IFERROR(E28/E24,"") -> 0.15219536 | F32: =IFERROR(F28/F24,"") -> 0.87701627 | H32: ROM 1 | J32: =[1]actual!AM328*1000 -> 0 | K32: =IFERROR([1]actual!AP329,"") -> 0 | L32: =IFERROR([1]actual!AP330,"") -> 0 | M32: =IFERROR([1]actual!AP331,"") -> 0 | N32: =IFERROR([1]actual!AP332,"") -> 0 | O32: =IFERROR([1]actual!AP333,"") -> 0 | R32: Actual | S32: =VLOOKUP('Summary Sep26'!C52,weather!$B$5:$K$35,3,0) -> 10.6 | T32: =+weather!D40 -> 40.6 | U32: =+weather!D44 -> 2342.4
C33: =C25 -> HCV HS | D33: =IFERROR(D29/D25,"") -> 4.064379 | E33: =IFERROR(E29/E25,"") -> 3.1688109 | F33: =IFERROR(F29/F25,"") -> 0.98129727 | H33: =IFERROR(J33/J30,0) -> 0 | J33: =J34 -> 0 | K33: =IFERROR(SUMPRODUCT($J$34:$J$34,K34:K34)/$J$33,"") | L33: =IFERROR(SUMPRODUCT($J$34:$J$34,L34:L34)/$J$33,"") | M33: =IFERROR(SUMPRODUCT($J$34:$J$34,M34:M34)/$J$33,"") | N33: =IFERROR(SUMPRODUCT($J$34:$J$34,N34:N34)/$J$33,"") | O33: =IFERROR(SUMPRODUCT($J$34:$J$34,O34:O34)/$J$33,"") | Q33: Rain & Slip. | R33: Prediction | S33: =HLOOKUP($B$1,[1]budget!$C$2:$N$25,24,0) -> 5.0017254 | T33: =+S33*'Summary Sep26'!C52 -> 35.012078 | U33: =VLOOKUP(E5,todate_plan,21,1) -> 1325.2421
C34: =C26 -> MCV LS | D34: =IFERROR(D30/D26,"") | E34: =IFERROR(E30/E26,"") | F34: =IFERROR(F30/F26,"") | H34: ROM 4 | J34: =[1]actual!AM334*1000 -> 0 | K34: =IFERROR([1]actual!AP335,"") | L34: =IFERROR([1]actual!AP336,"") | M34: =IFERROR([1]actual!AP337,"") | N34: =IFERROR([1]actual!AP338,"") | O34: =IFERROR([1]actual!AP339,"") | Q34: (Hrs) | R34: =R31 -> Outlook | S34: =HLOOKUP($B$1,'[1]Rainfall Out26'!$D$1:$O$14,14,0) -> 3.407665 | T34: =+S34*'Summary Sep26'!C52 -> 23.853655 | U34: =VLOOKUP(E5,'[1]Rainfall Out26'!$E$22:$I$389,5,1) -> 1057.871
R35: Actual | S35: =VLOOKUP('Summary Sep26'!C52,weather!$B$5:$K$35,9,0) -> 3.8833333 | T35: =+weather!J40 -> 10 | U35: =+weather!J44 -> 1002.0333
Q36: Rain & Slip. | R36: Prediction | S36: =+S33/24 -> 0.20840522 | T36: =+weather!G41 -> 0.20168248 | U36: =weather!N44 -> 0.22087369
Q37: (%) | R37: =R34 -> Outlook | S37: =+S34/24 -> 0.14198604 | T37: =weather!O44 -> 0.14198604 | U37: =weather!N45 -> 0.17631183
R38: Actual | S38: =+S35/24 -> 0.16180556 | T38: =+weather!J41 -> 0.05952381 | U38: =+weather!L44 -> 0.16700556
O40: Level | Q40: OB Removal | R40: Today | S40: MTD | T40: YTD
O41: ='Summary Sep26'!E86 -> 0,30 | Q41: Plan | R41: =VLOOKUP($E$5,todate_plan,16,TRUE) -> 214333.33 | S41: =HLOOKUP('To Date Summary'!$A$4,budget_plan,3,0)/'To Date Summary'!$A$3*'Summary Sep26'!$C$52 -> 1500333.3 | T41: =VLOOKUP(E5,todate_plan,17,1) -> 50875748
Q42: Actual | R42: =+'Summary Sep26'!G74 -> 203440 | S42: =+'Summary Sep26'!I74 -> 1608219.5 | T42: =+'Summary Sep26'!K74 -> 50925764
Q43: Ach. | R43: =IFERROR(R42/R41,"") -> 0.94917574 | S43: =IFERROR(S42/S41,"") -> 1.0719081 | T43: =IFERROR(T42/T41,"") -> 1.0009831
C46: Port Stock Yard | L46: FC Loading | M46: Today | N46: MTD | O46: YTD | Q46: Remark:
C47: Outlook | D47: =HLOOKUP('Summary Sep26'!C52,[1]plan!$D$5:$AH$560,504,0)*1000 -> 317646.33 | L47: Plan | M47: =VLOOKUP($E$5,todate_plan,14,TRUE) -> 23333.333 | N47: =HLOOKUP('To Date Summary'!$A$4,budget_plan,18,0)/'To Date Summary'!$A$3*'Summary Sep26'!$C$52 -> 163333.33 | O47: =VLOOKUP(E5,todate_plan,15,1) -> 5913333.3
C48: MTD | D48: ='Summary Sep26'!AE50 -> 386970.99 | E48: CV | F48: TS | G48: Ash | H48: IM | I48: TM | L48: Actual | M48: =+'Summary Sep26'!G70 -> 0 | N48: =+'Summary Sep26'!I70 -> 46610.33 | O48: =+'Summary Sep26'!K70 -> 5441415.6
...

Sheet Summary Sep26
D1: 46266
D3: 1 | E3: 2 | F3: 3 | G3: 4 | H3: 5 | I3: 6 | J3: 7 | K3: 8 | L3: 9 | M3: 10 | N3: 11 | O3: 12 | P3: 13 | Q3: 14 | R3: 15 | S3: 16 | T3: 17 | U3: 18 | V3: 19 | W3: 20 | X3: 21 | Y3: 22 | Z3: 23 | AA3: 24 | AB3: 25 | AC3: 26 | AD3: 27 | AE3: 28 | AF3: 29 | AG3: 30 | AH3: 31 | AI3: 32 | AJ3: 33 | AK3: 34 | AL3: 35 | AM3: 36 | AN3: 37
D4: Date | E4: OB Removal Inpit | I4: OB Outpit (Void Management) | M4: Coal Winning | Q4: ROM Stock | T4: ROM Transfer | U4: ROM Hauling | X4: FC Production | AB4: FC Stock at PSY | AF4: FC Load
F5: PAMA | G5: SNS | H5: Total | J5: TJP | K5: MPA | L5: Total | N5: PAMA | O5: SNS | P5: Total | Q5: Biangan | R5: SB1 | S5: Total | T5: Biangan to SB1 | U5: Biangan to Crusher | V5: SB1 to Crusher | W5: Total | X5: BEK.HCV.LS | Y5: BEK.HCV.HS | Z5: BEK.MCV.LS | AA5: Total | AB5: BEK.HCV.LS | AC5: BEK.HCV.HS | AD5: BEK.MCV.LS | AE5: Total | AF5: BEK.HCV.LS | AG5: BEK.HCV.HS | AH5: BEK.MCV.LS | AI5: Total
D6: 46023 | E6: 0 | F6: 4905685.4 | G6: 1398129.5 | H6: 6303814.9 | I6: 0 | J6: 760613.96 | K6: 180048.65 | L6: 940662.61 | M6: 0 | N6: 460932.83 | O6: 115504.12 | P6: 576436.96 | T6: 0 | U6: 717367.52 | V6: 27916.52 | W6: 745284.04 | X6: 590830.74 | Y6: 154453.3 | Z6: 0 | AA6: 745284.04 | AF6: 664424.55 | AG6: 147148.65 | AH6: 0 | AI6: 811573.2
D7: 46054 | E7: 0 | F7: 3981087.5 | G7: 1412893.7 | H7: 5393981.3 | I7: 0 | J7: 798131.35 | K7: 226735.46 | L7: 1024866.8 | M7: 0 | N7: 398702.2 | O7: 141164.39 | P7: 539866.59 | T7: 0 | U7: 724964.99 | V7: 0 | W7: 724964.99 | X7: 588667.56 | Y7: 136297.43 | Z7: 0 | AA7: 724964.99 | AF7: 588648.96 | AG7: 114918.42 | AH7: 0 | AI7: 703567.38
D8: 46082 | E8: 0 | F8: 4107521.7 | G8: 1497772.1 | H8: 5605293.8 | I8: 0 | J8: 852792.43 | K8: 216187.52 | L8: 1068979.9 | M8: 0 | N8: 465545.66 | O8: 146335.72 | P8: 611881.38 | T8: 0 | U8: 680586.91 | V8: 0 | W8: 680586.91 | X8: 560717.53 | Y8: 119869.38 | Z8: 0 | AA8: 680586.91 | AF8: 627786.88 | AG8: 120999.97 | AH8: 0 | AI8: 748786.85
D9: 46113 | E9: 0 | F9: 4530187.9 | G9: 1718704 | H9: 6248891.9 | I9: 0 | J9: 750562.78 | K9: 277268.81 | L9: 1027831.6 | M9: 0 | N9: 465845.17 | O9: 132507.39 | P9: 598352.56 | T9: 0 | U9: 644033.28 | V9: 0 | W9: 644033.28 | X9: 451594.63 | Y9: 192438.65 | Z9: 0 | AA9: 644033.28 | AF9: 441897.61 | AG9: 184549.87 | AH9: 0 | AI9: 626447.48
D10: 46143 | E10: 0 | F10: 4387802.4 | G10: 1591207.8 | H10: 5979010.2 | I10: 0 | J10: 766350.76 | K10: 347476.57 | L10: 1113827.3 | M10: 0 | N10: 424013.31 | O10: 161830.64 | P10: 585843.95 | T10: 0 | U10: 680271.52 | V10: 0 | W10: 680271.52 | X10: 556309.22 | Y10: 123962.3 | Z10: 0 | AA10: 680271.52 | AF10: 598161.88 | AG10: 87734.25 | AH10: 0 | AI10: 685896.13
D11: 46174 | E11: 0 | F11: 4381018.6 | G11: 1664166.1 | H11: 6045184.7 | I11: 0 | J11: 879907.71 | K11: 329535.45 | L11: 1209443.2 | M11: 0 | N11: 525436.92 | O11: 176766.64 | P11: 702203.56 | T11: 0 | U11: 702870.77 | V11: 0 | W11: 702870.77 | X11: 530901.96 | Y11: 115053.53 | Z11: 56915.28 | AA11: 702870.77 | AF11: 532294.75 | AG11: 113296.76 | AH11: 32554.42 | AI11: 678145.93
D12: 46204 | E12: 0 | F12: 5113178.9 | G12: 1628797.6 | H12: 6741976.6 | I12: 0 | J12: 906558.66 | K12: 552311.66 | L12: 1458870.3 | M12: 0 | N12: 667691.07 | O12: 217887.33 | P12: 885578.4 | T12: 0 | U12: 792669.72 | V12: 0 | W12: 792669.72 | X12: 443660.32 | Y12: 184064.04 | Z12: 164945.36 | AA12: 792669.72 | AF12: 368520.06 | AG12: 172023.18 | AH12: 120370.81 | AI12: 660914.05
D13: 46235 | E13: 0 | F13: 5020895 | G13: 1978496 | H13: 6999391 | I13: 0 | J13: 985266.61 | K13: 491318.54 | L13: 1476585.1 | M13: 0 | N13: 587322.98 | O13: 271255.12 | P13: 858578.1 | T13: 0 | U13: 574979.36 | V13: 0 | W13: 574979.36 | X13: 369217.01 | Y13: 100376.11 | Z13: 105386.24 | AA13: 574979.36 | AF13: 246006.73 | AG13: 87181.11 | AH13: 146286.46 | AI13: 479474.3
D14: 46266 | E14: 0 | H14: 0 | I14: 0 | L14: 0 | P14: 0 | W14: 0 | AA14: 0 | AI14: 0
D15: 46296 | E15: 0 | H15: 0 | I15: 0 | L15: 0 | P15: 0 | W15: 0 | AA15: 0 | AI15: 0
D16: 46327 | E16: 0 | H16: 0 | I16: 0 | L16: 0 | P16: 0 | W16: 0 | AA16: 0 | AI16: 0
D17: 46357 | E17: 0 | H17: 0 | I17: 0 | L17: 0 | P17: 0 | W17: 0 | AA17: 0 | AI17: 0
D18: 46238 | Q18: 481647.51 | R18: 0 | S18: 481647.51 | AB18: 199887.35 | AC18: 74273.103 | AD18: 14985.871 | AE18: 289146.33
A19: 1646266 | B19: 1 | C19: 1 | D19: 46266 | E19: 0 | F19: 179119.5 | G19: 64274.5 | H19: 243394 | I19: 0 | J19: 31861 | K19: 13955 | L19: 45816 | M19: 0 | N19: 18823.44 | O19: 9104.86 | P19: 27928.3 | Q19: 500162.83 | R19: 0 | S19: 500162.83 | T19: 0 | U19: 9412.98 | V19: 0 | W19: 9412.98 | X19: 0 | Y19: 9412.98 | Z19: 0 | AA19: 9412.98 | AB19: 188675.4 | AC19: 83686.083 | AD19: 14985.871 | AE19: 287347.36 | AF19: 11211.95 | AG19: 0 | AH19: 0 | AI19: 11211.95 | AJ19: 1 | AK19: 1 | AL19: 16 | AM19: 27928.3
A20: 1646267 | B20: 1 | C20: 2 | D20: 46267 | E20: 0 | F20: 177397.5 | G20: 66184 | H20: 243581.5 | I20: 0 | J20: 32960 | K20: 13266 | L20: 46226 | M20: 0 | N20: 17447.98 | O20: 8108.72 | P20: 25556.7 | Q20: 502939.92 | R20: 0 | S20: 502939.92 | T20: 0 | U20: 22779.61 | V20: 0 | W20: 22779.61 | X20: 0 | Y20: 22779.61 | Z20: 0 | AA20: 22779.61 | AB20: 188675.4 | AC20: 106465.69 | AD20: 14985.871 | AE20: 310126.97 | AF20: 0 | AG20: 0 | AH20: 0 | AI20: 0 | AJ20: 2 | AL20: 16 | AM20: 25556.7
A21: 1646268 | B21: 1 | C21: 3 | D21: 46268 | E21: 0 | F21: 181954.5 | G21: 60583.5 | H21: 242538 | I21: 0 | J21: 38373 | K21: 12986 | L21: 51359 | M21: 0 | N21: 16419.18 | O21: 8728.82 | P21: 25148 | Q21: 504056.8 | R21: 0 | S21: 504056.8 | T21: 0 | U21: 24031.12 | V21: 0 | W21: 24031.12 | X21: 0 | Y21: 11020.63 | Z21: 13010.49 | AA21: 24031.12 | AB21: 177630.61 | AC21: 117486.32 | AD21: 27996.361 | AE21: 323113.3 | AF21: 11044.79 | AG21: 0 | AH21: 0 | AI21: 11044.79 | AJ21: 3 | AK21: 3 | AL21: 16 | AM21: 25148
A22: 1646269 | B22: 1 | C22: 4 | D22: 46269 | E22: 0 | F22: 179655 | G22: 62890.5 | H22: 242545.5 | I22: 0 | J22: 26533 | K22: 12693 | L22: 39226 | M22: 0 | N22: 17207.74 | O22: 8435.36 | P22: 25643.1 | Q22: 506233.43 | R22: 0 | S22: 506233.43 | T22: 0 | U22: 23466.47 | V22: 0 | W22: 23466.47 | X22: 0 | Y22: 0 | Z22: 23466.47 | AA22: 23466.47 | AB22: 167062.08 | AC22: 117486.32 | AD22: 51462.831 | AE22: 336011.24 | AF22: 10568.53 | AG22: 0 | AH22: 0 | AI22: 10568.53 | AJ22: 4 | AL22: 16 | AM22: 25643.1
A23: 1646270 | B23: 1 | C23: 5 | D23: 46270 | E23: 0 | F23: 133434 | G23: 53497.5 | H23: 186931.5 | I23: 0 | J23: 30561 | K23: 12100 | L23: 42661 | M23: 0 | N23: 13313.06 | O23: 7538.9 | P23: 20851.96 | Q23: 506230.1 | R23: 0 | S23: 506230.1 | T23: 0 | U23: 20855.29 | V23: 0 | W23: 20855.29 | X23: 0 | Y23: 8143.53 | Z23: 12711.76 | AA23: 20855.29 | AB23: 167062.08 | AC23: 125629.85 | AD23: 64174.591 | AE23: 356866.53 | AF23: 0 | AG23: 0 | AH23: 0 | AI23: 0 | AJ23: 5 | AK23: 5 | AL23: 16 | AM23: 20851.96
A24: 1646271 | B24: 1 | C24: 6 | D24: 46271 | E24: 0 | F24: 182133 | G24: 63656 | H24: 245789 | I24: 0 | J24: 34857 | K24: 13396 | L24: 48253 | M24: 0 | N24: 17888.24 | O24: 8918.08 | P24: 26806.32 | Q24: 514395.13 | R24: 0 | S24: 514395.13 | T24: 0 | U24: 18641.29 | V24: 0 | W24: 18641.29 | X24: 9607.05 | Y24: 9034.24 | Z24: 0 | AA24: 18641.29 | AB24: 171181.11 | AC24: 126367.05 | AD24: 64174.591 | AE24: 361722.76 | AF24: 0 | AG24: 13785.06 | AH24: 0 | AI24: 13785.06 | AJ24: 6 | AL24: 16 | AM24: 26806.32
A25: 1646272 | B25: 1 | C25: 7 | D25: 46272 | E25: 0 | F25: 150381 | G25: 53059 | H25: 203440 | I25: 0 | J25: 32105 | K25: 11448 | L25: 43553 | M25: 0 | N25: 13704.44 | O25: 8456.4 | P25: 22160.84 | Q25: 511307.74 | R25: 0 | S25: 511307.74 | T25: 0 | U25: 25248.23 | V25: 0 | W25: 25248.23 | X25: 11700.3 | Y25: 13547.93 | Z25: 0 | AA25: 25248.23 | AB25: 182881.41 | AC25: 139914.98 | AD25: 64174.591 | AE25: 386970.99 | AF25: 0 | AG25: 0 | AH25: 0 | AI25: 0 | AJ25: 7 | AK25: 7 | AL25: 16 | AM25: 22160.84
A26: 1646273 | C26: 8 | D26: 46273 | E26: 0 | F26: 0 | G26: 0 | H26: 0 | I26: 0 | J26: 0 | K26: 0 | L26: 0 | M26: 0 | N26: 0 | O26: 0 | P26: 0 | Q26: 0 | R26: 0 | S26: 0 | T26: 0 | U26: 0 | V26: 0 | W26: 0 | X26: 0 | Y26: 0 | Z26: 0 | AA26: 0 | AB26: 0 | AC26: 0 | AD26: 0 | AE26: 0 | AF26: 0 | AG26: 0 | AH26: 0 | AI26: 0 | AJ26: 8 | AL26: 16
A27: 1646274 | C27: 9 | D27: 46274 | E27: 0 | F27: 0 | G27: 0 | H27: 0 | I27: 0 | J27: 0 | K27: 0 | L27: 0 | M27: 0 | N27: 0 | O27: 0 | P27: 0 | Q27: 0 | R27: 0 | S27: 0 | T27: 0 | U27: 0 | V27: 0 | W27: 0 | X27: 0 | Y27: 0 | Z27: 0 | AA27: 0 | AB27: 0 | AC27: 0 | AD27: 0 | AE27: 0 | AF27: 0 | AG27: 0 | AH27: 0 | AI27: 0 | AJ27: 9 | AK27: 9 | AL27: 16
A28: 1646275 | C28: 10 | D28: 46275 | E28: 0 | F28: 0 | G28: 0 | H28: 0 | I28: 0 | J28: 0 | K28: 0 | L28: 0 | M28: 0 | N28: 0 | O28: 0 | P28: 0 | Q28: 0 | R28: 0 | S28: 0 | T28: 0 | U28: 0 | V28: 0 | W28: 0 | X28: 0 | Y28: 0 | Z28: 0 | AA28: 0 | AB28: 0 | AC28: 0 | AD28: 0 | AE28: 0 | AF28: 0 | AG28: 0 | AH28: 0 | AI28: 0 | AJ28: 10 | AL28: 16
A29: 1646276 | C29: 11 | D29: 46276 | E29: 0 | F29: 0 | G29: 0 | H29: 0 | I29: 0 | J29: 0 | K29: 0 | L29: 0 | M29: 0 | N29: 0 | O29: 0 | P29: 0 | Q29: 0 | R29: 0 | S29: 0 | T29: 0 | U29: 0 | V29: 0 | W29: 0 | X29: 0 | Y29: 0 | Z29: 0 | AA29: 0 | AB29: 0 | AC29: 0 | AD29: 0 | AE29: 0 | AF29: 0 | AG29: 0 | AH29: 0 | AI29: 0 | AJ29: 11 | AK29: 11 | AL29: 16
A30: 1646277 | C30: 12 | D30: 46277 | E30: 0 | F30: 0 | G30: 0 | H30: 0 | I30: 0 | J30: 0 | K30: 0 | L30: 0 | M30: 0 | N30: 0 | O30: 0 | P30: 0 | Q30: 0 | R30: 0 | S30: 0 | T30: 0 | U30: 0 | V30: 0 | W30: 0 | X30: 0 | Y30: 0 | Z30: 0 | AA30: 0 | AB30: 0 | AC30: 0 | AD30: 0 | AE30: 0 | AF30: 0 | AG30: 0 | AH30: 0 | AI30: 0 | AJ30: 12 | AL30: 16
A31: 1646278 | C31: 13 | D31: 46278 | E31: 0 | F31: 0 | G31: 0 | H31: 0 | I31: 0 | J31: 0 | K31: 0 | L31: 0 | M31: 0 | N31: 0 | O31: 0 | P31: 0 | Q31: 0 | R31: 0 | S31: 0 | T31: 0 | U31: 0 | V31: 0 | W31: 0 | X31: 0 | Y31: 0 | Z31: 0 | AA31: 0 | AB31: 0 | AC31: 0 | AD31: 0 | AE31: 0 | AF31: 0 | AG31: 0 | AH31: 0 | AI31: 0 | AJ31: 13 | AK31: 13 | AL31: 16
A32: 1646279 | C32: 14 | D32: 46279 | E32: 0 | F32: 0 | G32: 0 | H32: 0 | I32: 0 | J32: 0 | K32: 0 | L32: 0 | M32: 0 | N32: 0 | O32: 0 | P32: 0 | Q32: 0 | R32: 0 | S32: 0 | T32: 0 | U32: 0 | V32: 0 | W32: 0 | X32: 0 | Y32: 0 | Z32: 0 | AA32: 0 | AB32: 0 | AC32: 0 | AD32: 0 | AE32: 0 | AF32: 0 | AG32: 0 | AH32: 0 | AI32: 0 | AJ32: 14 | AL32: 16
A33: 1646280 | C33: 15 | D33: 46280 | E33: 0 | F33: 0 | G33: 0 | H33: 0 | I33: 0 | J33: 0 | K33: 0 | L33: 0 | M33: 0 | N33: 0 | O33: 0 | P33: 0 | Q33: 0 | R33: 0 | S33: 0 | T33: 0 | U33: 0 | V33: 0 | W33: 0 | X33: 0 | Y33: 0 | Z33: 0 | AA33: 0 | AB33: 0 | AC33: 0 | AD33: 0 | AE33: 0 | AF33: 0 | AG33: 0 | AH33: 0 | AI33: 0 | AJ33: 15 | AK33: 15 | AL33: 16
A34: 1646281 | C34: 16 | D34: 46281 | E34: 0 | F34: 0 | G34: 0 | H34: 0 | I34: 0 | J34: 0 | K34: 0 | L34: 0 | M34: 0 | N34: 0 | O34: 0 | P34: 0 | Q34: 0 | R34: 0 | S34: 0 | T34: 0 | U34: 0 | V34: 0 | W34: 0 | X34: 0 | Y34: 0 | Z34: 0 | AA34: 0 | AB34: 0 | AC34: 0 | AD34: 0 | AE34: 0 | AF34: 0 | AG34: 0 | AH34: 0 | AI34: 0 | AJ34: 16 | AL34: 16
A35: 1646282 | C35: 17 | D35: 46282 | E35: 0 | F35: 0 | G35: 0 | H35: 0 | I35: 0 | J35: 0 | K35: 0 | L35: 0 | M35: 0 | N35: 0 | O35: 0 | P35: 0 | Q35: 0 | R35: 0 | S35: 0 | T35: 0 | U35: 0 | V35: 0 | W35: 0 | X35: 0 | Y35: 0 | Z35: 0 | AA35: 0 | AB35: 0 | AC35: 0 | AD35: 0 | AE35: 0 | AF35: 0 | AG35: 0 | AH35: 0 | AI35: 0 | AJ35: 17 | AK35: 17 | AL35: 16
A36: 1646283 | C36: 18 | D36: 46283 | E36: 0 | F36: 0 | G36: 0 | H36: 0 | I36: 0 | J36: 0 | K36: 0 | L36: 0 | M36: 0 | N36: 0 | O36: 0 | P36: 0 | Q36: 0 | R36: 0 | S36: 0 | T36: 0 | U36: 0 | V36: 0 | W36: 0 | X36: 0 | Y36: 0 | Z36: 0 | AA36: 0 | AB36: 0 | AC36: 0 | AD36: 0 | AE36: 0 | AF36: 0 | AG36: 0 | AH36: 0 | AI36: 0 | AJ36: 18 | AL36: 16
A37: 1646284 | C37: 19 | D37: 46284 | E37: 0 | F37: 0 | G37: 0 | H37: 0 | I37: 0 | J37: 0 | K37: 0 | L37: 0 | M37: 0 | N37: 0 | O37: 0 | P37: 0 | Q37: 0 | R37: 0 | S37: 0 | T37: 0 | U37: 0 | V37: 0 | W37: 0 | X37: 0 | Y37: 0 | Z37: 0 | AA37: 0 | AB37: 0 | AC37: 0 | AD37: 0 | AE37: 0 | AF37: 0 | AG37: 0 | AH37: 0 | AI37: 0 | AJ37: 19 | AK37: 19 | AL37: 16
A38: 1646285 | C38: 20 | D38: 46285 | E38: 0 | F38: 0 | G38: 0 | H38: 0 | I38: 0 | J38: 0 | K38: 0 | L38: 0 | M38: 0 | N38: 0 | O38: 0 | P38: 0 | Q38: 0 | R38: 0 | S38: 0 | T38: 0 | U38: 0 | V38: 0 | W38: 0 | X38: 0 | Y38: 0 | Z38: 0 | AA38: 0 | AB38: 0 | AC38: 0 | AD38: 0 | AE38: 0 | AF38: 0 | AG38: 0 | AH38: 0 | AI38: 0 | AJ38: 20 | AL38: 16
A39: 1646286 | C39: 21 | D39: 46286 | E39: 0 | F39: 0 | G39: 0 | H39: 0 | I39: 0 | J39: 0 | K39: 0 | L39: 0 | M39: 0 | N39: 0 | O39: 0 | P39: 0 | Q39: 0 | R39: 0 | S39: 0 | T39: 0 | U39: 0 | V39: 0 | W39: 0 | X39: 0 | Y39: 0 | Z39: 0 | AA39: 0 | AB39: 0 | AC39: 0 | AD39: 0 | AE39: 0 | AF39: 0 | AG39: 0 | AH39: 0 | AI39: 0 | AJ39: 21 | AK39: 21 | AL39: 16
A40: 1646287 | C40: 22 | D40: 46287 | E40: 0 | F40: 0 | G40: 0 | H40: 0 | I40: 0 | J40: 0 | K40: 0 | L40: 0 | M40: 0 | N40: 0 | O40: 0 | P40: 0 | Q40: 0 | R40: 0 | S40: 0 | T40: 0 | U40: 0 | V40: 0 | W40: 0 | X40: 0 | Y40: 0 | Z40: 0 | AA40: 0 | AB40: 0 | AC40: 0 | AD40: 0 | AE40: 0 | AF40: 0 | AG40: 0 | AH40: 0 | AI40: 0 | AJ40: 22 | AL40: 16
A41: 1646288 | C41: 23 | D41: 46288 | E41: 0 | F41: 0 | G41: 0 | H41: 0 | I41: 0 | J41: 0 | K41: 0 | L41: 0 | M41: 0 | N41: 0 | O41: 0 | P41: 0 | Q41: 0 | R41: 0 | S41: 0 | T41: 0 | U41: 0 | V41: 0 | W41: 0 | X41: 0 | Y41: 0 | Z41: 0 | AA41: 0 | AB41: 0 | AC41: 0 | AD41: 0 | AE41: 0 | AF41: 0 | AG41: 0 | AH41: 0 | AI41: 0 | AJ41: 23 | AK41: 23 | AL41: 16
...

Sheet To Date Summary
A3: 30 | B3: =+Dashboard!E5 -> 46272.44 | C3: Today | F3: % Achievement | H3: MTD | K3: % Achievement | M3: YTD | P3: % Achievement | R3: REMARK
A4: =TEXT(B3,"mmm") -> Sep | C4: Budget | D4: Outlook | E4: Actual | F4: By Budget | G4: By Outlook | H4: Budget | I4: Outlook | J4: Actual | K4: By Budget | L4: By Outlook | M4: Budget | N4: Outlook | O4: Actual | P4: By Budget | Q4: By Outlook
B6: OB | C6: =SUM(C7:C9) -> 214333.33 | D6: =SUM(D7:D9) -> 228436.33 | E6: =SUM(E7:E9) -> 203440 | F6: =+E6/C6 -> 0.94917574 | G6: =+E6/D6 -> 0.89057637 | H6: =SUM(H7:H9) -> 1500333.3 | I6: =SUM(I7:I9) -> 1599054.3 | J6: =SUM(J7:J9) -> 1608219.5 | K6: =+J6/H6 -> 1.0719081 | L6: =+J6/I6 -> 1.0057316 | M6: =SUM(M7:M9) -> 50850333 | N6: =SUM(N7:N9) -> 50916599 | O6: =SUM(O7:O9) -> 50925764 | P6: =+O6/M6 -> 1.0014834 | Q6: =+O6/N6 -> 1.00018
C7: =VLOOKUP($B$3,todate_plan,28,1) -> 0 | D7: =C37/$A$3 -> 0 | E7: ='Summary Sep26'!G75 -> 0 | F7: =IFERROR(E7/C7,0) -> 0 | G7: =IFERROR(E7/D7,0) -> 0 | H7: =HLOOKUP($A$4,budget_plan,4,0)/$A$3*'Summary Sep26'!$C$52 -> 0 | I7: =+C37/$A$3*'Summary Sep26'!$C$52 -> 0 | J7: ='Summary Sep26'!E50 -> 0 | K7: =IFERROR(J7/H7,0) -> 0 | L7: =IFERROR(J7/I7,0) -> 0 | M7: =VLOOKUP(B3,todate_plan,29,1) -> 0 | N7: =SUM('Summary Sep26'!E6:E17)+I7 -> 0 | O7: ='Summary Sep26'!K75 -> 0 | P7: =IFERROR(O7/M7,0) -> 0 | Q7: =IFERROR(O7/N7,0) -> 0
B8: PAMA | C8: =VLOOKUP($B$3,todate_plan,30,1) -> 164333.33 | D8: =C38/$A$3 -> 170081.67 | E8: ='Summary Sep26'!G76 -> 150381 | F8: =+E8/C8 -> 0.91509736 | G8: =+E8/D8 -> 0.88416937 | H8: =HLOOKUP($A$4,budget_plan,5,0)/$A$3*'Summary Sep26'!$C$52 -> 1150333.3 | I8: =+C38/$A$3*'Summary Sep26'!$C$52 -> 1190571.7 | J8: ='Summary Sep26'!F50 -> 1184074.5 | K8: =+J8/H8 -> 1.0293316 | L8: =+J8/I8 -> 0.99454282 | M8: =VLOOKUP(B3,todate_plan,31,1) -> 37900333 | N8: =SUM('Summary Sep26'!F6:F17)+'To Date Summary'!I8 -> 37617949 | O8: ='Summary Sep26'!K76 -> 37611452 | P8: =+O8/M8 -> 0.99237787 | Q8: =+O8/N8 -> 0.99982729
B9: SNS | C9: =VLOOKUP($B$3,todate_plan,32,1) -> 50000 | D9: =C39/$A$3 -> 58354.667 | E9: ='Summary Sep26'!G77 -> 53059 | F9: =+E9/C9 -> 1.06118 | G9: =IFERROR(E9/D9,0) -> 0.90925033 | H9: =HLOOKUP($A$4,budget_plan,6,0)/$A$3*'Summary Sep26'!$C$52 -> 350000 | I9: =+C39/$A$3*'Summary Sep26'!$C$52 -> 408482.67 | J9: ='Summary Sep26'!G50 -> 424145 | K9: =+J9/H9 -> 1.2118429 | L9: =IFERROR(J9/I9,0) -> 1.0383427 | M9: =VLOOKUP(B3,todate_plan,33,1) -> 12950000 | N9: =SUM('Summary Sep26'!G6:G17)+'To Date Summary'!I9 -> 13298650 | O9: ='Summary Sep26'!K77 -> 13314312 | P9: =+O9/M9 -> 1.0281322 | Q9: =+O9/N9 -> 1.0011777
B11: COAL | C11: =SUM(C12:C14) -> 22500 | D11: =SUM(D12:D14) -> 26233.333 | E11: =SUM(E12:E14) -> 22160.84 | F11: =+E11/C11 -> 0.98492622 | G11: =+E11/D11 -> 0.84475883 | H11: =SUM(H12:H14) -> 157500 | I11: =SUM(I12:I14) -> 183633.33 | J11: =SUM(J12:J14) -> 174095.22 | K11: =+J11/H11 -> 1.1053665 | L11: =+J11/I11 -> 0.94805892 | M11: =SUM(M12:M14) -> 5521500 | N11: =SUM(N12:N14) -> 5542374.8 | O11: =SUM(O12:O14) -> 5532836.7 | P11: =+O11/M11 -> 1.0020532 | Q11: =+O11/N11 -> 0.99827906
C12: =VLOOKUP($B$3,todate_plan,22,1) -> 0 | D12: =C41/$A$3 -> 0 | E12: 0 | F12: =IFERROR(E12/D12,0) -> 0 | G12: =IFERROR(E12/D12,0) -> 0 | H12: =HLOOKUP($A$4,budget_plan,8,0)/$A$3*'Summary Sep26'!$C$52 -> 0 | I12: =C41/$A$3*'Summary Sep26'!$C$52 -> 0 | J12: ='Summary Sep26'!M50 -> 0 | K12: =IFERROR(J12/H12,0) -> 0 | L12: =IFERROR(J12/I12,0) -> 0 | M12: =VLOOKUP(B3,todate_plan,23,1) -> 0 | N12: =SUM('Summary Sep26'!M6:M17)+'To Date Summary'!I12 -> 0 | O12: ='Summary Sep26'!K58 -> 0 | P12: =IFERROR(O12/M12,0) -> 0 | Q12: =IFERROR(O12/N12,0) -> 0
B13: PAMA | C13: =VLOOKUP($B$3,todate_plan,24,1) -> 17000 | D13: =C42/$A$3 -> 18900 | E13: ='Summary Sep26'!G59 -> 13704.44 | F13: =+E13/C13 -> 0.80614353 | G13: =+E13/D13 -> 0.72510265 | H13: =HLOOKUP($A$4,budget_plan,9,0)/$A$3*'Summary Sep26'!$C$52 -> 119000 | I13: =C42/$A$3*'Summary Sep26'!$C$52 -> 132300 | J13: ='Summary Sep26'!N50 -> 114804.08 | K13: =+J13/H13 -> 0.96474017 | L13: =+J13/I13 -> 0.86775571 | M13: =VLOOKUP(B3,todate_plan,25,1) -> 4094000 | N13: =SUM('Summary Sep26'!N6:N17)+'To Date Summary'!I13 -> 4127790.1 | O13: ='Summary Sep26'!K59 -> 4110294.2 | P13: =+O13/M13 -> 1.00398 | Q13: =+O13/N13 -> 0.99576143
B14: SNS | C14: =VLOOKUP($B$3,todate_plan,26,1) -> 5500 | D14: =C43/$A$3 -> 7333.3333 | E14: ='Summary Sep26'!G60 -> 8456.4 | F14: =+E14/C14 -> 1.5375273 | G14: =IFERROR(E14/D14,0) -> 1.1531455 | H14: =HLOOKUP($A$4,budget_plan,10,0)/$A$3*'Summary Sep26'!$C$52 -> 38500 | I14: =C43/$A$3*'Summary Sep26'!$C$52 -> 51333.333 | J14: ='Summary Sep26'!O50 -> 59291.14 | K14: =+J14/H14 -> 1.5400296 | L14: =IFERROR(J14/I14,0) -> 1.1550222 | M14: =VLOOKUP(B3,todate_plan,27,1) -> 1427500 | N14: =SUM('Summary Sep26'!O6:O17)+'To Date Summary'!I14 -> 1414584.7 | O14: ='Summary Sep26'!K60 -> 1422542.5 | P14: =+O14/M14 -> 0.99652714 | Q14: =+O14/N14 -> 1.0056255
B16: OUTPIT | C16: =SUM(C17:C18) -> 37596.667 | D16: =SUM(D17:D18) -> 44200 | E16: =SUM(E17:E18) -> 43553 | F16: =+E16/C16 -> 1.1584272 | G16: =+E16/D16 -> 0.98536199 | H16: =SUM(H17:H18) -> 263176.67 | I16: =SUM(I17:I18) -> 309400 | J16: =SUM(J17:J18) -> 317094 | K16: =+J16/H16 -> 1.2048713 | L16: =+J16/I16 -> 1.0248675 | M16: =SUM(M17:M18) -> 9151676.7 | N16: =SUM(N17:N18) -> 9630466.9 | O16: =SUM(O17:O18) -> 9638160.9 | P16: =+O16/M16 -> 1.0531579 | Q16: =+O16/N16 -> 1.0007989
B17: =+B45 -> MPA | C17: =VLOOKUP($B$3,'[1]Db_ Bgt Outpit'!$A$1:$I$366,6,1) -> 15283.333 | D17: =C45/$A$3 -> 14700 | E17: ='Summary Sep26'!G81 -> 11448 | F17: =+E17/C17 -> 0.74905125 | G17: =+E17/D17 -> 0.77877551 | H17: =HLOOKUP($A$4,'[1]Db_ Bgt Outpit'!$O$3:$AA$8,5,0)/$A$3*'Summary Sep26'!$C$52 -> 106983.33 | I17: =C45/$A$3*'Summary Sep26'!$C$52 -> 102900 | J17: ='Summary Sep26'!K50 -> 89844 | K17: =+J17/H17 -> 0.83979436 | L17: =+J17/I17 -> 0.87311953 | M17: =VLOOKUP(B3,'[1]Db_ Bgt Outpit'!$A$2:$K$366,11,1) -> 3435883.3 | N17: =SUM('Summary Sep26'!K6:K17)+'To Date Summary'!I17 -> 2723782.7 | O17: ='Summary Sep26'!K81 -> 2710726.7 | P17: =+O17/M17 -> 0.78894607 | Q17: =+O17/N17 -> 0.99520667
B18: =+B46 -> TJP | C18: =VLOOKUP($B$3,'[1]Db_ Bgt Outpit'!$A$1:$I$366,2,1) -> 22313.333 | D18: =C46/$A$3 -> 29500 | E18: ='Summary Sep26'!G80 -> 32105 | F18: =+E18/C18 -> 1.4388258 | G18: =IFERROR(E18/D18,0) -> 1.0883051 | H18: =HLOOKUP($A$4,'[1]Db_ Bgt Outpit'!$O$3:$AA$8,6,0)/$A$3*'Summary Sep26'!$C$52 -> 156193.33 | I18: =C46/$A$3*'Summary Sep26'!$C$52 -> 206500 | J18: ='Summary Sep26'!J50 -> 227250 | K18: =+J18/H18 -> 1.4549277 | L18: =IFERROR(J18/I18,0) -> 1.1004843 | M18: =VLOOKUP(B3,'[1]Db_ Bgt Outpit'!$A$2:$K$366,10,1) -> 5715793.3 | N18: =SUM('Summary Sep26'!J6:J17)+'To Date Summary'!I18 -> 6906684.3 | O18: ='Summary Sep26'!K80 -> 6927434.3 | P18: =+O18/M18 -> 1.2119812 | Q18: =+O18/N18 -> 1.0030043
B21: DISTANCE OB (M) | C21: =SUMPRODUCT($C$8:$C$9,C23:C24)/SUM($C$8:$C$9) -> 3591.8742 | D21: =SUMPRODUCT($D$8:$D$9,D23:D24)/SUM($D$8:$D$9) -> 3106.5171 | E21: =IFERROR(SUMPRODUCT($E$8:$E$9,E23:E24)/SUM($E$8:$E$9),0) -> 3020.4657 | F21: =E21-C21 -> -571.40849 | G21: =E21-D21 -> -86.051446 | H21: =SUMPRODUCT($H$8:$H$9,H23:H24)/SUM($H$8:$H$9) -> 3468.2737 | I21: =SUMPRODUCT($I$8:$I$9,I23:I24)/SUM($I$8:$I$9) -> 3106.5171 | J21: =SUMPRODUCT($J$8:$J$9,J23:J24)/SUM($J$8:$J$9) -> 2973.6609 | K21: =J21-H21 -> -494.61286 | L21: =J21-I21 -> -132.85628 | M21: =SUMPRODUCT($M$8:$M$9,M23:M24)/SUM($M$8:$M$9) -> 3635.7888 | N21: =SUMPRODUCT($N$8:$N$9,N23:N24)/SUM($N$8:$N$9) -> 3042.6021 | O21: =SUMPRODUCT($O$8:$O$9,O23:O24)/SUM($O$8:$O$9) -> 2950.1344 | P21: =O21-M21 -> -685.65434 | Q21: =O21-N21 -> -92.46764
C22: =VLOOKUP($B$3,todate_plan,28,1) -> 0 | D22: =IFERROR(C49/$A$3,0) -> 0 | E22: ='Summary Sep26'!G85 -> 0 | F22: =E22-C22 -> 0 | G22: =E22-D22 -> 0 | H22: =HLOOKUP($A$4,budget_plan,4,0)/$A$3*'Summary Sep26'!$C$52 -> 0 | I22: =IFERROR(C49/$A$3*'Summary Sep26'!$C$52,0) -> 0 | J22: ='Summary Sep26'!E60 -> 0 | K22: =J22-H22 -> 0 | L22: =J22-I22 -> 0 | M22: =IFERROR(VLOOKUP(B13,todate_plan,29,1),0) -> 0 | N22: =SUM('Summary Sep26'!E16:E27)+I22 -> 0 | O22: ='Summary Sep26'!K85 -> 0 | P22: =O22-M22 -> 0 | Q22: =O22-N22 -> 0
B23: PAMA | C23: =+'[1]base ob inpit'!AN104 -> 3637.3737 | D23: =+F38 -> 3126.8 | E23: =VLOOKUP($B$3,'[1]base ob inpit'!$AB$99:$AD$129,2,TRUE) -> 3158.972 | F23: =E23-C23 -> -478.40174 | G23: =E23-D23 -> 32.171982 | H23: =+'[1]base ob inpit'!AN112 -> 3549.8986 | I23: =+'[1]base ob inpit'!AT112 -> 3126.8 | J23: =+'[1]base ob inpit'!Y134 -> 3112.8388 | K23: =J23-H23 -> -437.05975 | L23: =J23-I23 -> -13.961186 | M23: =+'[1]base ob inpit'!AN113 -> 3855.2601 | N23: =+'[1]base ob inpit'!AT113 -> 3141.4239 | O23: =+'[1]base ob inpit'!AH113 -> 3080.6238 | P23: =O23-M23 -> -774.6363 | Q23: =O23-N23 -> -60.800099
B24: SNS | C24: =+'[1]base ob inpit'!AO104 -> 3442.3323 | D24: =+F39 -> 3047.4002 | E24: =VLOOKUP($B$3,'[1]base ob inpit'!$AB$99:$AD$129,3,TRUE) -> 2627.908 | F24: =E24-C24 -> -814.42427 | G24: =E24-D24 -> -419.49223 | H24: =+'[1]base ob inpit'!AO112 -> 3200 | I24: =+'[1]base ob inpit'!AU112 -> 3047.4002 | J24: =+'[1]base ob inpit'!Z134 -> 2585.1213 | K24: =J24-H24 -> -614.87867 | L24: =J24-I24 -> -462.2789 | M24: =+'[1]base ob inpit'!AO113 -> 2993.4695 | N24: =+'[1]base ob inpit'!AU113 -> 2763.0645 | O24: =+'[1]base ob inpit'!AI113 -> 2581.5166 | P24: =O24-M24 -> -411.95287 | Q24: =O24-N24 -> -181.54787
B26: DISTANCE COAL (M) | C26: =SUMPRODUCT($C$13:$C$14,C28:C29)/SUM($C$13:$C$14) -> 7289.6338 | D26: =SUMPRODUCT($D$13:$D$14,D28:D29)/SUM($D$13:$D$14) -> 8189.8564 | E26: =IFERROR(SUMPRODUCT($E$13:$E$14,E28:E29)/SUM($E$13:$E$14),0) -> 7807.9822 | F26: =E26-C26 -> 518.34841 | G26: =E26-D26 -> -381.87419 | H26: =SUMPRODUCT($H$13:$H$14,H28:H29)/SUM($H$13:$H$14) -> 7605.5926 | I26: =SUMPRODUCT($I$13:$I$14,I28:I29)/SUM($I$13:$I$14) -> 8189.8564 | J26: =SUMPRODUCT($J$13:$J$14,J28:J29)/SUM($J$13:$J$14) -> 7796.0458 | K26: =J26-H26 -> 190.45324 | L26: =J26-I26 -> -393.81058 | M26: =SUMPRODUCT($M$13:$M$14,M28:M29)/SUM($M$13:$M$14) -> 7090.1163 | N26: =SUMPRODUCT($N$13:$N$14,N28:N29)/SUM($N$13:$N$14) -> 8870.2516 | O26: =SUMPRODUCT($O$13:$O$14,O28:O29)/SUM($O$13:$O$14) -> 9138.6583 | P26: =O26-M26 -> 2048.542 | Q26: =O26-N26 -> 268.40668
C27: =VLOOKUP($B$3,todate_plan,22,1) -> 0 | D27: =C53/$A$3 -> 0 | E27: 0 | F27: =E27-C27 -> 0 | G27: =E27-D27 -> 0 | H27: =HLOOKUP($A$4,budget_plan,8,0)/$A$3*'Summary Sep26'!$C$52 -> 0 | I27: =C53/$A$3*'Summary Sep26'!$C$52 -> 0 | J27: ='Summary Sep26'!M60 -> 0 | K27: =J27-H27 -> 0 | L27: =J27-I27 -> 0 | M27: =IFERROR(VLOOKUP(B13,todate_plan,23,1),0) -> 0 | N27: =SUM('Summary Sep26'!M16:M27)+'To Date Summary'!I27 -> 0 | O27: 0 | P27: =O27-M27 -> 0 | Q27: =O27-N27 -> 0
B28: PAMA | C28: =+'[1]base coal'!BG240 -> 7545.1036 | D28: =+F42 -> 8826.6349 | E28: =VLOOKUP($B$3,'[1]base coal'!$BN$112:$BQ$142,2,TRUE) -> 8726.807 | F28: =E28-C28 -> 1181.7034 | G28: =E28-D28 -> -99.827921 | H28: =+'[1]base coal'!BG248 -> 7963.2843 | I28: =+'[1]base coal'!BM248 -> 8826.6349 | J28: =+'[1]base coal'!AS270 -> 8550.5662 | K28: =J28-H28 -> 587.28191 | L28: =J28-I28 -> -276.0687 | M28: =+'[1]base coal'!BG249 -> 7201.6062 | N28: =+'[1]base coal'!BM249 -> 9518.2959 | O28: =+'[1]base coal'!BA249 -> 9828.6205 | P28: =O28-M28 -> 2627.0143 | Q28: =O28-N28 -> 310.32466
B29: SNS | C29: =+'[1]base coal'!BH248 -> 6500 | D29: =+F43 -> 6548.7045 | E29: =VLOOKUP($B$3,'[1]base coal'!$BN$112:$BQ$142,3,TRUE) -> 6318.935 | F29: =E29-C29 -> -181.065 | G29: =E29-D29 -> -229.76955 | H29: =+'[1]base coal'!BH248 -> 6500 | I29: =+'[1]base coal'!BN248 -> 6548.7045 | J29: =+'[1]base coal'!AT270 -> 6335.0852 | K29: =J29-H29 -> -164.91475 | L29: =J29-I29 -> -213.6193 | M29: =+'[1]base coal'!BH249 -> 6770.3687 | N29: =+'[1]base coal'!BN249 -> 6979.2439 | O29: =+'[1]base coal'!BB249 -> 7145.0816 | P29: =O29-M29 -> 374.71288 | Q29: =O29-N29 -> 165.83765
B31: DISTANCE OUTPIT (M) | C31: =SUMPRODUCT($C$17:$C$18,C32:C33)/SUM($C$17:$C$18) -> 4284.5554 | D31: =SUMPRODUCT($D$17:$D$18,D32:D33)/SUM($D$17:$D$18) -> 4466.7421 | E31: =IFERROR(SUMPRODUCT($E$17:$E$18,E32:E33)/SUM($E$17:$E$18),0) -> 4904.1949 | F31: =E31-C31 -> 619.63952 | G31: =E31-D31 -> 437.45281 | H31: =SUMPRODUCT($H$17:$H$18,H32:H33)/SUM($H$17:$H$18) -> 4296.7462 | I31: =SUMPRODUCT($I$17:$I$18,I32:I33)/SUM($I$17:$I$18) -> 4466.7421 | J31: =SUMPRODUCT($J$17:$J$18,J32:J33)/SUM($J$17:$J$18) -> 4906.5984 | K31: =J31-H31 -> 609.85226 | L31: =J31-I31 -> 439.85634 | M31: =SUMPRODUCT($M$17:$M$18,M32:M33)/SUM($M$17:$M$18) -> 4060.1987 | N31: =SUMPRODUCT($N$17:$N$18,N32:N33)/SUM($N$17:$N$18) -> 4300.1441 | O31: =SUMPRODUCT($O$17:$O$18,O32:O33)/SUM($O$17:$O$18) -> 4039.1961 | P31: =O31-M31 -> -21.002535 | Q31: =O31-N31 -> -260.94791
B32: =+B17 -> MPA | C32: =+'[1]base ob outpit'!AJ103 -> 4700 | D32: =+F45 -> 4400 | E32: =VLOOKUP($B$3,'[1]base ob outpit'!$AC$57:$AF$87,2,TRUE) -> 4815 | F32: =E32-C32 -> 115 | G32: =E32-D32 -> 415 | H32: =+'[1]base ob outpit'!AJ111 -> 4000 | I32: =+'[1]base ob outpit'!AP111 -> 4400 | J32: =+'[1]base ob outpit'!AD111 -> 4851.7771 | K32: =J32-H32 -> 851.77707 | L32: =J32-I32 -> 451.77707 | M32: =+'[1]base ob outpit'!AJ112 -> 4312.6731 | N32: =+'[1]base ob outpit'!AP112 -> 4378.2666 | O32: =+'[1]base ob outpit'!AD112 -> 4237.8774 | P32: =O32-M32 -> -74.795679 | Q32: =O32-N32 -> -140.38919
B33: =+B18 -> TJP | C33: =+'[1]base ob outpit'!AK103 -> 4000 | D33: =+F46 -> 4500 | E33: =VLOOKUP($B$3,'[1]base ob outpit'!$AC$57:$AF$87,3,TRUE) -> 4936 | F33: =E33-C33 -> 936 | G33: =E33-D33 -> 436 | H33: =+'[1]base ob outpit'!AK111 -> 4500 | I33: =+'[1]base ob outpit'!AQ111 -> 4500 | J33: =+'[1]base ob outpit'!AE111 -> 4928.2722 | K33: =J33-H33 -> 428.27222 | L33: =J33-I33 -> 428.27222 | M33: =+'[1]base ob outpit'!AK112 -> 3908.431 | N33: =+'[1]base ob outpit'!AQ112 -> 4269.3349 | O33: =+'[1]base ob outpit'!AE112 -> 3961.4515 | P33: =O33-M33 -> 53.02054 | Q33: =O33-N33 -> -307.8834
A37: OB | B37: TRUST | D37: =+C37/1000 -> 0
B38: PAMA | C38: 5102450 | D38: =+C38/1000 -> 5102.45 | E38: 3.1268 | F38: =E38*1000 -> 3126.8
B39: SNS | C39: 1750640 | D39: =+C39/1000 -> 1750.64 | E39: 3.0474002 | F39: =E39*1000 -> 3047.4002
A41: Coal | B41: TRUST | D41: =SUM(C41:C41)/1000 -> 0 | G41: =J12/C41 -> #DIV/0! | I41: =C37/C41 -> #DIV/0!
B42: PAMA | C42: 567000 | D42: =+C42/1000 -> 567 | E42: 8.8266349 | F42: =E42*1000 -> 8826.6349 | G42: =J13/C42 -> 0.20247633 | I42: =C38/C42 -> 8.99903
B43: SNS | C43: 220000 | D43: =+C43/1000 -> 220 | E43: 6.5487045 | F43: =E43*1000 -> 6548.7045 | G43: =J14/C43 -> 0.26950518 | I43: =C39/C43 -> 7.9574545
A45: Void | B45: MPA | C45: 441000 | D45: =C45/1000 -> 441 | E45: 4.4 | F45: =E45*1000 -> 4400
B46: TJP | C46: 885000 | D46: =C46/1000 -> 885 | E46: 4.5 | F46: =E46*1000 -> 4500
B48: COAL WINNING | C48: PAMA | E48: TRUST | G48: SNS | I48: TOTAL
B49: BY ROM | C49: ROM 1 | D49: ROM 4 | E49: ROM 1 | F49: ROM 4 | G49: ROM 1 | H49: ROM 4
B50: Week1 | C50: ='[1]base coal'!AO184 -> 70611.68 | D50: ='[1]base coal'!AP184 -> 44192.4 | E50: ='[1]base coal'!AQ184 -> 0 | F50: ='[1]base coal'!AR184 -> 0 | G50: ='[1]base coal'!AS184 -> 59291.14 | H50: ='[1]base coal'!AT184 -> 0 | I50: =SUM(C50:H50) -> 174095.22
B51: Week2 | C51: ='[1]base coal'!AO185 -> 0 | D51: ='[1]base coal'!AP185 -> 0 | E51: ='[1]base coal'!AQ185 -> 0 | F51: ='[1]base coal'!AR185 -> 0 | G51: ='[1]base coal'!AS185 -> 0 | H51: ='[1]base coal'!AT185 -> 0 | I51: =SUM(C51:H51) -> 0
B52: Week3 | C52: ='[1]base coal'!AO186 -> 0 | D52: ='[1]base coal'!AP186 -> 0 | E52: ='[1]base coal'!AQ186 -> 0 | F52: ='[1]base coal'!AR186 -> 0 | G52: ='[1]base coal'!AS186 -> 0 | H52: ='[1]base coal'!AT186 -> 0 | I52: =SUM(C52:H52) -> 0
B53: Week4 | C53: ='[1]base coal'!AO187 -> 0 | D53: ='[1]base coal'!AP187 -> 0 | E53: ='[1]base coal'!AQ187 -> 0 | F53: ='[1]base coal'!AR187 -> 0 | G53: ='[1]base coal'!AS187 -> 0 | H53: ='[1]base coal'!AT187 -> 0 | I53: =SUM(C53:H53) -> 0
B54: MTD | C54: =SUM(C50:C53) -> 70611.68 | D54: =SUM(D50:D53) -> 44192.4 | E54: =SUM(E50:E53) -> 0 | F54: =SUM(F50:F53) -> 0 | G54: =SUM(G50:G53) -> 59291.14 | H54: =SUM(H50:H53) -> 0 | I54: =SUM(C54:H54) -> 174095.22 | J54: =I54-SUM(I50:I53) -> 0
B57: Distance OB | C57: P3000Bk14 | D57: P6000Bk14 | E57: P3000Bk18 | F57: P3000Bk20 | G57: P6000Bk20
...

Sheet Portion Blending
B2: =Dashboard!E5 -> 46272.44
B4: FC | C4: % Blending | E4: Tonnage Blending | G4: Ach./
B5: PRODUCTION | C5: Outlook | D5: Actual | E5: Outlook | F5: Actual | G5: Diff.
B7: ='Summary Sep26'!X5 -> BEK.HCV.LS
A8: =IF(AND(E8=0,F8=0),"x","") -> x | B8: ROM 1.U1 | C8: 0 | D8: =[1]actual!AM349 -> 0 | E8: =C8*E18 -> 0 | F8: =IFERROR(D8*$F$18,0) -> 0
A9: =IF(AND(E9=0,F9=0),"x","") | B9: ROM 1.B1 | C9: 0.18 | D9: =[1]actual!AM350 -> 0.44165927 | E9: =C9*E18 -> 93600 | F9: =IFERROR(D9*$F$18,0) -> 9410.5887
A10: =IF(AND(E10=0,F10=0),"x","") | B10: ROM 1.B2 | C10: 0.82 | D10: =[1]actual!AM351 -> 0.52954156 | E10: =C10*E18 -> 426400 | F10: =IFERROR(D10*$F$18,0) -> 11283.127
A11: =IF(AND(E11=0,F11=0),"x","") -> x | B11: ROM 1.B3 | C11: 0 | D11: =[1]actual!AM352 -> 0 | E11: =C11*E18 -> 0 | F11: =IFERROR(D11*$F$18,0) -> 0
A12: =IF(AND(E12=0,F12=0),"x","") -> x | B12: ROM 1.B4 | C12: 0 | D12: =[1]actual!AM353 -> 0 | E12: =C12*E19 -> 0 | F12: =IFERROR(D12*$F$18,0) -> 0
A13: =IF(AND(E13=0,F13=0),"x","") -> x | B13: ROM 4.U1 | C13: 0 | D13: =[1]actual!AM355 -> 0 | E13: =C13*E18 -> 0 | F13: =IFERROR(D13*$F$18,0) -> 0
A14: =IF(AND(E14=0,F14=0),"x","") | B14: ROM 4.B1 | C14: 0 | D14: =[1]actual!AM356 -> 0.0082777752 | E14: =C14*E18 -> 0 | F14: =IFERROR(D14*$F$18,0) -> 176.37745
A15: =IF(AND(E15=0,F15=0),"x","") | B15: ROM 4.B2 | C15: 0 | D15: =[1]actual!AM357 -> 0.020521388 | E15: =C15*E18 -> 0 | F15: =IFERROR(D15*$F$18,0) -> 437.2564
A16: =IF(AND(E16=0,F16=0),"x","") -> x | B16: ROM 1-01 | C16: 0 | D16: =[1]actual!AM367 -> 0 | E16: =C16*E18 -> 0 | F16: =IFERROR(D16*$F$18,0) -> 0
A17: =IF(AND(E17=0,F17=0),"x","") -> x | B17: ROM 4-01 | C17: 0 | D17: =[1]actual!AM368 -> 0 | E17: =C17*E18 -> 0 | F17: =IFERROR(D17*$F$18,0) -> 0
D18: Total FC | E18: 520000 | F18: =[1]actual!AM489*1000 -> 21307.35 | G18: =F18/E18 -> 0.040975673
C19: Quality | D19: CVadb | E19: 6621.5829 | F19: =[1]actual!AM490 -> 6720.9054 | G19: =+F19-E19 -> 99.322472
D20: CVar | E20: 6337.886 | F20: =+F19*(100-F24)/(100-F23) -> 6470.5744 | G20: =+F20-E20 -> 132.68836
D21: TS | E21: 0.59661565 | F21: =[1]actual!AM491 -> 0.63388726 | G21: =+F21-E21 -> 0.037271607
D22: ASH | E22: 3.5338754 | F22: =[1]actual!AM492 -> 3.5011049 | G22: =+F22-E22 -> -0.032770594
D23: IM | E23: 9.8721961 | F23: =[1]actual!AM493 -> 9.5806722 | G23: =+F23-E23 -> -0.29152387
D24: TM | E24: 13.733657 | F24: =[1]actual!AM494 -> 12.948487 | G24: =+F24-E24 -> -0.78516966
B26: ='Summary Sep26'!Y5 -> BEK.HCV.HS
A27: =IF(AND(E27=0,F27=0),"x","") -> x | B27: ROM 1.U1 | C27: 0 | D27: =[1]actual!AM371 -> 0 | E27: =C27*E37 -> 0 | F27: =IFERROR(D27*$F$37,0) -> 0
A28: =IF(AND(E28=0,F28=0),"x","") | B28: ROM 1.B1 | C28: 0 | D28: =[1]actual!AM372 -> 0.0020187586 | E28: =C28*E37 -> 0 | F28: =IFERROR(D28*$F$37,0) -> 149.26483
A29: =IF(AND(E29=0,F29=0),"x","") | B29: ROM 1.B2 | C29: 0.15 | D29: =[1]actual!AM373 -> 0.0069044988 | E29: =C29*E37 -> 25500 | F29: =IFERROR(D29*$F$37,0) -> 510.51119
A30: =IF(AND(E30=0,F30=0),"x","") | B30: ROM 1.B3 | C30: 0 | D30: =[1]actual!AM374 -> 0.0082232971 | E30: =C30*E36 -> 0 | F30: =IFERROR(D30*$F$37,0) -> 608.02171
A31: =IF(AND(E31=0,F31=0),"x","") -> x | B31: ROM 1.B4 | C31: 0 | D31: =[1]actual!AM375 -> 0 | E31: =C31*E37 -> 0 | F31: =IFERROR(D31*$F$37,0) -> 0
A32: =IF(AND(E32=0,F32=0),"x","") -> x | B32: ROM 4.U1 | C32: 0 | D32: =[1]actual!AM377 -> 0 | E32: =C32*E37 -> 0 | F32: =IFERROR(D32*$F$37,0) -> 0
A33: =IF(AND(E33=0,F33=0),"x","") | B33: ROM 4.B1 | C33: 0.4 | D33: =[1]actual!AM378 -> 0.53645331 | E33: =C33*E37 -> 68000 | F33: =IFERROR(D33*$F$37,0) -> 39664.779
A34: =IF(AND(E34=0,F34=0),"x","") | B34: ROM 4.B2 | C34: 0.45 | D34: =[1]actual!AM379 -> 0.44640013 | E34: =C34*E37 -> 76500 | F34: =IFERROR(D34*$F$37,0) -> 33006.344
A35: =IF(AND(E35=0,F35=0),"x","") -> x | B35: ROM 1-01 | C35: 0 | D35: =[1]actual!AM389 -> 0 | E35: =C35*E37 -> 0 | F35: =IFERROR(D35*$F$37,0) -> 0
A36: =IF(AND(E36=0,F36=0),"x","") -> x | B36: ROM 4-01 | C36: 0 | D36: =[1]actual!AM390 -> 0 | E36: =C36*E37 -> 0 | F36: =IFERROR(D36*$F$37,0) -> 0
D37: Total FC | E37: 170000 | F37: =[1]actual!AM495*1000 -> 73938.92 | G37: =F37/E37 -> 0.43493482
C38: Quality | D38: CVadb | E38: 6513.7364 | F38: =[1]actual!AM496 -> 6636.5202 | G38: =+F38-E38 -> 122.78387
D39: CVar | E39: 6240.441 | F39: =+F38*(100-F43)/(100-F42) -> 6390.2276 | G39: =+F39-E39 -> 149.78654
D40: TS | E40: 1.6673817 | F40: =[1]actual!AM497 -> 1.6162614 | G40: =+F40-E40 -> -0.051120277
D41: ASH | E41: 4.8836528 | F41: =[1]actual!AM498 -> 4.89667 | G41: =+F41-E41 -> 0.013017187
D42: IM | E42: 9.9076033 | F42: =[1]actual!AM499 -> 9.0987738 | G42: =+F42-E42 -> -0.80882948
D43: TM | E43: 13.687589 | F43: =[1]actual!AM500 -> 12.472275 | G43: =+F43-E43 -> -1.2153146
O44: =+Dashboard!T34/(24*(14+(('Summary Sep26'!E52)))) -> 0.070993022
...

Sheet Stock Information
D3: =D5 -> 46272.44
