Workbook
Name Calendar: #N/A
Name DayWeek: {1,2,3,4,5,6,7}
Name DayWeek: {1,2,3,4,5,6,7}
Name DayWeek: {1,2,3,4,5,6,7}
Name DayWeek: {1,2,3,4,5,6,7}
Name DayWeek: {1,2,3,4,5,6,7}
Name DayWeek: {1,2,3,4,5,6,7}
Name DayWeek: {1,2,3,4,5,6,7}
Name DayWeek: {1,2,3,4,5,6,7}
Name DayWeek: {1,2,3,4,5,6,7}
Name DayWeek: {1,2,3,4,5,6,7}
Name DayWeek: {1,2,3,4,5,6,7}
Name DayWeek: {1,2,3,4,5,6,7}
Name DayWeek: {1,2,3,4,5,6,7}
Name DayWeek: {1,2,3,4,5,6,7}
Name DayWeek: {1,2,3,4,5,6,7}
Name DayWeek: {1,2,3,4,5,6,7}
Name DayWeek: {1,2,3,4,5,6,7}
Name DayWeek: {1,2,3,4,5,6,7}
Name DayWeek: {1,2,3,4,5,6,7}
Name DayWeek: {1,2,3,4,5,6,7}
Name NumWeek: {0;1;2;3;4;5}
Name NumWeek: {0;1;2;3;4;5}
Name NumWeek: {0;1;2;3;4;5}
Name NumWeek: {0;1;2;3;4;5}
Name NumWeek: {0;1;2;3;4;5}
Name NumWeek: {0;1;2;3;4;5}
Name NumWeek: {0;1;2;3;4;5}
Name NumWeek: {0;1;2;3;4;5}
Name NumWeek: {0;1;2;3;4;5}
Name NumWeek: {0;1;2;3;4;5}
Name NumWeek: {0;1;2;3;4;5}
Name NumWeek: {0;1;2;3;4;5}
Name NumWeek: {0;1;2;3;4;5}
Name NumWeek: {0;1;2;3;4;5}
Name NumWeek: {0;1;2;3;4;5}
Name NumWeek: {0;1;2;3;4;5}
Name NumWeek: {0;1;2;3;4;5}
Name NumWeek: {0;1;2;3;4;5}
Name NumWeek: {0;1;2;3;4;5}
Name NumWeek: {0;1;2;3;4;5}

Sheet Sheet1
A4: OB (BCM)
B6: Daily
B7: =B35 -> #REF!
A28: Daily
A29: OB | B29: Act | C29: Bud | D29: Out
A30: ='Summary TCM'!C11 -> PAMA | B30: ='Summary TCM'!E11 -> 88536 | C30: ='Summary TCM'!F11/31 -> 106290.32 | D30: ='Summary TCM'!G11/31 -> 79032.258
A31: ='Summary TCM'!#REF! -> #REF! | B31: ='Summary TCM'!#REF! -> #REF! | C31: ='Summary TCM'!#REF!/31 -> #REF! | D31: ='Summary TCM'!#REF!/31 -> #REF!
A32: ='Summary TCM'!C12 -> MAP | B32: ='Summary TCM'!E12 -> 35470 | C32: ='Summary TCM'!F12/31 -> 32580.645 | D32: ='Summary TCM'!G12/31 -> 29032.258
A33: ='Summary TCM'!#REF! -> #REF! | B33: ='Summary TCM'!#REF! -> #REF! | C33: ='Summary TCM'!#REF!/31 -> #REF! | D33: ='Summary TCM'!#REF!/31 -> #REF!
A34: ='Summary TCM'!C125 -> PJPN | B34: ='Summary TCM'!E122 -> 20096 | C34: ='Summary TCM'!F122/31 -> 23225.806 | D34: ='Summary TCM'!G122/31 -> 16129.032
A35: TOTAL | B35: =SUM(B30:B34) -> #REF! | C35: =SUM(C30:C34) -> #REF! | D35: =SUM(D30:D34) -> #REF!

Sheet Sheet2
C7: 45047.455 | D7: MTD | G7: % Achievement | I7: YTD | L7: % Achievement
D8: Budget | E8: Outlook | F8: Actual | G8: By Budget | H8: By Outlook | I8: Budget | J8: Outlook | K8: Actual | L8: By Budget | M8: By Outlook
C10: OB
C11: PAMA
C12: MAP
C13: PJPN
C14: PJPN (VOID)
C16: COAL
C17: PAMA
C18: MAP
C19: PJPN
C20: PJPN (VOID)

Sheet Dashboard TCM
AC6: As update on
AC7: =+'Summary TCM'!F2 -> September | AE7: =TODAY()-1 -> 46272 | AF7: 10
A8: ='Summary TCM'!A8 -> 0.23333333
A9: ='Summary TCM'!A9 -> 0.13333333 | AC9: ROM Hauling | AD9: TONS | AE9: % on budg | AF9: % on outlook
AC10: BUDGET YTD | AD10: =+'Summary TCM'!K29 -> 3075000
AC11: Outlook YTD | AD11: =+'Summary TCM'!L29 -> 2469984.1
AC12: YTD | AD12: =+'Summary TCM'!M29 -> 2249549.9
AC13: BUDGET | AD13: =+'Summary TCM'!F29 -> 360000
AC14: OUTLOOK | AD14: =+'Summary TCM'!G29 -> 270000
Q15: HAC | T15: HAC Stock | AC15: MTD | AD15: =+'Summary TCM'!H29 -> 49565.76 | AE15: =+AD15/AD13 -> 0.13768267 | AF15: =+AD15/AD14 -> 0.18357689
E16: Actual | F16: Daily | G16: MTD | Q16: CONTC | R16: TONS | S16: ACH. | AC16: Q3 | AD16: ='Summary TCM'!AS57 -> 685563.46
E17: NB | F17: ='Summary TCM'!E119 -> 0mm/0h/0% | G17: ='Summary TCM'!H119 -> 0mm/0h/0% | Q17: OUTLOOK | AC17: Daily | AD17: ='Summary TCM'!E29 -> 16810.91
E18: =E19 -> SB2 | F18: =F19 -> 0mm/0h/0% | G18: =G19 -> 73mm/10h/6% | Q18: MTD | R18: ='Summary TCM'!H35 -> 1949.15 | T18: =MarchPQ42 -> #NAME? | AC18: SB 1 | AD18: =+'Summary TCM'!E36 -> 7369.26
E19: SB2 | F19: ='Summary TCM'!E7 -> 0mm/0h/0% | G19: ='Summary TCM'!H7 -> 73mm/10h/6% | Q19: Daily | R19: ='Summary TCM'!E35 -> 297.35 | AC19: ROM 1 | AD19: =+'Summary TCM'!E37 -> 0
G20: =+ROUND('Summary TCM'!BL130,0)&"mm/"&ROUND('Summary TCM'!BL131,0)&"h/"&ROUND('Summary TCM'!BL132*100,0)&"%" -> 0mm/0h/0% | AC20: ROM 1 (SMI) | AD20: =+'Summary TCM'!#REF! -> #REF!
E21: PLAN | G21: ='Summary TCM'!F6 -> 205mm/71h/10% | AC21: ROM 2 | AD21: =+'Summary TCM'!E38 -> 0
AC22: ROM 2 (SMI) | AD22: =+'Summary TCM'!#REF! -> #REF!
AC23: ROM 3 | AD23: =+'Summary TCM'!E39 -> 0
A24: a | AC24: ROM 3 (SMI) | AD24: =+'Summary TCM'!#REF! -> #REF!
AC25: ROM 4 | AD25: =+'Summary TCM'!E40 -> 2180.47
AC26: ROM 4 (SMI) | AD26: =+'Summary TCM'!#REF! -> #REF!
E27: OB REMOVAL PIT | J27: OB REMOVAL VOID | AD27: ROM 5 | AE27: =+'Summary TCM'!E41 -> 0
E28: CONTC | F28: BCM | G28: % on budg | H28: % on outlook | J28: CONTC | K28: BCM | L28: % on budg | M28: % on outlook | AD28: ROM 5 (SMI) | AE28: =+'Summary TCM'!#REF! -> #REF!
E29: BUDGET YTD | F29: =+'Summary TCM'!K10 -> 35970227 | J29: BUDGET YTD | K29: ='Summary TCM'!K120 -> 6420000 | AD29: ROM 6 | AE29: =+'Summary TCM'!E42 -> 5188.79
E30: Outlook YTD | F30: =+'Summary TCM'!L10 -> 31821732 | J30: Outlook YTD | K30: ='Summary TCM'!L120 -> 5931483.2 | W30: QUALITY BY PREDECTION | AD30: ROM 6 (SMI) | AE30: =+'Summary TCM'!#REF! -> #REF!
E31: YTD | F31: =+'Summary TCM'!M10 -> 29226543 | J31: YTD | K31: ='Summary TCM'!M120 -> 5589174.2 | Q31: ROM Stock | R31: Available | S31: Ready To Haul | T31: Rom Capacity | U31: Available Space | V31: CV | W31: TS | X31: ASH | AD31: HAC | AE31: ='Summary TCM'!E33 -> 2323.66
E32: BUDGET | F32: =+'Summary TCM'!F10 -> 4305000 | J32: BUDGET | K32: ='Summary TCM'!F120 -> 720000 | Q32: OUTLOOK | AD32: SB 2 | AE32: =+'Summary TCM'!E43 -> 4978.22
E33: OUTLOOK | F33: =+'Summary TCM'!G10 -> 3530000 | J33: OUTLOOK | K33: ='Summary TCM'!G120 -> 500000 | Q33: MTD | R33: ='Summary TCM'!E76 -> 191595.15 | S33: =+'Summary TCM'!F76 -> 149516.5 | T33: =+'Summary TCM'!G76 -> 600000 | U33: =+'Summary TCM'!H76 -> 637988.36 | AD33: ROM 1 | AE33: =+'Summary TCM'!E44 -> 0
E34: MTD | F34: =+'Summary TCM'!H10 -> 934811 | G34: =+F34/F32 -> 0.21714541 | H34: =+F34/F33 -> 0.26481898 | J34: MTD | K34: ='Summary TCM'!H120 -> 157691 | L34: =+K34/K32 -> 0.21901528 | M34: =+K34/K33 -> 0.315382 | Q34: NB | R34: ='Summary TCM'!E77 -> 62363.346 | S34: =R34 -> 62363.346 | T34: ='Summary TCM'!G77 -> 130000 | U34: =+'Summary TCM'!H77 -> 261661.46 | AD34: ROM 1 (SMI) | AE34: =+'Summary TCM'!#REF! -> #REF!
E35: Q3 | F35: ='Summary TCM'!AS17 -> 8845580.1 | J35: Q3 | K35: ='Summary TCM'!AS101 -> 1544241.1 | Q35: ='Summary TCM'!C78 -> ROM 1 | R35: =+'Summary TCM'!E79 -> 8443.1982 | S35: =+'Summary TCM'!F79 -> -313.35 | T35: =+'Summary TCM'!G79 -> 70000 | U35: =+'Summary TCM'!H79 -> 61556.802 | V35: ='Summary TCM'!I79 -> 5073 | W35: ='Summary TCM'!J79 -> 0.27 | X35: ='Summary TCM'!K79 -> 10.19 | AD35: ROM 2 | AE35: =+'Summary TCM'!E45 -> 0
E36: Daily | F36: =SUM(F37:F40) -> 133670 | J36: Daily | K36: =SUM(K37:K39) -> 20096 | Q36: ='Summary TCM'!C80 -> ROM 3 | R36: 0 | S36: 0 | T36: 0 | U36: 0 | AD36: ROM 2 (SMI) | AE36: =+'Summary TCM'!#REF! -> #REF!
E37: PAMA | F37: =+'Summary TCM'!E11 -> 88536 | J37: RML | K37: ='Summary TCM'!E121 -> 0 | Q37: ='Summary TCM'!C81 -> ROM 5 | R37: =+'Summary TCM'!E80 -> 0 | S37: =+'Summary TCM'!F80 -> 0 | T37: 0 | U37: 0 | V37: =+'Summary TCM'!I80 -> 0 | W37: =+'Summary TCM'!K80 -> 0 | X37: =+'Summary TCM'!L80 -> 0 | AD37: ROM 3 | AE37: =+'Summary TCM'!E46 -> 0
E38: MAP | F38: =+'Summary TCM'!E12 -> 35470 | J38: PJPN | K38: ='Summary TCM'!E122 -> 20096 | Q38: ='Summary TCM'!C83 -> ROM 6 | R38: =+'Summary TCM'!E83 -> 9895.338 | S38: =+'Summary TCM'!F83 -> 8765.2263 | T38: =+'Summary TCM'!G83 -> 110000 | U38: =+'Summary TCM'!H83 -> 100104.66 | V38: =+'Summary TCM'!I83 -> 6896 | W38: ='Summary TCM'!J83 -> 2.43 | X38: ='Summary TCM'!K83 -> 6.45 | AD38: ROM 3 (SMI) | AE38: =+'Summary TCM'!#REF! -> #REF!
E39: RML | AD39: ROM 4 | AE39: =+'Summary TCM'!E47 -> 0
B40: ='Summary TCM'!A29 -> 0 | E40: PJPN | F40: ='Summary TCM'!E13 -> 9664 | Q40: SB1 B05 | R40: ='Summary TCM'!E84 -> 61599.909 | S40: ='Summary TCM'!F84 -> 59053.163 | T40: ='Summary TCM'!G84 -> 130000 | U40: ='Summary TCM'!H84 -> 103958.8 | AD40: ROM 4 (SMI) | AE40: =+'Summary TCM'!#REF! -> #REF!
Q41: =R41/R40 -> #REF! | R41: =SUM(R42:R47) -> #REF! | AC41: ROM 5 | AD41: =+'Summary TCM'!E48 -> 3539.67
G42: ( ALL ) OB REMOVAL PIT +VOID | Q42: ROM 5 | R42: =+'Summary TCM'!E85 -> 12611.886 | S42: ='Summary TCM'!E85 -> 12611.886 | T42: ='Summary TCM'!F85 -> 11193.96 | U42: ='Summary TCM'!G85 -> 65000 | V42: ='Summary TCM'!I85 -> 7106 | W42: ='Summary TCM'!J85 -> 1.26 | X42: ='Summary TCM'!K85 -> 2.36 | AC42: ROM 5 (SMI) | AD42: =+'Summary TCM'!#REF! -> #REF!
G43: CONTC | H43: BCM | I43: % on budg | J43: % on outlook | R43: =+'Summary TCM'!E86 -> 35558.706 | S43: =+'Summary TCM'!F86 -> 34429.886 | T43: =+'Summary TCM'!G86 -> 0 | U43: =+'Summary TCM'!H86 -> 0 | V43: =+'Summary TCM'!I86 -> 6958 | W43: =+'Summary TCM'!K86 -> 2.55 | X43: =+'Summary TCM'!L86 -> 7 | AC43: ROM 6 | AD43: =+'Summary TCM'!E49 -> 1438.55
G44: BUDGET YTD | H44: =F29+K29 -> 42390227 | R44: =+'Summary TCM'!#REF! -> #REF! | S44: ='Summary TCM'!#REF! -> #REF! | T44: ='Summary TCM'!#REF! -> #REF! | U44: ='Summary TCM'!#REF! -> #REF! | V44: =+'Summary TCM'!#REF! -> #REF! | W44: =+'Summary TCM'!#REF! -> #REF! | X44: =+'Summary TCM'!#REF! -> #REF! | AC44: ROM 6 (SMI) | AD44: =+'Summary TCM'!#REF! -> #REF!
G45: Outlook YTD | H45: =F30+K30 -> 37753216 | R45: =+'Summary TCM'!#REF! -> #REF! | S45: =+'Summary TCM'!#REF! -> #REF! | T45: =+'Summary TCM'!#REF! -> #REF! | U45: =+'Summary TCM'!#REF! -> #REF! | V45: =+'Summary TCM'!#REF! -> #REF! | W45: =+'Summary TCM'!#REF! -> #REF! | X45: =+'Summary TCM'!#REF! -> #REF! | AC45: HAC | AD45: ='Summary TCM'!E35 -> 297.35
...

Sheet YTD
B4: DATE | C4: PIT Production | CF4: Coal Winning | DR4: ROM Transfer | EU4: ROM Hauling | GL4: FC Production | IJ4: Coal Loading (Barging) | JZ4: Stock Balance | LT4: Washing Plant | MA4: HAC
C5: summary | K5: details per contractor | AF5: details per pit | BW5: details of outpit per contractor | CF5: summary | CN5: details per destination per rom | DR5: summary | DX5: details per source-destination per ROM | EU5: summary | FC5: details per contractor | FI5: details per ROM per source location | GL5: summary | GR5: details of blending portion per product per ROM | HR5: details of quality per product | IJ5: summary | IU5: details per final product and blending on barge | JZ5: summary | KE5: details per location per material type | LT5: summary | MA5: summary | MI5: Blending Match | ML5: Source Availability | MO5: LS | MV5: HS
C6: OB | D6: ROM | E6: SR | F6: RS SB1 | H6: RS SB2 | K6: PAMA | O6: MAP | S6: PJPN | W6: RML | AA6: TRUST | AF6: PAMA P4500 B01 SB1 | AI6: PAMA P3000 B10 SB1 | AL6: PAMA P3000 B14 SB2 | AO6: PAMA P3800 B30 SB2 | AR6: PAMA P4000 B34 SB2 | AU6: PAMA P3000 B30 SB2 | AX6: TRUST P3000 B03 SB1 | BA6: TRUST P4000 B30 SB2 | BD6: RML P4200 B16 SB1 | BG6: RML P4200 B14 SB1 | BJ6: MAP P6200 B03 SB1 | BM6: MAP P4200 B16 SB1 | BP6: MAP P3000 B04E | BS6: PJPN P3000 B01A NB | BW6: PAMA | BX6: MAP | BY6: PJPN | BZ6: RML | CA6: TRUST | CB6: TOTAL | CC6: Notes | CF6: ROM 1 | CG6: ROM 2 | CH6: ROM 3 | CI6: ROM 4 | CJ6: ROM 5 | CK6: ROM 6 | CL6: TOTAL | CN6: PIT - ROM SB1 B05 | CT6: SUB TOTAL | CU6: PIT - ROM SB2 B24 | DA6: SUB TOTAL | DB6: PIT - ROM NB B24 (Void Project) | DH6: SUB TOTAL | DI6: PIT - ROM SB2 B14 (BAS's feeder) | DO6: SUB TOTAL | DR6: SB2 B30 - SB2 B24 | DS6: SB2 B30 - SB1 B05 | DT6: SB2 B14 - SB1 B05 | DU6: TOTAL | DV6: Notes | DX6: ROM SB2 B30 (PAMA's feeder) - ROM SB2 B24 | ED6: SUB TOTAL | EE6: ROM SB2 B30 (PAMA's feeder) - ROM SB1 B05 | EK6: SUB TOTAL | EL6: ROM SB2 B14 (BAS's feeder) - ROM SB1 B05 | ER6: SUB TOTAL | EU6: source location | EX6: TOTAL | EY6: Truck | EZ6: Trip | FA6: Notes | FC6: TRUST | FD6: RTL | FE6: RP | FF6: YFD | FG6: TOTAL | FI6: NB | FQ6: SUB TOTAL | FR6: SB1 B05 | FZ6: SUB TOTAL | GA6: SB2 B24 | GI6: SUB TOTAL | GL6: HCV-LS | GM6: HCV-HS | GN6: HCV-MS (SMI) | GO6: TOTAL | GP6: Notes | GR6: HCV-LS | GZ6: HCV-HS | HH6: HCV-MS (SMI) | HP6: Notes | HR6: HCV-LS | HW6: HCV-HS | IB6: HCV-MS (SMI) | IG6: Notes | IJ6: volume | IN6: status | IR6: Water Level | IS6: Notes | IU6: TCM HCV-LS | IZ6: SUB TOTAL | JA6: TCM HCV-HS | JF6: TCM HCV-MS (SMI) | JK6: SUB TOTAL | JL6: BEK MCV-LS | JQ6: SUB TOTAL | JR6: BEK MCV-HS | JW6: SUB TOTAL | JZ6: FC | KA6: ROM | KB6: WC | KC6: HAC CR1 | KE6: PSY | KH6: TOTAL | KI6: NB | KO6: SUB TOTAL | KP6: SB1 B05 | KV6: SUB TOTAL | KW6: SB2 B24 | LC6: SUB TOTAL | LD6: SB2 B30 (PAMA's feeder) | LJ6: SUB TOTAL | LK6: SB2 TEMP | LQ6: SUB TOTAL | LT6: HAC - WP | LU6: WP - WSY | LV6: WSY - CR3 | LW6: WSY Balance | LX6: Notes | MA6: PIT - HAC | MB6: HAC - WP | MC6: HAC - CR1 | MD6: HAC - CR3 | ME6: HAC Balance | MF6: Notes | ML6: assump. | MM6: 13000
F7: mm | G7: hours | H7: mm | I7: hours | K7: OB | L7: ROM | M7: SR | N7: Notes | O7: OB | P7: ROM | Q7: SR | R7: Notes | S7: OB | T7: ROM | U7: SR | V7: Notes | W7: OB | X7: ROM | Y7: SR | Z7: Notes | AA7: OB | AB7: ROM | AC7: SR | AD7: Notes | AF7: OB | AG7: ROM | AH7: SR | AI7: OB | AJ7: ROM | AK7: SR | AL7: OB | AM7: ROM | AN7: SR | AO7: OB | AP7: ROM | AQ7: SR | AR7: OB | AS7: ROM | AT7: SR | AU7: OB | AV7: ROM | AW7: SR | AX7: OB | AY7: ROM | AZ7: SR | BA7: OB | BB7: ROM | BC7: SR | BD7: OB | BE7: ROM | BF7: SR | BG7: OB | BH7: ROM | BI7: SR | BJ7: OB | BK7: ROM | BL7: SR | BM7: OB | BN7: ROM | BO7: SR | BP7: OB | BQ7: ROM | BR7: SR | BS7: OB | BT7: ROM | BU7: SR | CN7: ROM 1 | CO7: ROM 2 | CP7: ROM 3 | CQ7: ROM 4 | CR7: ROM 5 | CS7: ROM 6 | CU7: ROM 1 | CV7: ROM 2 | CW7: ROM 3 | CX7: ROM 4 | CY7: ROM 5 | CZ7: ROM 6 | DB7: ROM 1 | DC7: ROM 2 | DD7: ROM 3 | DE7: ROM 4 | DF7: ROM 5 | DG7: ROM 6 | DI7: ROM 1 | DJ7: ROM 2 | DK7: ROM 3 | DL7: ROM 4 | DM7: ROM 5 | DN7: ROM 6 | DX7: ROM 1 | DY7: ROM 2 | DZ7: ROM 3 | EA7: ROM 4 | EB7: ROM 5 | EC7: ROM 6 | EE7: ROM 1 | EF7: ROM 2 | EG7: ROM 3 | EH7: ROM 4 | EI7: ROM 5 | EJ7: ROM 6 | EL7: ROM 1 | EM7: ROM 2 | EN7: ROM 3 | EO7: ROM 4 | EP7: ROM 5 | EQ7: ROM 6 | EU7: NB | EV7: SB1 | EW7: SB2 | EY7: Shift A/B | EZ7: Shift A/B | FI7: ROM 1 | FJ7: ROM 2 | FK7: ROM 3 | FL7: ROM 4 | FM7: ROM 5 | FN7: ROM 6 | FO7: WC | FP7: HAC | FR7: ROM 1 | FS7: ROM 2 | FT7: ROM 3 | FU7: ROM 4 | FV7: ROM 5 | FW7: ROM 6 | FX7: WC | FY7: HAC | GA7: ROM 1 | GB7: ROM 2 | GC7: ROM 3 | GD7: ROM 4 | GE7: ROM 5 | GF7: ROM 6 | GG7: WC | GH7: HAC | GR7: ROM 1 | GS7: ROM 2 | GT7: ROM 3 | GU7: ROM 4 | GV7: ROM 5 | GW7: ROM 6 | GX7: WC | GY7: HAC | GZ7: ROM 1 | HA7: ROM 2 | HB7: ROM 3 | HC7: ROM 4 | HD7: ROM 5 | HE7: ROM 6 | HF7: WC | HG7: HAC | HH7: ROM 1 | HI7: ROM 2 | HJ7: ROM 3 | HK7: ROM 4 | HL7: ROM 5 | HM7: ROM 6 | HN7: WC | HO7: HAC | HR7: CV | HS7: TS | HT7: ASH | HU7: IM | HV7: TM | HW7: CV | HX7: TS | HY7: ASH | HZ7: IM | IA7: TM | IB7: CV | IC7: TS | ID7: ASH | IE7: IM | IF7: TM | IJ7: HCV-LS | IK7: HCV-HS | IL7: HCV-MS (SMI) | IM7: TOTAL | IN7: Completed | IO7: On Process of Loading | IP7: Queuing | IQ7: On the way | IU7: HCV-LS | IV7: HCV-HS | IW7: HCV-MS (SMI) | IX7: MCV-LS | IY7: MCV-HS | JA7: HCV-LS | JB7: HCV-HS | JC7: HCV-MS (SMI) | JD7: MCV-LS | JE7: MCV-HS | JF7: HCV-LS | JG7: HCV-HS | JH7: HCV-MS (SMI) | JI7: MCV-LS | JJ7: MCV-HS | JL7: HCV-LS | JM7: HCV-HS | JN7: HCV-MS (SMI) | JO7: MCV-LS | JP7: MCV-HS | JR7: HCV-LS | JS7: HCV-HS | JT7: HCV-MS (SMI) | JU7: MCV-LS | JV7: MCV-HS | KE7: HCV-LS | KF7: HCV-HS | KG7: HCV-MS (SMI) | KI7: ROM 1 | KJ7: ROM 2 | KK7: ROM 3 | KL7: ROM 4 | KM7: ROM 5 | KN7: ROM 6 | KP7: ROM 1 | KQ7: ROM 2 | KR7: ROM 3 | KS7: ROM 4 | KT7: ROM 5 | KU7: ROM 6 | KW7: ROM 1 | KX7: ROM 2 | KY7: ROM 3 | KZ7: ROM 4 | LA7: ROM 5 | LB7: ROM 6 | LD7: ROM 1 | LE7: ROM 2 | LF7: ROM 3 | LG7: ROM 4 | LH7: ROM 5 | LI7: ROM 6 | LK7: ROM 1 | LL7: ROM 2 | LM7: ROM 3 | LN7: ROM 4 | LO7: ROM 5 | LP7: ROM 6 | MI7: %LS | MJ7: %HS | ML7: %LS | MM7: %HS | MO7: ROM 1 | MP7: ROM 2 | MQ7: ROM 3 | MR7: ROM 4 | MS7: ROM 5 | MT7: ROM 6 | MV7: ROM 1 | MW7: ROM 2 | MX7: ROM 3 | MY7: ROM 4 | MZ7: ROM 5 | NA7: ROM 6
KH8: =SUM(KE8:KG8) -> 0 | KO8: =SUM(KI8:KN8) -> 0 | KV8: =SUM(KP8:KU8) -> 0 | LC8: =SUM(KW8:LB8) -> 0
B9: =COUNTIF(JZ10:MF40,"<"&0) -> 0 | KH9: =SUM(KE9:KG9) -> 0 | KO9: =SUM(KI9:KN9) -> 0 | KV9: =SUM(KP9:KU9) -> 0 | LC9: =SUM(KW9:LB9) -> 0 | LJ9: =SUM(LD9:LI9) -> 0
B10: 1 | C10: =+K10+O10+S10+W10+AA10 -> #REF! | D10: =+L10+P10+T10+X10+AB10 -> #REF! | E10: =IFERROR(C10/D10,0) -> 0 | K10: =+SUM(AF10,AO10,AR10,AU10+AI10+AL10) -> #REF! | L10: =+SUM(AG10,AP10,AS10,AV10+AJ10+AM10) -> #REF! | M10: =IFERROR(K10/L10,0) -> 0 | O10: =+SUM(BM10+BJ10) -> #REF! | P10: =+SUM(BB10+BK10) -> #REF! | Q10: =IFERROR(O10/P10,0) -> 0 | S10: =+BS10 -> #REF! | T10: =+BT10 -> #REF! | U10: =IFERROR(S10/T10,0) -> 0 | W10: =+BD10+BG10 -> #REF! | X10: =+BE10+BH10 -> #REF! | Y10: =IFERROR(W10/X10,0) -> 0 | AA10: =+AX10+BA10 -> #REF! | AB10: =+AY10+BB10 -> #REF! | AC10: =IFERROR(AA10/AB10,0) -> 0 | AF10: =+#REF!+#REF!+#REF!+#REF!+#REF!+#REF!+#REF!+#REF!+#REF!+#REF!+#REF!+#REF! -> #REF! | AG10: =+#REF!+#REF!+#REF!+#REF!+#REF!+#REF!+#REF!+#REF!+#REF!+#REF!+#REF!+#REF! -> #REF! | AH10: =IFERROR(AF10/AG10,0) -> 0 | AI10: =+#REF!+#REF!+#REF!+#REF!+#REF!+#REF!+#REF!+#REF!+#REF!+#REF!+#REF!+#REF! -> #REF! | AJ10: =+#REF!+#REF!+#REF!+#REF!+#REF!+#REF!+#REF!+#REF!+#REF!+#REF!+#REF!+#REF! -> #REF! | AK10: =IFERROR(AI10/AJ10,0) -> 0 | AL10: =+#REF!+#REF!+#REF!+#REF!+#REF!+#REF!+#REF!+#REF!+#REF!+#REF!+#REF!+#REF! -> #REF! | AM10: =+#REF!+#REF!+#REF!+#REF!+#REF!+#REF!+#REF!+#REF!+#REF!+#REF!+#REF!+#REF! -> #REF! | AN10: =IFERROR(AL10/AM10,0) -> 0 | AO10: =+#REF!+#REF!+#REF!+#REF!+#REF!+#REF!+#REF!+#REF!+#REF!+#REF!+#REF!+#REF! -> #REF! | AP10: =+#REF!+#REF!+#REF!+#REF!+#REF!+#REF!+#REF!+#REF!+#REF!+#REF!+#REF!+#REF! -> #REF! | AQ10: =IFERROR(AO10/AP10,0) -> 0 | AR10: =+#REF!+#REF!+#REF!+#REF!+#REF!+#REF!+#REF!+#REF!+#REF!+#REF!+#REF!+#REF! -> #REF! | AS10: =+#REF!+#REF!+#REF!+#REF!+#REF!+#REF!+#REF!+#REF!+#REF!+#REF!+#REF!+#REF! -> #REF! | AT10: =IFERROR(AR10/AS10,0) -> 0 | AU10: =+#REF!+#REF!+#REF!+#REF!+#REF!+#REF!+#REF!+#REF!+#REF!+#REF!+#REF!+#REF! -> #REF! | AV10: =+#REF!+#REF!+#REF!+#REF!+#REF!+#REF!+#REF!+#REF!+#REF!+#REF!+#REF!+#REF! -> #REF! | AW10: =IFERROR(AU10/AV10,0) -> 0 | AX10: =+#REF!+#REF!+#REF!+#REF!+#REF!+#REF!+#REF!+#REF!+#REF!+#REF!+#REF!+#REF! -> #REF! | AY10: =+#REF!+#REF!+#REF!+#REF!+#REF!+#REF!+#REF!+#REF!+#REF!+#REF!+#REF!+#REF! -> #REF! | AZ10: =IFERROR(AX10/AY10,0) -> 0 | BA10: =+#REF!+#REF!+#REF!+#REF!+#REF!+#REF!+#REF!+#REF!+#REF!+#REF!+#REF!+#REF! -> #REF! | BB10: =+#REF!+#REF!+#REF!+#REF!+#REF!+#REF!+#REF!+#REF!+#REF!+#REF!+#REF!+#REF! -> #REF! | BC10: =IFERROR(BA10/BB10,0) -> 0 | BD10: =+#REF!+#REF!+#REF!+#REF!+#REF!+#REF!+#REF!+#REF!+#REF!+#REF!+#REF!+#REF! -> #REF! | BE10: =+#REF!+#REF!+#REF!+#REF!+#REF!+#REF!+#REF!+#REF!+#REF!+#REF!+#REF!+#REF! -> #REF! | BF10: =IFERROR(BD10/BE10,0) -> 0 | BG10: =+#REF!+#REF!+#REF!+#REF!+#REF!+#REF!+#REF!+#REF!+#REF!+#REF!+#REF!+#REF! -> #REF! | BH10: =+#REF!+#REF!+#REF!+#REF!+#REF!+#REF!+#REF!+#REF!+#REF!+#REF!+#REF!+#REF! -> #REF! | BI10: =IFERROR(BG10/BH10,0) -> 0 | BJ10: =+#REF!+#REF!+#REF!+#REF!+#REF!+#REF!+#REF!+#REF!+#REF!+#REF!+#REF!+#REF! -> #REF! | BK10: =+#REF!+#REF!+#REF!+#REF!+#REF!+#REF!+#REF!+#REF!+#REF!+#REF!+#REF!+#REF! -> #REF! | BL10: =IFERROR(BJ10/BK10,0) -> 0 | BM10: =+#REF!+#REF!+#REF!+#REF!+#REF!+#REF!+#REF!+#REF!+#REF!+#REF!+#REF!+#REF! -> #REF! | BN10: =+#REF!+#REF!+#REF!+#REF!+#REF!+#REF!+#REF!+#REF!+#REF!+#REF!+#REF!+#REF! -> #REF! | BO10: =IFERROR(BM10/BN10,0) -> 0 | BP10: =+#REF!+#REF!+#REF!+#REF!+#REF!+#REF!+#REF!+#REF!+#REF!+#REF!+#REF!+#REF! -> #REF! | BQ10: =+#REF!+#REF!+#REF!+#REF!+#REF!+#REF!+#REF!+#REF!+#REF!+#REF!+#REF!+#REF! -> #REF! | BR10: =IFERROR(BP10/BQ10,0) -> 0 | BS10: =+#REF!+#REF!+#REF!+#REF!+#REF!+#REF!+#REF!+#REF!+#REF!+#REF!+#REF!+#REF! -> #REF! | BT10: =+#REF!+#REF!+#REF!+#REF!+#REF!+#REF!+#REF!+#REF!+#REF!+#REF!+#REF!+#REF! -> #REF! | BU10: =IFERROR(BS10/BT10,0) -> 0 | BW10: =+#REF!+#REF!+#REF!+#REF!+#REF!+#REF!+#REF!+#REF!+#REF!+#REF!+#REF!+#REF! -> #REF! | BX10: =+#REF!+#REF!+#REF!+#REF!+#REF!+#REF!+#REF!+#REF!+#REF!+#REF!+#REF!+#REF! -> #REF! | BY10: =+#REF!+#REF!+#REF!+#REF!+#REF!+#REF!+#REF!+#REF!+#REF!+#REF!+#REF!+#REF! -> #REF! | BZ10: =+#REF!+#REF!+#REF!+#REF!+#REF!+#REF!+#REF!+#REF!+#REF!+#REF!+#REF!+#REF! -> #REF! | CA10: =+#REF!+#REF!+#REF!+#REF!+#REF!+#REF!+#REF!+#REF!+#REF!+#REF!+#REF!+#REF! -> #REF! | CB10: =SUM(BW10:CA10) -> #REF! | CF10: =SUM(CN10,CU10,DB10,DI10) -> #REF! | CG10: =SUM(CO10,CV10,DC10,DJ10) -> #REF! | CH10: =SUM(CP10,CW10,DD10,DK10) -> #REF! | CI10: =SUM(CQ10,CX10,DE10,DL10) -> #REF! | CJ10: =SUM(CR10,CY10,DF10,DM10) -> #REF! | CK10: =SUM(CS10,CZ10,DG10,DN10) -> #REF! | CL10: =SUM(CF10:CK10) -> #REF! | CN10: =+#REF!+#REF!+#REF!+#REF!+#REF!+#REF!+#REF!+#REF!+#REF!+#REF!+#REF!+#REF! -> #REF! | CO10: =+#REF!+#REF!+#REF!+#REF!+#REF!+#REF!+#REF!+#REF!+#REF!+#REF!+#REF!+#REF! -> #REF! | CP10: =+#REF!+#REF!+#REF!+#REF!+#REF!+#REF!+#REF!+#REF!+#REF!+#REF!+#REF!+#REF! -> #REF! | CQ10: =+#REF!+#REF!+#REF!+#REF!+#REF!+#REF!+#REF!+#REF!+#REF!+#REF!+#REF!+#REF! -> #REF! | CR10: =+#REF!+#REF!+#REF!+#REF!+#REF!+#REF!+#REF!+#REF!+#REF!+#REF!+#REF!+#REF! -> #REF! | CS10: =+#REF!+#REF!+#REF!+#REF!+#REF!+#REF!+#REF!+#REF!+#REF!+#REF!+#REF!+#REF! -> #REF! | CT10: =SUM(CN10:CS10) -> #REF! | CU10: =+#REF!+#REF!+#REF!+#REF!+#REF!+#REF!+#REF!+#REF!+#REF!+#REF!+#REF!+#REF! -> #REF! | CV10: =+#REF!+#REF!+#REF!+#REF!+#REF!+#REF!+#REF!+#REF!+#REF!+#REF!+#REF!+#REF! -> #REF! | CW10: =+#REF!+#REF!+#REF!+#REF!+#REF!+#REF!+#REF!+#REF!+#REF!+#REF!+#REF!+#REF! -> #REF! | CX10: =+#REF!+#REF!+#REF!+#REF!+#REF!+#REF!+#REF!+#REF!+#REF!+#REF!+#REF!+#REF! -> #REF! | CY10: =+#REF!+#REF!+#REF!+#REF!+#REF!+#REF!+#REF!+#REF!+#REF!+#REF!+#REF!+#REF! -> #REF! | CZ10: =+#REF!+#REF!+#REF!+#REF!+#REF!+#REF!+#REF!+#REF!+#REF!+#REF!+#REF!+#REF! -> #REF! | DA10: =SUM(CU10:CZ10) -> #REF! | DB10: =+#REF!+#REF!+#REF!+#REF!+#REF!+#REF!+#REF!+#REF!+#REF!+#REF!+#REF!+#REF! -> #REF! | DC10: =+#REF!+#REF!+#REF!+#REF!+#REF!+#REF!+#REF!+#REF!+#REF!+#REF!+#REF!+#REF! -> #REF! | DD10: =+#REF!+#REF!+#REF!+#REF!+#REF!+#REF!+#REF!+#REF!+#REF!+#REF!+#REF!+#REF! -> #REF! | DE10: =+#REF!+#REF!+#REF!+#REF!+#REF!+#REF!+#REF!+#REF!+#REF!+#REF!+#REF!+#REF! -> #REF! | DF10: =+#REF!+#REF!+#REF!+#REF!+#REF!+#REF!+#REF!+#REF!+#REF!+#REF!+#REF!+#REF! -> #REF! | DG10: =+#REF!+#REF!+#REF!+#REF!+#REF!+#REF!+#REF!+#REF!+#REF!+#REF!+#REF!+#REF! -> #REF! | DH10: =SUM(DB10:DG10) -> #REF! | DI10: =+#REF!+#REF!+#REF!+#REF!+#REF!+#REF!+#REF!+#REF!+#REF!+#REF!+#REF!+#REF! -> #REF! | DJ10: =+#REF!+#REF!+#REF!+#REF!+#REF!+#REF!+#REF!+#REF!+#REF!+#REF!+#REF!+#REF! -> #REF! | DK10: =+#REF!+#REF!+#REF!+#REF!+#REF!+#REF!+#REF!+#REF!+#REF!+#REF!+#REF!+#REF! -> #REF! | DL10: =+#REF!+#REF!+#REF!+#REF!+#REF!+#REF!+#REF!+#REF!+#REF!+#REF!+#REF!+#REF! -> #REF! | DM10: =+#REF!+#REF!+#REF!+#REF!+#REF!+#REF!+#REF!+#REF!+#REF!+#REF!+#REF!+#REF! -> #REF! | DN10: =+#REF!+#REF!+#REF!+#REF!+#REF!+#REF!+#REF!+#REF!+#REF!+#REF!+#REF!+#REF! -> #REF! | DO10: =SUM(DI10:DN10) -> #REF! | DR10: =+ED10 -> #REF! | DS10: =+EK10 -> #REF! | DT10: =+ER10 -> #REF! | DU10: =SUM(DR10:DT10) -> #REF! | DX10: =+#REF!+#REF!+#REF!+#REF!+#REF!+#REF!+#REF!+#REF!+#REF!+#REF!+#REF!+#REF! -> #REF! | DY10: =+#REF!+#REF!+#REF!+#REF!+#REF!+#REF!+#REF!+#REF!+#REF!+#REF!+#REF!+#REF! -> #REF! | DZ10: =+#REF!+#REF!+#REF!+#REF!+#REF!+#REF!+#REF!+#REF!+#REF!+#REF!+#REF!+#REF! -> #REF! | EA10: =+#REF!+#REF!+#REF!+#REF!+#REF!+#REF!+#REF!+#REF!+#REF!+#REF!+#REF!+#REF! -> #REF! | EB10: =+#REF!+#REF!+#REF!+#REF!+#REF!+#REF!+#REF!+#REF!+#REF!+#REF!+#REF!+#REF! -> #REF! | EC10: =+#REF!+#REF!+#REF!+#REF!+#REF!+#REF!+#REF!+#REF!+#REF!+#REF!+#REF!+#REF! -> #REF! | ED10: =SUM(DX10:EC10) -> #REF! | EE10: =+#REF!+#REF!+#REF!+#REF!+#REF!+#REF!+#REF!+#REF!+#REF!+#REF!+#REF!+#REF! -> #REF! | EF10: =+#REF!+#REF!+#REF!+#REF!+#REF!+#REF!+#REF!+#REF!+#REF!+#REF!+#REF!+#REF! -> #REF! | EG10: =+#REF!+#REF!+#REF!+#REF!+#REF!+#REF!+#REF!+#REF!+#REF!+#REF!+#REF!+#REF! -> #REF! | EH10: =+#REF!+#REF!+#REF!+#REF!+#REF!+#REF!+#REF!+#REF!+#REF!+#REF!+#REF!+#REF! -> #REF! | EI10: =+#REF!+#REF!+#REF!+#REF!+#REF!+#REF!+#REF!+#REF!+#REF!+#REF!+#REF!+#REF! -> #REF! | EJ10: =+#REF!+#REF!+#REF!+#REF!+#REF!+#REF!+#REF!+#REF!+#REF!+#REF!+#REF!+#REF! -> #REF! | EK10: =SUM(EE10:EJ10) -> #REF! | EL10: =+#REF!+#REF!+#REF!+#REF!+#REF!+#REF!+#REF!+#REF!+#REF!+#REF!+#REF!+#REF! -> #REF! | EM10: =+#REF!+#REF!+#REF!+#REF!+#REF!+#REF!+#REF!+#REF!+#REF!+#REF!+#REF!+#REF! -> #REF! | EN10: =+#REF!+#REF!+#REF!+#REF!+#REF!+#REF!+#REF!+#REF!+#REF!+#REF!+#REF!+#REF! -> #REF! | EO10: =+#REF!+#REF!+#REF!+#REF!+#REF!+#REF!+#REF!+#REF!+#REF!+#REF!+#REF!+#REF! -> #REF! | EP10: =+#REF!+#REF!+#REF!+#REF!+#REF!+#REF!+#REF!+#REF!+#REF!+#REF!+#REF!+#REF! -> #REF! | EQ10: =+#REF!+#REF!+#REF!+#REF!+#REF!+#REF!+#REF!+#REF!+#REF!+#REF!+#REF!+#REF! -> #REF! | ER10: =SUM(EL10:EQ10) -> #REF! | EU10: =FQ10 -> #REF! | EV10: =+FZ10 -> #REF! | EW10: =+GI10 -> #REF! | EX10: =SUM(EU10:EW10) -> #REF! | FC10: =+#REF!+#REF!+#REF!+#REF!+#REF!+#REF!+#REF!+#REF!+#REF!+#REF!+#REF!+#REF! -> #REF! | FD10: =+#REF!+#REF!+#REF!+#REF!+#REF!+#REF!+#REF!+#REF!+#REF!+#REF!+#REF!+#REF! -> #REF! | FG10: =SUM(FC10:FF10) -> #REF! | FI10: =+#REF!+#REF!+#REF!+#REF!+#REF!+#REF!+#REF!+#REF!+#REF!+#REF!+#REF!+#REF! -> #REF! | FJ10: =+#REF!+#REF!+#REF!+#REF!+#REF!+#REF!+#REF!+#REF!+#REF!+#REF!+#REF!+#REF! -> #REF! | FK10: =+#REF!+#REF!+#REF!+#REF!+#REF!+#REF!+#REF!+#REF!+#REF!+#REF!+#REF!+#REF! -> #REF! | FL10: =+#REF!+#REF!+#REF!+#REF!+#REF!+#REF!+#REF!+#REF!+#REF!+#REF!+#REF!+#REF! -> #REF! | FM10: =+#REF!+#REF!+#REF!+#REF!+#REF!+#REF!+#REF!+#REF!+#REF!+#REF!+#REF!+#REF! -> #REF! | FN10: =+#REF!+#REF!+#REF!+#REF!+#REF!+#REF!+#REF!+#REF!+#REF!+#REF!+#REF!+#REF! -> #REF! | FO10: =+#REF!+#REF!+#REF!+#REF!+#REF!+#REF!+#REF!+#REF!+#REF!+#REF!+#REF!+#REF! -> #REF! | FP10: =+#REF!+#REF!+#REF!+#REF!+#REF!+#REF!+#REF!+#REF!+#REF!+#REF!+#REF!+#REF! -> #REF! | FQ10: =SUM(FI10:FP10) -> #REF! | FR10: =+#REF!+#REF!+#REF!+#REF!+#REF!+#REF!+#REF!+#REF!+#REF!+#REF!+#REF!+#REF! -> #REF! | FS10: =+#REF!+#REF!+#REF!+#REF!+#REF!+#REF!+#REF!+#REF!+#REF!+#REF!+#REF!+#REF! -> #REF! | FT10: =+#REF!+#REF!+#REF!+#REF!+#REF!+#REF!+#REF!+#REF!+#REF!+#REF!+#REF!+#REF! -> #REF! | FU10: =+#REF!+#REF!+#REF!+#REF!+#REF!+#REF!+#REF!+#REF!+#REF!+#REF!+#REF!+#REF! -> #REF! | FV10: =+#REF!+#REF!+#REF!+#REF!+#REF!+#REF!+#REF!+#REF!+#REF!+#REF!+#REF!+#REF! -> #REF! | FW10: =+#REF!+#REF!+#REF!+#REF!+#REF!+#REF!+#REF!+#REF!+#REF!+#REF!+#REF!+#REF! -> #REF! | FX10: =+#REF!+#REF!+#REF!+#REF!+#REF!+#REF!+#REF!+#REF!+#REF!+#REF!+#REF!+#REF! -> #REF! | FY10: =+#REF!+#REF!+#REF!+#REF!+#REF!+#REF!+#REF!+#REF!+#REF!+#REF!+#REF!+#REF! -> #REF! | FZ10: =SUM(FR10:FY10) -> #REF! | GA10: =+#REF!+#REF!+#REF!+#REF!+#REF!+#REF!+#REF!+#REF!+#REF!+#REF!+#REF!+#REF! -> #REF! | GB10: =+#REF!+#REF!+#REF!+#REF!+#REF!+#REF!+#REF!+#REF!+#REF!+#REF!+#REF!+#REF! -> #REF! | GC10: =+#REF!+#REF!+#REF!+#REF!+#REF!+#REF!+#REF!+#REF!+#REF!+#REF!+#REF!+#REF! -> #REF! | GD10: =+#REF!+#REF!+#REF!+#REF!+#REF!+#REF!+#REF!+#REF!+#REF!+#REF!+#REF!+#REF! -> #REF! | GE10: =+#REF!+#REF!+#REF!+#REF!+#REF!+#REF!+#REF!+#REF!+#REF!+#REF!+#REF!+#REF! -> #REF! | GF10: =+#REF!+#REF!+#REF!+#REF!+#REF!+#REF!+#REF!+#REF!+#REF!+#REF!+#REF!+#REF! -> #REF! | GG10: =+#REF!+#REF!+#REF!+#REF!+#REF!+#REF!+#REF!+#REF!+#REF!+#REF!+#REF!+#REF! -> #REF! | GH10: =+#REF!+#REF!+#REF!+#REF!+#REF!+#REF!+#REF!+#REF!+#REF!+#REF!+#REF!+#REF! -> #REF! | GI10: =SUM(GA10:GH10) -> #REF! | GL10: =+#REF!+#REF!+#REF!+#REF!+#REF!+#REF!+#REF!+#REF!+#REF!+#REF!+#REF!+#REF! -> #REF! | GM10: =+#REF!+#REF!+#REF!+#REF!+#REF!+#REF!+#REF!+#REF!+#REF!+#REF!+#REF!+#REF! -> #REF! | GN10: =+#REF!+#REF!+#REF!+#REF!+#REF!+#REF!+#REF!+#REF!+#REF!+#REF!+#REF!+#REF! -> #REF! | GO10: =+GL10+GN10+GM10 -> #REF! | IJ10: =SUM(IU10,JA10,JL10,JR10+JF10) -> #REF! | IK10: =SUM(IV10,JB10,JM10,JS10+JG10) -> #REF! | IL10: =SUM(IW10,JC10,JN10,JT10+JH10) -> #REF! | IM10: =SUM(IJ10:IL10) -> #REF! | IU10: =+#REF!+#REF!+#REF!+#REF!+#REF!+#REF!+#REF!+#REF!+#REF!+#REF!+#REF!+#REF! -> #REF! | IV10: =+#REF!+#REF!+#REF!+#REF!+#REF!+#REF!+#REF!+#REF!+#REF!+#REF!+#REF!+#REF! -> #REF! | IW10: =+#REF!+#REF!+#REF!+#REF!+#REF!+#REF!+#REF!+#REF!+#REF!+#REF!+#REF!+#REF! -> #REF! | IX10: =+#REF!+#REF!+#REF!+#REF!+#REF!+#REF!+#REF!+#REF!+#REF!+#REF!+#REF!+#REF! -> #REF! | IY10: =+#REF!+#REF!+#REF!+#REF!+#REF!+#REF!+#REF!+#REF!+#REF!+#REF!+#REF!+#REF! -> #REF! | IZ10: =SUM(IU10:IY10) -> #REF! | JA10: =+#REF!+#REF!+#REF!+#REF!+#REF!+#REF!+#REF!+#REF!+#REF!+#REF!+#REF!+#REF! -> #REF! | JB10: =+#REF!+#REF!+#REF!+#REF!+#REF!+#REF!+#REF!+#REF!+#REF!+#REF!+#REF!+#REF! -> #REF! | JC10: =+#REF!+#REF!+#REF!+#REF!+#REF!+#REF!+#REF!+#REF!+#REF!+#REF!+#REF!+#REF! -> #REF! | JD10: =+#REF!+#REF!+#REF!+#REF!+#REF!+#REF!+#REF!+#REF!+#REF!+#REF!+#REF!+#REF! -> #REF! | JE10: =+#REF!+#REF!+#REF!+#REF!+#REF!+#REF!+#REF!+#REF!+#REF!+#REF!+#REF!+#REF! -> #REF! | JF10: =+#REF!+#REF!+#REF!+#REF!+#REF!+#REF!+#REF!+#REF!+#REF!+#REF!+#REF!+#REF! -> #REF! | JG10: =+#REF!+#REF!+#REF!+#REF!+#REF!+#REF!+#REF!+#REF!+#REF!+#REF!+#REF!+#REF! -> #REF! | JH10: =+#REF!+#REF!+#REF!+#REF!+#REF!+#REF!+#REF!+#REF!+#REF!+#REF!+#REF!+#REF! -> #REF! | ... JJ10: =+#REF!+#REF!+#REF!+#REF!+#REF!+#REF!+#REF!+#REF!+#REF!+#REF!+#REF!+#REF! -> #REF! | JK10: =SUM(JF10:JJ10) -> #REF! | JL10: =+#REF!+#REF!+#REF!+#REF!+#REF!+#REF!+#REF!+#REF!+#REF!+#REF!+#REF!+#REF! -> #REF! | JM10: =+#REF!+#REF!+#REF!+#REF!+#REF!+#REF!+#REF!+#REF!+#REF!+#REF!+#REF!+#REF! -> #REF! | JN10: =+#REF!+#REF!+#REF!+#REF!+#REF!+#REF!+#REF!+#REF!+#REF!+#REF!+#REF!+#REF! -> #REF! | JO10: =+#REF!+#REF!+#REF!+#REF!+#REF!+#REF!+#REF!+#REF!+#REF!+#REF!+#REF!+#REF! -> #REF! | JP10: =+#REF!+#REF!+#REF!+#REF!+#REF!+#REF!+#REF!+#REF!+#REF!+#REF!+#REF!+#REF! -> #REF! | JQ10: =SUM(JL10:JP10) -> #REF! | JR10: =+#REF!+#REF!+#REF!+#REF!+#REF!+#REF!+#REF!+#REF!+#REF!+#REF!+#REF!+#REF! -> #REF! | JS10: =+#REF!+#REF!+#REF!+#REF!+#REF!+#REF!+#REF!+#REF!+#REF!+#REF!+#REF!+#REF! -> #REF! | JT10: =+#REF!+#REF!+#REF!+#REF!+#REF!+#REF!+#REF!+#REF!+#REF!+#REF!+#REF!+#REF! -> #REF! | JU10: =+#REF!+#REF!+#REF!+#REF!+#REF!+#REF!+#REF!+#REF!+#REF!+#REF!+#REF!+#REF! -> #REF! | JV10: =+#REF!+#REF!+#REF!+#REF!+#REF!+#REF!+#REF!+#REF!+#REF!+#REF!+#REF!+#REF! -> #REF! | JW10: =SUM(JR10:JV10) -> #REF! | JZ10: =+KH10 -> #REF! | KA10: =+SUM(KO10,KV10,LC10,LJ10,LQ10) -> #REF! | KB10: =+LW10 -> #REF! | KC10: =+KC9+MC10-FP10 -> #REF! | KE10: =+KE9+GL10-IJ10 -> #REF! | KF10: =+KF9+GM10-IK10 -> #REF! | KG10: =+KG9+GN10-IL10 -> #REF! | KH10: =SUM(KE10:KG10) -> #REF! | KI10: =+KI8+DB10-FI10 -> #REF! | KJ10: =+KJ9-FJ10 -> #REF! | KK10: =+KK9-FK10 -> #REF! | KL10: =+KL9-FL10 -> #REF! | KM10: =+KM9-FM10 -> #REF! | KN10: =+KN9-FN10 -> #REF! | KO10: =SUM(KI10:KN10) -> #REF! | KP10: =+KP9+CN10+EE10+EL10-FR10 -> #REF! | KQ10: =+KQ9+CO10+EF10+EM10-FS10 -> #REF! | KR10: =+KR9+CP10+EG10+EN10-FT10 -> #REF! | KS10: =+KS9+CQ10+EH10+EO10-FU10 -> #REF! | KT10: =+KT9+CR10+EI10+EP10-FV10 -> #REF! | KU10: =+KU9+CS10+EJ10+EQ10-FW10 -> #REF! | KV10: =SUM(KP10:KU10) -> #REF! | KW10: =+KW9+CU10+DX10-GA10 -> #REF! | KX10: =+KX9+CV10+DY10-GB10 -> #REF! | KY10: =+KY9+CW10+DZ10-GC10 -> #REF! | KZ10: =+KZ9+CX10+EA10-GD10 -> #REF! | LA10: =+LA9+CY10+EB10-GE10 -> #REF! | LB10: =+LB9+CZ10+EC10-GF10 -> #REF! | LC10: =SUM(KW10:LB10) -> #REF! | LJ10: =SUM(LD10:LI10) -> 0 | LK10: =+LK9+DI10-EL10 -> #REF! | LL10: =+LL9+DJ10-EM10 -> #REF! | LM10: =+LM9+DK10-EN10 -> #REF! | LN10: =+LN9+DL10-EO10 -> #REF! | LO10: =+LO9+DM10-EP10 -> #REF! | LP10: =+LP9+DN10-EQ10 -> #REF! | LQ10: =SUM(LK10:LP10) -> #REF! | LT10: =+#REF!+#REF!+#REF!+#REF!+#REF!+#REF!+#REF!+#REF!+#REF!+#REF!+#REF!+#REF! -> #REF! | LU10: =+#REF!+#REF!+#REF!+#REF!+#REF!+#REF!+#REF!+#REF!+#REF!+#REF!+#REF!+#REF! -> #REF! | LV10: =+FO10 -> #REF! | LW10: =+LW9+LU10-LV10 -> #REF! | MA10: =+#REF!+#REF!+#REF!+#REF!+#REF!+#REF!+#REF!+#REF!+#REF!+#REF!+#REF!+#REF! -> #REF! | MB10: =+LT10 -> #REF! | MC10: =+#REF!+#REF!+#REF!+#REF!+#REF!+#REF!+#REF!+#REF!+#REF!+#REF!+#REF!+#REF! -> #REF! | MD10: =+FP10+FY10+GH10 -> #REF! | ME10: =+ME9+MA10-MB10-MC10-MD10 -> #REF! | MI10: =IF(GL10=0,"",(IFERROR(IF(1-ABS(1-(GR10/GR$43))<0,0,1-ABS(1-(GR10/GR$43))),0)*GR$43)+(IFERROR(IF(1-ABS(1-(GS10/GS$43))<0,0,1-ABS(1-(GS10/GS$43))),0)*GS$43)+(IFERROR(IF(1-ABS(1-(GT10/GT$43))<0,0,1-ABS(1-(GT10/GT$43))),0)*GT$43)+(IFERROR(IF(1-ABS(1-(GU10/GU$43))<0,0,1-ABS(1-(GU10/GU$43))),0)*GU$43)+(IFERROR(IF(1-ABS(1-(GV10/GV$43))<0,0,1-ABS(1-(GV10/GV$43))),0)*GV$43)+(IFERROR(IF(1-ABS(1-(GW10/GW$43))<0,0,1-ABS(1-(GW10/GW$43))),0)*GW$43)+(IFERROR(IF(1-ABS(1-(GX10/GX$43))<0,0,1-ABS(1-(GX10/GX$43))),0)*GX$43)+(IFERROR(IF(1-ABS(1-(GY10/GY$43))<0,0,1-ABS(1-(GY10/GY$43))),0)*GY$43)) -> #REF! | MJ10: =IF(GN10=0,"",(IFERROR(IF(1-ABS(1-(HH10/HH$43))<0,0,1-ABS(1-(HH10/HH$43))),0)*HH$43)+(IFERROR(IF(1-ABS(1-(HI10/HI$43))<0,0,1-ABS(1-(HI10/HI$43))),0)*HI$43)+(IFERROR(IF(1-ABS(1-(HJ10/HJ$43))<0,0,1-ABS(1-(HJ10/HJ$43))),0)*HJ$43)+(IFERROR(IF(1-ABS(1-(HK10/HK$43))<0,0,1-ABS(1-(HK10/HK$43))),0)*HK$43)+(IFERROR(IF(1-ABS(1-(HL10/HL$43))<0,0,1-ABS(1-(HL10/HL$43))),0)*HL$43)+(IFERROR(IF(1-ABS(1-(HM10/HM$43))<0,0,1-ABS(1-(HM10/HM$43))),0)*HM$43)+(IFERROR(IF(1-ABS(1-(HN10/HN$43))<0,0,1-ABS(1-(HN10/HN$43))),0)*HN$43)+(IFERROR(IF(1-ABS(1-(HO10/HO$43))<0,0,1-ABS(1-(HO10/HO$43))),0)*HO$43)) -> #REF! | ML10: =IF(GO10>0,SUMPRODUCT(MO10:MT10,$GR$43:$GW$43),"") -> #REF! | MM10: =IF(GO10>0,SUMPRODUCT(MV10:NA10,$HH$43:$HM$43),"") -> #REF! | MO10: =IF(KP$43=0,0,IF(SUM(KP10,KW10)-KP$8-KW$8>KP$43,1,(SUM(KP10,KW10)-KP$8-KW$8)/KP$43)) -> 0 | MP10: =IF(KQ$43=0,0,IF(SUM(KQ10,KX10)-KQ$8-KX$8>KQ$43,1,(SUM(KQ10,KX10)-KQ$8-KX$8)/KQ$43)) -> 0 | MQ10: =IF(KR$43=0,0,IF(SUM(KR10,KY10)-KR$8-KY$8>KR$43,1,(SUM(KR10,KY10)-KR$8-KY$8)/KR$43)) -> 0 | MR10: =IF(KS$43=0,0,IF(SUM(KS10,KZ10)-KS$8-KZ$8>KS$43,1,(SUM(KS10,KZ10)-KS$8-KZ$8)/KS$43)) -> 0 | MS10: =IF(KT$43=0,0,IF(SUM(KT10,LA10)-KT$8-LA$8>KT$43,1,(SUM(KT10,LA10)-KT$8-LA$8)/KT$43)) -> 0 | MT10: =IF(KU$43=0,0,IF(SUM(KU10,LB10)-KU$8-LB$8>KU$43,1,(SUM(KU10,LB10)-KU$8-LB$8)/KU$43)) -> 0 | MV10: =+IF(KP$43=0,0,IF(SUM(KP10,KW10)-KP$8-KW$8>KP$43,1,(SUM(KP10,KW10)-KP$8-KW$8)/KP$43)) -> 0 | MW10: =+IF(KQ$43=0,0,IF(SUM(KQ10,KX10)-KQ$8-KX$8>KQ$43,1,(SUM(KQ10,KX10)-KQ$8-KX$8)/KQ$43)) -> 0 | MX10: =+IF(KR$43=0,0,IF(SUM(KR10,KY10)-KR$8-KY$8>KR$43,1,(SUM(KR10,KY10)-KR$8-KY$8)/KR$43)) -> 0 | MY10: =+IF(KS$43=0,0,IF(SUM(KS10,KZ10)-KS$8-KZ$8>KS$43,1,(SUM(KS10,KZ10)-KS$8-KZ$8)/KS$43)) -> 0 | MZ10: =+IF(KT$43=0,0,IF(SUM(KT10,LA10)-KT$8-LA$8>KT$43,1,(SUM(KT10,LA10)-KT$8-LA$8)/KT$43)) -> 0 | NA10: =+IF(KU$43=0,0,IF(SUM(KU10,LB10)-KU$8-LB$8>KU$43,1,(SUM(KU10,LB10)-KU$8-LB$8)/KU$43)) -> 0
B11: 2 | C11: =+K11+O11+S11+W11+AA11 -> #REF! | D11: =+L11+P11+T11+X11+AB11 -> #REF! | E11: =IFERROR(C11/D11,0) -> 0 | K11: =+SUM(AF11,AO11,AR11,AU11+AI11+AL11) -> #REF! | L11: =+SUM(AG11,AP11,AS11,AV11+AJ11+AM11) -> #REF! | M11: =IFERROR(K11/L11,0) -> 0 | O11: =+SUM(BA11+BJ11) -> #REF! | P11: =+SUM(BB11+BK11) -> #REF! | Q11: =IFERROR(O11/P11,0) -> 0 | S11: =+BS11 -> #REF! | T11: =+BT11 -> #REF! | U11: =IFERROR(S11/T11,0) -> 0 | W11: =+BD11+BG11 -> #REF! | X11: =+BE11+BH11 -> #REF! | Y11: =IFERROR(W11/X11,0) -> 0 | AA11: =+AX11+BA11 -> #REF! | AB11: =+AY11+BB11 -> #REF! | AC11: =IFERROR(AA11/AB11,0) -> 0 | AF11: =+#REF!+#REF!+#REF!+#REF!+#REF!+#REF!+#REF!+#REF!+#REF!+#REF!+#REF!+#REF! -> #REF! | AG11: =+#REF!+#REF!+#REF!+#REF!+#REF!+#REF!+#REF!+#REF!+#REF!+#REF!+#REF!+#REF! -> #REF! | AH11: =IFERROR(AF11/AG11,0) -> 0 | AI11: =+#REF!+#REF!+#REF!+#REF!+#REF!+#REF!+#REF!+#REF!+#REF!+#REF!+#REF!+#REF! -> #REF! | AJ11: =+#REF!+#REF!+#REF!+#REF!+#REF!+#REF!+#REF!+#REF!+#REF!+#REF!+#REF!+#REF! -> #REF! | AK11: =IFERROR(AI11/AJ11,0) -> 0 | AL11: =+#REF!+#REF!+#REF!+#REF!+#REF!+#REF!+#REF!+#REF!+#REF!+#REF!+#REF!+#REF! -> #REF! | AM11: =+#REF!+#REF!+#REF!+#REF!+#REF!+#REF!+#REF!+#REF!+#REF!+#REF!+#REF!+#REF! -> #REF! | AN11: =IFERROR(AL11/AM11,0) -> 0 | AO11: =+#REF!+#REF!+#REF!+#REF!+#REF!+#REF!+#REF!+#REF!+#REF!+#REF!+#REF!+#REF! -> #REF! | AP11: =+#REF!+#REF!+#REF!+#REF!+#REF!+#REF!+#REF!+#REF!+#REF!+#REF!+#REF!+#REF! -> #REF! | AQ11: =IFERROR(AO11/AP11,0) -> 0 | AR11: =+#REF!+#REF!+#REF!+#REF!+#REF!+#REF!+#REF!+#REF!+#REF!+#REF!+#REF!+#REF! -> #REF! | AS11: =+#REF!+#REF!+#REF!+#REF!+#REF!+#REF!+#REF!+#REF!+#REF!+#REF!+#REF!+#REF! -> #REF! | AT11: =IFERROR(AR11/AS11,0) -> 0 | AU11: =+#REF!+#REF!+#REF!+#REF!+#REF!+#REF!+#REF!+#REF!+#REF!+#REF!+#REF!+#REF! -> #REF! | AV11: =+#REF!+#REF!+#REF!+#REF!+#REF!+#REF!+#REF!+#REF!+#REF!+#REF!+#REF!+#REF! -> #REF! | AW11: =IFERROR(AU11/AV11,0) -> 0 | AX11: =+#REF!+#REF!+#REF!+#REF!+#REF!+#REF!+#REF!+#REF!+#REF!+#REF!+#REF!+#REF! -> #REF! | AY11: =+#REF!+#REF!+#REF!+#REF!+#REF!+#REF!+#REF!+#REF!+#REF!+#REF!+#REF!+#REF! -> #REF! | AZ11: =IFERROR(AX11/AY11,0) -> 0 | BA11: =+#REF!+#REF!+#REF!+#REF!+#REF!+#REF!+#REF!+#REF!+#REF!+#REF!+#REF!+#REF! -> #REF! | BB11: =+#REF!+#REF!+#REF!+#REF!+#REF!+#REF!+#REF!+#REF!+#REF!+#REF!+#REF!+#REF! -> #REF! | BC11: =IFERROR(BA11/BB11,0) -> 0 | BD11: =+#REF!+#REF!+#REF!+#REF!+#REF!+#REF!+#REF!+#REF!+#REF!+#REF!+#REF!+#REF! -> #REF! | BE11: =+#REF!+#REF!+#REF!+#REF!+#REF!+#REF!+#REF!+#REF!+#REF!+#REF!+#REF!+#REF! -> #REF! | BF11: =IFERROR(BD11/BE11,0) -> 0 | BG11: =+#REF!+#REF!+#REF!+#REF!+#REF!+#REF!+#REF!+#REF!+#REF!+#REF!+#REF!+#REF! -> #REF! | BH11: =+#REF!+#REF!+#REF!+#REF!+#REF!+#REF!+#REF!+#REF!+#REF!+#REF!+#REF!+#REF! -> #REF! | BI11: =IFERROR(BG11/BH11,0) -> 0 | BJ11: =+#REF!+#REF!+#REF!+#REF!+#REF!+#REF!+#REF!+#REF!+#REF!+#REF!+#REF!+#REF! -> #REF! | BK11: =+#REF!+#REF!+#REF!+#REF!+#REF!+#REF!+#REF!+#REF!+#REF!+#REF!+#REF!+#REF! -> #REF! | BL11: =IFERROR(BJ11/BK11,0) -> 0 | BM11: =+#REF!+#REF!+#REF!+#REF!+#REF!+#REF!+#REF!+#REF!+#REF!+#REF!+#REF!+#REF! -> #REF! | BN11: =+#REF!+#REF!+#REF!+#REF!+#REF!+#REF!+#REF!+#REF!+#REF!+#REF!+#REF!+#REF! -> #REF! | BO11: =IFERROR(BM11/BN11,0) -> 0 | BP11: =+#REF!+#REF!+#REF!+#REF!+#REF!+#REF!+#REF!+#REF!+#REF!+#REF!+#REF!+#REF! -> #REF! | BQ11: =+#REF!+#REF!+#REF!+#REF!+#REF!+#REF!+#REF!+#REF!+#REF!+#REF!+#REF!+#REF! -> #REF! | BR11: =IFERROR(BP11/BQ11,0) -> 0 | BS11: =+#REF!+#REF!+#REF!+#REF!+#REF!+#REF!+#REF!+#REF!+#REF!+#REF!+#REF!+#REF! -> #REF! | BT11: =+#REF!+#REF!+#REF!+#REF!+#REF!+#REF!+#REF!+#REF!+#REF!+#REF!+#REF!+#REF! -> #REF! | BU11: =IFERROR(BS11/BT11,0) -> 0 | BW11: =+#REF!+#REF!+#REF!+#REF!+#REF!+#REF!+#REF!+#REF!+#REF!+#REF!+#REF!+#REF! -> #REF! | BX11: =+#REF!+#REF!+#REF!+#REF!+#REF!+#REF!+#REF!+#REF!+#REF!+#REF!+#REF!+#REF! -> #REF! | BY11: =+#REF!+#REF!+#REF!+#REF!+#REF!+#REF!+#REF!+#REF!+#REF!+#REF!+#REF!+#REF! -> #REF! | BZ11: =+#REF!+#REF!+#REF!+#REF!+#REF!+#REF!+#REF!+#REF!+#REF!+#REF!+#REF!+#REF! -> #REF! | CA11: =+#REF!+#REF!+#REF!+#REF!+#REF!+#REF!+#REF!+#REF!+#REF!+#REF!+#REF!+#REF! -> #REF! | CB11: =SUM(BW11:CA11) -> #REF! | CF11: =SUM(CN11,CU11,DB11,DI11) -> #REF! | CG11: =SUM(CO11,CV11,DC11,DJ11) -> #REF! | CH11: =SUM(CP11,CW11,DD11,DK11) -> #REF! | CI11: =SUM(CQ11,CX11,DE11,DL11) -> #REF! | CJ11: =SUM(CR11,CY11,DF11,DM11) -> #REF! | CK11: =SUM(CS11,CZ11,DG11,DN11) -> #REF! | CL11: =SUM(CF11:CK11) -> #REF! | CN11: =+#REF!+#REF!+#REF!+#REF!+#REF!+#REF!+#REF!+#REF!+#REF!+#REF!+#REF!+#REF! -> #REF! | CO11: =+#REF!+#REF!+#REF!+#REF!+#REF!+#REF!+#REF!+#REF!+#REF!+#REF!+#REF!+#REF! -> #REF! | CP11: =+#REF!+#REF!+#REF!+#REF!+#REF!+#REF!+#REF!+#REF!+#REF!+#REF!+#REF!+#REF! -> #REF! | CQ11: =+#REF!+#REF!+#REF!+#REF!+#REF!+#REF!+#REF!+#REF!+#REF!+#REF!+#REF!+#REF! -> #REF! | CR11: =+#REF!+#REF!+#REF!+#REF!+#REF!+#REF!+#REF!+#REF!+#REF!+#REF!+#REF!+#REF! -> #REF! | CS11: =+#REF!+#REF!+#REF!+#REF!+#REF!+#REF!+#REF!+#REF!+#REF!+#REF!+#REF!+#REF! -> #REF! | CT11: =SUM(CN11:CS11) -> #REF! | CU11: =+#REF!+#REF!+#REF!+#REF!+#REF!+#REF!+#REF!+#REF!+#REF!+#REF!+#REF!+#REF! -> #REF! | CV11: =+#REF!+#REF!+#REF!+#REF!+#REF!+#REF!+#REF!+#REF!+#REF!+#REF!+#REF!+#REF! -> #REF! | CW11: =+#REF!+#REF!+#REF!+#REF!+#REF!+#REF!+#REF!+#REF!+#REF!+#REF!+#REF!+#REF! -> #REF! | CX11: =+#REF!+#REF!+#REF!+#REF!+#REF!+#REF!+#REF!+#REF!+#REF!+#REF!+#REF!+#REF! -> #REF! | CY11: =+#REF!+#REF!+#REF!+#REF!+#REF!+#REF!+#REF!+#REF!+#REF!+#REF!+#REF!+#REF! -> #REF! | CZ11: =+#REF!+#REF!+#REF!+#REF!+#REF!+#REF!+#REF!+#REF!+#REF!+#REF!+#REF!+#REF! -> #REF! | DA11: =SUM(CU11:CZ11) -> #REF! | DB11: =+#REF!+#REF!+#REF!+#REF!+#REF!+#REF!+#REF!+#REF!+#REF!+#REF!+#REF!+#REF! -> #REF! | DC11: =+#REF!+#REF!+#REF!+#REF!+#REF!+#REF!+#REF!+#REF!+#REF!+#REF!+#REF!+#REF! -> #REF! | DD11: =+#REF!+#REF!+#REF!+#REF!+#REF!+#REF!+#REF!+#REF!+#REF!+#REF!+#REF!+#REF! -> #REF! | DE11: =+#REF!+#REF!+#REF!+#REF!+#REF!+#REF!+#REF!+#REF!+#REF!+#REF!+#REF!+#REF! -> #REF! | DF11: =+#REF!+#REF!+#REF!+#REF!+#REF!+#REF!+#REF!+#REF!+#REF!+#REF!+#REF!+#REF! -> #REF! | DG11: =+#REF!+#REF!+#REF!+#REF!+#REF!+#REF!+#REF!+#REF!+#REF!+#REF!+#REF!+#REF! -> #REF! | DH11: =SUM(DB11:DG11) -> #REF! | DI11: =+#REF!+#REF!+#REF!+#REF!+#REF!+#REF!+#REF!+#REF!+#REF!+#REF!+#REF!+#REF! -> #REF! | DJ11: =+#REF!+#REF!+#REF!+#REF!+#REF!+#REF!+#REF!+#REF!+#REF!+#REF!+#REF!+#REF! -> #REF! | DK11: =+#REF!+#REF!+#REF!+#REF!+#REF!+#REF!+#REF!+#REF!+#REF!+#REF!+#REF!+#REF! -> #REF! | DL11: =+#REF!+#REF!+#REF!+#REF!+#REF!+#REF!+#REF!+#REF!+#REF!+#REF!+#REF!+#REF! -> #REF! | DM11: =+#REF!+#REF!+#REF!+#REF!+#REF!+#REF!+#REF!+#REF!+#REF!+#REF!+#REF!+#REF! -> #REF! | DN11: =+#REF!+#REF!+#REF!+#REF!+#REF!+#REF!+#REF!+#REF!+#REF!+#REF!+#REF!+#REF! -> #REF! | DO11: =SUM(DI11:DN11) -> #REF! | DR11: =+ED11 -> #REF! | DS11: =+EK11 -> #REF! | DT11: =+ER11 -> #REF! | DU11: =SUM(DR11:DT11) -> #REF! | DX11: =+#REF!+#REF!+#REF!+#REF!+#REF!+#REF!+#REF!+#REF!+#REF!+#REF!+#REF!+#REF! -> #REF! | DY11: =+#REF!+#REF!+#REF!+#REF!+#REF!+#REF!+#REF!+#REF!+#REF!+#REF!+#REF!+#REF! -> #REF! | DZ11: =+#REF!+#REF!+#REF!+#REF!+#REF!+#REF!+#REF!+#REF!+#REF!+#REF!+#REF!+#REF! -> #REF! | EA11: =+#REF!+#REF!+#REF!+#REF!+#REF!+#REF!+#REF!+#REF!+#REF!+#REF!+#REF!+#REF! -> #REF! | EB11: =+#REF!+#REF!+#REF!+#REF!+#REF!+#REF!+#REF!+#REF!+#REF!+#REF!+#REF!+#REF! -> #REF! | EC11: =+#REF!+#REF!+#REF!+#REF!+#REF!+#REF!+#REF!+#REF!+#REF!+#REF!+#REF!+#REF! -> #REF! | ED11: =SUM(DX11:EC11) -> #REF! | EE11: =+#REF!+#REF!+#REF!+#REF!+#REF!+#REF!+#REF!+#REF!+#REF!+#REF!+#REF!+#REF! -> #REF! | EF11: =+#REF!+#REF!+#REF!+#REF!+#REF!+#REF!+#REF!+#REF!+#REF!+#REF!+#REF!+#REF! -> #REF! | EG11: =+#REF!+#REF!+#REF!+#REF!+#REF!+#REF!+#REF!+#REF!+#REF!+#REF!+#REF!+#REF! -> #REF! | EH11: =+#REF!+#REF!+#REF!+#REF!+#REF!+#REF!+#REF!+#REF!+#REF!+#REF!+#REF!+#REF! -> #REF! | EI11: =+#REF!+#REF!+#REF!+#REF!+#REF!+#REF!+#REF!+#REF!+#REF!+#REF!+#REF!+#REF! -> #REF! | EJ11: =+#REF!+#REF!+#REF!+#REF!+#REF!+#REF!+#REF!+#REF!+#REF!+#REF!+#REF!+#REF! -> #REF! | EK11: =SUM(EE11:EJ11) -> #REF! | EL11: =+#REF!+#REF!+#REF!+#REF!+#REF!+#REF!+#REF!+#REF!+#REF!+#REF!+#REF!+#REF! -> #REF! | EM11: =+#REF!+#REF!+#REF!+#REF!+#REF!+#REF!+#REF!+#REF!+#REF!+#REF!+#REF!+#REF! -> #REF! | EN11: =+#REF!+#REF!+#REF!+#REF!+#REF!+#REF!+#REF!+#REF!+#REF!+#REF!+#REF!+#REF! -> #REF! | EO11: =+#REF!+#REF!+#REF!+#REF!+#REF!+#REF!+#REF!+#REF!+#REF!+#REF!+#REF!+#REF! -> #REF! | EP11: =+#REF!+#REF!+#REF!+#REF!+#REF!+#REF!+#REF!+#REF!+#REF!+#REF!+#REF!+#REF! -> #REF! | EQ11: =+#REF!+#REF!+#REF!+#REF!+#REF!+#REF!+#REF!+#REF!+#REF!+#REF!+#REF!+#REF! -> #REF! | ER11: =SUM(EL11:EQ11) -> #REF! | EU11: =FQ11 -> #REF! | EV11: =+FZ11 -> #REF! | EW11: =+GI11 -> #REF! | EX11: =SUM(EU11:EW11) -> #REF! | FC11: =+#REF!+#REF!+#REF!+#REF!+#REF!+#REF!+#REF!+#REF!+#REF!+#REF!+#REF!+#REF! -> #REF! | FD11: =+#REF!+#REF!+#REF!+#REF!+#REF!+#REF!+#REF!+#REF!+#REF!+#REF!+#REF!+#REF! -> #REF! | FG11: =SUM(FC11:FF11) -> #REF! | FI11: =+#REF!+#REF!+#REF!+#REF!+#REF!+#REF!+#REF!+#REF!+#REF!+#REF!+#REF!+#REF! -> #REF! | FJ11: =+#REF!+#REF!+#REF!+#REF!+#REF!+#REF!+#REF!+#REF!+#REF!+#REF!+#REF!+#REF! -> #REF! | FK11: =+#REF!+#REF!+#REF!+#REF!+#REF!+#REF!+#REF!+#REF!+#REF!+#REF!+#REF!+#REF! -> #REF! | FL11: =+#REF!+#REF!+#REF!+#REF!+#REF!+#REF!+#REF!+#REF!+#REF!+#REF!+#REF!+#REF! -> #REF! | FM11: =+#REF!+#REF!+#REF!+#REF!+#REF!+#REF!+#REF!+#REF!+#REF!+#REF!+#REF!+#REF! -> #REF! | FN11: =+#REF!+#REF!+#REF!+#REF!+#REF!+#REF!+#REF!+#REF!+#REF!+#REF!+#REF!+#REF! -> #REF! | FO11: =+#REF!+#REF!+#REF!+#REF!+#REF!+#REF!+#REF!+#REF!+#REF!+#REF!+#REF!+#REF! -> #REF! | FP11: =+#REF!+#REF!+#REF!+#REF!+#REF!+#REF!+#REF!+#REF!+#REF!+#REF!+#REF!+#REF! -> #REF! | FQ11: =SUM(FI11:FP11) -> #REF! | FR11: =+#REF!+#REF!+#REF!+#REF!+#REF!+#REF!+#REF!+#REF!+#REF!+#REF!+#REF!+#REF! -> #REF! | FS11: =+#REF!+#REF!+#REF!+#REF!+#REF!+#REF!+#REF!+#REF!+#REF!+#REF!+#REF!+#REF! -> #REF! | FT11: =+#REF!+#REF!+#REF!+#REF!+#REF!+#REF!+#REF!+#REF!+#REF!+#REF!+#REF!+#REF! -> #REF! | FU11: =+#REF!+#REF!+#REF!+#REF!+#REF!+#REF!+#REF!+#REF!+#REF!+#REF!+#REF!+#REF! -> #REF! | FV11: =+#REF!+#REF!+#REF!+#REF!+#REF!+#REF!+#REF!+#REF!+#REF!+#REF!+#REF!+#REF! -> #REF! | FW11: =+#REF!+#REF!+#REF!+#REF!+#REF!+#REF!+#REF!+#REF!+#REF!+#REF!+#REF!+#REF! -> #REF! | FX11: =+#REF!+#REF!+#REF!+#REF!+#REF!+#REF!+#REF!+#REF!+#REF!+#REF!+#REF!+#REF! -> #REF! | FY11: =+#REF!+#REF!+#REF!+#REF!+#REF!+#REF!+#REF!+#REF!+#REF!+#REF!+#REF!+#REF! -> #REF! | FZ11: =SUM(FR11:FY11) -> #REF! | GA11: =+#REF!+#REF!+#REF!+#REF!+#REF!+#REF!+#REF!+#REF!+#REF!+#REF!+#REF!+#REF! -> #REF! | GB11: =+#REF!+#REF!+#REF!+#REF!+#REF!+#REF!+#REF!+#REF!+#REF!+#REF!+#REF!+#REF! -> #REF! | GC11: =+#REF!+#REF!+#REF!+#REF!+#REF!+#REF!+#REF!+#REF!+#REF!+#REF!+#REF!+#REF! -> #REF! | GD11: =+#REF!+#REF!+#REF!+#REF!+#REF!+#REF!+#REF!+#REF!+#REF!+#REF!+#REF!+#REF! -> #REF! | GE11: =+#REF!+#REF!+#REF!+#REF!+#REF!+#REF!+#REF!+#REF!+#REF!+#REF!+#REF!+#REF! -> #REF! | GF11: =+#REF!+#REF!+#REF!+#REF!+#REF!+#REF!+#REF!+#REF!+#REF!+#REF!+#REF!+#REF! -> #REF! | GG11: =+#REF!+#REF!+#REF!+#REF!+#REF!+#REF!+#REF!+#REF!+#REF!+#REF!+#REF!+#REF! -> #REF! | GH11: =+#REF!+#REF!+#REF!+#REF!+#REF!+#REF!+#REF!+#REF!+#REF!+#REF!+#REF!+#REF! -> #REF! | GI11: =SUM(GA11:GH11) -> #REF! | GL11: =+#REF!+#REF!+#REF!+#REF!+#REF!+#REF!+#REF!+#REF!+#REF!+#REF!+#REF!+#REF! -> #REF! | GM11: =+#REF!+#REF!+#REF!+#REF!+#REF!+#REF!+#REF!+#REF!+#REF!+#REF!+#REF!+#REF! -> #REF! | GN11: =+#REF!+#REF!+#REF!+#REF!+#REF!+#REF!+#REF!+#REF!+#REF!+#REF!+#REF!+#REF! -> #REF! | GO11: =+GL11+GN11+GM11 -> #REF! | IJ11: =SUM(IU11,JA11,JL11,JR11+JF11) -> #REF! | IK11: =SUM(IV11,JB11,JM11,JS11+JG11) -> #REF! | IL11: =SUM(IW11,JC11,JN11,JT11+JH11) -> #REF! | IM11: =SUM(IJ11:IL11) -> #REF! | IU11: =+#REF!+#REF!+#REF!+#REF!+#REF!+#REF!+#REF!+#REF!+#REF!+#REF!+#REF!+#REF! -> #REF! | IV11: =+#REF!+#REF!+#REF!+#REF!+#REF!+#REF!+#REF!+#REF!+#REF!+#REF!+#REF!+#REF! -> #REF! | IW11: =+#REF!+#REF!+#REF!+#REF!+#REF!+#REF!+#REF!+#REF!+#REF!+#REF!+#REF!+#REF! -> #REF! | IX11: =+#REF!+#REF!+#REF!+#REF!+#REF!+#REF!+#REF!+#REF!+#REF!+#REF!+#REF!+#REF! -> #REF! | IY11: =+#REF!+#REF!+#REF!+#REF!+#REF!+#REF!+#REF!+#REF!+#REF!+#REF!+#REF!+#REF! -> #REF! | IZ11: =SUM(IU11:IY11) -> #REF! | JA11: =+#REF!+#REF!+#REF!+#REF!+#REF!+#REF!+#REF!+#REF!+#REF!+#REF!+#REF!+#REF! -> #REF! | JB11: =+#REF!+#REF!+#REF!+#REF!+#REF!+#REF!+#REF!+#REF!+#REF!+#REF!+#REF!+#REF! -> #REF! | JC11: =+#REF!+#REF!+#REF!+#REF!+#REF!+#REF!+#REF!+#REF!+#REF!+#REF!+#REF!+#REF! -> #REF! | JD11: =+#REF!+#REF!+#REF!+#REF!+#REF!+#REF!+#REF!+#REF!+#REF!+#REF!+#REF!+#REF! -> #REF! | JE11: =+#REF!+#REF!+#REF!+#REF!+#REF!+#REF!+#REF!+#REF!+#REF!+#REF!+#REF!+#REF! -> #REF! | JF11: =+#REF!+#REF!+#REF!+#REF!+#REF!+#REF!+#REF!+#REF!+#REF!+#REF!+#REF!+#REF! -> #REF! | JG11: =+#REF!+#REF!+#REF!+#REF!+#REF!+#REF!+#REF!+#REF!+#REF!+#REF!+#REF!+#REF! -> #REF! | JH11: =+#REF!+#REF!+#REF!+#REF!+#REF!+#REF!+#REF!+#REF!+#REF!+#REF!+#REF!+#REF! -> #REF! | ... JJ11: =+#REF!+#REF!+#REF!+#REF!+#REF!+#REF!+#REF!+#REF!+#REF!+#REF!+#REF!+#REF! -> #REF! | JK11: =SUM(JF11:JJ11) -> #REF! | JL11: =+#REF!+#REF!+#REF!+#REF!+#REF!+#REF!+#REF!+#REF!+#REF!+#REF!+#REF!+#REF! -> #REF! | JM11: =+#REF!+#REF!+#REF!+#REF!+#REF!+#REF!+#REF!+#REF!+#REF!+#REF!+#REF!+#REF! -> #REF! | JN11: =+#REF!+#REF!+#REF!+#REF!+#REF!+#REF!+#REF!+#REF!+#REF!+#REF!+#REF!+#REF! -> #REF! | JO11: =+#REF!+#REF!+#REF!+#REF!+#REF!+#REF!+#REF!+#REF!+#REF!+#REF!+#REF!+#REF! -> #REF! | JP11: =+#REF!+#REF!+#REF!+#REF!+#REF!+#REF!+#REF!+#REF!+#REF!+#REF!+#REF!+#REF! -> #REF! | JQ11: =SUM(JL11:JP11) -> #REF! | JR11: =+#REF!+#REF!+#REF!+#REF!+#REF!+#REF!+#REF!+#REF!+#REF!+#REF!+#REF!+#REF! -> #REF! | JS11: =+#REF!+#REF!+#REF!+#REF!+#REF!+#REF!+#REF!+#REF!+#REF!+#REF!+#REF!+#REF! -> #REF! | JT11: =+#REF!+#REF!+#REF!+#REF!+#REF!+#REF!+#REF!+#REF!+#REF!+#REF!+#REF!+#REF! -> #REF! | JU11: =+#REF!+#REF!+#REF!+#REF!+#REF!+#REF!+#REF!+#REF!+#REF!+#REF!+#REF!+#REF! -> #REF! | JV11: =+#REF!+#REF!+#REF!+#REF!+#REF!+#REF!+#REF!+#REF!+#REF!+#REF!+#REF!+#REF! -> #REF! | JW11: =SUM(JR11:JV11) -> #REF! | JZ11: =+KH11 -> #REF! | KA11: =+SUM(KO11,KV11,LC11,LJ11,LQ11) -> #REF! | KB11: =+LW11 -> #REF! | KC11: =+KC10+MC11-FP11 -> #REF! | KE11: =+KE10+GL11-IJ11 -> #REF! | KF11: =+KF10+GM11-IK11 -> #REF! | KG11: =+KG10+GN11-IL11 -> #REF! | KH11: =SUM(KE11:KG11) -> #REF! | KI11: =+KI10+DB11-FI11 -> #REF! | KJ11: =+KJ10-FJ11 -> #REF! | KK11: =+KK10-FK11 -> #REF! | KL11: =+KL10-FL11 -> #REF! | KM11: =+KM10-FM11 -> #REF! | KN11: =+KN10-FN11 -> #REF! | KO11: =SUM(KI11:KN11) -> #REF! | KP11: =+KP10+CN11+EE11+EL11-FR11 -> #REF! | KQ11: =+KQ10+CO11+EF11+EM11-FS11 -> #REF! | KR11: =+KR10+CP11+EG11+EN11-FT11 -> #REF! | KS11: =+KS10+CQ11+EH11+EO11-FU11 -> #REF! | KT11: =+KT10+CR11+EI11+EP11-FV11 -> #REF! | KU11: =+KU10+CS11+EJ11+EQ11-FW11 -> #REF! | KV11: =SUM(KP11:KU11) -> #REF! | KW11: =+KW10+CU11+DX11-GA11 -> #REF! | KX11: =+KX10+CV11+DY11-GB11 -> #REF! | KY11: =+KY10+CW11+DZ11-GC11 -> #REF! | KZ11: =+KZ10+CX11+EA11-GD11 -> #REF! | LA11: =+LA10+CY11+EB11-GE11 -> #REF! | LB11: =+LB10+CZ11+EC11-GF11 -> #REF! | LC11: =SUM(KW11:LB11) -> #REF! | LJ11: =SUM(LD11:LI11) -> 0 | LK11: =+LK10+DI11-EL11 -> #REF! | LL11: =+LL10+DJ11-EM11 -> #REF! | LM11: =+LM10+DK11-EN11 -> #REF! | LN11: =+LN10+DL11-EO11 -> #REF! | LO11: =+LO10+DM11-EP11 -> #REF! | LP11: =+LP10+DN11-EQ11 -> #REF! | LQ11: =SUM(LK11:LP11) -> #REF! | LT11: =+#REF!+#REF!+#REF!+#REF!+#REF!+#REF!+#REF!+#REF!+#REF!+#REF!+#REF!+#REF! -> #REF! | LU11: =+#REF!+#REF!+#REF!+#REF!+#REF!+#REF!+#REF!+#REF!+#REF!+#REF!+#REF!+#REF! -> #REF! | LV11: =+FO11 -> #REF! | LW11: =+LW10+LU11-LV11 -> #REF! | MA11: =+#REF!+#REF!+#REF!+#REF!+#REF!+#REF!+#REF!+#REF!+#REF!+#REF!+#REF!+#REF! -> #REF! | MB11: =+LT11 -> #REF! | MC11: =+#REF!+#REF!+#REF!+#REF!+#REF!+#REF!+#REF!+#REF!+#REF!+#REF!+#REF!+#REF! -> #REF! | MD11: =+FP11+FY11+GH11 -> #REF! | ME11: =+ME10+MA11-MB11-MC11-MD11 -> #REF! | MI11: =IF(GL11=0,"",(IFERROR(IF(1-ABS(1-(GR11/GR$43))<0,0,1-ABS(1-(GR11/GR$43))),0)*GR$43)+(IFERROR(IF(1-ABS(1-(GS11/GS$43))<0,0,1-ABS(1-(GS11/GS$43))),0)*GS$43)+(IFERROR(IF(1-ABS(1-(GT11/GT$43))<0,0,1-ABS(1-(GT11/GT$43))),0)*GT$43)+(IFERROR(IF(1-ABS(1-(GU11/GU$43))<0,0,1-ABS(1-(GU11/GU$43))),0)*GU$43)+(IFERROR(IF(1-ABS(1-(GV11/GV$43))<0,0,1-ABS(1-(GV11/GV$43))),0)*GV$43)+(IFERROR(IF(1-ABS(1-(GW11/GW$43))<0,0,1-ABS(1-(GW11/GW$43))),0)*GW$43)+(IFERROR(IF(1-ABS(1-(GX11/GX$43))<0,0,1-ABS(1-(GX11/GX$43))),0)*GX$43)+(IFERROR(IF(1-ABS(1-(GY11/GY$43))<0,0,1-ABS(1-(GY11/GY$43))),0)*GY$43)) -> #REF! | MJ11: =IF(GN11=0,"",(IFERROR(IF(1-ABS(1-(HH11/HH$43))<0,0,1-ABS(1-(HH11/HH$43))),0)*HH$43)+(IFERROR(IF(1-ABS(1-(HI11/HI$43))<0,0,1-ABS(1-(HI11/HI$43))),0)*HI$43)+(IFERROR(IF(1-ABS(1-(HJ11/HJ$43))<0,0,1-ABS(1-(HJ11/HJ$43))),0)*HJ$43)+(IFERROR(IF(1-ABS(1-(HK11/HK$43))<0,0,1-ABS(1-(HK11/HK$43))),0)*HK$43)+(IFERROR(IF(1-ABS(1-(HL11/HL$43))<0,0,1-ABS(1-(HL11/HL$43))),0)*HL$43)+(IFERROR(IF(1-ABS(1-(HM11/HM$43))<0,0,1-ABS(1-(HM11/HM$43))),0)*HM$43)+(IFERROR(IF(1-ABS(1-(HN11/HN$43))<0,0,1-ABS(1-(HN11/HN$43))),0)*HN$43)+(IFERROR(IF(1-ABS(1-(HO11/HO$43))<0,0,1-ABS(1-(HO11/HO$43))),0)*HO$43)) -> #REF! | ML11: =IF(GO11>0,SUMPRODUCT(MO11:MT11,$GR$43:$GW$43),"") -> #REF! | MM11: =IF(GO11>0,SUMPRODUCT(MV11:NA11,$HH$43:$HM$43),"") -> #REF! | MO11: =IF(KP$43=0,0,IF(SUM(KP11,KW11)-KP$8-KW$8>KP$43,1,(SUM(KP11,KW11)-KP$8-KW$8)/KP$43)) -> 0 | MP11: =IF(KQ$43=0,0,IF(SUM(KQ11,KX11)-KQ$8-KX$8>KQ$43,1,(SUM(KQ11,KX11)-KQ$8-KX$8)/KQ$43)) -> 0 | MQ11: =IF(KR$43=0,0,IF(SUM(KR11,KY11)-KR$8-KY$8>KR$43,1,(SUM(KR11,KY11)-KR$8-KY$8)/KR$43)) -> 0 | MR11: =IF(KS$43=0,0,IF(SUM(KS11,KZ11)-KS$8-KZ$8>KS$43,1,(SUM(KS11,KZ11)-KS$8-KZ$8)/KS$43)) -> 0 | MS11: =IF(KT$43=0,0,IF(SUM(KT11,LA11)-KT$8-LA$8>KT$43,1,(SUM(KT11,LA11)-KT$8-LA$8)/KT$43)) -> 0 | MT11: =IF(KU$43=0,0,IF(SUM(KU11,LB11)-KU$8-LB$8>KU$43,1,(SUM(KU11,LB11)-KU$8-LB$8)/KU$43)) -> 0 | MV11: =+IF(KP$43=0,0,IF(SUM(KP11,KW11)-KP$8-KW$8>KP$43,1,(SUM(KP11,KW11)-KP$8-KW$8)/KP$43)) -> 0 | MW11: =+IF(KQ$43=0,0,IF(SUM(KQ11,KX11)-KQ$8-KX$8>KQ$43,1,(SUM(KQ11,KX11)-KQ$8-KX$8)/KQ$43)) -> 0 | MX11: =+IF(KR$43=0,0,IF(SUM(KR11,KY11)-KR$8-KY$8>KR$43,1,(SUM(KR11,KY11)-KR$8-KY$8)/KR$43)) -> 0 | MY11: =+IF(KS$43=0,0,IF(SUM(KS11,KZ11)-KS$8-KZ$8>KS$43,1,(SUM(KS11,KZ11)-KS$8-KZ$8)/KS$43)) -> 0 | MZ11: =+IF(KT$43=0,0,IF(SUM(KT11,LA11)-KT$8-LA$8>KT$43,1,(SUM(KT11,LA11)-KT$8-LA$8)/KT$43)) -> 0 | NA11: =+IF(KU$43=0,0,IF(SUM(KU11,LB11)-KU$8-LB$8>KU$43,1,(SUM(KU11,LB11)-KU$8-LB$8)/KU$43)) -> 0
