Workbook
Name _1A1_Z1...A10_Z10: #REF!
Name _1A1_Z1...A10_Z10: #REF!
Name _Apr: [1]Validation!$A$33
Name _Aug: [1]Validation!$A$37
Name _Chubu1: [1]Validation!$A$5
Name _Chubu2: [1]Validation!$A$6
Name _Chubu3: [1]Validation!$A$7
Name _ChubuP1: [1]Chubu!$V$203
Name _ChubuP2: [1]Chubu!$V$204
Name _CLP: [1]Validation!$A$17
Name _CLPP1: [1]CLP!$V$203
Name _CLPP2: [1]CLP!$V$204
Name _DATE: #REF!
Name _Dec: [1]Validation!$A$41
Name _ENEL1: [1]Validation!$A$11
Name _ENELP1: '[1]Enel '!$V$264
Name _ENELP2: '[1]Enel '!$V$265
Name _EPDC: [1]Validation!$A$8
Name _EPDCP1: [1]EPDC!$V$203
Name _EPDCP2: [1]EPDC!$V$204
Name _Feb: [1]Validation!$A$31
Name _ffggggg: #REF!
Name _ffggggg: #REF!
Name _Formosa1: [1]Validation!$A$15
Name _Formosa2: [1]Validation!$A$16
Name _FORMOSAP1: [1]Formosa!$V$264
Name _FORMOSAP2: [1]Formosa!$V$265
Name _fs1: #REF!
Name _fs1: #REF!
Name _HEK1: [1]Validation!$A$20
Name _HEK2: [1]Validation!$A$21
Name _HEKP1: [1]HEK!$V$203
Name _HEKP2: [1]HEK!$V$204
Name _Huaneng1: [1]Validation!$A$18
Name _Huaneng2: [1]Validation!$A$19
Name _HUANP1: [1]Huaneng!$V$394
Name _HUANP2: [1]Huaneng!$V$395
Name _Jan: [1]Validation!$A$30
Name _Jul: [1]Validation!$A$36
Name _Jun: [1]Validation!$A$35
Name _Kobe: [1]Validation!$A$9
Name _KOBEP1: '[1]Kobe Steel'!$V$264
Name _KOBEP2: '[1]Kobe Steel'!$V$265
Name _Kospo: [1]Validation!$A$13
Name _KOSPOP1: [1]Kospo!$V$203
Name _KOSPOP2: [1]Kospo!$V$204
Name _Kowepo: [1]Validation!$A$14
Name _KOWEPOP1: [1]Kowepo!$V$264
Name _KOWEPOP2: [1]Kowepo!$V$265
Name _Mar: [1]Validation!$A$32
Name _May: [1]Validation!$A$34
Name _Nov: [1]Validation!$A$40
Name _Oct: [1]Validation!$A$39
Name _Sep: [1]Validation!$A$38
Name _SHIKOKUP1: [1]Shikoku!$V$203
Name _SHIKOKUP2: [1]Shikoku!$V$204
Name _Tirreno: [1]Validation!$A$12
Name _TIRRENOP1: [1]Tirreno!$V$264
Name _TIRRENOP2: [1]Tirreno!$V$265
Name _TJB1: [1]Validation!$A$22

Sheet Dashboard
AR6: Yearly | AS6: Actual
AR7: OB | AS7: =Summary!Q4/Summary!W4 -> 0.56133572 | AT7: =1-AS7 -> 0.43866428 | AV7: =G53/AW7 -> #DIV/0! | AW7: 0 | AX7: OB PIT 1
E8: Date | G8: MTD | L8: Total Month | Q8: Total Year to Date | AR8: ROM | AS8: =Summary!Q5/Summary!W5 -> 0.47572084 | AT8: =1-AS8 -> 0.52427916 | AV8: =G54/AW8 -> 0 | AW8: =Outlook!I4 -> 900253.65 | AX8: OB PIT 1
E9: =Summary!D3 -> 07-Sep-26 | AR9: FC | AS9: =Summary!Q9/Summary!W9 -> 0.44249128 | AT9: =1-AS9 -> 0.55750872 | AV9: =G56/AW9 -> #DIV/0! | AW9: 0 | AX9: ROM PIT 1
E10: Actual | G10: Actual | I10: Plan | K10: % Diff | M10: Outlook | O10: Budget | Q10: Actual | S10: Budget | AR10: Loading | AS10: =Summary!Q10/Summary!W10 -> 0.42703864 | AT10: =1-AS10 -> 0.57296136 | AV10: =G57/AW10 -> 0 | AW10: =Summary!J5 -> 158000 | AX10: ROM PIT 1
C12: OB (BCM) | E12: =Summary!$D$4 -> 36570.75 | G12: =Summary!E4 -> 238442.25 | I12: =Summary!F4 -> 190166.67 | K12: =IF(I12<=0,0,(G12-I12)/I12) -> 0.25385933 | M12: =Summary!J4 -> 815000 | O12: =Summary!K4 -> 1100000 | Q12: =+Summary!Q4 -> 6651828.3 | S12: =+Summary!T4 -> 8161666.7
C14: ROM (TON) | E14: =Summary!D5 -> 0 | G14: =Summary!E5 -> 1312.898 | I14: =Summary!F5 -> 36866.667 | K14: =IF(I14<=0,0,(G14-I14)/I14) -> -0.96438794 | M14: =Summary!J5 -> 158000 | O14: =Summary!K5 -> 163800 | Q14: =+Summary!Q5 -> 1427162.5 | S14: =+Summary!T5 -> 1944420 | AR14: Monthly
C16: SR (BCM/TON) | E16: =IF(OR(E12=0,E14=0),0,E12/E14) -> 0 | G16: =IF(OR(G12=0,G14=0),0,G12/G14) -> 181.61521 | I16: =IF(OR(I12=0,I14=0),0,I12/I14) -> 5.1582278 | K16: =IF(I16<=0,0,(G16-I16)/I16) -> 34.208839 | M16: =IF(OR(M12=0,M14=0),0,M12/M14) -> 5.1582278 | O16: =IF(OR(O12=0,O14=0),0,O12/O14) -> 6.7155067 | Q16: =IF(OR(Q12=0,Q14=0),0,Q12/Q14) -> 4.6608765 | S16: =IF(OR(S12=0,S14=0),0,S12/S14) -> 4.1974813 | AR16: OB | AS16: =G12/M12 -> 0.29256718 | AT16: =IF(1-AS16<0,0,AU16) -> 0.70743282 | AU16: =1-AS16 -> 0.70743282
C18: Outpit (BCM) | E18: =Summary!D7 -> 0 | G18: =Summary!E7 -> 3307.5 | I18: =Summary!F7 -> 0 | K18: =IF(I18<=0,0,(G18-I18)/I18) -> 0 | M18: =Summary!J7 -> 0 | O18: =Summary!K7 -> 0 | Q18: =+Summary!Q7 -> 12561.687 | S18: =+Summary!T7 -> 0 | AR18: FC | AS18: =G20/M20 -> 0 | AT18: =IF(1-AS18<0,0,AU18) -> 1 | AU18: =1-AS18 -> 1
C20: FC (TON) | E20: =Summary!D9 -> 0 | G20: =Summary!E9 -> 0 | I20: =Summary!F9 -> 37333.333 | K20: =IF(I20<=0,0,(G20-I20)/I20) -> -1 | M20: =Summary!J9 -> 160000 | O20: =Summary!K9 -> 170000 | Q20: =+Summary!Q9 -> 1349598.4 | S20: =+Summary!T9 -> 1884666.7 | AR20: ROM | AS20: =G14/M14 -> 0.008309481 | AT20: =IF(1-AS20<0,0,AU20) -> 0.99169052 | AU20: =1-AS20 -> 0.99169052
C22: FC LOAD (TON) | E22: =Summary!D10 -> 0 | G22: =Summary!E10 -> 0 | I22: =Summary!F10 -> 40833.333 | K22: =IF(I22<=0,0,(G22-I22)/I22) -> -1 | M22: =Summary!J10 -> 175000 | O22: =Summary!K10 -> 170000 | Q22: =+Summary!Q10 -> 1298197.5 | S22: =+Summary!T10 -> 1867166.7 | AR22: Coal Loading | AS22: =+G22/M22 -> 0 | AT22: =IF(1-AS22<0,0,AU22) -> 1 | AU22: =1-AS22 -> 1
C24: ROM STOCK (TON) | E24: =Summary!D8 -> 158177.17 | G24: =Summary!E8 -> 158177.17 | I24: =Summary!F8 -> 157816.36 | K24: =IF(I24<=0,0,(G24-I24)/I24) -> 0.00228629 | M24: =Summary!J8 -> 154864.27 | O24: =Summary!K8 -> 213183.93 | Q24: =+Summary!Q8 -> 158177.17 | S24: =+Summary!T8 -> 213183.93 | AR24: Road to Bonus Q1
C26: FC STOCK (TON) | E26: =Summary!D11 -> 53492.115 | G26: =Summary!E11 -> 53492.115 | I26: =Summary!F11 -> 49712.625 | K26: =IF(I26<=0,0,(G26-I26)/I26) -> 0.076026766 | M26: =Summary!J11 -> 38492.115 | O26: =Summary!K11 -> 84984.685 | Q26: =+Summary!Q11 -> 53492.115 | S26: =+Summary!T11 -> 84984.685 | AR26: ROM Prod | AS26: =Summary!O5 -> 483800 | AT26: =Summary!M5 -> 349194.85 | AU26: =AT26/AS26 -> 0.72177521 | AV26: =1-AU26 -> 0.27822479
C28: OB DISTANCE (KM) | E28: =Summary!D13 -> 1.0845163 | G28: =Summary!E13 -> 1.1029475 | I28: =Summary!F13 -> 1.25 | K28: =IF(I28<=0,0,(G28-I28)/I28) -> -0.11764201 | M28: =Summary!J13 -> 1.25 | O28: =Summary!K13 -> 1.2 | Q28: =+Summary!Q13 -> 0.75680776 | S28: =+Summary!T13 -> 1.2946992 | AR28: Coal Loading | AS28: =Summary!O10 -> 410000 | AT28: =+Summary!M10 -> 172530.37 | AU28: =AT28/AS28 -> 0.42080578 | AV28: =1-AU28 -> 0.57919422
C30: ROM DISTANCE (KM) | E30: =Summary!D14 -> 0 | G30: =Summary!E14 -> 12.908824 | I30: =Summary!F14 -> 13.75 | K30: =IF(I30<=0,0,(G30-I30)/I30) -> -0.061176436 | M30: =Summary!J14 -> 13.75 | O30: =Summary!K14 -> 14.25 | Q30: =+Summary!Q14 -> 10.478818 | S30: =+Summary!T14 -> 14.663126 | AR30: OB | AS30: =Summary!O4 -> 3270000 | AT30: =+Summary!M4 -> 2220016.2 | AU30: =AT30/AS30 -> 0.67890404 | AV30: =1-AU30 -> 0.32109596
AR33: FC Production | AS33: =+Summary!O9 -> 475000 | AT33: =Summary!M9 -> 208993.46 | AU33: =AT33/AS33 -> 0.43998622 | AV33: =1-AU33 -> 0.56001378
E34: WEATHER
C36: Rainfall (mm) | E36: =Summary!D15 -> 0 | G36: =Summary!E15 -> 0 | I36: =Summary!F15 -> 71.633333 | K36: =IF(I36<=0,0,(G36-I36)/I36) -> -1 | M36: =Summary!J15 -> 307 | O36: =Summary!K15 -> 307.22502 | Q36: =+Summary!Q15 -> 2833.87 | S36: =+Summary!T15 -> 3103.6393
C38: Rain Duration (hrs) | E38: =Summary!D16 -> 0 | G38: =Summary!E16 -> 0 | I38: =Summary!F16 -> 17.266667 | K38: =IF(I38<=0,0,(G38-I38)/I38) -> -1 | M38: =Summary!J16 -> 74 | O38: =Summary!K16 -> 71.422388 | Q38: =+Summary!Q16 -> 609.52 | S38: =+Summary!T16 -> 626.58836
C40: Slippery (hrs) | E40: =Summary!D17 -> 0 | G40: =Summary!E17 -> 0 | I40: =Summary!F17 -> 5.1333333 | K40: =IF(I40<=0,0,(G40-I40)/I40) -> -1 | M40: =Summary!J17 -> 22 | O40: =Summary!K17 -> 24.283612 | Q40: =+Summary!Q17 -> 178.6 | S40: =+Summary!T17 -> 213.04004
AR42: Weather | AU42: 3
E43: Contractor Performance
D44: OB REMOVAL | I44: COAL GETTING | AR44: Main Equipment Performance | AV44: Number,PA, UA, Productivity
AR45: Support Equipment Performance | AU45: 1 | AV45: Lack of Operator
AR46: Sliding | AV46: Long Distance
E47: Today | G47: MTD | I47: Achievement | L47: % Progress | AR47: Blockade | AU47: 1.5 | AV47: Working area
AR48: Road Condition | AU48: 1 | AV48: Crowded
AR49: hauling Road Condition | AU49: 1
D50: =+MAX(VLOOKUP($E$9,'Equipment '!$A$3:$U$36,4,FALSE),VLOOKUP(Dashboard!$E$9,'Equipment '!$A$3:$U$36,14,FALSE)) -> 13.925 | E50: =+MAX(VLOOKUP($E$9,'Equipment '!$A$3:$U$36,5,FALSE),VLOOKUP(Dashboard!$E$9,'Equipment '!$A$3:$U$36,15,FALSE)) -> 1.7583333 | G50: =+MAX(VLOOKUP($E$9,'Equipment '!$A$3:$U$36,2,FALSE),VLOOKUP(Dashboard!$E$9,'Equipment '!$A$3:$U$36,12,FALSE)) -> 4.5583333 | I50: =+MAX(VLOOKUP($E$9,'Equipment '!$A$3:$U$36,7,FALSE),VLOOKUP(Dashboard!$E$9,'Equipment '!$A$3:$U$36,17,FALSE)) -> 0 | K50: =+MAX(VLOOKUP($E$9,'Equipment '!$A$3:$U$36,6,FALSE),VLOOKUP(Dashboard!$E$9,'Equipment '!$A$3:$U$36,16,FALSE)) -> 0
AR51: - Idle activity in Pit by rain & slippery from 6:00 AM till 1:00 PM & from 12:15 AM till 2:00 AM
AR52: - Idle activity in hauling road by rain & slippery from 6:00 AM till 1:00 PM & from 12:15 AM till 2:00 AM
AR53: -SLS coal winning data has been updated
AF65: =13*31 -> 403
O67: Remark
O69: - No barging activity, waiting for the update loading plan and a rise in the WL downstream.
O70: - No coal hauling & crushing activity due to full stock in ROM - PSY area
O71: - Water level Port 4.90m
O74: ROM Stock | P74: Quantity (KTon) | R74: Quality
R75: CV (gar) | T75: Sulfur (adb) | V75: Ash (adb) | X75: TM (%)
O76: ROM 1 GRA | Q76: ='Quality ROM'!B105/1000 -> 98.828664 | S76: ='Quality ROM'!H105 -> 3731.4194 | T76: ='Production per Tunnel'!P4 -> 0.11220513 | U76: ='Quality ROM'!F105 -> 0.14 | V76: ='Production per Tunnel'!O4 -> 9.0914359 | W76: ='Quality ROM'!E105 -> 7.3742857 | X76: ='Production per Tunnel'!M4 -> 39.846068 | Y76: ='Quality ROM'!C105 -> 39.012857
...

Sheet Summary
D2: Yesterday | E2: =MID(Actual!C2,13,6) -> Sep'26 | J2: Total Month | M2: Quarterly 3 | Q2: YTD | V2: Total Year
D3: 07-Sep-26 | E3: MTD | F3: Outlook | G3: %Diff | H3: Budget | I3: =G3 -> %Diff | J3: Outlook | K3: Budget | L3: %Diff | M3: Actual | N3: Outlook | O3: Budget | P3: %Diff | Q3: Actual | R3: Outlook | S3: =G3 -> %Diff | T3: =H3 -> Budget | U3: =G3 -> %Diff | V3: Act + Outlook | W3: =H3 -> Budget | X3: %Diff | AA3: Road to 2 Mil
B4: OB | C4: BCM | D4: =Actual!AL34 -> 36570.75 | E4: =SUM(Actual!F28:AJ32) -> 238442.25 | F4: =((HLOOKUP(E$2,Outlook!$F$3:$Q$31,MATCH(B4,Outlook!$B$3:$B$31,0),FALSE))/Actual!E3)*(MID(D$3,1,2)) -> 190166.67 | G4: =IF(F4<=0,0,(E4-F4)/F4) -> 0.25385933 | H4: =((HLOOKUP(E$2,Budget!$E$3:$P$18,MATCH(B4,Budget!$B$3:$B$18,0),FALSE))/Actual!$E$3)*(MID(D$3,1,2)) -> 256666.67 | I4: =IF(H4<=0,0,(E4-H4)/H4) -> -0.071004221 | J4: =(HLOOKUP(E$2,Outlook!$F$3:$Q$31,MATCH(B4,Outlook!$B$3:$B$31,0),FALSE)) -> 815000 | K4: =HLOOKUP(E$2,Budget!$E$3:$P$18,MATCH(B4,Budget!$B$3:$B$18,0),FALSE) -> 1100000 | L4: =IF(K4<=0,0,(J4-K4)/K4) -> -0.25909091 | M4: =(SUMIF(Outlook!$L$2:$N$2,"actual",Outlook!$L$4:$N$4))+E4 -> 2220016.2 | N4: =+Outlook!N36 -> 2796573.9 | O4: =+Budget!M19 -> 3270000 | P4: =IF(O4<=0,0,(M4-O4)/O4) -> -0.32109596 | Q4: =(SUMIF(Outlook!$F$2:$Q$2,"actual",Outlook!$F$4:$Q$4))+$E$4 -> 6651828.3 | R4: =(SUMIF(Outlook!$F$2:$Q$2,"ACTUAL",Outlook!F4:Q4))+F4 -> 6603552.7 | S4: =IF(R4<=0,0,(Q4-R4)/R4) -> 0.0073105471 | T4: =(SUMIF(Budget!$E$2:$P$2,"PLANED",Budget!E4:P4))+H4 -> 8161666.7 | U4: =IF(T4<=0,0,(Q4-T4)/T4) -> -0.18499143 | V4: =Outlook!R4 -> 9650000 | W4: =Budget!Q4 -> 11850000 | X4: =IF(W4<=0,0,(V4-W4)/W4) -> -0.18565401
B5: ROM | C5: Ton | D5: =Actual!AL109 -> 0 | E5: =SUM(Actual!F109:AJ109) -> 1312.898 | F5: ='Graphic Production'!AI9 -> 36866.667 | G5: =IF(F5<=0,0,(E5-F5)/F5) -> -0.96438794 | H5: =((HLOOKUP(E$2,Budget!$E$3:$P$18,MATCH(B5,Budget!$B$3:$B$18,0),FALSE))/Actual!$E$3)*(MID(D$3,1,2)) -> 38220 | I5: =IF(H5<=0,0,(E5-H5)/H5) -> -0.96564893 | J5: =(HLOOKUP(E$2,Outlook!$F$3:$Q$31,MATCH(B5,Outlook!$B$3:$B$31,0),FALSE)) -> 158000 | K5: =HLOOKUP(E$2,Budget!$E$3:$P$18,MATCH(B5,Budget!$B$3:$B$18,0),FALSE) -> 163800 | L5: =IF(K5<=0,0,(J5-K5)/K5) -> -0.035409035 | M5: =(SUMIF(Outlook!$L$2:$N$2,"actual",Outlook!$L$5:$N$5))+$E$5 -> 349194.85 | N5: =+Outlook!N37 -> 505881.95 | O5: =+Budget!M20 -> 483800 | P5: =IF(O5<=0,0,(M5-O5)/O5) -> -0.27822479 | Q5: =(SUMIF(Outlook!$F$2:$Q$2,"actual",Outlook!$F$5:$Q$5))+$E$5 -> 1427162.5 | R5: =(SUMIF(Outlook!$F$2:$Q$2,"ACTUAL",Outlook!F5:Q5))+F5 -> 1462716.3 | S5: =IF(R5<=0,0,(Q5-R5)/R5) -> -0.024306674 | T5: =(SUMIF(Budget!$E$2:$P$2,"PLANED",Budget!E5:P5))+H5 -> 1944420 | U5: =IF(T5<=0,0,(Q5-T5)/T5) -> -0.26602147 | V5: =Outlook!R5 -> 2699999.6 | W5: =Budget!Q5 -> 3000000 | X5: =IF(W5<=0,0,(V5-W5)/W5) -> -0.10000012 | Z5: =+W5-Q5 -> 1572837.5 | AA5: =2000000-Q5 -> 572837.47 | AB5: =+AA5/6200 -> 92.39314 | AC5: days | AD5: =+Z5/6200 -> 253.68346
B6: SR | C6: BCM/Ton | D6: =IF(OR(D4=0,D5=0),0,D4/D5) -> 0 | E6: =IF(OR(E4=0,E5=0),0,E4/E5) -> 181.61521 | F6: =IF(OR(F4=0,F5=0),0,F4/F5) -> 5.1582278 | G6: =IF(F6<=0,0,(E6-F6)/F6) -> 34.208839 | H6: =IF(OR(H4=0,H5=0),0,H4/H5) -> 6.7155067 | I6: =IF(H6<=0,0,(E6-H6)/H6) -> 26.044156 | J6: =IF(OR(J4=0,J5=0),0,J4/J5) -> 5.1582278 | K6: =IF(OR(K4=0,K5=0),0,K4/K5) -> 6.7155067 | L6: =IF(K6<=0,0,(J6-K6)/K6) -> -0.23189298 | M6: =IF(OR(M4=0,M5=0),0,M4/M5) -> 6.3575285 | N6: =IF(OR(N4=0,N5=0),0,N4/N5) -> 5.5281157 | O6: =IF(OR(O4=0,O5=0),0,O4/O5) -> 6.7589913 | P6: =IF(O6<=0,0,(M6-O6)/O6) -> -0.059396855 | Q6: =IF(OR(Q4=0,Q5=0),0,Q4/Q5) -> 4.6608765 | R6: =IF(OR(R4=0,R5=0),0,R4/R5) -> 4.514582 | S6: =IF(R6<=0,0,(Q6-R6)/R6) -> 0.032404876 | T6: =IF(OR(T4=0,T5=0),0,T4/T5) -> 4.1974813 | U6: =IF(T6<=0,0,(Q6-T6)/T6) -> 0.11039838 | V6: =IF(OR(V4=0,V5=0),0,V4/V5) -> 3.5740746 | W6: =IF(OR(W4=0,W5=0),0,W4/W5) -> 3.95 | X6: =IF(W6<=0,0,(V6-W6)/W6) -> -0.095170998
B7: Outpit | C7: BCM | D7: =Actual!AL14 -> 0 | E7: =SUM(Actual!F10:AJ14) -> 3307.5 | F7: =((HLOOKUP(E$2,Outlook!$F$3:$Q$31,MATCH(B7,Outlook!$B$3:$B$31,0),FALSE))/Actual!E3)*(MID(D$3,1,2)) -> 0 | G7: =IF(F7<=0,0,(E7-F7)/F7) -> 0 | H7: =((HLOOKUP(E$2,Budget!$E$3:$P$18,MATCH(B7,Budget!$B$3:$B$18,0),FALSE))/Actual!$E$3)*(MID(D$3,1,2)) -> 0 | I7: =IF(H7<=0,0,(E7-H7)/H7) -> 0 | J7: =(HLOOKUP(E$2,Outlook!$F$3:$Q$31,MATCH(B7,Outlook!$B$3:$B$31,0),FALSE)) -> 0 | K7: =HLOOKUP(E$2,Budget!$E$3:$P$18,MATCH(B7,Budget!$B$3:$B$18,0),FALSE) -> 0 | L7: =IF(K7<=0,0,(J7-K7)/K7) -> 0 | M7: =(SUMIF(Outlook!$F$2:$H$2,"actual",Outlook!$F$7:$H$7))+E7 -> 3307.5 | N7: =SUM(Outlook!F7:H7) -> 0 | O7: =SUM(Budget!E7:G7) -> 0 | P7: =IF(O7<=0,0,(M7-O7)/O7) -> 0 | Q7: =(SUMIF(Outlook!$F$2:$Q$2,"actual",Outlook!$F$7:$Q$7))+E7 -> 12561.687 | R7: =(SUMIF(Outlook!$F$2:$Q$2,"ACTUAL",Outlook!F7:Q7))+F7 -> 9254.187 | S7: =IF(R7<=0,0,(Q7-R7)/R7) -> 0.35740579 | T7: =(SUMIF(Budget!$E$2:$P$2,"PLANED",Budget!E7:P7))+H7 -> 0 | U7: =IF(T7<=0,0,(Q7-T7)/T7) -> 0 | V7: =Outlook!R7 -> 9254.187 | W7: =Budget!Q7 -> 0 | X7: =IF(W7<=0,0,(V7-W7)/W7) -> 0
B8: ROM Stock | C8: Ton | D8: =Actual!AL158 -> 158177.17 | E8: =Actual!AL158 -> 158177.17 | F8: ='Graphic Production'!AI11 -> 157816.36 | G8: =IF(F8<=0,0,(E8-F8)/F8) -> 0.00228629 | H8: =(HLOOKUP(E$2,Budget!$E$3:$P$18,MATCH(B8,Budget!$B$3:$B$18,0),FALSE)) -> 213183.93 | I8: =IF(H8<=0,0,(E8-H8)/H8) -> -0.25802489 | J8: =(HLOOKUP(E$2,Outlook!$F$3:$Q$31,MATCH(B8,Outlook!$B$3:$B$31,0),FALSE)) -> 154864.27 | K8: =HLOOKUP(E$2,Budget!$E$3:$P$18,MATCH(B8,Budget!$B$3:$B$18,0),FALSE) -> 213183.93 | L8: =IF(K8<=0,0,(J8-K8)/K8) -> -0.27356499 | M8: =Actual!AL158 -> 158177.17 | N8: =+Outlook!N8 -> 154864.27 | O8: =+Budget!M8 -> 213183.93 | P8: =IF(O8<=0,0,(M8-O8)/O8) -> -0.25802489 | Q8: =Actual!AL158 -> 158177.17 | R8: =(HLOOKUP(E$2,Outlook!$F$3:$Q$31,MATCH(B8,Outlook!$B$3:$B$31,0),FALSE)) -> 154864.27 | S8: =IF(R8<=0,0,(Q8-R8)/R8) -> 0.021392268 | T8: =(HLOOKUP(E$2,Budget!$E$3:$P$18,MATCH(B8,Budget!$B$3:$B$18,0),FALSE)) -> 213183.93 | U8: =IF(T8<=0,0,(Q8-T8)/T8) -> -0.25802489 | V8: =Outlook!R8 -> 160462.66 | W8: =Budget!P8 -> 108183.93 | X8: =IF(W8<=0,0,(V8-W8)/W8) -> 0.48323931
B9: FC | C9: Ton | D9: =Actual!AL159 -> 0 | E9: =Actual!AK159 -> 0 | F9: ='Graphic Production'!AI12 -> 37333.333 | G9: =IF(F9<=0,0,(E9-F9)/F9) -> -1 | H9: =((HLOOKUP(E$2,Budget!$E$3:$P$18,MATCH(B9,Budget!$B$3:$B$18,0),FALSE))/Actual!$E$3)*(MID(D$3,1,2)) -> 39666.667 | I9: =IF(H9<=0,0,(E9-H9)/H9) -> -1 | J9: =(HLOOKUP(E$2,Outlook!$F$3:$Q$31,MATCH(B9,Outlook!$B$3:$B$31,0),FALSE)) -> 160000 | K9: =HLOOKUP(E$2,Budget!$E$3:$P$18,MATCH(B9,Budget!$B$3:$B$18,0),FALSE) -> 170000 | L9: =IF(K9<=0,0,(J9-K9)/K9) -> -0.058823529 | M9: =(SUMIF(Outlook!$L$2:$N$2,"actual",Outlook!$L$12:$N$12))+E9 -> 208993.46 | N9: =+Outlook!N39 -> 368993.46 | O9: =+Budget!M26 -> 475000 | P9: =IF(O9<=0,0,(M9-O9)/O9) -> -0.56001378 | Q9: =(SUMIF(Outlook!$F$2:$Q$2,"actual",Outlook!$F$12:$Q$12))+E9 -> 1349598.4 | R9: =(SUMIF(Outlook!$F$2:$Q$2,"ACTUAL",Outlook!F12:Q12))+F9 -> 1386931.7 | S9: =IF(R9<=0,0,(Q9-R9)/R9) -> -0.026917932 | T9: =(SUMIF(Budget!$E$2:$P$2,"PLANED",Budget!E9:P9))+$H$9 -> 1884666.7 | U9: =IF(T9<=0,0,(Q9-T9)/T9) -> -0.28390605 | V9: =Outlook!R12 -> 2620000 | W9: =Budget!Q9 -> 3050000 | X9: =IF(W9<=0,0,(V9-W9)/W9) -> -0.14098361 | Z9: =+W9-Q9 -> 1700401.6 | AA9: =2000000-Q9 -> 650401.61 | AB9: =+AA9/8500 -> 76.517837 | AC9: days | AD9: =+Z9/8500 -> 200.04725
B10: FC LOAD | C10: Ton | D10: =Actual!AL162 -> 0 | E10: =Actual!AK215 -> 0 | F10: ='Graphic Production'!AI15 -> 40833.333 | G10: =IF(F10<=0,0,(E10-F10)/F10) -> -1 | H10: =(HLOOKUP(E$2,Budget!$E$3:$P$18,MATCH(B10,Budget!$B$3:$B$18,0),FALSE))/(Actual!$E$3)*(MID(D$3,1,2)) -> 39666.667 | I10: =IF(H10<=0,0,(E10-H10)/H10) -> -1 | J10: =(HLOOKUP(E$2,Outlook!$F$3:$Q$31,MATCH(B10,Outlook!$B$3:$B$31,0),FALSE)) -> 175000 | K10: =HLOOKUP(E$2,Budget!$E$3:$P$18,MATCH(B10,Budget!$B$3:$B$18,0),FALSE) -> 170000 | L10: =IF(K10<=0,0,(J10-K10)/K10) -> 0.029411765 | M10: =(SUMIF(Outlook!$L$2:$N$2,"actual",Outlook!$L$14:$N$14))+E10 -> 172530.37 | N10: =+Outlook!N40 -> 347530.37 | O10: =+Budget!M27 -> 410000 | P10: =IF(O10<=0,0,(M10-O10)/O10) -> -0.57919422 | Q10: =(SUMIF(Outlook!$F$2:$Q$2,"actual",Outlook!$F$14:$Q$14))+$E$10 -> 1298197.5 | R10: =(SUMIF(Outlook!$F$2:$Q$2,"ACTUAL",Outlook!F14:Q14))+F10 -> 1339030.8 | S10: =IF(R10<=0,0,(Q10-R10)/R10) -> -0.030494693 | T10: =(SUMIF(Budget!$E$2:$P$2,"PLANED",Budget!E11:P11))+H10 -> 1867166.7 | U10: =IF(T10<=0,0,(Q10-T10)/T10) -> -0.3047233 | V10: =Outlook!R14 -> 2600000 | W10: =Budget!Q11 -> 3040000 | X10: =IF(W10<=0,0,(V10-W10)/W10) -> -0.14473684 | Z10: =+W10-Q10 -> 1741802.5 | AA10: =2000000-Q10 -> 701802.52 | AB10: =+AA10/7500 -> 93.573669 | AC10: barge | AD10: =+Z10/7500 -> 232.24034
B11: FC Stock | C11: Ton | D11: =Actual!AL163 -> 53492.115 | E11: =Actual!AL163 -> 53492.115 | F11: ='Graphic Production'!AI16 -> 49712.625 | G11: =IF(F11<=0,0,(E11-F11)/F11) -> 0.076026766 | H11: =((HLOOKUP(E$2,Budget!$E$3:$P$18,MATCH(B11,Budget!$B$3:$B$18,0),FALSE))) -> 84984.685 | I11: =IF(H11<=0,0,(E11-H11)/H11) -> -0.37056759 | J11: =(HLOOKUP(E$2,Outlook!$F$3:$Q$31,MATCH(B11,Outlook!$B$3:$B$31,0),FALSE)) -> 38492.115 | K11: =HLOOKUP(E$2,Budget!$E$3:$P$18,MATCH(B11,Budget!$B$3:$B$18,0),FALSE) -> 84984.685 | L11: =IF(K11<=0,0,(J11-K11)/K11) -> -0.54706998 | M11: =Actual!AL163 -> 53492.115 | N11: =+Outlook!N13 -> 38492.115 | O11: =+Budget!M10 -> 84984.685 | P11: =IF(O11<=0,0,(M11-O11)/O11) -> -0.37056759 | Q11: =Actual!AL163 -> 53492.115 | R11: =(HLOOKUP(E$2,Outlook!$F$3:$Q$31,MATCH(B11,Outlook!$B$3:$B$31,0),FALSE)) -> 38492.115 | S11: =IF(R11<=0,0,(Q11-R11)/R11) -> 0.3896902 | T11: =(HLOOKUP(E$2,Budget!$E$3:$P$18,MATCH(B11,Budget!$B$3:$B$18,0),FALSE)) -> 84984.685 | U11: =IF(T11<=0,0,(Q11-T11)/T11) -> -0.37056759 | V11: =Outlook!R13 -> 25691.206 | W11: =Budget!P10 -> 77484.685 | X11: =IF(W11<=0,0,(V11-W11)/W11) -> -0.66843505 | Z11: =+W9-Q10 -> 1751802.5 | AD11: =+Z11/7500 -> 233.57367
B12: Uncovered Coal | C12: Ton | D12: =Actual!AL164 -> 0 | E12: =Actual!AL164 -> 0 | F12: =(HLOOKUP(E$2,Outlook!$F$3:$Q$31,MATCH(B12,Outlook!$B$3:$B$31,0),FALSE)) -> 0 | G12: =IF(F12<=0,0,(E12-F12)/F12) -> 0 | H12: =(HLOOKUP(E$2,Budget!$E$3:$P$18,MATCH(B12,Budget!$B$3:$B$18,0),FALSE)) -> 0 | I12: =IF(H12<=0,0,(E12-H12)/H12) -> 0 | J12: =(HLOOKUP(E$2,Outlook!$F$3:$Q$31,MATCH(B12,Outlook!$B$3:$B$31,0),FALSE)) -> 0 | K12: =HLOOKUP(E$2,Budget!$E$3:$P$18,MATCH(B12,Budget!$B$3:$B$18,0),FALSE) -> 0 | L12: =IF(K12<=0,0,(J12-K12)/K12) -> 0 | M12: =Actual!AL164 -> 0 | N12: =F12 -> 0 | O12: =H12 -> 0 | P12: =IF(O12<=0,0,(M12-O12)/O12) -> 0 | Q12: =Actual!AL164 -> 0 | R12: =(HLOOKUP(E$2,Outlook!$F$3:$Q$31,MATCH(B12,Outlook!$B$3:$B$31,0),FALSE)) -> 0 | S12: =IF(R12<=0,0,(Q12-R12)/R12) -> 0 | T12: =(HLOOKUP(E$2,Budget!$E$3:$P$18,MATCH(B12,Budget!$B$3:$B$18,0),FALSE)) -> 0 | U12: =IF(T12<=0,0,(Q12-T12)/T12) -> 0 | V12: =Outlook!Q25 -> 0 | W12: =Budget!P12 -> 0 | X12: =IF(W12<=0,0,(V12-W12)/W12) -> 0
B13: OB Distance | C13: KM | D13: =Actual!AL219 -> 1.0845163 | E13: =Actual!AK219 -> 1.1029475 | F13: =(HLOOKUP(E$2,Outlook!$F$3:$Q$31,MATCH(B13,Outlook!$B$3:$B$31,0),FALSE)) -> 1.25 | G13: =IF(F13<=0,0,(E13-F13)/F13) -> -0.11764201 | H13: =((HLOOKUP(E$2,Budget!$E$3:$P$18,MATCH(B13,Budget!$B$3:$B$18,0),FALSE))) -> 1.2 | I13: =IF(H13<=0,0,(E13-H13)/H13) -> -0.080877095 | J13: =(HLOOKUP(E$2,Outlook!$F$3:$Q$31,MATCH(B13,Outlook!$B$3:$B$31,0),FALSE)) -> 1.25 | K13: =HLOOKUP(E$2,Budget!$E$3:$P$18,MATCH(B13,Budget!$B$3:$B$18,0),FALSE) -> 1.2 | L13: =IF(K13<=0,0,(J13-K13)/K13) -> 0.041666667 | M13: =IFERROR(E4*E13/E4,0) -> 1.1029475 | N13: =+Outlook!N41 -> 1.1098764 | O13: =Budget!M21 -> 1.3861162 | P13: =IF(O13<=0,0,(M13-O13)/O13) -> -0.20428931 | Q13: =(SUMPRODUCT(Outlook!F4:K4,Outlook!F26:K26)+Summary!$E$4*Summary!$E$13)/Summary!$Q$4 -> 0.75680776 | R13: =(SUMPRODUCT(Outlook!F4:K4,Outlook!F26:K26))/SUM(Outlook!F4:K4) -> 1.0765723 | S13: =IF(R13<=0,0,(Q13-R13)/R13) -> -0.29702094 | T13: =+SUMPRODUCT(Budget!E4:J4,Budget!E13:J13)/SUM(Budget!E4:J4) -> 1.2946992 | U13: =IF(T13<=0,0,(Q13-T13)/T13) -> -0.41545669 | V13: =Outlook!R26 -> 1.1698741 | W13: =Budget!Q13 -> 1.361308 | X13: =IF(W13<=0,0,(V13-W13)/W13) -> -0.14062498
B14: ROM Distance | C14: KM | D14: =Actual!AL225 -> 0 | E14: =Actual!AK225 -> 12.908824 | F14: =(HLOOKUP(E$2,Outlook!$F$3:$Q$31,MATCH(B14,Outlook!$B$3:$B$31,0),FALSE)) -> 13.75 | G14: =IF(F14<=0,0,(E14-F14)/F14) -> -0.061176436 | H14: =((HLOOKUP(E$2,Budget!$E$3:$P$18,MATCH(B14,Budget!$B$3:$B$18,0),FALSE))) -> 14.25 | I14: =IF(H14<=0,0,(E14-H14)/H14) -> -0.094117614 | J14: =(HLOOKUP(E$2,Outlook!$F$3:$Q$31,MATCH(B14,Outlook!$B$3:$B$31,0),FALSE)) -> 13.75 | K14: =HLOOKUP(E$2,Budget!$E$3:$P$18,MATCH(B14,Budget!$B$3:$B$18,0),FALSE) -> 14.25 | L14: =IF(K14<=0,0,(J14-K14)/K14) -> -0.035087719 | M14: =IFERROR(E5*E14/E5,0) -> 12.908824 | N14: =+Outlook!N42 -> 13.629134 | O14: =Budget!M22 -> 14.415358 | P14: =IF(O14<=0,0,(M14-O14)/O14) -> -0.10450893 | Q14: =(SUMPRODUCT(Outlook!F5:K5,Outlook!F27:K27)+Summary!$E$5*Summary!$E$14)/Summary!$Q$5 -> 10.478818 | R14: =(SUMPRODUCT(Outlook!F5:K5,Outlook!F27:K27))/SUM(Outlook!F5:K5) -> 13.857585 | S14: =IF(R14<=0,0,(Q14-R14)/R14) -> -0.24382075 | T14: =+SUMPRODUCT(Budget!E5:J5,Budget!E14:J14)/SUM(Budget!E5:J5) -> 14.663126 | U14: =IF(T14<=0,0,(Q14-T14)/T14) -> -0.2853626 | V14: =Outlook!R27 -> 13.873654 | W14: =Budget!Q14 -> 14.500008 | X14: =IF(W14<=0,0,(V14-W14)/W14) -> -0.043196814
B15: Rain fall | C15: mm. | D15: =Actual!AK178 -> 0 | E15: =Actual!AK177 -> 0 | F15: =((HLOOKUP(E$2,Outlook!$F$3:$Q$31,MATCH(B15,Outlook!$B$3:$B$31,0),FALSE))/Actual!$E$3)*(MID(D$3,1,2)) -> 71.633333 | G15: =IF(F15<=0,0,(E15-F15)/F15) -> -1 | H15: =((HLOOKUP(E$2,Budget!$E$3:$P$18,MATCH(B15,Budget!$B$3:$B$18,0),FALSE))/Actual!$E$3)*(MID(D$3,1,2)) -> 71.685838 | I15: =IF(H15<=0,0,(E15-H15)/H15) -> -1 | J15: =(HLOOKUP(E$2,Outlook!$F$3:$Q$31,MATCH(B15,Outlook!$B$3:$B$31,0),FALSE)) -> 307 | K15: =HLOOKUP(E$2,Budget!$E$3:$P$18,MATCH(B15,Budget!$B$3:$B$18,0),FALSE) -> 307.22502 | L15: =IF(K15<=0,0,(J15-K15)/K15) -> -0.00073242552 | M15: =(SUMIF(Outlook!$L$2:$N$2,"actual",Outlook!$L$28:$N$28))+E15 -> 275 | N15: =+Outlook!N43 -> 582 | O15: =Budget!M23 -> 809.67347 | P15: =IF(O15<=0,0,(M15-O15)/O15) -> -0.66035691 | Q15: =(SUMIF(Outlook!$F$2:$Q$2,"actual",Outlook!$F$28:$Q$28))+E15 -> 2833.87 | R15: =(SUMIF(Outlook!$F$2:$Q$2,"ACTUAL",Outlook!F28:Q28))+F15 -> 2905.5033 | S15: =IF(R15<=0,0,(Q15-R15)/R15) -> -0.024654363 | T15: =(SUMIF(Budget!$E$2:$P$2,"PLANED",Budget!E15:P15))+(((HLOOKUP(E$2,Budget!$E$3:$P$18,MATCH(B15,Budget!$B$3:$B$18,0),FALSE))/Actual!$E$3)*(MID(D$3,1,2))) -> 3103.6393 | U15: =IF(T15<=0,0,(Q15-T15)/T15) -> -0.086920309 | V15: =Outlook!R28 -> 4491.87 | W15: =Budget!Q15 -> 4690.7728 | X15: =IF(W15<=0,0,(V15-W15)/W15) -> -0.042403 | AA15: =Q5 -> 1427162.5
B16: Rain fall Duration | C16: hr. | D16: =Actual!AK185 -> 0 | E16: =Actual!AK184 -> 0 | F16: =((HLOOKUP(E$2,Outlook!$F$3:$Q$31,MATCH(B16,Outlook!$B$3:$B$31,0),FALSE))/Actual!$E$3)*MID(D$3,1,2) -> 17.266667 | G16: =IF(F16<=0,0,(E16-F16)/F16) -> -1 | H16: =((HLOOKUP(E$2,Budget!$E$3:$P$18,MATCH(B16,Budget!$B$3:$B$18,0),FALSE))/Actual!$E$3)*(MID(D$3,1,2)) -> 16.665224 | I16: =IF(H16<=0,0,(E16-H16)/H16) -> -1 | J16: =(HLOOKUP(E$2,Outlook!$F$3:$Q$31,MATCH(B16,Outlook!$B$3:$B$31,0),FALSE)) -> 74 | K16: =HLOOKUP(E$2,Budget!$E$3:$P$18,MATCH(B16,Budget!$B$3:$B$18,0),FALSE) -> 71.422388 | L16: =IF(K16<=0,0,(J16-K16)/K16) -> 0.036089691 | M16: =(SUMIF(Outlook!$L$2:$N$2,"actual",Outlook!$L$29:$N$29))+E16 -> 78.033333 | N16: =+Outlook!N44 -> 152.03333 | O16: =Budget!M24 -> 172.58955 | P16: =IF(O16<=0,0,(M16-O16)/O16) -> -0.54786757 | Q16: =((SUMIF(Outlook!$F$2:$Q$2,"actual",Outlook!$F$29:$Q$29))+E16) -> 609.52 | R16: =(SUMIF(Outlook!$F$2:$Q$2,"ACTUAL",Outlook!F29:Q29))+F16 -> 626.78667 | S16: =IF(R16<=0,0,(Q16-R16)/R16) -> -0.027547916 | T16: =(SUMIF(Budget!$E$2:$P$2,"PLANED",Budget!E16:P16))+(((HLOOKUP(E$2,Budget!$E$3:$P$18,MATCH(B16,Budget!$B$3:$B$18,0),FALSE))/Actual!$E$3)*(MID(D$3,1,2))) -> 626.58836 | U16: =IF(T16<=0,0,(Q16-T16)/T16) -> -0.027240146 | V16: =Outlook!R29 -> 1106.52 | W16: =Budget!Q16 -> 1090.7485 | X16: =IF(W16<=0,0,(V16-W16)/W16) -> 0.01445933
B17: Slippery time | C17: hr. | D17: =Actual!AK192 -> 0 | E17: =Actual!AK191 -> 0 | F17: =((HLOOKUP(E$2,Outlook!$F$3:$Q$31,MATCH(B17,Outlook!$B$3:$B$31,0),FALSE))/Actual!$E$3)*MID(D$3,1,2) -> 5.1333333 | G17: =IF(F17<=0,0,(E17-F17)/F17) -> -1 | H17: =((HLOOKUP(E$2,Budget!$E$3:$P$18,MATCH(B17,Budget!$B$3:$B$18,0),FALSE))/Actual!$E$3)*(MID(D$3,1,2)) -> 5.6661761 | I17: =IF(H17<=0,0,(E17-H17)/H17) -> -1 | J17: =(HLOOKUP(E$2,Outlook!$F$3:$Q$31,MATCH(B17,Outlook!$B$3:$B$31,0),FALSE)) -> 22 | K17: =HLOOKUP(E$2,Budget!$E$3:$P$18,MATCH(B17,Budget!$B$3:$B$18,0),FALSE) -> 24.283612 | L17: =IF(K17<=0,0,(J17-K17)/K17) -> -0.094039221 | M17: =(SUMIF(Outlook!$L$2:$N$2,"actual",Outlook!$L$30:$N$30))+E17 -> 21.7 | N17: =+Outlook!N45 -> 43.7 | O17: =Budget!M25 -> 58.680448 | P17: =IF(O17<=0,0,(M17-O17)/O17) -> -0.6302005 | Q17: =(SUMIF(Outlook!$F$2:$Q$2,"actual",Outlook!$F$30:$Q$30))+E17 -> 178.6 | R17: =(SUMIF(Outlook!$F$2:$Q$2,"ACTUAL",Outlook!F30:Q30))+F17 -> 183.73333 | S17: =IF(R17<=0,0,(Q17-R17)/R17) -> -0.027939042 | T17: =(SUMIF(Budget!$E$2:$P$2,"PLANED",Budget!E17:P17))+(((HLOOKUP(E$2,Budget!$E$3:$P$18,MATCH(B17,Budget!$B$3:$B$18,0),FALSE))/Actual!$E$3)*(MID(D$3,1,2))) -> 213.04004 | U17: =IF(T17<=0,0,(Q17-T17)/T17) -> -0.16165995 | V17: =Outlook!R30 -> 326.6 | W17: =Budget!Q17 -> 370.85449 | X17: =IF(W17<=0,0,(V17-W17)/W17) -> -0.11933115
B18: JBG Fuel stock | C18: Liter | D18: =Actual!AL167 -> 101525.99 | E18: =Actual!AL167 -> 101525.99 | F18: =(HLOOKUP(E$2,Outlook!$F$3:$Q$31,MATCH(B18,Outlook!$B$3:$B$31,0),FALSE)) -> 35000 | G18: =IF(F18<=0,0,(E18-F18)/F18) -> 1.9007427 | H18: =(HLOOKUP(E$2,Budget!$E$3:$P$18,MATCH(B18,Budget!$B$3:$B$18,0),FALSE)) -> #N/A | I18: =IF(H18<=0,0,(E18-H18)/H18) -> #N/A | J18: =(HLOOKUP(E$2,Outlook!$F$3:$Q$31,MATCH(B18,Outlook!$B$3:$B$31,0),FALSE)) -> 35000 | K18: =HLOOKUP(E$2,Budget!$E$3:$P$18,MATCH(B18,Budget!$B$3:$B$18,0),FALSE) -> #N/A | L18: =IF(K18<=0,0,(J18-K18)/K18) -> #N/A | Q18: =Actual!AL167 -> 101525.99 | R18: =Outlook!Q31 -> 35000 | S18: =IF(R18<=0,0,(Q18-R18)/R18) -> 1.9007427 | T18: =(HLOOKUP(E$2,Budget!$E$3:$P$18,MATCH(B18,Budget!$B$3:$B$18,0),FALSE)) -> #N/A | U18: =IF(T18<=0,0,(Q18-T18)/T18) -> #N/A | V18: =Outlook!Q31 -> 35000 | W18: =Budget!P18 -> 0 | X18: =IF(W18<=0,0,(V18-W18)/W18) -> 0
C69: 1 | D69: 2 | E69: 3 | F69: 4 | G69: 5 | H69: 6 | I69: 7 | J69: 8 | K69: 9 | L69: 10 | Q69: 11 | R69: 12 | S69: 13 | T69: 14 | U69: 15 | V69: 16 | W69: 17 | X69: 18 | Y69: 19 | Z69: 20 | AA69: 21 | AB69: 22 | AC69: 23 | AD69: 24 | AE69: 25 | AF69: 26 | AG69: 27 | AH69: 28 | AI69: 29 | AJ69: 30 | AK69: 31
B70: OB TJP | C70: =Actual!F139 -> 34987.5 | D70: =Actual!G139 -> 36594 | E70: =Actual!H139 -> 32709.75 | F70: =Actual!I139 -> 32669.25 | G70: =Actual!J139 -> 31549.5 | H70: =Actual!K139 -> 33361.5 | I70: =Actual!L139 -> 36570.75 | J70: =Actual!M139 -> 0 | ... L70: =Actual!O139 -> 0 | Q70: =Actual!P139 -> 0 | R70: =Actual!Q139 -> 0 | S70: =Actual!R139 -> 0 | T70: =Actual!S139 -> 0 | U70: =Actual!T139 -> 0 | V70: =Actual!U139 -> 0 | W70: =Actual!V139 -> 0 | X70: =Actual!W139 -> 0 | ... AK70: =Actual!AJ139 -> 0
B71: OB SNS | C71: =Actual!#REF! -> #REF! | D71: =Actual!#REF! -> #REF! | E71: =Actual!#REF! -> #REF! | F71: =Actual!#REF! -> #REF! | G71: =Actual!#REF! -> #REF! | H71: =Actual!#REF! -> #REF! | I71: =Actual!#REF! -> #REF! | J71: =Actual!#REF! -> #REF! | ... L71: =Actual!#REF! -> #REF! | Q71: =Actual!#REF! -> #REF! | R71: =Actual!#REF! -> #REF! | S71: =Actual!#REF! -> #REF! | T71: =Actual!#REF! -> #REF! | U71: =Actual!#REF! -> #REF! | V71: =Actual!#REF! -> #REF! | W71: =Actual!#REF! -> #REF! | X71: =Actual!#REF! -> #REF! | ... AK71: =Actual!#REF! -> #REF!
B72: ROM TJP | C72: =Actual!F142 -> 0 | D72: =Actual!G142 -> 0 | E72: =Actual!H142 -> 0 | F72: =Actual!I142 -> 0 | G72: =Actual!J142 -> 1312.898 | H72: =Actual!K142 -> 0 | I72: =Actual!L142 -> 0 | J72: =Actual!M142 -> 0 | ... L72: =Actual!O142 -> 0 | Q72: =Actual!P142 -> 0 | R72: =Actual!Q142 -> 0 | S72: =Actual!R142 -> 0 | T72: =Actual!S142 -> 0 | U72: =Actual!T142 -> 0 | V72: =Actual!U142 -> 0 | W72: =Actual!V142 -> 0 | X72: =Actual!W142 -> 0 | ... AK72: =Actual!AJ142 -> 0
B73: ROM SNS | C73: =Actual!#REF! -> #REF! | D73: =Actual!#REF! -> #REF! | E73: =Actual!#REF! -> #REF! | F73: =Actual!#REF! -> #REF! | G73: =Actual!#REF! -> #REF! | H73: =Actual!#REF! -> #REF! | I73: =Actual!#REF! -> #REF! | J73: =Actual!#REF! -> #REF! | ... L73: =Actual!#REF! -> #REF! | Q73: =Actual!#REF! -> #REF! | R73: =Actual!#REF! -> #REF! | S73: =Actual!#REF! -> #REF! | T73: =Actual!#REF! -> #REF! | U73: =Actual!#REF! -> #REF! | V73: =Actual!#REF! -> #REF! | W73: =Actual!#REF! -> #REF! | X73: =Actual!#REF! -> #REF! | ... AK73: =Actual!#REF! -> #REF!
B81: 1 | C81: 2 | D81: =C81+1 -> 3 | E81: =D81+1 -> 4 | F81: =E81+1 -> 5 | G81: =F81+1 -> 6 | H81: =G81+1 -> 7 | I81: =H81+1 -> 8 | J81: =I81+1 -> 9 | K81: =J81+1 -> 10 | L81: =K81+1 -> 11 | Q81: =L81+1 -> 12 | R81: =Q81+1 -> 13 | S81: =R81+1 -> 14 | T81: =S81+1 -> 15 | U81: =T81+1 -> 16 | V81: =U81+1 -> 17 | W81: =V81+1 -> 18 | X81: =W81+1 -> 19 | Y81: =X81+1 -> 20 | ... AJ81: =AI81+1 -> 31
A82: ROM Production | B82: =Actual!F151 -> 0 | C82: =Actual!G151 -> 0 | D82: =Actual!H151 -> 0 | E82: =Actual!I151 -> 0 | F82: =Actual!J151 -> 1312.898 | G82: =Actual!K151 -> 0 | H82: =Actual!L151 -> 0 | I82: =Actual!M151 -> 0 | ... L82: =Actual!P151 -> 0 | Q82: =Actual!Q151 -> 0 | R82: =Actual!R151 -> 0 | S82: =Actual!S151 -> 0 | T82: =Actual!T151 -> 0 | U82: =Actual!U151 -> 0 | V82: =Actual!V151 -> 0 | W82: =Actual!W151 -> 0 | X82: =Actual!X151 -> 0 | ... AJ82: =Actual!AJ151 -> 0
A83: Rainfall (mm) | B83: =Actual!F177 -> 0 | C83: =Actual!G177 -> 0 | D83: =Actual!H177 -> 0 | E83: =Actual!I177 -> 0 | F83: =Actual!J177 -> 0 | G83: =Actual!K177 -> 0 | H83: =Actual!L177 -> 0 | I83: =Actual!M177 -> 0 | ... L83: =Actual!P177 -> 0 | Q83: =Actual!Q177 -> 0 | R83: =Actual!R177 -> 0 | S83: =Actual!S177 -> 0 | T83: =Actual!T177 -> 0 | U83: =Actual!U177 -> 0 | V83: =Actual!V177 -> 0 | W83: =Actual!W177 -> 0 | X83: =Actual!X177 -> 0 | ... AJ83: =Actual!AJ177 -> 0
B86: 1 | C86: 2 | D86: =C86+1 -> 3 | E86: =D86+1 -> 4 | F86: =E86+1 -> 5 | G86: =F86+1 -> 6 | H86: =G86+1 -> 7 | I86: =H86+1 -> 8 | J86: =I86+1 -> 9 | K86: =J86+1 -> 10 | L86: =K86+1 -> 11 | Q86: =L86+1 -> 12 | R86: =Q86+1 -> 13 | S86: =R86+1 -> 14 | T86: =S86+1 -> 15 | U86: =T86+1 -> 16 | V86: =U86+1 -> 17 | W86: =V86+1 -> 18 | X86: =W86+1 -> 19 | Y86: =X86+1 -> 20 | ... AJ86: =AI86+1 -> 31
A87: ROM Production | B87: =B82 -> 0 | C87: =C82 -> 0 | D87: =D82 -> 0 | E87: =E82 -> 0 | F87: =F82 -> 1312.898 | G87: =G82 -> 0 | H87: =H82 -> 0 | I87: =I82 -> 0 | ... L87: =L82 -> 0 | Q87: =Q82 -> 0 | R87: =R82 -> 0 | S87: =S82 -> 0 | T87: =T82 -> 0 | U87: =U82 -> 0 | V87: =V82 -> 0 | W87: =W82 -> 0 | X87: =X82 -> 0 | ... AJ87: =AJ82 -> 0
A88: Rainfall (hr) | B88: =Actual!F197 -> 0 | C88: =Actual!G197 -> 0 | D88: =Actual!H197 -> 0 | E88: =Actual!I197 -> 0 | F88: =Actual!J197 -> 0 | G88: =Actual!K197 -> 0 | H88: =Actual!L197 -> 0 | I88: =Actual!M197 -> 0 | ... L88: =Actual!P197 -> 0 | Q88: =Actual!Q197 -> 0 | R88: =Actual!R197 -> 0 | S88: =Actual!S197 -> 0 | T88: =Actual!T197 -> 0 | U88: =Actual!U197 -> 0 | V88: =Actual!V197 -> 0 | W88: =Actual!W197 -> 0 | X88: =Actual!X197 -> 0 | ... AJ88: =Actual!AJ197 -> 0

Sheet Budget
B2: ="Plan Budget "&MID(Outlook!B2,9,16) -> Plan Budget Production 2026 | E2: =IF(Outlook!F2="ACTUAL","PLANED","PLAN") -> PLANED | F2: =IF(Outlook!G2="ACTUAL","PLANED","PLAN") -> PLANED | G2: =IF(Outlook!H2="ACTUAL","PLANED","PLAN") -> PLANED | H2: =IF(Outlook!I2="ACTUAL","PLANED","PLAN") -> PLANED | I2: =IF(Outlook!J2="ACTUAL","PLANED","PLAN") -> PLANED | J2: =IF(Outlook!K2="ACTUAL","PLANED","PLAN") -> PLANED | K2: =IF(Outlook!L2="ACTUAL","PLANED","PLAN") -> PLANED | L2: =IF(Outlook!M2="ACTUAL","PLANED","PLAN") -> PLANED | ... Q2: =IF(Outlook!R2="ACTUAL","PLANED","PLAN") -> PLAN
C3: Unit | D3: =Outlook!E3 -> EOP 2025 | E3: Jan'26 | F3: Feb'26 | G3: Mar'26 | H3: Apr'26 | I3: May'26 | J3: Jun'26 | K3: Jul'26 | L3: Aug'26 | M3: Sep'26 | N3: Oct'26 | O3: Nov'26 | P3: Dec'26 | Q3: Total
B4: OB | C4: BCM | E4: 885000 | F4: 865000 | G4: 960000 | H4: 995000 | I4: 1010000 | J4: 1020000 | K4: 1095000 | L4: 1075000 | M4: 1100000 | N4: 980000 | O4: 935000 | P4: 930000 | Q4: =SUM(E4:P4) -> 11850000
B5: ROM | C5: Tons | E5: 250000 | F5: 255000 | G5: 260000 | H5: 270000 | I5: 275000 | J5: 276200 | K5: 160000 | L5: 160000 | M5: 163800 | N5: 315000 | O5: 305000 | P5: 310000 | Q5: =SUM(E5:P5) -> 3000000
B6: SR | C6: BCM/Ton | E6: =E4/E5 -> 3.54 | F6: =F4/F5 -> 3.3921569 | G6: =G4/G5 -> 3.6923077 | H6: =H4/H5 -> 3.6851852 | I6: =I4/I5 -> 3.6727273 | J6: =J4/J5 -> 3.6929761 | K6: =K4/K5 -> 6.84375 | L6: =L4/L5 -> 6.71875 | ... P6: =P4/P5 -> 3 | Q6: =IF(Q4=0,0,IF(Q5=0,0,Q4/Q5)) -> 3.95
B7: Outpit | C7: BCM | E7: 0 | F7: 0 | G7: 0 | H7: 0 | I7: 0 | J7: 0 | K7: 0 | L7: 0 | M7: 0 | N7: 0 | O7: 0 | P7: 0 | Q7: =SUM(E7:P7) -> 0
B8: ROM Stock | C8: Tons | D8: 158400.33 | E8: 148400.33 | F8: 153400.33 | G8: 153400.33 | H8: 178400.33 | I8: 193400.33 | J8: 204383.93 | K8: 179383.93 | L8: 219383.93 | M8: 213183.93 | N8: 198183.93 | O8: 153183.93 | P8: 108183.93 | Q8: =P8 -> 108183.93
B9: FC | C9: Tons | E9: 260000 | F9: 250000 | G9: 260000 | H9: 245000 | I9: 260000 | J9: 265000 | K9: 185000 | L9: 120000 | M9: 170000 | N9: 330000 | O9: 350000 | P9: 355000 | Q9: =SUM(E9:P9) -> 3050000
B10: FC Stock | C10: Tons | D10: 67484.685 | E10: =D10+E9-E11 -> 57484.685 | F10: =E10+F9-F11 -> 44984.685 | G10: =F10+G9-G11 -> 34984.685 | H10: =G10+H9-H11 -> 17484.685 | I10: =H10+I9-I11 -> 9984.6852 | J10: =I10+J9-J11 -> 19984.685 | K10: =J10+K9-K11 -> 54984.685 | L10: =K10+L9-L11 -> 84984.685 | ... P10: =O10+P9-P11 -> 77484.685 | Q10: =P10 -> 77484.685
B11: FC LOAD | C11: Tons | E11: 270000 | F11: 262500 | G11: 270000 | H11: 262500 | I11: 267500 | J11: 255000 | K11: 150000 | L11: 90000 | M11: 170000 | N11: 337500 | O11: 345000 | P11: 360000 | Q11: =SUM(E11:P11) -> 3040000
B12: Uncovered Coal | C12: Tons
B13: OB Distance | C13: KM | E13: 1.1 | F13: 1.25 | G13: 1.2 | H13: 1.25 | I13: 1.4 | J13: 1.53 | K13: 1.53 | L13: 1.43 | M13: 1.2 | N13: 1.3 | O13: 1.5 | P13: 1.61 | Q13: =SUMPRODUCT(E4:P4,E13:P13)/Q4 -> 1.361308
B14: ROM Distance | C14: KM | E14: 14.75 | F14: 14.75 | G14: 14.75 | H14: 14.75 | I14: 14.5 | J14: 14.5 | K14: 14.5 | L14: 14.5 | M14: 14.25 | N14: 14.25 | O14: 14.25 | P14: 14.2975 | Q14: =SUMPRODUCT(E5:P5,E14:P14)/Q5 -> 14.500008
B15: Rain fall | C15: mm. | E15: 399.2175 | F15: 378.95 | G15: 504.9 | H15: 349.525 | I15: 545.7375 | J15: 351.175 | K15: 357.9125 | L15: 144.53595 | M15: 307.22502 | N15: 286.34707 | O15: 490.25399 | P15: 574.99331 | Q15: =SUM(E15:P15) -> 4690.7728 | S15: =+(G15-F15)/F15 -> 0.33236575
B16: Rain fall Duration | C16: hrs. | E16: 94.754478 | F16: 70.102985 | G16: 94.987313 | H16: 84.975373 | I16: 94.744776 | J16: 69.191045 | K16: 50.214925 | L16: 50.952239 | M16: 71.422388 | N16: 126.70149 | O16: 150.01418 | P16: 132.68731 | Q16: =SUM(E16:P16) -> 1090.7485 | S16: =+(G16-F16)/F16 -> 0.35496817
B17: Slippery time | C17: hr. | E17: 32.216522 | F17: 23.835015 | G17: 32.295687 | H17: 28.891627 | I17: 32.213224 | J17: 23.524955 | K17: 17.073075 | L17: 17.323761 | M17: 24.283612 | N17: 43.078507 | O17: 51.004821 | P17: 45.113687 | Q17: =SUM(E17:P17) -> 370.85449 | S17: =+S16/31*13 -> 0.14885762
B18: GPK Fuel stock | C18: Liters | S18: =+L17/31*13 -> 7.2648031 | T18: 12.446667 | U18: =+T18/S18 -> 1.7132834
G19: =+SUM(E4:G4) -> 2710000 | J19: =+SUM(H4:J4) -> 3025000 | M19: =+SUM(K4:M4) -> 3270000 | P19: =+SUM(N4:P4) -> 2845000 | S19: =+L16/31*13 -> 21.367068 | T19: 15.566667 | U19: =+T19/S19 -> 0.72853546
B20: Remark! | E20: =SUMPRODUCT(E4:O4,E13:O13)/SUM(E4:O4) -> 1.3401282 | G20: =+SUM(E5:G5) -> 765000 | J20: =+SUM(H5:J5) -> 821200 | M20: =+SUM(K5:M5) -> 483800 | P20: =+SUM(N5:P5) -> 930000
G21: =SUMPRODUCT(E4:G4,E13:G13)/SUM(E4:G4) -> 1.1833026 | J21: =SUMPRODUCT(H4:J4,H13:J13)/SUM(H4:J4) -> 1.3944959 | M21: =SUMPRODUCT(K4:M4,K13:M13)/SUM(K4:M4) -> 1.3861162 | P21: =SUMPRODUCT(N4:P4,N13:P13)/SUM(N4:P4) -> 1.467065
G22: =SUMPRODUCT(E5:G5,E14:G14)/SUM(E5:G5) -> 14.75 | J22: =SUMPRODUCT(H5:J5,H14:J14)/SUM(H5:J5) -> 14.582197 | M22: =SUMPRODUCT(K5:M5,K14:M14)/SUM(K5:M5) -> 14.415358 | P22: =SUMPRODUCT(N5:P5,N14:P14)/SUM(N5:P5) -> 14.265833
G23: =SUM(E15:G15) -> 1283.0675 | J23: =SUM(H15:J15) -> 1246.4375 | M23: =SUM(K15:M15) -> 809.67347 | P23: =SUM(N15:P15) -> 1351.5944 | R23: =P17/P16 -> 0.34
G24: =SUM(E16:G16) -> 259.84478 | J24: =SUM(H16:J16) -> 248.91119 | M24: =SUM(K16:M16) -> 172.58955 | P24: =SUM(N16:P16) -> 409.40299
G25: =SUM(E17:G17) -> 88.347224 | J25: =SUM(H17:J17) -> 84.629806 | M25: =SUM(K17:M17) -> 58.680448 | P25: =SUM(N17:P17) -> 139.19701
G26: =+SUM(E9:G9) -> 770000 | J26: =+SUM(H9:J9) -> 770000 | M26: =+SUM(K9:M9) -> 475000 | P26: =+SUM(N9:P9) -> 1035000
G27: =+SUM(E11:G11) -> 802500 | J27: =+SUM(H11:J11) -> 785000 | M27: =+SUM(K11:M11) -> 410000 | P27: =+SUM(N11:P11) -> 1042500
E29: Data actual rainfall 2013 - 2023
Q30: unit : mm. | S30: Note
F31: Jan | G31: Feb | H31: Mar | I31: Apr | J31: May | K31: Jun | L31: Jul | M31: Aug | N31: Sep | O31: Oct | P31: Nov | Q31: Dec | R31: Total
E32: 2013 | F32: 237 | G32: 522.4 | H32: 519 | I32: 443 | J32: 315.5 | K32: 63 | L32: 333.5 | M32: 59 | N32: 136.2 | O32: 155.3 | P32: 351 | Q32: 355 | R32: =SUM(F32:Q32) -> 3489.9 | S32: BEK/Biangan
E33: 2014 | F33: 200 | G33: 155.4 | H33: 261.6 | I33: 609.9 | J33: 209.3 | K33: 120.5 | L33: 134 | M33: 118.35 | N33: 36.7 | O33: 78.5 | P33: 367.9 | Q33: 286.6 | R33: =SUM(F33:Q33) -> 2578.75 | S33: BEK/Biangan
E34: 2015 | F34: 313.9 | G34: 385 | H34: 204.4 | I34: 425.25 | J34: 110.7 | K34: 146 | L34: 47.75 | M34: 2.15 | N34: 9.9 | O34: 68.4 | P34: 342 | Q34: 217.7 | R34: =SUM(F34:Q34) -> 2273.15 | S34: BEK/Biangan
E35: 2016 | F35: 209.9 | G35: 534.5 | H35: 507.1 | I35: 196.6 | J35: 233.5 | K35: 198.4 | L35: 338 | M35: 163.5 | N35: 460.6 | O35: 482.3 | P35: 388.3 | Q35: 252.6 | R35: =SUM(F35:Q35) -> 3965.3 | S35: BEK/Biangan
E36: 2017 | F36: 500.1 | G36: 208.8 | H36: 465.8 | I36: 481.14 | J36: 493.7 | K36: 269 | L36: 210.8 | M36: 196.05 | N36: 177.75 | O36: 143.6 | P36: 704.55 | Q36: 201.1 | R36: =SUM(F36:Q36) -> 4052.39 | S36: BEK/Biangan
E37: 2018 | F37: 233.45 | G37: 417 | H37: 178 | I37: 300.4 | J37: 269.85 | K37: 123 | L37: 227.8 | M37: 113.95 | N37: 183.5 | O37: 229 | P37: 320.2 | Q37: 248.35 | R37: =SUM(F37:Q37) -> 2844.5 | S37: (1-6) BEK/Biangan & (7-12)TCM PJPN
E38: 2019 | F38: 245.9 | G38: 217.2 | H38: 468.75 | I38: 332.5 | J38: 183.9 | K38: 276.3 | L38: 39 | M38: 99 | N38: 3.5 | O38: 131 | P38: 138.5 | Q38: 373.5 | R38: =SUM(F38:Q38) -> 2509.05 | S38: TCM/PJPN
E39: 2020 | F39: 287.5 | G39: 360 | H39: 470.5 | I39: 341 | J39: 308 | K39: 88.5 | L39: 58 | M39: 66.5 | N39: 87.5 | O39: 351 | P39: 271.5 | Q39: 369.5 | R39: =SUM(F39:Q39) -> 3059.5 | S39: TCM/PJPN
E40: 2021 | F40: 354 | G40: 183.5 | H40: 374.5 | I40: 471.10606 | J40: 301.25758 | K40: 209.18182 | L40: 48 | M40: 239 | N40: 353 | O40: 255.19338 | P40: 434 | Q40: 368.45477 | R40: =SUM(F40:Q40) -> 3591.1936 | S40: TCM/PJPN
E41: 2022 | F41: 407.7 | G41: 365.5 | H41: 394.5 | I41: 359.5 | J41: 280 | K41: 303.5 | L41: 269 | M41: 41 | N41: 441.5 | O41: 0 | P41: 447 | Q41: 526 | R41: =SUM(F41:Q41) -> 3835.2 | S41: GPK (Jan-Dec)
E42: 2023 | F42: 146 | G42: 386 | H42: 488 | I42: 173 | J42: 377 | K42: 180 | L42: 116.5 | M42: 53.5 | N42: 191.8 | O42: 256.08 | P42: 360.25 | Q42: 414.81 | R42: =SUM(F42:Q42) -> 3142.94 | S42: TCM/PJPN (Jan-Apr), GPK Port (May - Aug), GPK Pit (Sept), Outlook (Oct-Dec)
...

Sheet Actual
C2: 1.OB Actual Sep'26
C3: Total day ---> | D3: 30 | E3: 30 | F3: 01 | G3: 02 | H3: 03 | I3: 04 | J3: 05 | K3: 06 | L3: 07 | M3: 08 | N3: 09 | O3: 10 | P3: 11 | Q3: 12 | R3: 13 | S3: 14 | T3: 15 | U3: 16 | V3: 17 | W3: 18 | X3: 19 | Y3: 20 | Z3: 21 | AA3: 22 | AB3: 23 | AC3: 24 | AD3: 25 | AE3: 26 | AF3: 27 | AG3: 28 | AH3: 29 | AI3: 30 | AJ3: 31 | AK3: Total by Pit | AL3: EOP by clasification
B4: ARKA | C4: PIT 1 (Source) | E4: PAF(BCM) | F4: =+SUMIF($E$16:$E$27,$E4,F$16:F$27) -> 4489.5 | G4: =+SUMIF($E$16:$E$27,$E4,G$16:G$27) -> 4386 | H4: =+SUMIF($E$16:$E$27,$E4,H$16:H$27) -> 3888 | I4: =+SUMIF($E$16:$E$27,$E4,I$16:I$27) -> 16129.5 | J4: =+SUMIF($E$16:$E$27,$E4,J$16:J$27) -> 11241 | K4: =+SUMIF($E$16:$E$27,$E4,K$16:K$27) -> 8989.5 | L4: =+SUMIF($E$16:$E$27,$E4,L$16:L$27) -> 19191 | M4: =+SUMIF($E$16:$E$27,$E4,M$16:M$27) -> 0 | ... AJ4: =+SUMIF($E$16:$E$27,$E4,AJ$16:AJ$27) -> 0 | AK4: =SUM(F4:AJ4) -> 68314.5 | AL4: =HLOOKUP(LEFT(Summary!$D$3,2),Actual!F3:AJ9,2,FALSE) -> 19191
E5: NAF(BCM) | F5: =+SUMIF($E$16:$E$27,$E5,F$16:F$27) -> 21678 | G5: =+SUMIF($E$16:$E$27,$E5,G$16:G$27) -> 26761.5 | H5: =+SUMIF($E$16:$E$27,$E5,H$16:H$27) -> 25450.5 | I5: =+SUMIF($E$16:$E$27,$E5,I$16:I$27) -> 10998 | J5: =+SUMIF($E$16:$E$27,$E5,J$16:J$27) -> 16753.5 | K5: =+SUMIF($E$16:$E$27,$E5,K$16:K$27) -> 20683.5 | L5: =+SUMIF($E$16:$E$27,$E5,L$16:L$27) -> 15792 | M5: =+SUMIF($E$16:$E$27,$E5,M$16:M$27) -> 0 | ... AJ5: =+SUMIF($E$16:$E$27,$E5,AJ$16:AJ$27) -> 0 | AK5: =SUM(F5:AJ5) -> 138117 | AL5: =HLOOKUP(LEFT(Summary!D3,2),Actual!F3:AJ9,3,FALSE) -> 15792
E6: MUD (BCM) | F6: =+SUMIF($E$16:$E$27,$E6,F$16:F$27) -> 1318.5 | G6: =+SUMIF($E$16:$E$27,$E6,G$16:G$27) -> 0 | H6: =+SUMIF($E$16:$E$27,$E6,H$16:H$27) -> 1956.75 | I6: =+SUMIF($E$16:$E$27,$E6,I$16:I$27) -> 1575.75 | J6: =+SUMIF($E$16:$E$27,$E6,J$16:J$27) -> 2706 | K6: =+SUMIF($E$16:$E$27,$E6,K$16:K$27) -> 1297.5 | L6: =+SUMIF($E$16:$E$27,$E6,L$16:L$27) -> 317.25 | M6: =+SUMIF($E$16:$E$27,$E6,M$16:M$27) -> 0 | ... AJ6: =+SUMIF($E$16:$E$27,$E6,AJ$16:AJ$27) -> 0 | AK6: =SUM(F6:AJ6) -> 9171.75 | AL6: =HLOOKUP(LEFT(Summary!$D$3,2),Actual!$F$3:$AJ$9,4,FALSE) -> 317.25
E7: HAC (BCM) | F7: =+SUMIF($E$16:$E$27,$E7,F$16:F$27) -> 0 | G7: =+SUMIF($E$16:$E$27,$E7,G$16:G$27) -> 0 | H7: =+SUMIF($E$16:$E$27,$E7,H$16:H$27) -> 0 | I7: =+SUMIF($E$16:$E$27,$E7,I$16:I$27) -> 0 | J7: =+SUMIF($E$16:$E$27,$E7,J$16:J$27) -> 0 | K7: =+SUMIF($E$16:$E$27,$E7,K$16:K$27) -> 0 | L7: =+SUMIF($E$16:$E$27,$E7,L$16:L$27) -> 0 | M7: =+SUMIF($E$16:$E$27,$E7,M$16:M$27) -> 0 | ... AJ7: =+SUMIF($E$16:$E$27,$E7,AJ$16:AJ$27) -> 0 | AK7: =SUM(F7:AJ7) -> 0 | AL7: =HLOOKUP(LEFT(Summary!$D$3,2),Actual!$F$3:$AJ$9,5,FALSE) -> 0
E8: Top Soil (BCM) | F8: =+SUMIF($E$16:$E$27,$E8,F$16:F$27) -> 7501.5 | G8: =+SUMIF($E$16:$E$27,$E8,G$16:G$27) -> 5446.5 | H8: =+SUMIF($E$16:$E$27,$E8,H$16:H$27) -> 1414.5 | I8: =+SUMIF($E$16:$E$27,$E8,I$16:I$27) -> 3966 | J8: =+SUMIF($E$16:$E$27,$E8,J$16:J$27) -> 849 | K8: =+SUMIF($E$16:$E$27,$E8,K$16:K$27) -> 2391 | L8: =+SUMIF($E$16:$E$27,$E8,L$16:L$27) -> 1270.5 | M8: =+SUMIF($E$16:$E$27,$E8,M$16:M$27) -> 0 | ... AJ8: =+SUMIF($E$16:$E$27,$E8,AJ$16:AJ$27) -> 0 | AK8: =SUM(F8:AJ8) -> 22839 | AL8: =HLOOKUP(LEFT(Summary!D3,2),Actual!F3:AJ9,6,FALSE) -> 1270.5
E9: Total by day | F9: =SUM(F4:F8) -> 34987.5 | G9: =SUM(G4:G8) -> 36594 | H9: =SUM(H4:H8) -> 32709.75 | I9: =SUM(I4:I8) -> 32669.25 | J9: =SUM(J4:J8) -> 31549.5 | K9: =SUM(K4:K8) -> 33361.5 | L9: =SUM(L4:L8) -> 36570.75 | M9: =SUM(M4:M8) -> 0 | ... AK9: =SUM(AK4:AK8) -> 238442.25 | AL9: EOP by clasification
B10: ARKA | C10: OUTPIT (Source) | E10: PAF(BCM) | AK10: =SUM(F10:AJ10) -> 0 | AL10: =HLOOKUP(LEFT(Summary!$D$3,2),Actual!$F$3:$AJ$15,8,FALSE) -> 0
E11: NAF(BCM) | AK11: =SUM(F11:AJ11) -> 0 | AL11: =HLOOKUP(LEFT(Summary!$D$3,2),Actual!$F$3:$AJ$15,9,FALSE) -> 0
E12: MUD (BCM) | AK12: =SUM(F12:AJ12) -> 0 | AL12: =HLOOKUP(LEFT(Summary!$D$3,2),Actual!$F$3:$AJ$15,10,FALSE) -> 0
E13: HAC (BCM) | AK13: =SUM(F13:AJ13) -> 0 | AL13: =HLOOKUP(LEFT(Summary!$D$3,2),Actual!$F$3:$AJ$15,11,FALSE) -> 0
E14: Top Soil (BCM) | I14: 709.5 | J14: 594 | K14: 2004 | AK14: =SUM(F14:AJ14) -> 3307.5 | AL14: =HLOOKUP(LEFT(Summary!$D$3,2),Actual!$F$3:$AJ$15,12,FALSE) -> 0
E15: Total by day | F15: =SUM(F10:F14) -> 0 | G15: =SUM(G10:G14) -> 0 | H15: =SUM(H10:H14) -> 0 | I15: =SUM(I10:I14) -> 709.5 | J15: =SUM(J10:J14) -> 594 | K15: =SUM(K10:K14) -> 2004 | L15: =SUM(L10:L14) -> 0 | M15: =SUM(M10:M14) -> 0 | ... AK15: =SUM(AK10:AK14) -> 3307.5 | AL15: EOP by clasification
B16: ARKA | C16: In-Pit Dump | E16: PAF(BCM) | AK16: =SUM(F16:AJ16) -> 0
E17: NAF(BCM) | AK17: =SUM(F17:AJ17) -> 0
E18: MUD (BCM) | AK18: =SUM(F18:AJ18) -> 0
E19: HAC (BCM) | AK19: =SUM(F19:AJ19) -> 0
E20: Top Soil (BCM) | AK20: =SUM(F20:AJ20) -> 0
E21: Total by day | F21: =SUM(F16:F20) -> 0 | G21: =SUM(G16:G20) -> 0 | H21: =SUM(H16:H20) -> 0 | I21: =SUM(I16:I20) -> 0 | J21: =SUM(J16:J20) -> 0 | K21: =SUM(K16:K20) -> 0 | L21: =SUM(L16:L20) -> 0 | M21: =SUM(M16:M20) -> 0 | ... AK21: =SUM(AK16:AK20) -> 0
B22: ARKA | C22: Out-Pit Dump | E22: PAF(BCM) | F22: 4489.5 | G22: 4386 | H22: 3888 | I22: 16129.5 | J22: 11241 | K22: 8989.5 | L22: 19191 | AK22: =SUM(F22:AJ22) -> 68314.5
E23: NAF(BCM) | F23: 21678 | G23: 26761.5 | H23: 25450.5 | I23: 10998 | J23: 16753.5 | K23: 20683.5 | L23: 15792 | AK23: =SUM(F23:AJ23) -> 138117
E24: MUD (BCM) | F24: 1318.5 | H24: 1956.75 | I24: 1575.75 | J24: 2706 | K24: 1297.5 | L24: 317.25 | AK24: =SUM(F24:AJ24) -> 9171.75
E25: HAC (BCM) | AK25: =SUM(F25:AJ25) -> 0
E26: Top Soil (BCM) | F26: 7501.5 | G26: 5446.5 | H26: 1414.5 | I26: 3966 | J26: 849 | K26: 2391 | L26: 1270.5 | AK26: =SUM(F26:AJ26) -> 22839
E27: Total by day | F27: =SUM(F22:F26) -> 34987.5 | G27: =SUM(G22:G26) -> 36594 | H27: =SUM(H22:H26) -> 32709.75 | I27: =SUM(I22:I26) -> 32669.25 | J27: =SUM(J22:J26) -> 31549.5 | K27: =SUM(K22:K26) -> 33361.5 | L27: =SUM(L22:L26) -> 36570.75 | M27: =SUM(M22:M26) -> 0 | ... AK27: =SUM(AK22:AK26) -> 238442.25
B28: TOTAL | E28: PAF(BCM) | F28: =F4 -> 4489.5 | G28: =G4 -> 4386 | H28: =H4 -> 3888 | I28: =I4 -> 16129.5 | J28: =J4 -> 11241 | K28: =K4 -> 8989.5 | L28: =L4 -> 19191 | M28: =M4 -> 0 | ... AJ28: =AJ4 -> 0 | AK28: =SUM(F28:AJ28) -> 68314.5 | AL28: =AL4 -> 19191
E29: NAF(BCM) | F29: =F5 -> 21678 | G29: =G5 -> 26761.5 | H29: =H5 -> 25450.5 | I29: =I5 -> 10998 | J29: =J5 -> 16753.5 | K29: =K5 -> 20683.5 | L29: =L5 -> 15792 | M29: =M5 -> 0 | ... AJ29: =AJ5 -> 0 | AK29: =SUM(F29:AJ29) -> 138117 | AL29: =AL5 -> 15792
E30: MUD (BCM) | F30: =F6 -> 1318.5 | G30: =G6 -> 0 | H30: =H6 -> 1956.75 | I30: =I6 -> 1575.75 | J30: =J6 -> 2706 | K30: =K6 -> 1297.5 | L30: =L6 -> 317.25 | M30: =M6 -> 0 | ... AJ30: =AJ6 -> 0 | AK30: =SUM(F30:AJ30) -> 9171.75 | AL30: =AL6 -> 317.25
E31: HAC (BCM) | F31: =F7 -> 0 | G31: =G7 -> 0 | H31: =H7 -> 0 | I31: =I7 -> 0 | J31: =J7 -> 0 | K31: =K7 -> 0 | L31: =L7 -> 0 | M31: =M7 -> 0 | ... AJ31: =AJ7 -> 0 | AK31: =SUM(F31:AJ31) -> 0 | AL31: =AL7 -> 0
E32: Top Soil (BCM) | F32: =F8 -> 7501.5 | G32: =G8 -> 5446.5 | H32: =H8 -> 1414.5 | I32: =I8 -> 3966 | J32: =J8 -> 849 | K32: =K8 -> 2391 | L32: =L8 -> 1270.5 | M32: =M8 -> 0 | ... AJ32: =AJ8 -> 0 | AK32: =SUM(F32:AJ32) -> 22839 | AL32: =AL8 -> 1270.5
E33: Outpit (BCM) | F33: =+F15 -> 0 | G33: =+G15 -> 0 | H33: =+H15 -> 0 | I33: =+I15 -> 709.5 | J33: =+J15 -> 594 | K33: =+K15 -> 2004 | L33: =+L15 -> 0 | M33: =+M15 -> 0 | ... AJ33: =+AJ15 -> 0 | AK33: =SUM(F33:AJ33) -> 3307.5 | AT33: =F$125 -> 0 | AU33: =G$125 -> 0 | AV33: =H$125 -> 0 | AW33: =I$125 -> 0 | AX33: =J$125 -> 0 | AY33: =K$125 -> 0 | AZ33: =L$125 -> 0 | BA33: =M$125 -> 0 | ... BX33: =AJ$125 -> 0
E34: Total by day | F34: =SUM(F28:F33) -> 34987.5 | G34: =SUM(G28:G33) -> 36594 | H34: =SUM(H28:H33) -> 32709.75 | I34: =SUM(I28:I33) -> 33378.75 | J34: =SUM(J28:J33) -> 32143.5 | K34: =SUM(K28:K33) -> 35365.5 | L34: =SUM(L28:L33) -> 36570.75 | M34: =SUM(M28:M33) -> 0 | ... AK34: =SUM(AK28:AK33) -> 241749.75 | AL34: =SUM(AL28:AL32) -> 36570.75 | AM34: =HLOOKUP(LEFT(Summary!D3,2),Actual!F3:AJ34,6,FALSE) -> 1270.5
C36: OB katal - katal
C37: Total day ---> | E37: =E3 -> 30 | F37: 01 | G37: 02 | H37: 03 | I37: 04 | J37: 05 | K37: 06 | L37: 07 | M37: 08 | N37: 09 | O37: 10 | P37: 11 | Q37: 12 | R37: 13 | S37: 14 | T37: 15 | U37: 16 | V37: 17 | W37: 18 | X37: 19 | Y37: 20 | Z37: 21 | AA37: 22 | AB37: 23 | AC37: 24 | AD37: 25 | AE37: 26 | AF37: 27 | AG37: 28 | AH37: 29 | AI37: 30 | AJ37: 31 | AK37: Total by Clasification | AL37: EOP by clasification
C38: ARKA | E38: PAF(BCM) | AE38: 0 | AF38: 0 | AG38: 0 | AH38: 0 | AI38: 0 | AJ38: 0 | AK38: =SUM(F38:AJ38) -> 0 | AL38: =HLOOKUP(LEFT(Summary!C88,2),Actual!F37:AJ41,2,FALSE) -> #N/A
E39: NAF(BCM) | V39: 0 | W39: 0 | X39: 0 | Y39: 0 | Z39: 0 | AA39: 0 | AB39: 0 | AC39: 0 | AD39: 0 | AE39: 0 | AF39: 0 | AG39: 0 | AH39: 0 | AI39: 0 | AJ39: 0 | AK39: =SUM(F39:AJ39) -> 0
E40: Top Soil (BCM) | V40: 0 | W40: 0 | X40: 0 | Y40: 0 | Z40: 0 | AA40: 0 | AB40: 0 | AC40: 0 | AD40: 0 | AE40: 0 | AF40: 0 | AG40: 0 | AH40: 0 | AI40: 0 | AJ40: 0 | AK40: =SUM(F40:AJ40) -> 0
E41: Total by day | F41: =SUM(F38:F40) -> 0 | G41: =SUM(G38:G40) -> 0 | H41: =SUM(H38:H40) -> 0 | I41: =SUM(I38:I40) -> 0 | J41: =SUM(J38:J40) -> 0 | K41: =SUM(K38:K40) -> 0 | L41: =SUM(L38:L40) -> 0 | M41: =SUM(M38:M40) -> 0 | ... AK41: =SUM(AK38:AK40) -> 0
E42: PAF(BCM) | AK42: =SUM(F42:AJ42) -> 0 | AL42: =SUM(AK42:AK44) -> 0
...

Sheet Equipment 
A3: Date | B3: Equipment
B4: Shift 1 (06:00-18:00) | L4: Shift 2 (18:00-06:00) | Y4: Date | Z4: DT IWJ | AB4: DT SLS | AD4: DT ARKA | AF4: Total | AH4: EXC COAL | AI4: Rom Production (Ton) | AJ4: Rom Prod MtD (Ton)
B5: Exc. OB | C5: DT OB | D5: ADT OB | E5: OHT OB | F5: Exc. Coal | G5: DT Coal | H5: Dozer | I5: Gradder | J5: Compactor | K5: W.Truck | L5: Exc.OB | M5: DT OB | N5: ADT OB | O5: OHT OB | P5: Exc. Coal | Q5: DT Coal | R5: Dozer | S5: Gradder | T5: Compactor | U5: W.Truck | Z5: shift 1 | AA5: shift 2 | AB5: shift 1 | AC5: shift 2 | AD5: shift 1 | AE5: shift 2 | AF5: shift 1 | AG5: shift 2
A6: 01-Sep-26 | B6: =3.11902537103542+1.2362257689716 -> 4.3552511 | D6: 13.29414 | E6: 0.85294118 | F6: 0 | G6: =AB6+AD6+Z6 -> 0 | H6: 2.6495559 | I6: 0.93333333 | J6: 0 | K6: 1.675 | L6: =1.78333333333345+1.66269994027849 -> 3.4460333 | N6: 13.983967 | O6: 0.91666667 | P6: 0 | Q6: =AC6+AE6+AA6 -> 0 | R6: 2.6869565 | S6: 0.96666667 | T6: 0 | U6: 1.4833333 | Y6: =A6 -> 01-Sep-26 | AF6: =Z6+AB6+AD6 -> 0 | AG6: =AA6+AC6+AE6 -> 0 | AH6: =+MAX(VLOOKUP(A6,'Equipment '!$A$3:$U$36,6,FALSE),VLOOKUP(Y6,'Equipment '!$A$3:$U$36,16,FALSE)) -> 0 | AI6: =Actual!$F$156 -> 0 | AJ6: =AI6 -> 0
A7: 02-Sep-26 | B7: 3.9073318 | D7: 14.152725 | E7: 0.875 | F7: 0 | G7: =AB7+AD7+Z7 -> 0 | H7: 2.6719697 | I7: 0.86956522 | J7: 0 | K7: 2.5416667 | L7: =2.20989751887846+1.81046497212361 -> 4.0203625 | N7: 15.05008 | O7: 1.7112745 | P7: 0 | Q7: =AC7+AE7+AA7 -> 0 | R7: 2.7231997 | S7: 0.95 | T7: 0 | U7: 1.475 | Y7: =A7 -> 02-Sep-26 | AF7: =Z7+AB7+AD7 -> 0 | AG7: =AA7+AC7+AE7 -> 0 | AH7: =+MAX(VLOOKUP(A7,'Equipment '!$A$3:$U$36,6,FALSE),VLOOKUP(Y7,'Equipment '!$A$3:$U$36,16,FALSE)) -> 0 | AI7: =Actual!$G$156 -> 0 | AJ7: =AJ6+AI7 -> 0
A8: 03-Sep-26 | B8: =3.01868686868651+1.22154589269854 -> 4.2402328 | D8: 14.120055 | E8: 1.708628 | F8: 0 | G8: =AB8+AD8+Z8 -> 0 | H8: 1.8125 | I8: 0.87288136 | J8: 0.41666667 | K8: 2.575 | L8: =2.03173568396455+1.79608057196674 -> 3.8278163 | N8: 14.82369 | O8: 0.84042553 | P8: 0 | Q8: =AC8+AE8+AA8 -> 0 | R8: 1.8416667 | S8: 0.94166667 | T8: 0 | U8: 1.3666667 | Y8: =A8 -> 03-Sep-26 | AF8: =Z8+AB8+AD8 -> 0 | AG8: =AA8+AC8+AE8 -> 0 | AH8: =+MAX(VLOOKUP(A8,'Equipment '!$A$3:$U$36,6,FALSE),VLOOKUP(Y8,'Equipment '!$A$3:$U$36,16,FALSE)) -> 0 | AI8: =Actual!$H$156 -> 0 | AJ8: =AJ7+AI8 -> 0
A9: 04-Sep-26 | B9: =2.71412769722954+1.58992811098242 -> 4.3040558 | D9: 15.012545 | E9: 1.6833333 | F9: 0 | G9: =AB9+AD9+Z9 -> 0 | H9: 1.825 | I9: 0.87068966 | J9: 0.16666667 | K9: 2.1416667 | L9: =1.77959770114934+1.36535087719303 -> 3.1449486 | N9: 14.351624 | O9: 1.7160714 | P9: 0 | Q9: =AC9+AE9+AA9 -> 0 | R9: 1.825 | S9: 0.925 | T9: 0 | U9: 1.425 | Y9: =A9 -> 04-Sep-26 | AF9: =Z9+AB9+AD9 -> 0 | AG9: =AA9+AC9+AE9 -> 0 | AH9: =+MAX(VLOOKUP(A9,'Equipment '!$A$3:$U$36,6,FALSE),VLOOKUP(Y9,'Equipment '!$A$3:$U$36,16,FALSE)) -> 0 | AI9: =Actual!$I$156 -> 0 | AJ9: =AJ8+AI9 -> 0
A10: 05-Sep-26 | B10: =3.0183333333334+1 -> 4.0183333 | D10: 15.867088 | E10: 1.8 | F10: =1.96526508897449-1 -> 0.96526509 | G10: =AB10+AD10+Z10 -> 10 | H10: 1.8145174 | I10: 0.87288136 | J10: 0 | K10: 1.8166667 | L10: 2.6509489 | N10: 14.718949 | O10: 1.689548 | P10: 0.47598253 | Q10: =AC10+AE10+AA10 -> 0 | R10: 1.5490196 | S10: 0.86842105 | T10: 0 | U10: 1.2666667 | Y10: =A10 -> 05-Sep-26 | AD10: 10 | AF10: =Z10+AB10+AD10 -> 10 | AG10: =AA10+AC10+AE10 -> 0 | AH10: =+MAX(VLOOKUP(A10,'Equipment '!$A$3:$U$36,6,FALSE),VLOOKUP(Y10,'Equipment '!$A$3:$U$36,16,FALSE)) -> 0.96526509 | AI10: =Actual!$J$156 -> 1312.898 | AJ10: =AJ9+AI10 -> 1312.898
A11: 06-Sep-26 | B11: =3.33912429378531+0.732951445717406 -> 4.0720757 | D11: 15.558978 | E11: 1.7278325 | F11: 0 | G11: =AB11+AD11+Z11 -> 0 | H11: 1.8156162 | I11: 0.86725664 | J11: 0 | K11: 2.490506 | L11: =3.56902515723281+0.570372976776951 -> 4.1393981 | N11: 15.595785 | O11: 1.7333333 | P11: 0 | Q11: =AC11+AE11+AA11 -> 0 | R11: 1.9416667 | S11: 0.98333333 | T11: 0 | U11: 0.725 | Y11: =A11 -> 06-Sep-26 | AF11: =Z11+AB11+AD11 -> 0 | AG11: =AA11+AC11+AE11 -> 0 | AH11: =+MAX(VLOOKUP(A11,'Equipment '!$A$3:$U$36,6,FALSE),VLOOKUP(Y11,'Equipment '!$A$3:$U$36,16,FALSE)) -> 0 | AI11: =Actual!$K$156 -> 0 | AJ11: =AJ10+AI11 -> 1312.898
A12: 07-Sep-26 | B12: 3.75 | D12: 12.716667 | E12: 1.7583333 | F12: 0 | G12: =AB12+AD12+Z12 -> 0 | H12: 1.6083333 | I12: 0.81666667 | J12: 0 | K12: 2.5333333 | L12: 4.5583333 | N12: 13.925 | O12: 1.6166667 | Q12: =AC12+AE12+AA12 -> 0 | R12: 1.9333333 | S12: 0.96666667 | T12: 0 | U12: 0.89166667 | Y12: =A12 -> 07-Sep-26 | AF12: =Z12+AB12+AD12 -> 0 | AG12: =AA12+AC12+AE12 -> 0 | AH12: =+MAX(VLOOKUP(A12,'Equipment '!$A$3:$U$36,6,FALSE),VLOOKUP(Y12,'Equipment '!$A$3:$U$36,16,FALSE)) -> 0 | AI12: =Actual!$L$156 -> 0 | AJ12: =AJ11+AI12 -> 1312.898
A13: 08-Sep-26 | G13: =AB13+AD13+Z13 -> 0 | Q13: =AC13+AE13+AA13 -> 0 | Y13: =A13 -> 08-Sep-26 | AF13: =Z13+AB13+AD13 -> 0 | AG13: =AA13+AC13+AE13 -> 0 | AH13: =+MAX(VLOOKUP(A13,'Equipment '!$A$3:$U$36,6,FALSE),VLOOKUP(Y13,'Equipment '!$A$3:$U$36,16,FALSE)) -> 0 | AI13: =Actual!$M$156 -> 0 | AJ13: =AJ12+AI13 -> 1312.898
A14: 09-Sep-26 | G14: =AB14+AD14+Z14 -> 0 | Q14: =AC14+AE14+AA14 -> 0 | Y14: =A14 -> 09-Sep-26 | AF14: =Z14+AB14+AD14 -> 0 | AG14: =AA14+AC14+AE14 -> 0 | AH14: =+MAX(VLOOKUP(A14,'Equipment '!$A$3:$U$36,6,FALSE),VLOOKUP(Y14,'Equipment '!$A$3:$U$36,16,FALSE)) -> 0 | AI14: =Actual!$N$156 -> 0 | AJ14: =AJ13+AI14 -> 1312.898
A15: 10-Sep-26 | G15: =AB15+AD15+Z15 -> 0 | Q15: =AC15+AE15+AA15 -> 0 | Y15: =A15 -> 10-Sep-26 | AF15: =Z15+AB15+AD15 -> 0 | AG15: =AA15+AC15+AE15 -> 0 | AH15: =+MAX(VLOOKUP(A15,'Equipment '!$A$3:$U$36,6,FALSE),VLOOKUP(Y15,'Equipment '!$A$3:$U$36,16,FALSE)) -> 0 | AI15: =Actual!$O$156 -> 0 | AJ15: =AJ14+AI15 -> 1312.898
A16: 11-Sep-26 | G16: =AB16+AD16+Z16 -> 0 | Q16: =AC16+AE16+AA16 -> 0 | Y16: =A16 -> 11-Sep-26 | AF16: =Z16+AB16+AD16 -> 0 | AG16: =AA16+AC16+AE16 -> 0 | AH16: =+MAX(VLOOKUP(A16,'Equipment '!$A$3:$U$36,6,FALSE),VLOOKUP(Y16,'Equipment '!$A$3:$U$36,16,FALSE)) -> 0 | AI16: =Actual!$P$156 -> 0 | AJ16: =AJ15+AI16 -> 1312.898
A17: 12-Sep-26 | G17: =AB17+AD17+Z17 -> 0 | Q17: =AC17+AE17+AA17 -> 0 | Y17: =A17 -> 12-Sep-26 | AF17: =Z17+AB17+AD17 -> 0 | AG17: =AA17+AC17+AE17 -> 0 | AH17: =+MAX(VLOOKUP(A17,'Equipment '!$A$3:$U$36,6,FALSE),VLOOKUP(Y17,'Equipment '!$A$3:$U$36,16,FALSE)) -> 0 | AI17: =Actual!$Q$156 -> 0 | AJ17: =AJ16+AI17 -> 1312.898
A18: 13-Sep-26 | G18: =AB18+AD18+Z18 -> 0 | Q18: =AC18+AE18+AA18 -> 0 | Y18: =A18 -> 13-Sep-26 | AF18: =Z18+AB18+AD18 -> 0 | AG18: =AA18+AC18+AE18 -> 0 | AH18: =+MAX(VLOOKUP(A18,'Equipment '!$A$3:$U$36,6,FALSE),VLOOKUP(Y18,'Equipment '!$A$3:$U$36,16,FALSE)) -> 0 | AI18: =Actual!$R$156 -> 0 | AJ18: =AJ17+AI18 -> 1312.898
A19: 14-Sep-26 | G19: =AB19+AD19+Z19 -> 0 | Q19: =AC19+AE19+AA19 -> 0 | Y19: =A19 -> 14-Sep-26 | AF19: =Z19+AB19+AD19 -> 0 | AG19: =AA19+AC19+AE19 -> 0 | AH19: =+MAX(VLOOKUP(A19,'Equipment '!$A$3:$U$36,6,FALSE),VLOOKUP(Y19,'Equipment '!$A$3:$U$36,16,FALSE)) -> 0 | AI19: =Actual!$S$156 -> 0 | AJ19: =AJ18+AI19 -> 1312.898
A20: 15-Sep-26 | G20: =AB20+AD20+Z20 -> 0 | Q20: =AC20+AE20+AA20 -> 0 | Y20: =A20 -> 15-Sep-26 | AF20: =Z20+AB20+AD20 -> 0 | AG20: =AA20+AC20+AE20 -> 0 | AH20: =+MAX(VLOOKUP(A20,'Equipment '!$A$3:$U$36,6,FALSE),VLOOKUP(Y20,'Equipment '!$A$3:$U$36,16,FALSE)) -> 0 | AI20: =Actual!$T$156 -> 0 | AJ20: =AJ19+AI20 -> 1312.898
A21: 16-Sep-26 | G21: =AB21+AD21+Z21 -> 0 | Y21: =A21 -> 16-Sep-26 | AF21: =Z21+AB21+AD21 -> 0 | AG21: =AA21+AC21+AE21 -> 0 | AH21: =+MAX(VLOOKUP(A21,'Equipment '!$A$3:$U$36,6,FALSE),VLOOKUP(Y21,'Equipment '!$A$3:$U$36,16,FALSE)) -> 0 | AI21: =Actual!$U$156 -> 0 | AJ21: =AJ20+AI21 -> 1312.898
A22: 17-Sep-26 | G22: =AB22+AD22+Z22 -> 0 | Q22: =AC22+AE22+AA22 -> 0 | Y22: =A22 -> 17-Sep-26 | AF22: =Z22+AB22+AD22 -> 0 | AG22: =AA22+AC22+AE22 -> 0 | AH22: =+MAX(VLOOKUP(A22,'Equipment '!$A$3:$U$36,6,FALSE),VLOOKUP(Y22,'Equipment '!$A$3:$U$36,16,FALSE)) -> 0 | AI22: =Actual!$V$156 -> 0 | AJ22: =AJ21+AI22 -> 1312.898
A23: 18-Sep-26 | G23: =AB23+AD23+Z23 -> 0 | Q23: =AC23+AE23+AA23 -> 0 | Y23: =A23 -> 18-Sep-26 | AF23: =Z23+AB23+AD23 -> 0 | AG23: =AA23+AC23+AE23 -> 0 | AH23: =+MAX(VLOOKUP(A23,'Equipment '!$A$3:$U$36,6,FALSE),VLOOKUP(Y23,'Equipment '!$A$3:$U$36,16,FALSE)) -> 0 | AI23: =Actual!$W$156 -> 0 | AJ23: =AJ22+AI23 -> 1312.898
A24: 19-Sep-26 | G24: =AB24+AD24+Z24 -> 0 | Q24: =AC24+AE24+AA24 -> 0 | Y24: =A24 -> 19-Sep-26 | AF24: =Z24+AB24+AD24 -> 0 | AG24: =AA24+AC24+AE24 -> 0 | AH24: =+MAX(VLOOKUP(A24,'Equipment '!$A$3:$U$36,6,FALSE),VLOOKUP(Y24,'Equipment '!$A$3:$U$36,16,FALSE)) -> 0 | AI24: =Actual!$X$156 -> 0 | AJ24: =AJ23+AI24 -> 1312.898
A25: 20-Sep-26 | G25: =AB25+AD25+Z25 -> 0 | Q25: =AC25+AE25+AA25 -> 0 | Y25: =A25 -> 20-Sep-26 | AF25: =Z25+AB25+AD25 -> 0 | AG25: =AA25+AC25+AE25 -> 0 | AH25: =+MAX(VLOOKUP(A25,'Equipment '!$A$3:$U$36,6,FALSE),VLOOKUP(Y25,'Equipment '!$A$3:$U$36,16,FALSE)) -> 0 | AI25: =Actual!$Y$156 -> 0 | AJ25: =AJ24+AI25 -> 1312.898
A26: 21-Sep-26 | G26: =AB26+AD26+Z26 -> 0 | Q26: =AC26+AE26+AA26 -> 0 | Y26: =A26 -> 21-Sep-26 | AF26: =Z26+AB26+AD26 -> 0 | AG26: =AA26+AC26+AE26 -> 0 | AH26: =+MAX(VLOOKUP(A26,'Equipment '!$A$3:$U$36,6,FALSE),VLOOKUP(Y26,'Equipment '!$A$3:$U$36,16,FALSE)) -> 0 | AI26: =Actual!$Z$156 -> 0 | AJ26: =AJ25+AI26 -> 1312.898
