Workbook
Name basd: {#N/A,#N/A,FALSE,"M01";#N/A,#N/A,FALSE,"M02";#N/A,#N/A,FALSE,"M03";#N/A,#N/A,FALSE,"M04";#N/A,#N/A,FALSE,"M05";#N/A,#N/A,FALSE,"M08"}
Name basd_1: {#N/A,#N/A,FALSE,"M01";#N/A,#N/A,FALSE,"M02";#N/A,#N/A,FALSE,"M03";#N/A,#N/A,FALSE,"M04";#N/A,#N/A,FALSE,"M05";#N/A,#N/A,FALSE,"M08"}
Name basd_2: {#N/A,#N/A,FALSE,"M01";#N/A,#N/A,FALSE,"M02";#N/A,#N/A,FALSE,"M03";#N/A,#N/A,FALSE,"M04";#N/A,#N/A,FALSE,"M05";#N/A,#N/A,FALSE,"M08"}
Name BusinessUnit_10: NA()
Name BusinessUnit_2: NA()
Name Company_2: NA()
Name CostCenter_10: NA()
Name CostCenter_2: NA()
Name cxvx: {#N/A,#N/A,FALSE,"M01";#N/A,#N/A,FALSE,"M02";#N/A,#N/A,FALSE,"M03";#N/A,#N/A,FALSE,"M04";#N/A,#N/A,FALSE,"M05";#N/A,#N/A,FALSE,"M08"}
Name cxvx_1: {#N/A,#N/A,FALSE,"M01";#N/A,#N/A,FALSE,"M02";#N/A,#N/A,FALSE,"M03";#N/A,#N/A,FALSE,"M04";#N/A,#N/A,FALSE,"M05";#N/A,#N/A,FALSE,"M08"}
Name cxvx_2: {#N/A,#N/A,FALSE,"M01";#N/A,#N/A,FALSE,"M02";#N/A,#N/A,FALSE,"M03";#N/A,#N/A,FALSE,"M04";#N/A,#N/A,FALSE,"M05";#N/A,#N/A,FALSE,"M08"}
Name Image_SNS: INDEX(#REF!,MATCH(#REF!,#REF!,0))
Name Image_SNS: INDEX(#REF!,MATCH(#REF!,#REF!,0))
Name Image_SNS: INDEX(#REF!,MATCH(#REF!,#REF!,0))
Name Image_TJP: INDEX(#REF!,MATCH(#REF!,#REF!,0))
Name Image_TJP: INDEX(#REF!,MATCH(#REF!,#REF!,0))
Name Image_TJP: INDEX(#REF!,MATCH(#REF!,#REF!,0))
Name Slicer_Day: #N/A
Name Weat_Ico: INDEX(Weat_Con!$C$2:$C$3,MATCH(Weat_Con!$B$5,Weat_Con!$B$2:$B$3,0))
Name weather_ImgS: INDEX(#REF!,MATCH(#REF!,#REF!,0))

Sheet Dashboard
AV4: =Actual!AJ355 -> #DIV/0! | AW4: 2000
AV5: =Outlook!AJ6 -> 275870 | AW5: =AV5-Summary!E4 -> 275870
AR6: Yearly | AS6: Actual
D7: Data Report | F7: =TEXT(H7,"dddd") -> Monday | G7: , | H7: =Summary!D3 -> 07 Sept-26 | AR7: OB | AS7: =Summary!Q4/Summary!W4 -> 0 | AT7: =1-AS7 -> 1 | AV7: =(Dashboard!AV5-AW5)/Dashboard!AV5 -> 0 | AW7: 0 | AX7: OB UCEX
AR8: ROM | AS8: =Summary!Q5/Summary!W5 -> 0 | AT8: =1-AS8 -> 1 | AV8: =AX16+AX14 -> #VALUE! | AW8: 0 | AX8: OB U210
F9: Monthly | N9: =MID(Actual!C2,13,20) -> Sep'26 | AR9: FC | AS9: =Summary!Q8/Summary!W8 -> 0 | AT9: =1-AS9 -> 1 | AV9: 0 | AW9: 0 | AX9: ROM M45C
F10: Today | H10: MTD | J10: Plan | L10: % Diff | N10: Outlook | P10: Budget | AR10: Loading | AS10: =Summary!Q9/Summary!W9 -> 0 | AT10: =1-AS10 -> 1 | AV10: 0 | AW10: 0 | AX10: ROM U210
D12: WASTE REMOVAL | F12: =Summary!$D$4 -> 0 | H12: =Summary!$E$4 -> 0 | J12: =Summary!F4 -> 0 | L12: =IF(J12<=0,0,(H12-J12)/J12) -> 0 | N12: =Summary!J4 -> 0 | P12: =Summary!K4 -> 424996
D14: ROM PRODUCTION | F14: =Summary!$D$5 -> 0 | H14: =Summary!$E$5 -> 0 | J14: =Summary!$F$4 -> 0 | L14: =IF(J14<=0,0,(H14-J14)/J14) -> 0 | N14: =Summary!$J$5 -> 0 | P14: =Summary!$K$5 -> 65645 | AR14: Monthly | AX14: =IFERROR(((AV4-AW4)/AV4),"")
D16: SR | F16: =Summary!$D$6 -> 0 | H16: =Summary!$E$6 -> 0 | J16: =Summary!$F$6 -> 0 | L16: =IF(J16<=0,0,(H16-J16)/J16) -> 0 | N16: =Summary!$J$6 -> 0 | P16: =Summary!$K$6 -> 6.4741564 | AR16: OB | AS16: 0 | AT16: 1 | AU16: =1-AS16 -> 1 | AX16: 1
AX17: =AX14
D18: CRUSHED COAL | F18: =Summary!$D$8 -> 0 | H18: =Summary!$E$8 -> 0 | J18: =Summary!$F$8 -> 0 | L18: =IF(J18<=0,0,(H18-J18)/J18) -> 0 | N18: =Summary!$J$8 -> 0 | P18: =Summary!$K$8 -> 75000 | AR18: ROM | AS18: 0 | AT18: =IF(1-AS18<0,0,AU18) -> 1 | AU18: =1-AS18 -> 1 | AX18: 1
D20: BARGE LOADING | F20: =Summary!$D$9 -> 0 | H20: =Summary!$E$9 -> 0 | J20: =Summary!$F$9 -> 0 | L20: =IF(J20<=0,0,(H20-J20)/J20) -> 0 | N20: =Summary!$J$9 -> 0 | P20: =Summary!$K$9 -> 73000
D22: ROM STOCK | F22: =Summary!$D$7 -> 351.37 | H22: =Summary!$E$7 -> 351.37 | J22: =Summary!$F$7 -> 351.37 | L22: =IF(J22<=0,0,(H22-J22)/J22) -> 0 | N22: =Summary!$J$7 -> 351.37 | P22: =Summary!$K$7 -> 12353 | AR22: Road to Bonus Q1
D24: FC STOCK | F24: =Summary!$D$10 -> 1370.339 | H24: =Summary!$E$10 -> 1370.339 | J24: =Summary!$F$10 -> 1370 | L24: =IF(J24<=0,0,(H24-J24)/J24) -> 0.00024744526 | N24: =Summary!$J$10 -> 1370 | P24: =Summary!$K$10 -> 24556 | AR24: ROM Prod | AS24: =SUM(Budget!E5:G5) -> 0 | AT24: =Summary!E5 -> 0 | AU24: =AT24/AS24 -> #DIV/0! | AV24: =1-AU24 -> #DIV/0!
F26: DATA WEATHER | AR26: FC Production | AS26: =SUM(Budget!E8:G8) -> 0 | AT26: =Summary!E8 -> 0 | AU26: =AT26/AS26 -> #DIV/0! | AV26: =1-AU26 -> #DIV/0!
D28: RAINFALL | F28: =Summary!$D$12 -> 0 | H28: =Summary!$E$12 -> 0 | J28: =Summary!$F$12 -> 41.725822 | L28: =IF(J28<=0,0,(H28-J28)/J28) -> -1 | N28: =Summary!$J$12 -> 178.82495 | P28: =Summary!$K$12 -> 178.82495
F30: =Summary!$D$13 -> 0 | H30: =Summary!$E$13 -> 0 | J30: =Summary!$F$13 -> 9.6576667 | L30: =IF(J30<=0,0,(H30-J30)/J30) -> -1 | N30: =Summary!$J$13 -> 41.39 | P30: =Summary!$K$13 -> 41.39
D32: SLIPPERY | F32: =Summary!$D$14 -> 0 | H32: =Summary!$E$14 -> 0 | J32: =Summary!$F$14 -> 12.324667 | L32: =IF(J32<=0,0,(H32-J32)/J32) -> -1 | N32: =Summary!$J$14 -> 52.82 | P32: =Summary!$K$14 -> 52.82 | AR32: E-UCE | AT32: 22170 | AU32: 22170
AU33: =(AT32-AU32)/AT32 -> 0
F34: CONTRACTOR PERFORMANCE
F36: TODAY | H36: MTD | I36: ACHIEVEMENT | M36: PLAN | P36: % Diff
D38: OB | E38: UCEX | F38: =Actual!AN36 -> 0 | H38: =Actual!AK36 -> 0
D40: Dist | E40: UCEX | F40: =Actual!$AL$355 -> 0 | H40: =IFERROR(Actual!$AJ$355," ")
D42: TS | E42: NURSERY | F42: =Actual!AM42 -> 634.5 | H42: =Actual!AK42 -> 3780
D44: OB | E44: M45C | F44: =Actual!AM47 -> 0 | H44: =Actual!AK47 -> 1030.5
D46: TS | E46: M4EW | F46: =Actual!AM31 -> 1174.5 | H46: =Actual!AK31 -> 4711.5
F48: 0 | H48: =Summary!E37 -> 0
F50: - Number Outlook already used Number New Month Outlook
F51: - No production due to temporary standby (PIT) until further information

Sheet Summary
D2: Yesterday | E2: =MID(Actual!C2,13,6) -> Sep'26 | J2: Total Month | M2: Quarterly III | Q2: YTD | V2: Total Year
D3: 07 Sept-26 | E3: MTD | F3: Plan | G3: %Diff | H3: Budget | I3: =G3 -> %Diff | J3: Outlook | K3: Budget | L3: %Diff | M3: Actual | N3: Outlook | O3: Budget | P3: %Diff | Q3: Actual | R3: Outlook | S3: =G3 -> %Diff | T3: =H3 -> Budget | U3: =G3 -> %Diff | V3: Act + Outlook | W3: =H3 -> Budget | X3: %Diff
B4: Waste removal | C4: BCM | D4: =Actual!AM36 -> 0 | E4: =SUM(Actual!F32:AJ35) -> 0 | F4: =((HLOOKUP(E$2,Outlook!$F$3:$Q$25,MATCH(B4,Outlook!$B$3:$B$25,0),FALSE))/Actual!E3)*(MID(D$3,1,2)) -> 0 | G4: =IF(F4<=0,0,(E4-F4)/F4) -> 0 | H4: =((HLOOKUP(E$2,Budget!$E$3:$P$15,MATCH(B4,Budget!$B$3:$B$15,0),FALSE))/Actual!$E$3)*(MID(D$3,1,2)) -> 99165.733 | I4: =IF(H4<=0,0,(E4-H4)/H4) -> -1 | J4: =(HLOOKUP(E$2,Outlook!$F$3:$Q$25,MATCH(B4,Outlook!$B$3:$B$25,0),FALSE)) -> 0 | K4: =HLOOKUP(E$2,Budget!$E$3:$P$15,MATCH(B4,Budget!$B$3:$B$15,0),FALSE) -> 424996 | L4: =IF(K4<=0,0,(J4-K4)/K4) -> -1 | M4: =(SUMIF(Outlook!$O$2:$Q$2,"Actual",Outlook!$O$4:$Q$4))+$E$4 -> 0 | N4: =(SUMIF(Outlook!$O$2:$Q$2,"ACTUAL",Outlook!O4:Q4))+F4 -> 0 | O4: =(SUMIF(Budget!$K$2:$M$2,"PLANED",Budget!K4:M4))+H4 -> 904193.73 | P4: =IF(O4<=0,0,(M4-O4)/O4) -> -1 | Q4: =(SUMIF(Outlook!$F$2:$Q$2,"actual",Outlook!$F$4:$Q$4))+$E$4 -> 0 | R4: =(SUMIF(Outlook!$F$2:$Q$2,"ACTUAL",Outlook!F4:Q4))+F4 -> 0 | S4: =IF(R4<=0,0,(Q4-R4)/R4) -> 0 | T4: =(SUMIF(Budget!$E$2:$P$2,"PLANED",Budget!E4:P4))+H4 -> 2159773.7 | U4: =IF(T4<=0,0,(Q4-T4)/T4) -> -1 | V4: =Outlook!R4 -> 1402970 | W4: =Budget!Q4 -> 3407767 | X4: =IF(W4<=0,0,(V4-W4)/W4) -> -0.58830225
B5: ROM production | C5: Ton | D5: =Actual!AM157 -> 0 | E5: =SUM(Actual!F157:AJ157) -> 0 | F5: =((HLOOKUP(E$2,Outlook!$F$3:$Q$25,MATCH(B5,Outlook!$B$3:$B$25,0),FALSE))/Actual!E3)*(MID(D$3,1,2)) -> 0 | G5: =IF(F5<=0,0,(E5-F5)/F5) -> 0 | H5: =((HLOOKUP(E$2,Budget!$E$3:$P$15,MATCH(B5,Budget!$B$3:$B$15,0),FALSE))/Actual!$E$3)*(MID(D$3,1,2)) -> 15317.167 | I5: =IF(H5<=0,0,(E5-H5)/H5) -> -1 | J5: =(HLOOKUP(E$2,Outlook!$F$3:$Q$25,MATCH(B5,Outlook!$B$3:$B$25,0),FALSE)) -> 0 | K5: =HLOOKUP(E$2,Budget!$E$3:$P$15,MATCH(B5,Budget!$B$3:$B$15,0),FALSE) -> 65645 | L5: =IF(K5<=0,0,(J5-K5)/K5) -> -1 | M5: =(SUMIF(Outlook!$O$2:$Q$2,"Actual",Outlook!$O$4:$Q$4))+$E$4 -> 0 | N5: =(SUMIF(Outlook!$K$2:$M$2,"ACTUAL",Outlook!I5:K5))+F5 -> 0 | O5: =(SUMIF(Budget!$K$2:$M$2,"PLANED",Budget!K5:M5))+H5 -> 143842.17 | P5: =IF(O5<=0,0,(M5-O5)/O5) -> -1 | Q5: =(SUMIF(Outlook!$F$2:$Q$2,"actual",Outlook!$F$5:$Q$5))+E5 -> 0 | R5: =(SUMIF(Outlook!$F$2:$Q$2,"ACTUAL",Outlook!F5:Q5))+F5 -> 0 | S5: =IF(R5<=0,0,(Q5-R5)/R5) -> 0 | T5: =(SUMIF(Budget!$E$2:$P$2,"PLANED",Budget!E5:P5))+H5 -> 265592.17 | U5: =IF(T5<=0,0,(Q5-T5)/T5) -> -1 | V5: =Outlook!R5 -> 158989 | W5: =Budget!Q5 -> 539999 | X5: =IF(W5<=0,0,(V5-W5)/W5) -> -0.70557538
B6: Striping Ratio | C6: BCM/Ton | D6: =IF(OR(D4=0,D5=0),0,D4/D5) -> 0 | E6: =IF(OR(E4=0,E5=0),0,E4/E5) -> 0 | F6: =IF(OR(F4=0,F5=0),0,F4/F5) -> 0 | G6: =IF(F6<=0,0,(E6-F6)/F6) -> 0 | H6: =IF(OR(H4=0,H5=0),0,H4/H5) -> 6.4741564 | I6: =IF(H6<=0,0,(E6-H6)/H6) -> -1 | J6: =IF(OR(J4=0,J5=0),0,J4/J5) -> 0 | K6: =IF(OR(K4=0,K5=0),0,K4/K5) -> 6.4741564 | L6: =IF(K6<=0,0,(J6-K6)/K6) -> -1 | M6: =IF(OR(M4=0,M5=0),0,M4/M5) -> 0 | N6: =IF(OR(N4=0,N5=0),0,N4/N5) -> 0 | O6: =(SUMIF(Budget!$K$2:$M$2,"PLANED",Budget!K6:M6))+H6 -> 19.004626 | P6: =IF(O6<=0,0,(M6-O6)/O6) -> -1 | Q6: =IF(OR(Q4=0,Q5=0),0,Q4/Q5) -> 0 | R6: =IF(OR(R4=0,R5=0),0,R4/R5) -> 0 | S6: =IF(R6<=0,0,(Q6-R6)/R6) -> 0 | T6: =IF(OR(T4=0,T5=0),0,T4/T5) -> 8.131918 | U6: =IF(T6<=0,0,(Q6-T6)/T6) -> -1 | V6: =IF(OR(V4=0,V5=0),0,V4/V5) -> 8.8243212 | W6: =IF(OR(W4=0,W5=0),0,W4/W5) -> 6.3106913 | X6: =IF(W6<=0,0,(V6-W6)/W6) -> 0.39831292
B7: ROM stock | C7: Ton | D7: =Actual!AK231 -> 351.37 | E7: =Actual!AJ231 -> 351.37 | F7: =(HLOOKUP(E$2,Outlook!$F$3:$Q$25,MATCH(B7,Outlook!$B$3:$B$25,0),FALSE)) -> 351.37 | G7: =IF(F7<=0,0,(E7-F7)/F7) -> 0 | H7: =(HLOOKUP(E$2,Budget!$E$3:$P$15,MATCH(B7,Budget!$B$3:$B$15,0),FALSE)) -> 12353 | I7: =IF(H7<=0,0,(E7-H7)/H7) -> -0.9715559 | J7: =(HLOOKUP(E$2,Outlook!$F$3:$Q$25,MATCH(B7,Outlook!$B$3:$B$25,0),FALSE)) -> 351.37 | K7: =HLOOKUP(E$2,Budget!$E$3:$P$15,MATCH(B7,Budget!$B$3:$B$15,0),FALSE) -> 12353 | L7: =IF(K7<=0,0,(J7-K7)/K7) -> -0.9715559 | M7: =Actual!AK231 -> 351.37 | N7: =F7 -> 351.37 | O7: =H7 -> 12353 | P7: =IF(O7<=0,0,(M7-O7)/O7) -> -0.9715559 | Q7: =Actual!AK231 -> 351.37 | R7: =(HLOOKUP(E$2,Outlook!$F$3:$Q$25,MATCH(B7,Outlook!$B$3:$B$25,0),FALSE)) -> 351.37 | S7: =IF(R7<=0,0,(Q7-R7)/R7) -> 0 | T7: =(HLOOKUP(E$2,Budget!$E$3:$P$15,MATCH(B7,Budget!$B$3:$B$15,0),FALSE)) -> 12353 | U7: =IF(T7<=0,0,(Q7-T7)/T7) -> -0.9715559 | V7: =Outlook!Q7 -> 2970 | W7: =Budget!P7 -> 2160 | X7: =IF(W7<=0,0,(V7-W7)/W7) -> 0.375
B8: Crushed coal | C8: Ton | D8: =Actual!AK232 -> 0 | E8: =Actual!AJ232 -> 0 | F8: =((HLOOKUP(E$2,Outlook!$F$3:$Q$25,MATCH(B8,Outlook!$B$3:$B$25,0),FALSE))/Actual!E3)*(MID(D$3,1,2)) -> 0 | G8: =IF(F8<=0,0,(E8-F8)/F8) -> 0 | H8: =((HLOOKUP(E$2,Budget!$E$3:$P$15,MATCH(B8,Budget!$B$3:$B$15,0),FALSE))/Actual!$E$3)*(MID(D$3,1,2)) -> 17500 | I8: =IF(H8<=0,0,(E8-H8)/H8) -> -1 | J8: =(HLOOKUP(E$2,Outlook!$F$3:$Q$25,MATCH(B8,Outlook!$B$3:$B$25,0),FALSE)) -> 0 | K8: =HLOOKUP(E$2,Budget!$E$3:$P$15,MATCH(B8,Budget!$B$3:$B$15,0),FALSE) -> 75000 | L8: =IF(K8<=0,0,(J8-K8)/K8) -> -1 | M8: =(SUMIF(Outlook!$O$2:$Q$2,"Actual",Outlook!$O$4:$Q$4))+$E$4 -> 0 | N8: =(SUMIF(Outlook!$L$2:$N$2,"ACTUAL",Outlook!K8:M8))+F8 -> 0 | O8: =(SUMIF(Budget!$K$2:$M$2,"PLANED",Budget!K8:M8))+H8 -> 135500 | P8: =IF(O8<=0,0,(M8-O8)/O8) -> -1 | Q8: =(SUMIF(Outlook!$F$2:$Q$2,"actual",Outlook!$F$8:$Q$8))+E8 -> 0 | R8: =(SUMIF(Outlook!$F$2:$Q$2,"ACTUAL",Outlook!F8:Q8))+F8 -> 0 | S8: =IF(R8<=0,0,(Q8-R8)/R8) -> 0 | T8: =(SUMIF(Budget!$E$2:$P$2,"PLANED",Budget!E8:P8))+$H$8 -> 245501 | U8: =IF(T8<=0,0,(Q8-T8)/T8) -> -1 | V8: =Outlook!R8 -> 155989 | W8: =Budget!Q8 -> 537001 | X8: =IF(W8<=0,0,(V8-W8)/W8) -> -0.70951823
B9: Barge loading | C9: Ton | D9: =Actual!AK235 -> 0 | E9: =Actual!AJ283 -> 0 | F9: =((HLOOKUP(E$2,Outlook!$F$3:$Q$25,MATCH(B9,Outlook!$B$3:$B$25,0),FALSE))/Actual!E3)*(MID(D$3,1,2)) -> 0 | G9: =IF(F9<=0,0,(E9-F9)/F9) -> 0 | H9: =(HLOOKUP(E$2,Budget!$E$3:$P$15,MATCH(B9,Budget!$B$3:$B$15,0),FALSE))/(Actual!$E$3)*(MID(D$3,1,2)) -> 17033.333 | I9: =IF(H9<=0,0,(E9-H9)/H9) -> -1 | J9: =(HLOOKUP(E$2,Outlook!$F$3:$Q$25,MATCH(B9,Outlook!$B$3:$B$25,0),FALSE)) -> 0 | K9: =HLOOKUP(E$2,Budget!$E$3:$P$15,MATCH(B9,Budget!$B$3:$B$15,0),FALSE) -> 73000 | L9: =IF(K9<=0,0,(J9-K9)/K9) -> -1 | M9: =(SUMIF(Outlook!$O$2:$Q$2,"Actual",Outlook!$O$4:$Q$4))+$E$4 -> 0 | N9: =(SUMIF(Outlook!$K$2:$M$2,"ACTUAL",Outlook!L10:N10))+F9 -> 0 | O9: =(SUMIF(Budget!$K$2:$M$2,"PLANED",Budget!K9:M9))+H9 -> 60203.333 | P9: =IF(O9<=0,0,(M9-O9)/O9) -> -1 | Q9: =(SUMIF(Outlook!$F$2:$Q$2,"actual",Outlook!$F$10:$Q$10))+$E$9 -> 0 | R9: =(SUMIF(Outlook!$F$2:$Q$2,"ACTUAL",Outlook!F10:Q10))+F9 -> 0 | S9: =IF(R9<=0,0,(Q9-R9)/R9) -> 0 | T9: =(SUMIF(Budget!$E$2:$P$2,"PLANED",Budget!E10:P10))+H9 -> 221433.33 | U9: =IF(T9<=0,0,(Q9-T9)/T9) -> -1 | V9: =Outlook!R10 -> 153300 | W9: =Budget!Q10 -> 525600 | X9: =IF(W9<=0,0,(V9-W9)/W9) -> -0.70833333
B10: F/C stock | C10: Ton | D10: =Actual!AK236 -> 1370.339 | E10: =Actual!AK236 -> 1370.339 | F10: =((HLOOKUP(E$2,Outlook!$F$3:$Q$25,MATCH(B10,Outlook!$B$3:$B$25,0),FALSE))) -> 1370 | G10: =IF(F10<=0,0,(E10-F10)/F10) -> 0.00024744526 | H10: =((HLOOKUP(E$2,Budget!$E$3:$P$15,MATCH(B10,Budget!$B$3:$B$15,0),FALSE))) -> 24556 | I10: =IF(H10<=0,0,(E10-H10)/H10) -> -0.94419535 | J10: =(HLOOKUP(E$2,Outlook!$F$3:$Q$25,MATCH(B10,Outlook!$B$3:$B$25,0),FALSE)) -> 1370 | K10: =HLOOKUP(E$2,Budget!$E$3:$P$15,MATCH(B10,Budget!$B$3:$B$15,0),FALSE) -> 24556 | L10: =IF(K10<=0,0,(J10-K10)/K10) -> -0.94420915 | M10: =Actual!AK236 -> 1370.339 | N10: =F10 -> 1370 | O10: =H10 -> 24556 | P10: =IF(O10<=0,0,(M10-O10)/O10) -> -0.94419535 | Q10: =Actual!AK236 -> 1370.339 | R10: =(HLOOKUP(E$2,Outlook!$F$3:$Q$25,MATCH(B10,Outlook!$B$3:$B$25,0),FALSE)) -> 1370 | S10: =IF(R10<=0,0,(Q10-R10)/R10) -> 0.00024744526 | T10: =(HLOOKUP(E$2,Budget!$E$3:$P$15,MATCH(B10,Budget!$B$3:$B$15,0),FALSE)) -> 24556 | U10: =IF(T10<=0,0,(Q10-T10)/T10) -> -0.94419535 | V10: =Outlook!Q9 -> 3945.9841 | W10: =Budget!P9 -> 9908 | X10: =IF(W10<=0,0,(V10-W10)/W10) -> -0.60173758
B11: Uncovered Coal | C11: Ton | D11: =Actual!AK237 -> 0 | E11: =Actual!AK237 -> 0 | F11: =(HLOOKUP(E$2,Outlook!$F$3:$Q$25,MATCH(B11,Outlook!$B$3:$B$25,0),FALSE)) -> 0 | G11: =IF(F11<=0,0,(E11-F11)/F11) -> 0 | H11: =(HLOOKUP(E$2,Budget!$E$3:$P$15,MATCH(B11,Budget!$B$3:$B$15,0),FALSE)) -> 0 | I11: =IF(H11<=0,0,(E11-H11)/H11) -> 0 | J11: =(HLOOKUP(E$2,Outlook!$F$3:$Q$25,MATCH(B11,Outlook!$B$3:$B$25,0),FALSE)) -> 0 | K11: =HLOOKUP(E$2,Budget!$E$3:$P$15,MATCH(B11,Budget!$B$3:$B$15,0),FALSE) -> 0 | L11: =IF(K11<=0,0,(J11-K11)/K11) -> 0 | M11: =Actual!AK237 -> 0 | N11: =F11 -> 0 | O11: =H11 -> 0 | P11: =IF(O11<=0,0,(M11-O11)/O11) -> 0 | Q11: =Actual!AK237 -> 0 | R11: =(HLOOKUP(E$2,Outlook!$F$3:$Q$25,MATCH(B11,Outlook!$B$3:$B$25,0),FALSE)) -> 0 | S11: =IF(R11<=0,0,(Q11-R11)/R11) -> 0 | T11: =(HLOOKUP(E$2,Budget!$E$3:$P$15,MATCH(B11,Budget!$B$3:$B$15,0),FALSE)) -> 0 | U11: =IF(T11<=0,0,(Q11-T11)/T11) -> 0 | V11: =Outlook!Q21 -> 0 | W11: =Budget!P11 -> 0 | X11: =IF(W11<=0,0,(V11-W11)/W11) -> 0
B12: Rain fall | C12: mm. | D12: =Actual!AJ250 -> 0 | E12: =Actual!AJ249 -> 0 | F12: =((HLOOKUP(E$2,Outlook!$F$3:$Q$25,MATCH(B12,Outlook!$B$3:$B$25,0),FALSE))/Actual!$E$3)*(MID(D$3,1,2)) -> 41.725822 | G12: =IF(F12<=0,0,(E12-F12)/F12) -> -1 | H12: =((HLOOKUP(E$2,Budget!$E$3:$P$15,MATCH(B12,Budget!$B$3:$B$15,0),FALSE))/Actual!$E$3)*(MID(D$3,1,2)) -> 41.725822 | I12: =IF(H12<=0,0,(E12-H12)/H12) -> -1 | J12: =(HLOOKUP(E$2,Outlook!$F$3:$Q$25,MATCH(B12,Outlook!$B$3:$B$25,0),FALSE)) -> 178.82495 | K12: =HLOOKUP(E$2,Budget!$E$3:$P$15,MATCH(B12,Budget!$B$3:$B$15,0),FALSE) -> 178.82495 | L12: =IF(K12<=0,0,(J12-K12)/K12) -> 0 | M12: =(SUMIF(Outlook!$O$2:$Q$2,"Actual",Outlook!$O$4:$Q$4))+$E$4 -> 0 | N12: =(SUMIF(Outlook!$O$2:$Q$2,"ACTUAL",Outlook!O12:Q12))+F12 -> 41.725822 | O12: =(SUMIF(Budget!$K$2:$M$2,"PLANED",Budget!K12:M12))+H12 -> 462.85623 | P12: =IF(O12<=0,0,(M12-O12)/O12) -> -1 | Q12: =(SUMIF(Outlook!$F$2:$Q$2,"actual",Outlook!$F$22:$Q$22))+E12 -> 476.2 | R12: =(SUMIF(Outlook!$F$2:$Q$2,"ACTUAL",Outlook!F22:Q22))+F12 -> 517.92582 | S12: =IF(R12<=0,0,(Q12-R12)/R12) -> -0.080563317 | T12: =(SUMIF(Budget!$E$2:$P$2,"PLANED",Budget!E12:P12))+(((HLOOKUP(E$2,Budget!$E$3:$P$15,MATCH(B12,Budget!$B$3:$B$15,0),FALSE))/Actual!$E$3)*(MID(D$3,1,2))) -> 1399.2074 | U12: =IF(T12<=0,0,(Q12-T12)/T12) -> -0.65966446 | V12: =Outlook!R22 -> 1206.464 | W12: =Budget!Q12 -> 2087.7455 | X12: =IF(W12<=0,0,(V12-W12)/W12) -> -0.42212115
B13: Rain fall Duration | C13: hr. | D13: =Actual!AJ257 -> 0 | E13: =Actual!AJ256 -> 0 | F13: =((HLOOKUP(E$2,Outlook!$F$3:$Q$25,MATCH(B13,Outlook!$B$3:$B$25,0),FALSE))/Actual!$E$3)*MID(D$3,1,2) -> 9.6576667 | G13: =IF(F13<=0,0,(E13-F13)/F13) -> -1 | H13: =((HLOOKUP(E$2,Budget!$E$3:$P$15,MATCH(B13,Budget!$B$3:$B$15,0),FALSE))/Actual!$E$3)*(MID(D$3,1,2)) -> 9.6576667 | I13: =IF(H13<=0,0,(E13-H13)/H13) -> -1 | J13: =(HLOOKUP(E$2,Outlook!$F$3:$Q$25,MATCH(B13,Outlook!$B$3:$B$25,0),FALSE)) -> 41.39 | K13: =HLOOKUP(E$2,Budget!$E$3:$P$15,MATCH(B13,Budget!$B$3:$B$15,0),FALSE) -> 41.39 | L13: =IF(K13<=0,0,(J13-K13)/K13) -> 0 | M13: =(SUMIF(Outlook!$O$2:$Q$2,"Actual",Outlook!$O$4:$Q$4))+$E$4 -> 0 | N13: =(SUMIF(Outlook!$O$2:$Q$2,"ACTUAL",Outlook!O13:Q13))+F13 -> 9.6576667 | O13: =(SUMIF(Budget!$K$2:$M$2,"PLANED",Budget!K13:M13))+H13 -> 249.31767 | P13: =IF(O13<=0,0,(M13-O13)/O13) -> -1 | Q13: =((SUMIF(Outlook!$F$2:$Q$2,"actual",Outlook!$F$23:$Q$23))+E13) -> 333.86667 | R13: =(SUMIF(Outlook!$F$2:$Q$2,"ACTUAL",Outlook!F23:Q23))+F13 -> 343.52433 | S13: =IF(R13<=0,0,(Q13-R13)/R13) -> -0.028113486 | T13: =(SUMIF(Budget!$E$2:$P$2,"PLANED",Budget!E13:P13))+(((HLOOKUP(E$2,Budget!$E$3:$P$15,MATCH(B13,Budget!$B$3:$B$15,0),FALSE))/Actual!$E$3)*(MID(D$3,1,2))) -> 745.63433 | U13: =IF(T13<=0,0,(Q13-T13)/T13) -> -0.55223807 | V13: =Outlook!R23 -> 715.75667 | W13: =Budget!Q13 -> 1117.8667 | X13: =IF(W13<=0,0,(V13-W13)/W13) -> -0.35971195
B14: Slippery time | C14: hr. | D14: =Actual!AJ264 -> 0 | E14: =Actual!AJ263 -> 0 | F14: =((HLOOKUP(E$2,Outlook!$F$3:$Q$25,MATCH(B14,Outlook!$B$3:$B$25,0),FALSE))/Actual!$E$3)*MID(D$3,1,2) -> 12.324667 | G14: =IF(F14<=0,0,(E14-F14)/F14) -> -1 | H14: =((HLOOKUP(E$2,Budget!$E$3:$P$15,MATCH(B14,Budget!$B$3:$B$15,0),FALSE))/Actual!$E$3)*(MID(D$3,1,2)) -> 12.324667 | I14: =IF(H14<=0,0,(E14-H14)/H14) -> -1 | J14: =(HLOOKUP(E$2,Outlook!$F$3:$Q$25,MATCH(B14,Outlook!$B$3:$B$25,0),FALSE)) -> 52.82 | K14: =HLOOKUP(E$2,Budget!$E$3:$P$15,MATCH(B14,Budget!$B$3:$B$15,0),FALSE) -> 52.82 | L14: =IF(K14<=0,0,(J14-K14)/K14) -> 0 | M14: =(SUMIF(Outlook!$O$2:$Q$2,"Actual",Outlook!$O$4:$Q$4))+$E$4 -> 0 | N14: =(SUMIF(Outlook!$O$2:$Q$2,"ACTUAL",Outlook!O14:Q14))+F14 -> 12.324667 | O14: =(SUMIF(Budget!$K$2:$M$2,"PLANED",Budget!K14:M14))+H14 -> 122.40467 | P14: =IF(O14<=0,0,(M14-O14)/O14) -> -1 | Q14: =(SUMIF(Outlook!$F$2:$Q$2,"actual",Outlook!$F$24:$Q$24))+E14 -> 0 | R14: =(SUMIF(Outlook!$F$2:$Q$2,"ACTUAL",Outlook!F24:Q24))+F14 -> 12.324667 | S14: =IF(R14<=0,0,(Q14-R14)/R14) -> -1 | T14: =(SUMIF(Budget!$E$2:$P$2,"PLANED",Budget!E14:P14))+(((HLOOKUP(E$2,Budget!$E$3:$P$15,MATCH(B14,Budget!$B$3:$B$15,0),FALSE))/Actual!$E$3)*(MID(D$3,1,2))) -> 179.50467 | U14: =IF(T14<=0,0,(Q14-T14)/T14) -> -1 | V14: =Outlook!R24 -> 248.67 | W14: =Budget!Q14 -> 415.85 | X14: =IF(W14<=0,0,(V14-W14)/W14) -> -0.40201996
B15: JBG Fuel stock | C15: Liter | D15: =Actual!AK240 -> 0 | E15: =Actual!AK240 -> 0 | F15: =(HLOOKUP(E$2,Outlook!$F$3:$Q$25,MATCH(B15,Outlook!$B$3:$B$25,0),FALSE)) -> 35000 | G15: =IF(F15<=0,0,(E15-F15)/F15) -> -1 | H15: =(HLOOKUP(E$2,Budget!$E$3:$P$15,MATCH(B15,Budget!$B$3:$B$15,0),FALSE)) -> 35000 | I15: =IF(H15<=0,0,(E15-H15)/H15) -> -1 | J15: =(HLOOKUP(E$2,Outlook!$F$3:$Q$25,MATCH(B15,Outlook!$B$3:$B$25,0),FALSE)) -> 35000 | K15: =HLOOKUP(E$2,Budget!$E$3:$P$15,MATCH(B15,Budget!$B$3:$B$15,0),FALSE) -> 35000 | L15: =IF(K15<=0,0,(J15-K15)/K15) -> 0 | Q15: =Actual!AK240 -> 0 | R15: =Outlook!Q25 -> 35000 | S15: =IF(R15<=0,0,(Q15-R15)/R15) -> -1 | T15: =(HLOOKUP(E$2,Budget!$E$3:$P$15,MATCH(B15,Budget!$B$3:$B$15,0),FALSE)) -> 35000 | U15: =IF(T15<=0,0,(Q15-T15)/T15) -> -1 | V15: =Outlook!Q25 -> 35000 | W15: =Budget!P15 -> 35000 | X15: =IF(W15<=0,0,(V15-W15)/W15) -> 0
C66: 1 | D66: 2 | E66: 3 | F66: 4 | G66: 5 | H66: 6 | I66: 7 | J66: 8 | K66: 9 | L66: 10 | Q66: 11 | R66: 12 | S66: 13 | T66: 14 | U66: 15 | V66: 16 | W66: 17 | X66: 18 | Y66: 19 | Z66: 20 | AA66: 21 | AB66: 22 | AC66: 23 | AD66: 24 | AE66: 25 | AF66: 26 | AG66: 27 | AH66: 28 | AI66: 29 | AJ66: 30 | AK66: 31
B67: OB TJP | C67: =Actual!F212 -> 424.5 | D67: =Actual!G212 -> 1168.5 | E67: =Actual!H212 -> 1930.5 | F67: =Actual!I212 -> 1350 | G67: =Actual!J212 -> 1917 | H67: =Actual!K212 -> 0 | I67: =Actual!L212 -> 1809 | J67: =Actual!M212 -> 0 | ... L67: =Actual!O212 -> 0 | Q67: =Actual!P212 -> 0 | R67: =Actual!Q212 -> 0 | S67: =Actual!R212 -> 0 | T67: =Actual!S212 -> 0 | U67: =Actual!T212 -> 0 | V67: =Actual!U212 -> 0 | W67: =Actual!V212 -> 0 | X67: =Actual!W212 -> 0 | ... AK67: =Actual!AJ212 -> 0
B68: OB SNS | C68: =Actual!F194 -> 0 | D68: =Actual!G194 -> 0 | E68: =Actual!H194 -> 0 | F68: =Actual!I194 -> 0 | G68: =Actual!J194 -> 0 | H68: =Actual!K194 -> 0 | I68: =Actual!L194 -> 0 | J68: =Actual!M194 -> 0 | ... L68: =Actual!O194 -> 0 | Q68: =Actual!P194 -> 0 | R68: =Actual!Q194 -> 0 | S68: =Actual!R194 -> 0 | T68: =Actual!S194 -> 0 | U68: =Actual!T194 -> 0 | V68: =Actual!U194 -> 0 | W68: =Actual!V194 -> 0 | X68: =Actual!W194 -> 0 | ... AK68: =Actual!AJ194 -> 0
B69: ROM TJP | C69: =Actual!F215 -> 0 | D69: =Actual!G215 -> 0 | E69: =Actual!H215 -> 0 | F69: =Actual!I215 -> 0 | G69: =Actual!J215 -> 0 | H69: =Actual!K215 -> 0 | I69: =Actual!L215 -> 0 | J69: =Actual!M215 -> 0 | ... L69: =Actual!O215 -> 0 | Q69: =Actual!P215 -> 0 | R69: =Actual!Q215 -> 0 | S69: =Actual!R215 -> 0 | T69: =Actual!S215 -> 0 | U69: =Actual!T215 -> 0 | V69: =Actual!U215 -> 0 | W69: =Actual!V215 -> 0 | X69: =Actual!W215 -> 0 | ... AK69: =Actual!AJ215 -> 0
B70: ROM SNS | C70: =Actual!F197 -> 0 | D70: =Actual!G197 -> 0 | E70: =Actual!H197 -> 0 | F70: =Actual!I197 -> 0 | G70: =Actual!J197 -> 0 | H70: =Actual!K197 -> 0 | I70: =Actual!L197 -> 0 | J70: =Actual!M197 -> 0 | ... L70: =Actual!O197 -> 0 | Q70: =Actual!P197 -> 0 | R70: =Actual!Q197 -> 0 | S70: =Actual!R197 -> 0 | T70: =Actual!S197 -> 0 | U70: =Actual!T197 -> 0 | V70: =Actual!U197 -> 0 | W70: =Actual!V197 -> 0 | X70: =Actual!W197 -> 0 | ... AK70: =Actual!AJ197 -> 0
B78: 1 | C78: 2 | D78: =C78+1 -> 3 | E78: =D78+1 -> 4 | F78: =E78+1 -> 5 | G78: =F78+1 -> 6 | H78: =G78+1 -> 7 | I78: =H78+1 -> 8 | J78: =I78+1 -> 9 | K78: =J78+1 -> 10 | L78: =K78+1 -> 11 | Q78: =L78+1 -> 12 | R78: =Q78+1 -> 13 | S78: =R78+1 -> 14 | T78: =S78+1 -> 15 | U78: =T78+1 -> 16 | V78: =U78+1 -> 17 | W78: =V78+1 -> 18 | X78: =W78+1 -> 19 | Y78: =X78+1 -> 20 | ... AJ78: =AI78+1 -> 31
A79: ROM Production | B79: =Actual!F224 -> 0 | C79: =Actual!G224 -> 0 | D79: =Actual!H224 -> 0 | E79: =Actual!I224 -> 0 | F79: =Actual!J224 -> 0 | G79: =Actual!K224 -> 0 | H79: =Actual!L224 -> 0 | I79: =Actual!M224 -> 0 | ... L79: =Actual!P224 -> 0 | Q79: =Actual!Q224 -> 0 | R79: =Actual!R224 -> 0 | S79: =Actual!S224 -> 0 | T79: =Actual!T224 -> 0 | U79: =Actual!U224 -> 0 | V79: =Actual!V224 -> 0 | W79: =Actual!W224 -> 0 | X79: =Actual!X224 -> 0 | ... AJ79: =Actual!AJ224 -> 0
A80: Rainfall (mm) | B80: =Actual!E249 -> 0 | C80: =Actual!F249 -> 0 | D80: =Actual!G249 -> 0 | E80: =Actual!H249 -> 0 | F80: =Actual!I249 -> 0 | G80: =Actual!J249 -> 0 | H80: =Actual!K249 -> 0 | I80: =Actual!L249 -> 0 | ... L80: =Actual!O249 -> 0 | Q80: =Actual!P249 -> 0 | R80: =Actual!Q249 -> 0 | S80: =Actual!R249 -> 0 | T80: =Actual!S249 -> 0 | U80: =Actual!T249 -> 0 | V80: =Actual!U249 -> 0 | W80: =Actual!V249 -> 0 | X80: =Actual!W249 -> 0 | ... AJ80: =Actual!AI249 -> 0
B83: 1 | C83: 2 | D83: =C83+1 -> 3 | E83: =D83+1 -> 4 | F83: =E83+1 -> 5 | G83: =F83+1 -> 6 | H83: =G83+1 -> 7 | I83: =H83+1 -> 8 | J83: =I83+1 -> 9 | K83: =J83+1 -> 10 | L83: =K83+1 -> 11 | Q83: =L83+1 -> 12 | R83: =Q83+1 -> 13 | S83: =R83+1 -> 14 | T83: =S83+1 -> 15 | U83: =T83+1 -> 16 | V83: =U83+1 -> 17 | W83: =V83+1 -> 18 | X83: =W83+1 -> 19 | Y83: =X83+1 -> 20 | ... AJ83: =AI83+1 -> 31
A84: ROM Production | B84: =B79 -> 0 | C84: =C79 -> 0 | D84: =D79 -> 0 | E84: =E79 -> 0 | F84: =F79 -> 0 | G84: =G79 -> 0 | H84: =H79 -> 0 | I84: =I79 -> 0 | ... L84: =L79 -> 0 | Q84: =Q79 -> 0 | R84: =R79 -> 0 | S84: =S79 -> 0 | T84: =T79 -> 0 | U84: =U79 -> 0 | V84: =V79 -> 0 | W84: =W79 -> 0 | X84: =X79 -> 0 | ... AJ84: =AJ79 -> 0
A85: Rainfall (hr) | B85: =Actual!E269 -> 0 | C85: =Actual!F269 -> 0 | D85: =Actual!G269 -> 0 | E85: =Actual!H269 -> 0 | F85: =Actual!I269 -> 0 | G85: =Actual!J269 -> 0 | H85: =Actual!K269 -> 0 | I85: =Actual!L269 -> 0 | ... L85: =Actual!O269 -> 0 | Q85: =Actual!P269 -> 0 | R85: =Actual!Q269 -> 0 | S85: =Actual!R269 -> 0 | T85: =Actual!S269 -> 0 | U85: =Actual!T269 -> 0 | V85: =Actual!U269 -> 0 | W85: =Actual!V269 -> 0 | X85: =Actual!W269 -> 0 | ... AJ85: =Actual!AI269 -> 0

Sheet Actual
C2: 1.OB Actual Sep'26
C3: Total day ---> | E3: 30 | F3: 01 | G3: 02 | H3: 03 | I3: 04 | J3: 05 | K3: 06 | L3: 07 | M3: 08 | N3: 09 | O3: 10 | P3: 11 | Q3: 12 | R3: 13 | S3: 14 | T3: 15 | U3: 16 | V3: 17 | W3: 18 | X3: 19 | Y3: 20 | Z3: 21 | AA3: 22 | AB3: 23 | AC3: 24 | AD3: 25 | AE3: 26 | AF3: 27 | AG3: 28 | AH3: 29 | AI3: 30 | AJ3: 31 | AK3: Total by Pit | AL3: EOP by clasification
C4: Pit M45 C | E4: PAF(BCM) | F4: 0 | G4: 0 | H4: 0 | I4: 0 | J4: 0 | K4: 0 | L4: 0 | M4: 0 | N4: 0 | O4: 0 | P4: 0 | Q4: 0 | R4: 0 | S4: 0 | T4: 0 | U4: 0 | V4: 0 | W4: 0 | X4: 0 | Y4: 0 | Z4: 0 | AA4: 0 | AB4: 0 | AC4: 0 | AD4: 0 | AE4: 0 | AF4: 0 | AG4: 0 | AH4: 0 | AI4: 0 | AJ4: 0 | AK4: =SUM(F4:AJ4) -> 0 | AL4: =HLOOKUP(LEFT(Summary!D3,2),Actual!F3:AJ47,2,FALSE) -> 0
E5: NAF(BCM) | F5: 0 | G5: 0 | H5: 0 | I5: 0 | J5: 0 | K5: 0 | L5: 0 | M5: 0 | N5: 0 | O5: 0 | P5: 0 | Q5: 0 | R5: 0 | S5: 0 | T5: 0 | U5: 0 | V5: 0 | W5: 0 | X5: 0 | Y5: 0 | Z5: 0 | AA5: 0 | AB5: 0 | AC5: 0 | AD5: 0 | AE5: 0 | AF5: 0 | AG5: 0 | AH5: 0 | AI5: 0 | AJ5: 0 | AK5: =SUM(F5:AJ5) -> 0 | AL5: =HLOOKUP(LEFT(Summary!D3,2),Actual!F3:AJ47,3,FALSE) -> 0
E6: Top Soil (BCM) | F6: 0 | G6: 0 | H6: 0 | I6: 0 | J6: 0 | K6: 0 | L6: 0 | M6: 0 | N6: 0 | O6: 0 | P6: 0 | Q6: 0 | R6: 0 | S6: 0 | T6: 0 | U6: 0 | V6: 0 | W6: 0 | X6: 0 | Y6: 0 | Z6: 0 | AA6: 0 | AB6: 0 | AC6: 0 | AD6: 0 | AE6: 0 | AF6: 0 | AG6: 0 | AH6: 0 | AI6: 0 | AJ6: 0 | AK6: =SUM(F6:AJ6) -> 0 | AL6: =HLOOKUP(LEFT(Summary!D3,2),Actual!F3:AJ47,4,FALSE) -> 0
E7: Total by day | F7: =SUM(F4:F6) -> 0 | G7: 0 | H7: 0 | I7: =SUM(I4:I6) -> 0 | J7: =SUM(J4:J6) -> 0 | K7: =SUM(K4:K6) -> 0 | L7: =SUM(L4:L6) -> 0 | M7: =SUM(M4:M6) -> 0 | N7: =SUM(N4:N6) -> 0 | O7: =SUM(O4:O6) -> 0 | P7: =SUM(P4:P6) -> 0 | ... AK7: =SUM(AK4:AK6) -> 0 | AL7: =HLOOKUP(LEFT(Summary!D3,2),Actual!F3:AJ47,5,FALSE) -> 0 | AJR7: =Actual!$F$224/31 -> 0
C8: Pit UC_W | E8: PAF(BCM) | F8: 0 | G8: 0 | H8: 0 | I8: 0 | J8: 0 | K8: 0 | L8: 0 | M8: 0 | N8: 0 | O8: 0 | P8: 0 | Q8: 0 | R8: 0 | S8: 0 | T8: 0 | U8: 0 | V8: 0 | W8: 0 | X8: 0 | Y8: 0 | Z8: 0 | AA8: 0 | AB8: 0 | AC8: 0 | AD8: 0 | AE8: 0 | AF8: 0 | AG8: 0 | AH8: 0 | AI8: 0 | AJ8: 0 | AK8: =SUM(F8:AJ8) -> 0 | AL8: =HLOOKUP(LEFT(Summary!D3,2),Actual!F3:AJ47,6,FALSE) -> 0
E9: NAF(BCM) | F9: 0 | G9: 0 | H9: 0 | I9: 0 | J9: 0 | K9: 0 | L9: 0 | M9: 0 | N9: 0 | O9: 0 | P9: 0 | Q9: 0 | R9: 0 | S9: 0 | T9: 0 | U9: 0 | V9: 0 | W9: 0 | X9: 0 | Y9: 0 | Z9: 0 | AA9: 0 | AB9: 0 | AC9: 0 | AD9: 0 | AE9: 0 | AF9: 0 | AG9: 0 | AH9: 0 | AI9: 0 | AJ9: 0 | AK9: =SUM(F9:AJ9) -> 0 | AL9: =HLOOKUP(LEFT(Summary!D3,2),Actual!F3:AJ47,7,FALSE) -> 0
E10: Top Soil (BCM) | F10: 0 | G10: 0 | H10: 0 | I10: 0 | J10: 0 | K10: 0 | L10: 0 | M10: 0 | N10: 0 | O10: 0 | P10: 0 | Q10: 0 | R10: 0 | S10: 0 | T10: 0 | U10: 0 | V10: 0 | W10: 0 | X10: 0 | Y10: 0 | Z10: 0 | AA10: 0 | AB10: 0 | AC10: 0 | AD10: 0 | AE10: 0 | AF10: 0 | AG10: 0 | AH10: 0 | AI10: 0 | AJ10: 0 | AK10: =SUM(F10:AJ10) -> 0 | AL10: =HLOOKUP(LEFT(Summary!D3,2),Actual!F3:AJ47,8,FALSE) -> 0
E11: Total by day | F11: =SUM(F8:F10) -> 0 | G11: 0 | H11: 0 | I11: =SUM(I8:I10) -> 0 | J11: =SUM(J8:J10) -> 0 | K11: =SUM(K8:K10) -> 0 | L11: =SUM(L8:L10) -> 0 | M11: =SUM(M8:M10) -> 0 | N11: =SUM(N8:N10) -> 0 | O11: =SUM(O8:O10) -> 0 | P11: =SUM(P8:P10) -> 0 | ... AK11: =SUM(AK8:AK10) -> 0 | AL11: =HLOOKUP(LEFT(Summary!D3,2),Actual!F3:AJ47,9,FALSE) -> 0
B12: SNS | C12: PIT U210 | E12: PAF(BCM) | F12: 0 | G12: 0 | H12: 0 | I12: 0 | J12: 0 | K12: 0 | L12: 0 | M12: 0 | N12: 0 | O12: 0 | P12: 0 | Q12: 0 | R12: 0 | S12: 0 | T12: 0 | U12: 0 | V12: 0 | W12: 0 | X12: 0 | Y12: 0 | Z12: 0 | AA12: 0 | AB12: 0 | AC12: 0 | AD12: 0 | AE12: 0 | AF12: 0 | AG12: 0 | AH12: 0 | AI12: 0 | AJ12: 0 | AK12: =SUM(F12:AJ12) -> 0 | AL12: =HLOOKUP(LEFT(Summary!D3,2),Actual!F3:AJ47,10,FALSE) -> 0
E13: NAF(BCM) | F13: 0 | G13: 0 | H13: 0 | I13: 0 | J13: 0 | K13: 0 | L13: 0 | M13: 0 | N13: 0 | O13: 0 | P13: 0 | Q13: 0 | R13: 0 | S13: 0 | T13: 0 | U13: 0 | V13: 0 | W13: 0 | X13: 0 | Y13: 0 | Z13: 0 | AA13: 0 | AB13: 0 | AC13: 0 | AD13: 0 | AE13: 0 | AF13: 0 | AG13: 0 | AH13: 0 | AI13: 0 | AJ13: 0 | AK13: =SUM(F13:AJ13) -> 0 | AL13: =HLOOKUP(LEFT(Summary!D3,2),Actual!F3:AJ47,11,FALSE) -> 0
E14: MUD (BCM) | F14: 0 | G14: 0 | H14: 0 | I14: 0 | J14: 0 | K14: 0 | L14: 0 | M14: 0 | N14: 0 | O14: 0 | P14: 0 | Q14: 0 | R14: 0 | S14: 0 | T14: 0 | U14: 0 | V14: 0 | W14: 0 | X14: 0 | Y14: 0 | Z14: 0 | AA14: 0 | AB14: 0 | AC14: 0 | AD14: 0 | AE14: 0 | AF14: 0 | AG14: 0 | AH14: 0 | AI14: 0 | AJ14: 0 | AK14: =SUM(F14:AJ14) -> 0
E15: Top Soil (BCM) | F15: 0 | G15: 0 | H15: 0 | I15: 0 | J15: 0 | K15: 0 | L15: 0 | M15: 0 | N15: 0 | O15: 0 | P15: 0 | Q15: 0 | R15: 0 | S15: 0 | T15: 0 | U15: 0 | V15: 0 | W15: 0 | X15: 0 | Y15: 0 | Z15: 0 | AA15: 0 | AB15: 0 | AC15: 0 | AD15: 0 | AE15: 0 | AF15: 0 | AG15: 0 | AH15: 0 | AI15: 0 | AJ15: 0 | AK15: =SUM(F15:AJ15) -> 0 | AL15: =HLOOKUP(LEFT(Summary!D3,2),Actual!F3:AJ47,12,FALSE) -> 0
E16: Total by day | F16: =SUM(F12:F15) -> 0 | G16: =SUM(G12:G15) -> 0 | H16: =SUM(H12:H15) -> 0 | I16: =SUM(I12:I15) -> 0 | J16: =SUM(J12:J15) -> 0 | K16: =SUM(K12:K15) -> 0 | L16: =SUM(L12:L15) -> 0 | M16: =SUM(M12:M15) -> 0 | ... AK16: =SUM(AK12:AK15) -> 0 | AL16: =HLOOKUP(LEFT(Summary!D3,2),Actual!F3:AJ47,13,FALSE) -> 0
C17: Pit UEW | E17: PAF(BCM) | F17: 0 | G17: 0 | H17: 0 | I17: 0 | J17: 0 | K17: 0 | L17: 0 | M17: 0 | N17: 0 | O17: 0 | P17: 0 | Q17: 0 | R17: 0 | S17: 0 | T17: 0 | U17: 0 | V17: 0 | W17: 0 | X17: 0 | Y17: 0 | Z17: 0 | AA17: 0 | AB17: 0 | AC17: 0 | AD17: 0 | AE17: 0 | AF17: 0 | AG17: 0 | AH17: 0 | AI17: 0 | AJ17: 0 | AK17: =SUM(F17:AJ17) -> 0 | AL17: =HLOOKUP(LEFT(Summary!D3,2),Actual!F3:AJ47,14,FALSE) -> 0
E18: NAF(BCM) | F18: 0 | G18: 0 | H18: 0 | I18: 0 | J18: 0 | K18: 0 | L18: 0 | M18: 0 | N18: 0 | O18: 0 | P18: 0 | Q18: 0 | R18: 0 | S18: 0 | T18: 0 | U18: 0 | V18: 0 | W18: 0 | X18: 0 | Y18: 0 | Z18: 0 | AA18: 0 | AB18: 0 | AC18: 0 | AD18: 0 | AE18: 0 | AF18: 0 | AG18: 0 | AH18: 0 | AI18: 0 | AJ18: 0 | AK18: =SUM(F18:AJ18) -> 0 | AL18: =HLOOKUP(LEFT(Summary!D3,2),Actual!F3:AJ47,15,FALSE) -> 0
E19: MUD (BCM) | F19: 0 | G19: 0 | H19: 0 | I19: 0 | J19: 0 | K19: 0 | L19: 0 | M19: 0 | N19: 0 | O19: 0 | P19: 0 | Q19: 0 | R19: 0 | S19: 0 | T19: 0 | U19: 0 | V19: 0 | W19: 0 | X19: 0 | Y19: 0 | Z19: 0 | AA19: 0 | AB19: 0 | AC19: 0 | AD19: 0 | AE19: 0 | AF19: 0 | AG19: 0 | AH19: 0 | AI19: 0 | AJ19: 0 | AK19: =SUM(F19:AJ19) -> 0
E20: Top Soil (BCM) | F20: 0 | G20: 0 | H20: 0 | I20: 0 | J20: 0 | K20: 0 | L20: 0 | M20: 0 | N20: 0 | O20: 0 | P20: 0 | Q20: 0 | R20: 0 | S20: 0 | T20: 0 | U20: 0 | V20: 0 | W20: 0 | X20: 0 | Y20: 0 | Z20: 0 | AA20: 0 | AB20: 0 | AC20: 0 | AD20: 0 | AE20: 0 | AF20: 0 | AG20: 0 | AH20: 0 | AI20: 0 | AJ20: 0 | AK20: =SUM(F20:AJ20) -> 0 | AL20: =HLOOKUP(LEFT(Summary!D3,2),Actual!F3:AJ47,16,FALSE) -> 0
E21: Total by day | F21: =SUM(F17:F20) -> 0 | G21: =SUM(G17:G20) -> 0 | H21: =SUM(H17:H20) -> 0 | I21: =SUM(I17:I20) -> 0 | J21: =SUM(J17:J20) -> 0 | K21: =SUM(K17:K20) -> 0 | L21: =SUM(L17:L20) -> 0 | M21: =SUM(M17:M20) -> 0 | ... AK21: =SUM(AK17:AK20) -> 0 | AL21: =HLOOKUP(LEFT(Summary!D3,2),Actual!F3:AJ47,17,FALSE) -> 0
C22: Pit UCE | E22: PAF(BCM) | F22: 0 | G22: 0 | H22: 0 | I22: 0 | J22: 0 | K22: 0 | L22: 0 | M22: 0 | N22: 0 | O22: 0 | P22: 0 | Q22: 0 | R22: 0 | S22: 0 | T22: 0 | U22: 0 | V22: 0 | W22: 0 | X22: 0 | Y22: 0 | Z22: 0 | AA22: 0 | AB22: 0 | AC22: 0 | AD22: 0 | AE22: 0 | AF22: 0 | AG22: 0 | AH22: 0 | AI22: 0 | AJ22: 0 | AK22: =SUM(F22:AJ22) -> 0 | AL22: =HLOOKUP(LEFT(Summary!D3,2),Actual!F3:AJ47,18,FALSE) -> 0
E23: NAF(BCM) | F23: 0 | G23: 0 | H23: 0 | I23: 0 | J23: 0 | K23: 0 | L23: 0 | M23: 0 | N23: 0 | O23: 0 | P23: 0 | Q23: 0 | R23: 0 | S23: 0 | T23: 0 | U23: 0 | V23: 0 | W23: 0 | X23: 0 | Y23: 0 | Z23: 0 | AA23: 0 | AB23: 0 | AC23: 0 | AD23: 0 | AE23: 0 | AF23: 0 | AG23: 0 | AH23: 0 | AI23: 0 | AJ23: 0 | AK23: =SUM(F23:AJ23) -> 0 | AL23: =HLOOKUP(LEFT(Summary!D3,2),Actual!F3:AJ47,19,FALSE) -> 0
E24: MUD (BCM) | F24: 0 | G24: 0 | H24: 0 | I24: 0 | J24: 0 | K24: 0 | L24: 0 | M24: 0 | N24: 0 | O24: 0 | P24: 0 | Q24: 0 | R24: 0 | S24: 0 | T24: 0 | U24: 0 | V24: 0 | W24: 0 | X24: 0 | Y24: 0 | Z24: 0 | AA24: 0 | AB24: 0 | AC24: 0 | AD24: 0 | AE24: 0 | AF24: 0 | AG24: 0 | AH24: 0 | AI24: 0 | AJ24: 0 | AK24: =SUM(F24:AJ24) -> 0 | AL24: =HLOOKUP(LEFT(Summary!D3,2),Actual!F3:AJ47,20,FALSE) -> 0
E25: Top Soil (BCM) | F25: 0 | G25: 0 | H25: 0 | I25: 0 | J25: 0 | K25: 0 | L25: 0 | M25: 0 | N25: 0 | O25: 0 | P25: 0 | Q25: 0 | R25: 0 | S25: 0 | T25: 0 | U25: 0 | V25: 0 | W25: 0 | X25: 0 | Y25: 0 | Z25: 0 | AA25: 0 | AB25: 0 | AC25: 0 | AD25: 0 | AE25: 0 | AF25: 0 | AG25: 0 | AH25: 0 | AI25: 0 | AJ25: 0 | AK25: =SUM(F25:AJ25) -> 0
E26: Total | F26: =SUM(F22:F25) -> 0 | G26: =SUM(G22:G25) -> 0 | H26: =SUM(H22:H25) -> 0 | I26: =SUM(I22:I25) -> 0 | J26: =SUM(J22:J25) -> 0 | K26: =SUM(K22:K25) -> 0 | L26: =SUM(L22:L25) -> 0 | M26: =SUM(M22:M25) -> 0 | ... AJ26: =SUM(AJ22:AJ25) -> 0 | AK26: =SUM(AK22:AK24) -> 0 | AL26: =HLOOKUP(LEFT(Summary!D3,2),Actual!F3:AJ47,21,FALSE) -> 0
C27: PIT M4EW | E27: OB-PAF | F27: =SUMIFS(OB_Act[Volume (BCM)],OB_Act[Day],Actual!F$3,OB_Act[Dump Area],"M4EW",OB_Act[Material],$E27) -> 0 | G27: =SUMIFS(OB_Act[Volume (BCM)],OB_Act[Day],Actual!G$3,OB_Act[Dump Area],"M4EW",OB_Act[Material],$E27) -> 513 | H27: =SUMIFS(OB_Act[Volume (BCM)],OB_Act[Day],Actual!H$3,OB_Act[Dump Area],"M4EW",OB_Act[Material],$E27) -> 999 | I27: =SUMIFS(OB_Act[Volume (BCM)],OB_Act[Day],Actual!I$3,OB_Act[Dump Area],"M4EW",OB_Act[Material],$E27) -> 877.5 | J27: =SUMIFS(OB_Act[Volume (BCM)],OB_Act[Day],Actual!J$3,OB_Act[Dump Area],"M4EW",OB_Act[Material],$E27) -> 1147.5 | K27: =SUMIFS(OB_Act[Volume (BCM)],OB_Act[Day],Actual!K$3,OB_Act[Dump Area],"M4EW",OB_Act[Material],$E27) -> 0 | L27: =SUMIFS(OB_Act[Volume (BCM)],OB_Act[Day],Actual!L$3,OB_Act[Dump Area],"M4EW",OB_Act[Material],$E27) -> 1174.5 | M27: =SUMIFS(OB_Act[Volume (BCM)],OB_Act[Day],Actual!M$3,OB_Act[Dump Area],"M4EW",OB_Act[Material],$E27) -> 0 | ... AJ27: =SUMIFS(OB_Act[Volume (BCM)],OB_Act[Day],Actual!AJ$3,OB_Act[Dump Area],"M4EW",OB_Act[Material],$E27) -> 0 | AK27: =SUM(F27:AJ27) -> 4711.5 | AL27: =HLOOKUP(LEFT(Summary!D3,2),Actual!F3:AJ47,22,FALSE) -> 0
E28: OB-NAF | F28: =SUMIFS(OB_Act[Volume (BCM)],OB_Act[Day],Actual!F$3,OB_Act[Dump Area],"M4EW",OB_Act[Material],$E28) -> 0 | G28: =SUMIFS(OB_Act[Volume (BCM)],OB_Act[Day],Actual!G$3,OB_Act[Dump Area],"M4EW",OB_Act[Material],$E28) -> 0 | H28: =SUMIFS(OB_Act[Volume (BCM)],OB_Act[Day],Actual!H$3,OB_Act[Dump Area],"M4EW",OB_Act[Material],$E28) -> 0 | I28: =SUMIFS(OB_Act[Volume (BCM)],OB_Act[Day],Actual!I$3,OB_Act[Dump Area],"M4EW",OB_Act[Material],$E28) -> 0 | J28: =SUMIFS(OB_Act[Volume (BCM)],OB_Act[Day],Actual!J$3,OB_Act[Dump Area],"M4EW",OB_Act[Material],$E28) -> 0 | K28: =SUMIFS(OB_Act[Volume (BCM)],OB_Act[Day],Actual!K$3,OB_Act[Dump Area],"M4EW",OB_Act[Material],$E28) -> 0 | L28: =SUMIFS(OB_Act[Volume (BCM)],OB_Act[Day],Actual!L$3,OB_Act[Dump Area],"M4EW",OB_Act[Material],$E28) -> 0 | M28: =SUMIFS(OB_Act[Volume (BCM)],OB_Act[Day],Actual!M$3,OB_Act[Dump Area],"M4EW",OB_Act[Material],$E28) -> 0 | ... AJ28: =SUMIFS(OB_Act[Volume (BCM)],OB_Act[Day],Actual!AJ$3,OB_Act[Dump Area],"M4EW",OB_Act[Material],$E28) -> 0 | AK28: =SUM(F28:AJ28) -> 0 | AL28: =HLOOKUP(LEFT(Summary!D3,2),Actual!F3:AJ47,23,FALSE) -> 0
E29: MUD | F29: =SUMIFS(OB_Act[Volume (BCM)],OB_Act[Day],Actual!F$3,OB_Act[Dump Area],"M4EW",OB_Act[Material],$E29) -> 0 | G29: =SUMIFS(OB_Act[Volume (BCM)],OB_Act[Day],Actual!G$3,OB_Act[Dump Area],"M4EW",OB_Act[Material],$E29) -> 0 | H29: =SUMIFS(OB_Act[Volume (BCM)],OB_Act[Day],Actual!H$3,OB_Act[Dump Area],"M4EW",OB_Act[Material],$E29) -> 0 | I29: =SUMIFS(OB_Act[Volume (BCM)],OB_Act[Day],Actual!I$3,OB_Act[Dump Area],"M4EW",OB_Act[Material],$E29) -> 0 | J29: =SUMIFS(OB_Act[Volume (BCM)],OB_Act[Day],Actual!J$3,OB_Act[Dump Area],"M4EW",OB_Act[Material],$E29) -> 0 | K29: =SUMIFS(OB_Act[Volume (BCM)],OB_Act[Day],Actual!K$3,OB_Act[Dump Area],"M4EW",OB_Act[Material],$E29) -> 0 | L29: =SUMIFS(OB_Act[Volume (BCM)],OB_Act[Day],Actual!L$3,OB_Act[Dump Area],"M4EW",OB_Act[Material],$E29) -> 0 | M29: =SUMIFS(OB_Act[Volume (BCM)],OB_Act[Day],Actual!M$3,OB_Act[Dump Area],"M4EW",OB_Act[Material],$E29) -> 0 | ... AJ29: =SUMIFS(OB_Act[Volume (BCM)],OB_Act[Day],Actual!AJ$3,OB_Act[Dump Area],"M4EW",OB_Act[Material],$E29) -> 0 | AK29: =SUM(F29:AJ29) -> 0
E30: TS | F30: =SUMIFS(OB_Act[Volume (BCM)],OB_Act[Day],Actual!F$3,OB_Act[Dump Area],"M4EW",OB_Act[Material],$E30) -> 0 | G30: =SUMIFS(OB_Act[Volume (BCM)],OB_Act[Day],Actual!G$3,OB_Act[Dump Area],"M4EW",OB_Act[Material],$E30) -> 0 | H30: =SUMIFS(OB_Act[Volume (BCM)],OB_Act[Day],Actual!H$3,OB_Act[Dump Area],"M4EW",OB_Act[Material],$E30) -> 0 | I30: =SUMIFS(OB_Act[Volume (BCM)],OB_Act[Day],Actual!I$3,OB_Act[Dump Area],"M4EW",OB_Act[Material],$E30) -> 0 | J30: =SUMIFS(OB_Act[Volume (BCM)],OB_Act[Day],Actual!J$3,OB_Act[Dump Area],"M4EW",OB_Act[Material],$E30) -> 0 | K30: =SUMIFS(OB_Act[Volume (BCM)],OB_Act[Day],Actual!K$3,OB_Act[Dump Area],"M4EW",OB_Act[Material],$E30) -> 0 | L30: =SUMIFS(OB_Act[Volume (BCM)],OB_Act[Day],Actual!L$3,OB_Act[Dump Area],"M4EW",OB_Act[Material],$E30) -> 0 | M30: =SUMIFS(OB_Act[Volume (BCM)],OB_Act[Day],Actual!M$3,OB_Act[Dump Area],"M4EW",OB_Act[Material],$E30) -> 0 | ... AJ30: =SUMIFS(OB_Act[Volume (BCM)],OB_Act[Day],Actual!AJ$3,OB_Act[Dump Area],"M4EW",OB_Act[Material],$E30) -> 0 | AK30: =SUM(F30:AJ30) -> 0 | AL30: =HLOOKUP(LEFT(Summary!D3,2),Actual!F3:AJ47,24,FALSE) -> 0
E31: Total | F31: =SUM(F27:F30) -> 0 | G31: =SUM(G27:G30) -> 513 | H31: =SUM(H27:H30) -> 999 | I31: =SUM(I27:I30) -> 877.5 | J31: =SUM(J27:J30) -> 1147.5 | K31: =SUM(K27:K30) -> 0 | L31: =SUM(L27:L30) -> 1174.5 | M31: =SUM(M27:M30) -> 0 | ... AK31: =SUM(AK27:AK30) -> 4711.5 | AL31: =HLOOKUP(LEFT(Summary!D3,2),Actual!F3:AJ47,25,FALSE) -> 1174.5 | AM31: =HLOOKUP(LEFT(Summary!D3,2),Actual!F3:AJ52,29,FALSE) -> 1174.5
C32: PIT UCEX | E32: OB-PAF | F32: =SUMIFS(OB_Act[Volume (BCM)],OB_Act[Day],Actual!F$3,OB_Act[Pit],"PIT UCEX",OB_Act[Material],$E32) -> 0 | G32: =SUMIFS(OB_Act[Volume (BCM)],OB_Act[Day],Actual!G$3,OB_Act[Pit],"PIT UCEX",OB_Act[Material],$E32) -> 0 | H32: =SUMIFS(OB_Act[Volume (BCM)],OB_Act[Day],Actual!H$3,OB_Act[Pit],"PIT UCEX",OB_Act[Material],$E32) -> 0 | I32: =SUMIFS(OB_Act[Volume (BCM)],OB_Act[Day],Actual!I$3,OB_Act[Pit],"PIT UCEX",OB_Act[Material],$E32) -> 0 | J32: =SUMIFS(OB_Act[Volume (BCM)],OB_Act[Day],Actual!J$3,OB_Act[Pit],"PIT UCEX",OB_Act[Material],$E32) -> 0 | K32: =SUMIFS(OB_Act[Volume (BCM)],OB_Act[Day],Actual!K$3,OB_Act[Pit],"PIT UCEX",OB_Act[Material],$E32) -> 0 | L32: =SUMIFS(OB_Act[Volume (BCM)],OB_Act[Day],Actual!L$3,OB_Act[Pit],"PIT UCEX",OB_Act[Material],$E32) -> 0 | M32: =SUMIFS(OB_Act[Volume (BCM)],OB_Act[Day],Actual!M$3,OB_Act[Pit],"PIT UCEX",OB_Act[Material],$E32) -> 0 | ... AJ32: =SUMIFS(OB_Act[Volume (BCM)],OB_Act[Day],Actual!AJ$3,OB_Act[Pit],"PIT UCEX",OB_Act[Material],$E32) -> 0 | AK32: =SUM(F32:AJ32) -> 0 | AL32: =HLOOKUP(LEFT(Summary!D3,2),Actual!F3:AJ47,26,FALSE) -> 0
E33: OB-NAF | F33: =SUMIFS(OB_Act[Volume (BCM)],OB_Act[Day],Actual!F$3,OB_Act[Pit],"PIT UCEX",OB_Act[Material],$E33) -> 0 | G33: =SUMIFS(OB_Act[Volume (BCM)],OB_Act[Day],Actual!G$3,OB_Act[Pit],"PIT UCEX",OB_Act[Material],$E33) -> 0 | H33: =SUMIFS(OB_Act[Volume (BCM)],OB_Act[Day],Actual!H$3,OB_Act[Pit],"PIT UCEX",OB_Act[Material],$E33) -> 0 | I33: =SUMIFS(OB_Act[Volume (BCM)],OB_Act[Day],Actual!I$3,OB_Act[Pit],"PIT UCEX",OB_Act[Material],$E33) -> 0 | J33: =SUMIFS(OB_Act[Volume (BCM)],OB_Act[Day],Actual!J$3,OB_Act[Pit],"PIT UCEX",OB_Act[Material],$E33) -> 0 | K33: =SUMIFS(OB_Act[Volume (BCM)],OB_Act[Day],Actual!K$3,OB_Act[Pit],"PIT UCEX",OB_Act[Material],$E33) -> 0 | L33: =SUMIFS(OB_Act[Volume (BCM)],OB_Act[Day],Actual!L$3,OB_Act[Pit],"PIT UCEX",OB_Act[Material],$E33) -> 0 | M33: =SUMIFS(OB_Act[Volume (BCM)],OB_Act[Day],Actual!M$3,OB_Act[Pit],"PIT UCEX",OB_Act[Material],$E33) -> 0 | ... AJ33: =SUMIFS(OB_Act[Volume (BCM)],OB_Act[Day],Actual!AJ$3,OB_Act[Pit],"PIT UCEX",OB_Act[Material],$E33) -> 0 | AK33: =SUM(F33:AJ33) -> 0 | AL33: =HLOOKUP(LEFT(Summary!D3,2),Actual!F3:AJ47,27,FALSE) -> 0
E34: MUD | F34: =SUMIFS(OB_Act[Volume (BCM)],OB_Act[Day],Actual!F$3,OB_Act[Pit],"PIT UCEX",OB_Act[Material],$E34) -> 0 | G34: =SUMIFS(OB_Act[Volume (BCM)],OB_Act[Day],Actual!G$3,OB_Act[Pit],"PIT UCEX",OB_Act[Material],$E34) -> 0 | H34: =SUMIFS(OB_Act[Volume (BCM)],OB_Act[Day],Actual!H$3,OB_Act[Pit],"PIT UCEX",OB_Act[Material],$E34) -> 0 | I34: =SUMIFS(OB_Act[Volume (BCM)],OB_Act[Day],Actual!I$3,OB_Act[Pit],"PIT UCEX",OB_Act[Material],$E34) -> 0 | J34: =SUMIFS(OB_Act[Volume (BCM)],OB_Act[Day],Actual!J$3,OB_Act[Pit],"PIT UCEX",OB_Act[Material],$E34) -> 0 | K34: =SUMIFS(OB_Act[Volume (BCM)],OB_Act[Day],Actual!K$3,OB_Act[Pit],"PIT UCEX",OB_Act[Material],$E34) -> 0 | L34: =SUMIFS(OB_Act[Volume (BCM)],OB_Act[Day],Actual!L$3,OB_Act[Pit],"PIT UCEX",OB_Act[Material],$E34) -> 0 | M34: =SUMIFS(OB_Act[Volume (BCM)],OB_Act[Day],Actual!M$3,OB_Act[Pit],"PIT UCEX",OB_Act[Material],$E34) -> 0 | ... AJ34: =SUMIFS(OB_Act[Volume (BCM)],OB_Act[Day],Actual!AJ$3,OB_Act[Pit],"PIT UCEX",OB_Act[Material],$E34) -> 0 | AK34: =SUM(F34:AJ34) -> 0
E35: TS | F35: =SUMIFS(OB_Act[Volume (BCM)],OB_Act[Day],Actual!F$3,OB_Act[Pit],"PIT UCEX",OB_Act[Material],$E35) -> 0 | G35: =SUMIFS(OB_Act[Volume (BCM)],OB_Act[Day],Actual!G$3,OB_Act[Pit],"PIT UCEX",OB_Act[Material],$E35) -> 0 | H35: =SUMIFS(OB_Act[Volume (BCM)],OB_Act[Day],Actual!H$3,OB_Act[Pit],"PIT UCEX",OB_Act[Material],$E35) -> 0 | I35: =SUMIFS(OB_Act[Volume (BCM)],OB_Act[Day],Actual!I$3,OB_Act[Pit],"PIT UCEX",OB_Act[Material],$E35) -> 0 | J35: =SUMIFS(OB_Act[Volume (BCM)],OB_Act[Day],Actual!J$3,OB_Act[Pit],"PIT UCEX",OB_Act[Material],$E35) -> 0 | K35: =SUMIFS(OB_Act[Volume (BCM)],OB_Act[Day],Actual!K$3,OB_Act[Pit],"PIT UCEX",OB_Act[Material],$E35) -> 0 | L35: =SUMIFS(OB_Act[Volume (BCM)],OB_Act[Day],Actual!L$3,OB_Act[Pit],"PIT UCEX",OB_Act[Material],$E35) -> 0 | M35: =SUMIFS(OB_Act[Volume (BCM)],OB_Act[Day],Actual!M$3,OB_Act[Pit],"PIT UCEX",OB_Act[Material],$E35) -> 0 | ... AJ35: =SUMIFS(OB_Act[Volume (BCM)],OB_Act[Day],Actual!AJ$3,OB_Act[Pit],"PIT UCEX",OB_Act[Material],$E35) -> 0 | AK35: =SUM(F35:AJ35) -> 0 | AL35: =HLOOKUP(LEFT(Summary!D3,2),Actual!F3:AJ47,28,FALSE) -> 0
E36: Total by day | F36: =SUM(F32:F35) -> 0 | G36: =SUM(G32:G35) -> 0 | H36: =SUM(H32:H35) -> 0 | I36: =SUM(I32:I35) -> 0 | J36: =SUM(J32:J35) -> 0 | K36: =SUM(K32:K35) -> 0 | L36: =SUM(L32:L35) -> 0 | M36: =SUM(M32:M35) -> 0 | ... AK36: =SUM(AK32:AK35) -> 0 | AL36: EOP by clasification | AM36: =HLOOKUP(LEFT(Summary!D3,2),Actual!F3:AJ52,34,FALSE) -> 0 | AN36: =HLOOKUP(LEFT(Summary!D3,2),Actual!F3:AJ36,34,FALSE) -> 0
F37: 01 | G37: 02 | H37: 03 | I37: 04 | J37: 05 | K37: 06 | L37: 07 | M37: 08 | N37: 09 | O37: 10 | P37: 11 | Q37: 12 | R37: 13 | S37: 14 | T37: 15 | U37: 16 | V37: 17 | W37: 18 | X37: 19 | Y37: 20 | Z37: 21 | AA37: 22 | AB37: 23 | AC37: 24 | AD37: 25 | AE37: 26 | AF37: 27 | AG37: 28 | AH37: 29 | AI37: 30 | AJ37: 31
C38: Alternatif_Nursery | E38: OB-PAF | F38: =SUMIFS(OB_Act[Volume (BCM)],OB_Act[Day],Actual!F$3,OB_Act[Dump Area],"Alternatif_Nursery",OB_Act[Material],$E38) -> 0 | G38: =SUMIFS(OB_Act[Volume (BCM)],OB_Act[Day],Actual!G$3,OB_Act[Dump Area],"Alternatif_Nursery",OB_Act[Material],$E38) -> 0 | H38: =SUMIFS(OB_Act[Volume (BCM)],OB_Act[Day],Actual!H$3,OB_Act[Dump Area],"Alternatif_Nursery",OB_Act[Material],$E38) -> 0 | I38: =SUMIFS(OB_Act[Volume (BCM)],OB_Act[Day],Actual!I$3,OB_Act[Dump Area],"Alternatif_Nursery",OB_Act[Material],$E38) -> 0 | J38: =SUMIFS(OB_Act[Volume (BCM)],OB_Act[Day],Actual!J$3,OB_Act[Dump Area],"Alternatif_Nursery",OB_Act[Material],$E38) -> 0 | K38: =SUMIFS(OB_Act[Volume (BCM)],OB_Act[Day],Actual!K$3,OB_Act[Dump Area],"Alternatif_Nursery",OB_Act[Material],$E38) -> 0 | L38: =SUMIFS(OB_Act[Volume (BCM)],OB_Act[Day],Actual!L$3,OB_Act[Dump Area],"Alternatif_Nursery",OB_Act[Material],$E38) -> 0 | M38: =SUMIFS(OB_Act[Volume (BCM)],OB_Act[Day],Actual!M$3,OB_Act[Dump Area],"Alternatif_Nursery",OB_Act[Material],$E38) -> 0 | ... AJ38: =SUMIFS(OB_Act[Volume (BCM)],OB_Act[Day],Actual!AJ$3,OB_Act[Dump Area],"Alternatif_Nursery",OB_Act[Material],$E38) -> 0 | AK38: =SUM(F38:AJ38) -> 0 | AL38: =HLOOKUP(LEFT(Summary!D3,2),Actual!F3:AJ47,30,FALSE) -> 0
E39: OB-NAF | F39: =SUMIFS(OB_Act[Volume (BCM)],OB_Act[Day],Actual!F$3,OB_Act[Dump Area],"Alternatif_Nursery",OB_Act[Material],$E39) -> 0 | G39: =SUMIFS(OB_Act[Volume (BCM)],OB_Act[Day],Actual!G$3,OB_Act[Dump Area],"Alternatif_Nursery",OB_Act[Material],$E39) -> 0 | H39: =SUMIFS(OB_Act[Volume (BCM)],OB_Act[Day],Actual!H$3,OB_Act[Dump Area],"Alternatif_Nursery",OB_Act[Material],$E39) -> 0 | I39: =SUMIFS(OB_Act[Volume (BCM)],OB_Act[Day],Actual!I$3,OB_Act[Dump Area],"Alternatif_Nursery",OB_Act[Material],$E39) -> 0 | J39: =SUMIFS(OB_Act[Volume (BCM)],OB_Act[Day],Actual!J$3,OB_Act[Dump Area],"Alternatif_Nursery",OB_Act[Material],$E39) -> 0 | K39: =SUMIFS(OB_Act[Volume (BCM)],OB_Act[Day],Actual!K$3,OB_Act[Dump Area],"Alternatif_Nursery",OB_Act[Material],$E39) -> 0 | L39: =SUMIFS(OB_Act[Volume (BCM)],OB_Act[Day],Actual!L$3,OB_Act[Dump Area],"Alternatif_Nursery",OB_Act[Material],$E39) -> 0 | M39: =SUMIFS(OB_Act[Volume (BCM)],OB_Act[Day],Actual!M$3,OB_Act[Dump Area],"Alternatif_Nursery",OB_Act[Material],$E39) -> 0 | ... AJ39: =SUMIFS(OB_Act[Volume (BCM)],OB_Act[Day],Actual!AJ$3,OB_Act[Dump Area],"Alternatif_Nursery",OB_Act[Material],$E39) -> 0 | AK39: =SUM(F39:AJ39) -> 0 | AL39: =HLOOKUP(LEFT(Summary!D3,2),Actual!F3:AJ47,31,FALSE) -> 0
E40: MUD | F40: =SUMIFS(OB_Act[Volume (BCM)],OB_Act[Day],Actual!F$3,OB_Act[Dump Area],"Alternatif_Nursery",OB_Act[Material],$E40) -> 0 | G40: =SUMIFS(OB_Act[Volume (BCM)],OB_Act[Day],Actual!G$3,OB_Act[Dump Area],"Alternatif_Nursery",OB_Act[Material],$E40) -> 0 | H40: =SUMIFS(OB_Act[Volume (BCM)],OB_Act[Day],Actual!H$3,OB_Act[Dump Area],"Alternatif_Nursery",OB_Act[Material],$E40) -> 0 | I40: =SUMIFS(OB_Act[Volume (BCM)],OB_Act[Day],Actual!I$3,OB_Act[Dump Area],"Alternatif_Nursery",OB_Act[Material],$E40) -> 0 | J40: =SUMIFS(OB_Act[Volume (BCM)],OB_Act[Day],Actual!J$3,OB_Act[Dump Area],"Alternatif_Nursery",OB_Act[Material],$E40) -> 0 | K40: =SUMIFS(OB_Act[Volume (BCM)],OB_Act[Day],Actual!K$3,OB_Act[Dump Area],"Alternatif_Nursery",OB_Act[Material],$E40) -> 0 | L40: =SUMIFS(OB_Act[Volume (BCM)],OB_Act[Day],Actual!L$3,OB_Act[Dump Area],"Alternatif_Nursery",OB_Act[Material],$E40) -> 0 | M40: =SUMIFS(OB_Act[Volume (BCM)],OB_Act[Day],Actual!M$3,OB_Act[Dump Area],"Alternatif_Nursery",OB_Act[Material],$E40) -> 0 | ... AJ40: =SUMIFS(OB_Act[Volume (BCM)],OB_Act[Day],Actual!AJ$3,OB_Act[Dump Area],"Alternatif_Nursery",OB_Act[Material],$E40) -> 0 | AK40: =SUM(F40:AJ40) -> 0
E41: TS | F41: =SUMIFS(OB_Act[Volume (BCM)],OB_Act[Day],Actual!F$3,OB_Act[Dump Area],"Alternatif_Nursery",OB_Act[Material],$E41) -> 424.5 | G41: =SUMIFS(OB_Act[Volume (BCM)],OB_Act[Day],Actual!G$3,OB_Act[Dump Area],"Alternatif_Nursery",OB_Act[Material],$E41) -> 655.5 | H41: =SUMIFS(OB_Act[Volume (BCM)],OB_Act[Day],Actual!H$3,OB_Act[Dump Area],"Alternatif_Nursery",OB_Act[Material],$E41) -> 823.5 | I41: =SUMIFS(OB_Act[Volume (BCM)],OB_Act[Day],Actual!I$3,OB_Act[Dump Area],"Alternatif_Nursery",OB_Act[Material],$E41) -> 472.5 | J41: =SUMIFS(OB_Act[Volume (BCM)],OB_Act[Day],Actual!J$3,OB_Act[Dump Area],"Alternatif_Nursery",OB_Act[Material],$E41) -> 769.5 | K41: =SUMIFS(OB_Act[Volume (BCM)],OB_Act[Day],Actual!K$3,OB_Act[Dump Area],"Alternatif_Nursery",OB_Act[Material],$E41) -> 0 | L41: =SUMIFS(OB_Act[Volume (BCM)],OB_Act[Day],Actual!L$3,OB_Act[Dump Area],"Alternatif_Nursery",OB_Act[Material],$E41) -> 634.5 | M41: =SUMIFS(OB_Act[Volume (BCM)],OB_Act[Day],Actual!M$3,OB_Act[Dump Area],"Alternatif_Nursery",OB_Act[Material],$E41) -> 0 | ... AJ41: =SUMIFS(OB_Act[Volume (BCM)],OB_Act[Day],Actual!AJ$3,OB_Act[Dump Area],"Alternatif_Nursery",OB_Act[Material],$E41) -> 0 | AK41: =SUM(F41:AJ41) -> 3780 | AL41: =HLOOKUP(LEFT(Summary!D3,2),Actual!F3:AJ47,32,FALSE) -> 0
...

Sheet Budget
B2: ="Plan Budget "&MID(Outlook!B2,9,16) -> Plan Budget Production 2026 | E2: =IF(Outlook!F2="ACTUAL","PLANED","PLAN") -> PLANED | F2: =IF(Outlook!G2="ACTUAL","PLANED","PLAN") -> PLANED | G2: =IF(Outlook!H2="ACTUAL","PLANED","PLAN") -> PLANED | H2: =IF(Outlook!I2="ACTUAL","PLANED","PLAN") -> PLANED | I2: =IF(Outlook!J2="ACTUAL","PLANED","PLAN") -> PLANED | J2: =IF(Outlook!K2="ACTUAL","PLANED","PLAN") -> PLANED | K2: =IF(Outlook!L2="ACTUAL","PLANED","PLAN") -> PLANED | L2: =IF(Outlook!M2="ACTUAL","PLANED","PLAN") -> PLANED | ... Q2: =IF(Outlook!R2="ACTUAL","PLANED","PLAN") -> PLAN
C3: Unit | D3: =Outlook!E3 -> EOP 2025 | E3: Jan'26 | F3: Feb'26 | G3: Mar'26 | H3: Apr'26 | I3: May'26 | J3: Jun'26 | K3: Jul'26 | L3: Aug'26 | M3: Sep'26 | N3: Oct'26 | O3: Nov'26 | P3: Dec'26 | Q3: Total
B4: Waste Removal | C4: BCM | E4: 0 | F4: 0 | G4: 0 | H4: 385020 | I4: 431760 | J4: 438800 | K4: 397343 | L4: 407685 | M4: 424996 | N4: 373506 | O4: 275870 | P4: 272787 | Q4: =SUM(E4:P4) -> 3407767 | S4: =SUM(E4:J4) -> 1255580 | T4: 47865 | U4: =(T4/S4)*1 -> 0.038121824
B5: ROM Production | C5: Tons | E5: 0 | F5: 0 | G5: 0 | H5: 17001 | I5: 47759 | J5: 56990 | K5: 62730 | L5: 65795 | M5: 65645 | N5: 68584 | O5: 73282 | P5: 82213 | Q5: =SUM(E5:P5) -> 539999 | S5: =SUM(E5:J5) -> 121750
B6: SR | C6: BCM/Ton | E6: 0 | F6: 0 | G6: 0 | H6: =H4/H5 -> 22.646903 | I6: =I4/I5 -> 9.0403903 | J6: =J4/J5 -> 7.6995964 | K6: =K4/K5 -> 6.3341782 | L6: =L4/L5 -> 6.1962915 | M6: =M4/M5 -> 6.4741564 | N6: =N4/N5 -> 5.4459641 | O6: =O4/O5 -> 3.7644988 | P6: =P4/P5 -> 3.3180519 | Q6: =IF(Q4=0,0,IF(Q5=0,0,Q4/Q5)) -> 6.3106913
B7: ROM Stock | C7: Tons | D7: 0 | E7: 0 | F7: 0 | G7: 0 | H7: 0 | I7: 5758.93 | J7: 11692 | K7: 17305 | L7: 21927 | M7: 12353 | N7: 4813 | O7: 10047 | P7: 2160
B8: Crushed coal | C8: Tons | E8: 0 | F8: 0 | G8: 0 | H8: 17001 | I8: 42000 | J8: 51000 | K8: 57000 | L8: 61000 | M8: 75000 | N8: 76000 | O8: 68000 | P8: 90000 | Q8: =SUM(E8:P8) -> 537001
B9: F/C Stock | C9: Tons | D9: 11.742 | E9: 0 | F9: 0 | G9: 0 | H9: 9701 | I9: 29704 | J9: 22007 | K9: 20387 | L9: 22783 | M9: 24556 | N9: 20010 | O9: 210 | P9: 9908
B10: Barge loading | C10: Tons | E10: 0 | F10: 0 | G10: 0 | H10: 7300 | I10: 21900 | J10: 58400 | K10: 58400 | L10: 58400 | M10: 73000 | N10: 80300 | O10: 87600 | P10: 80300 | Q10: =SUM(E10:P10) -> 525600
B11: Uncovered coal | C11: Tons | E11: 0 | F11: 0 | G11: 0 | H11: 0 | I11: 0 | J11: 0 | K11: 0 | L11: 0 | M11: 0 | N11: 0 | O11: 0 | P11: 0
B12: Rain fall | C12: mm. | E12: 142.1 | F12: 81.2 | G12: 16 | H12: 33.5 | I12: 137.5 | J12: 526.05113 | K12: 258.0619 | L12: 163.06851 | M12: 178.82495 | N12: 121.50335 | O12: 175.55455 | P12: 254.38113 | Q12: =SUM(E12:P12) -> 2087.7455
B13: Rain fall Duration | C13: hrs. | E13: 88.416667 | F13: 74.533333 | G13: 13.983333 | H13: 37.3 | I13: 93.083333 | J13: 189 | K13: 151.4 | L13: 88.26 | M13: 41.39 | N13: 108.52 | O13: 105.96 | P13: 126.02 | Q13: =SUM(E13:P13) -> 1117.8667
B14: Slippery time | C14: hr. | E14: 0 | F14: 0 | G14: 0 | H14: 0 | I14: 0 | J14: 57.1 | K14: 59.17 | L14: 50.91 | M14: 52.82 | N14: 53.93 | O14: 71.22 | P14: 70.7 | Q14: =SUM(E14:P14) -> 415.85
B15: JBG Fuel stock | C15: Liters | E15: 35000 | F15: 35000 | G15: 35000 | H15: 35000 | I15: 35000 | J15: 35000 | K15: 35000 | L15: 35000 | M15: 35000 | N15: 35000 | O15: 35000 | P15: 35000
B17: Remark! | E17: =E13+E14 -> 88.416667
E20: Data actual rainfall 2004 - 2026 | S20: Data actual rainfall Duration 2012 - 2026 | AG20: Data actual Slippery 2012 - 2026
Q21: unit : mm. | AE21: unit : hours. | AS21: unit : mm.
F22: Jan | G22: Feb | H22: Mar | I22: Apr | J22: May | K22: Jun | L22: Jul | M22: Aug | N22: Sep | O22: Oct | P22: Nov | Q22: Dec | R22: Total | T22: Jan | U22: Feb | V22: Mar | W22: Apr | X22: May | Y22: Jun | Z22: Jul | AA22: Aug | AB22: Sep | AC22: Oct | AD22: Nov | AE22: Dec | AF22: Total | AH22: Jan | AI22: Feb | AJ22: Mar | AK22: Apr | AL22: May | AM22: Jun | AN22: Jul | AO22: Aug | AP22: Sep | AQ22: Oct | AR22: Nov | AS22: Dec | AT22: Total
E23: 2004 | F23: 292.2 | G23: 108.6 | H23: 333.4 | I23: 196 | J23: 324.6 | K23: 82.2 | L23: 79 | M23: 30 | N23: 36.4 | O23: 83.4 | P23: 55.6 | Q23: 148.7 | R23: =SUM(F23:Q23) -> 1770.1 | S23: 2004 | AF23: =SUM(T23:AE23) -> 0 | AG23: 2004 | AT23: =SUM(AH23:AS23) -> 0
E24: 2005 | F24: 199.3 | G24: 507 | H24: 376.5 | I24: 311 | J24: 279 | K24: 175.5 | L24: 90.2 | M24: 85.55 | N24: 11 | O24: 317 | P24: 348.6 | Q24: 313 | R24: =SUM(F24:Q24) -> 3013.65 | S24: 2005 | AF24: =SUM(T24:AE24) -> 0 | AG24: 2005 | AT24: =SUM(AH24:AS24) -> 0
E25: 2006 | F25: 303.5 | G25: 272 | H25: 367 | I25: 331 | J25: 120.5 | K25: 567 | L25: 109 | M25: 20 | N25: 38 | O25: 120 | P25: 165.73333 | Q25: 190 | R25: =SUM(F25:Q25) -> 2603.7333 | S25: 2006 | AF25: =SUM(T25:AE25) -> 0 | AG25: 2006 | AT25: =SUM(AH25:AS25) -> 0
E26: 2007 | F26: 281 | G26: 243 | H26: 293 | I26: 409 | J26: 274 | K26: 488 | L26: 956 | M26: 157 | N26: 91 | O26: 136 | P26: 58 | Q26: 24.8 | R26: =SUM(F26:Q26) -> 3410.8 | S26: 2007 | AF26: =SUM(T26:AE26) -> 0 | AG26: 2007 | AT26: =SUM(AH26:AS26) -> 0
E27: 2008 | F27: 117.16667 | G27: 78.866667 | H27: 173.23333 | I27: 192.4 | J27: 640 | K27: 190.83333 | L27: 325.23333 | M27: 401.2 | N27: 286 | O27: 166.43333 | P27: 477.76667 | Q27: 446.1 | R27: =SUM(F27:Q27) -> 3495.2333 | S27: 2008 | AF27: =SUM(T27:AE27) -> 0 | AG27: 2008 | AT27: =SUM(AH27:AS27) -> 0
E28: 2009 | F28: 340.13333 | G28: 162.7 | H28: 102.66667 | I28: 118.33333 | J28: 343.66667 | K28: 81.333333 | L28: 161.66667 | M28: 74.666667 | N28: 4.6666667 | O28: 110.66667 | P28: 150.66667 | Q28: 79.333333 | R28: =SUM(F28:Q28) -> 1730.5 | S28: 2009 | AF28: =SUM(T28:AE28) -> 0 | AG28: 2009 | AT28: =SUM(AH28:AS28) -> 0
E29: 2010 | F29: 177.25 | G29: 201.7 | H29: 267.9 | I29: 289.7 | J29: 295.35 | K29: 271 | L29: 327.15 | M29: 431.2 | N29: 203.45 | O29: 299.15 | P29: 163.65 | Q29: 70.2 | R29: =SUM(F29:Q29) -> 2997.7 | S29: 2010 | AF29: =SUM(T29:AE29) -> 0 | AG29: 2010 | AT29: =SUM(AH29:AS29) -> 0
E30: 2011 | F30: 125.05 | G30: 171.95 | H30: 201.81 | I30: 219 | J30: 111 | K30: 150.65 | L30: 80.9 | M30: 14.65 | N30: 83.05 | O30: 229.25 | P30: 244.75 | Q30: 267 | R30: =SUM(F30:Q30) -> 1899.06 | S30: 2011 | AF30: =SUM(T30:AE30) -> 0 | AG30: 2011 | AT30: =SUM(AH30:AS30) -> 0
E31: 2012 | F31: 187.26667 | G31: 135.66667 | H31: 188.06667 | I31: 126.63333 | J31: 114.13333 | K31: 158 | L31: 421 | M31: 307 | N31: 46 | O31: 92 | P31: 147.13333 | Q31: 236.23673 | R31: =SUM(F31:Q31) -> 2159.1367 | S31: 2012 | T31: 163 | U31: 58 | V31: 77 | W31: 72 | X31: 67 | Y31: 87 | Z31: 243 | AA31: 47 | AB31: 25 | AC31: 54.716667 | AD31: 80.033333 | AE31: 61.122222 | AF31: =SUM(T31:AE31) -> 1034.8722 | AG31: 2012 | AH31: 18 | AI31: 18 | AJ31: 24 | AK31: 13 | AL31: 26 | AM31: 24 | AN31: 20.5 | AO31: 6.5 | AP31: 6.5 | AQ31: 12.9 | AR31: 23.85 | AS31: 27.92 | AT31: =SUM(AH31:AS31) -> 221.17
E32: 2013 | F32: 191 | G32: 251.16667 | H32: 204.46667 | I32: 238 | J32: 160.93333 | K32: 171.33333 | L32: 464.86667 | M32: 257.86667 | N32: 172.4 | O32: 35 | P32: 152.06667 | Q32: 473 | R32: =SUM(F32:Q32) -> 2772.1 | S32: 2013 | T32: 197.06667 | U32: 143.53333 | V32: 74.733333 | W32: 68.016667 | X32: 76.45 | Y32: 65.95 | Z32: 220.98333 | AA32: 119.71667 | AB32: 81.416667 | AC32: 8.9833333 | AD32: 89.932778 | AE32: 203.54861 | AF32: =SUM(T32:AE32) -> 1350.3314 | AG32: 2013 | AH32: 27.35 | AI32: 23.58 | AJ32: 34.48 | AK32: 28.9 | AL32: 24.48 | AM32: 14.083333 | AN32: 30.5 | AO32: 15.083333 | AP32: 19.833333 | AQ32: 3.5 | AR32: 18.033056 | AS32: 37.983333 | AT32: =SUM(AH32:AS32) -> 277.80639
E33: 2014 | F33: 188.2 | G33: 174 | H33: 372.13333 | I33: 190.4 | J33: 292 | K33: 315.15 | L33: 174.59972 | M33: 196.4 | N33: 6 | O33: 110.93 | P33: 128.95 | Q33: 474.2 | R33: =SUM(F33:Q33) -> 2622.9631 | S33: 2014 | T33: 101.03306 | U33: 54.249722 | V33: 70.485694 | W33: 77 | X33: 92.3 | Y33: 114.15361 | Z33: 56.232778 | AA33: 83.77 | AB33: 5.5 | AC33: 21 | AD33: 20 | AE33: 132.26556 | AF33: =SUM(T33:AE33) -> 827.99042 | AG33: 2014 | AH33: 23.999861 | AI33: 15.16625 | AJ33: 19.833194 | AK33: 16.33 | AL33: 24.1 | AM33: 24.256528 | AN33: 21.5 | AO33: 11.4 | AP33: 1 | AQ33: 4 | AR33: 11.58 | AS33: 37.083056 | AT33: =SUM(AH33:AS33) -> 210.24889
E34: 2015 | F34: 238.5 | G34: 228 | H34: 127 | I34: 293.86667 | J34: 327.43333 | K34: 287.91333 | L34: 4.07 | M34: 1.1 | N34: 0 | O34: 57.35 | P34: 134.675 | Q34: 300.565 | R34: =SUM(F34:Q34) -> 2000.4733 | S34: 2015 | T34: 128.16583 | U34: 90.47 | V34: 45.23 | W34: 104.98528 | X34: 104.49944 | Y34: 143.09972 | Z34: 2.7 | AA34: 1 | AB34: 0 | AC34: 7.43 | AD34: 29.67 | AE34: 116.65 | AF34: =SUM(T34:AE34) -> 773.90028 | AG34: 2015 | AH34: 24.329722 | AI34: 42.25 | AJ34: 14.5 | AK34: 27.733333 | AL34: 20.5 | AM34: 14.833333 | AN34: 2 | AO34: 0 | AP34: 0 | AQ34: 2 | AR34: 11.45 | AS34: 26.4 | AT34: =SUM(AH34:AS34) -> 185.99639
E35: 2016 | F35: 223 | G35: 322.7 | H35: 351.475 | I35: 488.95 | J35: 337 | K35: 207 | L35: 228.4 | M35: 32.55 | N35: 140 | O35: 138.2 | P35: 208.15 | Q35: 156.7 | R35: =SUM(F35:Q35) -> 2834.125 | S35: 2016 | T35: 138.54167 | U35: 126.25667 | V35: 95.856667 | W35: 103.43333 | X35: 91.171667 | Y35: 74.933333 | Z35: 151.4 | AA35: 71.4 | AB35: 91.208333 | AC35: 67.74 | AD35: 105.09958 | AE35: 100 | AF35: =SUM(T35:AE35) -> 1217.0412 | AG35: 2016 | AH35: 24 | AI35: 33.17 | AJ35: 14.83 | AK35: 32 | AL35: 19.6 | AM35: 11.2 | AN35: 7.5 | AO35: 3 | AP35: 12 | AQ35: 17.1 | AR35: 18.2 | AS35: 37.93 | AT35: =SUM(AH35:AS35) -> 230.53
E36: 2017 | F36: 322.5 | G36: 185.4 | H36: 99.25 | I36: 260.95 | J36: 741 | K36: 533 | L36: 315.5 | M36: 291.3 | N36: 255.4 | O36: 104.8 | P36: 265.7 | Q36: 222.4 | R36: =SUM(F36:Q36) -> 3597.2 | S36: 2017 | T36: 68.24 | U36: 103.5 | V36: 44.63 | W36: 66.58 | X36: 168.97 | Y36: 157.41 | Z36: 104.76 | AA36: 91.25 | AB36: 38.16 | AC36: 49.04 | AD36: 105.96 | AE36: 74.82 | AF36: =SUM(T36:AE36) -> 1073.32 | AG36: 2017 | AH36: 63.02 | AI36: 20.5 | AJ36: 28.3 | AK36: 30.66 | AL36: 64.13 | AM36: 60.47 | AN36: 59.08 | AO36: 54.4 | AP36: 38.7 | AQ36: 39.86 | AR36: 73.02 | AS36: 66.046667 | AT36: =SUM(AH36:AS36) -> 598.18667
E37: 2018 | F37: 288.8 | G37: 310.3 | H37: 320 | I37: 62.5 | J37: 1000 | K37: 684 | L37: 121.5 | M37: 94.5 | N37: 107 | O37: 12 | P37: 176.5 | Q37: 271.8 | R37: =SUM(F37:Q37) -> 3448.9 | S37: 2018 | T37: 93.44 | U37: 90.25 | V37: 65.75 | W37: 33.92 | X37: 166.1 | Y37: 155.95 | Z37: 104.65 | AA37: 26.42 | AB37: 41.39 | AC37: 8.83 | AD37: 166.57667 | AE37: 100.77 | AF37: =SUM(T37:AE37) -> 1054.0467 | AG37: 2018 | AH37: 65.43 | AI37: 65.56 | AJ37: 60.51 | AK37: 24.58 | AL37: 92.94 | AM37: 59.72 | AN37: 27.48 | AO37: 17.31 | AP37: 28.5 | AQ37: 12.2 | AR37: 82.87 | AS37: 93.0967 | AT37: =SUM(AH37:AS37) -> 630.1967
