Workbook
Name _1A1_Z1...A10_Z10: 'present dem'!#REF!
Name _1A1_Z1...A10_Z10: 'present pen'!#REF!
Name _1A1_Z1...A10_Z10: #REF!
Name _Apr: [1]Validation!$A$33
Name _Aug: [1]Validation!$A$37
Name _Chubu1: [1]Validation!$A$5
Name _CHUBU10: '[2]Platinum Cstmr Performance 2010'!$C$58
Name _Chubu2: [1]Validation!$A$6
Name _Chubu3: [1]Validation!$A$7
Name _CHUBU4: '[2]Platinum Cstmr Performance 2010'!$C$21
Name _CHUBU5: '[2]Platinum Cstmr Performance 2010'!$C$25
Name _CHUBU6: '[2]Platinum Cstmr Performance 2010'!$C$34
Name _CHUBU7: '[2]Platinum Cstmr Performance 2010'!$C$44
Name _CHUBU8: '[2]Platinum Cstmr Performance 2010'!$C$49
Name _CHUBU9: '[2]Platinum Cstmr Performance 2010'!$C$57
Name _ChubuP1: [1]Chubu!$V$203
Name _ChubuP2: [1]Chubu!$V$204
Name _CLP: [1]Validation!$A$17
Name _CLPP1: [1]CLP!$V$203
Name _CLPP2: [1]CLP!$V$204
Name _DATE: #REF!
Name _Dec: [1]Validation!$A$41
Name _ENEL1: [1]Validation!$A$11
Name _ENEL10: '[2]Platinum Cstmr Performance 2010'!$C$48
Name _ENEL11: '[2]Platinum Cstmr Performance 2010'!$C$52
Name _ENEL12: '[2]Platinum Cstmr Performance 2010'!$C$59
Name _ENEL13: '[2]Platinum Cstmr Performance 2010'!$C$67
Name _ENEL2: '[2]Platinum Cstmr Performance 2010'!$C$12
Name _ENEL3: '[2]Platinum Cstmr Performance 2010'!$C$15
Name _ENEL4: '[2]Platinum Cstmr Performance 2010'!$C$20
Name _ENEL5: '[2]Platinum Cstmr Performance 2010'!$C$22
Name _ENEL6: '[2]Platinum Cstmr Performance 2010'!$C$29
Name _ENEL7: '[2]Platinum Cstmr Performance 2010'!$C$33
Name _ENEL8: '[2]Platinum Cstmr Performance 2010'!$C$39
Name _ENEL9: '[2]Platinum Cstmr Performance 2010'!$C$43
Name _ENELP1: '[1]Enel '!$V$264
Name _ENELP2: '[1]Enel '!$V$265
Name _EPDC: [1]Validation!$A$8
Name _EPDC1: '[2]Platinum Cstmr Performance 2010'!$C$17
Name _EPDC2: '[2]Platinum Cstmr Performance 2010'!$C$24
Name _EPDC3: '[2]Platinum Cstmr Performance 2010'!$C$38
Name _EPDC4: '[2]Platinum Cstmr Performance 2010'!$C$50
Name _EPDC5: '[2]Platinum Cstmr Performance 2010'!$C$69
Name _EPDC6: '[2]Platinum Cstmr Performance 2010'!#REF!
Name _EPDCP1: [1]EPDC!$V$203
Name _EPDCP2: [1]EPDC!$V$204
Name _Feb: [1]Validation!$A$31
Name _ffggggg: #REF!
Name _Formosa1: [1]Validation!$A$15
Name _FORMOSA10: '[2]Platinum Cstmr Performance 2010'!$C$42
Name _FORMOSA11: '[2]Platinum Cstmr Performance 2010'!$C$51
Name _FORMOSA12: '[2]Platinum Cstmr Performance 2010'!$C$53
Name _FORMOSA13: '[2]Platinum Cstmr Performance 2010'!$C$54
Name _FORMOSA14: '[2]Platinum Cstmr Performance 2010'!$C$60
Name _FORMOSA15: '[2]Platinum Cstmr Performance 2010'!$C$61
Name _FORMOSA16: '[2]Platinum Cstmr Performance 2010'!$C$64
Name _FORMOSA17: '[2]Platinum Cstmr Performance 2010'!$C$66
Name _FORMOSA18: '[2]Platinum Cstmr Performance 2010'!$C$68
Name _Formosa2: [1]Validation!$A$16
Name _FORMOSA3: '[2]Platinum Cstmr Performance 2010'!$C$23

Sheet Demurage 2024 (2)
B3: Actual
B4: Outlook
B5: Budget
S6: =Q11/O11 -> -1.0785907
E8: Month | F8: BoCT | I8: Non BoCT | L8: Direct barge | O8: Total Shipment ITM by Month | R8: Remark | V8: =3000000/29000000 -> 0.10344828
F9: ton | G9: Dem /Desp | H9: $ | I9: ton | J9: Dem /Desp | K9: $ | L9: ton | M9: Dem /Desp | N9: $ | O9: ton | P9: Dem /Desp | Q9: $
E10: Jan | F10: 755824.29 | G10: -2.1013876 | H10: =F10*G10 -> -1588279.8 | I10: 909711 | J10: -1.8616287 | K10: =I10*J10 -> -1693544.1 | L10: 12338 | M10: 0 | N10: =L10*M10 -> 0 | O10: =F10+I10+L10 -> 1677873.3 | P10: -1.9696318 | Q10: =H10+K10+N10 -> -3281823.9 | S10: =F10/O10 -> 0.45046565 | T10: =I10/O10 -> 0.54218099 | V10: 0.65 | W10: 0.3 | X10: 0.05
E11: Feb | F11: 857042.29 | G11: -0.42049509 | H11: =F11*G11 -> -360382.08 | I11: 486985 | J11: -2.2530058 | K11: =I11*J11 -> -1097180 | L11: 7330.677 | M11: 0 | N11: =L11*M11 -> 0 | O11: =F11+I11+L11 -> 1351358 | P11: -1.0908125 | Q11: =H11+K11+N11 -> -1457562.1 | S11: =F11/O11 -> 0.63420819 | T11: =I11/O11 -> 0.36036713
E12: Mar | F12: 722477.59 | G12: -1.112219 | H12: =F12*G12 -> -803553.33 | I12: 1250157 | J12: -0.84507802 | K12: =I12*J12 -> -1056480.2 | L12: 14728 | M12: 0 | N12: =L12*M12 -> 0 | O12: =F12+I12+L12 -> 1987362.6 | P12: -0.9402088 | Q12: =H12+K12+N12 -> -1860033.5 | S12: =F12/O12 -> 0.36353587 | T12: =I12/O12 -> 0.6290533 | V12: =(V10/1)*$V$8 -> 0.067241379 | W12: =(W10/1)*$V$8 -> 0.031034483 | X12: =(X10/1)*$V$8 -> 0.0051724138
E13: Apr | F13: 845558.15 | G13: -1.2413323 | H13: =F13*G13 -> -1049618.7 | I13: 934063 | J13: -1.3486084 | K13: =I13*J13 -> -1259685.2 | L13: 21910 | M13: 0 | N13: =L13*M13 -> 0 | O13: =F13+I13+L13 -> 1801531.1 | P13: -1.2969537 | Q13: =H13+K13+N13 -> -2309303.8 | S13: =F13/O13 -> 0.46935528 | T13: =I13/O13 -> 0.51848285
E14: May | F14: 751034 | G14: -0.91 | H14: =F14*G14 -> -683440.94 | I14: 1171558 | J14: -1.42 | K14: =I14*J14 -> -1663612.4 | L14: 14887 | M14: 0 | N14: =L14*M14 -> 0 | O14: =F14+I14+L14 -> 1937479 | P14: -1.23 | Q14: =H14+K14+N14 -> -2347053.3 | R14: =I14+L14 -> 1186445 | S14: =F14/O14 -> 0.38763465 | T14: =I14/O14 -> 0.60468165
E15: Jun | F15: 874691.37 | G15: -1.8022147 | H15: =F15*G15 -> -1576381.6 | I15: 1161537 | J15: -0.60482458 | K15: =I15*J15 -> -702526.13 | L15: 7031.128 | M15: 0 | N15: =L15*M15 -> 0 | O15: =F15+I15+L15 -> 2043259.5 | P15: -1.1174109 | Q15: =H15+K15+N15 -> -2278907.8 | R15: =I15+L15 -> 1168568.1 | S15: =F15/O15 -> 0.42808629 | T15: =I15/O15 -> 0.56847258 | V15: =(V10/0.95)*V8 -> 0.070780399 | W15: =(W10/0.95)*V8 -> 0.032667877
E16: Jul | F16: 1112142.3 | G16: -1.0197914 | H16: =F16*G16 -> -1134153.1 | I16: 938269 | J16: -1.6057868 | K16: =I16*J16 -> -1506660 | L16: 20308 | M16: 0 | N16: =L16*M16 -> 0 | O16: =F16+I16+L16 -> 2070719.3 | P16: -1.2910604 | Q16: =H16+K16+N16 -> -2640813.1 | R16: =I16+L16 -> 958577 | S16: =F16/O16 -> 0.53708018 | T16: =I16/O16 -> 0.4531126 | AA16: 1742344
E17: Aug | F17: 979553.05 | G17: -0.59617265 | H17: =F17*G17 -> -583982.74 | I17: 1121741 | J17: -0.68522889 | K17: =I17*J17 -> -768649.34 | L17: 7805 | M17: 0 | N17: =L17*M17 -> 0 | O17: =F17+I17+L17 -> 2109099 | P17: -0.64386749 | Q17: =H17+K17+N17 -> -1352632.1 | R17: =I17+L17 -> 1129546 | S17: =F17/O17 -> 0.46444146 | T17: =I17/O17 -> 0.5318579 | AA17: =O10+O11+AA16 -> 4771575.3
E18: Sep | F18: 1000387.3 | G18: -0.64839451 | H18: =F18*G18 -> -648645.62 | I18: 950660 | J18: -1.1383313 | K18: =I18*J18 -> -1082166.1 | L18: 0 | M18: 0 | N18: =L18*M18 -> 0 | O18: =F18+I18+L18 -> 1951047.3 | P18: -0.8871193 | Q18: =H18+K18+N18 -> -1730811.7 | R18: =I18+L18 -> 950660 | S18: =F18/O18 -> 0.51274374 | T18: =I18/O18 -> 0.48725626 | AA18: =4500000-O10-O11 -> 1470768.7
E19: Oct | F19: 935548.53 | G19: -1.0590987 | H19: =F19*G19 -> -990838.21 | I19: 1238499 | J19: -0.46349625 | K19: =I19*J19 -> -574039.64 | L19: 30009 | M19: 0 | N19: =L19*M19 -> 0 | O19: =F19+I19+L19 -> 2204056.5 | P19: -0.71630967 | Q19: =H19+K19+N19 -> -1564877.8 | R19: =I19+L19 -> 1268508 | S19: =F19/O19 -> 0.42446667 | T19: =I19/O19 -> 0.56191798 | AA19: 1820000
E20: Nov | F20: 955072.27 | G20: -0.8447289 | H20: =F20*G20 -> -806777.15 | I20: 1138196 | J20: -1.5187429 | K20: =I20*J20 -> -1728627 | L20: 45007 | M20: 0 | N20: =L20*M20 -> 0 | O20: =F20+I20+L20 -> 2138275.3 | P20: -1.2176908 | Q20: =H20+K20+N20 -> -2535404.2 | R20: =I20+L20 -> 1183203 | S20: =F20/O20 -> 0.44665544 | T20: =I20/O20 -> 0.53229629 | AA20: =AA19-30000 -> 1790000
E21: Dec | F21: 983000 | G21: -1.225769 | H21: =F21*G21 -> -1204931 | I21: 1560210 | J21: -1.2796592 | K21: =I21*J21 -> -1996537.1 | L21: 90000 | M21: 0 | N21: =L21*M21 -> 0 | O21: =F21+I21+L21 -> 2633210 | P21: -1.2667588 | Q21: =H21+K21+N21 -> -3201468.1 | R21: =I21+L21 -> 1650210 | S21: =F21/O21 -> 0.37330862 | T21: =I21/O21 -> 0.59251256
R22: -1
E23: Actual Q1 | F23: =SUM(F10:F12) -> 2335344.2 | G23: =SUMPRODUCT(F10:F12,G10:G12)/SUM(F10:F12) -> -1.1785052 | H23: =SUM(H10:H12) -> -2752215.2 | I23: =SUM(I10:I12) -> 2646853 | J23: =SUMPRODUCT(I10:I12,J10:J12)/SUM(I10:I12) -> -1.4535013 | K23: =SUM(K10:K12) -> -3847204.4 | L23: =SUM(L10:L12) -> 34396.677 | M23: =SUMPRODUCT(L10:L12,M10:M12)/SUM(L10:L12) -> 0 | N23: =SUM(N10:N12) -> 0 | O23: =SUM(O10:O12) -> 5016593.8 | P23: =SUMPRODUCT(O10:O12,P10:P12)/SUM(O10:O12) -> -1.3250837 | Q23: =SUM(Q10:Q12) -> -6599419.5
E24: Actual Q2 | F24: =SUM(F13:F15) -> 2471283.5 | G24: =SUMPRODUCT(F13:F15,G13:G15)/SUM(F13:F15) -> -1.3391589 | H24: =SUM(H13:H15) -> -3309441.2 | I24: =SUM(I13:I15) -> 3267158 | J24: =SUMPRODUCT(I13:I15,J13:J15)/SUM(I13:I15) -> -1.1097791 | K24: =SUM(K13:K15) -> -3625823.7 | L24: =SUM(L13:L15) -> 43828.128 | M24: =SUMPRODUCT(L13:L15,M13:M15)/SUM(L13:L15) -> 0 | N24: =SUM(N13:N15) -> 0 | O24: =SUM(O13:O15) -> 5782269.7 | P24: =SUMPRODUCT(O13:O15,P13:P15)/SUM(O13:O15) -> -1.211075 | Q24: =SUM(Q13:Q15) -> -6935264.9 | AA24: =0.61/1.1 -> 0.55454545
E25: Act Smstr 1 | F25: =SUM(F10:F15) -> 4806627.7 | G25: =SUMPRODUCT(F10:F15,G10:G15)/SUM(F10:F15) -> -1.2611038 | H25: =SUM(H10:H15) -> -6061656.4 | I25: =SUM(I10:I15) -> 5914011 | J25: =SUMPRODUCT(I10:I15,J10:J15)/SUM(I10:I15) -> -1.2636142 | K25: =SUM(K10:K15) -> -7473028 | L25: =SUM(L10:L15) -> 78224.805 | M25: =SUMPRODUCT(L10:L15,M10:M15)/SUM(L10:L15) -> 0 | N25: =SUM(N10:N15) -> 0 | O25: =SUM(O10:O15) -> 10798863 | P25: =SUMPRODUCT(O10:O15,P10:P15)/SUM(O10:O15) -> -1.2640375 | Q25: =SUM(Q10:Q15) -> -13534684
E26: Act Q3 | F26: =SUM(F16:F18) -> 3092082.6 | G26: =SUMPRODUCT(F16:F18,G16:G18)/SUM(F16:F18) -> -0.76543281 | H26: =SUM(H16:H18) -> -2366781.5 | I26: =SUM(I16:I18) -> 3010670 | J26: =SUMPRODUCT(I16:I18,J16:J18)/SUM(I16:I18) -> -1.1151921 | K26: =SUM(K16:K18) -> -3357475.4 | L26: =SUM(L16:L18) -> 28113 | M26: =SUMPRODUCT(L16:L18,M16:M18)/SUM(L16:L18) -> 0 | N26: =SUM(N16:N18) -> 0 | O26: =SUM(O16:O18) -> 6130865.6 | P26: =SUMPRODUCT(O16:O18,P16:P18)/SUM(O16:O18) -> -0.93986982 | Q26: =SUM(Q16:Q18) -> -5724256.8 | AA26: 0.61
E27: Prediction Q4 | F27: =SUM(F19:F21) -> 2873620.8 | G27: =SUMPRODUCT(F19:F21,G19:G21)/SUM(F19:F21) -> -1.0448652 | H27: =SUM(H19:H21) -> -3002546.3 | I27: =SUM(I19:I21) -> 3936905 | J27: =SUMPRODUCT(I19:I21,J19:J21)/SUM(I19:I21) -> -1.0920263 | K27: =SUM(K19:K21) -> -4299203.8 | L27: =SUM(L19:L21) -> 165016 | M27: =SUMPRODUCT(L19:L21,M19:M21)/SUM(L19:L21) -> 0 | N27: =SUM(N19:N21) -> 0 | O27: =SUM(O19:O21) -> 6975541.8 | P27: =SUMPRODUCT(O19:O21,P19:P21)/SUM(O19:O21) -> -1.0777926 | Q27: =SUM(Q19:Q21) -> -7301750.1 | S27: 2000 | AA27: 1.1
E28: Prediction Smstr 2 | F28: =SUM(F16:F21) -> 5965703.4 | G28: =SUMPRODUCT(F16:F21,G16:G21)/SUM(F16:F21) -> -0.90003264 | H28: =SUM(H16:H21) -> -5369327.8 | I28: =SUM(I16:I21) -> 6947575 | J28: =SUMPRODUCT(I16:I21,J16:J21)/SUM(I16:I21) -> -1.102065 | K28: =SUM(K16:K21) -> -7656679.2 | L28: =SUM(L16:L21) -> 193129 | M28: =SUMPRODUCT(L16:L21,M16:M21)/SUM(L16:L21) -> 0 | N28: =SUM(N16:N21) -> 0 | O28: =SUM(O16:O21) -> 13106407 | P28: =SUMPRODUCT(O16:O21,P16:P21)/SUM(O16:O21) -> -1.0132756 | Q28: =SUM(Q16:Q21) -> -13026007 | S28: 29000000
S29: =S27/S28 -> 6.8965517e-05
E30: Act Jan-Jun24 | F30: =SUM(F10:F16) -> 5918770 | G30: =SUMPRODUCT(F10:F16,G10:G16)/SUM(F10:F16) -> -1.215761 | H30: =SUM(H10:H16) -> -7195809.5 | I30: =SUM(I10:I16) -> 6852280 | J30: =SUMPRODUCT(I10:I16,J10:J16)/SUM(I10:I16) -> -1.3104672 | K30: =SUM(K10:K16) -> -8979688 | L30: =SUM(L10:L16) -> 98532.805 | M30: =SUMPRODUCT(L10:L16,M10:M16)/SUM(L10:L16) -> 0 | N30: =SUM(N10:N16) -> 0 | O30: =SUM(O10:O15) -> 10798863 | P30: =SUMPRODUCT(O10:O16,P10:P16)/SUM(O10:O16) -> -1.2683855 | Q30: =SUM(Q10:Q16) -> -16175498
E31: Predict Jan-Dec'24 | F31: =SUM(F10:F21) -> 10772331 | G31: =SUMPRODUCT(F10:F21,G10:G21)/SUM(F10:F21) -> -1.061143 | H31: =SUM(H10:H21) -> -11430984 | I31: =SUM(I10:I21) -> 12861586 | J31: =SUMPRODUCT(I10:I21,J10:J21)/SUM(I10:I21) -> -1.1763485 | K31: =SUM(K10:K21) -> -15129707 | L31: =SUM(L10:L21) -> 271353.8 | M31: =SUMPRODUCT(L10:L21,M10:M21)/SUM(L10:L21) -> 0 | N31: =SUM(N10:N21) -> 0 | O31: =SUM(O10:O21) -> 23905271 | P31: =SUMPRODUCT(O10:O21,P10:P21)/SUM(O10:O21) -> -1.1265537 | Q31: =SUM(Q10:Q21) -> -26560691
E32: in K ton | F32: 1000 | T32: 14163796 | U32: 0.59
J33: =SUMPRODUCT(I10:I19,J10:J19)/SUM(I10:I19) -> -1.1221432 | K33: ` | M33: =O23/6719422 -> 0.74658116 | O33: =27000000-O31 -> 3094729.1 | P33: =SUMPRODUCT(O10:O20,P10:P20)/SUM(O10:O20) -> -1.1091981 | Q33: -14985762 | T33: 15836204 | U33: 0.43
G34: =SUMPRODUCT(F10:F20,G10:G20)/SUM(F10:F20) -> -1.0446121 | J34: =SUMPRODUCT(I10:I20,J10:J20)/SUM(I10:I20) -> -1.1620859 | O34: =O31-400000 -> 23505271 | Q34: =12000000+29000000 -> 41000000 | S34: =Q34-Q33 -> 55985762 | U34: =SUMPRODUCT(T32:T33,U32:U33)/SUM(T32:T33) -> 0.50554024 | AI34: `
C35: =O33/70000 -> 44.210416 | F35: =SUM(F10:F17) -> 6898323 | G35: =SUMPRODUCT(F10:F17,G10:G17)/SUM(F10:F17) -> -1.1277802 | H35: =SUM(H10:H17) -> -7779792.3 | I35: =SUM(I10:I17) -> 7974021 | J35: =SUMPRODUCT(I10:I17,J10:J17)/SUM(I10:I17) -> -1.2225121 | K35: =SUM(K10:K17) -> -9748337.3 | L35: =SUM(L10:L17) -> 106337.8 | M35: =SUMPRODUCT(L10:L17,M10:M17)/SUM(L10:L17) -> 0 | N35: =SUM(N10:N17) -> 0 | O35: =SUM(O10:O17) -> 14978682 | P35: =SUMPRODUCT(O10:O17,P10:P17)/SUM(O10:O17) -> -1.1804492 | Q35: =SUM(Q10:Q17) -> -17528130
C37: =177*2 -> 354 | F37: =F10 -> 755824.29 | G37: =I10 -> 909711 | H37: =L10 -> 12338 | I37: =SUM(F37:H37) -> 1677873.3 | J37: =G10 -> -2.1013876 | K37: =J10 -> -1.8616287 | L37: =M10 -> 0 | M37: =SUMPRODUCT(F37:H37,J37:L37)/SUM(F37:H37) -> -1.9559426 | O37: 30000000 | Q37: =SUMPRODUCT(F37:G37,J37:K37)/I37 -> -1.9559426
F38: =F11 -> 857042.29 | G38: =I11 -> 486985 | H38: =L11 -> 7330.677 | I38: =SUM(F38:H38) -> 1351358 | J38: =G11 -> -0.42049509 | K38: =J11 -> -2.2530058 | L38: =M11 -> 0 | M38: =SUMPRODUCT(F38:H38,J38:L38)/SUM(F38:H38) -> -1.0785907 | O38: =O37-O31 -> 6094729.1 | Q38: =SUMPRODUCT(F38:G38,J38:K38)/I38 -> -1.0785907
F39: =F12 -> 722477.59 | G39: =I12 -> 1250157 | H39: =L12 -> 14728 | I39: =SUM(F39:H39) -> 1987362.6 | J39: =G12 -> -1.112219 | K39: =J12 -> -0.84507802 | L39: =M12 -> 0 | M39: =SUMPRODUCT(F39:H39,J39:L39)/SUM(F39:H39) -> -0.93593063 | Q39: =SUMPRODUCT(F39:G39,J39:K39)/I39 -> -0.93593063
C40: =498.63/938500 -> 0.00053130527 | F40: =F13 -> 845558.15 | G40: =I13 -> 934063 | H40: =L13 -> 21910 | I40: =SUM(F40:H40) -> 1801531.1 | J40: =G13 -> -1.2413323 | K40: =J13 -> -1.3486084 | L40: =M13 -> 0 | M40: =SUMPRODUCT(F40:H40,J40:L40)/SUM(F40:H40) -> -1.2818562 | O40: =O31-65000-80000 -> 23760271 | Q40: =SUMPRODUCT(F40:G40,J40:K40)/I40 -> -1.2818562 | R40: 29116933
F41: =F14 -> 751034 | G41: =I14 -> 1171558 | H41: =L14 -> 14887 | I41: =SUM(F41:H41) -> 1937479 | J41: =G14 -> -0.91 | K41: =J14 -> -1.42 | L41: =M14 -> 0 | M41: =SUMPRODUCT(F41:H41,J41:L41)/SUM(F41:H41) -> -1.2113955 | P41: =O31*P31 -> -26930571 | Q41: =SUMPRODUCT(F41:G41,J41:K41)/I41 -> -1.2113955
F42: =F15 -> 874691.37 | G42: =I15 -> 1161537 | H42: =L15 -> 7031.128 | I42: =SUM(F42:H42) -> 2043259.5 | J42: =G15 -> -1.8022147 | K42: =J15 -> -0.60482458 | L42: =M15 -> 0 | M42: =SUMPRODUCT(F42:H42,J42:L42)/SUM(F42:H42) -> -1.1153296 | Q42: =SUMPRODUCT(F42:G42,J42:K42)/I42 -> -1.1153296
F43: =F16 -> 1112142.3 | G43: =I16 -> 938269 | H43: =L16 -> 20308 | I43: =SUM(F43:H43) -> 2070719.3 | J43: =G16 -> -1.0197914 | K43: =J16 -> -1.6057868 | L43: =M16 -> 0 | M43: =SUMPRODUCT(F43:H43,J43:L43)/SUM(F43:H43) -> -1.275312 | O43: =(F20+F21)/2 -> 969036.14 | Q43: =SUMPRODUCT(F43:G43,J43:K43)/I43 -> -1.275312
F44: =F17 -> 979553.05 | G44: =I17 -> 1121741 | H44: =L17 -> 7805 | I44: =SUM(F44:H44) -> 2109099 | J44: =G17 -> -0.59617265 | K44: =J17 -> -0.68522889 | L44: =M17 -> 0 | M44: =SUMPRODUCT(F44:H44,J44:L44)/SUM(F44:H44) -> -0.6413317 | Q44: =SUMPRODUCT(F44:G44,J44:K44)/I44 -> -0.6413317
...

Sheet Demurage 2026
B3: Actual
B4: Outlook
B5: Budget
E8: Month | F8: BoCT | I8: Non BoCT | L8: Direct barge | O8: Total Shipment ITM by Month | R8: Remark
F9: ton | G9: Dem /Desp | H9: $ | I9: ton | J9: Dem /Desp | K9: $ | L9: ton | M9: Dem /Desp | N9: $ | O9: ton | P9: Dem /Desp | Q9: $
E10: Jan | F10: 1049005 | G10: -0.57 | H10: =F10*G10 -> -597932.86 | I10: 1092734.9 | J10: -0.19 | K10: =I10*J10 -> -207619.63 | L10: 42522 | M10: 0 | N10: =L10*M10 -> 0 | O10: =F10+I10+L10 -> 2184261.9 | P10: -0.37 | Q10: =H10+K10+N10 -> -805552.49
E11: Feb | F11: 865634 | G11: -0.37 | H11: =F11*G11 -> -320284.58 | I11: 1191839 | J11: -0.24 | K11: =I11*J11 -> -286041.36 | L11: 65133 | M11: 0 | N11: =L11*M11 -> 0 | O11: =F11+I11+L11 -> 2122606 | P11: -0.29 | Q11: =H11+K11+N11 -> -606325.94
E12: Mar | F12: 941705.85 | G12: -0.86 | H12: =F12*G12 -> -809867.03 | I12: 949790.48 | J12: -0.37 | K12: =I12*J12 -> -351422.48 | L12: 60101 | M12: 0 | N12: =L12*M12 -> 0 | O12: =F12+I12+L12 -> 1951597.3 | P12: -0.6 | Q12: =H12+K12+N12 -> -1161289.5
E13: Apr | F13: 948486.78 | G13: -0.42 | H13: =F13*G13 -> -398364.45 | I13: 923560 | J13: -0.47 | K13: =I13*J13 -> -434073.2 | L13: 15008 | M13: 0 | N13: =L13*M13 -> 0 | O13: =F13+I13+L13 -> 1887054.8 | P13: -0.44 | Q13: =H13+K13+N13 -> -832437.65
E14: May | F14: 755972.04 | G14: -0.19 | H14: =F14*G14 -> -143634.69 | I14: 1282215 | J14: -0.38 | K14: =I14*J14 -> -487241.7 | L14: 7544 | M14: 0 | N14: =L14*M14 -> 0 | O14: =F14+I14+L14 -> 2045731 | P14: -0.31 | Q14: =H14+K14+N14 -> -630876.39 | R14: =I14+L14 -> 1289759
E15: Jun | F15: 1015599 | G15: -0.72 | H15: =F15*G15 -> -731231.28 | I15: 1087577 | J15: -0.46 | K15: =I15*J15 -> -500285.42 | L15: 37513 | M15: 0 | N15: =L15*M15 -> 0 | O15: =F15+I15+L15 -> 2140689 | P15: -0.58 | Q15: =H15+K15+N15 -> -1231516.7 | R15: =I15+L15 -> 1125090
E16: Jul | F16: 1080333 | G16: -0.26 | H16: =F16*G16 -> -280886.58 | I16: 1344420 | J16: -0.25 | K16: =I16*J16 -> -336105 | L16: 7608 | M16: 0 | N16: =L16*M16 -> 0 | O16: =F16+I16+L16 -> 2432361 | P16: -0.25 | Q16: =H16+K16+N16 -> -616991.58 | R16: =I16+L16 -> 1352028
E17: Aug | F17: 965853 | G17: -0.25 | H17: =F17*G17 -> -241463.25 | I17: 869059 | J17: -0.11 | K17: =I17*J17 -> -95596.49 | L17: 0 | M17: 0 | N17: =L17*M17 -> 0 | O17: =F17+I17+L17 -> 1834912 | P17: -0.19 | Q17: =H17+K17+N17 -> -337059.74 | R17: =I17+L17 -> 869059
E18: Sep | F18: 1046262 | G18: -1.03 | H18: =F18*G18 -> -1077649.9 | I18: 1029914.7 | J18: -1.35 | K18: =I18*J18 -> -1390384.8 | L18: 7500 | M18: 0 | N18: =L18*M18 -> 0 | O18: =F18+I18+L18 -> 2083676.7 | P18: -1.19 | Q18: =H18+K18+N18 -> -2468034.7 | R18: =I18+L18 -> 1037414.7
E19: Oct | F19: 1177000 | G19: -0.71 | H19: =F19*G19 -> -835670 | I19: 1126000 | J19: -0.53 | K19: =I19*J19 -> -596780 | L19: 247500 | M19: 0 | N19: =L19*M19 -> 0 | O19: =F19+I19+L19 -> 2550500 | P19: -0.61 | Q19: =H19+K19+N19 -> -1432450 | R19: =I19+L19 -> 1373500
E20: Nov | F20: 1185000 | G20: -0.32 | H20: =F20*G20 -> -379200 | I20: 1004000 | J20: -0.31 | K20: =I20*J20 -> -311240 | L20: 405000 | M20: 0 | N20: =L20*M20 -> 0 | O20: =F20+I20+L20 -> 2594000 | P20: -0.31 | Q20: =H20+K20+N20 -> -690440 | R20: =I20+L20 -> 1409000
E21: Dec | F21: 150000 | G21: 0 | H21: =F21*G21 -> 0 | I21: 220000 | J21: 0 | K21: =I21*J21 -> 0 | L21: 285000 | M21: 0 | N21: =L21*M21 -> 0 | O21: =F21+I21+L21 -> 655000 | P21: 0 | Q21: =H21+K21+N21 -> 0 | R21: =I21+L21 -> 505000
R22: -1
E23: Actual Q1 | F23: =SUM(F10:F12) -> 2856344.9 | G23: =SUMPRODUCT(F10:F12,G10:G12)/SUM(F10:F12) -> -0.60499854 | H23: =SUM(H10:H12) -> -1728084.5 | I23: =SUM(I10:I12) -> 3234364.4 | J23: =SUMPRODUCT(I10:I12,J10:J12)/SUM(I10:I12) -> -0.2612827 | K23: =SUM(K10:K12) -> -845083.47 | L23: =SUM(L10:L12) -> 167756 | M23: =SUMPRODUCT(L10:L12,M10:M12)/SUM(L10:L12) -> 0 | N23: =SUM(N10:N12) -> 0 | O23: =SUM(O10:O12) -> 6258465.2 | P23: =SUMPRODUCT(O10:O12,P10:P12)/SUM(O10:O12) -> -0.41458903 | Q23: =SUM(Q10:Q12) -> -2573167.9
E24: Actual Q2 | F24: =SUM(F13:F15) -> 2720057.8 | G24: =SUMPRODUCT(F13:F15,G13:G15)/SUM(F13:F15) -> -0.46808947 | H24: =SUM(H13:H15) -> -1273230.4 | I24: =SUM(I13:I15) -> 3293352 | J24: =SUMPRODUCT(I13:I15,J13:J15)/SUM(I13:I15) -> -0.43165757 | K24: =SUM(K13:K15) -> -1421600.3 | L24: =SUM(L13:L15) -> 60065 | M24: =SUMPRODUCT(L13:L15,M13:M15)/SUM(L13:L15) -> 0 | N24: =SUM(N13:N15) -> 0 | O24: =SUM(O13:O15) -> 6073474.8 | P24: =SUMPRODUCT(O13:O15,P13:P15)/SUM(O13:O15) -> -0.44555719 | Q24: =SUM(Q13:Q15) -> -2694830.7
E25: Actual S1 | F25: =SUM(F10:F15) -> 5576402.7 | G25: =SUMPRODUCT(F10:F15,G10:G15)/SUM(F10:F15) -> -0.53821703 | H25: =SUM(H10:H15) -> -3001314.9 | I25: =SUM(I10:I15) -> 6527716.4 | J25: =SUMPRODUCT(I10:I15,J10:J15)/SUM(I10:I15) -> -0.34723993 | K25: =SUM(K10:K15) -> -2266683.8 | L25: =SUM(L10:L15) -> 227821 | M25: =SUMPRODUCT(L10:L15,M10:M15)/SUM(L10:L15) -> 0 | N25: =SUM(N10:N15) -> 0 | O25: =SUM(O10:O15) -> 12331940 | P25: =SUMPRODUCT(O10:O15,P10:P15)/SUM(O10:O15) -> -0.42984083 | Q25: =SUM(Q10:Q15) -> -5267998.7
E26: Prediction Q3 | F26: =SUM(F16:F18) -> 3092448 | G26: =SUMPRODUCT(F16:F18,G16:G18)/SUM(F16:F18) -> -0.51738936 | H26: =SUM(H16:H18) -> -1599999.7 | I26: =SUM(I16:I18) -> 3243393.7 | J26: =SUMPRODUCT(I16:I18,J16:J18)/SUM(I16:I18) -> -0.56178389 | K26: =SUM(K16:K18) -> -1822086.3 | L26: =SUM(L16:L18) -> 15108 | M26: =SUMPRODUCT(L16:L18,M16:M18)/SUM(L16:L18) -> 0 | N26: =SUM(N16:N18) -> 0 | O26: =SUM(O16:O18) -> 6350949.7 | P26: =SUMPRODUCT(O16:O18,P16:P18)/SUM(O16:O18) -> -0.5410685 | Q26: =SUM(Q16:Q18) -> -3422086
E27: Prediction Q4 | F27: =SUM(F19:F21) -> 2512000 | G27: =SUMPRODUCT(F19:F21,G19:G21)/SUM(F19:F21) -> -0.48362659 | H27: =SUM(H19:H21) -> -1214870 | I27: =SUM(I19:I21) -> 2350000 | J27: 0 | K27: =SUM(K19:K21) -> -908020 | L27: =SUM(L19:L21) -> 937500 | M27: 0 | N27: =SUM(N19:N21) -> 0 | O27: =SUM(O19:O21) -> 5799500 | P27: =SUMPRODUCT(O19:O21,P19:P21)/SUM(O19:O21) -> -0.40692215 | Q27: =SUM(Q19:Q21) -> -2122890
E28: Prediction S2 | F28: =SUM(F16:F21) -> 5604448 | G28: =SUMPRODUCT(F16:F21,G16:G21)/SUM(F16:F21) -> -0.50225637 | H28: =SUM(H16:H21) -> -2814869.7 | I28: =SUM(I16:I21) -> 5593393.7 | J28: =SUMPRODUCT(I16:I21,J16:J21)/SUM(I16:I21) -> -0.48809479 | K28: =SUM(K16:K21) -> -2730106.3 | L28: =SUM(L16:L21) -> 952608 | M28: =SUMPRODUCT(L16:L21,M16:M21)/SUM(L16:L21) -> 0 | N28: =SUM(N16:N21) -> 0 | O28: =SUM(O16:O21) -> 12150450 | P28: =SUMPRODUCT(O16:O21,P16:P21)/SUM(O16:O21) -> -0.47703945 | Q28: =SUM(Q16:Q21) -> -5544976
E30: Predict Jan-Dec '26 | F30: =SUM(F10:F21) -> 11180851 | G30: =SUMPRODUCT(F10:F21,G10:G21)/SUM(F10:F21) -> -0.5201916 | H30: =SUM(H10:H21) -> -5816184.6 | I30: =SUM(I10:I21) -> 12121110 | J30: =SUMPRODUCT(I10:I21,J10:J21)/SUM(I10:I21) -> -0.41223865 | K30: =SUM(K10:K21) -> -4996790.1 | L30: =SUM(L10:L21) -> 1180429 | M30: =SUMPRODUCT(L10:L21,M10:M21)/SUM(L10:L21) -> 0 | N30: =SUM(N10:N21) -> 0 | O30: =SUM(O10:O21) -> 24482390 | P30: =SUMPRODUCT(O10:O21,P10:P21)/SUM(O10:O21) -> -0.4532652 | Q30: =SUM(Q10:Q21) -> -10812975
AI32: `
C33: =O31/70000 -> 0
C35: =177*2 -> 354
C38: =498.63/938500 -> 0.00053130527
Q72: 0.82565812
Q73: 0.39171475
Q74: 0.33133509
Q75: 0.4
Q76: =AVERAGE(Q72:Q75) -> 0.48717699
R170: Mar | S170: Apr | T170: May | U170: Jun | V170: Jul | W170: Aug | X170: Sep | Y170: Oct | Z170: Nov | AA170: Dec
R171: 2461 | S171: 2507 | T171: 2464 | U171: 2615 | V171: 2421 | W171: 2877 | X171: 2579 | Y171: 2313 | Z171: 2628.2752 | AA171: 2476.2011
Z181: 12279
Z184: 12272.838 | AA184: 759138.08
Z185: 12279 | AA185: 1895796
AA187: =SUMPRODUCT(Z184:Z185,AA184:AA185)/SUM(AA184:AA185) -> 12277.238
...

Sheet present dem
B3: Actual
B4: Outlook
B5: Budget
R6: =P11/N11 -> -0.28565167
D8: Month | E8: BoCT | H8: Non BoCT | K8: Direct barge | N8: Total Shipment ITM by Month | Q8: Remark | U8: =3000000/29000000 -> 0.10344828
E9: ton | F9: Dem /Desp | G9: $ | H9: ton | I9: Dem /Desp | J9: $ | K9: ton | L9: Dem /Desp | M9: $ | N9: ton | O9: Dem /Desp | P9: $
D10: Jan | E10: ='Demurage 2026'!F10/$E$32 -> 1049.005 | F10: ='Demurage 2026'!G10 -> -0.57 | G10: =E10*F10 -> -597.93286 | H10: ='Demurage 2026'!I10/$E$32 -> 1092.7349 | I10: ='Demurage 2026'!J10 -> -0.19 | J10: =H10*I10 -> -207.61963 | K10: ='Demurage 2026'!L10/$E$32 -> 42.522 | L10: ='Demurage 2026'!M10 -> 0 | M10: =K10*L10 -> 0 | N10: =E10+H10+K10 -> 2184.2619 | O10: ='Demurage 2026'!P10 -> -0.37 | P10: =G10+J10+M10 -> -805.55249 | R10: =E10/N10 -> 0.48025605 | S10: =H10/N10 -> 0.5002765 | U10: 0.65 | V10: 0.3 | W10: 0.05
D11: Feb | E11: ='Demurage 2026'!F11/$E$32 -> 865.634 | F11: ='Demurage 2026'!G11 -> -0.37 | G11: =E11*F11 -> -320.28458 | H11: ='Demurage 2026'!I11/$E$32 -> 1191.839 | I11: ='Demurage 2026'!J11 -> -0.24 | J11: =H11*I11 -> -286.04136 | K11: ='Demurage 2026'!L11/$E$32 -> 65.133 | L11: ='Demurage 2026'!M11 -> 0 | M11: =K11*L11 -> 0 | N11: =E11+H11+K11 -> 2122.606 | O11: ='Demurage 2026'!P11 -> -0.29 | P11: =G11+J11+M11 -> -606.32594 | R11: =E11/N11 -> 0.40781662 | S11: =H11/N11 -> 0.56149799
D12: Mar | E12: ='Demurage 2026'!F12/$E$32 -> 941.70585 | F12: ='Demurage 2026'!G12 -> -0.86 | G12: =E12*F12 -> -809.86703 | H12: ='Demurage 2026'!I12/$E$32 -> 949.79048 | I12: ='Demurage 2026'!J12 -> -0.37 | J12: =H12*I12 -> -351.42248 | K12: ='Demurage 2026'!L12/$E$32 -> 60.101 | L12: ='Demurage 2026'!M12 -> 0 | M12: =K12*L12 -> 0 | N12: =E12+H12+K12 -> 1951.5973 | O12: ='Demurage 2026'!P12 -> -0.6 | P12: =G12+J12+M12 -> -1161.2895 | R12: =E12/N12 -> 0.48253082 | S12: =H12/N12 -> 0.48667338 | U12: =(U10/1)*$U$8 -> 0.067241379 | V12: =(V10/1)*$U$8 -> 0.031034483 | W12: =(W10/1)*$U$8 -> 0.0051724138
D13: Apr | E13: ='Demurage 2026'!F13/$E$32 -> 948.48678 | F13: ='Demurage 2026'!G13 -> -0.42 | G13: =E13*F13 -> -398.36445 | H13: ='Demurage 2026'!I13/$E$32 -> 923.56 | I13: ='Demurage 2026'!J13 -> -0.47 | J13: =H13*I13 -> -434.0732 | K13: ='Demurage 2026'!L13/$E$32 -> 15.008 | L13: ='Demurage 2026'!M13 -> 0 | M13: =K13*L13 -> 0 | N13: =E13+H13+K13 -> 1887.0548 | O13: ='Demurage 2026'!P13 -> -0.44 | P13: =G13+J13+M13 -> -832.43765 | R13: =E13/N13 -> 0.50262811 | S13: =H13/N13 -> 0.48941875
D14: May | E14: ='Demurage 2026'!F14/$E$32 -> 755.97204 | F14: ='Demurage 2026'!G14 -> -0.19 | G14: =E14*F14 -> -143.63469 | H14: ='Demurage 2026'!I14/$E$32 -> 1282.215 | I14: ='Demurage 2026'!J14 -> -0.38 | J14: =H14*I14 -> -487.2417 | K14: ='Demurage 2026'!L14/$E$32 -> 7.544 | L14: ='Demurage 2026'!M14 -> 0 | M14: =K14*L14 -> 0 | N14: =E14+H14+K14 -> 2045.731 | O14: ='Demurage 2026'!P14 -> -0.31 | P14: =G14+J14+M14 -> -630.87639 | Q14: =H14+K14 -> 1289.759 | R14: =E14/N14 -> 0.36953638 | S14: =H14/N14 -> 0.62677594
D15: Jun | E15: ='Demurage 2026'!F15/$E$32 -> 1015.599 | F15: ='Demurage 2026'!G15 -> -0.72 | G15: =E15*F15 -> -731.23128 | H15: ='Demurage 2026'!I15/$E$32 -> 1087.577 | I15: ='Demurage 2026'!J15 -> -0.46 | J15: =H15*I15 -> -500.28542 | K15: ='Demurage 2026'!L15/$E$32 -> 37.513 | L15: ='Demurage 2026'!M15 -> 0 | M15: =K15*L15 -> 0 | N15: =E15+H15+K15 -> 2140.689 | O15: ='Demurage 2026'!P15 -> -0.58 | P15: =G15+J15+M15 -> -1231.5167 | Q15: =H15+K15 -> 1125.09 | R15: =E15/N15 -> 0.47442622 | S15: =H15/N15 -> 0.50804998 | U15: =(U10/0.95)*U8 -> 0.070780399 | V15: =(V10/0.95)*U8 -> 0.032667877
D16: Jul | E16: ='Demurage 2026'!F16/$E$32 -> 1080.333 | F16: ='Demurage 2026'!G16 -> -0.26 | G16: =E16*F16 -> -280.88658 | H16: ='Demurage 2026'!I16/$E$32 -> 1344.42 | I16: ='Demurage 2026'!J16 -> -0.25 | J16: =H16*I16 -> -336.105 | K16: ='Demurage 2026'!L16/$E$32 -> 7.608 | L16: ='Demurage 2026'!M16 -> 0 | M16: =K16*L16 -> 0 | N16: =E16+H16+K16 -> 2432.361 | O16: ='Demurage 2026'!P16 -> -0.25 | P16: =G16+J16+M16 -> -616.99158 | Q16: =H16+K16 -> 1352.028 | R16: =E16/N16 -> 0.44414994 | S16: =H16/N16 -> 0.55272223
D17: Aug | E17: ='Demurage 2026'!F17/$E$32 -> 965.853 | F17: ='Demurage 2026'!G17 -> -0.25 | G17: =E17*F17 -> -241.46325 | H17: ='Demurage 2026'!I17/$E$32 -> 869.059 | I17: ='Demurage 2026'!J17 -> -0.11 | J17: =H17*I17 -> -95.59649 | K17: ='Demurage 2026'!L17/$E$32 -> 0 | L17: ='Demurage 2026'!M17 -> 0 | M17: =K17*L17 -> 0 | N17: =E17+H17+K17 -> 1834.912 | O17: ='Demurage 2026'!P17 -> -0.19 | P17: =G17+J17+M17 -> -337.05974 | Q17: =H17+K17 -> 869.059 | R17: =E17/N17 -> 0.52637565 | S17: =H17/N17 -> 0.47362435
D18: Sep | E18: ='Demurage 2026'!F18/$E$32 -> 1046.262 | F18: ='Demurage 2026'!G18 -> -1.03 | G18: =E18*F18 -> -1077.6499 | H18: ='Demurage 2026'!I18/$E$32 -> 1029.9147 | I18: ='Demurage 2026'!J18 -> -1.35 | J18: =H18*I18 -> -1390.3848 | K18: ='Demurage 2026'!L18/$E$32 -> 7.5 | L18: ='Demurage 2026'!M18 -> 0 | M18: =K18*L18 -> 0 | N18: =E18+H18+K18 -> 2083.6767 | O18: ='Demurage 2026'!P18 -> -1.19 | P18: =G18+J18+M18 -> -2468.0347 | Q18: =H18+K18 -> 1037.4147 | R18: =E18/N18 -> 0.502123 | S18: =H18/N18 -> 0.49427759
D19: Oct | E19: ='Demurage 2026'!F19/$E$32 -> 1177 | F19: ='Demurage 2026'!G19 -> -0.71 | G19: =E19*F19 -> -835.67 | H19: ='Demurage 2026'!I19/$E$32 -> 1126 | I19: ='Demurage 2026'!J19 -> -0.53 | J19: =H19*I19 -> -596.78 | K19: ='Demurage 2026'!L19/$E$32 -> 247.5 | L19: ='Demurage 2026'!M19 -> 0 | M19: =K19*L19 -> 0 | N19: =E19+H19+K19 -> 2550.5 | O19: ='Demurage 2026'!P19 -> -0.61 | P19: =G19+J19+M19 -> -1432.45 | Q19: =H19+K19 -> 1373.5 | R19: =E19/N19 -> 0.46147814 | S19: =H19/N19 -> 0.44148206
D20: Nov | E20: ='Demurage 2026'!F20/$E$32 -> 1185 | F20: ='Demurage 2026'!G20 -> -0.32 | G20: =E20*F20 -> -379.2 | H20: ='Demurage 2026'!I20/$E$32 -> 1004 | I20: ='Demurage 2026'!J20 -> -0.31 | J20: =H20*I20 -> -311.24 | K20: ='Demurage 2026'!L20/$E$32 -> 405 | L20: ='Demurage 2026'!M20 -> 0 | M20: =K20*L20 -> 0 | N20: =E20+H20+K20 -> 2594 | O20: ='Demurage 2026'!P20 -> -0.31 | P20: =G20+J20+M20 -> -690.44 | Q20: =H20+K20 -> 1409 | R20: =E20/N20 -> 0.45682344 | S20: =H20/N20 -> 0.38704703
D21: Dec | E21: ='Demurage 2026'!F21/$E$32 -> 150 | F21: ='Demurage 2026'!G21 -> 0 | G21: =E21*F21 -> 0 | H21: ='Demurage 2026'!I21/$E$32 -> 220 | I21: ='Demurage 2026'!J21 -> 0 | J21: =H21*I21 -> 0 | K21: ='Demurage 2026'!L21/$E$32 -> 285 | L21: ='Demurage 2026'!M21 -> 0 | M21: =K21*L21 -> 0 | N21: =E21+H21+K21 -> 655 | O21: ='Demurage 2026'!P21 -> 0 | P21: =G21+J21+M21 -> 0 | Q21: =H21+K21 -> 505 | R21: =E21/N21 -> 0.22900763 | S21: =H21/N21 -> 0.33587786
Q22: -1
D23: ='Demurage 2026'!E23 -> Actual Q1 | E23: =SUM(E10:E12) -> 2856.3449 | F23: =SUMPRODUCT(E10:E12,F10:F12)/SUM(E10:E12) -> -0.60499854 | G23: =SUM(G10:G12) -> -1728.0845 | H23: =SUM(H10:H12) -> 3234.3644 | I23: =SUMPRODUCT(H10:H12,I10:I12)/SUM(H10:H12) -> -0.2612827 | J23: =SUM(J10:J12) -> -845.08347 | K23: =SUM(K10:K12) -> 167.756 | L23: =SUMPRODUCT(K10:K12,L10:L12)/SUM(K10:K12) -> 0 | M23: =SUM(M10:M12) -> 0 | N23: =SUM(N10:N12) -> 6258.4652 | O23: =SUMPRODUCT(N10:N12,O10:O12)/SUM(N10:N12) -> -0.41458903 | P23: =SUM(P10:P12) -> -2573.1679
D24: ='Demurage 2026'!E24 -> Actual Q2 | E24: =SUM(E13:E15) -> 2720.0578 | F24: =SUMPRODUCT(E13:E15,F13:F15)/SUM(E13:E15) -> -0.46808947 | G24: =SUM(G13:G15) -> -1273.2304 | H24: =SUM(H13:H15) -> 3293.352 | I24: =SUMPRODUCT(H13:H15,I13:I15)/SUM(H13:H15) -> -0.43165757 | J24: =SUM(J13:J15) -> -1421.6003 | K24: =SUM(K13:K15) -> 60.065 | L24: =SUMPRODUCT(K13:K15,L13:L15)/SUM(K13:K15) -> 0 | M24: =SUM(M13:M15) -> 0 | N24: =SUM(N13:N15) -> 6073.4748 | O24: =SUMPRODUCT(N13:N15,O13:O15)/SUM(N13:N15) -> -0.44555719 | P24: =SUM(P13:P15) -> -2694.8307
D25: ='Demurage 2026'!E25 -> Actual S1 | E25: =SUM(E10:E15) -> 5576.4027 | F25: =SUMPRODUCT(E10:E15,F10:F15)/SUM(E10:E15) -> -0.53821703 | G25: =SUM(G10:G15) -> -3001.3149 | H25: =SUM(H10:H15) -> 6527.7164 | I25: =SUMPRODUCT(H10:H15,I10:I15)/SUM(H10:H15) -> -0.34723993 | J25: =SUM(J10:J15) -> -2266.6838 | K25: =SUM(K10:K15) -> 227.821 | L25: =SUMPRODUCT(K10:K15,L10:L15)/SUM(K10:K15) -> 0 | M25: =SUM(M10:M15) -> 0 | N25: =SUM(N10:N15) -> 12331.94 | O25: =SUMPRODUCT(N10:N15,O10:O15)/SUM(N10:N15) -> -0.42984083 | P25: =SUM(P10:P15) -> -5267.9987
D26: ='Demurage 2026'!E26 -> Prediction Q3 | E26: =SUM(E16:E18) -> 3092.448 | F26: =SUMPRODUCT(E16:E18,F16:F18)/SUM(E16:E18) -> -0.51738936 | G26: =SUM(G16:G18) -> -1599.9997 | H26: =SUM(H16:H18) -> 3243.3937 | I26: =SUMPRODUCT(H16:H18,I16:I18)/SUM(H16:H18) -> -0.56178389 | J26: =SUM(J16:J18) -> -1822.0863 | K26: =SUM(K16:K18) -> 15.108 | L26: =SUMPRODUCT(K16:K18,L16:L18)/SUM(K16:K18) -> 0 | M26: =SUM(M16:M18) -> 0 | N26: =SUM(N16:N18) -> 6350.9497 | O26: =SUMPRODUCT(N16:N18,O16:O18)/SUM(N16:N18) -> -0.5410685 | P26: =SUM(P16:P18) -> -3422.086
D27: ='Demurage 2026'!E27 -> Prediction Q4 | E27: =SUM(E19:E21) -> 2512 | F27: =SUMPRODUCT(E19:E21,F19:F21)/SUM(E19:E21) -> -0.48362659 | G27: =SUM(G19:G21) -> -1214.87 | H27: =SUM(H19:H21) -> 2350 | I27: =SUMPRODUCT(H19:H21,I19:I21)/SUM(H19:H21) -> -0.38639149 | J27: =SUM(J19:J21) -> -908.02 | K27: =SUM(K19:K21) -> 937.5 | L27: =SUMPRODUCT(K19:K21,L19:L21)/SUM(K19:K21) -> 0 | M27: =SUM(M19:M21) -> 0 | N27: =SUM(N19:N21) -> 5799.5 | O27: =SUMPRODUCT(N19:N21,O19:O21)/SUM(N19:N21) -> -0.40692215 | P27: =SUM(P19:P21) -> -2122.89 | R27: 2000
D28: ='Demurage 2026'!E28 -> Prediction S2 | E28: =SUM(E16:E21) -> 5604.448 | F28: =SUMPRODUCT(E16:E21,F16:F21)/SUM(E16:E21) -> -0.50225637 | G28: =SUM(G16:G21) -> -2814.8697 | H28: =SUM(H16:H21) -> 5593.3937 | I28: =SUMPRODUCT(H16:H21,I16:I21)/SUM(H16:H21) -> -0.48809479 | J28: =SUM(J16:J21) -> -2730.1063 | K28: =SUM(K16:K21) -> 952.608 | L28: =SUMPRODUCT(K16:K21,L16:L21)/SUM(K16:K21) -> 0 | M28: =SUM(M16:M21) -> 0 | N28: =SUM(N16:N21) -> 12150.45 | O28: =SUMPRODUCT(N16:N21,O16:O21)/SUM(N16:N21) -> -0.47703945 | P28: =SUM(P16:P21) -> -5544.976 | R28: 29000000
R29: =R27/R28 -> 6.8965517e-05
D30: Act Jan-Jun24 | E30: =SUM(E10:E15) -> 5576.4027 | F30: =SUMPRODUCT(E10:E15,F10:F15)/SUM(E10:E15) -> -0.53821703 | G30: =SUM(G10:G15) -> -3001.3149 | H30: =SUM(H10:H15) -> 6527.7164 | I30: =SUMPRODUCT(H10:H15,I10:I15)/SUM(H10:H15) -> -0.34723993 | J30: =SUM(J10:J15) -> -2266.6838 | K30: =SUM(K10:K14) -> 190.308 | L30: =SUMPRODUCT(K10:K15,L10:L15)/SUM(K10:K15) -> 0 | M30: =SUM(M10:M15) -> 0 | N30: =SUM(N10:N15) -> 12331.94 | O30: =SUMPRODUCT(N10:N15,O10:O15)/SUM(N10:N15) -> -0.42984083 | P30: =SUM(P10:P15) -> -5267.9987
D31: Predict Jan - Dec 2025 | E31: =SUM(E10:E21) -> 11180.851 | F31: =SUMPRODUCT(E10:E21,F10:F21)/SUM(E10:E21) -> -0.5201916 | G31: =SUM(G10:G21) -> -5816.1846 | H31: =SUM(H10:H21) -> 12121.11 | I31: =SUMPRODUCT(H10:H21,I10:I21)/SUM(H10:H21) -> -0.41223865 | J31: =SUM(J10:J21) -> -4996.7901 | K31: =SUM(K10:K21) -> 1180.429 | L31: =SUMPRODUCT(K10:K21,L10:L21)/SUM(K10:K21) -> 0 | M31: =SUM(M10:M21) -> 0 | N31: =SUM(N10:N21) -> 24482.39 | O31: =SUMPRODUCT(N10:N21,O10:O21)/SUM(N10:N21) -> -0.4532652 | P31: =SUM(P10:P21) -> -10812.975
D32: * in K ton | E32: 1000 | S32: 14163796 | T32: 0.59
S33: 15836204 | T33: 0.43
R34: =P34-P33 -> 0 | T34: =SUMPRODUCT(S32:S33,T32:T33)/SUM(S32:S33) -> 0.50554024
Q40: 29116933
P74: 0.82565812
P75: 0.39171475
P76: 0.33133509
P77: 0.4
P78: =AVERAGE(P74:P77) -> 0.48717699
Q172: Mar | R172: Apr | S172: May | T172: Jun | U172: Jul | V172: Aug | W172: Sep | X172: Oct | Y172: Nov | Z172: Dec
Q173: 2461 | R173: 2507 | S173: 2464 | T173: 2615 | U173: 2421 | V173: 2877 | W173: 2579 | X173: 2313 | Y173: 2628.2752 | Z173: 2476.2011
Y183: 12279
...

Sheet summary Demurage&penalty
B2: Month | C2: BoCT | F2: Non BoCT | I2: Total Shipment ITM by Month
C3: ton | D3: Dem /Desp | E3: Pen/Bons | F3: ton | G3: Dem /Desp | H3: Pen/Bons | I3: ton | J3: Dem /Desp | K3: Pen/Bons
B4: Jan | C4: =#REF! -> #REF! | D4: =#REF! -> #REF! | E4: =#REF! -> #REF! | F4: =#REF!+#REF! -> #REF! | G4: =#REF! -> #REF! | H4: =P31 -> #REF! | I4: =C4+F4 -> #REF! | J4: =O45 -> #REF! | K4: =O31 -> #REF!
B5: Feb | C5: =#REF! -> #REF! | D5: =#REF! -> #REF! | E5: =#REF! -> #REF! | F5: =#REF!+#REF! -> #REF! | G5: =#REF! -> #REF! | H5: =P32 -> #REF! | I5: =C5+F5 -> #REF! | J5: =O46 -> #REF! | K5: =O32 -> #REF!
B6: Mar | C6: =#REF! -> #REF! | D6: =#REF! -> #REF! | E6: =#REF! -> #REF! | F6: =#REF!+#REF! -> #REF! | G6: =#REF! -> #REF! | H6: =P33 -> #REF! | I6: =C6+F6 -> #REF! | J6: =O47 -> #REF! | K6: =O33 -> #REF!
B7: Apr | C7: =#REF! -> #REF! | D7: =#REF! -> #REF! | E7: =#REF! -> #REF! | F7: =#REF!+#REF! -> #REF! | G7: =#REF! -> #REF! | H7: =P34 -> #REF! | I7: =C7+F7 -> #REF! | J7: =O48 -> #REF! | K7: =O34 -> #REF!
B8: May | C8: =#REF! -> #REF! | D8: =#REF! -> #REF! | E8: =#REF! -> #REF! | F8: =#REF!+#REF! -> #REF! | G8: =#REF! -> #REF! | H8: =P35 -> #REF! | I8: =C8+F8 -> #REF! | J8: =O49 -> #REF! | K8: =O35 -> #REF!
B9: Jun | C9: =#REF! -> #REF! | D9: =#REF! -> #REF! | E9: =#REF! -> #REF! | F9: =#REF!+#REF! -> #REF! | G9: =#REF! -> #REF! | H9: =P36 -> #REF! | I9: =C9+F9 -> #REF! | J9: =O50 -> #REF! | K9: =O36 -> #REF!
B10: Jul | C10: =#REF! -> #REF! | D10: =#REF! -> #REF! | E10: =#REF! -> #REF! | F10: =#REF!+#REF! -> #REF! | G10: =#REF! -> #REF! | H10: =P37 -> #REF! | I10: =C10+F10 -> #REF! | J10: =O51 -> #REF! | K10: =O37 -> #REF!
B11: Aug | C11: =#REF! -> #REF! | D11: =#REF! -> #REF! | E11: =#REF! -> #REF! | F11: =#REF!+#REF! -> #REF! | G11: =#REF! -> #REF! | H11: =P38 -> #REF! | I11: =C11+F11 -> #REF! | J11: =O52 -> #REF! | K11: =O38 -> #REF!
B12: Sep | C12: =#REF! -> #REF! | D12: =#REF! -> #REF! | E12: =#REF! -> #REF! | F12: =#REF!+#REF! -> #REF! | G12: =#REF! -> #REF! | H12: =P39 -> #REF! | I12: =C12+F12 -> #REF! | J12: =O53 -> #REF! | K12: =O39 -> #REF!
B13: Oct | C13: =#REF! -> #REF! | D13: =#REF! -> #REF! | E13: =#REF! -> #REF! | F13: =#REF!+#REF! -> #REF! | G13: =#REF! -> #REF! | H13: =P40 -> #REF! | I13: =C13+F13 -> #REF! | J13: =O54 -> #REF! | K13: =O40 -> #REF!
B14: Nov | C14: =#REF! -> #REF! | D14: =#REF! -> #REF! | E14: =#REF! -> #REF! | F14: =#REF!+#REF! -> #REF! | G14: =#REF! -> #REF! | H14: =P41 -> #REF! | I14: =C14+F14 -> #REF! | J14: =O55 -> #REF! | K14: =O41 -> #REF!
B15: Dec | C15: =#REF! -> #REF! | D15: =#REF! -> #REF! | E15: =#REF! -> #REF! | F15: =#REF!+#REF! -> #REF! | G15: =#REF! -> #REF! | H15: =P42 -> #REF! | I15: =C15+F15 -> #REF! | J15: =O56 -> #REF! | K15: =O42 -> #REF!
B17: Actual Q1 | C17: =SUM(C4:C6) -> #REF! | D17: =SUMPRODUCT(C4:C6,D4:D6)/SUM(C4:C6) -> #REF! | E17: =SUM(E4:E6) -> #REF! | F17: =SUM(F4:F15) -> #REF! | G17: =SUMPRODUCT(F4:F6,G4:G6)/SUM(F4:F6) -> #REF! | H17: =SUM(H4:H6) -> #REF! | I17: =SUM(I4:I6) -> #REF! | J17: =SUMPRODUCT(I4:I6,J4:J6)/SUM(I4:I6) -> #REF! | K17: =SUM(K4:K6) -> #REF!
B18: Actual Q2 | C18: =SUM(C7:C9) -> #REF! | D18: =SUMPRODUCT(C7:C9,D7:D9)/SUM(C7:C9) -> #REF! | E18: =SUM(E7:E9) -> #REF! | F18: =SUM(F7:F9) -> #REF! | G18: =SUMPRODUCT(F7:F9,G7:G9)/SUM(F7:F9) -> #REF! | H18: =SUM(H7:H9) -> #REF! | I18: =SUM(I7:I9) -> #REF! | J18: =SUMPRODUCT(I7:I9,J7:J9)/SUM(I7:I9) -> #REF! | K18: =SUM(K7:K9) -> #REF!
B19: Actual Smstr 1 | C19: =SUM(C4:C9) -> #REF! | D19: =SUMPRODUCT(C4:C9,D4:D9)/SUM(C4:C9) -> #REF! | E19: =SUM(E4:E9) -> #REF! | F19: =SUM(F4:F9) -> #REF! | G19: =SUMPRODUCT(F4:F9,G4:G9)/SUM(F4:F9) -> #REF! | H19: =SUM(H4:H9) -> #REF! | I19: =SUM(I4:I9) -> #REF! | J19: =SUMPRODUCT(I4:I9,J4:J9)/SUM(I4:I9) -> #REF! | K19: =SUM(K4:K9) -> #REF!
B20: Actual Q3 | C20: =SUM(C10:C12) -> #REF! | D20: =SUMPRODUCT(C10:C12,D10:D12)/SUM(C10:C12) -> #REF! | E20: =SUM(E10:E12) -> #REF! | F20: =SUM(F10:F12) -> #REF! | G20: =SUMPRODUCT(F10:F12,G10:G12)/SUM(F10:F12) -> #REF! | H20: =SUM(H10:H12) -> #REF! | I20: =SUM(I10:I12) -> #REF! | J20: =SUMPRODUCT(I10:I12,J10:J12)/SUM(I10:I12) -> #REF! | K20: =SUM(K10:K12) -> #REF!
B21: Prediction Q4 | C21: =SUM(C13:C15) -> #REF! | D21: =SUMPRODUCT(C13:C15,D13:D15)/SUM(C13:C15) -> #REF! | E21: =SUM(E13:E15) -> #REF! | F21: =SUM(F13:F15) -> #REF! | G21: =SUMPRODUCT(F13:F15,G13:G15)/SUM(F13:F15) -> #REF! | H21: =SUM(H13:H15) -> #REF! | I21: =SUM(I13:I15) -> #REF! | J21: =SUMPRODUCT(I13:I15,J13:J15)/SUM(I13:I15) -> #REF! | K21: =SUM(K13:K15) -> #REF!
B22: Prediction Smstr 2 | C22: =SUM(C10:C15) -> #REF! | D22: =SUMPRODUCT(C10:C15,D10:D15)/SUM(C10:C15) -> #REF! | E22: =SUM(E10:E15) -> #REF! | F22: =SUM(F10:F15) -> #REF! | G22: =SUMPRODUCT(F10:F15,G10:G15)/SUM(F10:F15) -> #REF! | H22: =SUM(H10:H15) -> #REF! | I22: =SUM(I10:I15) -> #REF! | J22: =SUMPRODUCT(I10:I15,J10:J15)/SUM(I10:I15) -> #REF! | K22: =SUM(K10:K15) -> #REF!
B24: Actual Jan-Jun'20 | C24: =SUM(C4:C9) -> #REF! | D24: =SUMPRODUCT(C4:C9,D4:D9)/SUM(C4:C9) -> #REF! | E24: =SUMPRODUCT(C4:C9,E4:E9)/SUM(C4:C9) -> #REF! | F24: =SUM(F4:F9) -> #REF! | G24: =SUMPRODUCT(F4:F9,G4:G9)/SUM(F4:F9) -> #REF! | H24: =SUMPRODUCT(F4:F9,H4:H9)/SUM(F4:F9) -> #REF! | I24: =SUM(I4:I9) -> #REF! | J24: =SUMPRODUCT(I4:I9,J4:J9)/SUM(I4:I9) -> #REF! | K24: =SUMPRODUCT(I4:I9,K4:K9)/SUM(I4:I9) -> #REF!
B25: Predict Jan-Dec'20 | C25: =SUM(C4:C15) -> #REF! | D25: =SUMPRODUCT(C4:C15,D4:D15)/SUM(C4:C15) -> #REF! | E25: =SUMPRODUCT(C4:C15,E4:E15)/SUM(C4:C15) -> #REF! | F25: =SUM(F4:F15) -> #REF! | G25: =SUMPRODUCT(F4:F15,G4:G15)/SUM(F4:F15) -> #REF! | H25: =SUMPRODUCT(F4:F15,H4:H15)/SUM(F4:F15) -> #REF! | I25: =SUM(I4:I15) -> #REF! | J25: =SUMPRODUCT(I4:I15,J4:J15)/SUM(I4:I15) -> #REF! | K25: =SUMPRODUCT(I4:I15,K4:K15)/SUM(I4:I15) -> #REF!
B30: Tonnage (Ton) | G30: Budget Penalty ($/ton) | J30: Averge Budget | L30: Actual/Prediction Penalty ($/ton) | O30: Averge penalty Actual ITM | P30: Averge penalty Actual Non BoCT
B31: Jan | C31: =#REF! -> #REF! | D31: =#REF! -> #REF! | E31: =#REF! -> #REF! | G31: =#REF! -> #REF! | H31: =#REF! -> #REF! | I31: =#REF! -> #REF! | J31: =SUMPRODUCT($C$31:$E$31,G31:I31)/SUM($C$31:$E$31) -> #REF! | L31: =#REF! -> #REF! | M31: =#REF! -> #REF! | N31: =#REF! -> #REF! | O31: =SUMPRODUCT(C31:E31,L31:N31)/SUM(C31:E31) -> #REF! | P31: =SUMPRODUCT(D31:E31,M31:N31)/SUM(D31:E31) -> #REF!
B32: Feb | C32: =#REF! -> #REF! | D32: =#REF! -> #REF! | E32: =#REF! -> #REF! | G32: =#REF! -> #REF! | H32: =#REF! -> #REF! | I32: =#REF! -> #REF! | J32: =SUMPRODUCT($C$31:$E$31,G32:I32)/SUM($C$31:$E$31) -> #REF! | L32: =#REF! -> #REF! | M32: =#REF! -> #REF! | N32: =#REF! -> #REF! | O32: =SUMPRODUCT(C32:E32,L32:N32)/SUM(C32:E32) -> #REF! | P32: =SUMPRODUCT(D32:E32,M32:N32)/SUM(D32:E32) -> #REF!
B33: Mar | C33: =#REF! -> #REF! | D33: =#REF! -> #REF! | E33: =#REF! -> #REF! | G33: =#REF! -> #REF! | H33: =#REF! -> #REF! | I33: =#REF! -> #REF! | J33: =SUMPRODUCT($C$31:$E$31,G33:I33)/SUM($C$31:$E$31) -> #REF! | L33: =#REF! -> #REF! | M33: =#REF! -> #REF! | N33: =#REF! -> #REF! | O33: =SUMPRODUCT(C33:E33,L33:N33)/SUM(C33:E33) -> #REF! | P33: =SUMPRODUCT(D33:E33,M33:N33)/SUM(D33:E33) -> #REF!
B34: Apr | C34: =#REF! -> #REF! | D34: =#REF! -> #REF! | E34: =#REF! -> #REF! | G34: =#REF! -> #REF! | H34: =#REF! -> #REF! | I34: =#REF! -> #REF! | J34: =SUMPRODUCT($C$31:$E$31,G34:I34)/SUM($C$31:$E$31) -> #REF! | L34: =#REF! -> #REF! | M34: =#REF! -> #REF! | N34: =#REF! -> #REF! | O34: =SUMPRODUCT(C34:E34,L34:N34)/SUM(C34:E34) -> #REF! | P34: =SUMPRODUCT(D34:E34,M34:N34)/SUM(D34:E34) -> #REF!
B35: May | C35: =#REF! -> #REF! | D35: =#REF! -> #REF! | E35: =#REF! -> #REF! | G35: =#REF! -> #REF! | H35: =#REF! -> #REF! | I35: =#REF! -> #REF! | J35: =SUMPRODUCT($C$31:$E$31,G35:I35)/SUM($C$31:$E$31) -> #REF! | L35: =#REF! -> #REF! | M35: =#REF! -> #REF! | N35: =#REF! -> #REF! | O35: =SUMPRODUCT(C35:E35,L35:N35)/SUM(C35:E35) -> #REF! | P35: =SUMPRODUCT(D35:E35,M35:N35)/SUM(D35:E35) -> #REF!
B36: Jun | C36: =#REF! -> #REF! | D36: =#REF! -> #REF! | E36: =#REF! -> #REF! | G36: =#REF! -> #REF! | H36: =#REF! -> #REF! | I36: =#REF! -> #REF! | J36: =SUMPRODUCT($C$31:$E$31,G36:I36)/SUM($C$31:$E$31) -> #REF! | L36: =#REF! -> #REF! | M36: =#REF! -> #REF! | N36: =#REF! -> #REF! | O36: =SUMPRODUCT(C36:E36,L36:N36)/SUM(C36:E36) -> #REF! | P36: =SUMPRODUCT(D36:E36,M36:N36)/SUM(D36:E36) -> #REF!
B37: Jul | C37: =#REF! -> #REF! | D37: =#REF! -> #REF! | E37: =#REF! -> #REF! | G37: =#REF! -> #REF! | H37: =#REF! -> #REF! | I37: =#REF! -> #REF! | J37: =SUMPRODUCT($C$31:$E$31,G37:I37)/SUM($C$31:$E$31) -> #REF! | L37: =#REF! -> #REF! | M37: =#REF! -> #REF! | N37: =#REF! -> #REF! | O37: =SUMPRODUCT(C37:E37,L37:N37)/SUM(C37:E37) -> #REF! | P37: =SUMPRODUCT(D37:E37,M37:N37)/SUM(D37:E37) -> #REF!
B38: Aug | C38: =#REF! -> #REF! | D38: =#REF! -> #REF! | E38: =#REF! -> #REF! | G38: =#REF! -> #REF! | H38: =#REF! -> #REF! | I38: =#REF! -> #REF! | J38: =SUMPRODUCT($C$31:$E$31,G38:I38)/SUM($C$31:$E$31) -> #REF! | L38: =#REF! -> #REF! | M38: =#REF! -> #REF! | N38: =#REF! -> #REF! | O38: =SUMPRODUCT(C38:E38,L38:N38)/SUM(C38:E38) -> #REF! | P38: =SUMPRODUCT(D38:E38,M38:N38)/SUM(D38:E38) -> #REF!
B39: Sep | C39: =#REF! -> #REF! | D39: =#REF! -> #REF! | E39: =#REF! -> #REF! | G39: =#REF! -> #REF! | H39: =#REF! -> #REF! | I39: =#REF! -> #REF! | J39: =SUMPRODUCT($C$31:$E$31,G39:I39)/SUM($C$31:$E$31) -> #REF! | L39: =#REF! -> #REF! | M39: =#REF! -> #REF! | N39: =#REF! -> #REF! | O39: =SUMPRODUCT(C39:E39,L39:N39)/SUM(C39:E39) -> #REF! | P39: =SUMPRODUCT(D39:E39,M39:N39)/SUM(D39:E39) -> #REF!
B40: Oct | C40: =#REF! -> #REF! | D40: =#REF! -> #REF! | E40: =#REF! -> #REF! | G40: =#REF! -> #REF! | H40: =#REF! -> #REF! | I40: =#REF! -> #REF! | J40: =SUMPRODUCT($C$31:$E$31,G40:I40)/SUM($C$31:$E$31) -> #REF! | L40: =#REF! -> #REF! | M40: =#REF! -> #REF! | N40: =#REF! -> #REF! | O40: =SUMPRODUCT(C40:E40,L40:N40)/SUM(C40:E40) -> #REF! | P40: =SUMPRODUCT(D40:E40,M40:N40)/SUM(D40:E40) -> #REF!
B41: Nov | C41: =#REF! -> #REF! | D41: =#REF! -> #REF! | E41: =#REF! -> #REF! | G41: =#REF! -> #REF! | H41: =#REF! -> #REF! | I41: =#REF! -> #REF! | J41: =SUMPRODUCT($C$31:$E$31,G41:I41)/SUM($C$31:$E$31) -> #REF! | L41: =#REF! -> #REF! | M41: =#REF! -> #REF! | N41: =#REF! -> #REF! | O41: =SUMPRODUCT(C41:E41,L41:N41)/SUM(C41:E41) -> #REF! | P41: =SUMPRODUCT(D41:E41,M41:N41)/SUM(D41:E41) -> #REF!
B42: Dec | C42: =#REF! -> #REF! | D42: =#REF! -> #REF! | E42: =#REF! -> #REF! | G42: =#REF! -> #REF! | H42: =#REF! -> #REF! | I42: =#REF! -> #REF! | J42: =SUMPRODUCT($C$31:$E$31,G42:I42)/SUM($C$31:$E$31) -> #REF! | L42: =#REF! -> #REF! | M42: =#REF! -> #REF! | N42: =#REF! -> #REF! | O42: =SUMPRODUCT(C42:E42,L42:N42)/SUM(C42:E42) -> #REF! | P42: =SUMPRODUCT(D42:E42,M42:N42)/SUM(D42:E42) -> #REF!
B43: Total | C43: =SUM(C31:C42) -> #REF! | D43: =SUM(D31:D42) -> #REF! | E43: =SUM(E31:E42) -> #REF!
L44: Actual/Prediction Demurage ($/ton) | O44: Averge demmurage Actual ITM
L45: =D4 -> #REF! | M45: =G4 -> #REF! | O45: =SUMPRODUCT(C31:E31,L45:N45)/SUM(C31:E31) -> #REF!
L46: =D5 -> #REF! | M46: =G5 -> #REF! | O46: =SUMPRODUCT(C32:E32,L46:N46)/SUM(C32:E32) -> #REF!
L47: =D6 -> #REF! | M47: =G6 -> #REF! | O47: =SUMPRODUCT(C33:E33,L47:N47)/SUM(C33:E33) -> #REF!
...

Sheet summ present
B2: Month | C2: BoCT | F2: Non BoCT | I2: Total Shipment ITM by Month
C3: ton | D3: Dem /Desp | E3: Pen/Bons | F3: ton | G3: Dem /Desp | H3: Pen/Bons | I3: ton | J3: Dem /Desp | K3: Pen/Bons
B4: Jan | C4: ='summary Demurage&penalty'!C4/'summ present'!$C$26 -> #REF! | D4: =#REF! -> #REF! | E4: =#REF! -> #REF! | F4: ='summary Demurage&penalty'!F4/'summ present'!$C$26 -> #REF! | G4: =#REF! -> #REF! | H4: =P31 -> #REF! | I4: =C4+F4 -> #REF! | J4: =O45 -> #REF! | K4: =O31 -> #REF!
B5: Feb | C5: ='summary Demurage&penalty'!C5/'summ present'!$C$26 -> #REF! | D5: =#REF! -> #REF! | E5: =#REF! -> #REF! | F5: ='summary Demurage&penalty'!F5/'summ present'!$C$26 -> #REF! | G5: =#REF! -> #REF! | H5: =P32 -> #REF! | I5: =C5+F5 -> #REF! | J5: =O46 -> #REF! | K5: =O32 -> #REF!
B6: Mar | C6: ='summary Demurage&penalty'!C6/'summ present'!$C$26 -> #REF! | D6: =#REF! -> #REF! | E6: =#REF! -> #REF! | F6: ='summary Demurage&penalty'!F6/'summ present'!$C$26 -> #REF! | G6: =#REF! -> #REF! | H6: =P33 -> #REF! | I6: =C6+F6 -> #REF! | J6: =O47 -> #REF! | K6: =O33 -> #REF!
B7: Apr | C7: ='summary Demurage&penalty'!C7/'summ present'!$C$26 -> #REF! | D7: =#REF! -> #REF! | E7: =#REF! -> #REF! | F7: ='summary Demurage&penalty'!F7/'summ present'!$C$26 -> #REF! | G7: =#REF! -> #REF! | H7: =P34 -> #REF! | I7: =C7+F7 -> #REF! | J7: =O48 -> #REF! | K7: =O34 -> #REF!
B8: May | C8: ='summary Demurage&penalty'!C8/'summ present'!$C$26 -> #REF! | D8: =#REF! -> #REF! | E8: =#REF! -> #REF! | F8: ='summary Demurage&penalty'!F8/'summ present'!$C$26 -> #REF! | G8: =#REF! -> #REF! | H8: =P35 -> #REF! | I8: =C8+F8 -> #REF! | J8: =O49 -> #REF! | K8: =O35 -> #REF!
B9: Jun | C9: ='summary Demurage&penalty'!C9/'summ present'!$C$26 -> #REF! | D9: =#REF! -> #REF! | E9: =#REF! -> #REF! | F9: ='summary Demurage&penalty'!F9/'summ present'!$C$26 -> #REF! | G9: =#REF! -> #REF! | H9: =P36 -> #REF! | I9: =C9+F9 -> #REF! | J9: =O50 -> #REF! | K9: =O36 -> #REF!
B10: Jul | C10: ='summary Demurage&penalty'!C10/'summ present'!$C$26 -> #REF! | D10: =#REF! -> #REF! | E10: =#REF! -> #REF! | F10: ='summary Demurage&penalty'!F10/'summ present'!$C$26 -> #REF! | G10: =#REF! -> #REF! | H10: =P37 -> #REF! | I10: =C10+F10 -> #REF! | J10: =O51 -> #REF! | K10: =O37 -> #REF!
B11: Aug | C11: ='summary Demurage&penalty'!C11/'summ present'!$C$26 -> #REF! | D11: =#REF! -> #REF! | E11: =#REF! -> #REF! | F11: ='summary Demurage&penalty'!F11/'summ present'!$C$26 -> #REF! | G11: =#REF! -> #REF! | H11: =P38 -> #REF! | I11: =C11+F11 -> #REF! | J11: =O52 -> #REF! | K11: =O38 -> #REF!
B12: Sep | C12: ='summary Demurage&penalty'!C12/'summ present'!$C$26 -> #REF! | D12: =#REF! -> #REF! | E12: =#REF! -> #REF! | F12: ='summary Demurage&penalty'!F12/'summ present'!$C$26 -> #REF! | G12: =#REF! -> #REF! | H12: =P39 -> #REF! | I12: =C12+F12 -> #REF! | J12: =O53 -> #REF! | K12: =O39 -> #REF!
B13: Oct | C13: ='summary Demurage&penalty'!C13/'summ present'!$C$26 -> #REF! | D13: =#REF! -> #REF! | E13: =#REF! -> #REF! | F13: ='summary Demurage&penalty'!F13/'summ present'!$C$26 -> #REF! | G13: =#REF! -> #REF! | H13: =P40 -> #REF! | I13: =C13+F13 -> #REF! | J13: =O54 -> #REF! | K13: =O40 -> #REF!
B14: Nov | C14: ='summary Demurage&penalty'!C14/'summ present'!$C$26 -> #REF! | D14: =#REF! -> #REF! | E14: =#REF! -> #REF! | F14: ='summary Demurage&penalty'!F14/'summ present'!$C$26 -> #REF! | G14: =#REF! -> #REF! | H14: =P41 -> #REF! | I14: =C14+F14 -> #REF! | J14: =O55 -> #REF! | K14: =O41 -> #REF!
B15: Dec | C15: ='summary Demurage&penalty'!C15/'summ present'!$C$26 -> #REF! | D15: =#REF! -> #REF! | E15: =#REF! -> #REF! | F15: ='summary Demurage&penalty'!F15/'summ present'!$C$26 -> #REF! | G15: =#REF! -> #REF! | H15: =P42 -> #REF! | I15: =C15+F15 -> #REF! | J15: =O56 -> #REF! | K15: =O42 -> #REF!
B17: Prediction Q1 | C17: =SUM(C4:C6) -> #REF! | D17: =SUMPRODUCT(C4:C6,D4:D6)/SUM(C4:C6) -> #REF! | E17: =SUM(E4:E6) -> #REF! | F17: =SUM(F4:F15) -> #REF! | G17: =SUMPRODUCT(F4:F6,G4:G6)/SUM(F4:F6) -> #REF! | H17: =SUM(H4:H6) -> #REF! | I17: =SUM(I4:I6) -> #REF! | J17: =SUMPRODUCT(I4:I6,J4:J6)/SUM(I4:I6) -> #REF! | K17: =SUM(K4:K6) -> #REF!
B18: Prediction Q2 | C18: =SUM(C7:C9) -> #REF! | D18: =SUMPRODUCT(C7:C9,D7:D9)/SUM(C7:C9) -> #REF! | E18: =SUM(E7:E9) -> #REF! | F18: =SUM(F7:F9) -> #REF! | G18: =SUMPRODUCT(F7:F9,G7:G9)/SUM(F7:F9) -> #REF! | H18: =SUM(H7:H9) -> #REF! | I18: =SUM(I7:I9) -> #REF! | J18: =SUMPRODUCT(I7:I9,J7:J9)/SUM(I7:I9) -> #REF! | K18: =SUM(K7:K9) -> #REF!
B19: Prediction Smstr 1 | C19: =SUM(C4:C9) -> #REF! | D19: =SUMPRODUCT(C4:C9,D4:D9)/SUM(C4:C9) -> #REF! | E19: =SUM(E4:E9) -> #REF! | F19: =SUM(F4:F9) -> #REF! | G19: =SUMPRODUCT(F4:F9,G4:G9)/SUM(F4:F9) -> #REF! | H19: =SUM(H4:H9) -> #REF! | I19: =SUM(I4:I9) -> #REF! | J19: =SUMPRODUCT(I4:I9,J4:J9)/SUM(I4:I9) -> #REF! | K19: =SUM(K4:K9) -> #REF!
B20: Prediction Q3 | C20: =SUM(C10:C12) -> #REF! | D20: =SUMPRODUCT(C10:C12,D10:D12)/SUM(C10:C12) -> #REF! | E20: =SUM(E10:E12) -> #REF! | F20: =SUM(F10:F12) -> #REF! | G20: =SUMPRODUCT(F10:F12,G10:G12)/SUM(F10:F12) -> #REF! | H20: =SUM(H10:H12) -> #REF! | I20: =SUM(I10:I12) -> #REF! | J20: =SUMPRODUCT(I10:I12,J10:J12)/SUM(I10:I12) -> #REF! | K20: =SUM(K10:K12) -> #REF!
B21: Prediction Q4 | C21: =SUM(C13:C15) -> #REF! | D21: =SUMPRODUCT(C13:C15,D13:D15)/SUM(C13:C15) -> #REF! | E21: =SUM(E13:E15) -> #REF! | F21: =SUM(F13:F15) -> #REF! | G21: =SUMPRODUCT(F13:F15,G13:G15)/SUM(F13:F15) -> #REF! | H21: =SUM(H13:H15) -> #REF! | I21: =SUM(I13:I15) -> #REF! | J21: =SUMPRODUCT(I13:I15,J13:J15)/SUM(I13:I15) -> #REF! | K21: =SUM(K13:K15) -> #REF!
B22: Prediction Smstr 2 | C22: =SUM(C10:C15) -> #REF! | D22: =SUMPRODUCT(C10:C15,D10:D15)/SUM(C10:C15) -> #REF! | E22: =SUM(E10:E15) -> #REF! | F22: =SUM(F10:F15) -> #REF! | G22: =SUMPRODUCT(F10:F15,G10:G15)/SUM(F10:F15) -> #REF! | H22: =SUM(H10:H15) -> #REF! | I22: =SUM(I10:I15) -> #REF! | J22: =SUMPRODUCT(I10:I15,J10:J15)/SUM(I10:I15) -> #REF! | K22: =SUM(K10:K15) -> #REF!
B24: Predict Jan-Jun'21 | C24: =SUM(C4:C9) -> #REF! | D24: =SUMPRODUCT(C4:C9,D4:D9)/SUM(C4:C9) -> #REF! | E24: =SUMPRODUCT(C4:C9,E4:E9)/SUM(C4:C9) -> #REF! | F24: =SUM(F4:F9) -> #REF! | G24: =SUMPRODUCT(F4:F9,G4:G9)/SUM(F4:F9) -> #REF! | H24: =SUMPRODUCT(F4:F9,H4:H9)/SUM(F4:F9) -> #REF! | I24: =SUM(I4:I9) -> #REF! | J24: =SUMPRODUCT(I4:I9,J4:J9)/SUM(I4:I9) -> #REF! | K24: =SUMPRODUCT(I4:I9,K4:K9)/SUM(I4:I9) -> #REF!
B25: Predict Jan-Dec'21 | C25: =SUM(C4:C15) -> #REF! | D25: =SUMPRODUCT(C4:C15,D4:D15)/SUM(C4:C15) -> #REF! | E25: =SUMPRODUCT(C4:C15,E4:E15)/SUM(C4:C15) -> #REF! | F25: =SUM(F4:F15) -> #REF! | G25: =SUMPRODUCT(F4:F15,G4:G15)/SUM(F4:F15) -> #REF! | H25: =SUMPRODUCT(F4:F15,H4:H15)/SUM(F4:F15) -> #REF! | I25: =SUM(I4:I15) -> #REF! | J25: =SUMPRODUCT(I4:I15,J4:J15)/SUM(I4:I15) -> #REF! | K25: =SUMPRODUCT(I4:I15,K4:K15)/SUM(I4:I15) -> #REF!
B26: * in K ton | C26: 1000
B30: Tonnage (Ton) | G30: Budget Penalty ($/ton) | J30: Averge Budget | L30: Actual/Prediction Penalty ($/ton) | O30: Averge penalty Actual ITM | P30: Averge penalty Actual Non BoCT
B31: Jan | C31: =#REF! -> #REF! | D31: =#REF! -> #REF! | E31: =#REF! -> #REF! | G31: =#REF! -> #REF! | H31: =#REF! -> #REF! | I31: =#REF! -> #REF! | J31: =SUMPRODUCT($C$31:$E$31,G31:I31)/SUM($C$31:$E$31) -> #REF! | L31: =#REF! -> #REF! | M31: =#REF! -> #REF! | N31: =#REF! -> #REF! | O31: =SUMPRODUCT(C31:E31,L31:N31)/SUM(C31:E31) -> #REF! | P31: =SUMPRODUCT(D31:E31,M31:N31)/SUM(D31:E31) -> #REF!
B32: Feb | C32: =#REF! -> #REF! | D32: =#REF! -> #REF! | E32: =#REF! -> #REF! | G32: =#REF! -> #REF! | H32: =#REF! -> #REF! | I32: =#REF! -> #REF! | J32: =SUMPRODUCT($C$31:$E$31,G32:I32)/SUM($C$31:$E$31) -> #REF! | L32: =#REF! -> #REF! | M32: =#REF! -> #REF! | N32: =#REF! -> #REF! | O32: =SUMPRODUCT(C32:E32,L32:N32)/SUM(C32:E32) -> #REF! | P32: =SUMPRODUCT(D32:E32,M32:N32)/SUM(D32:E32) -> #REF!
B33: Mar | C33: =#REF! -> #REF! | D33: =#REF! -> #REF! | E33: =#REF! -> #REF! | G33: =#REF! -> #REF! | H33: =#REF! -> #REF! | I33: =#REF! -> #REF! | J33: =SUMPRODUCT($C$31:$E$31,G33:I33)/SUM($C$31:$E$31) -> #REF! | L33: =#REF! -> #REF! | M33: =#REF! -> #REF! | N33: =#REF! -> #REF! | O33: =SUMPRODUCT(C33:E33,L33:N33)/SUM(C33:E33) -> #REF! | P33: =SUMPRODUCT(D33:E33,M33:N33)/SUM(D33:E33) -> #REF!
B34: Apr | C34: =#REF! -> #REF! | D34: =#REF! -> #REF! | E34: =#REF! -> #REF! | G34: =#REF! -> #REF! | H34: =#REF! -> #REF! | I34: =#REF! -> #REF! | J34: =SUMPRODUCT($C$31:$E$31,G34:I34)/SUM($C$31:$E$31) -> #REF! | L34: =#REF! -> #REF! | M34: =#REF! -> #REF! | N34: =#REF! -> #REF! | O34: =SUMPRODUCT(C34:E34,L34:N34)/SUM(C34:E34) -> #REF! | P34: =SUMPRODUCT(D34:E34,M34:N34)/SUM(D34:E34) -> #REF!
B35: May | C35: =#REF! -> #REF! | D35: =#REF! -> #REF! | E35: =#REF! -> #REF! | G35: =#REF! -> #REF! | H35: =#REF! -> #REF! | I35: =#REF! -> #REF! | J35: =SUMPRODUCT($C$31:$E$31,G35:I35)/SUM($C$31:$E$31) -> #REF! | L35: =#REF! -> #REF! | M35: =#REF! -> #REF! | N35: =#REF! -> #REF! | O35: =SUMPRODUCT(C35:E35,L35:N35)/SUM(C35:E35) -> #REF! | P35: =SUMPRODUCT(D35:E35,M35:N35)/SUM(D35:E35) -> #REF!
B36: Jun | C36: =#REF! -> #REF! | D36: =#REF! -> #REF! | E36: =#REF! -> #REF! | G36: =#REF! -> #REF! | H36: =#REF! -> #REF! | I36: =#REF! -> #REF! | J36: =SUMPRODUCT($C$31:$E$31,G36:I36)/SUM($C$31:$E$31) -> #REF! | L36: =#REF! -> #REF! | M36: =#REF! -> #REF! | N36: =#REF! -> #REF! | O36: =SUMPRODUCT(C36:E36,L36:N36)/SUM(C36:E36) -> #REF! | P36: =SUMPRODUCT(D36:E36,M36:N36)/SUM(D36:E36) -> #REF!
B37: Jul | C37: =#REF! -> #REF! | D37: =#REF! -> #REF! | E37: =#REF! -> #REF! | G37: =#REF! -> #REF! | H37: =#REF! -> #REF! | I37: =#REF! -> #REF! | J37: =SUMPRODUCT($C$31:$E$31,G37:I37)/SUM($C$31:$E$31) -> #REF! | L37: =#REF! -> #REF! | M37: =#REF! -> #REF! | N37: =#REF! -> #REF! | O37: =SUMPRODUCT(C37:E37,L37:N37)/SUM(C37:E37) -> #REF! | P37: =SUMPRODUCT(D37:E37,M37:N37)/SUM(D37:E37) -> #REF!
B38: Aug | C38: =#REF! -> #REF! | D38: =#REF! -> #REF! | E38: =#REF! -> #REF! | G38: =#REF! -> #REF! | H38: =#REF! -> #REF! | I38: =#REF! -> #REF! | J38: =SUMPRODUCT($C$31:$E$31,G38:I38)/SUM($C$31:$E$31) -> #REF! | L38: =#REF! -> #REF! | M38: =#REF! -> #REF! | N38: =#REF! -> #REF! | O38: =SUMPRODUCT(C38:E38,L38:N38)/SUM(C38:E38) -> #REF! | P38: =SUMPRODUCT(D38:E38,M38:N38)/SUM(D38:E38) -> #REF!
B39: Sep | C39: =#REF! -> #REF! | D39: =#REF! -> #REF! | E39: =#REF! -> #REF! | G39: =#REF! -> #REF! | H39: =#REF! -> #REF! | I39: =#REF! -> #REF! | J39: =SUMPRODUCT($C$31:$E$31,G39:I39)/SUM($C$31:$E$31) -> #REF! | L39: =#REF! -> #REF! | M39: =#REF! -> #REF! | N39: =#REF! -> #REF! | O39: =SUMPRODUCT(C39:E39,L39:N39)/SUM(C39:E39) -> #REF! | P39: =SUMPRODUCT(D39:E39,M39:N39)/SUM(D39:E39) -> #REF!
B40: Oct | C40: =#REF! -> #REF! | D40: =#REF! -> #REF! | E40: =#REF! -> #REF! | G40: =#REF! -> #REF! | H40: =#REF! -> #REF! | I40: =#REF! -> #REF! | J40: =SUMPRODUCT($C$31:$E$31,G40:I40)/SUM($C$31:$E$31) -> #REF! | L40: =#REF! -> #REF! | M40: =#REF! -> #REF! | N40: =#REF! -> #REF! | O40: =SUMPRODUCT(C40:E40,L40:N40)/SUM(C40:E40) -> #REF! | P40: =SUMPRODUCT(D40:E40,M40:N40)/SUM(D40:E40) -> #REF!
B41: Nov | C41: =#REF! -> #REF! | D41: =#REF! -> #REF! | E41: =#REF! -> #REF! | G41: =#REF! -> #REF! | H41: =#REF! -> #REF! | I41: =#REF! -> #REF! | J41: =SUMPRODUCT($C$31:$E$31,G41:I41)/SUM($C$31:$E$31) -> #REF! | L41: =#REF! -> #REF! | M41: =#REF! -> #REF! | N41: =#REF! -> #REF! | O41: =SUMPRODUCT(C41:E41,L41:N41)/SUM(C41:E41) -> #REF! | P41: =SUMPRODUCT(D41:E41,M41:N41)/SUM(D41:E41) -> #REF!
B42: Dec | C42: =#REF! -> #REF! | D42: =#REF! -> #REF! | E42: =#REF! -> #REF! | G42: =#REF! -> #REF! | H42: =#REF! -> #REF! | I42: =#REF! -> #REF! | J42: =SUMPRODUCT($C$31:$E$31,G42:I42)/SUM($C$31:$E$31) -> #REF! | L42: =#REF! -> #REF! | M42: =#REF! -> #REF! | N42: =#REF! -> #REF! | O42: =SUMPRODUCT(C42:E42,L42:N42)/SUM(C42:E42) -> #REF! | P42: =SUMPRODUCT(D42:E42,M42:N42)/SUM(D42:E42) -> #REF!
B43: Total | C43: =SUM(C31:C42) -> #REF! | D43: =SUM(D31:D42) -> #REF! | E43: =SUM(E31:E42) -> #REF!
L44: Actual/Prediction Demurage ($/ton) | O44: Averge demmurage Actual ITM
L45: =D4 -> #REF! | M45: =G4 -> #REF! | O45: =SUMPRODUCT(C31:E31,L45:N45)/SUM(C31:E31) -> #REF!
L46: =D5 -> #REF! | M46: =G5 -> #REF! | O46: =SUMPRODUCT(C32:E32,L46:N46)/SUM(C32:E32) -> #REF!
...

Sheet present
B3: Actual
B4: Outlook
B5: Budget
R6: =P11/N11 -> #REF!
D8: Month | E8: BoCT | H8: Non BoCT | K8: Direct barge | N8: Total Shipment ITM by Month | Q8: Remark | U8: =3000000/29000000 -> 0.10344828
E9: ton | F9: Dem /Desp | G9: $ | H9: ton | I9: Dem /Desp | J9: $ | K9: ton | L9: Dem /Desp | M9: $ | N9: ton | O9: Dem /Desp | P9: $
D10: Jan | E10: =#REF!/present!$E$32 -> #REF! | F10: =#REF! -> #REF! | G10: =E10*F10 -> #REF! | H10: =#REF!/present!$E$32 -> #REF! | I10: =#REF! -> #REF! | J10: =H10*I10 -> #REF! | K10: =#REF!/present!$E$32 -> #REF! | L10: 0 | M10: =K10*L10 -> #REF! | N10: =E10+H10+K10 -> #REF! | O10: =L37 -> #REF! | P10: =G10+J10+M10 -> #REF! | R10: =E10/N10 -> #REF! | S10: =H10/N10 -> #REF! | U10: 0.65 | V10: 0.3 | W10: 0.05
D11: Feb | E11: =#REF!/present!$E$32 -> #REF! | F11: =#REF! -> #REF! | G11: =E11*F11 -> #REF! | H11: =#REF!/present!$E$32 -> #REF! | I11: =#REF! -> #REF! | J11: =H11*I11 -> #REF! | K11: =#REF!/present!$E$32 -> #REF! | L11: 0 | M11: =K11*L11 -> #REF! | N11: =E11+H11+K11 -> #REF! | O11: =L38 -> #REF! | P11: =G11+J11+M11 -> #REF! | R11: =E11/N11 -> #REF! | S11: =H11/N11 -> #REF!
D12: Mar | E12: =#REF!/present!$E$32 -> #REF! | F12: =#REF! -> #REF! | G12: =E12*F12 -> #REF! | H12: =#REF!/present!$E$32 -> #REF! | I12: =#REF! -> #REF! | J12: =H12*I12 -> #REF! | K12: =#REF!/present!$E$32 -> #REF! | L12: 0 | M12: =K12*L12 -> #REF! | N12: =E12+H12+K12 -> #REF! | O12: =L39 -> #REF! | P12: =G12+J12+M12 -> #REF! | R12: =E12/N12 -> #REF! | S12: =H12/N12 -> #REF! | U12: =(U10/1)*$U$8 -> 0.067241379 | V12: =(V10/1)*$U$8 -> 0.031034483 | W12: =(W10/1)*$U$8 -> 0.0051724138
