Workbook
Name _1A1_Z1...A10_Z10: #REF!
Name _1A1_Z1...A10_Z10: #REF!
Name _Apr: [1]Validation!$A$33
Name _Aug: [1]Validation!$A$37
Name _Chubu1: [1]Validation!$A$5
Name _Chubu2: [1]Validation!$A$6
Name _Chubu3: [1]Validation!$A$7
Name _ChubuP1: [1]Chubu!$V$203
Name _ChubuP2: [1]Chubu!$V$204
Name _CLP: [1]Validation!$A$17
Name _CLPP1: [1]CLP!$V$203
Name _CLPP2: [1]CLP!$V$204
Name _DATE: #REF!
Name _DATE: #REF!
Name _Dec: [1]Validation!$A$41
Name _ENEL1: [1]Validation!$A$11
Name _ENELP1: '[1]Enel '!$V$264
Name _ENELP2: '[1]Enel '!$V$265
Name _EPDC: [1]Validation!$A$8
Name _EPDCP1: [1]EPDC!$V$203
Name _EPDCP2: [1]EPDC!$V$204
Name _Feb: [1]Validation!$A$31
Name _ffggggg: #REF!
Name _ffggggg: #REF!
Name _Formosa1: [1]Validation!$A$15
Name _Formosa2: [1]Validation!$A$16
Name _FORMOSAP1: [1]Formosa!$V$264
Name _FORMOSAP2: [1]Formosa!$V$265
Name _fs1: #REF!
Name _fs1: #REF!
Name _HEK1: [1]Validation!$A$20
Name _HEK2: [1]Validation!$A$21
Name _HEKP1: [1]HEK!$V$203
Name _HEKP2: [1]HEK!$V$204
Name _Huaneng1: [1]Validation!$A$18
Name _Huaneng2: [1]Validation!$A$19
Name _HUANP1: [1]Huaneng!$V$394
Name _HUANP2: [1]Huaneng!$V$395
Name _Jan: [1]Validation!$A$30
Name _Jul: [1]Validation!$A$36
Name _Jun: [1]Validation!$A$35
Name _Kobe: [1]Validation!$A$9
Name _KOBEP1: '[1]Kobe Steel'!$V$264
Name _KOBEP2: '[1]Kobe Steel'!$V$265
Name _Kospo: [1]Validation!$A$13
Name _KOSPOP1: [1]Kospo!$V$203
Name _KOSPOP2: [1]Kospo!$V$204
Name _Kowepo: [1]Validation!$A$14
Name _KOWEPOP1: [1]Kowepo!$V$264
Name _KOWEPOP2: [1]Kowepo!$V$265
Name _Mar: [1]Validation!$A$32
Name _May: [1]Validation!$A$34
Name _Nov: [1]Validation!$A$40
Name _Oct: [1]Validation!$A$39
Name _Sep: [1]Validation!$A$38
Name _SHIKOKUP1: [1]Shikoku!$V$203
Name _SHIKOKUP2: [1]Shikoku!$V$204
Name _Tirreno: [1]Validation!$A$12
Name _TIRRENOP1: [1]Tirreno!$V$264
Name _TIRRENOP2: [1]Tirreno!$V$265

Sheet Budget 2025
A1: ITM plan year 2024
A2: As of 18 Nov'24
A4: IMM | B4: Jan | C4: Feb | D4: Mar | E4: Apr | F4: May | G4: Jun | H4: Jul | I4: Aug | J4: Sep | K4: Oct | L4: Nov | M4: Dec | N4: Total
A5: OB Removal (KBcm) | B5: =SUM(B6:B7) -> 7619.4483 | C5: =SUM(C6:C7) -> 7224.3023 | D5: =SUM(D6:D7) -> 6870.0231 | E5: =SUM(E6:E7) -> 7815.9147 | F5: =SUM(F6:F7) -> 8233.4755 | G5: =SUM(G6:G7) -> 7596.8792 | H5: =SUM(H6:H7) -> 8769.11 | I5: =SUM(I6:I7) -> 8498.0492 | ... M5: =SUM(M6:M7) -> 7566.691 | N5: =SUM(B5:M5) -> 94714.478 | P5: Done
A6: PAMA (WB) | B6: 2904.786 | C6: 2754.4503 | D6: 2424.321 | E6: 2767.1447 | F6: 2927.6178 | G6: 2460.4194 | H6: 3157.9028 | I6: 3107.2173 | J6: 2899.6426 | K6: 2829.8233 | L6: 2690.1553 | M6: 2609.1784 | N6: =SUM(B6:M6) -> 33532.659
A7: PAMA (EB) | B7: 4714.6622 | C7: 4469.852 | D7: 4445.7021 | E7: 5048.77 | F7: 5305.8577 | G7: 5136.4598 | H7: 5611.2072 | I7: 5390.8319 | J7: 5542.5331 | K7: 5412.2853 | L7: 5146.1452 | M7: 4957.5126 | N7: =SUM(B7:M7) -> 61181.819
A8: ROM Production (Kton) | B8: =SUM(B9:B11) -> 537.5 | C8: =SUM(C9:C11) -> 532.5 | D8: =SUM(D9:D11) -> 537.5 | E8: =SUM(E9:E11) -> 537.5 | F8: =SUM(F9:F11) -> 537.5 | G8: =SUM(G9:G11) -> 537.5 | H8: =SUM(H9:H11) -> 610 | I8: =SUM(I9:I11) -> 625 | ... M8: =SUM(M9:M11) -> 620 | N8: =SUM(B8:M8) -> 6950
A9: PAMA (WB) | B9: 192.5 | C9: 187.5 | D9: 192.5 | E9: 190 | F9: 185 | G9: 155 | H9: 130 | I9: 135 | J9: 145 | K9: 110 | L9: 120 | M9: 120 | N9: =SUM(B9:M9) -> 1862.5
A10: PAMA (EB) | B10: 345 | C10: 345 | D10: 345 | E10: 347.5 | F10: 352.5 | G10: 382.5 | H10: 480 | I10: 490 | J10: 480 | K10: 515 | L10: 505 | M10: 500 | N10: =SUM(B10:M10) -> 5087.5
A11: Fine Coal | B11: 0 | C11: 0 | D11: 0 | E11: 0 | F11: 0 | G11: 0 | H11: 0 | I11: 0 | J11: 0 | K11: 0 | L11: 0 | M11: 0 | N11: =SUM(B11:M11) -> 0
A12: SR ROM Total | B12: =B5/B8 -> 14.175718 | C12: =C5/C8 -> 13.566765 | D12: =D5/D8 -> 12.781438 | E12: =E5/E8 -> 14.541237 | F12: =F5/F8 -> 15.318094 | G12: =G5/G8 -> 14.133729 | H12: =H5/H8 -> 14.37559 | I12: =I5/I8 -> 13.596879 | ... N12: =N5/N8 -> 13.627982
A13: FC Product (Kton) | B13: =SUM(B14:B16) -> 541.75 | C13: =SUM(C14:C16) -> 536.75 | D13: =SUM(D14:D16) -> 541.75 | E13: =SUM(E14:E16) -> 551.75 | F13: =SUM(F14:F16) -> 551.75 | G13: =SUM(G14:G16) -> 551.75 | H13: =SUM(H14:H16) -> 635.75 | I13: =SUM(I14:I16) -> 637.75 | ... M13: =SUM(M14:M16) -> 637.75 | N13: =SUM(B13:M13) -> 7100
A14: PAMA (WB) | B14: 192.5 | C14: 187.5 | D14: 192.5 | E14: 190 | F14: 185 | G14: 155 | H14: 130 | I14: 135 | J14: 145 | K14: 110 | L14: 120 | M14: 120 | N14: =SUM(B14:M14) -> 1862.5
A15: PAMA (EB) | B15: 345 | C15: 345 | D15: 345 | E15: 349 | F15: 354 | G15: 384 | H15: 493 | I15: 490 | J15: 480 | K15: 515 | L15: 505 | M15: 505 | N15: =SUM(B15:M15) -> 5110
A16: Fine Coal | B16: 4.25 | C16: 4.25 | D16: 4.25 | E16: 12.75 | F16: 12.75 | G16: 12.75 | H16: 12.75 | I16: 12.75 | J16: 12.75 | K16: 12.75 | L16: 12.75 | M16: 12.75 | N16: =SUM(B16:M16) -> 127.5
A17: SR FC Total | B17: =B5/B13 -> 14.06451 | C17: =C5/C13 -> 13.459343 | D17: =D5/D13 -> 12.681169 | E17: =E5/E13 -> 14.165681 | F17: =F5/F13 -> 14.922475 | G17: =G5/G13 -> 13.768698 | H17: =H5/H13 -> 13.793331 | I17: =I5/I13 -> 13.325048 | ... N17: =N5/N13 -> 13.340067
A18: IMM-WB.HCV.LS | B18: 154.9822 | C18: 150.19218 | D18: 153.44456 | E18: 142.73183 | F18: 131.89202 | G18: 90.256716 | H18: 45.052829 | I18: 60.104109 | J18: 62.623268 | K18: 73.637876 | L18: 78.465632 | M18: 85.419934 | N18: =SUM(B18:M18) -> 1228.8032
A19: CV(GAR) | B19: 6066.6995 | C19: 6061.099 | D19: 6072.9614 | E19: 6113.1737 | F19: 6106.3251 | G19: 6216.0563 | H19: 6397.4706 | I19: 6374.5335 | J19: 6369.463 | K19: 6395.7374 | L19: 6207.9868 | M19: 6224.9984 | N19: =SUMPRODUCT(B19:M19,$B$18:$M$18)/SUM($B$18:$M$18) -> 6169.7769
A20: TS | B20: 0.79938883 | C20: 0.79960479 | D20: 0.80630914 | E20: 0.80238321 | F20: 0.79513307 | G20: 0.79813522 | H20: 0.8000568 | I20: 0.80071014 | J20: 0.80424058 | K20: 0.87778388 | L20: 0.89103139 | M20: 0.79704817 | N20: =SUMPRODUCT(B20:M20,$B$18:$M$18)/SUM($B$18:$M$18) -> 0.81080181
A21: Ash | B21: 8.5931913 | C21: 8.5723462 | D21: 8.4652505 | E21: 8.3496537 | F21: 8.4544991 | G21: 8.0611616 | H21: 8.0877488 | I21: 8.0139288 | J21: 8.093906 | K21: 8.3113445 | L21: 8.6583469 | M21: 8.1211956 | N21: =SUMPRODUCT(B21:M21,$B$18:$M$18)/SUM($B$18:$M$18) -> 8.3745645
A22: Moist | B22: 8.4967581 | C22: 8.6035878 | D22: 8.5701167 | E22: 8.295887 | F22: 8.4360236 | G22: 8.1042227 | H22: 7.1124623 | I22: 7.0457455 | J22: 7.1276119 | K22: 7.1603037 | L22: 7.2146756 | M22: 7.5402791 | N22: =SUMPRODUCT(B22:M22,$B$18:$M$18)/SUM($B$18:$M$18) -> 8.0403443
A23: TM | B23: 13.52212 | C23: 13.62895 | D23: 13.595479 | E23: 13.321249 | F23: 13.461386 | G23: 13.129585 | H23: 12.137825 | I23: 12.071108 | J23: 12.152974 | K23: 12.185666 | L23: 12.240038 | M23: 12.565641 | N23: =SUMPRODUCT(B23:M23,$B$18:$M$18)/SUM($B$18:$M$18) -> 13.065707
A24: IMM-WB.HCV.HS | B24: 37.517805 | C24: 37.307818 | D24: 39.055444 | E24: 47.268165 | F24: 53.10798 | G24: 64.743284 | H24: 84.947171 | I24: 74.895891 | J24: 82.376732 | K24: 36.362124 | L24: 41.534368 | M24: 34.580066 | N24: =SUM(B24:M24) -> 633.69685
A25: CV(GAR) | B25: 5995.4058 | C25: 6102.8668 | D25: 6012.8803 | E25: 5956.2491 | F25: 5900.982 | G25: 5903.8514 | H25: 5953.1501 | I25: 5935.2903 | J25: 5994.0694 | K25: 5972.607 | L25: 5974.5067 | M25: 5973.0938 | N25: =SUMPRODUCT(B25:M25,$B$24:$M$24)/SUM($B$24:$M$24) -> 5965.7827
A26: TS | B26: 2.4295613 | C26: 2.4050655 | D26: 2.5318666 | E26: 2.5966145 | F26: 2.6452674 | G26: 2.7646957 | H26: 2.7577905 | I26: 2.7055365 | J26: 2.6431822 | K26: 2.4886633 | L26: 2.3842149 | M26: 1.9721835 | N26: =SUMPRODUCT(B26:M26,$B$24:$M$24)/SUM($B$24:$M$24) -> 2.5790489
A27: Ash | B27: 13.650338 | C27: 13.07266 | D27: 13.53618 | E27: 14.197739 | F27: 14.74821 | G27: 14.555829 | H27: 13.682949 | I27: 14.42353 | J27: 13.830267 | K27: 13.802136 | L27: 13.963262 | M27: 13.239605 | N27: =SUMPRODUCT(B27:M27,$B$24:$M$24)/SUM($B$24:$M$24) -> 13.960595
A28: Moist | B28: 6.0446714 | C28: 6.0271092 | D28: 6.0381378 | E28: 6.0670306 | F28: 6.0650682 | G28: 7.0545207 | H28: 6.8576285 | I28: 6.9141156 | J28: 7.151348 | K28: 7.5030578 | L28: 7.5101273 | M28: 7.1237139 | N28: =SUMPRODUCT(B28:M28,$B$24:$M$24)/SUM($B$24:$M$24) -> 6.7439986
A29: TM | B29: 11.070034 | C29: 11.052472 | D29: 11.0635 | E29: 11.092393 | F29: 11.090431 | G29: 12.079883 | H29: 11.882991 | I29: 11.939478 | J29: 12.17671 | K29: 12.52842 | L29: 12.53549 | M29: 12.149076 | N29: =SUMPRODUCT(B29:M29,$B$24:$M$24)/SUM($B$24:$M$24) -> 11.769361
A30: IMM-EB.MCV.LS | B30: 3.3845713 | C30: 2.1986171 | D30: 2.3031178 | E30: 2.767207 | F30: 1.8758652 | G30: 1.1105575 | H30: 0 | I30: 0 | J30: 0 | K30: 0 | L30: 0 | M30: 0 | N30: =SUM(B30:M30) -> 13.639936
A31: CV(GAR) | B31: 5821.883 | C31: 5816.4871 | D31: 5824.2204 | E31: 5826.2223 | F31: 5821.6228 | G31: 5824.0809 | H31: 0 | I31: 0 | J31: 0 | K31: 0 | L31: 0 | M31: 0 | N31: =SUMPRODUCT(B31:M31,$B$30:$M$30)/SUM($B$30:$M$30) -> 5822.4314
A32: TS | B32: 0.89812632 | C32: 0.89994494 | D32: 0.90129647 | E32: 0.90153154 | F32: 0.90292127 | G32: 0.90325732 | H32: 0 | I32: 0 | J32: 0 | K32: 0 | L32: 0 | M32: 0 | N32: =SUMPRODUCT(B32:M32,$B$30:$M$30)/SUM($B$30:$M$30) -> 0.90072278
A33: Ash | B33: 8.6642459 | C33: 8.6537904 | D33: 8.6423873 | E33: 8.5289327 | F33: 8.5159535 | G33: 8.5014972 | H33: 0 | I33: 0 | J33: 0 | K33: 0 | L33: 0 | M33: 0 | N33: =SUMPRODUCT(B33:M33,$B$30:$M$30)/SUM($B$30:$M$30) -> 8.5977728
A34: Moist | B34: 11.332981 | C34: 11.336869 | D34: 11.369268 | E34: 11.350128 | F34: 11.399581 | G34: 11.357707 | H34: 0 | I34: 0 | J34: 0 | K34: 0 | L34: 0 | M34: 0 | N34: =SUMPRODUCT(B34:M34,$B$30:$M$30)/SUM($B$30:$M$30) -> 11.354386
A35: TM | B35: 16.332981 | C35: 16.336869 | D35: 16.369268 | E35: 16.350128 | F35: 16.399581 | G35: 16.357707 | H35: 0 | I35: 0 | J35: 0 | K35: 0 | L35: 0 | M35: 0 | N35: =SUMPRODUCT(B35:M35,$B$30:$M$30)/SUM($B$30:$M$30) -> 16.354386
A36: IMM-EB.MCV.MS | B36: 2.5218825 | C36: 7.2154786 | D36: 26.720101 | E36: 6.3272233 | F36: 12.630174 | G36: 4.8087851 | H36: 12.094951 | I36: 14.998053 | J36: 83.697273 | K36: 94.400599 | L36: 71.33532 | M36: 85.965624 | N36: =SUM(B36:M36) -> 422.71546
A37: CV(GAR) | B37: 6013.744 | C37: 5958.5719 | D37: 6011.5142 | E37: 6033.7912 | F37: 5987.1311 | G37: 6002.8141 | H37: 6036.2059 | I37: 6005.6296 | J37: 5996.4183 | K37: 6012.5832 | L37: 6026.6617 | M37: 6027.4417 | N37: =SUMPRODUCT(B37:M37,$B$36:$M$36)/SUM($N$36) -> 6013.6725
A38: TS | B38: 1.5719259 | C38: 1.5704928 | D38: 1.5645055 | E38: 1.5541281 | F38: 1.5514426 | G38: 1.5490809 | H38: 1.5706205 | I38: 1.5667221 | J38: 1.5492652 | K38: 1.553251 | L38: 1.5598162 | M38: 1.5724278 | N38: =SUMPRODUCT(B38:M38,$B$36:$M$36)/SUM($N$36) -> 1.5594733
A39: Ash | B39: 6.0748082 | C39: 6.153097 | D39: 6.1792076 | E39: 5.197632 | F39: 5.2945573 | G39: 5.236934 | H39: 5.1052577 | I39: 5.3674075 | J39: 5.3569251 | K39: 5.169691 | L39: 5.1649103 | M39: 5.3009891 | N39: =SUMPRODUCT(B39:M39,$B$36:$M$36)/SUM($N$36) -> 5.3287414
A40: Moist | B40: 10.127325 | C40: 10.233784 | D40: 10.532647 | E40: 10.3526 | F40: 10.781854 | G40: 10.481305 | H40: 10.365903 | I40: 10.468448 | J40: 10.443604 | K40: 10.274018 | L40: 10.240397 | M40: 9.9507726 | N40: =SUMPRODUCT(B40:M40,$B$36:$M$36)/SUM($N$36) -> 10.279207
A41: TM | B41: 15.127325 | C41: 15.233784 | D41: 15.532647 | E41: 15.3526 | F41: 15.781854 | G41: 15.481305 | H41: 15.365903 | I41: 15.468448 | J41: 15.443604 | K41: 15.274018 | L41: 15.240397 | M41: 14.950773 | N41: =SUMPRODUCT(B41:M41,$B$36:$M$36)/SUM($N$36) -> 15.279207
...

Sheet Outlook 5+7
A1: ITM outlook 2025 (5+7)
B3: Act. | C3: Act. | D3: Act. | E3: Act. | F3: Act. | G3: Out. | H3: Out. | I3: Out. | J3: Out. | K3: Out. | L3: Out. | M3: Out. | N3: Out.
A4: IMM | B4: Jan | C4: Feb | D4: Mar | E4: Apr | F4: May | G4: Jun | H4: Jul | I4: Aug | J4: Sep | K4: Oct | L4: Nov | M4: Dec | N4: Total | P4: Budget 2025
A5: OB Removal (KBcm) | B5: =SUM(B6:B7) -> 6763.0376 | C5: =SUM(C6:C7) -> 7421.6153 | D5: =SUM(D6:D7) -> 6667.0223 | E5: =SUM(E6:E7) -> 6530.8426 | F5: =SUM(F6:F7) -> 7716.6778 | G5: =SUM(G6:G7) -> 7640.3811 | H5: =SUM(H6:H7) -> 8789.2468 | I5: =SUM(I6:I7) -> 8512.679 | ... M5: =SUM(M6:M7) -> 8731.4478 | N5: =SUM(B5:M5) -> 95196.778 | P5: ='Budget 2025'!N5 -> 94714.478 | Q5: =N5/P5 -> 1.0050921
A6: PAMA (WB) | B6: 2244.6941 | C6: 2827.069 | D6: 2295.7418 | E6: 2096.5402 | F6: 2379.9843 | G6: 2514.006 | H6: 3223.0037 | I6: 3121.8471 | J6: 2945.2593 | K6: 3295.4855 | L6: 3411.2248 | M6: 3319.0402 | N6: =SUM(B6:M6) -> 33673.896 | P6: ='Budget 2025'!N6 -> 33532.659
A7: PAMA (EB) | B7: 4518.3435 | C7: 4594.5463 | D7: 4371.2805 | E7: 4434.3024 | F7: 5336.6935 | G7: 5126.3751 | H7: 5566.2431 | I7: 5390.8319 | J7: 5542.5331 | K7: 5628.2853 | L7: 5601.0402 | M7: 5412.4076 | N7: =SUM(B7:M7) -> 61522.883 | P7: ='Budget 2025'!N7 -> 61181.819
A8: ROM Production (Kton) | B8: =SUM(B9:B11) -> 542.83357 | C8: =SUM(C9:C11) -> 554.11951 | D8: =SUM(D9:D11) -> 482.78672 | E8: =SUM(E9:E11) -> 444.51201 | F8: =SUM(F9:F11) -> 639.80024 | G8: =SUM(G9:G11) -> 584.49964 | H8: =SUM(H9:H11) -> 610 | I8: =SUM(I9:I11) -> 660 | ... N8: =SUM(N9:N11) -> 7060 | P8: ='Budget 2025'!N8 -> 6950 | Q8: =N8/P8 -> 1.0158273
A9: PAMA (WB) | B9: 158.42587 | C9: 192.58567 | D9: 141.12357 | E9: 88.560644 | F9: 157.3174 | G9: 155.35257 | H9: 165 | I9: 159.13427 | J9: 130 | K9: 130 | L9: 130 | M9: 125 | N9: =SUM(B9:M9) -> 1732.5 | P9: ='Budget 2025'!N9 -> 1862.5
A10: PAMA (EB) | B10: 384.4077 | C10: 361.53383 | D10: 341.66315 | E10: 355.95136 | F10: 482.48284 | G10: 429.14707 | H10: 445 | I10: 500.86573 | J10: 530 | K10: 520 | L10: 520 | M10: 456.44832 | N10: =SUM(B10:M10) -> 5327.5 | P10: ='Budget 2025'!N10 -> 5087.5
A11: Fine Coal (WB) | B11: 0 | C11: 0 | D11: 0 | E11: 0 | F11: 0 | G11: 0 | H11: 0 | I11: 0 | J11: 0 | K11: 0 | L11: 0 | M11: 0 | N11: =SUM(B11:M11) -> 0 | P11: ='Budget 2025'!N11 -> 0
A12: SR ROM Total | B12: =B5/B8 -> 12.458768 | C12: =C5/C8 -> 13.393528 | D12: =D5/D8 -> 13.809457 | E12: =E5/E8 -> 14.692162 | F12: =F5/F8 -> 12.061074 | G12: =G5/G8 -> 13.071661 | H12: =H5/H8 -> 14.408601 | I12: =I5/I8 -> 12.897998 | ... N12: =N5/N8 -> 13.483963 | P12: ='Budget 2025'!N12 -> 13.627982
A13: FC Product (Kton) | B13: =SUM(B14:B16) -> 612.68293 | C13: =SUM(C14:C16) -> 584.91494 | D13: =SUM(D14:D16) -> 501.01074 | E13: =SUM(E14:E16) -> 479.30495 | F13: =SUM(F14:F16) -> 584.25 | G13: =SUM(G14:G16) -> 584.25 | H13: =SUM(H14:H16) -> 625.75 | I13: =SUM(I14:I16) -> 672.75 | ... M13: =SUM(M14:M16) -> 533.33645 | N13: =SUM(B13:M13) -> 7135 | P13: ='Budget 2025'!N13 -> 7100
A14: PAMA (WB) | B14: 203.84233 | C14: 213.15935 | D14: 151.07621 | E14: 100.53441 | F14: 165 | G14: 148.5 | H14: 175 | I14: 165 | J14: 130 | K14: 115 | L14: 115 | M14: 47.887695 | N14: =SUM(B14:M14) -> 1730 | P14: ='Budget 2025'!N14 -> 1862.5
A15: PAMA (EB) | B15: 408.8406 | C15: 371.75559 | D15: 349.93453 | E15: 378.57866 | F15: 415 | G15: 431.5 | H15: 446.5 | I15: 495 | J15: 530 | K15: 514.25 | L15: 514.25 | M15: 472.69875 | N15: =SUM(B15:M15) -> 5328.3081 | P15: ='Budget 2025'!N15 -> 5110
A16: Fine Coal | B16: 0 | C16: 0 | D16: 0 | E16: 0.19186901 | F16: 4.25 | G16: 4.25 | H16: 4.25 | I16: 12.75 | J16: 12.75 | K16: 12.75 | L16: 12.75 | M16: 12.75 | N16: =SUM(B16:M16) -> 76.691869 | P16: ='Budget 2025'!N48 -> 127.5
A17: SR FC Total | B17: =B5/B13 -> 11.038397 | C17: =C5/C13 -> 12.688367 | D17: =D5/D13 -> 13.307145 | E17: =E5/E13 -> 13.625652 | F17: =F5/F13 -> 13.207835 | G17: =G5/G13 -> 13.077246 | H17: =H5/H13 -> 14.04594 | I17: =I5/I13 -> 12.653555 | ... N17: =N5/N13 -> 13.342225 | P17: ='Budget 2025'!N17 -> 13.340067
A18: IMM-WB.HCV.LS | B18: 146.18254 | C18: 147.46076 | D18: 104.99952 | E18: 70.128194 | F18: 84.530923 | G18: 80 | H18: 103.46868 | I18: 82.675146 | J18: 60.50972 | K18: 65.595478 | L18: 65.952916 | M18: 48.775508 | N18: =SUM(B18:M18) -> 1060.2794 | P18: ='Budget 2025'!N18 -> 1228.8032
A19: CV(GAR) | B19: 6193.9879 | C19: 6105.8162 | D19: 6211.2744 | E19: 6152.0829 | F19: 6133.0399 | G19: 6018.8393 | H19: 6259.4326 | I19: 6259.7603 | J19: 6374.9065 | K19: 6404.4206 | L19: 6235.6329 | M19: 6223.7752 | N19: =SUMPRODUCT(B19:M19,$B$18:$M$18)/SUM($B$18:$M$18) -> 6201.4106 | P19: ='Budget 2025'!N19 -> 6169.7769
A20: TS | B20: 0.61677597 | C20: 0.68122223 | D20: 0.59905828 | E20: 0.64019198 | F20: 0.77254239 | G20: 0.79832043 | H20: 0.80275322 | I20: 0.79618928 | J20: 0.79960709 | K20: 0.83275698 | L20: 0.85461338 | M20: 0.83967214 | N20: =SUMPRODUCT(B20:M20,$B$18:$M$18)/SUM($B$18:$M$18) -> 0.73263216 | P20: ='Budget 2025'!N20 -> 0.81080181
A21: Ash | B21: 8.41834 | C21: 8.393601 | D21: 8.4815141 | E21: 7.9869977 | F21: 8.4695031 | G21: 9.2585939 | H21: 8.4062057 | I21: 8.1871295 | J21: 8.1272132 | K21: 8.2097683 | L21: 8.2591108 | M21: 8.1430637 | N21: =SUMPRODUCT(B21:M21,$B$18:$M$18)/SUM($B$18:$M$18) -> 8.3888049 | P21: ='Budget 2025'!N21 -> 8.3745645
A22: Moist | B22: 8.6372078 | C22: 9.4241924 | D22: 8.714191 | E22: 9.2338941 | F22: 8.7192877 | G22: 8.4902139 | H22: 8.1639926 | I22: 7.7018819 | J22: 7.1238159 | K22: 7.1444558 | L22: 7.0733875 | M22: 7.6542883 | N22: =SUMPRODUCT(B22:M22,$B$18:$M$18)/SUM($B$18:$M$18) -> 8.3488792 | P22: ='Budget 2025'!N22 -> 8.0403443
A23: TM | B23: 11.489526 | C23: 12.325215 | D23: 11.133918 | E23: 12.344042 | F23: 12.370062 | G23: 13.468985 | H23: 13.189355 | I23: 12.727244 | J23: 12.149178 | K23: 12.169818 | L23: 12.09875 | M23: 12.679651 | N23: =SUMPRODUCT(B23:M23,$B$18:$M$18)/SUM($B$18:$M$18) -> 12.281377 | P23: ='Budget 2025'!N23 -> 13.065707
A24: IMM-WB.HCV.HS | B24: 57.659789 | C24: 65.698593 | D24: 46.076686 | E24: 30.406221 | F24: 42.82342 | G24: 68.5 | H24: 71.531318 | I24: 76.459121 | J24: 69.49028 | K24: 49.404522 | L24: 49.047084 | M24: 42.623578 | N24: =SUM(B24:M24) -> 669.72061 | P24: ='Budget 2025'!N24 -> 633.69685
A25: CV(GAR) | B25: 5947.3932 | C25: 5939.4465 | D25: 6026.7648 | E25: 5928.2234 | F25: 6043.0525 | G25: 5829.9751 | H25: 5962.1308 | I25: 5928.4411 | J25: 6005.5198 | K25: 5894.1649 | L25: 5910.574 | M25: 5803.498 | N25: =SUMPRODUCT(B25:M25,$B$24:$M$24)/SUM($B$24:$M$24) -> 5934.9716 | P25: ='Budget 2025'!N25 -> 5965.7827
A26: TS | B26: 1.9789488 | C26: 2.2887477 | D26: 2.1709775 | E26: 1.9301202 | F26: 2.0257524 | G26: 2.7517791 | H26: 2.7609279 | I26: 2.6985423 | J26: 2.6091248 | K26: 2.6713147 | L26: 2.6349423 | M26: 2.6741838 | N26: =SUMPRODUCT(B26:M26,$B$24:$M$24)/SUM($B$24:$M$24) -> 2.4767988 | P26: ='Budget 2025'!N26 -> 2.5790489
A27: Ash | B27: 12.398872 | C27: 11.628956 | D27: 11.380259 | E27: 12.152459 | F27: 11.490738 | G27: 14.102785 | H27: 13.50972 | I27: 14.370514 | J27: 13.324647 | K27: 14.771804 | L27: 14.891748 | M27: 15.987903 | N27: =SUMPRODUCT(B27:M27,$B$24:$M$24)/SUM($B$24:$M$24) -> 13.384121 | P27: ='Budget 2025'!N27 -> 13.960595
A28: Moist | B28: 7.8249272 | C28: 7.5595294 | D28: 6.9977463 | E28: 7.2613478 | F28: 7.0928299 | G28: 6.9884659 | H28: 6.8342267 | I28: 6.842531 | J28: 6.8309987 | K28: 7.4057237 | L28: 7.4333415 | M28: 7.7595329 | N28: =SUMPRODUCT(B28:M28,$B$24:$M$24)/SUM($B$24:$M$24) -> 7.199164 | P28: ='Budget 2025'!N28 -> 6.7439986
A29: TM | B29: 10.911081 | C29: 11.826969 | D29: 11.261991 | E29: 11.642346 | F29: 10.959217 | G29: 11.441842 | H29: 11.859589 | I29: 11.867893 | J29: 11.856361 | K29: 12.431086 | L29: 12.458704 | M29: 12.784895 | N29: =SUMPRODUCT(B29:M29,$B$24:$M$24)/SUM($B$24:$M$24) -> 11.768988 | P29: ='Budget 2025'!N29 -> 11.769361
A30: IMM-EB.MCV.LS | B30: 4.1511632 | C30: 4.8753097 | D30: 8.972062 | E30: 7.4826072 | F30: 9.8667018 | G30: 5 | H30: 0 | I30: 0 | J30: 0 | K30: 0 | L30: 0 | M30: 0 | N30: =SUM(B30:M30) -> 40.347844 | P30: ='Budget 2025'!N30 -> 13.639936
A31: CV(GAR) | B31: 5768.2424 | C31: 5970.6107 | D31: 5842.9196 | E31: 6060.3315 | F31: 5981.1886 | G31: 5806.2841 | H31: 0 | I31: 0 | J31: 0 | K31: 0 | L31: 0 | M31: 0 | N31: =SUMPRODUCT(B31:M31,$B$30:$M$30)/SUM($B$30:$M$30) -> 5920.2577 | P31: ='Budget 2025'!N31 -> 5822.4314
A32: TS | B32: 0.90470615 | C32: 0.97326494 | D32: 0.89969842 | E32: 0.91618026 | F32: 0.8618658 | G32: 0.96191016 | H32: 0 | I32: 0 | J32: 0 | K32: 0 | L32: 0 | M32: 0 | N32: =SUMPRODUCT(B32:M32,$B$30:$M$30)/SUM($B$30:$M$30) -> 0.91061722 | P32: ='Budget 2025'!N32 -> 0.90072278
A33: Ash | B33: 8.4980056 | C33: 6.454713 | D33: 6.9734339 | E33: 5.5176512 | F33: 5.7561377 | G33: 8.5334852 | H33: 0 | I33: 0 | J33: 0 | K33: 0 | L33: 0 | M33: 0 | N33: =SUMPRODUCT(B33:M33,$B$30:$M$30)/SUM($B$30:$M$30) -> 6.6932784 | P33: ='Budget 2025'!N33 -> 8.5977728
A34: Moist | B34: 10.861527 | C34: 11.334285 | D34: 10.91524 | E34: 11.119528 | F34: 11.717851 | G34: 12.262 | H34: 0 | I34: 0 | J34: 0 | K34: 0 | L34: 0 | M34: 0 | N34: =SUMPRODUCT(B34:M34,$B$30:$M$30)/SUM($B$30:$M$30) -> 11.361399 | P34: ='Budget 2025'!N34 -> 11.354386
A35: TM | B35: 14.308473 | C35: 13.960815 | D35: 14.885351 | E35: 13.934471 | F35: 14.518515 | G35: 16.983743 | H35: 0 | I35: 0 | J35: 0 | K35: 0 | L35: 0 | M35: 0 | N35: =SUMPRODUCT(B35:M35,$B$30:$M$30)/SUM($B$30:$M$30) -> 14.708274 | P35: ='Budget 2025'!N35 -> 16.354386
A36: IMM-EB.MCV.MS | B36: 16.385665 | C36: 4.2318727 | D36: 27.481461 | E36: 41.321236 | F36: 24.257871 | G36: 30 | H36: 35.332551 | I36: 30.006916 | J36: 80.262722 | K36: 88.158617 | L36: 72.825823 | M36: 60.655507 | N36: =SUM(B36:M36) -> 510.92024 | P36: ='Budget 2025'!N36 -> 422.71546
A37: CV(GAR) | B37: 6095.6967 | C37: 5702.0802 | D37: 5950.0061 | E37: 5974.4204 | F37: 6089.8148 | G37: 5925.7778 | H37: 6020.8684 | I37: 6014.9125 | J37: 6007.8378 | K37: 6000.1278 | L37: 6040.3042 | M37: 6028.3846 | N37: =SUMPRODUCT(B37:M37,$B$36:$M$36)/SUM($B$36:$M$36) -> 6008.4367 | P37: ='Budget 2025'!N37 -> 6013.6725
A38: TS | B38: 1.5214168 | C38: 1.2568182 | D38: 1.4097729 | E38: 1.483995 | F38: 1.5035755 | G38: 1.594328 | H38: 1.5694494 | I38: 1.5852908 | J38: 1.5745159 | K38: 1.5677879 | L38: 1.5893548 | M38: 1.5744014 | N38: =SUMPRODUCT(B38:M38,$B$36:$M$36)/SUM($B$36:$M$36) -> 1.5530175 | P38: ='Budget 2025'!N38 -> 1.5594733
A39: Ash | B39: 5.147646 | C39: 7.9572727 | D39: 6.2814993 | E39: 5.8970893 | F39: 5.4006541 | G39: 5.6494087 | H39: 5.1963486 | I39: 5.2259008 | J39: 5.4473366 | K39: 5.4652901 | L39: 5.2152649 | M39: 5.283928 | N39: =SUMPRODUCT(B39:M39,$B$36:$M$36)/SUM($B$36:$M$36) -> 5.4696627 | P39: ='Budget 2025'!N39 -> 5.3287414
A40: Moist | B40: 11.52539 | C40: 13.017273 | D40: 11.444174 | E40: 12.148882 | F40: 11.241298 | G40: 10.901372 | H40: 10.507448 | I40: 10.479721 | J40: 10.349522 | K40: 10.24656 | L40: 10.128647 | M40: 9.9250832 | N40: =SUMPRODUCT(B40:M40,$B$36:$M$36)/SUM($B$36:$M$36) -> 10.607408 | P40: ='Budget 2025'!N40 -> 10.279207
A41: TM | B41: 13.645355 | C41: 15.082727 | D41: 14.292213 | E41: 14.144596 | F41: 13.581215 | G41: 16.0053 | H41: 15.507448 | I41: 15.479721 | J41: 15.349522 | K41: 15.24656 | L41: 15.128647 | M41: 14.925083 | N41: =SUMPRODUCT(B41:M41,$B$36:$M$36)/SUM($B$36:$M$36) -> 15.011817 | P41: ='Budget 2025'!N41 -> 15.279207
...

Sheet Outlook Quarterly 5+7
A1: ITM outlook 2025 (4+8)
B3: Act. | C3: Out. | D3: Out. | E3: Out. | F3: Out.
A4: IMM | B4: Q1 | C4: Q2 | D4: Q3 | E4: Q4 | F4: Total | H4: Budget 2025
A5: OB Removal (KBcm) | B5: =SUM(B6:B7) -> 20851.675 | C5: =SUM(C6:C7) -> 21887.902 | D5: =SUM(D6:D7) -> 25789.718 | E5: =SUM(E6:E7) -> 26667.483 | F5: =SUM(B5:E5) -> 95196.778 | H5: ='Budget 2025'!N5 -> 94714.478 | I5: =F5/H5 -> 1.0050921
A6: PAMA (WB) | B6: =SUMIFS('Outlook 5+7'!$B6:$M6,'Outlook 5+7'!$B$185:$M$185,'Outlook Quarterly 5+7'!B$4) -> 7367.5048 | C6: =SUMIFS('Outlook 5+7'!$B6:$M6,'Outlook 5+7'!$B$185:$M$185,'Outlook Quarterly 5+7'!C$4) -> 6990.5305 | D6: =SUMIFS('Outlook 5+7'!$B6:$M6,'Outlook 5+7'!$B$185:$M$185,'Outlook Quarterly 5+7'!D$4) -> 9290.1101 | E6: =SUMIFS('Outlook 5+7'!$B6:$M6,'Outlook 5+7'!$B$185:$M$185,'Outlook Quarterly 5+7'!E$4) -> 10025.75 | F6: =SUM(B6:E6) -> 33673.896 | H6: ='Budget 2025'!N6 -> 33532.659
A7: PAMA (EB) | B7: =SUMIFS('Outlook 5+7'!$B7:$M7,'Outlook 5+7'!$B$185:$M$185,'Outlook Quarterly 5+7'!B$4) -> 13484.17 | C7: =SUMIFS('Outlook 5+7'!$B7:$M7,'Outlook 5+7'!$B$185:$M$185,'Outlook Quarterly 5+7'!C$4) -> 14897.371 | D7: =SUMIFS('Outlook 5+7'!$B7:$M7,'Outlook 5+7'!$B$185:$M$185,'Outlook Quarterly 5+7'!D$4) -> 16499.608 | E7: =SUMIFS('Outlook 5+7'!$B7:$M7,'Outlook 5+7'!$B$185:$M$185,'Outlook Quarterly 5+7'!E$4) -> 16641.733 | F7: =SUM(B7:E7) -> 61522.883 | H7: ='Budget 2025'!N7 -> 61181.819
A8: ROM Production (Kton) | B8: =SUM(B9:B11) -> 1579.7398 | C8: =SUM(C9:C11) -> 1668.8119 | D8: =SUM(D9:D11) -> 1930 | E8: =SUM(E9:E11) -> 1881.4483 | F8: =SUM(F9:F11) -> 7060 | H8: ='Budget 2025'!N8 -> 6950 | I8: =F8/H8 -> 1.0158273
A9: PAMA (WB) | B9: =SUMIFS('Outlook 5+7'!$B9:$M9,'Outlook 5+7'!$B$185:$M$185,'Outlook Quarterly 5+7'!B$4) -> 492.13512 | C9: =SUMIFS('Outlook 5+7'!$B9:$M9,'Outlook 5+7'!$B$185:$M$185,'Outlook Quarterly 5+7'!C$4) -> 401.23062 | D9: =SUMIFS('Outlook 5+7'!$B9:$M9,'Outlook 5+7'!$B$185:$M$185,'Outlook Quarterly 5+7'!D$4) -> 454.13427 | E9: =SUMIFS('Outlook 5+7'!$B9:$M9,'Outlook 5+7'!$B$185:$M$185,'Outlook Quarterly 5+7'!E$4) -> 385 | F9: =SUM(B9:E9) -> 1732.5 | H9: ='Budget 2025'!N9 -> 1862.5
A10: PAMA (EB) | B10: =SUMIFS('Outlook 5+7'!$B10:$M10,'Outlook 5+7'!$B$185:$M$185,'Outlook Quarterly 5+7'!B$4) -> 1087.6047 | C10: =SUMIFS('Outlook 5+7'!$B10:$M10,'Outlook 5+7'!$B$185:$M$185,'Outlook Quarterly 5+7'!C$4) -> 1267.5813 | D10: =SUMIFS('Outlook 5+7'!$B10:$M10,'Outlook 5+7'!$B$185:$M$185,'Outlook Quarterly 5+7'!D$4) -> 1475.8657 | E10: =SUMIFS('Outlook 5+7'!$B10:$M10,'Outlook 5+7'!$B$185:$M$185,'Outlook Quarterly 5+7'!E$4) -> 1496.4483 | F10: =SUM(B10:E10) -> 5327.5 | H10: ='Budget 2025'!N10 -> 5087.5
A11: Fine Coal (WB) | B11: =SUMIFS('Outlook 5+7'!$B11:$M11,'Outlook 5+7'!$B$185:$M$185,'Outlook Quarterly 5+7'!B$4) -> 0 | C11: =SUMIFS('Outlook 5+7'!$B11:$M11,'Outlook 5+7'!$B$185:$M$185,'Outlook Quarterly 5+7'!C$4) -> 0 | D11: =SUMIFS('Outlook 5+7'!$B11:$M11,'Outlook 5+7'!$B$185:$M$185,'Outlook Quarterly 5+7'!D$4) -> 0 | E11: =SUMIFS('Outlook 5+7'!$B11:$M11,'Outlook 5+7'!$B$185:$M$185,'Outlook Quarterly 5+7'!E$4) -> 0 | F11: =SUM(B11:E11) -> 0 | H11: ='Budget 2025'!N11 -> 0
A12: SR ROM Total | B12: =B5/B8 -> 13.199437 | C12: =C5/C8 -> 13.115859 | D12: =D5/D8 -> 13.362548 | E12: =E5/E8 -> 14.173912 | F12: =F5/F8 -> 13.483963 | H12: ='Budget 2025'!N12 -> 13.627982
A13: FC Product (Kton) | B13: =SUM(B14:B16) -> 1698.6086 | C13: =SUM(C14:C16) -> 1647.8049 | D13: =SUM(D14:D16) -> 1971.25 | E13: =SUM(E14:E16) -> 1817.3364 | F13: =SUM(B13:E13) -> 7135 | H13: ='Budget 2025'!N13 -> 7100
A14: PAMA (WB) | B14: =SUMIFS('Outlook 5+7'!$B14:$M14,'Outlook 5+7'!$B$185:$M$185,'Outlook Quarterly 5+7'!B$4) -> 568.07789 | C14: =SUMIFS('Outlook 5+7'!$B14:$M14,'Outlook 5+7'!$B$185:$M$185,'Outlook Quarterly 5+7'!C$4) -> 414.03441 | D14: =SUMIFS('Outlook 5+7'!$B14:$M14,'Outlook 5+7'!$B$185:$M$185,'Outlook Quarterly 5+7'!D$4) -> 470 | E14: =SUMIFS('Outlook 5+7'!$B14:$M14,'Outlook 5+7'!$B$185:$M$185,'Outlook Quarterly 5+7'!E$4) -> 277.8877 | F14: =SUM(B14:E14) -> 1730 | H14: ='Budget 2025'!N14 -> 1862.5
A15: PAMA (EB) | B15: =SUMIFS('Outlook 5+7'!$B15:$M15,'Outlook 5+7'!$B$185:$M$185,'Outlook Quarterly 5+7'!B$4) -> 1130.5307 | C15: =SUMIFS('Outlook 5+7'!$B15:$M15,'Outlook 5+7'!$B$185:$M$185,'Outlook Quarterly 5+7'!C$4) -> 1225.0787 | D15: =SUMIFS('Outlook 5+7'!$B15:$M15,'Outlook 5+7'!$B$185:$M$185,'Outlook Quarterly 5+7'!D$4) -> 1471.5 | E15: =SUMIFS('Outlook 5+7'!$B15:$M15,'Outlook 5+7'!$B$185:$M$185,'Outlook Quarterly 5+7'!E$4) -> 1501.1988 | F15: =SUM(B15:E15) -> 5328.3081 | H15: ='Budget 2025'!N15 -> 5110
A16: Fine Coal | B16: =SUMIFS('Outlook 5+7'!$B16:$M16,'Outlook 5+7'!$B$185:$M$185,'Outlook Quarterly 5+7'!B$4) -> 0 | C16: =SUMIFS('Outlook 5+7'!$B16:$M16,'Outlook 5+7'!$B$185:$M$185,'Outlook Quarterly 5+7'!C$4) -> 8.691869 | D16: =SUMIFS('Outlook 5+7'!$B16:$M16,'Outlook 5+7'!$B$185:$M$185,'Outlook Quarterly 5+7'!D$4) -> 29.75 | E16: =SUMIFS('Outlook 5+7'!$B16:$M16,'Outlook 5+7'!$B$185:$M$185,'Outlook Quarterly 5+7'!E$4) -> 38.25 | F16: =SUM(B16:E16) -> 76.691869 | H16: ='Budget 2025'!N48 -> 127.5
A17: SR FC Total | B17: =B5/B13 -> 12.275739 | C17: =C5/C13 -> 13.283066 | D17: =D5/D13 -> 13.082926 | E17: =E5/E13 -> 14.673939 | F17: =F5/F13 -> 13.342225 | H17: ='Budget 2025'!N17 -> 13.340067
A18: IMM-WB.HCV.LS | B18: =SUMIFS('Outlook 5+7'!$B18:$M18,'Outlook 5+7'!$B$185:$M$185,'Outlook Quarterly 5+7'!B$4) -> 398.64282 | C18: =SUMIFS('Outlook 5+7'!$B18:$M18,'Outlook 5+7'!$B$185:$M$185,'Outlook Quarterly 5+7'!C$4) -> 234.65912 | D18: =SUMIFS('Outlook 5+7'!$B18:$M18,'Outlook 5+7'!$B$185:$M$185,'Outlook Quarterly 5+7'!D$4) -> 246.65355 | E18: =SUMIFS('Outlook 5+7'!$B18:$M18,'Outlook 5+7'!$B$185:$M$185,'Outlook Quarterly 5+7'!E$4) -> 180.3239 | F18: =SUM(B18:E18) -> 1060.2794 | H18: ='Budget 2025'!N18 -> 1228.8032
A19: CV(GAR) | B19: =SUMPRODUCT('Outlook 5+7'!$B19:$D19,'Outlook 5+7'!$B$18:$D$18)/SUM('Outlook 5+7'!$B$18:$D$18) -> 6165.9257 | C19: =SUMPRODUCT('Outlook 5+7'!$E19:$G19,'Outlook 5+7'!$E$18:$G$18)/SUM('Outlook 5+7'!$E$18:$G$18) -> 6099.7976 | D19: =SUMPRODUCT('Outlook 5+7'!$H19:$J19,'Outlook 5+7'!$H$18:$J$18)/SUM('Outlook 5+7'!$H$18:$J$18) -> 6287.8708 | E19: =SUMPRODUCT('Outlook 5+7'!$K19:$M19,'Outlook 5+7'!$K$18:$M$18)/SUM('Outlook 5+7'!$K$18:$M$18) -> 6293.8245 | F19: =SUMPRODUCT(B19:E19,$B$18:$E$18)/SUM($B$18:$E$18) -> 6201.4106 | H19: ='Budget 2025'!N19 -> 6169.7769
A20: TS | B20: =SUMPRODUCT('Outlook 5+7'!$B20:$D20,'Outlook 5+7'!$B$18:$D$18)/SUM('Outlook 5+7'!$B$18:$D$18) -> 0.63594838 | C20: =SUMPRODUCT('Outlook 5+7'!$E20:$G20,'Outlook 5+7'!$E$18:$G$18)/SUM('Outlook 5+7'!$E$18:$G$18) -> 0.74177754 | D20: =SUMPRODUCT('Outlook 5+7'!$H20:$J20,'Outlook 5+7'!$H$18:$J$18)/SUM('Outlook 5+7'!$H$18:$J$18) -> 0.79978125 | E20: =SUMPRODUCT('Outlook 5+7'!$K20:$M20,'Outlook 5+7'!$K$18:$M$18)/SUM('Outlook 5+7'!$K$18:$M$18) -> 0.84262136 | F20: =SUMPRODUCT(B20:E20,$B$18:$E$18)/SUM($B$18:$E$18) -> 0.73263216 | H20: ='Budget 2025'!N20 -> 0.81080181
A21: Ash | B21: =SUMPRODUCT('Outlook 5+7'!$B21:$D21,'Outlook 5+7'!$B$18:$D$18)/SUM('Outlook 5+7'!$B$18:$D$18) -> 8.4258284 | C21: =SUMPRODUCT('Outlook 5+7'!$E21:$G21,'Outlook 5+7'!$E$18:$G$18)/SUM('Outlook 5+7'!$E$18:$G$18) -> 8.5943226 | D21: =SUMPRODUCT('Outlook 5+7'!$H21:$J21,'Outlook 5+7'!$H$18:$J$18)/SUM('Outlook 5+7'!$H$18:$J$18) -> 8.264331 | E21: =SUMPRODUCT('Outlook 5+7'!$K21:$M21,'Outlook 5+7'!$K$18:$M$18)/SUM('Outlook 5+7'!$K$18:$M$18) -> 8.2097723 | F21: =SUMPRODUCT(B21:E21,$B$18:$E$18)/SUM($B$18:$E$18) -> 8.3888049 | H21: ='Budget 2025'!N21 -> 8.3745645
A22: Moist | B22: =SUMPRODUCT('Outlook 5+7'!$B22:$D22,'Outlook 5+7'!$B$18:$D$18)/SUM('Outlook 5+7'!$B$18:$D$18) -> 8.9485957 | C22: =SUMPRODUCT('Outlook 5+7'!$E22:$G22,'Outlook 5+7'!$E$18:$G$18)/SUM('Outlook 5+7'!$E$18:$G$18) -> 8.7949827 | D22: =SUMPRODUCT('Outlook 5+7'!$H22:$J22,'Outlook 5+7'!$H$18:$J$18)/SUM('Outlook 5+7'!$H$18:$J$18) -> 7.75392 | E22: =SUMPRODUCT('Outlook 5+7'!$K22:$M22,'Outlook 5+7'!$K$18:$M$18)/SUM('Outlook 5+7'!$K$18:$M$18) -> 7.2563665 | F22: =SUMPRODUCT(B22:E22,$B$18:$E$18)/SUM($B$18:$E$18) -> 8.3488792 | H22: ='Budget 2025'!N22 -> 8.0403443
A23: TM | B23: =SUMPRODUCT('Outlook 5+7'!$B23:$D23,'Outlook 5+7'!$B$18:$D$18)/SUM('Outlook 5+7'!$B$18:$D$18) -> 11.704989 | C23: =SUMPRODUCT('Outlook 5+7'!$E23:$G23,'Outlook 5+7'!$E$18:$G$18)/SUM('Outlook 5+7'!$E$18:$G$18) -> 12.73693 | D23: =SUMPRODUCT('Outlook 5+7'!$H23:$J23,'Outlook 5+7'!$H$18:$J$18)/SUM('Outlook 5+7'!$H$18:$J$18) -> 12.779282 | E23: =SUMPRODUCT('Outlook 5+7'!$K23:$M23,'Outlook 5+7'!$K$18:$M$18)/SUM('Outlook 5+7'!$K$18:$M$18) -> 12.281729 | F23: =SUMPRODUCT(B23:E23,$B$18:$E$18)/SUM($B$18:$E$18) -> 12.281377 | H23: ='Budget 2025'!N23 -> 13.065707
A24: IMM-WB.HCV.HS | B24: =SUMIFS('Outlook 5+7'!$B24:$M24,'Outlook 5+7'!$B$185:$M$185,'Outlook Quarterly 5+7'!B$4) -> 169.43507 | C24: =SUMIFS('Outlook 5+7'!$B24:$M24,'Outlook 5+7'!$B$185:$M$185,'Outlook Quarterly 5+7'!C$4) -> 141.72964 | D24: =SUMIFS('Outlook 5+7'!$B24:$M24,'Outlook 5+7'!$B$185:$M$185,'Outlook Quarterly 5+7'!D$4) -> 217.48072 | E24: =SUMIFS('Outlook 5+7'!$B24:$M24,'Outlook 5+7'!$B$185:$M$185,'Outlook Quarterly 5+7'!E$4) -> 141.07518 | F24: =SUM(B24:E24) -> 669.72061 | H24: ='Budget 2025'!N24 -> 633.69685
A25: CV(GAR) | B25: =SUMPRODUCT('Outlook 5+7'!$B25:$D25,'Outlook 5+7'!$B$24:$D$24)/SUM('Outlook 5+7'!$B$24:$D$24) -> 5965.8964 | C25: =SUMPRODUCT('Outlook 5+7'!$E25:$G25,'Outlook 5+7'!$E$24:$G$24)/SUM('Outlook 5+7'!$E$24:$G$24) -> 5915.434 | D25: =SUMPRODUCT('Outlook 5+7'!$H25:$J25,'Outlook 5+7'!$H$24:$J$24)/SUM('Outlook 5+7'!$H$24:$J$24) -> 5964.1504 | E25: =SUMPRODUCT('Outlook 5+7'!$K25:$M25,'Outlook 5+7'!$K$24:$M$24)/SUM('Outlook 5+7'!$K$24:$M$24) -> 5872.4763 | F25: =SUMPRODUCT(B25:E25,$B$24:$E$24)/SUM($B$24:$E$24) -> 5934.9716 | H25: ='Budget 2025'!N25 -> 5965.7827
A26: TS | B26: =SUMPRODUCT('Outlook 5+7'!$B26:$D26,'Outlook 5+7'!$B$24:$D$24)/SUM('Outlook 5+7'!$B$24:$D$24) -> 2.1512944 | C26: =SUMPRODUCT('Outlook 5+7'!$E26:$G26,'Outlook 5+7'!$E$24:$G$24)/SUM('Outlook 5+7'!$E$24:$G$24) -> 2.3561351 | D26: =SUMPRODUCT('Outlook 5+7'!$H26:$J26,'Outlook 5+7'!$H$24:$J$24)/SUM('Outlook 5+7'!$H$24:$J$24) -> 2.6904904 | E26: =SUMPRODUCT('Outlook 5+7'!$K26:$M26,'Outlook 5+7'!$K$24:$M$24)/SUM('Outlook 5+7'!$K$24:$M$24) -> 2.6595361 | F26: =SUMPRODUCT(B26:E26,$B$24:$E$24)/SUM($B$24:$E$24) -> 2.4767988 | H26: ='Budget 2025'!N26 -> 2.5790489
A27: Ash | B27: =SUMPRODUCT('Outlook 5+7'!$B27:$D27,'Outlook 5+7'!$B$24:$D$24)/SUM('Outlook 5+7'!$B$24:$D$24) -> 11.823332 | C27: =SUMPRODUCT('Outlook 5+7'!$E27:$G27,'Outlook 5+7'!$E$24:$G$24)/SUM('Outlook 5+7'!$E$24:$G$24) -> 12.895142 | D27: =SUMPRODUCT('Outlook 5+7'!$H27:$J27,'Outlook 5+7'!$H$24:$J$24)/SUM('Outlook 5+7'!$H$24:$J$24) -> 13.753212 | E27: =SUMPRODUCT('Outlook 5+7'!$K27:$M27,'Outlook 5+7'!$K$24:$M$24)/SUM('Outlook 5+7'!$K$24:$M$24) -> 15.180929 | F27: =SUMPRODUCT(B27:E27,$B$24:$E$24)/SUM($B$24:$E$24) -> 13.384121 | H27: ='Budget 2025'!N27 -> 13.960595
A28: Moist | B28: =SUMPRODUCT('Outlook 5+7'!$B28:$D28,'Outlook 5+7'!$B$24:$D$24)/SUM('Outlook 5+7'!$B$24:$D$24) -> 7.4970729 | C28: =SUMPRODUCT('Outlook 5+7'!$E28:$G28,'Outlook 5+7'!$E$24:$G$24)/SUM('Outlook 5+7'!$E$24:$G$24) -> 7.0785426 | D28: =SUMPRODUCT('Outlook 5+7'!$H28:$J28,'Outlook 5+7'!$H$24:$J$24)/SUM('Outlook 5+7'!$H$24:$J$24) -> 6.8361148 | E28: =SUMPRODUCT('Outlook 5+7'!$K28:$M28,'Outlook 5+7'!$K$24:$M$24)/SUM('Outlook 5+7'!$K$24:$M$24) -> 7.5222232 | F28: =SUMPRODUCT(B28:E28,$B$24:$E$24)/SUM($B$24:$E$24) -> 7.199164 | H28: ='Budget 2025'!N28 -> 6.7439986
A29: TM | B29: =SUMPRODUCT('Outlook 5+7'!$B29:$D29,'Outlook 5+7'!$B$24:$D$24)/SUM('Outlook 5+7'!$B$24:$D$24) -> 11.361645 | C29: =SUMPRODUCT('Outlook 5+7'!$E29:$G29,'Outlook 5+7'!$E$24:$G$24)/SUM('Outlook 5+7'!$E$24:$G$24) -> 11.339033 | D29: =SUMPRODUCT('Outlook 5+7'!$H29:$J29,'Outlook 5+7'!$H$24:$J$24)/SUM('Outlook 5+7'!$H$24:$J$24) -> 11.861477 | E29: =SUMPRODUCT('Outlook 5+7'!$K29:$M29,'Outlook 5+7'!$K$24:$M$24)/SUM('Outlook 5+7'!$K$24:$M$24) -> 12.547586 | F29: =SUMPRODUCT(B29:E29,$B$24:$E$24)/SUM($B$24:$E$24) -> 11.768988 | H29: ='Budget 2025'!N29 -> 11.769361
A30: IMM-EB.MCV.LS | B30: =SUMIFS('Outlook 5+7'!$B30:$M30,'Outlook 5+7'!$B$185:$M$185,'Outlook Quarterly 5+7'!B$4) -> 17.998535 | C30: =SUMIFS('Outlook 5+7'!$B30:$M30,'Outlook 5+7'!$B$185:$M$185,'Outlook Quarterly 5+7'!C$4) -> 22.349309 | D30: =SUMIFS('Outlook 5+7'!$B30:$M30,'Outlook 5+7'!$B$185:$M$185,'Outlook Quarterly 5+7'!D$4) -> 0 | E30: =SUMIFS('Outlook 5+7'!$B30:$M30,'Outlook 5+7'!$B$185:$M$185,'Outlook Quarterly 5+7'!E$4) -> 0 | F30: =SUM(B30:E30) -> 40.347844 | H30: ='Budget 2025'!N30 -> 13.639936
A31: CV(GAR) | B31: =SUMPRODUCT('Outlook 5+7'!$B31:$D31,'Outlook 5+7'!$B$30:$D$30)/SUM('Outlook 5+7'!$B$30:$D$30) -> 5860.2842 | C31: =SUMPRODUCT('Outlook 5+7'!$E31:$G31,'Outlook 5+7'!$E$30:$G$30)/SUM('Outlook 5+7'!$E$30:$G$30) -> 5968.5561 | D31: =IFERROR(SUMPRODUCT('Outlook 5+7'!$H31:$J31,'Outlook 5+7'!$H$30:$J$30)/SUM('Outlook 5+7'!$H$30:$J$30),0) -> 0 | E31: =IFERROR(SUMPRODUCT('Outlook 5+7'!$K31:$M31,'Outlook 5+7'!$K$30:$M$30)/SUM('Outlook 5+7'!$K$30:$M$30),0) -> 0 | F31: =SUMPRODUCT(B31:E31,$B$30:$E$30)/SUM($B$30:$E$30) -> 5920.2577 | H31: ='Budget 2025'!N31 -> 5822.4314
A32: TS | B32: =SUMPRODUCT('Outlook 5+7'!$B32:$D32,'Outlook 5+7'!$B$30:$D$30)/SUM('Outlook 5+7'!$B$30:$D$30) -> 0.92078055 | C32: =SUMPRODUCT('Outlook 5+7'!$E32:$G32,'Outlook 5+7'!$E$30:$G$30)/SUM('Outlook 5+7'!$E$30:$G$30) -> 0.9024324 | D32: =IFERROR(SUMPRODUCT('Outlook 5+7'!$H32:$J32,'Outlook 5+7'!$H$30:$J$30)/SUM('Outlook 5+7'!$H$30:$J$30),0) -> 0 | E32: =IFERROR(SUMPRODUCT('Outlook 5+7'!$K32:$M32,'Outlook 5+7'!$K$30:$M$30)/SUM('Outlook 5+7'!$K$30:$M$30),0) -> 0 | F32: =SUMPRODUCT(B32:E32,$B$30:$E$30)/SUM($B$30:$E$30) -> 0.91061722 | H32: ='Budget 2025'!N32 -> 0.90072278
A33: Ash | B33: =SUMPRODUCT('Outlook 5+7'!$B33:$D33,'Outlook 5+7'!$B$30:$D$30)/SUM('Outlook 5+7'!$B$30:$D$30) -> 7.1845522 | C33: =SUMPRODUCT('Outlook 5+7'!$E33:$G33,'Outlook 5+7'!$E$30:$G$30)/SUM('Outlook 5+7'!$E$30:$G$30) -> 6.2976415 | D33: =IFERROR(SUMPRODUCT('Outlook 5+7'!$H33:$J33,'Outlook 5+7'!$H$30:$J$30)/SUM('Outlook 5+7'!$H$30:$J$30),0) -> 0 | E33: =IFERROR(SUMPRODUCT('Outlook 5+7'!$K33:$M33,'Outlook 5+7'!$K$30:$M$30)/SUM('Outlook 5+7'!$K$30:$M$30),0) -> 0 | F33: =SUMPRODUCT(B33:E33,$B$30:$E$30)/SUM($B$30:$E$30) -> 6.6932784 | H33: ='Budget 2025'!N33 -> 8.5977728
A34: Moist | B34: =SUMPRODUCT('Outlook 5+7'!$B34:$D34,'Outlook 5+7'!$B$30:$D$30)/SUM('Outlook 5+7'!$B$30:$D$30) -> 11.01636 | C34: =SUMPRODUCT('Outlook 5+7'!$E34:$G34,'Outlook 5+7'!$E$30:$G$30)/SUM('Outlook 5+7'!$E$30:$G$30) -> 11.639268 | D34: =IFERROR(SUMPRODUCT('Outlook 5+7'!$H34:$J34,'Outlook 5+7'!$H$30:$J$30)/SUM('Outlook 5+7'!$H$30:$J$30),0) -> 0 | E34: =IFERROR(SUMPRODUCT('Outlook 5+7'!$K34:$M34,'Outlook 5+7'!$K$30:$M$30)/SUM('Outlook 5+7'!$K$30:$M$30),0) -> 0 | F34: =SUMPRODUCT(B34:E34,$B$30:$E$30)/SUM($B$30:$E$30) -> 11.361399 | H34: ='Budget 2025'!N34 -> 11.354386
A35: TM | B35: =SUMPRODUCT('Outlook 5+7'!$B35:$D35,'Outlook 5+7'!$B$30:$D$30)/SUM('Outlook 5+7'!$B$30:$D$30) -> 14.501869 | C35: =SUMPRODUCT('Outlook 5+7'!$E35:$G35,'Outlook 5+7'!$E$30:$G$30)/SUM('Outlook 5+7'!$E$30:$G$30) -> 14.874498 | D35: =IFERROR(SUMPRODUCT('Outlook 5+7'!$H35:$J35,'Outlook 5+7'!$H$30:$J$30)/SUM('Outlook 5+7'!$H$30:$J$30),0) -> 0 | E35: =IFERROR(SUMPRODUCT('Outlook 5+7'!$K35:$M35,'Outlook 5+7'!$K$30:$M$30)/SUM('Outlook 5+7'!$K$30:$M$30),0) -> 0 | F35: =SUMPRODUCT(B35:E35,$B$30:$E$30)/SUM($B$30:$E$30) -> 14.708274 | H35: ='Budget 2025'!N35 -> 16.354386
A36: IMM-EB.MCV.MS | B36: =SUMIFS('Outlook 5+7'!$B36:$M36,'Outlook 5+7'!$B$185:$M$185,'Outlook Quarterly 5+7'!B$4) -> 48.098999 | C36: =SUMIFS('Outlook 5+7'!$B36:$M36,'Outlook 5+7'!$B$185:$M$185,'Outlook Quarterly 5+7'!C$4) -> 95.579107 | D36: =SUMIFS('Outlook 5+7'!$B36:$M36,'Outlook 5+7'!$B$185:$M$185,'Outlook Quarterly 5+7'!D$4) -> 145.60219 | E36: =SUMIFS('Outlook 5+7'!$B36:$M36,'Outlook 5+7'!$B$185:$M$185,'Outlook Quarterly 5+7'!E$4) -> 221.63995 | F36: =SUM(B36:E36) -> 510.92024 | H36: ='Budget 2025'!N36 -> 422.71546
A37: CV(GAR) | B37: =SUMPRODUCT('Outlook 5+7'!$B37:$D37,'Outlook 5+7'!$B$36:$D$36)/SUM('Outlook 5+7'!$B$36:$D$36) -> 5977.8247 | C37: =SUMPRODUCT('Outlook 5+7'!$E37:$G37,'Outlook 5+7'!$E$36:$G$36)/SUM('Outlook 5+7'!$E$36:$G$36) -> 5988.4396 | D37: =IFERROR(SUMPRODUCT('Outlook 5+7'!$H37:$J37,'Outlook 5+7'!$H$36:$J$36)/SUM('Outlook 5+7'!$H$36:$J$36),0) -> 6012.4579 | E37: =IFERROR(SUMPRODUCT('Outlook 5+7'!$K37:$M37,'Outlook 5+7'!$K$36:$M$36)/SUM('Outlook 5+7'!$K$36:$M$36),0) -> 6021.0618 | F37: =SUMPRODUCT(B37:E37,$B$36:$E$36)/SUM($B$36:$E$36) -> 6008.4367 | H37: ='Budget 2025'!N37 -> 6013.6725
A38: TS | B38: =SUMPRODUCT('Outlook 5+7'!$B38:$D38,'Outlook 5+7'!$B$36:$D$36)/SUM('Outlook 5+7'!$B$36:$D$36) -> 1.4343487 | C38: =SUMPRODUCT('Outlook 5+7'!$E38:$G38,'Outlook 5+7'!$E$36:$G$36)/SUM('Outlook 5+7'!$E$36:$G$36) -> 1.5235954 | D38: =IFERROR(SUMPRODUCT('Outlook 5+7'!$H38:$J38,'Outlook 5+7'!$H$36:$J$36)/SUM('Outlook 5+7'!$H$36:$J$36),0) -> 1.5755071 | E38: =IFERROR(SUMPRODUCT('Outlook 5+7'!$K38:$M38,'Outlook 5+7'!$K$36:$M$36)/SUM('Outlook 5+7'!$K$36:$M$36),0) -> 1.5766842 | F38: =SUMPRODUCT(B38:E38,$B$36:$E$36)/SUM($B$36:$E$36) -> 1.5530175 | H38: ='Budget 2025'!N38 -> 1.5594733
A39: Ash | B39: =SUMPRODUCT('Outlook 5+7'!$B39:$D39,'Outlook 5+7'!$B$36:$D$36)/SUM('Outlook 5+7'!$B$36:$D$36) -> 6.0426735 | C39: =SUMPRODUCT('Outlook 5+7'!$E39:$G39,'Outlook 5+7'!$E$36:$G$36)/SUM('Outlook 5+7'!$E$36:$G$36) -> 5.6933536 | D39: =IFERROR(SUMPRODUCT('Outlook 5+7'!$H39:$J39,'Outlook 5+7'!$H$36:$J$36)/SUM('Outlook 5+7'!$H$36:$J$36),0) -> 5.3407952 | E39: =IFERROR(SUMPRODUCT('Outlook 5+7'!$K39:$M39,'Outlook 5+7'!$K$36:$M$36)/SUM('Outlook 5+7'!$K$36:$M$36),0) -> 5.3335047 | F39: =SUMPRODUCT(B39:E39,$B$36:$E$36)/SUM($B$36:$E$36) -> 5.4696627 | H39: ='Budget 2025'!N39 -> 5.3287414
A40: Moist | B40: =SUMPRODUCT('Outlook 5+7'!$B40:$D40,'Outlook 5+7'!$B$36:$D$36)/SUM('Outlook 5+7'!$B$36:$D$36) -> 11.610247 | C40: =SUMPRODUCT('Outlook 5+7'!$E40:$G40,'Outlook 5+7'!$E$36:$G$36)/SUM('Outlook 5+7'!$E$36:$G$36) -> 11.526975 | D40: =IFERROR(SUMPRODUCT('Outlook 5+7'!$H40:$J40,'Outlook 5+7'!$H$36:$J$36)/SUM('Outlook 5+7'!$H$36:$J$36),0) -> 10.414678 | E40: =IFERROR(SUMPRODUCT('Outlook 5+7'!$K40:$M40,'Outlook 5+7'!$K$36:$M$36)/SUM('Outlook 5+7'!$K$36:$M$36),0) -> 10.119839 | F40: =SUMPRODUCT(B40:E40,$B$36:$E$36)/SUM($B$36:$E$36) -> 10.607408 | H40: ='Budget 2025'!N40 -> 10.279207
A41: TM | B41: =SUMPRODUCT('Outlook 5+7'!$B41:$D41,'Outlook 5+7'!$B$36:$D$36)/SUM('Outlook 5+7'!$B$36:$D$36) -> 14.141402 | C41: =SUMPRODUCT('Outlook 5+7'!$E41:$G41,'Outlook 5+7'!$E$36:$G$36)/SUM('Outlook 5+7'!$E$36:$G$36) -> 14.585641 | D41: =IFERROR(SUMPRODUCT('Outlook 5+7'!$H41:$J41,'Outlook 5+7'!$H$36:$J$36)/SUM('Outlook 5+7'!$H$36:$J$36),0) -> 15.414678 | E41: =IFERROR(SUMPRODUCT('Outlook 5+7'!$K41:$M41,'Outlook 5+7'!$K$36:$M$36)/SUM('Outlook 5+7'!$K$36:$M$36),0) -> 15.119839 | F41: =SUMPRODUCT(B41:E41,$B$36:$E$36)/SUM($B$36:$E$36) -> 15.011817 | H41: ='Budget 2025'!N41 -> 15.279207
...

Sheet BudgVSact. June
B2: SITES | C2: OB | E2: ROM | G2: FC | I2: SR (OB/ROM) | K2: Diff. (Act.%)
C3: Budget | D3: Actual | E3: Budget | F3: Actual | G3: Budget | H3: Actual | I3: Budget | J3: Actual | K3: OB | L3: ROM
B4: IMM | C4: =SUM('Budget 2025'!B5:G5) -> 45360.043 | D4: =SUM('Outlook 5+7'!B5:G5) -> 42739.577 | E4: =SUM('Budget 2025'!B8:G8) -> 3220 | F4: =SUM('Outlook 5+7'!B8:G8) -> 3248.5517 | G4: =SUM('Budget 2025'!B13:G13) -> 3275.5 | H4: =SUM('Outlook 5+7'!B13:G13) -> 3346.4136 | I4: =C4/E4 -> 14.08697 | J4: =D4/F4 -> 13.156502 | K4: =D4/C4 -> 0.94222963 | L4: =F4/E4 -> 1.008867
B5: TCM | C5: =SUM('Budget 2025'!B56:G56) -> 25550 | D5: =SUM('Outlook 5+7'!B56:G56) -> 21119.949 | E5: =SUM('Budget 2025'!B60:G60) -> 1487 | F5: =SUM('Outlook 5+7'!B60:G60) -> 1379.7147 | G5: =SUM('Budget 2025'!B65:G65) -> 1562 | H5: =SUM('Outlook 5+7'!B66:G66) -> 1471.5346 | I5: =C5/E5 -> 17.182246 | J5: =D5/F5 -> 15.307476 | K5: =D5/C5 -> 0.8266125 | L5: =F5/E5 -> 0.92785118
B6: BEK | C6: =SUM('Budget 2025'!B105:G105) -> 45094 | D6: =SUM('Outlook 5+7'!B100:G100) -> 43274.208 | E6: =SUM('Budget 2025'!B109:G109) -> 3966.5 | F6: =SUM('Outlook 5+7'!B104:G104) -> 4667.3703 | G6: =SUM('Budget 2025'!B115:G115) -> 4050 | H6: =SUM('Outlook 5+7'!B110:G110) -> 4378.6184 | I6: =C6/E6 -> 11.368713 | J6: =D6/F6 -> 9.2716466 | K6: =D6/C6 -> 0.95964448 | L6: =F6/E6 -> 1.1766974
B7: JBG | C7: =SUM('Budget 2025'!B130:G130) -> 1603.028 | D7: =SUM('Outlook 5+7'!B125:G125) -> 160 | E7: =SUM('Budget 2025'!B132:G132) -> 57 | F7: =SUM('Outlook 5+7'!B127:G127) -> 0 | G7: =SUM('Budget 2025'!B137:G137) -> 53 | H7: =SUM('Outlook 5+7'!B132:G132) -> 0 | I7: =C7/E7 -> 28.123298 | J7: =D7/F7 -> #DIV/0! | K7: =D7/C7 -> 0.099811107 | L7: =F7/E7 -> 0
B8: GPK | C8: =SUM('Budget 2025'!B145:G145) -> 3825 | D8: =SUM('Outlook 5+7'!B140:G140) -> 3504.6301 | E8: =SUM('Budget 2025'!B147:G147) -> 1062 | F8: =SUM('Outlook 5+7'!B142:G142) -> 1202.5745 | G8: =SUM('Budget 2025'!B152:G152) -> 1100 | H8: =SUM('Outlook 5+7'!B148:G148) -> 1187.4358 | I8: =C8/E8 -> 3.6016949 | J8: =D8/F8 -> 2.9142727 | K8: =D8/C8 -> 0.91624316 | L8: =F8/E8 -> 1.1323677
B9: TIS | C9: =SUM('Budget 2025'!B160:G160) -> 4924.429 | D9: =SUM('Outlook 5+7'!B156:G156) -> 4594.1727 | E9: =SUM('Budget 2025'!B162:G162) -> 270.88602 | F9: =SUM('Outlook 5+7'!B158:G158) -> 267.94092 | G9: =SUM('Budget 2025'!B166:G166) -> 245 | H9: =SUM('Outlook 5+7'!B163:G163) -> 157.69274 | I9: =C9/E9 -> 18.178971 | J9: =D9/F9 -> 17.146215 | K9: =D9/C9 -> 0.9329351 | L9: =F9/E9 -> 0.9891279
B10: TOTAL | C10: =SUM(C4:C9) -> 126356.5 | D10: =SUM(D4:D9) -> 115392.54 | E10: =SUM(E4:E9) -> 10063.386 | F10: =SUM(F4:F9) -> 10766.152 | G10: =SUM(G4:G9) -> 10285.5 | H10: =SUM(H4:H9) -> 10541.695 | I10: =C10/E10 -> 12.556062 | J10: =D10/F10 -> 10.718085 | K10: =D10/C10 -> 0.91322992 | L10: =F10/E10 -> 1.069834
F11: =F10/E10 -> 1.069834 | H11: =H10/G10 -> 1.0249084
