Workbook
Name _1__MINE_STOCKYARD_34: #REF!
Name _1__MINE_STOCKYARD_34: #REF!
Name _1__MINE_STOCKYARD_34: #REF!
Name _1__MINE_STOCKYARD_34: #REF!
Name _1__MINE_STOCKYARD_34: #REF!
Name _1__MINE_STOCKYARD_34_10: #REF!
Name _1__MINE_STOCKYARD_34_10: #REF!
Name _1__MINE_STOCKYARD_34_10: #REF!
Name _1__MINE_STOCKYARD_34_10: #REF!
Name _1__MINE_STOCKYARD_34_10: #REF!
Name _1__MINE_STOCKYARD_34_12: #REF!
Name _1__MINE_STOCKYARD_34_12: #REF!
Name _1__MINE_STOCKYARD_34_12: #REF!
Name _1__MINE_STOCKYARD_34_12: #REF!
Name _1__MINE_STOCKYARD_34_12: #REF!
Name _1__MINE_STOCKYARD_34_13: #REF!
Name _1__MINE_STOCKYARD_34_13: #REF!
Name _1__MINE_STOCKYARD_34_13: #REF!
Name _1__MINE_STOCKYARD_34_13: #REF!
Name _1__MINE_STOCKYARD_34_13: #REF!
Name _1__MINE_STOCKYARD_34_4: #REF!
Name _1__MINE_STOCKYARD_34_4: #REF!
Name _1__MINE_STOCKYARD_34_4: #REF!
Name _1__MINE_STOCKYARD_34_4: #REF!
Name _1__MINE_STOCKYARD_34_4: #REF!
Name _1A1_Z1...A10_Z10: #REF!
Name _1A1_Z1...A10_Z10: #REF!
Name _1A1_Z1...A10_Z10: #REF!
Name _1A1_Z1...A10_Z10: #REF!
Name _1A1_Z1...A10_Z10: #REF!
Name _1A1_Z1...A10_Z10: #REF!
Name _1A1_Z1...A10_Z10: #REF!
Name _1A1_Z1...A10_Z10: #REF!
Name _1A1_Z1...A10_Z10: #REF!
Name _Apr: [1]Validation!$A$33
Name _Apr: [2]Validation!$A$33
Name _Aug: [1]Validation!$A$37
Name _Aug: [2]Validation!$A$37
Name _Chubu1: [1]Validation!$A$5
Name _Chubu1: [2]Validation!$A$5
Name _Chubu2: [1]Validation!$A$6
Name _Chubu2: [2]Validation!$A$6
Name _Chubu3: [1]Validation!$A$7
Name _Chubu3: [2]Validation!$A$7
Name _ChubuP1: [1]Chubu!$V$203
Name _ChubuP1: [2]Chubu!$V$203
Name _ChubuP2: [1]Chubu!$V$204
Name _ChubuP2: [2]Chubu!$V$204
Name _CLP: [1]Validation!$A$17
Name _CLP: [2]Validation!$A$17
Name _CLPP1: [1]CLP!$V$203
Name _CLPP1: [2]CLP!$V$203
Name _CLPP2: [1]CLP!$V$204
Name _CLPP2: [2]CLP!$V$204
Name _DATE: #REF!
Name _DATE: #REF!
Name _DATE: #REF!
Name _DATE: #REF!
Name _DATE: #REF!
Name _DATE: #REF!

Sheet Pro Outlook 06 Jan 2026
P1: A | S1: A
B2: FINAL DRAFT OF ITM PLANBASE
B3: ITM MINE PLAN YEAR 2025
D4: Act | E4: Act | F4: Act | G4: Act | H4: Act | I4: Act | J4: Act | K4: Act | L4: Act | M4: Act | N4: Act | O4: Act | P4: 46028 | S4: Y2025 Bgt
A5: ok | B5: IMM | C5: EO Y24 | D5: Jan | E5: Feb | F5: Mar | G5: Apr | H5: May | I5: Jun | J5: Jul | K5: Aug | L5: Sep | M5: Oct | N5: Nov | O5: Dec | S5: Total
B6: ROM Production | D6: 542.83357 | E6: 554.11951 | F6: 482.78672 | G6: 444.51201 | H6: 639.80024 | I6: 581.91609 | J6: 700.57043 | K6: 501.69548 | L6: 550.72239 | M6: 650.56649 | N6: 654.91044 | O6: 602.17213 | P6: =SUM(D6:O6) -> 6906.6055 | S6: 6950 | T6: Done | U6: ROM exclude fine coal
B7: FC Product (Kton) | D7: 612.68293 | E7: 584.91494 | F7: 501.01074 | G7: 479.30495 | H7: 587.89845 | I7: 588.81158 | J7: 635.40798 | K7: 595.5322 | L7: 562.70584 | M7: 651.08386 | N7: 641.92383 | O7: 660.90965 | P7: =SUM(P9,P15,P21,P27,P33,P39) -> 7102.187 | S7: 7100
B8: FC Ready to Haul Product (Kton) | D8: 601.14336 | E8: 585.33662 | F8: 497.28483 | G8: 489.59278 | H8: 579.75802 | I8: 570.54402 | J8: 613.68195 | K8: 645.26844 | L8: 552.02088 | M8: 652.97927 | N8: 616.85711 | O8: 674.28096 | P8: =SUM(D8:O8) -> 7078.7483 | S8: 7100
B9: IMM-WB.HCV.LS | D9: 146.18254 | E9: 147.46076 | F9: 104.99952 | G9: 70.128194 | H9: 84.530923 | I9: 85.31518 | J9: 119.56926 | K9: 57.606521 | L9: 44.664901 | M9: 55.25837 | N9: 52.535889 | O9: 33.925349 | P9: =SUM(D9:O9) -> 1002.1774 | S9: 1228.8032
B10: CV (GAR) | D10: 6193.9879 | E10: 6105.8162 | F10: 6211.2744 | G10: 6152.0829 | H10: 6133.0399 | I10: 6095.5899 | J10: 6027.0339 | K10: 6323.4648 | L10: 6478.2496 | M10: 6399.4105 | N10: 6258.3819 | O10: 6269.7198 | P10: =SUMPRODUCT(D10:O10,$D$9:$O$9)/SUM($D$9:$O$9) -> 6183.8339 | S10: 6169.7769
B11: TS | D11: 0.61677597 | E11: 0.68122223 | F11: 0.59905828 | G11: 0.64019198 | H11: 0.77254239 | I11: 0.68498819 | J11: 0.88431051 | K11: 0.87124756 | L11: 0.99071489 | M11: 0.98923831 | N11: 0.92651159 | O11: 1.0297165 | P11: =SUMPRODUCT(D11:O11,$D$9:$O$9)/SUM($D$9:$O$9) -> 0.7589512 | S11: 0.81080181
B12: Ash | D12: 8.41834 | E12: 8.393601 | F12: 8.4815141 | G12: 7.9869977 | H12: 8.4695031 | I12: 7.7685138 | J12: 8.2568684 | K12: 6.1980757 | L12: 6.1102154 | M12: 6.7219 | N12: 7.0407335 | O12: 6.0500959 | P12: =SUMPRODUCT(D12:O12,$D$9:$O$9)/SUM($D$9:$O$9) -> 7.8444497 | S12: 8.3745645
B13: Moist | D13: 8.6372078 | E13: 9.4241924 | F13: 8.714191 | G13: 9.2338941 | H13: 8.7192877 | I13: 9.9019574 | J13: 9.7312726 | K13: 8.8103686 | L13: 7.4340647 | M13: 7.6935216 | N13: 9.2252263 | O13: 8.5892544 | P13: =SUMPRODUCT(D13:O13,$D$9:$O$9)/SUM($D$9:$O$9) -> 8.9814481 | S13: 8.0403443
B14: TM | D14: 11.489526 | E14: 12.325215 | F14: 11.133918 | G14: 12.344042 | H14: 12.370062 | I14: 12.73142 | J14: 12.953025 | K14: 12.05475 | L14: 10.96115 | M14: 11.147027 | N14: 11.653184 | O14: 12.626764 | P14: =SUMPRODUCT(D14:O14,$D$9:$O$9)/SUM($D$9:$O$9) -> 12.026763 | S14: 13.065707
B15: IMM-WB.HCV.HS | D15: 57.659789 | E15: 65.698593 | F15: 46.076686 | G15: 30.406221 | H15: 42.82342 | I15: 47.49773 | J15: 71.153679 | K15: 54.975435 | L15: 53.349838 | M15: 83.413274 | N15: 67.363141 | O15: 79.065254 | P15: =SUM(D15:O15) -> 699.48306 | S15: 633.69685
B16: CV (GAR) | D16: 5947.3932 | E16: 5939.4465 | F16: 6026.7648 | G16: 5928.2234 | H16: 6043.0525 | I16: 6015.1688 | J16: 6025.5954 | K16: 6219.9241 | L16: 6110.0715 | M16: 6170.7695 | N16: 5993.56 | O16: 6014.2541 | P16: =SUMPRODUCT(D16:O16,$D$15:$O$15)/SUM($D$15:$O$15) -> 6041.9237 | S16: 5965.7827
B17: TS | D17: 1.9789488 | E17: 2.2887477 | F17: 2.1709775 | G17: 1.9301202 | H17: 2.0257524 | I17: 2.5171695 | J17: 2.517463 | K17: 2.3312516 | L17: 2.673021 | M17: 2.3581053 | N17: 2.4947734 | O17: 2.1149493 | P17: =SUMPRODUCT(D17:O17,$D$15:$O$15)/SUM($D$15:$O$15) -> 2.3036548 | S17: 2.5790489
B18: Ash | D18: 12.398872 | E18: 11.628956 | F18: 11.380259 | G18: 12.152459 | H18: 11.490738 | I18: 11.721002 | J18: 11.274462 | K18: 8.2055884 | L18: 10.665238 | M18: 9.8990025 | N18: 11.465018 | O18: 8.5307605 | P18: =SUMPRODUCT(D18:O18,$D$15:$O$15)/SUM($D$15:$O$15) -> 10.745678 | S18: 13.960595
B19: Moist | D19: 7.8249272 | E19: 7.5595294 | F19: 6.9977463 | G19: 7.2613478 | H19: 7.0928299 | I19: 7.1802963 | J19: 7.4285939 | K19: 7.7994087 | L19: 6.8073634 | M19: 6.91033 | N19: 7.2685027 | O19: 8.6333709 | P19: =SUMPRODUCT(D19:O19,$D$15:$O$15)/SUM($D$15:$O$15) -> 7.4412177 | S19: 6.7439986
B20: TM | D20: 10.911081 | E20: 11.826969 | F20: 11.261991 | G20: 11.642346 | H20: 10.959217 | I20: 10.871461 | J20: 10.665209 | K20: 11.303541 | L20: 10.575958 | M20: 10.884744 | N20: 11.290435 | O20: 13.144635 | P20: =SUMPRODUCT(D20:O20,$D$15:$O$15)/SUM($D$15:$O$15) -> 11.318399 | S20: 11.769361
B21: IMM-EB.MCV.LS | D21: 4.1511632 | E21: 4.8753097 | F21: 8.972062 | G21: 7.4826072 | H21: 9.8667018 | I21: 5.265915 | J21: 0 | K21: 0 | L21: 0 | M21: 0 | N21: 0 | O21: 0 | P21: =SUM(D21:O21) -> 40.613759 | S21: 13.639936
B22: CV (GAR) | D22: 5768.2424 | E22: 5970.6107 | F22: 5842.9196 | G22: 6060.3315 | H22: 5981.1886 | I22: 5851.139 | J22: 0 | K22: 0 | L22: 0 | M22: 0 | N22: 0 | O22: 0 | P22: =SUMPRODUCT(D22:O22,$D$21:$O$21)/SUM($D$21:$O$21) -> 5925.3273 | S22: 5822.4314
B23: TS | D23: 0.90470615 | E23: 0.97326494 | F23: 0.89969842 | G23: 0.91618026 | H23: 0.8618658 | I23: 1.031383 | J23: 0 | K23: 0 | L23: 0 | M23: 0 | N23: 0 | O23: 0 | P23: =SUMPRODUCT(D23:O23,$D$21:$O$21)/SUM($D$21:$O$21) -> 0.9199608 | S23: 0.90072278
B24: Ash | D24: 8.4980056 | E24: 6.454713 | F24: 6.9734339 | G24: 5.5176512 | H24: 5.7561377 | I24: 6.6074957 | J24: 0 | K24: 0 | L24: 0 | M24: 0 | N24: 0 | O24: 0 | P24: =SUMPRODUCT(D24:O24,$D$21:$O$21)/SUM($D$21:$O$21) -> 6.4556062 | S24: 8.5977728
B25: Moist | D25: 10.861527 | E25: 11.334285 | F25: 10.91524 | G25: 11.119528 | H25: 11.717851 | I25: 11.463808 | J25: 0 | K25: 0 | L25: 0 | M25: 0 | N25: 0 | O25: 0 | P25: =SUMPRODUCT(D25:O25,$D$21:$O$21)/SUM($D$21:$O$21) -> 11.263803 | S25: 11.354386
B26: TM | D26: 14.308473 | E26: 13.960815 | F26: 14.885351 | G26: 13.934471 | H26: 14.518515 | I26: 15.49119 | J26: 0 | K26: 0 | L26: 0 | M26: 0 | N26: 0 | O26: 0 | P26: =SUMPRODUCT(D26:O26,$D$21:$O$21)/SUM($D$21:$O$21) -> 14.52965 | S26: 16.354386
B27: IMM-EB.MCV.MS | D27: 16.385665 | E27: 4.2318727 | F27: 27.481461 | G27: 41.321236 | H27: 24.257871 | I27: 32.490626 | J27: 33.660431 | K27: 63.500811 | L27: 68.485178 | M27: 121.38451 | N27: 87.133232 | O27: 39.389008 | P27: =SUM(D27:O27) -> 559.7219 | S27: 422.71546
B28: CV (GAR) | D28: 6095.6967 | E28: 5702.0802 | F28: 5950.0061 | G28: 5974.4204 | H28: 6089.8148 | I28: 6004.3095 | J28: 6212.717 | K28: 6104.6147 | L28: 6209.1597 | M28: 6155.1716 | N28: 6120.7271 | O28: 6109.1027 | P28: =SUMPRODUCT(D28:O28,$D$27:$O$27)/SUM($D$27:$O$27) -> 6110.7246 | S28: 6013.6725
B29: TS | D29: 1.5214168 | E29: 1.2568182 | F29: 1.4097729 | G29: 1.483995 | H29: 1.5035755 | I29: 1.4015116 | J29: 1.4871012 | K29: 1.5742532 | L29: 1.6603096 | M29: 1.71484 | N29: 1.6253156 | O29: 1.5135433 | P29: =SUMPRODUCT(D29:O29,$D$27:$O$27)/SUM($D$27:$O$27) -> 1.5819306 | S29: 1.5594733
B30: Ash | D30: 5.147646 | E30: 7.9572727 | F30: 6.2814993 | G30: 5.8970893 | H30: 5.4006541 | I30: 5.6630745 | J30: 4.2812106 | K30: 4.8911374 | L30: 4.1354356 | M30: 4.6429276 | N30: 4.7296051 | O30: 4.8504805 | P30: =SUMPRODUCT(D30:O30,$D$27:$O$27)/SUM($D$27:$O$27) -> 4.9202689 | S30: 5.3287414
B31: Moist | D31: 11.52539 | E31: 13.017273 | F31: 11.444174 | G31: 12.148882 | H31: 11.241298 | I31: 12.009315 | J31: 11.373018 | K31: 11.099242 | L31: 10.854497 | M31: 10.67932 | N31: 11.313208 | O31: 11.039075 | P31: =SUMPRODUCT(D31:O31,$D$27:$O$27)/SUM($D$27:$O$27) -> 11.204154 | S31: 10.279207
B32: TM | D32: 13.645355 | E32: 15.082727 | F32: 14.292213 | G32: 14.144596 | H32: 13.581215 | I32: 14.361058 | J32: 13.136979 | K32: 13.821241 | L32: 13.353758 | M32: 13.438844 | N32: 13.824669 | O32: 13.470155 | P32: =SUMPRODUCT(D32:O32,$D$27:$O$27)/SUM($D$27:$O$27) -> 13.688107 | S32: 15.279207
B33: IMM-EB.MCV.HS | D33: 388.30377 | E33: 362.64841 | F33: 313.48101 | G33: 329.77482 | H33: 426.41004 | I33: 418.24213 | J33: 407.96146 | K33: 419.31498 | L33: 396.20593 | M33: 390.94802 | N33: 434.89157 | O33: 505.81519 | P33: =SUM(D33:O33) -> 4793.9973 | S33: 4673.6446
B34: CV (GAR) | D34: 5993.4453 | E34: 6000.7559 | F34: 5998.3259 | G34: 5980.6624 | H34: 6016.1816 | I34: 6037.4357 | J34: 6026.8584 | K34: 6058.0917 | L34: 6116.4858 | M34: 6067.558 | N34: 6089.1963 | O34: 6075.0833 | P34: =SUMPRODUCT(D34:O34,$D$33:$O$33)/SUM($D$33:$O$33) -> 6041.3086 | S34: 5913.433
B35: TS | D35: 2.2774465 | E35: 2.2808086 | F35: 2.3121792 | G35: 2.3365919 | H35: 2.2916822 | I35: 2.3282708 | J35: 2.4293167 | K35: 2.3306678 | L35: 2.3995535 | M35: 2.3971127 | N35: 2.2574273 | O35: 2.212017 | P35: =SUMPRODUCT(D35:O35,$D$33:$O$33)/SUM($D$33:$O$33) -> 2.3184507 | S35: 2.4112912
B36: Ash | D36: 5.9664259 | E36: 5.8860489 | F36: 6.233699 | G36: 5.97695 | H36: 5.7339946 | I36: 5.8093453 | J36: 5.9732711 | K36: 5.2092445 | L36: 4.4746161 | M36: 5.0721745 | N36: 4.6123291 | O36: 4.6540032 | P36: =SUMPRODUCT(D36:O36,$D$33:$O$33)/SUM($D$33:$O$33) -> 5.4209928 | S36: 5.7201801
B37: Moist | D37: 11.432183 | E37: 11.490454 | F37: 11.114391 | G37: 11.487337 | H37: 11.507948 | I37: 11.274038 | J37: 10.928006 | K37: 11.160217 | L37: 10.970967 | M37: 11.00537 | N37: 11.415273 | O37: 11.203886 | P37: =SUMPRODUCT(D37:O37,$D$33:$O$33)/SUM($D$33:$O$33) -> 11.247308 | S37: 10.558328
B38: TM | D38: 13.742009 | E38: 13.585975 | F38: 13.470646 | G38: 13.788683 | H38: 13.727396 | I38: 13.462718 | J38: 13.439047 | K38: 13.806023 | L38: 13.876325 | M38: 13.825875 | N38: 13.866785 | O38: 14.120403 | P38: =SUMPRODUCT(D38:O38,$D$33:$O$33)/SUM($D$33:$O$33) -> 13.739007 | S38: 15.558328
B39: Fine Coal | D39: 0 | E39: 0 | F39: 0 | G39: 0.19186901 | H39: 0.0094999788 | I39: 0 | J39: 3.063153 | K39: 0.13444362 | L39: 0 | M39: 0.079692288 | N39: 0 | O39: 2.7148458 | P39: =SUM(D39:O39) -> 6.1935036 | S39: 127.5
B40: CV (GAR) | D40: 3146.0674 | E40: 3146.0674 | F40: 3146.0674 | G40: 3966.2693 | H40: 4270.5018 | I40: 3146.0674 | J40: 3378.667 | K40: 3635.6911 | L40: 3146.0674 | M40: 3838.5829 | N40: 3146.0674 | O40: 3146.0674 | P40: =SUMPRODUCT(D40:O40,$D$39:$O$39)/SUM($D$39:$O$39) -> 3307.7782 | S40: 3146.0674
...

Sheet Pro Outlook (Quarterly)
H1: A | K1: A
B2: FINAL DRAFT OF ITM PLANBASE
B3: ITM MINE PLAN YEAR 2025
D4: Act | E4: Act | F4: Act | G4: Act | H4: ='Pro Outlook 06 Jan 2026'!P4 -> 46028 | K4: Y2025 Bgt
A5: ok | B5: IMM | C5: EO Y24 | D5: Q1 | E5: Q2 | F5: Q3 | G5: Q4 | K5: Total
B6: ROM Production | D6: =SUM('Pro Outlook 06 Jan 2026'!D6:F6) -> 1579.7398 | E6: =SUM('Pro Outlook 06 Jan 2026'!G6:I6) -> 1666.2283 | F6: =SUM('Pro Outlook 06 Jan 2026'!J6:L6) -> 1752.9883 | G6: =SUM('Pro Outlook 06 Jan 2026'!M6:O6) -> 1907.6491 | H6: =SUM(D6:G6) -> 6906.6055 | K6: 6950 | L6: Done | M6: ROM exclude fine coal
B7: FC Product (Kton) | D7: =(D9+D15+D21+D27+D33+D39) -> 1698.6086 | E7: =(E9+E15+E21+E27+E33+E39) -> 1656.015 | F7: =(F9+F15+F21+F27+F33+F39) -> 1793.646 | G7: =(G9+G15+G21+G27+G33+G39) -> 1953.9173 | H7: =SUM(H9,H15,H21,H27,H33,H39) -> 7102.187 | K7: 7100
B8: FC Ready to Haul Product (Kton) | D8: =SUM('Pro Outlook 06 Jan 2026'!D8:F8) -> 1683.7648 | E8: =SUM('Pro Outlook 06 Jan 2026'!G8:I8) -> 1639.8948 | F8: =SUM('Pro Outlook 06 Jan 2026'!J8:L8) -> 1810.9713 | G8: =SUM('Pro Outlook 06 Jan 2026'!M8:O8) -> 1944.1173 | H8: =SUM(D8:G8) -> 7078.7483 | K8: 7100
B9: IMM-WB.HCV.LS | D9: =SUM('Pro Outlook 06 Jan 2026'!D9:F9) -> 398.64282 | E9: =SUM('Pro Outlook 06 Jan 2026'!G9:I9) -> 239.9743 | F9: =SUM('Pro Outlook 06 Jan 2026'!J9:L9) -> 221.84068 | G9: =SUM('Pro Outlook 06 Jan 2026'!M9:O9) -> 141.71961 | H9: =SUM(D9:G9) -> 1002.1774 | K9: 1228.8032
B10: CV (GAR) | D10: =SUMPRODUCT('Pro Outlook 06 Jan 2026'!D10:F10,'Pro Outlook 06 Jan 2026'!$D$9:$F$9)/SUM('Pro Outlook 06 Jan 2026'!$D$9:$F$9) -> 6165.9257 | E10: =SUMPRODUCT('Pro Outlook 06 Jan 2026'!G10:I10,'Pro Outlook 06 Jan 2026'!$G$9:$I$9)/SUM('Pro Outlook 06 Jan 2026'!$G$9:$I$9) -> 6125.2907 | F10: =SUMPRODUCT('Pro Outlook 06 Jan 2026'!J10:L10,'Pro Outlook 06 Jan 2026'!$J$9:$L$9)/SUM('Pro Outlook 06 Jan 2026'!$J$9:$L$9) -> 6194.8564 | G10: =SUMPRODUCT('Pro Outlook 06 Jan 2026'!M10:O10,'Pro Outlook 06 Jan 2026'!$M$9:$O$9)/SUM('Pro Outlook 06 Jan 2026'!$M$9:$O$9) -> 6316.0849 | H10: =SUMPRODUCT(D10:G10,$D$9:$G$9)/SUM($D$9:$G$9) -> 6183.8339 | J10: =SUMPRODUCT(D9:F9,D10:F10)/H9 -> 5290.6656 | K10: 6169.7769
B11: TS | D11: =SUMPRODUCT('Pro Outlook 06 Jan 2026'!D11:F11,'Pro Outlook 06 Jan 2026'!$D$9:$F$9)/SUM('Pro Outlook 06 Jan 2026'!$D$9:$F$9) -> 0.63594838 | E11: =SUMPRODUCT('Pro Outlook 06 Jan 2026'!G11:I11,'Pro Outlook 06 Jan 2026'!$G$9:$I$9)/SUM('Pro Outlook 06 Jan 2026'!$G$9:$I$9) -> 0.70273826 | F11: =SUMPRODUCT('Pro Outlook 06 Jan 2026'!J11:L11,'Pro Outlook 06 Jan 2026'!$J$9:$L$9)/SUM('Pro Outlook 06 Jan 2026'!$J$9:$L$9) -> 0.90234161 | G11: =SUMPRODUCT('Pro Outlook 06 Jan 2026'!M11:O11,'Pro Outlook 06 Jan 2026'!$M$9:$O$9)/SUM('Pro Outlook 06 Jan 2026'!$M$9:$O$9) -> 0.97567514 | H11: =SUMPRODUCT(D11:G11,$D$9:$G$9)/SUM($D$9:$G$9) -> 0.7589512 | J11: =SUMPRODUCT(D9:F9,D11:F11)/H9 -> 0.62097933 | K11: 0.81080181
B12: Ash | D12: =SUMPRODUCT('Pro Outlook 06 Jan 2026'!D12:F12,'Pro Outlook 06 Jan 2026'!$D$9:$F$9)/SUM('Pro Outlook 06 Jan 2026'!$D$9:$F$9) -> 8.4258284 | E12: =SUMPRODUCT('Pro Outlook 06 Jan 2026'!G12:I12,'Pro Outlook 06 Jan 2026'!$G$9:$I$9)/SUM('Pro Outlook 06 Jan 2026'!$G$9:$I$9) -> 8.0792853 | F12: =SUMPRODUCT('Pro Outlook 06 Jan 2026'!J12:L12,'Pro Outlook 06 Jan 2026'!$J$9:$L$9)/SUM('Pro Outlook 06 Jan 2026'!$J$9:$L$9) -> 7.2900487 | G12: =SUMPRODUCT('Pro Outlook 06 Jan 2026'!M12:O12,'Pro Outlook 06 Jan 2026'!$M$9:$O$9)/SUM('Pro Outlook 06 Jan 2026'!$M$9:$O$9) -> 6.6792737 | H12: =SUMPRODUCT(D12:G12,$D$9:$G$9)/SUM($D$9:$G$9) -> 7.8444497 | J12: =SUMPRODUCT(D9:F9,D12:F12)/H9 -> 6.8999223 | K12: 8.3745645
B13: Moist | D13: =SUMPRODUCT('Pro Outlook 06 Jan 2026'!D13:F13,'Pro Outlook 06 Jan 2026'!$D$9:$F$9)/SUM('Pro Outlook 06 Jan 2026'!$D$9:$F$9) -> 8.9485957 | E13: =SUMPRODUCT('Pro Outlook 06 Jan 2026'!G13:I13,'Pro Outlook 06 Jan 2026'!$G$9:$I$9)/SUM('Pro Outlook 06 Jan 2026'!$G$9:$I$9) -> 9.2901326 | F13: =SUMPRODUCT('Pro Outlook 06 Jan 2026'!J13:L13,'Pro Outlook 06 Jan 2026'!$J$9:$L$9)/SUM('Pro Outlook 06 Jan 2026'!$J$9:$L$9) -> 9.029622 | G13: =SUMPRODUCT('Pro Outlook 06 Jan 2026'!M13:O13,'Pro Outlook 06 Jan 2026'!$M$9:$O$9)/SUM('Pro Outlook 06 Jan 2026'!$M$9:$O$9) -> 8.4757529 | H13: =SUMPRODUCT(D13:G13,$D$9:$G$9)/SUM($D$9:$G$9) -> 8.9814481 | J13: =SUMPRODUCT(D9:F9,D13:F13)/H9 -> 7.7828775 | K13: 8.0403443
B14: TM | D14: =SUMPRODUCT('Pro Outlook 06 Jan 2026'!D14:F14,'Pro Outlook 06 Jan 2026'!$D$9:$F$9)/SUM('Pro Outlook 06 Jan 2026'!$D$9:$F$9) -> 11.704989 | E14: =SUMPRODUCT('Pro Outlook 06 Jan 2026'!G14:I14,'Pro Outlook 06 Jan 2026'!$G$9:$I$9)/SUM('Pro Outlook 06 Jan 2026'!$G$9:$I$9) -> 12.490927 | F14: =SUMPRODUCT('Pro Outlook 06 Jan 2026'!J14:L14,'Pro Outlook 06 Jan 2026'!$J$9:$L$9)/SUM('Pro Outlook 06 Jan 2026'!$J$9:$L$9) -> 12.318725 | G14: =SUMPRODUCT('Pro Outlook 06 Jan 2026'!M14:O14,'Pro Outlook 06 Jan 2026'!$M$9:$O$9)/SUM('Pro Outlook 06 Jan 2026'!$M$9:$O$9) -> 11.688886 | H14: =SUMPRODUCT(D14:G14,$D$9:$G$9)/SUM($D$9:$G$9) -> 12.026763 | J14: =SUMPRODUCT(D9:F9,D14:F14)/H9 -> 10.373818 | K14: 13.065707
B15: IMM-WB.HCV.HS | D15: =SUM('Pro Outlook 06 Jan 2026'!D15:F15) -> 169.43507 | E15: =SUM('Pro Outlook 06 Jan 2026'!G15:I15) -> 120.72737 | F15: =SUM('Pro Outlook 06 Jan 2026'!J15:L15) -> 179.47895 | G15: =SUM('Pro Outlook 06 Jan 2026'!M15:O15) -> 229.84167 | H15: =SUM(D15:G15) -> 699.48306 | K15: 633.69685
B16: CV (GAR) | D16: =SUMPRODUCT('Pro Outlook 06 Jan 2026'!D16:F16,'Pro Outlook 06 Jan 2026'!$D$15:$F$15)/SUM('Pro Outlook 06 Jan 2026'!$D$15:$F$15) -> 5965.8964 | E16: =SUMPRODUCT('Pro Outlook 06 Jan 2026'!G16:I16,'Pro Outlook 06 Jan 2026'!$G$15:$I$15)/SUM('Pro Outlook 06 Jan 2026'!$G$15:$I$15) -> 6003.1615 | F16: =SUMPRODUCT('Pro Outlook 06 Jan 2026'!J16:L16,'Pro Outlook 06 Jan 2026'!$J$15:$L$15)/SUM('Pro Outlook 06 Jan 2026'!$J$15:$L$15) -> 6110.2298 | G16: =SUMPRODUCT('Pro Outlook 06 Jan 2026'!M16:O16,'Pro Outlook 06 Jan 2026'!$M$15:$O$15)/SUM('Pro Outlook 06 Jan 2026'!$M$15:$O$15) -> 6064.991 | H16: =SUMPRODUCT(D16:G16,$D$15:$G$15)/SUM($D$15:$G$15) -> 6041.9237 | J16: =SUMPRODUCT(D15:F15,D16:F16)/H15 -> 4049.041 | K16: 5965.7827
B17: TS | D17: =SUMPRODUCT('Pro Outlook 06 Jan 2026'!D17:F17,'Pro Outlook 06 Jan 2026'!$D$15:$F$15)/SUM('Pro Outlook 06 Jan 2026'!$D$15:$F$15) -> 2.1512944 | E17: =SUMPRODUCT('Pro Outlook 06 Jan 2026'!G17:I17,'Pro Outlook 06 Jan 2026'!$G$15:$I$15)/SUM('Pro Outlook 06 Jan 2026'!$G$15:$I$15) -> 2.1950047 | F17: =SUMPRODUCT('Pro Outlook 06 Jan 2026'!J17:L17,'Pro Outlook 06 Jan 2026'!$J$15:$L$15)/SUM('Pro Outlook 06 Jan 2026'!$J$15:$L$15) -> 2.5066648 | G17: =SUMPRODUCT('Pro Outlook 06 Jan 2026'!M17:O17,'Pro Outlook 06 Jan 2026'!$M$15:$O$15)/SUM('Pro Outlook 06 Jan 2026'!$M$15:$O$15) -> 2.3145153 | H17: =SUMPRODUCT(D17:G17,$D$15:$G$15)/SUM($D$15:$G$15) -> 2.3036548 | J17: =SUMPRODUCT(D15:F15,D17:F17)/H15 -> 1.5431331 | K17: 2.5790489
B18: Ash | D18: =SUMPRODUCT('Pro Outlook 06 Jan 2026'!D18:F18,'Pro Outlook 06 Jan 2026'!$D$15:$F$15)/SUM('Pro Outlook 06 Jan 2026'!$D$15:$F$15) -> 11.823332 | E18: =SUMPRODUCT('Pro Outlook 06 Jan 2026'!G18:I18,'Pro Outlook 06 Jan 2026'!$G$15:$I$15)/SUM('Pro Outlook 06 Jan 2026'!$G$15:$I$15) -> 11.747991 | F18: =SUMPRODUCT('Pro Outlook 06 Jan 2026'!J18:L18,'Pro Outlook 06 Jan 2026'!$J$15:$L$15)/SUM('Pro Outlook 06 Jan 2026'!$J$15:$L$15) -> 10.153357 | G18: =SUMPRODUCT('Pro Outlook 06 Jan 2026'!M18:O18,'Pro Outlook 06 Jan 2026'!$M$15:$O$15)/SUM('Pro Outlook 06 Jan 2026'!$M$15:$O$15) -> 9.8873046 | H18: =SUMPRODUCT(D18:G18,$D$15:$G$15)/SUM($D$15:$G$15) -> 10.745678 | J18: =SUMPRODUCT(D15:F15,D18:F18)/H15 -> 7.4968291 | K18: 13.960595
B19: Moist | D19: =SUMPRODUCT('Pro Outlook 06 Jan 2026'!D19:F19,'Pro Outlook 06 Jan 2026'!$D$15:$F$15)/SUM('Pro Outlook 06 Jan 2026'!$D$15:$F$15) -> 7.4970729 | E19: =SUMPRODUCT('Pro Outlook 06 Jan 2026'!G19:I19,'Pro Outlook 06 Jan 2026'!$G$15:$I$15)/SUM('Pro Outlook 06 Jan 2026'!$G$15:$I$15) -> 7.1696845 | F19: =SUMPRODUCT('Pro Outlook 06 Jan 2026'!J19:L19,'Pro Outlook 06 Jan 2026'!$J$15:$L$15)/SUM('Pro Outlook 06 Jan 2026'!$J$15:$L$15) -> 7.3575168 | G19: =SUMPRODUCT('Pro Outlook 06 Jan 2026'!M19:O19,'Pro Outlook 06 Jan 2026'!$M$15:$O$15)/SUM('Pro Outlook 06 Jan 2026'!$M$15:$O$15) -> 7.608029 | H19: =SUMPRODUCT(D19:G19,$D$15:$G$15)/SUM($D$15:$G$15) -> 7.4412177 | J19: =SUMPRODUCT(D15:F15,D19:F19)/H15 -> 4.9413114 | K19: 6.7439986
B20: TM | D20: =SUMPRODUCT('Pro Outlook 06 Jan 2026'!D20:F20,'Pro Outlook 06 Jan 2026'!$D$15:$F$15)/SUM('Pro Outlook 06 Jan 2026'!$D$15:$F$15) -> 11.361645 | E20: =SUMPRODUCT('Pro Outlook 06 Jan 2026'!G20:I20,'Pro Outlook 06 Jan 2026'!$G$15:$I$15)/SUM('Pro Outlook 06 Jan 2026'!$G$15:$I$15) -> 11.096743 | F20: =SUMPRODUCT('Pro Outlook 06 Jan 2026'!J20:L20,'Pro Outlook 06 Jan 2026'!$J$15:$L$15)/SUM('Pro Outlook 06 Jan 2026'!$J$15:$L$15) -> 10.834204 | G20: =SUMPRODUCT('Pro Outlook 06 Jan 2026'!M20:O20,'Pro Outlook 06 Jan 2026'!$M$15:$O$15)/SUM('Pro Outlook 06 Jan 2026'!$M$15:$O$15) -> 11.781046 | H20: =SUMPRODUCT(D20:G20,$D$15:$G$15)/SUM($D$15:$G$15) -> 11.318399 | J20: =SUMPRODUCT(D15:F15,D20:F20)/H15 -> 7.4472901 | K20: 11.769361
B21: IMM-EB.MCV.LS | D21: =SUM('Pro Outlook 06 Jan 2026'!D21:F21) -> 17.998535 | E21: =SUM('Pro Outlook 06 Jan 2026'!G21:I21) -> 22.615224 | F21: =SUM('Pro Outlook 06 Jan 2026'!J21:L21) -> 0 | G21: =SUM('Pro Outlook 06 Jan 2026'!M21:O21) -> 0 | H21: =SUM(D21:G21) -> 40.613759 | K21: 13.639936
B22: CV (GAR) | D22: =SUMPRODUCT('Pro Outlook 06 Jan 2026'!D22:F22,'Pro Outlook 06 Jan 2026'!$D$21:$F$21)/SUM('Pro Outlook 06 Jan 2026'!$D$21:$F$21) -> 5860.2842 | E22: =SUMPRODUCT('Pro Outlook 06 Jan 2026'!G22:I22,'Pro Outlook 06 Jan 2026'!$G$21:$I$21)/SUM('Pro Outlook 06 Jan 2026'!$G$21:$I$21) -> 5977.0925 | F22: 0 | G22: 0 | H22: =SUMPRODUCT(D22:G22,$D$21:$G$21)/SUM($D$21:$G$21) -> 5925.3273 | J22: =SUMPRODUCT(D21:F21,D22:F22)/H21 -> 5925.3273 | K22: 5822.4314
B23: TS | D23: =SUMPRODUCT('Pro Outlook 06 Jan 2026'!D23:F23,'Pro Outlook 06 Jan 2026'!$D$21:$F$21)/SUM('Pro Outlook 06 Jan 2026'!$D$21:$F$21) -> 0.92078055 | E23: =SUMPRODUCT('Pro Outlook 06 Jan 2026'!G23:I23,'Pro Outlook 06 Jan 2026'!$G$21:$I$21)/SUM('Pro Outlook 06 Jan 2026'!$G$21:$I$21) -> 0.91930839 | F23: 0 | G23: 0 | H23: =SUMPRODUCT(D23:G23,$D$21:$G$21)/SUM($D$21:$G$21) -> 0.9199608 | J23: =SUMPRODUCT(D21:F21,D23:F23)/H21 -> 0.9199608 | K23: 0.90072278
B24: Ash | D24: =SUMPRODUCT('Pro Outlook 06 Jan 2026'!D24:F24,'Pro Outlook 06 Jan 2026'!$D$21:$F$21)/SUM('Pro Outlook 06 Jan 2026'!$D$21:$F$21) -> 7.1845522 | E24: =SUMPRODUCT('Pro Outlook 06 Jan 2026'!G24:I24,'Pro Outlook 06 Jan 2026'!$G$21:$I$21)/SUM('Pro Outlook 06 Jan 2026'!$G$21:$I$21) -> 5.8754678 | F24: 0 | G24: 0 | H24: =SUMPRODUCT(D24:G24,$D$21:$G$21)/SUM($D$21:$G$21) -> 6.4556062 | J24: =SUMPRODUCT(D21:F21,D24:F24)/H21 -> 6.4556062 | K24: 8.5977728
B25: Moist | D25: =SUMPRODUCT('Pro Outlook 06 Jan 2026'!D25:F25,'Pro Outlook 06 Jan 2026'!$D$21:$F$21)/SUM('Pro Outlook 06 Jan 2026'!$D$21:$F$21) -> 11.01636 | E25: =SUMPRODUCT('Pro Outlook 06 Jan 2026'!G25:I25,'Pro Outlook 06 Jan 2026'!$G$21:$I$21)/SUM('Pro Outlook 06 Jan 2026'!$G$21:$I$21) -> 11.460733 | F25: 0 | G25: 0 | H25: =SUMPRODUCT(D25:G25,$D$21:$G$21)/SUM($D$21:$G$21) -> 11.263803 | J25: =SUMPRODUCT(D21:F21,D25:F25)/H21 -> 11.263803 | K25: 11.354386
B26: TM | D26: =SUMPRODUCT('Pro Outlook 06 Jan 2026'!D26:F26,'Pro Outlook 06 Jan 2026'!$D$21:$F$21)/SUM('Pro Outlook 06 Jan 2026'!$D$21:$F$21) -> 14.501869 | E26: =SUMPRODUCT('Pro Outlook 06 Jan 2026'!G26:I26,'Pro Outlook 06 Jan 2026'!$G$21:$I$21)/SUM('Pro Outlook 06 Jan 2026'!$G$21:$I$21) -> 14.55176 | F26: 0 | G26: 0 | H26: =SUMPRODUCT(D26:G26,$D$21:$G$21)/SUM($D$21:$G$21) -> 14.52965 | J26: =SUMPRODUCT(D21:F21,D26:F26)/H21 -> 14.52965 | K26: 16.354386
B27: IMM-EB.MCV.MS | D27: =SUM('Pro Outlook 06 Jan 2026'!D27:F27) -> 48.098999 | E27: =SUM('Pro Outlook 06 Jan 2026'!G27:I27) -> 98.069733 | F27: =SUM('Pro Outlook 06 Jan 2026'!J27:L27) -> 165.64642 | G27: =SUM('Pro Outlook 06 Jan 2026'!M27:O27) -> 247.90675 | H27: =SUM(D27:G27) -> 559.7219 | K27: 422.71546
B28: CV (GAR) | D28: =SUMPRODUCT('Pro Outlook 06 Jan 2026'!D28:F28,'Pro Outlook 06 Jan 2026'!$D$27:$F$27)/SUM('Pro Outlook 06 Jan 2026'!$D$27:$F$27) -> 5977.8247 | E28: =SUMPRODUCT('Pro Outlook 06 Jan 2026'!G28:I28,'Pro Outlook 06 Jan 2026'!$G$27:$I$27)/SUM('Pro Outlook 06 Jan 2026'!$G$27:$I$27) -> 6012.8659 | F28: =SUMPRODUCT('Pro Outlook 06 Jan 2026'!J28:L28,'Pro Outlook 06 Jan 2026'!$J$27:$L$27)/SUM('Pro Outlook 06 Jan 2026'!$J$27:$L$27) -> 6169.8051 | G28: =SUMPRODUCT('Pro Outlook 06 Jan 2026'!M28:O28,'Pro Outlook 06 Jan 2026'!$M$27:$O$27)/SUM('Pro Outlook 06 Jan 2026'!$M$27:$O$27) -> 6135.7455 | H28: =SUMPRODUCT(D28:G28,$D$27:$G$27)/SUM($D$27:$G$27) -> 6110.7246 | J28: =SUMPRODUCT(D27:F27,D28:F28)/H27 -> 3393.138 | K28: 6013.6725
B29: TS | D29: =SUMPRODUCT('Pro Outlook 06 Jan 2026'!D29:F29,'Pro Outlook 06 Jan 2026'!$D$27:$F$27)/SUM('Pro Outlook 06 Jan 2026'!$D$27:$F$27) -> 1.4343487 | E29: =SUMPRODUCT('Pro Outlook 06 Jan 2026'!G29:I29,'Pro Outlook 06 Jan 2026'!$G$27:$I$27)/SUM('Pro Outlook 06 Jan 2026'!$G$27:$I$27) -> 1.4615114 | F29: =SUMPRODUCT('Pro Outlook 06 Jan 2026'!J29:L29,'Pro Outlook 06 Jan 2026'!$J$27:$L$27)/SUM('Pro Outlook 06 Jan 2026'!$J$27:$L$27) -> 1.5921227 | G29: =SUMPRODUCT('Pro Outlook 06 Jan 2026'!M29:O29,'Pro Outlook 06 Jan 2026'!$M$27:$O$27)/SUM('Pro Outlook 06 Jan 2026'!$M$27:$O$27) -> 1.651391 | H29: =SUMPRODUCT(D29:G29,$D$27:$G$27)/SUM($D$27:$G$27) -> 1.5819306 | J29: =SUMPRODUCT(D27:F27,D29:F29)/H27 -> 0.85051201 | K29: 1.5594733
B30: Ash | D30: =SUMPRODUCT('Pro Outlook 06 Jan 2026'!D30:F30,'Pro Outlook 06 Jan 2026'!$D$27:$F$27)/SUM('Pro Outlook 06 Jan 2026'!$D$27:$F$27) -> 6.0426735 | E30: =SUMPRODUCT('Pro Outlook 06 Jan 2026'!G30:I30,'Pro Outlook 06 Jan 2026'!$G$27:$I$27)/SUM('Pro Outlook 06 Jan 2026'!$G$27:$I$27) -> 5.6967651 | F30: =SUMPRODUCT('Pro Outlook 06 Jan 2026'!J30:L30,'Pro Outlook 06 Jan 2026'!$J$27:$L$27)/SUM('Pro Outlook 06 Jan 2026'!$J$27:$L$27) -> 4.4547575 | G30: =SUMPRODUCT('Pro Outlook 06 Jan 2026'!M30:O30,'Pro Outlook 06 Jan 2026'!$M$27:$O$27)/SUM('Pro Outlook 06 Jan 2026'!$M$27:$O$27) -> 4.70637 | H30: =SUMPRODUCT(D30:G30,$D$27:$G$27)/SUM($D$27:$G$27) -> 4.9202689 | J30: =SUMPRODUCT(D27:F27,D30:F30)/H27 -> 2.8357679 | K30: 5.3287414
B31: Moist | D31: =SUMPRODUCT('Pro Outlook 06 Jan 2026'!D31:F31,'Pro Outlook 06 Jan 2026'!$D$27:$F$27)/SUM('Pro Outlook 06 Jan 2026'!$D$27:$F$27) -> 11.610247 | E31: =SUMPRODUCT('Pro Outlook 06 Jan 2026'!G31:I31,'Pro Outlook 06 Jan 2026'!$G$27:$I$27)/SUM('Pro Outlook 06 Jan 2026'!$G$27:$I$27) -> 11.878149 | F31: =SUMPRODUCT('Pro Outlook 06 Jan 2026'!J31:L31,'Pro Outlook 06 Jan 2026'!$J$27:$L$27)/SUM('Pro Outlook 06 Jan 2026'!$J$27:$L$27) -> 11.053687 | G31: =SUMPRODUCT('Pro Outlook 06 Jan 2026'!M31:O31,'Pro Outlook 06 Jan 2026'!$M$27:$O$27)/SUM('Pro Outlook 06 Jan 2026'!$M$27:$O$27) -> 10.959276 | H31: =SUMPRODUCT(D31:G31,$D$27:$G$27)/SUM($D$27:$G$27) -> 11.204154 | J31: =SUMPRODUCT(D27:F27,D31:F31)/H27 -> 6.3501749 | K31: 10.279207
B32: TM | D32: =SUMPRODUCT('Pro Outlook 06 Jan 2026'!D32:F32,'Pro Outlook 06 Jan 2026'!$D$27:$F$27)/SUM('Pro Outlook 06 Jan 2026'!$D$27:$F$27) -> 14.141402 | E32: =SUMPRODUCT('Pro Outlook 06 Jan 2026'!G32:I32,'Pro Outlook 06 Jan 2026'!$G$27:$I$27)/SUM('Pro Outlook 06 Jan 2026'!$G$27:$I$27) -> 14.076956 | F32: =SUMPRODUCT('Pro Outlook 06 Jan 2026'!J32:L32,'Pro Outlook 06 Jan 2026'!$J$27:$L$27)/SUM('Pro Outlook 06 Jan 2026'!$J$27:$L$27) -> 13.488917 | G32: =SUMPRODUCT('Pro Outlook 06 Jan 2026'!M32:O32,'Pro Outlook 06 Jan 2026'!$M$27:$O$27)/SUM('Pro Outlook 06 Jan 2026'!$M$27:$O$27) -> 13.579427 | H32: =SUMPRODUCT(D32:G32,$D$27:$G$27)/SUM($D$27:$G$27) -> 13.688107 | J32: =SUMPRODUCT(D27:F27,D32:F32)/H27 -> 7.6736348 | K32: 15.279207
B33: IMM-EB.MCV.HS | D33: =SUM('Pro Outlook 06 Jan 2026'!D33:F33) -> 1064.4332 | E33: =SUM('Pro Outlook 06 Jan 2026'!G33:I33) -> 1174.427 | F33: =SUM('Pro Outlook 06 Jan 2026'!J33:L33) -> 1223.4824 | G33: =SUM('Pro Outlook 06 Jan 2026'!M33:O33) -> 1331.6548 | H33: =SUM(D33:G33) -> 4793.9973 | K33: 4673.6446
B34: CV (GAR) | D34: =SUMPRODUCT('Pro Outlook 06 Jan 2026'!D34:F34,'Pro Outlook 06 Jan 2026'!$D$33:$F$33)/SUM('Pro Outlook 06 Jan 2026'!$D$33:$F$33) -> 5997.3733 | E34: =SUMPRODUCT('Pro Outlook 06 Jan 2026'!G34:I34,'Pro Outlook 06 Jan 2026'!$G$33:$I$33)/SUM('Pro Outlook 06 Jan 2026'!$G$33:$I$33) -> 6013.777 | F34: =SUMPRODUCT('Pro Outlook 06 Jan 2026'!J34:L34,'Pro Outlook 06 Jan 2026'!$J$33:$L$33)/SUM('Pro Outlook 06 Jan 2026'!$J$33:$L$33) -> 6066.5872 | G34: =SUMPRODUCT('Pro Outlook 06 Jan 2026'!M34:O34,'Pro Outlook 06 Jan 2026'!$M$33:$O$33)/SUM('Pro Outlook 06 Jan 2026'!$M$33:$O$33) -> 6077.4831 | H34: =SUMPRODUCT(D34:G34,$D$33:$G$33)/SUM($D$33:$G$33) -> 6041.3086 | J34: =SUMPRODUCT(D33:F33,D34:F34)/H33 -> 4353.133 | K34: 5913.433
B35: TS | D35: =SUMPRODUCT('Pro Outlook 06 Jan 2026'!D35:F35,'Pro Outlook 06 Jan 2026'!$D$33:$F$33)/SUM('Pro Outlook 06 Jan 2026'!$D$33:$F$33) -> 2.2888209 | E35: =SUMPRODUCT('Pro Outlook 06 Jan 2026'!G35:I35,'Pro Outlook 06 Jan 2026'!$G$33:$I$33)/SUM('Pro Outlook 06 Jan 2026'!$G$33:$I$33) -> 2.3173228 | F35: =SUMPRODUCT('Pro Outlook 06 Jan 2026'!J35:L35,'Pro Outlook 06 Jan 2026'!$J$33:$L$33)/SUM('Pro Outlook 06 Jan 2026'!$J$33:$L$33) -> 2.3858692 | G35: =SUMPRODUCT('Pro Outlook 06 Jan 2026'!M35:O35,'Pro Outlook 06 Jan 2026'!$M$33:$O$33)/SUM('Pro Outlook 06 Jan 2026'!$M$33:$O$33) -> 2.2811876 | H35: =SUMPRODUCT(D35:G35,$D$33:$G$33)/SUM($D$33:$G$33) -> 2.3184507 | J35: =SUMPRODUCT(D33:F33,D35:F35)/H33 -> 1.6847928 | K35: 2.4112912
B36: Ash | D36: =SUMPRODUCT('Pro Outlook 06 Jan 2026'!D36:F36,'Pro Outlook 06 Jan 2026'!$D$33:$F$33)/SUM('Pro Outlook 06 Jan 2026'!$D$33:$F$33) -> 6.0177551 | E36: =SUMPRODUCT('Pro Outlook 06 Jan 2026'!G36:I36,'Pro Outlook 06 Jan 2026'!$G$33:$I$33)/SUM('Pro Outlook 06 Jan 2026'!$G$33:$I$33) -> 5.8290498 | F36: =SUMPRODUCT('Pro Outlook 06 Jan 2026'!J36:L36,'Pro Outlook 06 Jan 2026'!$J$33:$L$33)/SUM('Pro Outlook 06 Jan 2026'!$J$33:$L$33) -> 5.2261056 | G36: =SUMPRODUCT('Pro Outlook 06 Jan 2026'!M36:O36,'Pro Outlook 06 Jan 2026'!$M$33:$O$33)/SUM('Pro Outlook 06 Jan 2026'!$M$33:$O$33) -> 4.7631603 | H36: =SUMPRODUCT(D36:G36,$D$33:$G$33)/SUM($D$33:$G$33) -> 5.4209928 | J36: =SUMPRODUCT(D33:F33,D36:F36)/H33 -> 4.0979038 | K36: 5.7201801
B37: Moist | D37: =SUMPRODUCT('Pro Outlook 06 Jan 2026'!D37:F37,'Pro Outlook 06 Jan 2026'!$D$33:$F$33)/SUM('Pro Outlook 06 Jan 2026'!$D$33:$F$33) -> 11.358445 | E37: =SUMPRODUCT('Pro Outlook 06 Jan 2026'!G37:I37,'Pro Outlook 06 Jan 2026'!$G$33:$I$33)/SUM('Pro Outlook 06 Jan 2026'!$G$33:$I$33) -> 11.418859 | F37: =SUMPRODUCT('Pro Outlook 06 Jan 2026'!J37:L37,'Pro Outlook 06 Jan 2026'!$J$33:$L$33)/SUM('Pro Outlook 06 Jan 2026'!$J$33:$L$33) -> 11.021502 | G37: =SUMPRODUCT('Pro Outlook 06 Jan 2026'!M37:O37,'Pro Outlook 06 Jan 2026'!$M$33:$O$33)/SUM('Pro Outlook 06 Jan 2026'!$M$33:$O$33) -> 11.21464 | H37: =SUMPRODUCT(D37:G37,$D$33:$G$33)/SUM($D$33:$G$33) -> 11.247308 | J37: =SUMPRODUCT(D33:F33,D37:F37)/H33 -> 8.1321563 | K37: 10.558328
B38: TM | D38: =SUMPRODUCT('Pro Outlook 06 Jan 2026'!D38:F38,'Pro Outlook 06 Jan 2026'!$D$33:$F$33)/SUM('Pro Outlook 06 Jan 2026'!$D$33:$F$33) -> 13.608931 | E38: =SUMPRODUCT('Pro Outlook 06 Jan 2026'!G38:I38,'Pro Outlook 06 Jan 2026'!$G$33:$I$33)/SUM('Pro Outlook 06 Jan 2026'!$G$33:$I$33) -> 13.650347 | F38: =SUMPRODUCT('Pro Outlook 06 Jan 2026'!J38:L38,'Pro Outlook 06 Jan 2026'!$J$33:$L$33)/SUM('Pro Outlook 06 Jan 2026'!$J$33:$L$33) -> 13.706424 | G38: =SUMPRODUCT('Pro Outlook 06 Jan 2026'!M38:O38,'Pro Outlook 06 Jan 2026'!$M$33:$O$33)/SUM('Pro Outlook 06 Jan 2026'!$M$33:$O$33) -> 13.951108 | H38: =SUMPRODUCT(D38:G38,$D$33:$G$33)/SUM($D$33:$G$33) -> 13.739007 | J38: =SUMPRODUCT(D33:F33,D38:F38)/H33 -> 9.8637313 | K38: 15.558328
B39: Fine Coal | D39: =SUM('Pro Outlook 06 Jan 2026'!D39:F39) -> 0 | E39: =SUM('Pro Outlook 06 Jan 2026'!G39:I39) -> 0.20136899 | F39: =SUM('Pro Outlook 06 Jan 2026'!J39:L39) -> 3.1975966 | G39: =SUM('Pro Outlook 06 Jan 2026'!M39:O39) -> 2.794538 | H39: =SUM(D39:G39) -> 6.1935036 | K39: 127.5
B40: CV (GAR) | D40: 3146.0674 | E40: =SUMPRODUCT('Pro Outlook 06 Jan 2026'!G40:I40,'Pro Outlook 06 Jan 2026'!$G$39:$I$39)/SUM('Pro Outlook 06 Jan 2026'!$G$39:$I$39) -> 3980.6221 | F40: =SUMPRODUCT('Pro Outlook 06 Jan 2026'!J40:L40,'Pro Outlook 06 Jan 2026'!$J$39:$L$39)/SUM('Pro Outlook 06 Jan 2026'!$J$39:$L$39) -> 3389.4737 | G40: =SUMPRODUCT('Pro Outlook 06 Jan 2026'!M40:O40,'Pro Outlook 06 Jan 2026'!$M$39:$O$39)/SUM('Pro Outlook 06 Jan 2026'!$M$39:$O$39) -> 3165.816 | H40: =SUMPRODUCT(D40:G40,$D$39:$G$39)/SUM($D$39:$G$39) -> 3307.7782 | J40: =SUMPRODUCT(D39:F39,D40:F40)/H39 -> 1879.3471 | K40: 3146.0674
...

Sheet IMM 2025
A1: IMM 2025 Production Plan - 2nd Draft Year 2025
A3: Draft file | B3: 1st Draft 2025 OPT5 email
A4: Draft date | B4: 45576
C5: 2025
A6: Mine | B6: Unit | C6: Jan | D6: Feb | E6: Mar | F6: Apr | G6: May | H6: Jun | I6: Jul | J6: Aug | K6: Sep | L6: Oct | M6: Nov | N6: Dec | O6: Total
A7: IMM
A8: OB removal | B8: KBCM | C8: 7619.4483 | D8: 7224.3023 | E8: 6870.0231 | F8: 7815.9147 | G8: 8233.4755 | H8: 7596.8792 | I8: 8769.11 | J8: 8498.0492 | K8: 8442.1757 | L8: 8242.1086 | M8: 7836.3005 | N8: 7566.691 | O8: =SUM(C8:N8) -> 94714.478
A9: ROM production | B9: Kton | C9: 550 | D9: 545 | E9: 550 | F9: 550 | G9: 550 | H9: 550 | I9: 622.5 | J9: 637.5 | K9: 637.5 | L9: 637.5 | M9: 637.5 | N9: 632.5 | O9: =SUM(C9:N9) -> 7100 | P9: Include Fine Coal 150 KT
A10: FC production | B10: Kton | C10: 541.75 | D10: 536.75 | E10: 541.75 | F10: 551.75 | G10: 551.75 | H10: 551.75 | I10: 635.75 | J10: 637.75 | K10: 637.75 | L10: 637.75 | M10: 637.75 | N10: 637.75 | O10: =SUM(C10:N10) -> 7100 | P10: Include Fine Coal 127.5 KT
A11: SR (OB:ROM) | B11: BCM/Ton | C11: =C8/C9 -> 13.853542 | D11: =D8/D9 -> 13.255601 | E11: =E8/E9 -> 12.490951 | F11: =F8/F9 -> 14.210754 | G11: =G8/G9 -> 14.969956 | H11: =H8/H9 -> 13.812508 | I11: =I8/I9 -> 14.086924 | J11: =J8/J9 -> 13.330273 | ... O11: =O8/O9 -> 13.340067
A12: SR (OB:FC) | B12: BCM/Ton | C12: =C8/C10 -> 14.06451 | D12: =D8/D10 -> 13.459343 | E12: =E8/E10 -> 12.681169 | F12: =F8/F10 -> 14.165681 | G12: =G8/G10 -> 14.922475 | H12: =H8/H10 -> 13.768698 | I12: =I8/I10 -> 13.793331 | J12: =J8/J10 -> 13.325048 | ... O12: =O8/O10 -> 13.340067
A13: Product type
A14: IMM WB HCV LS | B14: KTon | C14: 154.9822 | D14: 150.19218 | E14: 153.44456 | F14: 142.73183 | G14: 131.89202 | H14: 90.256716 | I14: 45.052829 | J14: 60.104109 | K14: 62.623268 | L14: 73.637876 | M14: 78.465632 | N14: 85.419934 | O14: =SUM(C14:N14) -> 1228.8032
A15: CV (ADB) | B15: Kcal/kg | C15: 6419.2447 | D15: 6413.7544 | E15: 6426.1701 | F15: 6467.5963 | G15: 6460.924 | H15: 6575.6487 | I15: 6763.3802 | J15: 6738.8545 | K15: 6733.8335 | L15: 6761.7471 | M15: 6563.4722 | N15: 6582.7854 | O15: =IFERROR(SUMPRODUCT(C15:N15,$C$14:$N$14)/$O$14,0) -> 6526.4022
A16: CV (GAR) | B16: Kcal/kg | C16: 6066.6995 | D16: 6061.099 | E16: 6072.9614 | F16: 6113.1737 | G16: 6106.3251 | H16: 6216.0563 | I16: 6397.4706 | J16: 6374.5335 | K16: 6369.463 | L16: 6395.7374 | M16: 6207.9868 | N16: 6224.9984 | O16: =IFERROR(SUMPRODUCT(C16:N16,$C$14:$N$14)/$O$14,0) -> 6169.7769
A17: TS | B17: % | C17: 0.79938883 | D17: 0.79960479 | E17: 0.80630914 | F17: 0.80238321 | G17: 0.79513307 | H17: 0.79813522 | I17: 0.8000568 | J17: 0.80071014 | K17: 0.80424058 | L17: 0.87778388 | M17: 0.89103139 | N17: 0.79704817 | O17: =IFERROR(SUMPRODUCT(C17:N17,$C$14:$N$14)/$O$14,0) -> 0.81080181
A18: Ash | B18: % | C18: 8.5931913 | D18: 8.5723462 | E18: 8.4652505 | F18: 8.3496537 | G18: 8.4544991 | H18: 8.0611616 | I18: 8.0877488 | J18: 8.0139288 | K18: 8.093906 | L18: 8.3113445 | M18: 8.6583469 | N18: 8.1211956 | O18: =IFERROR(SUMPRODUCT(C18:N18,$C$14:$N$14)/$O$14,0) -> 8.3745645
A19: IM | B19: % | C19: 8.4967581 | D19: 8.6035878 | E19: 8.5701167 | F19: 8.295887 | G19: 8.4360236 | H19: 8.1042227 | I19: 7.1124623 | J19: 7.0457455 | K19: 7.1276119 | L19: 7.1603037 | M19: 7.2146756 | N19: 7.5402791 | O19: =IFERROR(SUMPRODUCT(C19:N19,$C$14:$N$14)/$O$14,0) -> 8.0403443
A20: TM | B20: % | C20: 13.52212 | D20: 13.62895 | E20: 13.595479 | F20: 13.321249 | G20: 13.461386 | H20: 13.129585 | I20: 12.137825 | J20: 12.071108 | K20: 12.152974 | L20: 12.185666 | M20: 12.240038 | N20: 12.565641 | O20: =IFERROR(SUMPRODUCT(C20:N20,$C$14:$N$14)/$O$14,0) -> 13.065707
A21: IMM WB HCV HS | B21: KTon | C21: 37.517805 | D21: 37.307818 | E21: 39.055444 | F21: 47.268165 | G21: 53.10798 | H21: 64.743284 | I21: 84.947171 | J21: 74.895891 | K21: 82.376732 | L21: 36.362124 | M21: 41.534368 | N21: 34.580066 | O21: =SUM(C21:N21) -> 633.69685
A22: CV (ADB) | B22: Kcal/kg | C22: 6334.2014 | D22: 6447.6669 | E22: 6352.6384 | F22: 6292.9167 | G22: 6234.5184 | H22: 6241.3054 | I22: 6292.6616 | J22: 6274.0003 | K22: 6337.0578 | L22: 6315.7415 | M22: 6317.778 | N22: 6314.7744 | O22: =IFERROR(SUMPRODUCT(C22:N22,$C$21:$N$21)/$O$21,0) -> 6305.5853
A23: CV (GAR) | B23: Kcal/kg | C23: 5995.4058 | D23: 6102.8668 | E23: 6012.8803 | F23: 5956.2491 | G23: 5900.982 | H23: 5903.8514 | I23: 5953.1501 | J23: 5935.2903 | K23: 5994.0694 | L23: 5972.607 | M23: 5974.5067 | N23: 5973.0938 | O23: =IFERROR(SUMPRODUCT(C23:N23,$C$21:$N$21)/$O$21,0) -> 5965.7827
A24: TS | B24: % | C24: 2.4295613 | D24: 2.4050655 | E24: 2.5318666 | F24: 2.5966145 | G24: 2.6452674 | H24: 2.7646957 | I24: 2.7577905 | J24: 2.7055365 | K24: 2.6431822 | L24: 2.4886633 | M24: 2.3842149 | N24: 1.9721835 | O24: =IFERROR(SUMPRODUCT(C24:N24,$C$21:$N$21)/$O$21,0) -> 2.5790489
A25: Ash | B25: % | C25: 13.650338 | D25: 13.07266 | E25: 13.53618 | F25: 14.197739 | G25: 14.74821 | H25: 14.555829 | I25: 13.682949 | J25: 14.42353 | K25: 13.830267 | L25: 13.802136 | M25: 13.963262 | N25: 13.239605 | O25: =IFERROR(SUMPRODUCT(C25:N25,$C$21:$N$21)/$O$21,0) -> 13.960595
A26: IM | B26: % | C26: 6.0446714 | D26: 6.0271092 | E26: 6.0381378 | F26: 6.0670306 | G26: 6.0650682 | H26: 7.0545207 | I26: 6.8576285 | J26: 6.9141156 | K26: 7.151348 | L26: 7.5030578 | M26: 7.5101273 | N26: 7.1237139 | O26: =IFERROR(SUMPRODUCT(C26:N26,$C$21:$N$21)/$O$21,0) -> 6.7439986
A27: TM | B27: % | C27: 11.070034 | D27: 11.052472 | E27: 11.0635 | F27: 11.092393 | G27: 11.090431 | H27: 12.079883 | I27: 11.882991 | J27: 11.939478 | K27: 12.17671 | L27: 12.52842 | M27: 12.53549 | N27: 12.149076 | O27: =IFERROR(SUMPRODUCT(C27:N27,$C$21:$N$21)/$O$21,0) -> 11.769361
A28: IMM EB MCV LS | B28: KTon | C28: 3.3845713 | D28: 2.1986171 | E28: 2.3031178 | F28: 2.767207 | G28: 1.8758652 | H28: 1.1105575 | I28: 0 | J28: 0 | K28: 0 | L28: 0 | M28: 0 | N28: 0 | O28: =SUM(C28:N28) -> 13.639936
A29: CV (ADB) | B29: Kcal/kg | C29: 6169.8029 | D29: 6164.1006 | E29: 6172.431 | F29: 6174.4728 | G29: 6169.8042 | H29: 6172.235 | I29: 0 | J29: 0 | K29: 0 | L29: 0 | M29: 0 | N29: 0 | O29: =IFERROR(SUMPRODUCT(C29:N29,$C$28:$N$28)/$O$28,0) -> 6170.4731
A30: CV (GAR) | B30: Kcal/kg | C30: 5821.883 | D30: 5816.4871 | E30: 5824.2204 | F30: 5826.2223 | G30: 5821.6228 | H30: 5824.0809 | I30: 0 | J30: 0 | K30: 0 | L30: 0 | M30: 0 | N30: 0 | O30: =IFERROR(SUMPRODUCT(C30:N30,$C$28:$N$28)/$O$28,0) -> 5822.4314
A31: TS | B31: % | C31: 0.89812632 | D31: 0.89994494 | E31: 0.90129647 | F31: 0.90153154 | G31: 0.90292127 | H31: 0.90325732 | I31: 0 | J31: 0 | K31: 0 | L31: 0 | M31: 0 | N31: 0 | O31: =IFERROR(SUMPRODUCT(C31:N31,$C$28:$N$28)/$O$28,0) -> 0.90072278
A32: Ash | B32: % | C32: 8.6642459 | D32: 8.6537904 | E32: 8.6423873 | F32: 8.5289327 | G32: 8.5159535 | H32: 8.5014972 | I32: 0 | J32: 0 | K32: 0 | L32: 0 | M32: 0 | N32: 0 | O32: =IFERROR(SUMPRODUCT(C32:N32,$C$28:$N$28)/$O$28,0) -> 8.5977728
A33: IM | B33: % | C33: 11.332981 | D33: 11.336869 | E33: 11.369268 | F33: 11.350128 | G33: 11.399581 | H33: 11.357707 | I33: 0 | J33: 0 | K33: 0 | L33: 0 | M33: 0 | N33: 0 | O33: =IFERROR(SUMPRODUCT(C33:N33,$C$28:$N$28)/$O$28,0) -> 11.354386
A34: TM | B34: % | C34: 16.332981 | D34: 16.336869 | E34: 16.369268 | F34: 16.350128 | G34: 16.399581 | H34: 16.357707 | I34: 0 | J34: 0 | K34: 0 | L34: 0 | M34: 0 | N34: 0 | O34: =IFERROR(SUMPRODUCT(C34:N34,$C$28:$N$28)/$O$28,0) -> 16.354386
A35: IMM EB MCV MS | B35: KTon | C35: 2.5218825 | D35: 7.2154786 | E35: 26.720101 | F35: 6.3272233 | G35: 12.630174 | H35: 4.8087851 | I35: 12.094951 | J35: 14.998053 | K35: 83.697273 | L35: 94.400599 | M35: 71.33532 | N35: 85.965624 | O35: =SUM(C35:N35) -> 422.71546
A36: CV (ADB) | B36: Kcal/kg | C36: 6368.0243 | D36: 6310.0428 | E36: 6367.3626 | F36: 6390.1986 | G36: 6342.5849 | H36: 6357.9317 | I36: 6392.812 | J36: 6360.8597 | K36: 6350.9993 | L36: 6367.4084 | M36: 6382.1767 | N36: 6381.7919 | O36: =IFERROR(SUMPRODUCT(C36:N36,$C$35:$N$35)/$O$35,0) -> 6368.5845
A37: CV (GAR) | B37: Kcal/kg | C37: 6013.744 | D37: 5958.5719 | E37: 6011.5142 | F37: 6033.7912 | G37: 5987.1311 | H37: 6002.8141 | I37: 6036.2059 | J37: 6005.6296 | K37: 5996.4183 | L37: 6012.5832 | M37: 6026.6617 | N37: 6027.4417 | O37: =IFERROR(SUMPRODUCT(C37:N37,$C$35:$N$35)/$O$35,0) -> 6013.6725
A38: TS | B38: % | C38: 1.5719259 | D38: 1.5704928 | E38: 1.5645055 | F38: 1.5541281 | G38: 1.5514426 | H38: 1.5490809 | I38: 1.5706205 | J38: 1.5667221 | K38: 1.5492652 | L38: 1.553251 | M38: 1.5598162 | N38: 1.5724278 | O38: =IFERROR(SUMPRODUCT(C38:N38,$C$35:$N$35)/$O$35,0) -> 1.5594733
A39: Ash | B39: % | C39: 6.0748082 | D39: 6.153097 | E39: 6.1792076 | F39: 5.197632 | G39: 5.2945573 | H39: 5.236934 | I39: 5.1052577 | J39: 5.3674075 | K39: 5.3569251 | L39: 5.169691 | M39: 5.1649103 | N39: 5.3009891 | O39: =IFERROR(SUMPRODUCT(C39:N39,$C$35:$N$35)/$O$35,0) -> 5.3287414
A40: Moist | B40: % | C40: 10.127325 | D40: 10.233784 | E40: 10.532647 | F40: 10.3526 | G40: 10.781854 | H40: 10.481305 | I40: 10.365903 | J40: 10.468448 | K40: 10.443604 | L40: 10.274018 | M40: 10.240397 | N40: 9.9507726 | O40: =IFERROR(SUMPRODUCT(C40:N40,$C$35:$N$35)/$O$35,0) -> 10.279207
A41: TM | B41: % | C41: 15.127325 | D41: 15.233784 | E41: 15.532647 | F41: 15.3526 | G41: 15.781854 | H41: 15.481305 | I41: 15.365903 | J41: 15.468448 | K41: 15.443604 | L41: 15.274018 | M41: 15.240397 | N41: 14.950773 | O41: =IFERROR(SUMPRODUCT(C41:N41,$C$35:$N$35)/$O$35,0) -> 15.279207
...

Sheet TCM 2025
A1: TCM 2025 Production Plan - 2nd Draft
A3: Draft file | B3: Draft Production Plan Year 2025 TCM (12 Oct 2024)_V2.1
A4: Draft date | B4: 45577
C5: 2025
A6: Mine | B6: Unit | C6: Jan | D6: Feb | E6: Mar | F6: Apr | G6: May | H6: Jun | I6: Jul | J6: Aug | K6: Sep | L6: Oct | M6: Nov | N6: Dec | O6: Total
A7: TCM
A8: OB removal | B8: KBCM | C8: 4195 | D8: 4015 | E8: 4020 | F8: 4250 | G8: 4410 | H8: 4660 | I8: 4720 | J8: 5055 | K8: 4740 | L8: 3990 | M8: 3805 | N8: 3790 | O8: =SUM(C8:N8) -> 51650
A9: ROM production | B9: Kton | C9: 200 | D9: 215 | E9: 217 | F9: 255 | G9: 285 | H9: 315 | I9: 310 | J9: 335.38697 | K9: 307 | L9: 300 | M9: 281 | N9: 280 | O9: =SUM(C9:N9) -> 3300.387
A10: FC production | B10: Kton | C10: =SUM(C14,C21,C28) -> 217 | D10: =SUM(D14,D21,D28) -> 235 | E10: =SUM(E14,E21,E28) -> 258 | F10: =SUM(F14,F21,F28) -> 257 | G10: =SUM(G14,G21,G28) -> 290 | H10: =SUM(H14,H21,H28) -> 305 | I10: =SUM(I14,I21,I28) -> 315 | J10: =SUM(J14,J21,J28) -> 320 | ... N10: =SUM(N14,N21,N28) -> 253 | O10: =SUM(C10:N10) -> 3230
A11: SR (OB:ROM) | B11: BCM/Ton | C11: =C8/C9 -> 20.975 | D11: =D8/D9 -> 18.674419 | E11: =E8/E9 -> 18.525346 | F11: =F8/F9 -> 16.666667 | G11: =G8/G9 -> 15.473684 | H11: =H8/H9 -> 14.793651 | I11: =I8/I9 -> 15.225806 | J11: =J8/J9 -> 15.072142 | ... O11: =O8/O9 -> 15.64968
A12: SR (OB:FC) | B12: BCM/Ton | C12: =C8/C10 -> 19.331797 | D12: =D8/D10 -> 17.085106 | E12: =E8/E10 -> 15.581395 | F12: =F8/F10 -> 16.536965 | G12: =G8/G10 -> 15.206897 | H12: =H8/H10 -> 15.278689 | I12: =I8/I10 -> 14.984127 | J12: =J8/J10 -> 15.796875 | ... O12: =O8/O10 -> 15.990712
A13: Product type
A14: TCM HCV LS | B14: KTon | C14: 110 | D14: 130 | E14: 130 | F14: 140 | G14: 150 | H14: 170 | I14: 170 | J14: 150 | K14: 155 | L14: 115 | M14: 115 | N14: 95 | O14: =SUM(C14:N14) -> 1630 | Q14: =O14/O10 -> 0.50464396
A15: CV (ADB) | B15: Kcal/kg | C15: 6736.8284 | D15: 6845.675 | E15: 6855.2974 | F15: 6799.3995 | G15: 6851.0847 | H15: 6896.7899 | I15: 6784.1768 | J15: 6817.3511 | K15: 6897.6838 | L15: 6835.9324 | M15: 6832.8721 | N15: 6795.1116 | O15: =IFERROR(SUMPRODUCT(C15:N15,$C$14:$N$14)/$O$14,0) -> 6832.3388
A16: CV (GAR) | B16: Kcal/kg | C16: 6331.7794 | D16: 6327.6426 | E16: 6345.3425 | F16: 6327.8237 | G16: 6373.2296 | H16: 6243.3002 | I16: 6268.7387 | J16: 6402.2298 | K16: 6455.744 | L16: 6429.1851 | M16: 6453.9309 | N16: 6360.7189 | O16: =IFERROR(SUMPRODUCT(C16:N16,$C$14:$N$14)/$O$14,0) -> 6355.6513
A17: TS | B17: % | C17: 0.63238992 | D17: 0.69248101 | E17: 0.65200146 | F17: 0.65479545 | G17: 0.61486788 | H17: 0.63759554 | I17: 0.63464407 | J17: 0.55063001 | K17: 0.52383377 | L17: 0.52785903 | M17: 0.54698263 | N17: 0.54360501 | O17: =IFERROR(SUMPRODUCT(C17:N17,$C$14:$N$14)/$O$14,0) -> 0.60341466
A18: Ash | B18: % | C18: 5.1400008 | D18: 4.5591191 | E18: 4.5963271 | F18: 5.123741 | G18: 4.8279056 | H18: 4.5406009 | I18: 5.4694098 | J18: 4.9514041 | K18: 4.2318464 | L18: 4.7988367 | M18: 4.9300384 | N18: 4.9975468 | O18: =IFERROR(SUMPRODUCT(C18:N18,$C$14:$N$14)/$O$14,0) -> 4.8411374
A19: IM | B19: % | C19: 7.9684127 | D19: 7.5073713 | E19: 7.3053122 | F19: 7.3141874 | G19: 7.2934236 | H19: 7.0845272 | I19: 7.3044097 | J19: 7.5575721 | K19: 7.1826946 | L19: 7.4774674 | M19: 7.32496 | N19: 7.623105 | O19: =IFERROR(SUMPRODUCT(C19:N19,$C$14:$N$14)/$O$14,0) -> 7.3863318
A20: TM | B20: % | C20: 13.501774 | D20: 14.506561 | E20: 14.200726 | F20: 13.742458 | G20: 13.759599 | H20: 15.888522 | I20: 14.347097 | J20: 13.186565 | K20: 13.12957 | L20: 12.982685 | M20: 12.464583 | N20: 13.528504 | O20: =IFERROR(SUMPRODUCT(C20:N20,$C$14:$N$14)/$O$14,0) -> 13.846499
A21: TCM HCV HS | B21: KTon | C21: 100 | D21: 100 | E21: 120 | F21: 110 | G21: 130 | H21: 120 | I21: 130 | J21: 150 | K21: 120 | L21: 130 | M21: 120 | N21: 150 | O21: =SUM(C21:N21) -> 1480 | Q21: =O21/O10 -> 0.45820433
A22: CV (ADB) | B22: Kcal/kg | C22: 6866.5729 | D22: 6778.7713 | E22: 6894.8648 | F22: 6822.1779 | G22: 6836.7655 | H22: 6757.1099 | I22: 6815.116 | J22: 6823.9609 | K22: 6790.9747 | L22: 6843.9084 | M22: 6814.7913 | N22: 6804.9311 | O22: =IFERROR(SUMPRODUCT(C22:N22,$C$21:$N$21)/$O$21,0) -> 6820.7361
A23: CV (GAR) | B23: Kcal/kg | C23: 6528.8013 | D23: 6523.441 | E23: 6602.1856 | F23: 6481.0855 | G23: 6487.5274 | H23: 6515.5714 | I23: 6445.0323 | J23: 6472.1448 | K23: 6412.4032 | L23: 6476.7335 | M23: 6460.6228 | N23: 6423.2952 | O23: =IFERROR(SUMPRODUCT(C23:N23,$C$21:$N$21)/$O$21,0) -> 6482.812
A24: TS | B24: % | C24: 1.841903 | D24: 2.1453577 | E24: 1.7213437 | F24: 1.7720411 | G24: 1.7757748 | H24: 2.0870683 | I24: 1.8137934 | J24: 1.8286935 | K24: 1.8482141 | L24: 1.8968174 | M24: 1.8190294 | N24: 1.9904989 | O24: =IFERROR(SUMPRODUCT(C24:N24,$C$21:$N$21)/$O$21,0) -> 1.8762421
A25: Ash | B25: % | C25: 6.7257046 | D25: 7.6729169 | E25: 55.965647 | F25: 5.9370559 | G25: 5.2917713 | H25: 7.3265169 | I25: 5.9374766 | J25: 5.9831574 | K25: 6.0080332 | L25: 6.0190798 | M25: 6.0931432 | N25: 5.9789559 | O25: =IFERROR(SUMPRODUCT(C25:N25,$C$21:$N$21)/$O$21,0) -> 10.254553
A26: IM | B26: % | C26: 7.2396068 | D26: 7.1179754 | E26: 6.7065054 | F26: 6.8833178 | G26: 6.7128751 | H26: 6.6876777 | I26: 6.6455047 | J26: 6.3583255 | K26: 6.7263938 | L26: 6.4663362 | M26: 6.2063256 | N26: 6.1537235 | O26: =IFERROR(SUMPRODUCT(C26:N26,$C$21:$N$21)/$O$21,0) -> 6.6257918
A27: TM | B27: % | C27: 11.802557 | D27: 10.616485 | E27: 10.666708 | F27: 11.538927 | G27: 11.478201 | H27: 10.023203 | I27: 11.714968 | J27: 11.186115 | K27: 11.926049 | L27: 11.484406 | M27: 11.080835 | N27: 11.416834 | O27: =IFERROR(SUMPRODUCT(C27:N27,$C$21:$N$21)/$O$21,0) -> 11.252249
A28: TCM.LCV.MS.HA | B28: KTon | C28: 7 | D28: 5 | E28: 8 | F28: 7 | G28: 10 | H28: 15 | I28: 15 | J28: 20 | K28: 10 | L28: 8 | M28: 7 | N28: 8 | O28: =SUM(C28:N28) -> 120 | Q28: =O28/O10 -> 0.037151703
A29: CV (ADB) | B29: Kcal/kg | C29: 3851.3 | D29: 3874.3 | E29: 4709.15 | F29: 3863.65 | G29: 3953.65 | H29: 6126.55 | I29: 6034.4 | J29: 5942.25 | K29: 5918.25 | L29: 5969.25 | M29: 5910.25 | N29: 5938.25 | O29: =IFERROR(SUMPRODUCT(C29:N29,$C$28:$N$28)/$O$28,0) -> 5397.1613
A30: CV (GAR) | B30: Kcal/kg | C30: 3581.7631 | D30: 3599.0009 | E30: 4341.3047 | F30: 3587.2263 | G30: 3651.2002 | H30: 5641.0449 | I30: 5567.1958 | J30: 5442.6121 | K30: 5422.5222 | L30: 5471.7948 | M30: 5388.109 | N30: 5438.9485 | O30: =IFERROR(SUMPRODUCT(C30:N30,$C$28:$N$28)/$O$28,0) -> 4963.5346
A31: TS | B31: % | C31: 1.16 | D31: 1.15 | E31: 1.44 | F31: 0.51 | G31: 0.5 | H31: 1.45 | I31: 1.5216667 | J31: 1.5933333 | K31: 1.6133333 | L31: 1.5833333 | M31: 1.5533333 | N31: 1.6133333 | O31: =IFERROR(SUMPRODUCT(C31:N31,$C$28:$N$28)/$O$28,0) -> 1.3581806
A32: Ash | B32: % | C32: 13.6 | D32: 13.18 | E32: 12.69 | F32: 14.445 | G32: 14.2 | H32: 6.835 | I32: 8.9933333 | J32: 11.151667 | K32: 11.141667 | L32: 11.011667 | M32: 11.171667 | N32: 11.981667 | O32: =IFERROR(SUMPRODUCT(C32:N32,$C$28:$N$28)/$O$28,0) -> 11.164653
A33: IM | B33: % | C33: 7.41 | D33: 7.54 | E33: 7.16 | F33: 6.52 | G33: 6.43 | H33: 6.09 | I33: 6.1266667 | J33: 6.1633333 | K33: 6.1633333 | L33: 6.1633333 | M33: 6.1633333 | N33: 6.1633333 | O33: =IFERROR(SUMPRODUCT(C33:N33,$C$28:$N$28)/$O$28,0) -> 6.3891389
A34: TM | B34: % | C34: 13.89 | D34: 14.11 | E34: 14.412 | F34: 13.208 | G34: 13.588 | H34: 13.532 | I34: 13.394667 | J34: 14.053333 | K34: 14.023333 | L34: 13.983333 | M34: 14.453333 | N34: 14.053333 | O34: =IFERROR(SUMPRODUCT(C34:N34,$C$28:$N$28)/$O$28,0) -> 13.850656

Sheet BEK 2025
A1: BEK 2025 Production Plan - 2nd Draft
A3: Draft file | B3: 00. BEK Production Budget Y25_ver2.2_08Oct24_rwsp
A4: Draft date | B4: 45573
C5: 2025
A6: Mine | B6: Unit | C6: Jan | D6: Feb | E6: Mar | F6: Apr | G6: May | H6: Jun | I6: Jul | J6: Aug | K6: Sep | L6: Oct | M6: Nov | N6: Dec | O6: Total
A7: BEK
A8: OB removal | B8: KBCM | C8: 7995 | D8: 7084 | E8: 7619 | F8: 7232 | G8: 7571 | H8: 7593 | I8: 8097 | J8: 8330 | K8: 7698 | L8: 7482 | M8: 6860 | N8: 7389 | O8: =SUM(C8:N8) -> 90950
A9: ROM production | B9: Kton | C9: 684 | D9: 658 | E9: 685.5 | F9: 564 | G9: 663 | H9: 712 | I9: 745 | J9: 752 | K9: 704 | L9: 627.5 | M9: 589 | N9: 616 | O9: =SUM(C9:N9) -> 8000
A10: FC production | B10: Kton | C10: 700 | D10: 700 | E10: 700 | F10: 650 | G10: 650 | H10: 650 | I10: 700 | J10: 710 | K10: 700 | L10: 660 | M10: 640 | N10: 640 | O10: =SUM(C10:N10) -> 8100
A11: SR (OB:ROM) | B11: BCM/Ton | C11: =C8/C9 -> 11.688596 | D11: =D8/D9 -> 10.765957 | E11: =E8/E9 -> 11.114515 | F11: =F8/F9 -> 12.822695 | G11: =G8/G9 -> 11.419306 | H11: =H8/H9 -> 10.664326 | I11: =I8/I9 -> 10.868456 | J11: =J8/J9 -> 11.077128 | ... O11: =O8/O9 -> 11.36875
A12: SR (OB:FC) | B12: BCM/Ton | C12: =C8/C10 -> 11.421429 | D12: =D8/D10 -> 10.12 | E12: =E8/E10 -> 10.884286 | F12: =F8/F10 -> 11.126154 | G12: =G8/G10 -> 11.647692 | H12: =H8/H10 -> 11.681538 | I12: =I8/I10 -> 11.567143 | J12: =J8/J10 -> 11.732394 | ... O12: =O8/O10 -> 11.228395
A13: Product type
A14: BEK MCV LS | B14: KTon | C14: 400 | D14: 480 | E14: 480 | F14: 465 | G14: 465 | H14: 460 | I14: 500 | J14: 490 | K14: 480 | L14: 460 | M14: 440 | N14: 440 | O14: =SUM(C14:N14) -> 5560
A15: CV (ADB) | B15: Kcal/kg | C15: 6356.6925 | D15: 6211.4538 | E15: 6164.5544 | F15: 6166.0095 | G15: 6215.11 | H15: 6171.0497 | I15: 6202.3209 | J15: 6155.9114 | K15: 6139.5186 | L15: 6134.6756 | M15: 6109.9273 | N15: 6139.0823 | O15: =IFERROR(SUMPRODUCT(C15:N15,$C$14:$N$14)/$O$14,0) -> 6178.9758
A16: CV (GAR) | B16: Kcal/kg | C16: 6030.4358 | D16: 5774.2277 | E16: 5860.9708 | F16: 5868.1864 | G16: 5954.6027 | H16: 5916.1255 | I16: 5984.187 | J16: 5944.3266 | K16: 5921.0085 | L16: 5916.7362 | M16: 5898.291 | N16: 5928.9325 | O16: =IFERROR(SUMPRODUCT(C16:N16,$C$14:$N$14)/$O$14,0) -> 5915.2264
A17: TS | B17: % | C17: 0.53158467 | D17: 0.52888777 | E17: 0.51140211 | F17: 0.47876764 | G17: 0.51889296 | H17: 0.54684188 | I17: 0.61559945 | J17: 0.6516434 | K17: 0.57082929 | L17: 0.61027739 | M17: 0.68842584 | N17: 0.67517043 | O17: =IFERROR(SUMPRODUCT(C17:N17,$C$14:$N$14)/$O$14,0) -> 0.57720242
A18: Ash | B18: % | C18: 4.5798127 | D18: 4.3819201 | E18: 4.705923 | F18: 4.7159272 | G18: 4.4700417 | H18: 4.6727263 | I18: 5.1675001 | J18: 5.2806867 | K18: 5.376416 | L18: 5.2082429 | M18: 4.9554985 | N18: 5.0376143 | O18: =IFERROR(SUMPRODUCT(C18:N18,$C$14:$N$14)/$O$14,0) -> 4.8848466
A19: IM | B19: % | C19: 11.53253 | D19: 12.161692 | E19: 11.768774 | F19: 10.98217 | G19: 11.996305 | H19: 11.373388 | I19: 10.851381 | J19: 11.259922 | K19: 11.128284 | L19: 11.312912 | M19: 11.810254 | N19: 11.519677 | O19: =IFERROR(SUMPRODUCT(C19:N19,$C$14:$N$14)/$O$14,0) -> 11.469447
A20: TM | B20: % | C20: 16.073116 | D20: 18.344658 | E20: 16.113866 | F20: 15.2818 | G20: 15.684993 | H20: 15.034526 | I20: 13.986713 | J20: 14.310007 | K20: 14.291295 | L20: 14.463594 | M20: 14.864979 | N20: 14.548488 | O20: =IFERROR(SUMPRODUCT(C20:N20,$C$14:$N$14)/$O$14,0) -> 15.241913
A21: BEK MCV MS | B21: KTon | C21: 300 | D21: 220 | E21: 220 | F21: 185 | G21: 185 | H21: 190 | I21: 200 | J21: 220 | K21: 220 | L21: 200 | M21: 200 | N21: 200 | O21: =SUM(C21:N21) -> 2540
A22: CV (ADB) | B22: Kcal/kg | C22: 6236.9634 | D22: 6049.986 | E22: 6043.243 | F22: 6018.0484 | G22: 5964.0677 | H22: 5984.9901 | I22: 5967.3108 | J22: 6020.9507 | K22: 6068.0016 | L22: 6040.4014 | M22: 5983.9188 | N22: 6135.5256 | O22: =IFERROR(SUMPRODUCT(C22:N22,$C$21:$N$21)/$O$21,0) -> 6051.3543
A23: CV (GAR) | B23: Kcal/kg | C23: 5978.3055 | D23: 5788.4874 | E23: 5780.4749 | F23: 5757.1239 | G23: 5689.0306 | H23: 5723.4269 | I23: 5710.0663 | J23: 5767.3036 | K23: 5816.7184 | L23: 5783.944 | M23: 5714.3882 | N23: 5899.7671 | O23: =IFERROR(SUMPRODUCT(C23:N23,$C$21:$N$21)/$O$21,0) -> 5792.8232
A24: TS | B24: % | C24: 1.7870244 | D24: 1.8050808 | E24: 1.7534847 | F24: 1.753 | G24: 1.7123074 | H24: 1.7853721 | I24: 1.8238816 | J24: 1.741996 | K24: 1.7014005 | L24: 1.760588 | M24: 1.7678142 | N24: 1.7232917 | O24: =IFERROR(SUMPRODUCT(C24:N24,$C$21:$N$21)/$O$21,0) -> 1.7606128
A25: Ash | B25: % | C25: 4.7301045 | D25: 5.5271121 | E25: 5.5457883 | F25: 5.7432541 | G25: 6.1338157 | H25: 6.4531615 | I25: 6.4437426 | J25: 6.2121469 | K25: 5.7608226 | L25: 5.8895184 | M25: 6.1089249 | N25: 5.11197 | O25: =IFERROR(SUMPRODUCT(C25:N25,$C$21:$N$21)/$O$21,0) -> 5.7572097
A26: IM | B26: % | C26: 11.089448 | D26: 10.939008 | E26: 11.103271 | F26: 10.753088 | G26: 10.931757 | H26: 10.542872 | I26: 10.9263 | J26: 10.532728 | K26: 10.519639 | L26: 10.608982 | M26: 10.409757 | N26: 10.300642 | O26: =IFERROR(SUMPRODUCT(C26:N26,$C$21:$N$21)/$O$21,0) -> 10.736864
A27: TM | B27: % | C27: 14.776726 | D27: 14.788492 | E27: 14.968616 | F27: 14.622566 | G27: 15.039201 | H27: 14.452435 | I27: 14.766174 | J27: 14.301753 | K27: 14.225128 | L27: 14.404258 | M27: 14.445125 | N27: 13.747354 | O27: =IFERROR(SUMPRODUCT(C27:N27,$C$21:$N$21)/$O$21,0) -> 14.551759

Sheet JBG 2025
A1: JBG 2025 Production Plan - 2nd draft
A3: Draft file | B3: JBG Production Budget 2025 update 16112024
A4: Draft date | B4: 45612
C5: 2025
A6: Mine | B6: Unit | C6: Jan | D6: Feb | E6: Mar | F6: Apr | G6: May | H6: Jun | I6: Jul | J6: Aug | K6: Sep | L6: Oct | M6: Nov | N6: Dec | O6: Total
A7: JBG
A8: OB removal | B8: KBCM | C8: 103.007 | D8: 93.07 | E8: 98.059 | F8: 280.6245 | G8: 579.3785 | H8: 448.889 | I8: 536.383 | J8: 575.345 | K8: 590.094 | L8: 632.103 | M8: 557.72 | N8: 543.935 | O8: =SUM(C8:N8) -> 5038.608
A9: ROM production | B9: Kton | C9: 0 | D9: 0 | E9: 0 | F9: 0 | G9: 20 | H9: 37 | I9: 51 | J9: 60 | K9: 70 | L9: 75 | M9: 68 | N9: 67 | O9: =SUM(C9:N9) -> 448
A10: FC production | B10: Kton | C10: 0 | D10: 0 | E10: 0 | F10: 0 | G10: 18 | H10: 35 | I10: 50 | J10: 58 | K10: 68 | L10: 72 | M10: 66 | N10: 66 | O10: =SUM(C10:N10) -> 433
A11: SR (OB:ROM) | B11: BCM/Ton | C11: =C8/C9 -> #DIV/0! | D11: =D8/D9 -> #DIV/0! | E11: =E8/E9 -> #DIV/0! | F11: =F8/F9 -> #DIV/0! | G11: =G8/G9 -> 28.968925 | H11: =H8/H9 -> 12.132135 | I11: =I8/I9 -> 10.517314 | J11: =J8/J9 -> 9.5890833 | ... N11: =N8/N9 -> 8.1184328 | O11: =IFERROR(O8/O9,0) -> 11.246893
A12: SR (OB:FC) | B12: BCM/Ton | C12: =C8/C10 -> #DIV/0! | D12: =D8/D10 -> #DIV/0! | E12: =E8/E10 -> #DIV/0! | F12: =F8/F10 -> #DIV/0! | G12: =G8/G10 -> 32.187694 | H12: =H8/H10 -> 12.8254 | I12: =I8/I10 -> 10.72766 | J12: =J8/J10 -> 9.9197414 | ... O12: =O8/O10 -> 11.636508
A13: Product type
A14: JBG | B14: KTon | C14: =C10 -> 0 | D14: =D10 -> 0 | E14: =E10 -> 0 | F14: =F10 -> 0 | G14: =G10 -> 18 | H14: =H10 -> 35 | I14: =I10 -> 50 | J14: =J10 -> 58 | ... N14: =N10 -> 66 | O14: =SUM(C14:N14) -> 433
A15: CV (ADB) | B15: Kcal/kg | C15: 0 | D15: 0 | E15: 0 | F15: 0 | G15: 5253.8295 | H15: 5240.7986 | I15: 5259.589 | J15: 5280.4872 | K15: 5246.6256 | L15: 5280.3769 | M15: 5298.5008 | N15: 5258.6221 | O15: =IFERROR(SUMPRODUCT(C15:N15,$C$14:$N$14)/$O$14,0) -> 5267.8346
A16: CV (GAR) | B16: Kcal/kg | C16: 0 | D16: 0 | E16: 0 | F16: 0 | G16: 4442.3525 | H16: 4414.0197 | I16: 4416.3842 | J16: 4432.5862 | K16: 4408.926 | L16: 4423.0872 | M16: 4453.786 | N16: 4407.9045 | O16: =IFERROR(SUMPRODUCT(C16:N16,$C$14:$N$14)/$O$14,0) -> 4423.7946
A17: TS | B17: % | C17: 0 | D17: 0 | E17: 0 | F17: 0 | G17: 0.38873573 | H17: 0.35403485 | I17: 0.38863712 | J17: 0.37485739 | K17: 0.36433237 | L17: 0.35476496 | M17: 0.35693132 | N17: 0.38385934 | O17: =IFERROR(SUMPRODUCT(C17:N17,$C$14:$N$14)/$O$14,0) -> 0.36898824
A18: Ash | B18: % | C18: 0 | D18: 0 | E18: 0 | F18: 0 | G18: 4.346919 | H18: 4.2775243 | I18: 4.5771833 | J18: 4.4107108 | K18: 4.3137914 | L18: 4.4379835 | M18: 4.3733361 | N18: 4.6218111 | O18: =IFERROR(SUMPRODUCT(C18:N18,$C$14:$N$14)/$O$14,0) -> 4.4323109
A19: IM | B19: % | C19: 0 | D19: 0 | E19: 0 | F19: 0 | G19: 17.434024 | H19: 17.20378 | I19: 17.033951 | J19: 16.871627 | K19: 16.977285 | L19: 16.725081 | M19: 16.935727 | N19: 16.762054 | O19: =IFERROR(SUMPRODUCT(C19:N19,$C$14:$N$14)/$O$14,0) -> 16.925892
A20: TM | B20: % | C20: 0 | D20: 0 | E20: 0 | F20: 0 | G20: 30.186701 | H20: 30.265561 | I20: 30.33487 | J20: 30.219758 | K20: 30.233061 | L20: 30.245087 | M20: 30.17827 | N20: 30.227937 | O20: =IFERROR(SUMPRODUCT(C20:N20,$C$14:$N$14)/$O$14,0) -> 30.236602

Sheet GPK 2025
A1: GPK 2025 Production Plan - 2nd Draft
A3: Draft file | B3: Draft GPK Production Plan 2025 Ver.1.3 (2.1 MTon) (22 Sept'24_)
A4: Draft date | B4: 45557
B5: Mine | C5: Unit | D5: Jan | E5: Feb | F5: Mar | G5: Apr | H5: May | I5: Jun | J5: Jul | K5: Aug | L5: Sep | M5: Oct | N5: Nov | O5: Dec | P5: Total
B6: GPK
B7: OB Removal | C7: KBCM | D7: 630 | E7: 580 | F7: 630 | G7: 610 | H7: 700 | I7: 675 | J7: 745 | K7: 790 | L7: 785 | M7: 880 | N7: 705 | O7: 770 | P7: =SUM(D7:O7) -> 8500
B8: ROM Production | C8: Kton | D8: 184 | E8: 166 | F8: 182 | G8: 175 | H8: 180 | I8: 175 | J8: 160 | K8: 160 | L8: 160 | M8: 196 | N8: 175 | O8: 187 | P8: =SUM(D8:O8) -> 2100
B9: FC Production | C9: Kton | D9: 200 | E9: 180 | F9: 190 | G9: 175 | H9: 180 | I9: 175 | J9: 90 | K9: 50 | L9: 90 | M9: 210 | N9: 260 | O9: 250 | P9: =SUM(D9:O9) -> 2050
B10: SR (OB:ROM) | C10: BCM/Ton | D10: =IFERROR(D7/D8,"-") -> 3.423913 | E10: =IFERROR(E7/E8,"-") -> 3.4939759 | F10: =IFERROR(F7/F8,"-") -> 3.4615385 | G10: =IFERROR(G7/G8,"-") -> 3.4857143 | H10: =IFERROR(H7/H8,"-") -> 3.8888889 | I10: =IFERROR(I7/I8,"-") -> 3.8571429 | J10: =IFERROR(J7/J8,"-") -> 4.65625 | K10: =IFERROR(K7/K8,"-") -> 4.9375 | ... O10: =IFERROR(O7/O8,"-") -> 4.1176471 | P10: =P7/P8 -> 4.047619
