Workbook
Name _1A1_Z1...A10_Z10: #REF!
Name _1A1_Z1...A10_Z10: #REF!
Name _Apr: [1]Validation!$A$33
Name _Aug: [1]Validation!$A$37
Name _Chubu1: [1]Validation!$A$5
Name _Chubu2: [1]Validation!$A$6
Name _Chubu3: [1]Validation!$A$7
Name _ChubuP1: [1]Chubu!$V$203
Name _ChubuP2: [1]Chubu!$V$204
Name _CLP: [1]Validation!$A$17
Name _CLPP1: [1]CLP!$V$203
Name _CLPP2: [1]CLP!$V$204
Name _DATE: #REF!
Name _DATE: #REF!
Name _Dec: [1]Validation!$A$41
Name _ENEL1: [1]Validation!$A$11
Name _ENELP1: '[1]Enel '!$V$264
Name _ENELP2: '[1]Enel '!$V$265
Name _EPDC: [1]Validation!$A$8
Name _EPDCP1: [1]EPDC!$V$203
Name _EPDCP2: [1]EPDC!$V$204
Name _Feb: [1]Validation!$A$31
Name _ffggggg: #REF!
Name _ffggggg: #REF!
Name _Formosa1: [1]Validation!$A$15
Name _Formosa2: [1]Validation!$A$16
Name _FORMOSAP1: [1]Formosa!$V$264
Name _FORMOSAP2: [1]Formosa!$V$265
Name _fs1: #REF!
Name _fs1: #REF!
Name _HEK1: [1]Validation!$A$20
Name _HEK2: [1]Validation!$A$21
Name _HEKP1: [1]HEK!$V$203
Name _HEKP2: [1]HEK!$V$204
Name _Huaneng1: [1]Validation!$A$18
Name _Huaneng2: [1]Validation!$A$19
Name _HUANP1: [1]Huaneng!$V$394
Name _HUANP2: [1]Huaneng!$V$395
Name _Jan: [1]Validation!$A$30
Name _Jul: [1]Validation!$A$36
Name _Jun: [1]Validation!$A$35
Name _Kobe: [1]Validation!$A$9
Name _KOBEP1: '[1]Kobe Steel'!$V$264
Name _KOBEP2: '[1]Kobe Steel'!$V$265
Name _Kospo: [1]Validation!$A$13
Name _KOSPOP1: [1]Kospo!$V$203
Name _KOSPOP2: [1]Kospo!$V$204
Name _Kowepo: [1]Validation!$A$14
Name _KOWEPOP1: [1]Kowepo!$V$264
Name _KOWEPOP2: [1]Kowepo!$V$265
Name _Mar: [1]Validation!$A$32
Name _May: [1]Validation!$A$34
Name _Nov: [1]Validation!$A$40
Name _Oct: [1]Validation!$A$39
Name _Sep: [1]Validation!$A$38
Name _SHIKOKUP1: [1]Shikoku!$V$203
Name _SHIKOKUP2: [1]Shikoku!$V$204
Name _Tirreno: [1]Validation!$A$12
Name _TIRRENOP1: [1]Tirreno!$V$264
Name _TIRRENOP2: [1]Tirreno!$V$265

Sheet Budget 2025
A1: ITM plan year 2024
A2: As of 18 Nov'24
A4: IMM | B4: Jan | C4: Feb | D4: Mar | E4: Apr | F4: May | G4: Jun | H4: Jul | I4: Aug | J4: Sep | K4: Oct | L4: Nov | M4: Dec | N4: Total
A5: OB Removal (KBcm) | B5: =SUM(B6:B7) -> 7619.4483 | C5: =SUM(C6:C7) -> 7224.3023 | D5: =SUM(D6:D7) -> 6870.0231 | E5: =SUM(E6:E7) -> 7815.9147 | F5: =SUM(F6:F7) -> 8233.4755 | G5: =SUM(G6:G7) -> 7596.8792 | H5: =SUM(H6:H7) -> 8769.11 | I5: =SUM(I6:I7) -> 8498.0492 | ... M5: =SUM(M6:M7) -> 7566.691 | N5: =SUM(B5:M5) -> 94714.478 | P5: Done
A6: PAMA (WB) | B6: 2904.786 | C6: 2754.4503 | D6: 2424.321 | E6: 2767.1447 | F6: 2927.6178 | G6: 2460.4194 | H6: 3157.9028 | I6: 3107.2173 | J6: 2899.6426 | K6: 2829.8233 | L6: 2690.1553 | M6: 2609.1784 | N6: =SUM(B6:M6) -> 33532.659
A7: PAMA (EB) | B7: 4714.6622 | C7: 4469.852 | D7: 4445.7021 | E7: 5048.77 | F7: 5305.8577 | G7: 5136.4598 | H7: 5611.2072 | I7: 5390.8319 | J7: 5542.5331 | K7: 5412.2853 | L7: 5146.1452 | M7: 4957.5126 | N7: =SUM(B7:M7) -> 61181.819
A8: ROM Production (Kton) | B8: =SUM(B9:B11) -> 537.5 | C8: =SUM(C9:C11) -> 532.5 | D8: =SUM(D9:D11) -> 537.5 | E8: =SUM(E9:E11) -> 537.5 | F8: =SUM(F9:F11) -> 537.5 | G8: =SUM(G9:G11) -> 537.5 | H8: =SUM(H9:H11) -> 610 | I8: =SUM(I9:I11) -> 625 | ... M8: =SUM(M9:M11) -> 620 | N8: =SUM(B8:M8) -> 6950
A9: PAMA (WB) | B9: 192.5 | C9: 187.5 | D9: 192.5 | E9: 190 | F9: 185 | G9: 155 | H9: 130 | I9: 135 | J9: 145 | K9: 110 | L9: 120 | M9: 120 | N9: =SUM(B9:M9) -> 1862.5
A10: PAMA (EB) | B10: 345 | C10: 345 | D10: 345 | E10: 347.5 | F10: 352.5 | G10: 382.5 | H10: 480 | I10: 490 | J10: 480 | K10: 515 | L10: 505 | M10: 500 | N10: =SUM(B10:M10) -> 5087.5
A11: Fine Coal | B11: 0 | C11: 0 | D11: 0 | E11: 0 | F11: 0 | G11: 0 | H11: 0 | I11: 0 | J11: 0 | K11: 0 | L11: 0 | M11: 0 | N11: =SUM(B11:M11) -> 0
A12: SR ROM Total | B12: =B5/B8 -> 14.175718 | C12: =C5/C8 -> 13.566765 | D12: =D5/D8 -> 12.781438 | E12: =E5/E8 -> 14.541237 | F12: =F5/F8 -> 15.318094 | G12: =G5/G8 -> 14.133729 | H12: =H5/H8 -> 14.37559 | I12: =I5/I8 -> 13.596879 | ... N12: =N5/N8 -> 13.627982
A13: FC Product (Kton) | B13: =SUM(B14:B16) -> 541.75 | C13: =SUM(C14:C16) -> 536.75 | D13: =SUM(D14:D16) -> 541.75 | E13: =SUM(E14:E16) -> 551.75 | F13: =SUM(F14:F16) -> 551.75 | G13: =SUM(G14:G16) -> 551.75 | H13: =SUM(H14:H16) -> 635.75 | I13: =SUM(I14:I16) -> 637.75 | ... M13: =SUM(M14:M16) -> 637.75 | N13: =SUM(B13:M13) -> 7100
A14: PAMA (WB) | B14: 192.5 | C14: 187.5 | D14: 192.5 | E14: 190 | F14: 185 | G14: 155 | H14: 130 | I14: 135 | J14: 145 | K14: 110 | L14: 120 | M14: 120 | N14: =SUM(B14:M14) -> 1862.5
A15: PAMA (EB) | B15: 345 | C15: 345 | D15: 345 | E15: 349 | F15: 354 | G15: 384 | H15: 493 | I15: 490 | J15: 480 | K15: 515 | L15: 505 | M15: 505 | N15: =SUM(B15:M15) -> 5110
A16: Fine Coal | B16: 4.25 | C16: 4.25 | D16: 4.25 | E16: 12.75 | F16: 12.75 | G16: 12.75 | H16: 12.75 | I16: 12.75 | J16: 12.75 | K16: 12.75 | L16: 12.75 | M16: 12.75 | N16: =SUM(B16:M16) -> 127.5
A17: SR FC Total | B17: =B5/B13 -> 14.06451 | C17: =C5/C13 -> 13.459343 | D17: =D5/D13 -> 12.681169 | E17: =E5/E13 -> 14.165681 | F17: =F5/F13 -> 14.922475 | G17: =G5/G13 -> 13.768698 | H17: =H5/H13 -> 13.793331 | I17: =I5/I13 -> 13.325048 | ... N17: =N5/N13 -> 13.340067
A18: IMM-WB.HCV.LS | B18: 154.9822 | C18: 150.19218 | D18: 153.44456 | E18: 142.73183 | F18: 131.89202 | G18: 90.256716 | H18: 45.052829 | I18: 60.104109 | J18: 62.623268 | K18: 73.637876 | L18: 78.465632 | M18: 85.419934 | N18: =SUM(B18:M18) -> 1228.8032
A19: CV(GAR) | B19: 6066.6995 | C19: 6061.099 | D19: 6072.9614 | E19: 6113.1737 | F19: 6106.3251 | G19: 6216.0563 | H19: 6397.4706 | I19: 6374.5335 | J19: 6369.463 | K19: 6395.7374 | L19: 6207.9868 | M19: 6224.9984 | N19: =SUMPRODUCT(B19:M19,$B$18:$M$18)/SUM($B$18:$M$18) -> 6169.7769
A20: TS | B20: 0.79938883 | C20: 0.79960479 | D20: 0.80630914 | E20: 0.80238321 | F20: 0.79513307 | G20: 0.79813522 | H20: 0.8000568 | I20: 0.80071014 | J20: 0.80424058 | K20: 0.87778388 | L20: 0.89103139 | M20: 0.79704817 | N20: =SUMPRODUCT(B20:M20,$B$18:$M$18)/SUM($B$18:$M$18) -> 0.81080181
A21: Ash | B21: 8.5931913 | C21: 8.5723462 | D21: 8.4652505 | E21: 8.3496537 | F21: 8.4544991 | G21: 8.0611616 | H21: 8.0877488 | I21: 8.0139288 | J21: 8.093906 | K21: 8.3113445 | L21: 8.6583469 | M21: 8.1211956 | N21: =SUMPRODUCT(B21:M21,$B$18:$M$18)/SUM($B$18:$M$18) -> 8.3745645
A22: Moist | B22: 8.4967581 | C22: 8.6035878 | D22: 8.5701167 | E22: 8.295887 | F22: 8.4360236 | G22: 8.1042227 | H22: 7.1124623 | I22: 7.0457455 | J22: 7.1276119 | K22: 7.1603037 | L22: 7.2146756 | M22: 7.5402791 | N22: =SUMPRODUCT(B22:M22,$B$18:$M$18)/SUM($B$18:$M$18) -> 8.0403443
A23: TM | B23: 13.52212 | C23: 13.62895 | D23: 13.595479 | E23: 13.321249 | F23: 13.461386 | G23: 13.129585 | H23: 12.137825 | I23: 12.071108 | J23: 12.152974 | K23: 12.185666 | L23: 12.240038 | M23: 12.565641 | N23: =SUMPRODUCT(B23:M23,$B$18:$M$18)/SUM($B$18:$M$18) -> 13.065707
A24: IMM-WB.HCV.HS | B24: 37.517805 | C24: 37.307818 | D24: 39.055444 | E24: 47.268165 | F24: 53.10798 | G24: 64.743284 | H24: 84.947171 | I24: 74.895891 | J24: 82.376732 | K24: 36.362124 | L24: 41.534368 | M24: 34.580066 | N24: =SUM(B24:M24) -> 633.69685
A25: CV(GAR) | B25: 5995.4058 | C25: 6102.8668 | D25: 6012.8803 | E25: 5956.2491 | F25: 5900.982 | G25: 5903.8514 | H25: 5953.1501 | I25: 5935.2903 | J25: 5994.0694 | K25: 5972.607 | L25: 5974.5067 | M25: 5973.0938 | N25: =SUMPRODUCT(B25:M25,$B$24:$M$24)/SUM($B$24:$M$24) -> 5965.7827
A26: TS | B26: 2.4295613 | C26: 2.4050655 | D26: 2.5318666 | E26: 2.5966145 | F26: 2.6452674 | G26: 2.7646957 | H26: 2.7577905 | I26: 2.7055365 | J26: 2.6431822 | K26: 2.4886633 | L26: 2.3842149 | M26: 1.9721835 | N26: =SUMPRODUCT(B26:M26,$B$24:$M$24)/SUM($B$24:$M$24) -> 2.5790489
A27: Ash | B27: 13.650338 | C27: 13.07266 | D27: 13.53618 | E27: 14.197739 | F27: 14.74821 | G27: 14.555829 | H27: 13.682949 | I27: 14.42353 | J27: 13.830267 | K27: 13.802136 | L27: 13.963262 | M27: 13.239605 | N27: =SUMPRODUCT(B27:M27,$B$24:$M$24)/SUM($B$24:$M$24) -> 13.960595
A28: Moist | B28: 6.0446714 | C28: 6.0271092 | D28: 6.0381378 | E28: 6.0670306 | F28: 6.0650682 | G28: 7.0545207 | H28: 6.8576285 | I28: 6.9141156 | J28: 7.151348 | K28: 7.5030578 | L28: 7.5101273 | M28: 7.1237139 | N28: =SUMPRODUCT(B28:M28,$B$24:$M$24)/SUM($B$24:$M$24) -> 6.7439986
A29: TM | B29: 11.070034 | C29: 11.052472 | D29: 11.0635 | E29: 11.092393 | F29: 11.090431 | G29: 12.079883 | H29: 11.882991 | I29: 11.939478 | J29: 12.17671 | K29: 12.52842 | L29: 12.53549 | M29: 12.149076 | N29: =SUMPRODUCT(B29:M29,$B$24:$M$24)/SUM($B$24:$M$24) -> 11.769361
A30: IMM-EB.MCV.LS | B30: 3.3845713 | C30: 2.1986171 | D30: 2.3031178 | E30: 2.767207 | F30: 1.8758652 | G30: 1.1105575 | H30: 0 | I30: 0 | J30: 0 | K30: 0 | L30: 0 | M30: 0 | N30: =SUM(B30:M30) -> 13.639936
A31: CV(GAR) | B31: 5821.883 | C31: 5816.4871 | D31: 5824.2204 | E31: 5826.2223 | F31: 5821.6228 | G31: 5824.0809 | H31: 0 | I31: 0 | J31: 0 | K31: 0 | L31: 0 | M31: 0 | N31: =SUMPRODUCT(B31:M31,$B$30:$M$30)/SUM($B$30:$M$30) -> 5822.4314
A32: TS | B32: 0.89812632 | C32: 0.89994494 | D32: 0.90129647 | E32: 0.90153154 | F32: 0.90292127 | G32: 0.90325732 | H32: 0 | I32: 0 | J32: 0 | K32: 0 | L32: 0 | M32: 0 | N32: =SUMPRODUCT(B32:M32,$B$30:$M$30)/SUM($B$30:$M$30) -> 0.90072278
A33: Ash | B33: 8.6642459 | C33: 8.6537904 | D33: 8.6423873 | E33: 8.5289327 | F33: 8.5159535 | G33: 8.5014972 | H33: 0 | I33: 0 | J33: 0 | K33: 0 | L33: 0 | M33: 0 | N33: =SUMPRODUCT(B33:M33,$B$30:$M$30)/SUM($B$30:$M$30) -> 8.5977728
A34: Moist | B34: 11.332981 | C34: 11.336869 | D34: 11.369268 | E34: 11.350128 | F34: 11.399581 | G34: 11.357707 | H34: 0 | I34: 0 | J34: 0 | K34: 0 | L34: 0 | M34: 0 | N34: =SUMPRODUCT(B34:M34,$B$30:$M$30)/SUM($B$30:$M$30) -> 11.354386
A35: TM | B35: 16.332981 | C35: 16.336869 | D35: 16.369268 | E35: 16.350128 | F35: 16.399581 | G35: 16.357707 | H35: 0 | I35: 0 | J35: 0 | K35: 0 | L35: 0 | M35: 0 | N35: =SUMPRODUCT(B35:M35,$B$30:$M$30)/SUM($B$30:$M$30) -> 16.354386
A36: IMM-EB.MCV.MS | B36: 2.5218825 | C36: 7.2154786 | D36: 26.720101 | E36: 6.3272233 | F36: 12.630174 | G36: 4.8087851 | H36: 12.094951 | I36: 14.998053 | J36: 83.697273 | K36: 94.400599 | L36: 71.33532 | M36: 85.965624 | N36: =SUM(B36:M36) -> 422.71546
A37: CV(GAR) | B37: 6013.744 | C37: 5958.5719 | D37: 6011.5142 | E37: 6033.7912 | F37: 5987.1311 | G37: 6002.8141 | H37: 6036.2059 | I37: 6005.6296 | J37: 5996.4183 | K37: 6012.5832 | L37: 6026.6617 | M37: 6027.4417 | N37: =SUMPRODUCT(B37:M37,$B$36:$M$36)/SUM($N$36) -> 6013.6725
A38: TS | B38: 1.5719259 | C38: 1.5704928 | D38: 1.5645055 | E38: 1.5541281 | F38: 1.5514426 | G38: 1.5490809 | H38: 1.5706205 | I38: 1.5667221 | J38: 1.5492652 | K38: 1.553251 | L38: 1.5598162 | M38: 1.5724278 | N38: =SUMPRODUCT(B38:M38,$B$36:$M$36)/SUM($N$36) -> 1.5594733
A39: Ash | B39: 6.0748082 | C39: 6.153097 | D39: 6.1792076 | E39: 5.197632 | F39: 5.2945573 | G39: 5.236934 | H39: 5.1052577 | I39: 5.3674075 | J39: 5.3569251 | K39: 5.169691 | L39: 5.1649103 | M39: 5.3009891 | N39: =SUMPRODUCT(B39:M39,$B$36:$M$36)/SUM($N$36) -> 5.3287414
A40: Moist | B40: 10.127325 | C40: 10.233784 | D40: 10.532647 | E40: 10.3526 | F40: 10.781854 | G40: 10.481305 | H40: 10.365903 | I40: 10.468448 | J40: 10.443604 | K40: 10.274018 | L40: 10.240397 | M40: 9.9507726 | N40: =SUMPRODUCT(B40:M40,$B$36:$M$36)/SUM($N$36) -> 10.279207
A41: TM | B41: 15.127325 | C41: 15.233784 | D41: 15.532647 | E41: 15.3526 | F41: 15.781854 | G41: 15.481305 | H41: 15.365903 | I41: 15.468448 | J41: 15.443604 | K41: 15.274018 | L41: 15.240397 | M41: 14.950773 | N41: =SUMPRODUCT(B41:M41,$B$36:$M$36)/SUM($N$36) -> 15.279207
...

Sheet Outlook 6+6
A1: ITM outlook 2025 (6+6)
B3: Act. | C3: Act. | D3: Act. | E3: Act. | F3: Act. | G3: Act. | H3: Out. | I3: Out. | J3: Out. | K3: Out. | L3: Out. | M3: Out. | N3: Out.
A4: IMM | B4: Jan | C4: Feb | D4: Mar | E4: Apr | F4: May | G4: Jun | H4: Jul | I4: Aug | J4: Sep | K4: Oct | L4: Nov | M4: Dec | N4: Total | P4: Budget 2025
A5: OB Removal (KBcm) | B5: =SUM(B6:B7) -> 6763.0376 | C5: =SUM(C6:C7) -> 7421.6153 | D5: =SUM(D6:D7) -> 6667.0223 | E5: =SUM(E6:E7) -> 6530.8426 | F5: =SUM(F6:F7) -> 7716.6778 | G5: =SUM(G6:G7) -> 7595.242 | H5: =SUM(H6:H7) -> 8982.5413 | I5: =SUM(I6:I7) -> 8828.7539 | ... M5: =SUM(M6:M7) -> 8253.8722 | N5: =SUM(B5:M5) -> 95195.876 | P5: ='Budget 2025'!N5 -> 94714.478 | Q5: =N5/P5 -> 1.0050826
A6: PAMA (WB) | B6: 2244.6941 | C6: 2827.069 | D6: 2295.7418 | E6: 2096.5402 | F6: 2379.9843 | G6: 2441.293 | H6: 2684.5774 | I6: 2586.0616 | J6: 2605.3533 | K6: 2792.096 | L6: 2669.408 | M6: 2582.3384 | N6: =SUM(B6:M6) -> 30205.157 | P6: ='Budget 2025'!N6 -> 33532.659
A7: PAMA (EB) | B7: 4518.3435 | C7: 4594.5463 | D7: 4371.2805 | E7: 4434.3024 | F7: 5336.6935 | G7: 5153.949 | H7: 6297.9639 | I7: 6242.6923 | J7: 6289.3368 | K7: 6192.3978 | L7: 5887.6794 | M7: 5671.5338 | N7: =SUM(B7:M7) -> 64990.719 | P7: ='Budget 2025'!N7 -> 61181.819
A8: ROM Production (Kton) | B8: =SUM(B9:B11) -> 542.83357 | C8: =SUM(C9:C11) -> 554.11951 | D8: =SUM(D9:D11) -> 482.78672 | E8: =SUM(E9:E11) -> 444.51201 | F8: =SUM(F9:F11) -> 639.80024 | G8: =SUM(G9:G11) -> 581.91609 | H8: =SUM(H9:H11) -> 635.31454 | I8: =SUM(I9:I11) -> 660 | ... N8: =SUM(N9:N11) -> 7072.5 | P8: ='Budget 2025'!N8 -> 6950 | Q8: =N8/P8 -> 1.0176259
A9: PAMA (WB) | B9: 158.42587 | C9: 192.58567 | D9: 141.12357 | E9: 88.560644 | F9: 157.3174 | G9: 130.17205 | H9: 115.13017 | I9: 130 | J9: 130 | K9: 130 | L9: 130 | M9: 125 | N9: =SUM(B9:M9) -> 1628.3154 | P9: ='Budget 2025'!N9 -> 1862.5
A10: PAMA (EB) | B10: 384.4077 | C10: 361.53383 | D10: 341.66315 | E10: 355.95136 | F10: 482.48284 | G10: 451.74403 | H10: 520.18437 | I10: 530 | J10: 520 | K10: 520 | L10: 520 | M10: 456.21734 | N10: =SUM(B10:M10) -> 5444.1846 | P10: ='Budget 2025'!N10 -> 5087.5
A11: Fine Coal (WB) | B11: 0 | C11: 0 | D11: 0 | E11: 0 | F11: 0 | G11: 0 | H11: 0 | I11: 0 | J11: 0 | K11: 0 | L11: 0 | M11: 0 | N11: =SUM(B11:M11) -> 0 | P11: ='Budget 2025'!N11 -> 0
A12: SR ROM Total | B12: =B5/B8 -> 12.458768 | C12: =C5/C8 -> 13.393528 | D12: =D5/D8 -> 13.809457 | E12: =E5/E8 -> 14.692162 | F12: =F5/F8 -> 12.061074 | G12: =G5/G8 -> 13.052126 | H12: =H5/H8 -> 14.138731 | I12: =I5/I8 -> 13.3769 | ... N12: =N5/N8 -> 13.460004 | P12: ='Budget 2025'!N12 -> 13.627982
A13: FC Product (Kton) | B13: =SUM(B14:B16) -> 612.68293 | C13: =SUM(C14:C16) -> 584.91494 | D13: =SUM(D14:D16) -> 501.01074 | E13: =SUM(E14:E16) -> 479.30495 | F13: =SUM(F14:F16) -> 587.89845 | G13: =SUM(G14:G16) -> 588.81158 | H13: =SUM(H14:H16) -> 625.75 | I13: =SUM(I14:I16) -> 664.25 | ... M13: =SUM(M14:M16) -> 553.62641 | N13: =SUM(B13:M13) -> 7135 | P13: ='Budget 2025'!N13 -> 7100
A14: PAMA (WB) | B14: 203.84233 | C14: 213.15935 | D14: 151.07621 | E14: 100.53441 | F14: 127.35434 | G14: 132.81291 | H14: 175 | I14: 160 | J14: 130 | K14: 115 | L14: 115 | M14: 106.22044 | N14: =SUM(B14:M14) -> 1730 | P14: ='Budget 2025'!N14 -> 1862.5
A15: PAMA (EB) | B15: 408.8406 | C15: 371.75559 | D15: 349.93453 | E15: 378.57866 | F15: 460.53461 | G15: 455.99867 | H15: 446.5 | I15: 500 | J15: 538.5 | K15: 504.25 | L15: 504.25 | M15: 434.65597 | N15: =SUM(B15:M15) -> 5353.7986 | P15: ='Budget 2025'!N15 -> 5110
A16: Fine Coal | B16: 0 | C16: 0 | D16: 0 | E16: 0.19186901 | F16: 0.0094999788 | G16: 0 | H16: 4.25 | I16: 4.25 | J16: 4.25 | K16: 12.75 | L16: 12.75 | M16: 12.75 | N16: =SUM(B16:M16) -> 51.201369 | P16: ='Budget 2025'!N48 -> 127.5
A17: SR FC Total | B17: =B5/B13 -> 11.038397 | C17: =C5/C13 -> 12.688367 | D17: =D5/D13 -> 13.307145 | E17: =E5/E13 -> 13.625652 | F17: =F5/F13 -> 13.125868 | G17: =G5/G13 -> 12.899274 | H17: =H5/H13 -> 14.35484 | I17: =I5/I13 -> 13.291312 | ... N17: =N5/N13 -> 13.342099 | P17: ='Budget 2025'!N17 -> 13.340067
A18: IMM-WB.HCV.LS | B18: 146.18254 | C18: 147.46076 | D18: 104.99952 | E18: 70.128194 | F18: 84.530923 | G18: 85.31518 | H18: 110 | I18: 82.532988 | J18: 60.337255 | K18: 65.622327 | L18: 60.81637 | M18: 46.8 | N18: =SUM(B18:M18) -> 1064.7261 | P18: ='Budget 2025'!N18 -> 1228.8032
A19: CV(GAR) | B19: 6193.9879 | C19: 6105.8162 | D19: 6211.2744 | E19: 6152.0829 | F19: 6133.0399 | G19: 6095.5899 | H19: 5925.7694 | I19: 6154.0269 | J19: 6337.0595 | K19: 6300.2368 | L19: 6181.488 | M19: 6258.309 | N19: =SUMPRODUCT(B19:M19,$B$18:$M$18)/SUM($B$18:$M$18) -> 6153.9592 | P19: ='Budget 2025'!N19 -> 6169.7769
A20: TS | B20: 0.61677597 | C20: 0.68122223 | D20: 0.59905828 | E20: 0.64019198 | F20: 0.77254239 | G20: 0.68498819 | H20: 0.9609861 | I20: 0.9907543 | J20: 0.81135624 | K20: 0.90349601 | L20: 0.84119688 | M20: 0.8164343 | N20: =SUMPRODUCT(B20:M20,$B$18:$M$18)/SUM($B$18:$M$18) -> 0.75817243 | P20: ='Budget 2025'!N20 -> 0.81080181
A21: Ash | B21: 8.41834 | C21: 8.393601 | D21: 8.4815141 | E21: 7.9869977 | F21: 8.4695031 | G21: 7.7685138 | H21: 9.6264563 | I21: 8.3292906 | J21: 8.637946 | K21: 8.98472 | L21: 8.7768602 | M21: 8.2000182 | N21: =SUMPRODUCT(B21:M21,$B$18:$M$18)/SUM($B$18:$M$18) -> 8.5208716 | P21: ='Budget 2025'!N21 -> 8.3745645
A22: Moist | B22: 8.6372078 | C22: 9.4241924 | D22: 8.714191 | E22: 9.2338941 | F22: 8.7192877 | G22: 9.9019574 | H22: 8.8241966 | I22: 7.8616937 | J22: 7.2805442 | K22: 7.269403 | L22: 7.2517444 | M22: 7.1512635 | N22: =SUMPRODUCT(B22:M22,$B$18:$M$18)/SUM($B$18:$M$18) -> 8.5545237 | P22: ='Budget 2025'!N22 -> 8.0403443
A23: TM | B23: 11.489526 | C23: 12.325215 | D23: 11.133918 | E23: 12.344042 | F23: 12.370062 | G23: 12.73142 | H23: 13.51332 | I23: 12.882139 | J23: 12.305907 | K23: 12.294765 | L23: 12.277107 | M23: 12.176626 | N23: =SUMPRODUCT(B23:M23,$B$18:$M$18)/SUM($B$18:$M$18) -> 12.284013 | P23: ='Budget 2025'!N23 -> 13.065707
A24: IMM-WB.HCV.HS | B24: 57.659789 | C24: 65.698593 | D24: 46.076686 | E24: 30.406221 | F24: 42.82342 | G24: 47.49773 | H24: 65 | I24: 77.467012 | J24: 69.662745 | K24: 49.377673 | L24: 54.18363 | M24: 59.420442 | N24: =SUM(B24:M24) -> 665.27394 | P24: ='Budget 2025'!N24 -> 633.69685
A25: CV(GAR) | B25: 5947.3932 | C25: 5939.4465 | D25: 6026.7648 | E25: 5928.2234 | F25: 6043.0525 | G25: 6015.1688 | H25: 5986.6305 | I25: 5963.8688 | J25: 5931.2924 | K25: 5803.0189 | L25: 5831.9498 | M25: 5854.6471 | N25: =SUMPRODUCT(B25:M25,$B$24:$M$24)/SUM($B$24:$M$24) -> 5937.8903 | P25: ='Budget 2025'!N25 -> 5965.7827
A26: TS | B26: 1.9789488 | C26: 2.2887477 | D26: 2.1709775 | E26: 1.9301202 | F26: 2.0257524 | G26: 2.5171695 | H26: 2.5490188 | I26: 2.6090631 | J26: 2.787434 | K26: 2.82215 | L26: 2.7371964 | M26: 2.5772142 | N26: =SUMPRODUCT(B26:M26,$B$24:$M$24)/SUM($B$24:$M$24) -> 2.4535552 | P26: ='Budget 2025'!N26 -> 2.5790489
A27: Ash | B27: 12.398872 | C27: 11.628956 | D27: 11.380259 | E27: 12.152459 | F27: 11.490738 | G27: 11.721002 | H27: 11.783674 | I27: 12.597043 | J27: 14.256213 | K27: 15.989352 | L27: 15.85054 | M27: 16.138101 | N27: =SUMPRODUCT(B27:M27,$B$24:$M$24)/SUM($B$24:$M$24) -> 13.173223 | P27: ='Budget 2025'!N27 -> 13.960595
A28: Moist | B28: 7.8249272 | C28: 7.5595294 | D28: 6.9977463 | E28: 7.2613478 | F28: 7.0928299 | G28: 7.1802963 | H28: 7.6688492 | I28: 7.625046 | J28: 6.9691952 | K28: 7.3730054 | L28: 7.266614 | M28: 6.9805455 | N28: =SUMPRODUCT(B28:M28,$B$24:$M$24)/SUM($B$24:$M$24) -> 7.3399579 | P28: ='Budget 2025'!N28 -> 6.7439986
A29: TM | B29: 10.911081 | C29: 11.826969 | D29: 11.261991 | E29: 11.642346 | F29: 10.959217 | G29: 10.871461 | H29: 12.477139 | I29: 12.645825 | J29: 11.994558 | K29: 12.398368 | L29: 12.291976 | M29: 12.005908 | N29: =SUMPRODUCT(B29:M29,$B$24:$M$24)/SUM($B$24:$M$24) -> 11.848633 | P29: ='Budget 2025'!N29 -> 11.769361
A30: IMM-EB.MCV.LS | B30: 4.1511632 | C30: 4.8753097 | D30: 8.972062 | E30: 7.4826072 | F30: 9.8667018 | G30: 5.265915 | H30: 0 | I30: 0 | J30: 0 | K30: 0 | L30: 0 | M30: 0 | N30: =SUM(B30:M30) -> 40.613759 | P30: ='Budget 2025'!N30 -> 13.639936
A31: CV(GAR) | B31: 5768.2424 | C31: 5970.6107 | D31: 5842.9196 | E31: 6060.3315 | F31: 5981.1886 | G31: 5851.139 | H31: 0 | I31: 0 | J31: 0 | K31: 0 | L31: 0 | M31: 0 | N31: =SUMPRODUCT(B31:M31,$B$30:$M$30)/SUM($B$30:$M$30) -> 5925.3273 | P31: ='Budget 2025'!N31 -> 5822.4314
A32: TS | B32: 0.90470615 | C32: 0.97326494 | D32: 0.89969842 | E32: 0.91618026 | F32: 0.8618658 | G32: 1.031383 | H32: 0 | I32: 0 | J32: 0 | K32: 0 | L32: 0 | M32: 0 | N32: =SUMPRODUCT(B32:M32,$B$30:$M$30)/SUM($B$30:$M$30) -> 0.9199608 | P32: ='Budget 2025'!N32 -> 0.90072278
A33: Ash | B33: 8.4980056 | C33: 6.454713 | D33: 6.9734339 | E33: 5.5176512 | F33: 5.7561377 | G33: 6.6074957 | H33: 0 | I33: 0 | J33: 0 | K33: 0 | L33: 0 | M33: 0 | N33: =SUMPRODUCT(B33:M33,$B$30:$M$30)/SUM($B$30:$M$30) -> 6.4556062 | P33: ='Budget 2025'!N33 -> 8.5977728
A34: Moist | B34: 10.861527 | C34: 11.334285 | D34: 10.91524 | E34: 11.119528 | F34: 11.717851 | G34: 11.463808 | H34: 0 | I34: 0 | J34: 0 | K34: 0 | L34: 0 | M34: 0 | N34: =SUMPRODUCT(B34:M34,$B$30:$M$30)/SUM($B$30:$M$30) -> 11.263803 | P34: ='Budget 2025'!N34 -> 11.354386
A35: TM | B35: 14.308473 | C35: 13.960815 | D35: 14.885351 | E35: 13.934471 | F35: 14.518515 | G35: 15.49119 | H35: 0 | I35: 0 | J35: 0 | K35: 0 | L35: 0 | M35: 0 | N35: =SUMPRODUCT(B35:M35,$B$30:$M$30)/SUM($B$30:$M$30) -> 14.52965 | P35: ='Budget 2025'!N35 -> 16.354386
A36: IMM-EB.MCV.MS | B36: 16.385665 | C36: 4.2318727 | D36: 27.481461 | E36: 41.321236 | F36: 24.257871 | G36: 32.490626 | H36: 35 | I36: 30.467451 | J36: 80.151998 | K36: 88.528775 | L36: 72.511649 | M36: 60.948547 | N36: =SUM(B36:M36) -> 513.77715 | P36: ='Budget 2025'!N36 -> 422.71546
A37: CV(GAR) | B37: 6095.6967 | C37: 5702.0802 | D37: 5950.0061 | E37: 5974.4204 | F37: 6089.8148 | G37: 6004.3095 | H37: 5920.2903 | I37: 6012.8395 | J37: 6017.1851 | K37: 5997.8717 | L37: 6036.7778 | M37: 6034.8958 | N37: =SUMPRODUCT(B37:M37,$B$36:$M$36)/SUM($B$36:$M$36) -> 6007.3557 | P37: ='Budget 2025'!N37 -> 6013.6725
A38: TS | B38: 1.5214168 | C38: 1.2568182 | D38: 1.4097729 | E38: 1.483995 | F38: 1.5035755 | G38: 1.4015116 | H38: 1.5626347 | I38: 1.6135068 | J38: 1.5927849 | K38: 1.5670642 | L38: 1.5972032 | M38: 1.5768974 | N38: =SUMPRODUCT(B38:M38,$B$36:$M$36)/SUM($B$36:$M$36) -> 1.5463767 | P38: ='Budget 2025'!N38 -> 1.5594733
A39: Ash | B39: 5.147646 | C39: 7.9572727 | D39: 6.2814993 | E39: 5.8970893 | F39: 5.4006541 | G39: 5.6630745 | H39: 6.9484476 | I39: 5.7415659 | J39: 5.4286145 | K39: 5.4881788 | L39: 5.2385808 | M39: 5.2611881 | N39: =SUMPRODUCT(B39:M39,$B$36:$M$36)/SUM($B$36:$M$36) -> 5.6229617 | P39: ='Budget 2025'!N39 -> 5.3287414
A40: Moist | B40: 11.52539 | C40: 13.017273 | D40: 11.444174 | E40: 12.148882 | F40: 11.241298 | G40: 12.009315 | H40: 10.737886 | I40: 10.505685 | J40: 10.288957 | K40: 10.252837 | L40: 10.153584 | M40: 9.8519594 | N40: =SUMPRODUCT(B40:M40,$B$36:$M$36)/SUM($B$36:$M$36) -> 10.682264 | P40: ='Budget 2025'!N40 -> 10.279207
A41: TM | B41: 13.645355 | C41: 15.082727 | D41: 14.292213 | E41: 14.144596 | F41: 13.581215 | G41: 14.361058 | H41: 15.732427 | I41: 15.505685 | J41: 15.288957 | K41: 15.252837 | L41: 15.153584 | M41: 14.851959 | N41: =SUMPRODUCT(B41:M41,$B$36:$M$36)/SUM($B$36:$M$36) -> 14.916071 | P41: ='Budget 2025'!N41 -> 15.279207
...

Sheet Outlook Quarterly 6+6
A1: ITM outlook 2025 (4+8)
B3: Act. | C3: Out. | D3: Out. | E3: Out. | F3: Out.
A4: IMM | B4: Q1 | C4: Q2 | D4: Q3 | E4: Q4 | F4: Total | H4: Budget 2025
A5: OB Removal (KBcm) | B5: =SUM(B6:B7) -> 20851.675 | C5: =SUM(C6:C7) -> 21842.762 | D5: =SUM(D6:D7) -> 26705.985 | E5: =SUM(E6:E7) -> 25795.453 | F5: =SUM(B5:E5) -> 95195.876 | H5: ='Budget 2025'!N5 -> 94714.478 | I5: =F5/H5 -> 1.0050826
A6: PAMA (WB) | B6: =SUMIFS('Outlook 6+6'!$B6:$M6,'Outlook 6+6'!$B$185:$M$185,'Outlook Quarterly 6+6'!B$4) -> 7367.5048 | C6: =SUMIFS('Outlook 6+6'!$B6:$M6,'Outlook 6+6'!$B$185:$M$185,'Outlook Quarterly 6+6'!C$4) -> 6917.8176 | D6: =SUMIFS('Outlook 6+6'!$B6:$M6,'Outlook 6+6'!$B$185:$M$185,'Outlook Quarterly 6+6'!D$4) -> 7875.9923 | E6: =SUMIFS('Outlook 6+6'!$B6:$M6,'Outlook 6+6'!$B$185:$M$185,'Outlook Quarterly 6+6'!E$4) -> 8043.8424 | F6: =SUM(B6:E6) -> 30205.157 | H6: ='Budget 2025'!N6 -> 33532.659
A7: PAMA (EB) | B7: =SUMIFS('Outlook 6+6'!$B7:$M7,'Outlook 6+6'!$B$185:$M$185,'Outlook Quarterly 6+6'!B$4) -> 13484.17 | C7: =SUMIFS('Outlook 6+6'!$B7:$M7,'Outlook 6+6'!$B$185:$M$185,'Outlook Quarterly 6+6'!C$4) -> 14924.945 | D7: =SUMIFS('Outlook 6+6'!$B7:$M7,'Outlook 6+6'!$B$185:$M$185,'Outlook Quarterly 6+6'!D$4) -> 18829.993 | E7: =SUMIFS('Outlook 6+6'!$B7:$M7,'Outlook 6+6'!$B$185:$M$185,'Outlook Quarterly 6+6'!E$4) -> 17751.611 | F7: =SUM(B7:E7) -> 64990.719 | H7: ='Budget 2025'!N7 -> 61181.819
A8: ROM Production (Kton) | B8: =SUM(B9:B11) -> 1579.7398 | C8: =SUM(C9:C11) -> 1666.2283 | D8: =SUM(D9:D11) -> 1945.3145 | E8: =SUM(E9:E11) -> 1881.2173 | F8: =SUM(F9:F11) -> 7072.5 | H8: ='Budget 2025'!N8 -> 6950 | I8: =F8/H8 -> 1.0176259
A9: PAMA (WB) | B9: =SUMIFS('Outlook 6+6'!$B9:$M9,'Outlook 6+6'!$B$185:$M$185,'Outlook Quarterly 6+6'!B$4) -> 492.13512 | C9: =SUMIFS('Outlook 6+6'!$B9:$M9,'Outlook 6+6'!$B$185:$M$185,'Outlook Quarterly 6+6'!C$4) -> 376.0501 | D9: =SUMIFS('Outlook 6+6'!$B9:$M9,'Outlook 6+6'!$B$185:$M$185,'Outlook Quarterly 6+6'!D$4) -> 375.13017 | E9: =SUMIFS('Outlook 6+6'!$B9:$M9,'Outlook 6+6'!$B$185:$M$185,'Outlook Quarterly 6+6'!E$4) -> 385 | F9: =SUM(B9:E9) -> 1628.3154 | H9: ='Budget 2025'!N9 -> 1862.5
A10: PAMA (EB) | B10: =SUMIFS('Outlook 6+6'!$B10:$M10,'Outlook 6+6'!$B$185:$M$185,'Outlook Quarterly 6+6'!B$4) -> 1087.6047 | C10: =SUMIFS('Outlook 6+6'!$B10:$M10,'Outlook 6+6'!$B$185:$M$185,'Outlook Quarterly 6+6'!C$4) -> 1290.1782 | D10: =SUMIFS('Outlook 6+6'!$B10:$M10,'Outlook 6+6'!$B$185:$M$185,'Outlook Quarterly 6+6'!D$4) -> 1570.1844 | E10: =SUMIFS('Outlook 6+6'!$B10:$M10,'Outlook 6+6'!$B$185:$M$185,'Outlook Quarterly 6+6'!E$4) -> 1496.2173 | F10: =SUM(B10:E10) -> 5444.1846 | H10: ='Budget 2025'!N10 -> 5087.5
A11: Fine Coal (WB) | B11: =SUMIFS('Outlook 6+6'!$B11:$M11,'Outlook 6+6'!$B$185:$M$185,'Outlook Quarterly 6+6'!B$4) -> 0 | C11: =SUMIFS('Outlook 6+6'!$B11:$M11,'Outlook 6+6'!$B$185:$M$185,'Outlook Quarterly 6+6'!C$4) -> 0 | D11: =SUMIFS('Outlook 6+6'!$B11:$M11,'Outlook 6+6'!$B$185:$M$185,'Outlook Quarterly 6+6'!D$4) -> 0 | E11: =SUMIFS('Outlook 6+6'!$B11:$M11,'Outlook 6+6'!$B$185:$M$185,'Outlook Quarterly 6+6'!E$4) -> 0 | F11: =SUM(B11:E11) -> 0 | H11: ='Budget 2025'!N11 -> 0
A12: SR ROM Total | B12: =B5/B8 -> 13.199437 | C12: =C5/C8 -> 13.109105 | D12: =D5/D8 -> 13.728364 | E12: =E5/E8 -> 13.712107 | F12: =F5/F8 -> 13.460004 | H12: ='Budget 2025'!N12 -> 13.627982
A13: FC Product (Kton) | B13: =SUM(B14:B16) -> 1698.6086 | C13: =SUM(C14:C16) -> 1656.015 | D13: =SUM(D14:D16) -> 1962.75 | E13: =SUM(E14:E16) -> 1817.6264 | F13: =SUM(B13:E13) -> 7135 | H13: ='Budget 2025'!N13 -> 7100
A14: PAMA (WB) | B14: =SUMIFS('Outlook 6+6'!$B14:$M14,'Outlook 6+6'!$B$185:$M$185,'Outlook Quarterly 6+6'!B$4) -> 568.07789 | C14: =SUMIFS('Outlook 6+6'!$B14:$M14,'Outlook 6+6'!$B$185:$M$185,'Outlook Quarterly 6+6'!C$4) -> 360.70167 | D14: =SUMIFS('Outlook 6+6'!$B14:$M14,'Outlook 6+6'!$B$185:$M$185,'Outlook Quarterly 6+6'!D$4) -> 465 | E14: =SUMIFS('Outlook 6+6'!$B14:$M14,'Outlook 6+6'!$B$185:$M$185,'Outlook Quarterly 6+6'!E$4) -> 336.22044 | F14: =SUM(B14:E14) -> 1730 | H14: ='Budget 2025'!N14 -> 1862.5
A15: PAMA (EB) | B15: =SUMIFS('Outlook 6+6'!$B15:$M15,'Outlook 6+6'!$B$185:$M$185,'Outlook Quarterly 6+6'!B$4) -> 1130.5307 | C15: =SUMIFS('Outlook 6+6'!$B15:$M15,'Outlook 6+6'!$B$185:$M$185,'Outlook Quarterly 6+6'!C$4) -> 1295.1119 | D15: =SUMIFS('Outlook 6+6'!$B15:$M15,'Outlook 6+6'!$B$185:$M$185,'Outlook Quarterly 6+6'!D$4) -> 1485 | E15: =SUMIFS('Outlook 6+6'!$B15:$M15,'Outlook 6+6'!$B$185:$M$185,'Outlook Quarterly 6+6'!E$4) -> 1443.156 | F15: =SUM(B15:E15) -> 5353.7986 | H15: ='Budget 2025'!N15 -> 5110
A16: Fine Coal | B16: =SUMIFS('Outlook 6+6'!$B16:$M16,'Outlook 6+6'!$B$185:$M$185,'Outlook Quarterly 6+6'!B$4) -> 0 | C16: =SUMIFS('Outlook 6+6'!$B16:$M16,'Outlook 6+6'!$B$185:$M$185,'Outlook Quarterly 6+6'!C$4) -> 0.20136899 | D16: =SUMIFS('Outlook 6+6'!$B16:$M16,'Outlook 6+6'!$B$185:$M$185,'Outlook Quarterly 6+6'!D$4) -> 12.75 | E16: =SUMIFS('Outlook 6+6'!$B16:$M16,'Outlook 6+6'!$B$185:$M$185,'Outlook Quarterly 6+6'!E$4) -> 38.25 | F16: =SUM(B16:E16) -> 51.201369 | H16: ='Budget 2025'!N48 -> 127.5
A17: SR FC Total | B17: =B5/B13 -> 12.275739 | C17: =C5/C13 -> 13.189955 | D17: =D5/D13 -> 13.606412 | E17: =E5/E13 -> 14.191835 | F17: =F5/F13 -> 13.342099 | H17: ='Budget 2025'!N17 -> 13.340067
A18: IMM-WB.HCV.LS | B18: =SUMIFS('Outlook 6+6'!$B18:$M18,'Outlook 6+6'!$B$185:$M$185,'Outlook Quarterly 6+6'!B$4) -> 398.64282 | C18: =SUMIFS('Outlook 6+6'!$B18:$M18,'Outlook 6+6'!$B$185:$M$185,'Outlook Quarterly 6+6'!C$4) -> 239.9743 | D18: =SUMIFS('Outlook 6+6'!$B18:$M18,'Outlook 6+6'!$B$185:$M$185,'Outlook Quarterly 6+6'!D$4) -> 252.87024 | E18: =SUMIFS('Outlook 6+6'!$B18:$M18,'Outlook 6+6'!$B$185:$M$185,'Outlook Quarterly 6+6'!E$4) -> 173.2387 | F18: =SUM(B18:E18) -> 1064.7261 | H18: ='Budget 2025'!N18 -> 1228.8032
A19: CV(GAR) | B19: =SUMPRODUCT('Outlook 6+6'!$B19:$D19,'Outlook 6+6'!$B$18:$D$18)/SUM('Outlook 6+6'!$B$18:$D$18) -> 6165.9257 | C19: =SUMPRODUCT('Outlook 6+6'!$E19:$G19,'Outlook 6+6'!$E$18:$G$18)/SUM('Outlook 6+6'!$E$18:$G$18) -> 6125.2907 | D19: =SUMPRODUCT('Outlook 6+6'!$H19:$J19,'Outlook 6+6'!$H$18:$J$18)/SUM('Outlook 6+6'!$H$18:$J$18) -> 6098.4069 | E19: =SUMPRODUCT('Outlook 6+6'!$K19:$M19,'Outlook 6+6'!$K$18:$M$18)/SUM('Outlook 6+6'!$K$18:$M$18) -> 6247.2227 | F19: =SUMPRODUCT(B19:E19,$B$18:$E$18)/SUM($B$18:$E$18) -> 6153.9592 | H19: ='Budget 2025'!N19 -> 6169.7769
A20: TS | B20: =SUMPRODUCT('Outlook 6+6'!$B20:$D20,'Outlook 6+6'!$B$18:$D$18)/SUM('Outlook 6+6'!$B$18:$D$18) -> 0.63594838 | C20: =SUMPRODUCT('Outlook 6+6'!$E20:$G20,'Outlook 6+6'!$E$18:$G$18)/SUM('Outlook 6+6'!$E$18:$G$18) -> 0.70273826 | D20: =SUMPRODUCT('Outlook 6+6'!$H20:$J20,'Outlook 6+6'!$H$18:$J$18)/SUM('Outlook 6+6'!$H$18:$J$18) -> 0.93499887 | E20: =SUMPRODUCT('Outlook 6+6'!$K20:$M20,'Outlook 6+6'!$K$18:$M$18)/SUM('Outlook 6+6'!$K$18:$M$18) -> 0.85810607 | F20: =SUMPRODUCT(B20:E20,$B$18:$E$18)/SUM($B$18:$E$18) -> 0.75817243 | H20: ='Budget 2025'!N20 -> 0.81080181
A21: Ash | B21: =SUMPRODUCT('Outlook 6+6'!$B21:$D21,'Outlook 6+6'!$B$18:$D$18)/SUM('Outlook 6+6'!$B$18:$D$18) -> 8.4258284 | C21: =SUMPRODUCT('Outlook 6+6'!$E21:$G21,'Outlook 6+6'!$E$18:$G$18)/SUM('Outlook 6+6'!$E$18:$G$18) -> 8.0792853 | D21: =SUMPRODUCT('Outlook 6+6'!$H21:$J21,'Outlook 6+6'!$H$18:$J$18)/SUM('Outlook 6+6'!$H$18:$J$18) -> 8.9672132 | E21: =SUMPRODUCT('Outlook 6+6'!$K21:$M21,'Outlook 6+6'!$K$18:$M$18)/SUM('Outlook 6+6'!$K$18:$M$18) -> 8.6997645 | F21: =SUMPRODUCT(B21:E21,$B$18:$E$18)/SUM($B$18:$E$18) -> 8.5208716 | H21: ='Budget 2025'!N21 -> 8.3745645
A22: Moist | B22: =SUMPRODUCT('Outlook 6+6'!$B22:$D22,'Outlook 6+6'!$B$18:$D$18)/SUM('Outlook 6+6'!$B$18:$D$18) -> 8.9485957 | C22: =SUMPRODUCT('Outlook 6+6'!$E22:$G22,'Outlook 6+6'!$E$18:$G$18)/SUM('Outlook 6+6'!$E$18:$G$18) -> 9.2901326 | D22: =SUMPRODUCT('Outlook 6+6'!$H22:$J22,'Outlook 6+6'!$H$18:$J$18)/SUM('Outlook 6+6'!$H$18:$J$18) -> 8.1417202 | E22: =SUMPRODUCT('Outlook 6+6'!$K22:$M22,'Outlook 6+6'!$K$18:$M$18)/SUM('Outlook 6+6'!$K$18:$M$18) -> 7.2312888 | F22: =SUMPRODUCT(B22:E22,$B$18:$E$18)/SUM($B$18:$E$18) -> 8.5545237 | H22: ='Budget 2025'!N22 -> 8.0403443
A23: TM | B23: =SUMPRODUCT('Outlook 6+6'!$B23:$D23,'Outlook 6+6'!$B$18:$D$18)/SUM('Outlook 6+6'!$B$18:$D$18) -> 11.704989 | C23: =SUMPRODUCT('Outlook 6+6'!$E23:$G23,'Outlook 6+6'!$E$18:$G$18)/SUM('Outlook 6+6'!$E$18:$G$18) -> 12.490927 | D23: =SUMPRODUCT('Outlook 6+6'!$H23:$J23,'Outlook 6+6'!$H$18:$J$18)/SUM('Outlook 6+6'!$H$18:$J$18) -> 13.019212 | E23: =SUMPRODUCT('Outlook 6+6'!$K23:$M23,'Outlook 6+6'!$K$18:$M$18)/SUM('Outlook 6+6'!$K$18:$M$18) -> 12.256651 | F23: =SUMPRODUCT(B23:E23,$B$18:$E$18)/SUM($B$18:$E$18) -> 12.284013 | H23: ='Budget 2025'!N23 -> 13.065707
A24: IMM-WB.HCV.HS | B24: =SUMIFS('Outlook 6+6'!$B24:$M24,'Outlook 6+6'!$B$185:$M$185,'Outlook Quarterly 6+6'!B$4) -> 169.43507 | C24: =SUMIFS('Outlook 6+6'!$B24:$M24,'Outlook 6+6'!$B$185:$M$185,'Outlook Quarterly 6+6'!C$4) -> 120.72737 | D24: =SUMIFS('Outlook 6+6'!$B24:$M24,'Outlook 6+6'!$B$185:$M$185,'Outlook Quarterly 6+6'!D$4) -> 212.12976 | E24: =SUMIFS('Outlook 6+6'!$B24:$M24,'Outlook 6+6'!$B$185:$M$185,'Outlook Quarterly 6+6'!E$4) -> 162.98175 | F24: =SUM(B24:E24) -> 665.27394 | H24: ='Budget 2025'!N24 -> 633.69685
A25: CV(GAR) | B25: =SUMPRODUCT('Outlook 6+6'!$B25:$D25,'Outlook 6+6'!$B$24:$D$24)/SUM('Outlook 6+6'!$B$24:$D$24) -> 5965.8964 | C25: =SUMPRODUCT('Outlook 6+6'!$E25:$G25,'Outlook 6+6'!$E$24:$G$24)/SUM('Outlook 6+6'!$E$24:$G$24) -> 6003.1615 | D25: =SUMPRODUCT('Outlook 6+6'!$H25:$J25,'Outlook 6+6'!$H$24:$J$24)/SUM('Outlook 6+6'!$H$24:$J$24) -> 5960.1454 | E25: =SUMPRODUCT('Outlook 6+6'!$K25:$M25,'Outlook 6+6'!$K$24:$M$24)/SUM('Outlook 6+6'!$K$24:$M$24) -> 5831.4598 | F25: =SUMPRODUCT(B25:E25,$B$24:$E$24)/SUM($B$24:$E$24) -> 5937.8903 | H25: ='Budget 2025'!N25 -> 5965.7827
A26: TS | B26: =SUMPRODUCT('Outlook 6+6'!$B26:$D26,'Outlook 6+6'!$B$24:$D$24)/SUM('Outlook 6+6'!$B$24:$D$24) -> 2.1512944 | C26: =SUMPRODUCT('Outlook 6+6'!$E26:$G26,'Outlook 6+6'!$E$24:$G$24)/SUM('Outlook 6+6'!$E$24:$G$24) -> 2.1950047 | D26: =SUMPRODUCT('Outlook 6+6'!$H26:$J26,'Outlook 6+6'!$H$24:$J$24)/SUM('Outlook 6+6'!$H$24:$J$24) -> 2.649241 | E26: =SUMPRODUCT('Outlook 6+6'!$K26:$M26,'Outlook 6+6'!$K$24:$M$24)/SUM('Outlook 6+6'!$K$24:$M$24) -> 2.7046075 | F26: =SUMPRODUCT(B26:E26,$B$24:$E$24)/SUM($B$24:$E$24) -> 2.4535552 | H26: ='Budget 2025'!N26 -> 2.5790489
A27: Ash | B27: =SUMPRODUCT('Outlook 6+6'!$B27:$D27,'Outlook 6+6'!$B$24:$D$24)/SUM('Outlook 6+6'!$B$24:$D$24) -> 11.823332 | C27: =SUMPRODUCT('Outlook 6+6'!$E27:$G27,'Outlook 6+6'!$E$24:$G$24)/SUM('Outlook 6+6'!$E$24:$G$24) -> 11.747991 | D27: =SUMPRODUCT('Outlook 6+6'!$H27:$J27,'Outlook 6+6'!$H$24:$J$24)/SUM('Outlook 6+6'!$H$24:$J$24) -> 12.89268 | E27: =SUMPRODUCT('Outlook 6+6'!$K27:$M27,'Outlook 6+6'!$K$24:$M$24)/SUM('Outlook 6+6'!$K$24:$M$24) -> 15.997435 | F27: =SUMPRODUCT(B27:E27,$B$24:$E$24)/SUM($B$24:$E$24) -> 13.173223 | H27: ='Budget 2025'!N27 -> 13.960595
A28: Moist | B28: =SUMPRODUCT('Outlook 6+6'!$B28:$D28,'Outlook 6+6'!$B$24:$D$24)/SUM('Outlook 6+6'!$B$24:$D$24) -> 7.4970729 | C28: =SUMPRODUCT('Outlook 6+6'!$E28:$G28,'Outlook 6+6'!$E$24:$G$24)/SUM('Outlook 6+6'!$E$24:$G$24) -> 7.1696845 | D28: =SUMPRODUCT('Outlook 6+6'!$H28:$J28,'Outlook 6+6'!$H$24:$J$24)/SUM('Outlook 6+6'!$H$24:$J$24) -> 7.4230887 | E28: =SUMPRODUCT('Outlook 6+6'!$K28:$M28,'Outlook 6+6'!$K$24:$M$24)/SUM('Outlook 6+6'!$K$24:$M$24) -> 7.194551 | F28: =SUMPRODUCT(B28:E28,$B$24:$E$24)/SUM($B$24:$E$24) -> 7.3399579 | H28: ='Budget 2025'!N28 -> 6.7439986
A29: TM | B29: =SUMPRODUCT('Outlook 6+6'!$B29:$D29,'Outlook 6+6'!$B$24:$D$24)/SUM('Outlook 6+6'!$B$24:$D$24) -> 11.361645 | C29: =SUMPRODUCT('Outlook 6+6'!$E29:$G29,'Outlook 6+6'!$E$24:$G$24)/SUM('Outlook 6+6'!$E$24:$G$24) -> 11.096743 | D29: =SUMPRODUCT('Outlook 6+6'!$H29:$J29,'Outlook 6+6'!$H$24:$J$24)/SUM('Outlook 6+6'!$H$24:$J$24) -> 12.380263 | E29: =SUMPRODUCT('Outlook 6+6'!$K29:$M29,'Outlook 6+6'!$K$24:$M$24)/SUM('Outlook 6+6'!$K$24:$M$24) -> 12.219913 | F29: =SUMPRODUCT(B29:E29,$B$24:$E$24)/SUM($B$24:$E$24) -> 11.848633 | H29: ='Budget 2025'!N29 -> 11.769361
A30: IMM-EB.MCV.LS | B30: =SUMIFS('Outlook 6+6'!$B30:$M30,'Outlook 6+6'!$B$185:$M$185,'Outlook Quarterly 6+6'!B$4) -> 17.998535 | C30: =SUMIFS('Outlook 6+6'!$B30:$M30,'Outlook 6+6'!$B$185:$M$185,'Outlook Quarterly 6+6'!C$4) -> 22.615224 | D30: =SUMIFS('Outlook 6+6'!$B30:$M30,'Outlook 6+6'!$B$185:$M$185,'Outlook Quarterly 6+6'!D$4) -> 0 | E30: =SUMIFS('Outlook 6+6'!$B30:$M30,'Outlook 6+6'!$B$185:$M$185,'Outlook Quarterly 6+6'!E$4) -> 0 | F30: =SUM(B30:E30) -> 40.613759 | H30: ='Budget 2025'!N30 -> 13.639936
A31: CV(GAR) | B31: =SUMPRODUCT('Outlook 6+6'!$B31:$D31,'Outlook 6+6'!$B$30:$D$30)/SUM('Outlook 6+6'!$B$30:$D$30) -> 5860.2842 | C31: =SUMPRODUCT('Outlook 6+6'!$E31:$G31,'Outlook 6+6'!$E$30:$G$30)/SUM('Outlook 6+6'!$E$30:$G$30) -> 5977.0925 | D31: =IFERROR(SUMPRODUCT('Outlook 6+6'!$H31:$J31,'Outlook 6+6'!$H$30:$J$30)/SUM('Outlook 6+6'!$H$30:$J$30),0) -> 0 | E31: =IFERROR(SUMPRODUCT('Outlook 6+6'!$K31:$M31,'Outlook 6+6'!$K$30:$M$30)/SUM('Outlook 6+6'!$K$30:$M$30),0) -> 0 | F31: =SUMPRODUCT(B31:E31,$B$30:$E$30)/SUM($B$30:$E$30) -> 5925.3273 | H31: ='Budget 2025'!N31 -> 5822.4314
A32: TS | B32: =SUMPRODUCT('Outlook 6+6'!$B32:$D32,'Outlook 6+6'!$B$30:$D$30)/SUM('Outlook 6+6'!$B$30:$D$30) -> 0.92078055 | C32: =SUMPRODUCT('Outlook 6+6'!$E32:$G32,'Outlook 6+6'!$E$30:$G$30)/SUM('Outlook 6+6'!$E$30:$G$30) -> 0.91930839 | D32: =IFERROR(SUMPRODUCT('Outlook 6+6'!$H32:$J32,'Outlook 6+6'!$H$30:$J$30)/SUM('Outlook 6+6'!$H$30:$J$30),0) -> 0 | E32: =IFERROR(SUMPRODUCT('Outlook 6+6'!$K32:$M32,'Outlook 6+6'!$K$30:$M$30)/SUM('Outlook 6+6'!$K$30:$M$30),0) -> 0 | F32: =SUMPRODUCT(B32:E32,$B$30:$E$30)/SUM($B$30:$E$30) -> 0.9199608 | H32: ='Budget 2025'!N32 -> 0.90072278
A33: Ash | B33: =SUMPRODUCT('Outlook 6+6'!$B33:$D33,'Outlook 6+6'!$B$30:$D$30)/SUM('Outlook 6+6'!$B$30:$D$30) -> 7.1845522 | C33: =SUMPRODUCT('Outlook 6+6'!$E33:$G33,'Outlook 6+6'!$E$30:$G$30)/SUM('Outlook 6+6'!$E$30:$G$30) -> 5.8754678 | D33: =IFERROR(SUMPRODUCT('Outlook 6+6'!$H33:$J33,'Outlook 6+6'!$H$30:$J$30)/SUM('Outlook 6+6'!$H$30:$J$30),0) -> 0 | E33: =IFERROR(SUMPRODUCT('Outlook 6+6'!$K33:$M33,'Outlook 6+6'!$K$30:$M$30)/SUM('Outlook 6+6'!$K$30:$M$30),0) -> 0 | F33: =SUMPRODUCT(B33:E33,$B$30:$E$30)/SUM($B$30:$E$30) -> 6.4556062 | H33: ='Budget 2025'!N33 -> 8.5977728
A34: Moist | B34: =SUMPRODUCT('Outlook 6+6'!$B34:$D34,'Outlook 6+6'!$B$30:$D$30)/SUM('Outlook 6+6'!$B$30:$D$30) -> 11.01636 | C34: =SUMPRODUCT('Outlook 6+6'!$E34:$G34,'Outlook 6+6'!$E$30:$G$30)/SUM('Outlook 6+6'!$E$30:$G$30) -> 11.460733 | D34: =IFERROR(SUMPRODUCT('Outlook 6+6'!$H34:$J34,'Outlook 6+6'!$H$30:$J$30)/SUM('Outlook 6+6'!$H$30:$J$30),0) -> 0 | E34: =IFERROR(SUMPRODUCT('Outlook 6+6'!$K34:$M34,'Outlook 6+6'!$K$30:$M$30)/SUM('Outlook 6+6'!$K$30:$M$30),0) -> 0 | F34: =SUMPRODUCT(B34:E34,$B$30:$E$30)/SUM($B$30:$E$30) -> 11.263803 | H34: ='Budget 2025'!N34 -> 11.354386
A35: TM | B35: =SUMPRODUCT('Outlook 6+6'!$B35:$D35,'Outlook 6+6'!$B$30:$D$30)/SUM('Outlook 6+6'!$B$30:$D$30) -> 14.501869 | C35: =SUMPRODUCT('Outlook 6+6'!$E35:$G35,'Outlook 6+6'!$E$30:$G$30)/SUM('Outlook 6+6'!$E$30:$G$30) -> 14.55176 | D35: =IFERROR(SUMPRODUCT('Outlook 6+6'!$H35:$J35,'Outlook 6+6'!$H$30:$J$30)/SUM('Outlook 6+6'!$H$30:$J$30),0) -> 0 | E35: =IFERROR(SUMPRODUCT('Outlook 6+6'!$K35:$M35,'Outlook 6+6'!$K$30:$M$30)/SUM('Outlook 6+6'!$K$30:$M$30),0) -> 0 | F35: =SUMPRODUCT(B35:E35,$B$30:$E$30)/SUM($B$30:$E$30) -> 14.52965 | H35: ='Budget 2025'!N35 -> 16.354386
A36: IMM-EB.MCV.MS | B36: =SUMIFS('Outlook 6+6'!$B36:$M36,'Outlook 6+6'!$B$185:$M$185,'Outlook Quarterly 6+6'!B$4) -> 48.098999 | C36: =SUMIFS('Outlook 6+6'!$B36:$M36,'Outlook 6+6'!$B$185:$M$185,'Outlook Quarterly 6+6'!C$4) -> 98.069733 | D36: =SUMIFS('Outlook 6+6'!$B36:$M36,'Outlook 6+6'!$B$185:$M$185,'Outlook Quarterly 6+6'!D$4) -> 145.61945 | E36: =SUMIFS('Outlook 6+6'!$B36:$M36,'Outlook 6+6'!$B$185:$M$185,'Outlook Quarterly 6+6'!E$4) -> 221.98897 | F36: =SUM(B36:E36) -> 513.77715 | H36: ='Budget 2025'!N36 -> 422.71546
A37: CV(GAR) | B37: =SUMPRODUCT('Outlook 6+6'!$B37:$D37,'Outlook 6+6'!$B$36:$D$36)/SUM('Outlook 6+6'!$B$36:$D$36) -> 5977.8247 | C37: =SUMPRODUCT('Outlook 6+6'!$E37:$G37,'Outlook 6+6'!$E$36:$G$36)/SUM('Outlook 6+6'!$E$36:$G$36) -> 6012.8659 | D37: =IFERROR(SUMPRODUCT('Outlook 6+6'!$H37:$J37,'Outlook 6+6'!$H$36:$J$36)/SUM('Outlook 6+6'!$H$36:$J$36),0) -> 5992.987 | E37: =IFERROR(SUMPRODUCT('Outlook 6+6'!$K37:$M37,'Outlook 6+6'!$K$36:$M$36)/SUM('Outlook 6+6'!$K$36:$M$36),0) -> 6020.7454 | F37: =SUMPRODUCT(B37:E37,$B$36:$E$36)/SUM($B$36:$E$36) -> 6007.3557 | H37: ='Budget 2025'!N37 -> 6013.6725
A38: TS | B38: =SUMPRODUCT('Outlook 6+6'!$B38:$D38,'Outlook 6+6'!$B$36:$D$36)/SUM('Outlook 6+6'!$B$36:$D$36) -> 1.4343487 | C38: =SUMPRODUCT('Outlook 6+6'!$E38:$G38,'Outlook 6+6'!$E$36:$G$36)/SUM('Outlook 6+6'!$E$36:$G$36) -> 1.4615114 | D38: =IFERROR(SUMPRODUCT('Outlook 6+6'!$H38:$J38,'Outlook 6+6'!$H$36:$J$36)/SUM('Outlook 6+6'!$H$36:$J$36),0) -> 1.5898738 | E38: =IFERROR(SUMPRODUCT('Outlook 6+6'!$K38:$M38,'Outlook 6+6'!$K$36:$M$36)/SUM('Outlook 6+6'!$K$36:$M$36),0) -> 1.5796087 | F38: =SUMPRODUCT(B38:E38,$B$36:$E$36)/SUM($B$36:$E$36) -> 1.5463767 | H38: ='Budget 2025'!N38 -> 1.5594733
A39: Ash | B39: =SUMPRODUCT('Outlook 6+6'!$B39:$D39,'Outlook 6+6'!$B$36:$D$36)/SUM('Outlook 6+6'!$B$36:$D$36) -> 6.0426735 | C39: =SUMPRODUCT('Outlook 6+6'!$E39:$G39,'Outlook 6+6'!$E$36:$G$36)/SUM('Outlook 6+6'!$E$36:$G$36) -> 5.6967651 | D39: =IFERROR(SUMPRODUCT('Outlook 6+6'!$H39:$J39,'Outlook 6+6'!$H$36:$J$36)/SUM('Outlook 6+6'!$H$36:$J$36),0) -> 5.8593879 | E39: =IFERROR(SUMPRODUCT('Outlook 6+6'!$K39:$M39,'Outlook 6+6'!$K$36:$M$36)/SUM('Outlook 6+6'!$K$36:$M$36),0) -> 5.344327 | F39: =SUMPRODUCT(B39:E39,$B$36:$E$36)/SUM($B$36:$E$36) -> 5.6229617 | H39: ='Budget 2025'!N39 -> 5.3287414
A40: Moist | B40: =SUMPRODUCT('Outlook 6+6'!$B40:$D40,'Outlook 6+6'!$B$36:$D$36)/SUM('Outlook 6+6'!$B$36:$D$36) -> 11.610247 | C40: =SUMPRODUCT('Outlook 6+6'!$E40:$G40,'Outlook 6+6'!$E$36:$G$36)/SUM('Outlook 6+6'!$E$36:$G$36) -> 11.878149 | D40: =IFERROR(SUMPRODUCT('Outlook 6+6'!$H40:$J40,'Outlook 6+6'!$H$36:$J$36)/SUM('Outlook 6+6'!$H$36:$J$36),0) -> 10.442204 | E40: =IFERROR(SUMPRODUCT('Outlook 6+6'!$K40:$M40,'Outlook 6+6'!$K$36:$M$36)/SUM('Outlook 6+6'!$K$36:$M$36),0) -> 10.110353 | F40: =SUMPRODUCT(B40:E40,$B$36:$E$36)/SUM($B$36:$E$36) -> 10.682264 | H40: ='Budget 2025'!N40 -> 10.279207
A41: TM | B41: =SUMPRODUCT('Outlook 6+6'!$B41:$D41,'Outlook 6+6'!$B$36:$D$36)/SUM('Outlook 6+6'!$B$36:$D$36) -> 14.141402 | C41: =SUMPRODUCT('Outlook 6+6'!$E41:$G41,'Outlook 6+6'!$E$36:$G$36)/SUM('Outlook 6+6'!$E$36:$G$36) -> 14.076956 | D41: =IFERROR(SUMPRODUCT('Outlook 6+6'!$H41:$J41,'Outlook 6+6'!$H$36:$J$36)/SUM('Outlook 6+6'!$H$36:$J$36),0) -> 15.440891 | E41: =IFERROR(SUMPRODUCT('Outlook 6+6'!$K41:$M41,'Outlook 6+6'!$K$36:$M$36)/SUM('Outlook 6+6'!$K$36:$M$36),0) -> 15.110353 | F41: =SUMPRODUCT(B41:E41,$B$36:$E$36)/SUM($B$36:$E$36) -> 14.916071 | H41: ='Budget 2025'!N41 -> 15.279207
...

Sheet BudgVSact. June
B2: SITES | C2: OB | E2: ROM | G2: FC | I2: SR (OB/ROM) | K2: Diff. (Act.%)
C3: Budget | D3: Actual | E3: Budget | F3: Actual | G3: Budget | H3: Actual | I3: Budget | J3: Actual | K3: OB | L3: ROM
B4: IMM | C4: =SUM('Budget 2025'!B5:G5) -> 45360.043 | D4: =SUM('Outlook 6+6'!B5:G5) -> 42694.438 | E4: =SUM('Budget 2025'!B8:G8) -> 3220 | F4: =SUM('Outlook 6+6'!B8:G8) -> 3245.9681 | G4: =SUM('Budget 2025'!B13:G13) -> 3275.5 | H4: =SUM('Outlook 6+6'!B13:G13) -> 3354.6236 | I4: =C4/E4 -> 14.08697 | J4: =D4/F4 -> 13.153067 | K4: =D4/C4 -> 0.9412345 | L4: =F4/E4 -> 1.0080646
B5: TCM | C5: =SUM('Budget 2025'!B56:G56) -> 25550 | D5: =SUM('Outlook 6+6'!B56:G56) -> 20130.313 | E5: =SUM('Budget 2025'!B60:G60) -> 1487 | F5: =SUM('Outlook 6+6'!B60:G60) -> 1343.5369 | G5: =SUM('Budget 2025'!B65:G65) -> 1562 | H5: =SUM('Outlook 6+6'!B66:G66) -> 1462.0756 | I5: =C5/E5 -> 17.182246 | J5: =D5/F5 -> 14.983074 | K5: =D5/C5 -> 0.78787918 | L5: =F5/E5 -> 0.9035218
B6: BEK | C6: =SUM('Budget 2025'!B105:G105) -> 45094 | D6: =SUM('Outlook 6+6'!B100:G100) -> 39545.484 | E6: =SUM('Budget 2025'!B109:G109) -> 3966.5 | F6: =SUM('Outlook 6+6'!B104:G104) -> 4387.4354 | G6: =SUM('Budget 2025'!B115:G115) -> 4050 | H6: =SUM('Outlook 6+6'!B110:G110) -> 4230.0256 | I6: =C6/E6 -> 11.368713 | J6: =D6/F6 -> 9.0133484 | K6: =D6/C6 -> 0.87695667 | L6: =F6/E6 -> 1.1061226
B7: JBG | C7: =SUM('Budget 2025'!B130:G130) -> 1603.028 | D7: =SUM('Outlook 6+6'!B125:G125) -> 47.865 | E7: =SUM('Budget 2025'!B132:G132) -> 57 | F7: =SUM('Outlook 6+6'!B127:G127) -> 0 | G7: =SUM('Budget 2025'!B137:G137) -> 53 | H7: =SUM('Outlook 6+6'!B132:G132) -> 0 | I7: =C7/E7 -> 28.123298 | J7: =D7/F7 -> #DIV/0! | K7: =D7/C7 -> 0.029859117 | L7: =F7/E7 -> 0
B8: GPK | C8: =SUM('Budget 2025'!B145:G145) -> 3825 | D8: =SUM('Outlook 6+6'!B140:G140) -> 3616.9188 | E8: =SUM('Budget 2025'!B147:G147) -> 1062 | F8: =SUM('Outlook 6+6'!B142:G142) -> 1176.9001 | G8: =SUM('Budget 2025'!B152:G152) -> 1100 | H8: =SUM('Outlook 6+6'!B148:G148) -> 1175.4582 | I8: =C8/E8 -> 3.6016949 | J8: =D8/F8 -> 3.0732591 | K8: =D8/C8 -> 0.94559969 | L8: =F8/E8 -> 1.1081921
B9: TIS | C9: =SUM('Budget 2025'!B160:G160) -> 4924.429 | D9: =SUM('Outlook 6+6'!B156:G156) -> 4484.7972 | E9: =SUM('Budget 2025'!B162:G162) -> 270.88602 | F9: =SUM('Outlook 6+6'!B158:G158) -> 263.88573 | G9: =SUM('Budget 2025'!B166:G166) -> 245 | H9: =SUM('Outlook 6+6'!B163:G163) -> 153.86795 | I9: =C9/E9 -> 18.178971 | J9: =D9/F9 -> 16.995224 | K9: =D9/C9 -> 0.9107243 | L9: =F9/E9 -> 0.9741578
B10: TOTAL | C10: =SUM(C4:C9) -> 126356.5 | D10: =SUM(D4:D9) -> 110519.82 | E10: =SUM(E4:E9) -> 10063.386 | F10: =SUM(F4:F9) -> 10417.726 | G10: =SUM(G4:G9) -> 10285.5 | H10: =SUM(H4:H9) -> 10376.051 | I10: =C10/E10 -> 12.556062 | J10: =D10/F10 -> 10.608823 | K10: =D10/C10 -> 0.87466664 | L10: =F10/E10 -> 1.0352108
F11: =F10/E10 -> 1.0352108 | H11: =H10/G10 -> 1.0088037
