Workbook
Name _1__MINE_STOCKYARD_34: #REF!
Name _1__MINE_STOCKYARD_34: #REF!
Name _1__MINE_STOCKYARD_34: #REF!
Name _1__MINE_STOCKYARD_34: #REF!
Name _1__MINE_STOCKYARD_34: #REF!
Name _1__MINE_STOCKYARD_34: #REF!
Name _1__MINE_STOCKYARD_34: #REF!
Name _1__MINE_STOCKYARD_34: #REF!
Name _1__MINE_STOCKYARD_34: #REF!
Name _1__MINE_STOCKYARD_34: #REF!
Name _1__MINE_STOCKYARD_34: #REF!
Name _1__MINE_STOCKYARD_34: #REF!
Name _1__MINE_STOCKYARD_34_10: #REF!
Name _1__MINE_STOCKYARD_34_10: #REF!
Name _1__MINE_STOCKYARD_34_10: #REF!
Name _1__MINE_STOCKYARD_34_10: #REF!
Name _1__MINE_STOCKYARD_34_10: #REF!
Name _1__MINE_STOCKYARD_34_10: #REF!
Name _1__MINE_STOCKYARD_34_10: #REF!
Name _1__MINE_STOCKYARD_34_10: #REF!
Name _1__MINE_STOCKYARD_34_10: #REF!
Name _1__MINE_STOCKYARD_34_10: #REF!
Name _1__MINE_STOCKYARD_34_10: #REF!
Name _1__MINE_STOCKYARD_34_12: #REF!
Name _1__MINE_STOCKYARD_34_12: #REF!
Name _1__MINE_STOCKYARD_34_12: #REF!
Name _1__MINE_STOCKYARD_34_12: #REF!
Name _1__MINE_STOCKYARD_34_12: #REF!
Name _1__MINE_STOCKYARD_34_12: #REF!
Name _1__MINE_STOCKYARD_34_12: #REF!
Name _1__MINE_STOCKYARD_34_12: #REF!
Name _1__MINE_STOCKYARD_34_12: #REF!
Name _1__MINE_STOCKYARD_34_12: #REF!
Name _1__MINE_STOCKYARD_34_12: #REF!
Name _1__MINE_STOCKYARD_34_13: #REF!
Name _1__MINE_STOCKYARD_34_13: #REF!
Name _1__MINE_STOCKYARD_34_13: #REF!
Name _1__MINE_STOCKYARD_34_13: #REF!
Name _1__MINE_STOCKYARD_34_13: #REF!
Name _1__MINE_STOCKYARD_34_4: #REF!
Name _1__MINE_STOCKYARD_34_4: #REF!
Name _1__MINE_STOCKYARD_34_4: #REF!
Name _1__MINE_STOCKYARD_34_4: #REF!
Name _1__MINE_STOCKYARD_34_4: #REF!
Name _1A1_Z1...A10_Z10: #REF!
Name _1A1_Z1...A10_Z10: #REF!
Name _1A1_Z1...A10_Z10: #REF!
Name _1A1_Z1...A10_Z10: #REF!
Name _1A1_Z1...A10_Z10: #REF!
Name _1A1_Z1...A10_Z10: #REF!
Name _1A1_Z1...A10_Z10: #REF!
Name _1A1_Z1...A10_Z10: #REF!
Name _1A1_Z1...A10_Z10: #REF!
Name _1A1_Z1...A10_Z10: #REF!
Name _Apr: #REF!
Name _Apr: [1]Validation!$A$33
Name _Apr: [2]Validation!$A$33
Name _Aug: #REF!
Name _Aug: [1]Validation!$A$37
Name _Aug: [2]Validation!$A$37

Sheet Summary
B3: Descriptions | C3: Unit | D3: IMM | F3: TCM | H3: BEK | J3: JBG | L3: GPK | N3: TIS | P3: NPR | R3: EBP (3rd Party) | S3: TOTAL
D4: 1st Draft | E4: 2nd Draft | F4: 1st Draft | G4: 2nd Draft | H4: 1st Draft | I4: 2nd Draft | J4: 1st Draft | K4: 2nd Draft | L4: 1st Draft | M4: 2nd Draft | N4: 1st Draft | O4: 2nd Draft | P4: 1st Draft | Q4: 2nd Draft | S4: 1st Draft | T4: 2nd Draft
B5: OB Removal | C5: KBCM | D5: 78721.154 | E5: ='IMM 2025'!O8 -> 94714.478 | F5: 50840 | G5: ='TCM 2025'!O8 -> 51650 | H5: 90480 | I5: ='BEK 2025'!O8 -> 90950 | J5: 4423.838 | K5: ='JBG 2025'!O8 -> 5038.608 | L5: 8500 | M5: ='GPK 2025'!P7 -> 8500 | N5: 12308.953 | O5: ='TIS 2025'!O8 -> 12700.68 | P5: 10587 | Q5: ='NPR 2025'!O8 -> 5683.5 | S5: =SUM(D5,F5,H5,J5,L5,N5,P5) -> 255860.95 | T5: =SUM(E5,G5,I5,K5,M5,O5,Q5) -> 269237.27
B6: ROM production | C6: Kton | D6: 6000 | E6: ='IMM 2025'!O9 -> 7100 | F6: 3300.387 | G6: ='TCM 2025'!O9 -> 3300.387 | H6: 8008 | I6: ='BEK 2025'!O9 -> 8000 | J6: 316.831 | K6: ='JBG 2025'!O9 -> 448 | L6: 2100 | M6: ='GPK 2025'!P8 -> 2100 | N6: 666.98441 | O6: ='TIS 2025'!O9 -> 606 | P6: 700 | Q6: ='NPR 2025'!O9 -> 450 | S6: =SUM(D6,F6,H6,J6,L6,N6,P6) -> 21092.202 | T6: =SUM(E6,G6,I6,K6,M6,O6,Q6) -> 22004.387
B7: FC production | C7: Kton | D7: 6127.5 | E7: ='IMM 2025'!O10 -> 7100 | F7: 3200 | G7: ='TCM 2025'!O10 -> 3230 | H7: 7950 | I7: ='BEK 2025'!O10 -> 8100 | J7: 304.00971 | K7: ='JBG 2025'!O10 -> 433 | L7: 2050 | M7: ='GPK 2025'!P9 -> 2050 | N7: 625 | O7: ='TIS 2025'!O10 -> 590 | P7: 682.5 | Q7: ='NPR 2025'!O10 -> 300 | R7: =('EBP - 3rd Party Coal'!S36)/1000 -> 5501.8 | S7: =SUM(D7,F7,H7,J7,L7,N7,P7,R7) -> 26440.81 | T7: =SUM(E7,G7,I7,K7,M7,O7,Q7,R7) -> 27304.8
B8: SR (OB:ROM) | C8: BCM/Ton | D8: 13.120192 | E8: ='IMM 2025'!O11 -> 13.340067 | F8: 15.404254 | G8: ='TCM 2025'!O11 -> 15.64968 | H8: 11.298701 | I8: ='BEK 2025'!O11 -> 11.36875 | J8: 13.962769 | K8: ='JBG 2025'!O11 -> 11.246893 | L8: 4.047619 | M8: ='GPK 2025'!P10 -> 4.047619 | N8: 18.454634 | O8: ='TIS 2025'!O11 -> 20.958218 | P8: 15.124286 | Q8: ='NPR 2025'!O11 -> 12.63 | S8: =S5/S6 -> 12.130594 | T8: =T5/T6 -> 12.235618
B9: SR (OB:FC) | C9: BCM/Ton | D9: 12.84719 | E9: ='IMM 2025'!O12 -> 13.340067 | F9: 15.8875 | G9: ='TCM 2025'!O12 -> 15.990712 | H9: 11.381132 | I9: ='BEK 2025'!O12 -> 11.228395 | J9: 14.551634 | K9: ='JBG 2025'!O12 -> 11.636508 | L9: 4.1463415 | M9: ='GPK 2025'!P11 -> 4.1463415 | N9: 19.694326 | O9: ='TIS 2025'!O12 -> 21.526576 | P9: 15.512088 | Q9: ='NPR 2025'!O12 -> 18.945 | S9: =S5/S7 -> 9.6767439 | T9: =T5/T7 -> 9.8604372
B12: *IMM include fine coal 150KT

Sheet ITm Conso
A1: Total ITM 2024 Production Plan - 2nd Draft
C3: 2024 | P3: Confidence level (Draft 2) | Q3: Draft 1
A4: Mine | B4: Unit | C4: Jan | D4: Feb | E4: Mar | F4: Apr | G4: May | H4: Jun | I4: Jul | J4: Aug | K4: Sep | L4: Oct | M4: Nov | N4: Dec | O4: Total
A5: ITM | P5: =((P12*O14)+(P18*O20)+(P24*O26)+(P30*O32)+(P36*O38)+(P42*O44)+(P48*O50))/O7 -> 70.958657
A6: OB removal | B6: KBCM | C6: =C13+C19+C25+C31+C37+C43+C49 -> 21524.955 | D6: =D13+D19+D25+D31+D37+D43+D49 -> 19829.632 | E6: =E13+E19+E25+E31+E37+E43+E49 -> 20321.082 | F6: =F13+F19+F25+F31+F37+F43+F49 -> 21703.339 | G6: =G13+G19+G25+G31+G37+G43+G49 -> 23064.604 | H6: =H13+H19+H25+H31+H37+H43+H49 -> 22648.128 | I6: =I13+I19+I25+I31+I37+I43+I49 -> 24797.033 | J6: =J13+J19+J25+J31+J37+J43+J49 -> 25292.544 | ... N6: =N13+N19+N25+N31+N37+N43+N49 -> 21721.126 | O6: =SUM(C6:N6) -> 269237.27
A7: ROM production | B7: Kton | C7: =C14+C20+C26+C32+C38+C44+C50 -> 1648 | D7: =D14+D20+D26+D32+D38+D44+D50 -> 1619 | E7: =E14+E20+E26+E32+E38+E44+E50 -> 1676.5 | F7: =F14+F20+F26+F32+F38+F44+F50 -> 1589 | G7: =G14+G20+G26+G32+G38+G44+G50 -> 1780 | H7: =H14+H20+H26+H32+H38+H44+H50 -> 1900 | I7: =I14+I20+I26+I32+I38+I44+I50 -> 2010.5 | J7: =J14+J20+J26+J32+J38+J44+J50 -> 2069.887 | ... N7: =N14+N20+N26+N32+N38+N44+N50 -> 1897.5 | O7: =SUM(C7:N7) -> 22004.387
A8: FC production | B8: Kton | C8: =C15+C21+C27+C33+C39+C45+C51 -> 1688.75 | D8: =D15+D21+D27+D33+D39+D45+D51 -> 1681.75 | E8: =E15+E21+E27+E33+E39+E45+E51 -> 1729.75 | F8: =F15+F21+F27+F33+F39+F45+F51 -> 1678.75 | G8: =G15+G21+G27+G33+G39+G45+G51 -> 1756.75 | H8: =H15+H21+H27+H33+H39+H45+H51 -> 1803.75 | I8: =I15+I21+I27+I33+I39+I45+I51 -> 1890.75 | J8: =J15+J21+J27+J33+J39+J45+J51 -> 1875.75 | ... N8: =N15+N21+N27+N33+N39+N45+N51 -> 1949.75 | O8: =SUM(C8:N8) -> 21803
A9: SR (OB:ROM) | B9: BCM/Ton | C9: =C6/C7 -> 13.061259 | D9: =D6/D7 -> 12.248074 | E9: =E6/E7 -> 12.121135 | F9: =F6/F7 -> 13.658489 | G9: =G6/G7 -> 12.957643 | H9: =H6/H7 -> 11.920067 | I9: =I6/I7 -> 12.333764 | J9: =J6/J7 -> 12.219288 | ... O9: =O6/O7 -> 12.235618
A10: SR (OB:FC) | B10: BCM/Ton | C10: =C6/C8 -> 12.746087 | D10: =D6/D8 -> 11.79107 | E10: =E6/E8 -> 11.747988 | F10: =F6/F8 -> 12.928274 | G10: =G6/G8 -> 13.129133 | H10: =H6/H8 -> 12.556135 | I10: =I6/I8 -> 13.114919 | J10: =J6/J8 -> 13.483963 | ... O10: =O6/O8 -> 12.348634
A12: IMM | P12: ='IMM Confidence Level'!D2 -> 66.2 | Q12: 72.4
A13: OB removal | B13: KBCM | C13: ='IMM 2025'!C8 -> 7619.4483 | D13: ='IMM 2025'!D8 -> 7224.3023 | E13: ='IMM 2025'!E8 -> 6870.0231 | F13: ='IMM 2025'!F8 -> 7815.9147 | G13: ='IMM 2025'!G8 -> 8233.4755 | H13: ='IMM 2025'!H8 -> 7596.8792 | I13: ='IMM 2025'!I8 -> 8769.11 | J13: ='IMM 2025'!J8 -> 8498.0492 | ... N13: ='IMM 2025'!N8 -> 7566.691 | O13: =SUM(C13:N13) -> 94714.478 | P13: ='[66]IMM 2024'!P6 -> 0
A14: ROM production | B14: Kton | C14: ='IMM 2025'!C9 -> 550 | D14: ='IMM 2025'!D9 -> 545 | E14: ='IMM 2025'!E9 -> 550 | F14: ='IMM 2025'!F9 -> 550 | G14: ='IMM 2025'!G9 -> 550 | H14: ='IMM 2025'!H9 -> 550 | I14: ='IMM 2025'!I9 -> 622.5 | J14: ='IMM 2025'!J9 -> 637.5 | ... N14: ='IMM 2025'!N9 -> 632.5 | O14: =SUM(C14:N14) -> 7100 | P14: ='[66]IMM 2024'!P7 -> 0
A15: FC production | B15: Kton | C15: ='IMM 2025'!C10 -> 541.75 | D15: ='IMM 2025'!D10 -> 536.75 | E15: ='IMM 2025'!E10 -> 541.75 | F15: ='IMM 2025'!F10 -> 551.75 | G15: ='IMM 2025'!G10 -> 551.75 | H15: ='IMM 2025'!H10 -> 551.75 | I15: ='IMM 2025'!I10 -> 635.75 | J15: ='IMM 2025'!J10 -> 637.75 | ... N15: ='IMM 2025'!N10 -> 637.75 | O15: =SUM(C15:N15) -> 7100 | P15: Include Fine Coal 127.5 KT
A16: SR (OB:ROM) | B16: BCM/Ton | C16: ='IMM 2025'!C11 -> 13.853542 | D16: ='IMM 2025'!D11 -> 13.255601 | E16: ='IMM 2025'!E11 -> 12.490951 | F16: ='IMM 2025'!F11 -> 14.210754 | G16: ='IMM 2025'!G11 -> 14.969956 | H16: ='IMM 2025'!H11 -> 13.812508 | I16: ='IMM 2025'!I11 -> 14.086924 | J16: ='IMM 2025'!J11 -> 13.330273 | ... N16: ='IMM 2025'!N11 -> 11.963148 | O16: =O13/O14 -> 13.340067 | P16: ='[66]IMM 2024'!P9 -> 0
A17: SR (OB:FC) | B17: BCM/Ton | C17: ='IMM 2025'!C12 -> 14.06451 | D17: ='IMM 2025'!D12 -> 13.459343 | E17: ='IMM 2025'!E12 -> 12.681169 | F17: ='IMM 2025'!F12 -> 14.165681 | G17: ='IMM 2025'!G12 -> 14.922475 | H17: ='IMM 2025'!H12 -> 13.768698 | I17: ='IMM 2025'!I12 -> 13.793331 | J17: ='IMM 2025'!J12 -> 13.325048 | ... N17: ='IMM 2025'!N12 -> 11.864666 | O17: =O13/O15 -> 13.340067 | P17: ='[66]IMM 2024'!P10 -> 0
A18: TCM | P18: ='TCM Confidence Level'!D2 -> 74.8 | Q18: 65.4
A19: OB removal | B19: KBCM | C19: ='TCM 2025'!C8 -> 4195 | D19: ='TCM 2025'!D8 -> 4015 | E19: ='TCM 2025'!E8 -> 4020 | F19: ='TCM 2025'!F8 -> 4250 | G19: ='TCM 2025'!G8 -> 4410 | H19: ='TCM 2025'!H8 -> 4660 | I19: ='TCM 2025'!I8 -> 4720 | J19: ='TCM 2025'!J8 -> 5055 | ... N19: ='TCM 2025'!N8 -> 3790 | O19: =SUM(C19:N19) -> 51650
A20: ROM production | B20: Kton | C20: ='TCM 2025'!C9 -> 200 | D20: ='TCM 2025'!D9 -> 215 | E20: ='TCM 2025'!E9 -> 217 | F20: ='TCM 2025'!F9 -> 255 | G20: ='TCM 2025'!G9 -> 285 | H20: ='TCM 2025'!H9 -> 315 | I20: ='TCM 2025'!I9 -> 310 | J20: ='TCM 2025'!J9 -> 335.38697 | ... N20: ='TCM 2025'!N9 -> 280 | O20: =SUM(C20:N20) -> 3300.387
A21: FC production | B21: Kton | C21: ='TCM 2025'!C10 -> 217 | D21: ='TCM 2025'!D10 -> 235 | E21: ='TCM 2025'!E10 -> 258 | F21: ='TCM 2025'!F10 -> 257 | G21: ='TCM 2025'!G10 -> 290 | H21: ='TCM 2025'!H10 -> 305 | I21: ='TCM 2025'!I10 -> 315 | J21: ='TCM 2025'!J10 -> 320 | ... N21: ='TCM 2025'!N10 -> 253 | O21: =SUM(C21:N21) -> 3230
A22: SR (OB:ROM) | B22: BCM/Ton | C22: ='TCM 2025'!C11 -> 20.975 | D22: ='TCM 2025'!D11 -> 18.674419 | E22: ='TCM 2025'!E11 -> 18.525346 | F22: ='TCM 2025'!F11 -> 16.666667 | G22: ='TCM 2025'!G11 -> 15.473684 | H22: ='TCM 2025'!H11 -> 14.793651 | I22: ='TCM 2025'!I11 -> 15.225806 | J22: ='TCM 2025'!J11 -> 15.072142 | ... N22: ='TCM 2025'!N11 -> 13.535714 | O22: =O19/O20 -> 15.64968
A23: SR (OB:FC) | B23: BCM/Ton | C23: ='TCM 2025'!C12 -> 19.331797 | D23: ='TCM 2025'!D12 -> 17.085106 | E23: ='TCM 2025'!E12 -> 15.581395 | F23: ='TCM 2025'!F12 -> 16.536965 | G23: ='TCM 2025'!G12 -> 15.206897 | H23: ='TCM 2025'!H12 -> 15.278689 | I23: ='TCM 2025'!I12 -> 14.984127 | J23: ='TCM 2025'!J12 -> 15.796875 | ... N23: ='TCM 2025'!N12 -> 14.980237 | O23: =O19/O21 -> 15.990712
A24: BEK | P24: ='BEK Confidence Level'!D2 -> 74 | Q24: 71.6
A25: OB removal | B25: KBCM | C25: ='BEK 2025'!C8 -> 7995 | D25: ='BEK 2025'!D8 -> 7084 | E25: ='BEK 2025'!E8 -> 7619 | F25: ='BEK 2025'!F8 -> 7232 | G25: ='BEK 2025'!G8 -> 7571 | H25: ='BEK 2025'!H8 -> 7593 | I25: ='BEK 2025'!I8 -> 8097 | J25: ='BEK 2025'!J8 -> 8330 | ... N25: ='BEK 2025'!N8 -> 7389 | O25: =SUM(C25:N25) -> 90950
A26: ROM production | B26: Kton | C26: ='BEK 2025'!C9 -> 684 | D26: ='BEK 2025'!D9 -> 658 | E26: ='BEK 2025'!E9 -> 685.5 | F26: ='BEK 2025'!F9 -> 564 | G26: ='BEK 2025'!G9 -> 663 | H26: ='BEK 2025'!H9 -> 712 | I26: ='BEK 2025'!I9 -> 745 | J26: ='BEK 2025'!J9 -> 752 | ... N26: ='BEK 2025'!N9 -> 616 | O26: =SUM(C26:N26) -> 8000
A27: FC production | B27: Kton | C27: ='BEK 2025'!C10 -> 700 | D27: ='BEK 2025'!D10 -> 700 | E27: ='BEK 2025'!E10 -> 700 | F27: ='BEK 2025'!F10 -> 650 | G27: ='BEK 2025'!G10 -> 650 | H27: ='BEK 2025'!H10 -> 650 | I27: ='BEK 2025'!I10 -> 700 | J27: ='BEK 2025'!J10 -> 710 | ... N27: ='BEK 2025'!N10 -> 640 | O27: =SUM(C27:N27) -> 8100
A28: SR (OB:ROM) | B28: BCM/Ton | C28: ='BEK 2025'!C11 -> 11.688596 | D28: ='BEK 2025'!D11 -> 10.765957 | E28: ='BEK 2025'!E11 -> 11.114515 | F28: ='BEK 2025'!F11 -> 12.822695 | G28: ='BEK 2025'!G11 -> 11.419306 | H28: ='BEK 2025'!H11 -> 10.664326 | I28: ='BEK 2025'!I11 -> 10.868456 | J28: ='BEK 2025'!J11 -> 11.077128 | ... N28: ='BEK 2025'!N11 -> 11.99513 | O28: =O25/O26 -> 11.36875
A29: SR (OB:FC) | B29: BCM/Ton | C29: ='BEK 2025'!C12 -> 11.421429 | D29: ='BEK 2025'!D12 -> 10.12 | E29: ='BEK 2025'!E12 -> 10.884286 | F29: ='BEK 2025'!F12 -> 11.126154 | G29: ='BEK 2025'!G12 -> 11.647692 | H29: ='BEK 2025'!H12 -> 11.681538 | I29: ='BEK 2025'!I12 -> 11.567143 | J29: ='BEK 2025'!J12 -> 11.732394 | ... N29: ='BEK 2025'!N12 -> 11.545313 | O29: =O25/O27 -> 11.228395
A30: JBG | P30: ='JBG Confidence Level'!D2 -> 69.4 | Q30: 73.4
A31: OB removal | B31: KBCM | C31: ='JBG 2025'!C8 -> 103.007 | D31: ='JBG 2025'!D8 -> 93.07 | E31: ='JBG 2025'!E8 -> 98.059 | F31: ='JBG 2025'!F8 -> 280.6245 | G31: ='JBG 2025'!G8 -> 579.3785 | H31: ='JBG 2025'!H8 -> 448.889 | I31: ='JBG 2025'!I8 -> 536.383 | J31: ='JBG 2025'!J8 -> 575.345 | ... N31: ='JBG 2025'!N8 -> 543.935 | O31: =SUM(C31:N31) -> 5038.608
A32: ROM production | B32: Kton | C32: ='JBG 2025'!C9 -> 0 | D32: ='JBG 2025'!D9 -> 0 | E32: ='JBG 2025'!E9 -> 0 | F32: ='JBG 2025'!F9 -> 0 | G32: ='JBG 2025'!G9 -> 20 | H32: ='JBG 2025'!H9 -> 37 | I32: ='JBG 2025'!I9 -> 51 | J32: ='JBG 2025'!J9 -> 60 | ... N32: ='JBG 2025'!N9 -> 67 | O32: =SUM(C32:N32) -> 448
A33: FC production | B33: Kton | C33: ='JBG 2025'!C10 -> 0 | D33: ='JBG 2025'!D10 -> 0 | E33: ='JBG 2025'!E10 -> 0 | F33: ='JBG 2025'!F10 -> 0 | G33: ='JBG 2025'!G10 -> 18 | H33: ='JBG 2025'!H10 -> 35 | I33: ='JBG 2025'!I10 -> 50 | J33: ='JBG 2025'!J10 -> 58 | ... N33: ='JBG 2025'!N10 -> 66 | O33: =SUM(C33:N33) -> 433
A34: SR (OB:ROM) | B34: BCM/Ton | C34: ='JBG 2025'!C11 -> #DIV/0! | D34: ='JBG 2025'!D11 -> #DIV/0! | E34: ='JBG 2025'!E11 -> #DIV/0! | F34: ='JBG 2025'!F11 -> #DIV/0! | G34: ='JBG 2025'!G11 -> 28.968925 | H34: ='JBG 2025'!H11 -> 12.132135 | I34: ='JBG 2025'!I11 -> 10.517314 | J34: ='JBG 2025'!J11 -> 9.5890833 | ... N34: ='JBG 2025'!N11 -> 8.1184328 | O34: =O31/O32 -> 11.246893
A35: SR (OB:FC) | B35: BCM/Ton | C35: ='JBG 2025'!C12 -> #DIV/0! | D35: ='JBG 2025'!D12 -> #DIV/0! | E35: ='JBG 2025'!E12 -> #DIV/0! | F35: ='JBG 2025'!F12 -> #DIV/0! | G35: ='JBG 2025'!G12 -> 32.187694 | H35: ='JBG 2025'!H12 -> 12.8254 | I35: ='JBG 2025'!I12 -> 10.72766 | J35: ='JBG 2025'!J12 -> 9.9197414 | ... N35: ='JBG 2025'!N12 -> 8.2414394 | O35: =O31/O33 -> 11.636508
A36: GPK | P36: {='GPK Confidence Level'!M4:N4} -> 70 | Q36: 0
A37: OB removal | B37: KBCM | C37: ='GPK 2025'!D7 -> 630 | D37: ='GPK 2025'!E7 -> 580 | E37: ='GPK 2025'!F7 -> 630 | F37: ='GPK 2025'!G7 -> 610 | G37: ='GPK 2025'!H7 -> 700 | H37: ='GPK 2025'!I7 -> 675 | I37: ='GPK 2025'!J7 -> 745 | J37: ='GPK 2025'!K7 -> 790 | ... N37: ='GPK 2025'!O7 -> 770 | O37: =SUM(C37:N37) -> 8500
A38: ROM production | B38: Kton | C38: ='GPK 2025'!D8 -> 184 | D38: ='GPK 2025'!E8 -> 166 | E38: ='GPK 2025'!F8 -> 182 | F38: ='GPK 2025'!G8 -> 175 | G38: ='GPK 2025'!H8 -> 180 | H38: ='GPK 2025'!I8 -> 175 | I38: ='GPK 2025'!J8 -> 160 | J38: ='GPK 2025'!K8 -> 160 | ... N38: ='GPK 2025'!O8 -> 187 | O38: =SUM(C38:N38) -> 2100
A39: FC production | B39: Kton | C39: ='GPK 2025'!D9 -> 200 | D39: ='GPK 2025'!E9 -> 180 | E39: ='GPK 2025'!F9 -> 190 | F39: ='GPK 2025'!G9 -> 175 | G39: ='GPK 2025'!H9 -> 180 | H39: ='GPK 2025'!I9 -> 175 | I39: ='GPK 2025'!J9 -> 90 | J39: ='GPK 2025'!K9 -> 50 | ... N39: ='GPK 2025'!O9 -> 250 | O39: =SUM(C39:N39) -> 2050
A40: SR (OB:ROM) | B40: BCM/Ton | C40: ='GPK 2025'!D10 -> 3.423913 | D40: ='GPK 2025'!E10 -> 3.4939759 | E40: ='GPK 2025'!F10 -> 3.4615385 | F40: ='GPK 2025'!G10 -> 3.4857143 | G40: ='GPK 2025'!H10 -> 3.8888889 | H40: ='GPK 2025'!I10 -> 3.8571429 | I40: ='GPK 2025'!J10 -> 4.65625 | J40: ='GPK 2025'!K10 -> 4.9375 | ... N40: ='GPK 2025'!O10 -> 4.1176471 | O40: =O37/O38 -> 4.047619
A41: SR (OB:FC) | B41: BCM/Ton | C41: ='GPK 2025'!D11 -> 3.15 | D41: ='GPK 2025'!E11 -> 3.2222222 | E41: ='GPK 2025'!F11 -> 3.3157895 | F41: ='GPK 2025'!G11 -> 3.4857143 | G41: ='GPK 2025'!H11 -> 3.8888889 | H41: ='GPK 2025'!I11 -> 3.8571429 | I41: ='GPK 2025'!J11 -> 8.2777778 | J41: ='GPK 2025'!K11 -> 15.8 | ... N41: ='GPK 2025'!O11 -> 3.08 | O41: =O37/O39 -> 4.1463415
A42: TIS | P42: ='TIS Confidence Level'!D3 -> 68.6 | Q42: 51.2
...

Sheet Action to Follow
C1: Action to be Follow:
B3: No. | C3: Parameter | E3: IMM | G3: TCM | I3: BEK | K3: JBG | M3: TIS | O3: NPR | Q3: GPK
E4: Descriptions | F4: Duedate | G4: Descriptions | H4: Duedate | I4: Descriptions | J4: Duedate | K4: Descriptions | L4: Duedate | M4: Descriptions | N4: Duedate | O4: Descriptions | P4: Duedate | Q4: Descriptions | R4: Duedate
B5: 1 | C5: PERMIT AND LICENSE
B6: 1.1 | C6: AMDAL & FS (Mandatory) | G6: All pit already state in AMDAL and FS | M6: 1. Already get direction PDLUK for addendum Type A (ANDAL & RKL-RPL) 2. + Readiness PERTEK & RINTEK in 2024 *Process doc. 3. TIS still use existing document of FS approval in 2010 (545/K.355a/2010) and AMDAL in 2008 (660.1/014.C/KL-X/2008) 4. improve Data Geology & Area (by Pre-production) | N6: Andal addendum: 2025 | O6: AMDAL draft revision is on progress, AMDAL awaiting for Pertek completion | Q6: - Progress Revision FS and AMDAL in 2024 -2025 | R6: 45839
B7: 1.2 | C7: RKAB & Reclamation Plan (Administration and Operation License) | E7: Need Revision RKAB 2025 For PIT 13W1 & 13ALT1 | F7: - Sep 2025 - Dec 2024 - 2025 | G7: Start to Revise RKAB 2025 in April '25 | H7: 45748 | I7: Need revise on 2Q25 if having plan to increasing production | J7: 45658 | M7: 1. Follow up the finding of ESDM, preparation Technical and Document in Q4 2024 then to submission the document RR. 2. Blending Study for base on Revise RKAB including updating LoMP and Technical Study (requierment for Revision the Document) | Q7: - RKAB approve 2024 with prod Volume 1.5 Mton, and Need RKAB revision in 2nd Smester 2025 | R7: H2 2025
B8: 1.3 | C8: Forestry Permit (Working Area) | E8: TC progress since Aug'24 and the RTB would Submitted on Dec'24 | F8: 45627 | G8: Need Timber Cruising at P3000BK20 SB2, P4400Bk25 SB2, Disposal BK23 and Cut Bk15 NB | I8: Need add. Quota to get new PPKH | M8: Get start to propose corridor permit by July 2025 & improvement data by additional data of Geology | N8: 45839 | Q8: - Already have PPKH permit , and progress preparation fulfillment Regulation and Obligation plan 2025
B9: 2 | C9: AREA READINESS
B10: 2.1 | C10: Land compensation - community issue | E10: Trees Compensation For Pit 19A | G10: Uncompensated area at Cut BK15 NB around 31.77 Ha | K10: Land compensate issue should be solve before re-disturbed permit expired in December 2024 | M10: * Area Pit location in IPPKH already compensate on year 2005, remaind of SK PPKH 1260 around +13 Ha or additional policy for Land management * Begin land management area for facility and Infra for 2025, include area prospect of Pit. | Q10: - need support land Management in Q1 2025 with area 170 Ha for Pit and Disposal area 2025 | R10: Q1 2025
B11: 2.2 | C11: Working area determination - pegging (PAK) | E11: All areas had PAK | J11: Q1 2025
B12: 2.3 | C12: Timber cruising and log cutting (PSDH/DR) | E12: TC progress since Aug'24 and finished on Nov'24 | F12: 45597 | G12: Need Timber Cruising at P3000BK20 SB2, P4400Bk25 SB2, Cut Bk15 NB, Disposal BK23 | M12: * Selection consultan / vendor for TC activity - under get register administration (Get account SIPPUH) *Already cover area of mining activies in 2025 (70%) but need to cover remaining area until end of 2025 and next year (2 years) | Q12: on progress preparation contract and plan activity timber Cruising in Q4 2024, | R12: Q4 2024
B13: 2.4 | C13: Annual Forestry Fee (PNBP) | E13: PNBP PKH for SK 281 waiting payment would be paid on End Oct.24 | F13: 45536 | M13: * PNBP PKH IPPKH SK.1260, to complete T0 in July 2024, * Need proposing revision baseline of PNBP PKH area IPPKH SK.1260 after revise FS & AMDAL in 2025 | Q13: PNBP PKH and PSDH-DR on schedule
B14: 3 | C14: GEOLOGICAL INFORMATION
B15: 3.1 | C15: Infill drilling | G15: lack of drill hole at Cut BK15 NB and Cut BK16 NB | M15: after get SK PAK and to be better get approval Log Cutting * Infill drilling plan for area IPPKH SK.1260 need cover at less 70% area prospect * To Complete Infill drilling on IPPKH SK.1260 by Q3 2024 of Priority Area Prospect | O15: Progress infill drilling 73% for infill drilling
B16: 3.2 | C16: Geological model | M16: Geological model Update as Exploration Drill end of June'24 | O16: Cut off drilling data 5 August 2024
B17: 3.3 | C17: PAF/NAF Information | M17: get complete material identification from 25% become 80% in area IPPKH1 by Sep'24 (Special in prospect area of seam 3000) | N17: 45536 | O17: PAF & NAF sample already sent to lab, awaiting for results. Handling method already determined | Q17: on progress modeling material PAF and Naf as update data drilling exploration
B18: 3.4 | C18: Ground water modelling (in the pit) | E18: Ground Water Modelling represent by regional hidrology-hidrogeology study at WB (2022) and EB (2019) | M18: 1) Install pizometer in 4 locations to identify ground water surface after get SK PAK and report Hidrogeology 2 a) Hidrogeology study commence by Oct'23 2 b) get completed analysis for area IUP by Dec'24 3) Install Piezometer as recommendation in 2025 (4 Drill hole position) | N18: 45627 | Q18: don’t have Ground water modeling in area all IUP GPK ground water modeling is part in the FS and Hydrogeology study part, and will prepare in 2024-2025 | R18: 45839
B19: 3.5 | C19: Coal Quantity (mineable) | M19: to fulfill the Exploration data and Update the Resource and Reserve The drill holes data already covered area pit 2026 (increase confident level data) base on last update on June 2024 need to additional and improvement the data for the Geologycal model end of 2024 | N19: 45627 | O19: Done for 2025, data cut off 5 August 2024
B20: 3.6 | C20: Coal Quality | O20: coal quality sample already sent to lab, awaiting for results
B21: 4 | C21: MINE PLANNING AND OPERATION
B22: 4.1 | C22: Mine planning design (pit design and scheduling) | G22: Completed running schedulling 00% (still on progress simulation material balance due to lack of area disposal) | J22: H2 2025 | O22: Pit design, OB volume, and ROM coal volume for yearly plan 2025 complete
B23: 4.2 | C23: Geothechnical information (slope stability) | G23: Need to revise design P3000 BK30 SB2 and P4400 BK26 SB2 as recommendation geotech and disposal or outpit design that need to checked by Geotech | M23: 1. complete data drilling IPPKH 1260 and IPPKH exploration for Geotech and AMD by Sep'24 2. Need to get recommendation of geotechnical for disposal design 3. IPPKH exploration for Geology & Geotech and AMD by Sep'24 cause limited area disposal in 2025 | N23: 45536 | O23: Geotechnical sample already sent to lab, awaiting for results. | Q23: on progress review and recommendation
B24: 4.3 | C24: Material management | G24: still on progress simulation material balance due to lack of area disposal at P3000Bk20 PAMA and P4400Bk26 MAP | M24: 1. Will get review TDS and MED team regarding outpit plan disposal in 2025 2. Material management in area PPKH SK1260 still need to be prepared for its readiness status (land management, timber cutting permit, disposal sequence vs availability of fleet)
B25: 4.4 | C25: Mine Dewatering: Drainage System (Pump & Pipe Requirement) and Setpond | E25: On Process detail calculation | F25: 45627 | G25: Not yet get SLO permit setpond (Estimate in Dec '24) | H25: 45627 | M25: in early 2025 need maintance the sequence mining without drainage system to out pit. 1. Complete construct settling pond by Dec'24 and approval of PERTEK Permit 2. Delay The PERTEK doc. approved and Verification and permit to operate settling pond (SLO) granted by KLHK | N25: 45627 | O25: Pump requirements still on water volume calculation and pump spesification selection | Q25: already have Pertek Settling pond, and progress trial pumping until October and propose SLO on november 2024 | R25: 45597
B26: 4.5 | C26: Reclamation | E26: Revision reclamation plan due to plan clearing higher than plan in the existing document | F26: 45565 | G26: On progress preparing boundary based on progress inpit and outpit dump | M26: Not ready RR doc. And JAMREK, need : 1. to confirm the data of Resource and Reserve, Plan Design Pit and/Outpit and LoMP 2. Reclamation plan will conduct on document propose and approval 3. in 2024 no Reclamation activities but 2025 will be update the Plan and Sequence Minining as LOMP | Q26: Reclamation plan starting in 2026
B27: 5 | C27: SUPPORTING FACILITY
B28: 5.1 | C28: Contractor readiness (mining) | G28: PJPN and PAMA Production Y2025 as exisiting capacity in Y2024, MAP need additional fleet 1xPC500 to increase production as target | M28: Speed up readiness manpower of UFA & PJPN (inc. facilities of mess) | Q28: - Mining contractor PT arka contract valid until December 31st 2024, On progress amendment contract with new rate - land Clearing and General Support contract PT. IWJ valid contract until May 2025
B29: 5.2 | C29: Contractor readiness (hauling) | G29: As capacity in 2024 | O29: Need tender process for hauling contractor | Q29: - Contract Coal hauling Contractor PT. ARKA valid until December 2024 and on progress amendment contract - Outstanding issue contractor sellection Coal hauling Contract PT. SLS , Waiting Approval from Senior management - Additional Support Coal hauling Contractor PT. IWJ still use Rental rate contract in 2024
B30: 5.3 | C30: Crushing Capability | G30: As capacity in 2024 | M30: 1. FC Production as target but need Blending study for Blending portion 2. Manage stock yard and fornt loading for limited area stock in PSY with supply in ROM Stock 3. Closed monitor with marketing & STSC for the Barging | Q30: Crushing already finish , need improvement for second Feeder BLC to increase production rate

Sheet IMM 2025
A1: IMM 2025 Production Plan - 2nd Draft Year 2025
A3: Draft file | B3: 1st Draft 2025 OPT5 email
A4: Draft date | B4: 45576
C5: 2025
A6: Mine | B6: Unit | C6: Jan | D6: Feb | E6: Mar | F6: Apr | G6: May | H6: Jun | I6: Jul | J6: Aug | K6: Sep | L6: Oct | M6: Nov | N6: Dec | O6: Total
A7: IMM
A8: OB removal | B8: KBCM | C8: 7619.4483 | D8: 7224.3023 | E8: 6870.0231 | F8: 7815.9147 | G8: 8233.4755 | H8: 7596.8792 | I8: 8769.11 | J8: 8498.0492 | K8: 8442.1757 | L8: 8242.1086 | M8: 7836.3005 | N8: 7566.691 | O8: =SUM(C8:N8) -> 94714.478
A9: ROM production | B9: Kton | C9: 550 | D9: 545 | E9: 550 | F9: 550 | G9: 550 | H9: 550 | I9: 622.5 | J9: 637.5 | K9: 637.5 | L9: 637.5 | M9: 637.5 | N9: 632.5 | O9: =SUM(C9:N9) -> 7100 | P9: Include Fine Coal 150 KT
A10: FC production | B10: Kton | C10: 541.75 | D10: 536.75 | E10: 541.75 | F10: 551.75 | G10: 551.75 | H10: 551.75 | I10: 635.75 | J10: 637.75 | K10: 637.75 | L10: 637.75 | M10: 637.75 | N10: 637.75 | O10: =SUM(C10:N10) -> 7100 | P10: Include Fine Coal 127.5 KT
A11: SR (OB:ROM) | B11: BCM/Ton | C11: =C8/C9 -> 13.853542 | D11: =D8/D9 -> 13.255601 | E11: =E8/E9 -> 12.490951 | F11: =F8/F9 -> 14.210754 | G11: =G8/G9 -> 14.969956 | H11: =H8/H9 -> 13.812508 | I11: =I8/I9 -> 14.086924 | J11: =J8/J9 -> 13.330273 | ... O11: =O8/O9 -> 13.340067
A12: SR (OB:FC) | B12: BCM/Ton | C12: =C8/C10 -> 14.06451 | D12: =D8/D10 -> 13.459343 | E12: =E8/E10 -> 12.681169 | F12: =F8/F10 -> 14.165681 | G12: =G8/G10 -> 14.922475 | H12: =H8/H10 -> 13.768698 | I12: =I8/I10 -> 13.793331 | J12: =J8/J10 -> 13.325048 | ... O12: =O8/O10 -> 13.340067
A13: Product type
A14: IMM WB HCV LS | B14: KTon | C14: 154.9822 | D14: 150.19218 | E14: 153.44456 | F14: 142.73183 | G14: 131.89202 | H14: 90.256716 | I14: 45.052829 | J14: 60.104109 | K14: 62.623268 | L14: 73.637876 | M14: 78.465632 | N14: 85.419934 | O14: =SUM(C14:N14) -> 1228.8032
A15: CV (ADB) | B15: Kcal/kg | C15: 6419.2447 | D15: 6413.7544 | E15: 6426.1701 | F15: 6467.5963 | G15: 6460.924 | H15: 6575.6487 | I15: 6763.3802 | J15: 6738.8545 | K15: 6733.8335 | L15: 6761.7471 | M15: 6563.4722 | N15: 6582.7854 | O15: =IFERROR(SUMPRODUCT(C15:N15,$C$14:$N$14)/$O$14,0) -> 6526.4022
A16: CV (GAR) | B16: Kcal/kg | C16: 6066.6995 | D16: 6061.099 | E16: 6072.9614 | F16: 6113.1737 | G16: 6106.3251 | H16: 6216.0563 | I16: 6397.4706 | J16: 6374.5335 | K16: 6369.463 | L16: 6395.7374 | M16: 6207.9868 | N16: 6224.9984 | O16: =IFERROR(SUMPRODUCT(C16:N16,$C$14:$N$14)/$O$14,0) -> 6169.7769
A17: TS | B17: % | C17: 0.79938883 | D17: 0.79960479 | E17: 0.80630914 | F17: 0.80238321 | G17: 0.79513307 | H17: 0.79813522 | I17: 0.8000568 | J17: 0.80071014 | K17: 0.80424058 | L17: 0.87778388 | M17: 0.89103139 | N17: 0.79704817 | O17: =IFERROR(SUMPRODUCT(C17:N17,$C$14:$N$14)/$O$14,0) -> 0.81080181
A18: Ash | B18: % | C18: 8.5931913 | D18: 8.5723462 | E18: 8.4652505 | F18: 8.3496537 | G18: 8.4544991 | H18: 8.0611616 | I18: 8.0877488 | J18: 8.0139288 | K18: 8.093906 | L18: 8.3113445 | M18: 8.6583469 | N18: 8.1211956 | O18: =IFERROR(SUMPRODUCT(C18:N18,$C$14:$N$14)/$O$14,0) -> 8.3745645
A19: IM | B19: % | C19: 8.4967581 | D19: 8.6035878 | E19: 8.5701167 | F19: 8.295887 | G19: 8.4360236 | H19: 8.1042227 | I19: 7.1124623 | J19: 7.0457455 | K19: 7.1276119 | L19: 7.1603037 | M19: 7.2146756 | N19: 7.5402791 | O19: =IFERROR(SUMPRODUCT(C19:N19,$C$14:$N$14)/$O$14,0) -> 8.0403443
A20: TM | B20: % | C20: 13.52212 | D20: 13.62895 | E20: 13.595479 | F20: 13.321249 | G20: 13.461386 | H20: 13.129585 | I20: 12.137825 | J20: 12.071108 | K20: 12.152974 | L20: 12.185666 | M20: 12.240038 | N20: 12.565641 | O20: =IFERROR(SUMPRODUCT(C20:N20,$C$14:$N$14)/$O$14,0) -> 13.065707
A21: IMM WB HCV HS | B21: KTon | C21: 37.517805 | D21: 37.307818 | E21: 39.055444 | F21: 47.268165 | G21: 53.10798 | H21: 64.743284 | I21: 84.947171 | J21: 74.895891 | K21: 82.376732 | L21: 36.362124 | M21: 41.534368 | N21: 34.580066 | O21: =SUM(C21:N21) -> 633.69685
A22: CV (ADB) | B22: Kcal/kg | C22: 6334.2014 | D22: 6447.6669 | E22: 6352.6384 | F22: 6292.9167 | G22: 6234.5184 | H22: 6241.3054 | I22: 6292.6616 | J22: 6274.0003 | K22: 6337.0578 | L22: 6315.7415 | M22: 6317.778 | N22: 6314.7744 | O22: =IFERROR(SUMPRODUCT(C22:N22,$C$21:$N$21)/$O$21,0) -> 6305.5853
A23: CV (GAR) | B23: Kcal/kg | C23: 5995.4058 | D23: 6102.8668 | E23: 6012.8803 | F23: 5956.2491 | G23: 5900.982 | H23: 5903.8514 | I23: 5953.1501 | J23: 5935.2903 | K23: 5994.0694 | L23: 5972.607 | M23: 5974.5067 | N23: 5973.0938 | O23: =IFERROR(SUMPRODUCT(C23:N23,$C$21:$N$21)/$O$21,0) -> 5965.7827
A24: TS | B24: % | C24: 2.4295613 | D24: 2.4050655 | E24: 2.5318666 | F24: 2.5966145 | G24: 2.6452674 | H24: 2.7646957 | I24: 2.7577905 | J24: 2.7055365 | K24: 2.6431822 | L24: 2.4886633 | M24: 2.3842149 | N24: 1.9721835 | O24: =IFERROR(SUMPRODUCT(C24:N24,$C$21:$N$21)/$O$21,0) -> 2.5790489
A25: Ash | B25: % | C25: 13.650338 | D25: 13.07266 | E25: 13.53618 | F25: 14.197739 | G25: 14.74821 | H25: 14.555829 | I25: 13.682949 | J25: 14.42353 | K25: 13.830267 | L25: 13.802136 | M25: 13.963262 | N25: 13.239605 | O25: =IFERROR(SUMPRODUCT(C25:N25,$C$21:$N$21)/$O$21,0) -> 13.960595
A26: IM | B26: % | C26: 6.0446714 | D26: 6.0271092 | E26: 6.0381378 | F26: 6.0670306 | G26: 6.0650682 | H26: 7.0545207 | I26: 6.8576285 | J26: 6.9141156 | K26: 7.151348 | L26: 7.5030578 | M26: 7.5101273 | N26: 7.1237139 | O26: =IFERROR(SUMPRODUCT(C26:N26,$C$21:$N$21)/$O$21,0) -> 6.7439986
A27: TM | B27: % | C27: 11.070034 | D27: 11.052472 | E27: 11.0635 | F27: 11.092393 | G27: 11.090431 | H27: 12.079883 | I27: 11.882991 | J27: 11.939478 | K27: 12.17671 | L27: 12.52842 | M27: 12.53549 | N27: 12.149076 | O27: =IFERROR(SUMPRODUCT(C27:N27,$C$21:$N$21)/$O$21,0) -> 11.769361
A28: IMM EB MCV LS | B28: KTon | C28: 3.3845713 | D28: 2.1986171 | E28: 2.3031178 | F28: 2.767207 | G28: 1.8758652 | H28: 1.1105575 | I28: 0 | J28: 0 | K28: 0 | L28: 0 | M28: 0 | N28: 0 | O28: =SUM(C28:N28) -> 13.639936
A29: CV (ADB) | B29: Kcal/kg | C29: 6169.8029 | D29: 6164.1006 | E29: 6172.431 | F29: 6174.4728 | G29: 6169.8042 | H29: 6172.235 | I29: 0 | J29: 0 | K29: 0 | L29: 0 | M29: 0 | N29: 0 | O29: =IFERROR(SUMPRODUCT(C29:N29,$C$28:$N$28)/$O$28,0) -> 6170.4731
A30: CV (GAR) | B30: Kcal/kg | C30: 5821.883 | D30: 5816.4871 | E30: 5824.2204 | F30: 5826.2223 | G30: 5821.6228 | H30: 5824.0809 | I30: 0 | J30: 0 | K30: 0 | L30: 0 | M30: 0 | N30: 0 | O30: =IFERROR(SUMPRODUCT(C30:N30,$C$28:$N$28)/$O$28,0) -> 5822.4314
A31: TS | B31: % | C31: 0.89812632 | D31: 0.89994494 | E31: 0.90129647 | F31: 0.90153154 | G31: 0.90292127 | H31: 0.90325732 | I31: 0 | J31: 0 | K31: 0 | L31: 0 | M31: 0 | N31: 0 | O31: =IFERROR(SUMPRODUCT(C31:N31,$C$28:$N$28)/$O$28,0) -> 0.90072278
A32: Ash | B32: % | C32: 8.6642459 | D32: 8.6537904 | E32: 8.6423873 | F32: 8.5289327 | G32: 8.5159535 | H32: 8.5014972 | I32: 0 | J32: 0 | K32: 0 | L32: 0 | M32: 0 | N32: 0 | O32: =IFERROR(SUMPRODUCT(C32:N32,$C$28:$N$28)/$O$28,0) -> 8.5977728
A33: IM | B33: % | C33: 11.332981 | D33: 11.336869 | E33: 11.369268 | F33: 11.350128 | G33: 11.399581 | H33: 11.357707 | I33: 0 | J33: 0 | K33: 0 | L33: 0 | M33: 0 | N33: 0 | O33: =IFERROR(SUMPRODUCT(C33:N33,$C$28:$N$28)/$O$28,0) -> 11.354386
A34: TM | B34: % | C34: 16.332981 | D34: 16.336869 | E34: 16.369268 | F34: 16.350128 | G34: 16.399581 | H34: 16.357707 | I34: 0 | J34: 0 | K34: 0 | L34: 0 | M34: 0 | N34: 0 | O34: =IFERROR(SUMPRODUCT(C34:N34,$C$28:$N$28)/$O$28,0) -> 16.354386
A35: IMM EB MCV MS | B35: KTon | C35: 2.5218825 | D35: 7.2154786 | E35: 26.720101 | F35: 6.3272233 | G35: 12.630174 | H35: 4.8087851 | I35: 12.094951 | J35: 14.998053 | K35: 83.697273 | L35: 94.400599 | M35: 71.33532 | N35: 85.965624 | O35: =SUM(C35:N35) -> 422.71546
A36: CV (ADB) | B36: Kcal/kg | C36: 6368.0243 | D36: 6310.0428 | E36: 6367.3626 | F36: 6390.1986 | G36: 6342.5849 | H36: 6357.9317 | I36: 6392.812 | J36: 6360.8597 | K36: 6350.9993 | L36: 6367.4084 | M36: 6382.1767 | N36: 6381.7919 | O36: =IFERROR(SUMPRODUCT(C36:N36,$C$35:$N$35)/$O$35,0) -> 6368.5845
A37: CV (GAR) | B37: Kcal/kg | C37: 6013.744 | D37: 5958.5719 | E37: 6011.5142 | F37: 6033.7912 | G37: 5987.1311 | H37: 6002.8141 | I37: 6036.2059 | J37: 6005.6296 | K37: 5996.4183 | L37: 6012.5832 | M37: 6026.6617 | N37: 6027.4417 | O37: =IFERROR(SUMPRODUCT(C37:N37,$C$35:$N$35)/$O$35,0) -> 6013.6725
A38: TS | B38: % | C38: 1.5719259 | D38: 1.5704928 | E38: 1.5645055 | F38: 1.5541281 | G38: 1.5514426 | H38: 1.5490809 | I38: 1.5706205 | J38: 1.5667221 | K38: 1.5492652 | L38: 1.553251 | M38: 1.5598162 | N38: 1.5724278 | O38: =IFERROR(SUMPRODUCT(C38:N38,$C$35:$N$35)/$O$35,0) -> 1.5594733
A39: Ash | B39: % | C39: 6.0748082 | D39: 6.153097 | E39: 6.1792076 | F39: 5.197632 | G39: 5.2945573 | H39: 5.236934 | I39: 5.1052577 | J39: 5.3674075 | K39: 5.3569251 | L39: 5.169691 | M39: 5.1649103 | N39: 5.3009891 | O39: =IFERROR(SUMPRODUCT(C39:N39,$C$35:$N$35)/$O$35,0) -> 5.3287414
A40: Moist | B40: % | C40: 10.127325 | D40: 10.233784 | E40: 10.532647 | F40: 10.3526 | G40: 10.781854 | H40: 10.481305 | I40: 10.365903 | J40: 10.468448 | K40: 10.443604 | L40: 10.274018 | M40: 10.240397 | N40: 9.9507726 | O40: =IFERROR(SUMPRODUCT(C40:N40,$C$35:$N$35)/$O$35,0) -> 10.279207
A41: TM | B41: % | C41: 15.127325 | D41: 15.233784 | E41: 15.532647 | F41: 15.3526 | G41: 15.781854 | H41: 15.481305 | I41: 15.365903 | J41: 15.468448 | K41: 15.443604 | L41: 15.274018 | M41: 15.240397 | N41: 14.950773 | O41: =IFERROR(SUMPRODUCT(C41:N41,$C$35:$N$35)/$O$35,0) -> 15.279207
...

Sheet TCM 2025
A1: TCM 2025 Production Plan - 2nd Draft
A3: Draft file | B3: Draft Production Plan Year 2025 TCM (12 Oct 2024)_V2.1
A4: Draft date | B4: 45577
C5: 2025
A6: Mine | B6: Unit | C6: Jan | D6: Feb | E6: Mar | F6: Apr | G6: May | H6: Jun | I6: Jul | J6: Aug | K6: Sep | L6: Oct | M6: Nov | N6: Dec | O6: Total
A7: TCM
A8: OB removal | B8: KBCM | C8: 4195 | D8: 4015 | E8: 4020 | F8: 4250 | G8: 4410 | H8: 4660 | I8: 4720 | J8: 5055 | K8: 4740 | L8: 3990 | M8: 3805 | N8: 3790 | O8: =SUM(C8:N8) -> 51650
A9: ROM production | B9: Kton | C9: 200 | D9: 215 | E9: 217 | F9: 255 | G9: 285 | H9: 315 | I9: 310 | J9: 335.38697 | K9: 307 | L9: 300 | M9: 281 | N9: 280 | O9: =SUM(C9:N9) -> 3300.387
A10: FC production | B10: Kton | C10: =SUM(C14,C21,C28) -> 217 | D10: =SUM(D14,D21,D28) -> 235 | E10: =SUM(E14,E21,E28) -> 258 | F10: =SUM(F14,F21,F28) -> 257 | G10: =SUM(G14,G21,G28) -> 290 | H10: =SUM(H14,H21,H28) -> 305 | I10: =SUM(I14,I21,I28) -> 315 | J10: =SUM(J14,J21,J28) -> 320 | ... N10: =SUM(N14,N21,N28) -> 253 | O10: =SUM(C10:N10) -> 3230
A11: SR (OB:ROM) | B11: BCM/Ton | C11: =C8/C9 -> 20.975 | D11: =D8/D9 -> 18.674419 | E11: =E8/E9 -> 18.525346 | F11: =F8/F9 -> 16.666667 | G11: =G8/G9 -> 15.473684 | H11: =H8/H9 -> 14.793651 | I11: =I8/I9 -> 15.225806 | J11: =J8/J9 -> 15.072142 | ... O11: =O8/O9 -> 15.64968
A12: SR (OB:FC) | B12: BCM/Ton | C12: =C8/C10 -> 19.331797 | D12: =D8/D10 -> 17.085106 | E12: =E8/E10 -> 15.581395 | F12: =F8/F10 -> 16.536965 | G12: =G8/G10 -> 15.206897 | H12: =H8/H10 -> 15.278689 | I12: =I8/I10 -> 14.984127 | J12: =J8/J10 -> 15.796875 | ... O12: =O8/O10 -> 15.990712
A13: Product type
A14: TCM HCV LS | B14: KTon | C14: 110 | D14: 130 | E14: 130 | F14: 140 | G14: 150 | H14: 170 | I14: 170 | J14: 150 | K14: 155 | L14: 115 | M14: 115 | N14: 95 | O14: =SUM(C14:N14) -> 1630 | Q14: =O14/O10 -> 0.50464396
A15: CV (ADB) | B15: Kcal/kg | C15: 6736.8284 | D15: 6845.675 | E15: 6855.2974 | F15: 6799.3995 | G15: 6851.0847 | H15: 6896.7899 | I15: 6784.1768 | J15: 6817.3511 | K15: 6897.6838 | L15: 6835.9324 | M15: 6832.8721 | N15: 6795.1116 | O15: =IFERROR(SUMPRODUCT(C15:N15,$C$14:$N$14)/$O$14,0) -> 6832.3388
A16: CV (GAR) | B16: Kcal/kg | C16: 6331.7794 | D16: 6327.6426 | E16: 6345.3425 | F16: 6327.8237 | G16: 6373.2296 | H16: 6243.3002 | I16: 6268.7387 | J16: 6402.2298 | K16: 6455.744 | L16: 6429.1851 | M16: 6453.9309 | N16: 6360.7189 | O16: =IFERROR(SUMPRODUCT(C16:N16,$C$14:$N$14)/$O$14,0) -> 6355.6513
A17: TS | B17: % | C17: 0.63238992 | D17: 0.69248101 | E17: 0.65200146 | F17: 0.65479545 | G17: 0.61486788 | H17: 0.63759554 | I17: 0.63464407 | J17: 0.55063001 | K17: 0.52383377 | L17: 0.52785903 | M17: 0.54698263 | N17: 0.54360501 | O17: =IFERROR(SUMPRODUCT(C17:N17,$C$14:$N$14)/$O$14,0) -> 0.60341466
A18: Ash | B18: % | C18: 5.1400008 | D18: 4.5591191 | E18: 4.5963271 | F18: 5.123741 | G18: 4.8279056 | H18: 4.5406009 | I18: 5.4694098 | J18: 4.9514041 | K18: 4.2318464 | L18: 4.7988367 | M18: 4.9300384 | N18: 4.9975468 | O18: =IFERROR(SUMPRODUCT(C18:N18,$C$14:$N$14)/$O$14,0) -> 4.8411374
A19: IM | B19: % | C19: 7.9684127 | D19: 7.5073713 | E19: 7.3053122 | F19: 7.3141874 | G19: 7.2934236 | H19: 7.0845272 | I19: 7.3044097 | J19: 7.5575721 | K19: 7.1826946 | L19: 7.4774674 | M19: 7.32496 | N19: 7.623105 | O19: =IFERROR(SUMPRODUCT(C19:N19,$C$14:$N$14)/$O$14,0) -> 7.3863318
A20: TM | B20: % | C20: 13.501774 | D20: 14.506561 | E20: 14.200726 | F20: 13.742458 | G20: 13.759599 | H20: 15.888522 | I20: 14.347097 | J20: 13.186565 | K20: 13.12957 | L20: 12.982685 | M20: 12.464583 | N20: 13.528504 | O20: =IFERROR(SUMPRODUCT(C20:N20,$C$14:$N$14)/$O$14,0) -> 13.846499
A21: TCM HCV HS | B21: KTon | C21: 100 | D21: 100 | E21: 120 | F21: 110 | G21: 130 | H21: 120 | I21: 130 | J21: 150 | K21: 120 | L21: 130 | M21: 120 | N21: 150 | O21: =SUM(C21:N21) -> 1480 | Q21: =O21/O10 -> 0.45820433
A22: CV (ADB) | B22: Kcal/kg | C22: 6866.5729 | D22: 6778.7713 | E22: 6894.8648 | F22: 6822.1779 | G22: 6836.7655 | H22: 6757.1099 | I22: 6815.116 | J22: 6823.9609 | K22: 6790.9747 | L22: 6843.9084 | M22: 6814.7913 | N22: 6804.9311 | O22: =IFERROR(SUMPRODUCT(C22:N22,$C$21:$N$21)/$O$21,0) -> 6820.7361
A23: CV (GAR) | B23: Kcal/kg | C23: 6528.8013 | D23: 6523.441 | E23: 6602.1856 | F23: 6481.0855 | G23: 6487.5274 | H23: 6515.5714 | I23: 6445.0323 | J23: 6472.1448 | K23: 6412.4032 | L23: 6476.7335 | M23: 6460.6228 | N23: 6423.2952 | O23: =IFERROR(SUMPRODUCT(C23:N23,$C$21:$N$21)/$O$21,0) -> 6482.812
A24: TS | B24: % | C24: 1.841903 | D24: 2.1453577 | E24: 1.7213437 | F24: 1.7720411 | G24: 1.7757748 | H24: 2.0870683 | I24: 1.8137934 | J24: 1.8286935 | K24: 1.8482141 | L24: 1.8968174 | M24: 1.8190294 | N24: 1.9904989 | O24: =IFERROR(SUMPRODUCT(C24:N24,$C$21:$N$21)/$O$21,0) -> 1.8762421
A25: Ash | B25: % | C25: 6.7257046 | D25: 7.6729169 | E25: 55.965647 | F25: 5.9370559 | G25: 5.2917713 | H25: 7.3265169 | I25: 5.9374766 | J25: 5.9831574 | K25: 6.0080332 | L25: 6.0190798 | M25: 6.0931432 | N25: 5.9789559 | O25: =IFERROR(SUMPRODUCT(C25:N25,$C$21:$N$21)/$O$21,0) -> 10.254553
A26: IM | B26: % | C26: 7.2396068 | D26: 7.1179754 | E26: 6.7065054 | F26: 6.8833178 | G26: 6.7128751 | H26: 6.6876777 | I26: 6.6455047 | J26: 6.3583255 | K26: 6.7263938 | L26: 6.4663362 | M26: 6.2063256 | N26: 6.1537235 | O26: =IFERROR(SUMPRODUCT(C26:N26,$C$21:$N$21)/$O$21,0) -> 6.6257918
A27: TM | B27: % | C27: 11.802557 | D27: 10.616485 | E27: 10.666708 | F27: 11.538927 | G27: 11.478201 | H27: 10.023203 | I27: 11.714968 | J27: 11.186115 | K27: 11.926049 | L27: 11.484406 | M27: 11.080835 | N27: 11.416834 | O27: =IFERROR(SUMPRODUCT(C27:N27,$C$21:$N$21)/$O$21,0) -> 11.252249
A28: TCM.LCV.MS.HA | B28: KTon | C28: 7 | D28: 5 | E28: 8 | F28: 7 | G28: 10 | H28: 15 | I28: 15 | J28: 20 | K28: 10 | L28: 8 | M28: 7 | N28: 8 | O28: =SUM(C28:N28) -> 120 | Q28: =O28/O10 -> 0.037151703
A29: CV (ADB) | B29: Kcal/kg | C29: 3851.3 | D29: 3874.3 | E29: 4709.15 | F29: 3863.65 | G29: 3953.65 | H29: 6126.55 | I29: 6034.4 | J29: 5942.25 | K29: 5918.25 | L29: 5969.25 | M29: 5910.25 | N29: 5938.25 | O29: =IFERROR(SUMPRODUCT(C29:N29,$C$28:$N$28)/$O$28,0) -> 5397.1613
A30: CV (GAR) | B30: Kcal/kg | C30: 3581.7631 | D30: 3599.0009 | E30: 4341.3047 | F30: 3587.2263 | G30: 3651.2002 | H30: 5641.0449 | I30: 5567.1958 | J30: 5442.6121 | K30: 5422.5222 | L30: 5471.7948 | M30: 5388.109 | N30: 5438.9485 | O30: =IFERROR(SUMPRODUCT(C30:N30,$C$28:$N$28)/$O$28,0) -> 4963.5346
A31: TS | B31: % | C31: 1.16 | D31: 1.15 | E31: 1.44 | F31: 0.51 | G31: 0.5 | H31: 1.45 | I31: 1.5216667 | J31: 1.5933333 | K31: 1.6133333 | L31: 1.5833333 | M31: 1.5533333 | N31: 1.6133333 | O31: =IFERROR(SUMPRODUCT(C31:N31,$C$28:$N$28)/$O$28,0) -> 1.3581806
A32: Ash | B32: % | C32: 13.6 | D32: 13.18 | E32: 12.69 | F32: 14.445 | G32: 14.2 | H32: 6.835 | I32: 8.9933333 | J32: 11.151667 | K32: 11.141667 | L32: 11.011667 | M32: 11.171667 | N32: 11.981667 | O32: =IFERROR(SUMPRODUCT(C32:N32,$C$28:$N$28)/$O$28,0) -> 11.164653
A33: IM | B33: % | C33: 7.41 | D33: 7.54 | E33: 7.16 | F33: 6.52 | G33: 6.43 | H33: 6.09 | I33: 6.1266667 | J33: 6.1633333 | K33: 6.1633333 | L33: 6.1633333 | M33: 6.1633333 | N33: 6.1633333 | O33: =IFERROR(SUMPRODUCT(C33:N33,$C$28:$N$28)/$O$28,0) -> 6.3891389
A34: TM | B34: % | C34: 13.89 | D34: 14.11 | E34: 14.412 | F34: 13.208 | G34: 13.588 | H34: 13.532 | I34: 13.394667 | J34: 14.053333 | K34: 14.023333 | L34: 13.983333 | M34: 14.453333 | N34: 14.053333 | O34: =IFERROR(SUMPRODUCT(C34:N34,$C$28:$N$28)/$O$28,0) -> 13.850656

Sheet BEK 2025
A1: BEK 2025 Production Plan - 2nd Draft
A3: Draft file | B3: 00. BEK Production Budget Y25_ver2.2_08Oct24_rwsp
A4: Draft date | B4: 45573
C5: 2025
A6: Mine | B6: Unit | C6: Jan | D6: Feb | E6: Mar | F6: Apr | G6: May | H6: Jun | I6: Jul | J6: Aug | K6: Sep | L6: Oct | M6: Nov | N6: Dec | O6: Total
A7: BEK
A8: OB removal | B8: KBCM | C8: 7995 | D8: 7084 | E8: 7619 | F8: 7232 | G8: 7571 | H8: 7593 | I8: 8097 | J8: 8330 | K8: 7698 | L8: 7482 | M8: 6860 | N8: 7389 | O8: =SUM(C8:N8) -> 90950
A9: ROM production | B9: Kton | C9: 684 | D9: 658 | E9: 685.5 | F9: 564 | G9: 663 | H9: 712 | I9: 745 | J9: 752 | K9: 704 | L9: 627.5 | M9: 589 | N9: 616 | O9: =SUM(C9:N9) -> 8000
A10: FC production | B10: Kton | C10: 700 | D10: 700 | E10: 700 | F10: 650 | G10: 650 | H10: 650 | I10: 700 | J10: 710 | K10: 700 | L10: 660 | M10: 640 | N10: 640 | O10: =SUM(C10:N10) -> 8100
A11: SR (OB:ROM) | B11: BCM/Ton | C11: =C8/C9 -> 11.688596 | D11: =D8/D9 -> 10.765957 | E11: =E8/E9 -> 11.114515 | F11: =F8/F9 -> 12.822695 | G11: =G8/G9 -> 11.419306 | H11: =H8/H9 -> 10.664326 | I11: =I8/I9 -> 10.868456 | J11: =J8/J9 -> 11.077128 | ... O11: =O8/O9 -> 11.36875
A12: SR (OB:FC) | B12: BCM/Ton | C12: =C8/C10 -> 11.421429 | D12: =D8/D10 -> 10.12 | E12: =E8/E10 -> 10.884286 | F12: =F8/F10 -> 11.126154 | G12: =G8/G10 -> 11.647692 | H12: =H8/H10 -> 11.681538 | I12: =I8/I10 -> 11.567143 | J12: =J8/J10 -> 11.732394 | ... O12: =O8/O10 -> 11.228395
A13: Product type
A14: BEK MCV LS | B14: KTon | C14: 400 | D14: 480 | E14: 480 | F14: 465 | G14: 465 | H14: 460 | I14: 500 | J14: 490 | K14: 480 | L14: 460 | M14: 440 | N14: 440 | O14: =SUM(C14:N14) -> 5560
A15: CV (ADB) | B15: Kcal/kg | C15: 6356.6925 | D15: 6211.4538 | E15: 6164.5544 | F15: 6166.0095 | G15: 6215.11 | H15: 6171.0497 | I15: 6202.3209 | J15: 6155.9114 | K15: 6139.5186 | L15: 6134.6756 | M15: 6109.9273 | N15: 6139.0823 | O15: =IFERROR(SUMPRODUCT(C15:N15,$C$14:$N$14)/$O$14,0) -> 6178.9758
A16: CV (GAR) | B16: Kcal/kg | C16: 6030.4358 | D16: 5774.2277 | E16: 5860.9708 | F16: 5868.1864 | G16: 5954.6027 | H16: 5916.1255 | I16: 5984.187 | J16: 5944.3266 | K16: 5921.0085 | L16: 5916.7362 | M16: 5898.291 | N16: 5928.9325 | O16: =IFERROR(SUMPRODUCT(C16:N16,$C$14:$N$14)/$O$14,0) -> 5915.2264
A17: TS | B17: % | C17: 0.53158467 | D17: 0.52888777 | E17: 0.51140211 | F17: 0.47876764 | G17: 0.51889296 | H17: 0.54684188 | I17: 0.61559945 | J17: 0.6516434 | K17: 0.57082929 | L17: 0.61027739 | M17: 0.68842584 | N17: 0.67517043 | O17: =IFERROR(SUMPRODUCT(C17:N17,$C$14:$N$14)/$O$14,0) -> 0.57720242
A18: Ash | B18: % | C18: 4.5798127 | D18: 4.3819201 | E18: 4.705923 | F18: 4.7159272 | G18: 4.4700417 | H18: 4.6727263 | I18: 5.1675001 | J18: 5.2806867 | K18: 5.376416 | L18: 5.2082429 | M18: 4.9554985 | N18: 5.0376143 | O18: =IFERROR(SUMPRODUCT(C18:N18,$C$14:$N$14)/$O$14,0) -> 4.8848466
A19: IM | B19: % | C19: 11.53253 | D19: 12.161692 | E19: 11.768774 | F19: 10.98217 | G19: 11.996305 | H19: 11.373388 | I19: 10.851381 | J19: 11.259922 | K19: 11.128284 | L19: 11.312912 | M19: 11.810254 | N19: 11.519677 | O19: =IFERROR(SUMPRODUCT(C19:N19,$C$14:$N$14)/$O$14,0) -> 11.469447
A20: TM | B20: % | C20: 16.073116 | D20: 18.344658 | E20: 16.113866 | F20: 15.2818 | G20: 15.684993 | H20: 15.034526 | I20: 13.986713 | J20: 14.310007 | K20: 14.291295 | L20: 14.463594 | M20: 14.864979 | N20: 14.548488 | O20: =IFERROR(SUMPRODUCT(C20:N20,$C$14:$N$14)/$O$14,0) -> 15.241913
A21: BEK MCV MS | B21: KTon | C21: 300 | D21: 220 | E21: 220 | F21: 185 | G21: 185 | H21: 190 | I21: 200 | J21: 220 | K21: 220 | L21: 200 | M21: 200 | N21: 200 | O21: =SUM(C21:N21) -> 2540
A22: CV (ADB) | B22: Kcal/kg | C22: 6236.9634 | D22: 6049.986 | E22: 6043.243 | F22: 6018.0484 | G22: 5964.0677 | H22: 5984.9901 | I22: 5967.3108 | J22: 6020.9507 | K22: 6068.0016 | L22: 6040.4014 | M22: 5983.9188 | N22: 6135.5256 | O22: =IFERROR(SUMPRODUCT(C22:N22,$C$21:$N$21)/$O$21,0) -> 6051.3543
A23: CV (GAR) | B23: Kcal/kg | C23: 5978.3055 | D23: 5788.4874 | E23: 5780.4749 | F23: 5757.1239 | G23: 5689.0306 | H23: 5723.4269 | I23: 5710.0663 | J23: 5767.3036 | K23: 5816.7184 | L23: 5783.944 | M23: 5714.3882 | N23: 5899.7671 | O23: =IFERROR(SUMPRODUCT(C23:N23,$C$21:$N$21)/$O$21,0) -> 5792.8232
A24: TS | B24: % | C24: 1.7870244 | D24: 1.8050808 | E24: 1.7534847 | F24: 1.753 | G24: 1.7123074 | H24: 1.7853721 | I24: 1.8238816 | J24: 1.741996 | K24: 1.7014005 | L24: 1.760588 | M24: 1.7678142 | N24: 1.7232917 | O24: =IFERROR(SUMPRODUCT(C24:N24,$C$21:$N$21)/$O$21,0) -> 1.7606128
A25: Ash | B25: % | C25: 4.7301045 | D25: 5.5271121 | E25: 5.5457883 | F25: 5.7432541 | G25: 6.1338157 | H25: 6.4531615 | I25: 6.4437426 | J25: 6.2121469 | K25: 5.7608226 | L25: 5.8895184 | M25: 6.1089249 | N25: 5.11197 | O25: =IFERROR(SUMPRODUCT(C25:N25,$C$21:$N$21)/$O$21,0) -> 5.7572097
A26: IM | B26: % | C26: 11.089448 | D26: 10.939008 | E26: 11.103271 | F26: 10.753088 | G26: 10.931757 | H26: 10.542872 | I26: 10.9263 | J26: 10.532728 | K26: 10.519639 | L26: 10.608982 | M26: 10.409757 | N26: 10.300642 | O26: =IFERROR(SUMPRODUCT(C26:N26,$C$21:$N$21)/$O$21,0) -> 10.736864
A27: TM | B27: % | C27: 14.776726 | D27: 14.788492 | E27: 14.968616 | F27: 14.622566 | G27: 15.039201 | H27: 14.452435 | I27: 14.766174 | J27: 14.301753 | K27: 14.225128 | L27: 14.404258 | M27: 14.445125 | N27: 13.747354 | O27: =IFERROR(SUMPRODUCT(C27:N27,$C$21:$N$21)/$O$21,0) -> 14.551759

Sheet JBG 2025
A1: JBG 2025 Production Plan - 2nd draft
A3: Draft file | B3: JBG Production Budget 2025 update 16112024
A4: Draft date | B4: 45612
C5: 2025
A6: Mine | B6: Unit | C6: Jan | D6: Feb | E6: Mar | F6: Apr | G6: May | H6: Jun | I6: Jul | J6: Aug | K6: Sep | L6: Oct | M6: Nov | N6: Dec | O6: Total
A7: JBG
A8: OB removal | B8: KBCM | C8: 103.007 | D8: 93.07 | E8: 98.059 | F8: 280.6245 | G8: 579.3785 | H8: 448.889 | I8: 536.383 | J8: 575.345 | K8: 590.094 | L8: 632.103 | M8: 557.72 | N8: 543.935 | O8: =SUM(C8:N8) -> 5038.608
A9: ROM production | B9: Kton | C9: 0 | D9: 0 | E9: 0 | F9: 0 | G9: 20 | H9: 37 | I9: 51 | J9: 60 | K9: 70 | L9: 75 | M9: 68 | N9: 67 | O9: =SUM(C9:N9) -> 448
A10: FC production | B10: Kton | C10: 0 | D10: 0 | E10: 0 | F10: 0 | G10: 18 | H10: 35 | I10: 50 | J10: 58 | K10: 68 | L10: 72 | M10: 66 | N10: 66 | O10: =SUM(C10:N10) -> 433
A11: SR (OB:ROM) | B11: BCM/Ton | C11: =C8/C9 -> #DIV/0! | D11: =D8/D9 -> #DIV/0! | E11: =E8/E9 -> #DIV/0! | F11: =F8/F9 -> #DIV/0! | G11: =G8/G9 -> 28.968925 | H11: =H8/H9 -> 12.132135 | I11: =I8/I9 -> 10.517314 | J11: =J8/J9 -> 9.5890833 | ... N11: =N8/N9 -> 8.1184328 | O11: =IFERROR(O8/O9,0) -> 11.246893
A12: SR (OB:FC) | B12: BCM/Ton | C12: =C8/C10 -> #DIV/0! | D12: =D8/D10 -> #DIV/0! | E12: =E8/E10 -> #DIV/0! | F12: =F8/F10 -> #DIV/0! | G12: =G8/G10 -> 32.187694 | H12: =H8/H10 -> 12.8254 | I12: =I8/I10 -> 10.72766 | J12: =J8/J10 -> 9.9197414 | ... O12: =O8/O10 -> 11.636508
A13: Product type
A14: JBG | B14: KTon | C14: =C10 -> 0 | D14: =D10 -> 0 | E14: =E10 -> 0 | F14: =F10 -> 0 | G14: =G10 -> 18 | H14: =H10 -> 35 | I14: =I10 -> 50 | J14: =J10 -> 58 | ... N14: =N10 -> 66 | O14: =SUM(C14:N14) -> 433
A15: CV (ADB) | B15: Kcal/kg | C15: 0 | D15: 0 | E15: 0 | F15: 0 | G15: 5253.8295 | H15: 5240.7986 | I15: 5259.589 | J15: 5280.4872 | K15: 5246.6256 | L15: 5280.3769 | M15: 5298.5008 | N15: 5258.6221 | O15: =IFERROR(SUMPRODUCT(C15:N15,$C$14:$N$14)/$O$14,0) -> 5267.8346
A16: CV (GAR) | B16: Kcal/kg | C16: 0 | D16: 0 | E16: 0 | F16: 0 | G16: 4689.0912 | H16: 4653.2238 | I16: 4416.3842 | J16: 4432.5862 | K16: 4408.926 | L16: 4423.0872 | M16: 4453.786 | N16: 4407.9045 | O16: =IFERROR(SUMPRODUCT(C16:N16,$C$14:$N$14)/$O$14,0) -> 4453.3868
A17: TS | B17: % | C17: 0 | D17: 0 | E17: 0 | F17: 0 | G17: 4.346919 | H17: 4.2775243 | I17: 0.38863712 | J17: 0.37485739 | K17: 0.36433237 | L17: 0.35476496 | M17: 0.35693132 | N17: 0.38385934 | O17: =IFERROR(SUMPRODUCT(C17:N17,$C$14:$N$14)/$O$14,0) -> 0.85067284
A18: Ash | B18: % | C18: 0 | D18: 0 | E18: 0 | F18: 0 | G18: 17.434024 | H18: 17.20378 | I18: 4.5771833 | J18: 4.4107108 | K18: 4.3137914 | L18: 4.4379835 | M18: 4.3733361 | N18: 4.6218111 | O18: =IFERROR(SUMPRODUCT(C18:N18,$C$14:$N$14)/$O$14,0) -> 6.0211951
A19: IM | B19: % | C19: 0 | D19: 0 | E19: 0 | F19: 0 | G19: 30.186701 | H19: 30.265561 | I19: 17.033951 | J19: 16.871627 | K19: 16.977285 | L19: 16.725081 | M19: 16.935727 | N19: 16.762054 | O19: =IFERROR(SUMPRODUCT(C19:N19,$C$14:$N$14)/$O$14,0) -> 18.511829
A20: TM | B20: % | C20: 0 | D20: 0 | E20: 0 | F20: 0 | G20: 37.690987 | H20: 38.083874 | I20: 30.33487 | J20: 30.219758 | K20: 30.233061 | L20: 30.245087 | M20: 30.17827 | N20: 30.227937 | O20: =IFERROR(SUMPRODUCT(C20:N20,$C$14:$N$14)/$O$14,0) -> 31.180524

Sheet GPK 2025
A1: GPK 2025 Production Plan - 2nd Draft
A3: Draft file | B3: Draft GPK Production Plan 2025 Ver.1.3 (2.1 MTon) (22 Sept'24_)
A4: Draft date | B4: 45557
B5: Mine | C5: Unit | D5: Jan | E5: Feb | F5: Mar | G5: Apr | H5: May | I5: Jun | J5: Jul | K5: Aug | L5: Sep | M5: Oct | N5: Nov | O5: Dec | P5: Total
B6: GPK
B7: OB Removal | C7: KBCM | D7: 630 | E7: 580 | F7: 630 | G7: 610 | H7: 700 | I7: 675 | J7: 745 | K7: 790 | L7: 785 | M7: 880 | N7: 705 | O7: 770 | P7: =SUM(D7:O7) -> 8500
B8: ROM Production | C8: Kton | D8: 184 | E8: 166 | F8: 182 | G8: 175 | H8: 180 | I8: 175 | J8: 160 | K8: 160 | L8: 160 | M8: 196 | N8: 175 | O8: 187 | P8: =SUM(D8:O8) -> 2100
B9: FC Production | C9: Kton | D9: 200 | E9: 180 | F9: 190 | G9: 175 | H9: 180 | I9: 175 | J9: 90 | K9: 50 | L9: 90 | M9: 210 | N9: 260 | O9: 250 | P9: =SUM(D9:O9) -> 2050
B10: SR (OB:ROM) | C10: BCM/Ton | D10: =IFERROR(D7/D8,"-") -> 3.423913 | E10: =IFERROR(E7/E8,"-") -> 3.4939759 | F10: =IFERROR(F7/F8,"-") -> 3.4615385 | G10: =IFERROR(G7/G8,"-") -> 3.4857143 | H10: =IFERROR(H7/H8,"-") -> 3.8888889 | I10: =IFERROR(I7/I8,"-") -> 3.8571429 | J10: =IFERROR(J7/J8,"-") -> 4.65625 | K10: =IFERROR(K7/K8,"-") -> 4.9375 | ... O10: =IFERROR(O7/O8,"-") -> 4.1176471 | P10: =P7/P8 -> 4.047619
B11: SR (OB:FC) | C11: BCM/Ton | D11: =IFERROR(D7/D9,"-") -> 3.15 | E11: =IFERROR(E7/E9,"-") -> 3.2222222 | F11: =IFERROR(F7/F9,"-") -> 3.3157895 | G11: =IFERROR(G7/G9,"-") -> 3.4857143 | H11: =IFERROR(H7/H9,"-") -> 3.8888889 | I11: =IFERROR(I7/I9,"-") -> 3.8571429 | J11: =IFERROR(J7/J9,"-") -> 8.2777778 | K11: =IFERROR(K7/K9,"-") -> 15.8 | ... O11: =IFERROR(O7/O9,"-") -> 3.08 | P11: =P7/P9 -> 4.1463415
B12: Product type
B13: GPK LCV LS | C13: Kton | D13: 200 | E13: 180 | F13: 190 | G13: 175 | H13: 180 | I13: 175 | J13: 90 | K13: 50 | L13: 90 | M13: 210 | N13: 260 | O13: 250 | P13: =SUM(D13:O13) -> 2050
B14: CV (ADB) | C14: Kcal/Kg | D14: 4214.9372 | E14: 4210.4116 | F14: 4317.487 | G14: 4512.7819 | H14: 4537.3358 | I14: 4602.8515 | J14: 4588.206 | K14: 4598.3567 | L14: 4627.3989 | M14: 4548.2078 | N14: 4445.7477 | O14: 4421.1064 | P14: =IFERROR(SUMPRODUCT(D13:O13,$D$14:$O$14)/$P$13,0) -> 4443.2962
B15: CV (GAR) | C15: Kcal/Kg | D15: 3597.7504 | E15: 3594.5296 | F15: 3663.6762 | G15: 3731.5323 | H15: 3747.0877 | I15: 3753.0309 | J15: 3709.9842 | K15: 3710.8591 | L15: 3754.9789 | M15: 3802.469 | N15: 3810.8052 | O15: 3790.9104 | P15: =IFERROR(SUMPRODUCT(D13:O13,$D$15:$O$15)/$P$13,0) -> 3727.504
B16: TS | C16: % | D16: 0.1156884 | E16: 0.11701099 | F16: 0.15581461 | G16: 0.15133328 | H16: 0.15302003 | I16: 0.14876312 | J16: 0.16963776 | K16: 0.16909767 | L16: 0.15832888 | M16: 0.16553178 | N16: 0.17247669 | O16: 0.16287235 | P16: =IFERROR(SUMPRODUCT(D16:O16,$D$13:$O$13)/$P$13,0) -> 0.15227341
B17: Ash | C17: % | D17: 10.145655 | E17: 10.213899 | F17: 9.4791857 | G17: 8.26645 | H17: 7.972028 | I17: 8.1086561 | J17: 9.7174821 | K17: 9.7409059 | L17: 8.5788059 | M17: 6.4455548 | N17: 5.4512093 | O17: 5.908571 | P17: =IFERROR(SUMPRODUCT(D17:O17,$D$13:$O$13)/$P$13,0) -> 7.9761082
B18: IM | C18: % | D18: 27.273779 | E18: 27.292036 | F18: 26.977085 | G18: 25.12425 | H18: 25.063918 | I18: 24.254236 | J18: 31.602711 | K18: 31.478111 | L18: 27.521644 | M18: 26.441746 | N18: 28.914291 | O18: 29.042201 | P18: =IFERROR(SUMPRODUCT(D18:O18,$D$13:$O$13)/$P$13,0) -> 27.254556
B19: TM | C19: % | D19: 37.918497 | E19: 37.923034 | F19: 38.042986 | G19: 37.950931 | H19: 37.978956 | I19: 38.073811 | J19: 37.717541 | K19: 37.733817 | L19: 37.863692 | M19: 38.416454 | N19: 39.068495 | O19: 39.167628 | P19: =IFERROR(SUMPRODUCT(D19:O19,$D$13:$O$13)/$P$13,0) -> 38.285233

Sheet TIS 2025
A1: TIS 2025 Production Plan - 2nd Draft
A3: Draft file | B3: TIS_Draft Plan Production Y2025_R03 (18Nov24)
A4: Draft date | B4: 45614
C5: 2025
A6: Mine | B6: Unit | C6: Jan | D6: Feb | E6: Mar | F6: Apr | G6: May | H6: Jun | I6: Jul | J6: Aug | K6: Sep | L6: Oct | M6: Nov | N6: Dec | O6: Total
A7: TIS
A8: OB removal | B8: KBCM | C8: 982.5 | D8: 833.26 | E8: 955 | F8: 979.8 | G8: 1028.75 | H8: 1131.36 | I8: 1343.54 | J8: 1450.15 | K8: 1249.8 | L8: 960.24 | M8: 867.28 | N8: 919 | O8: =SUM(C8:N8) -> 12700.68
A9: ROM production | B9: Kton | C9: 30 | D9: 35 | E9: 42 | F9: 45 | G9: 57 | H9: 56 | I9: 62 | J9: 65 | K9: 60 | L9: 54 | M9: 50 | N9: 50 | O9: =SUM(C9:N9) -> 606
A10: FC production | B10: Kton | C10: 30 | D10: 30 | E10: 40 | F10: 45 | G10: 50 | H10: 50 | I10: 60 | J10: 60 | K10: 55 | L10: 55 | M10: 55 | N10: 60 | O10: =SUM(C10:N10) -> 590
A11: SR (OB:ROM) | B11: BCM/Ton | C11: =C8/C9 -> 32.75 | D11: =D8/D9 -> 23.807429 | E11: =E8/E9 -> 22.738095 | F11: =F8/F9 -> 21.773333 | G11: =G8/G9 -> 18.048246 | H11: =H8/H9 -> 20.202857 | I11: =I8/I9 -> 21.67 | J11: =J8/J9 -> 22.31 | ... O11: =O8/O9 -> 20.958218
A12: SR (OB:FC) | B12: BCM/Ton | C12: =C8/C10 -> 32.75 | D12: =D8/D10 -> 27.775333 | E12: =E8/E10 -> 23.875 | F12: =F8/F10 -> 21.773333 | G12: =G8/G10 -> 20.575 | H12: =H8/H10 -> 22.6272 | I12: =I8/I10 -> 22.392333 | J12: =J8/J10 -> 24.169167 | ... O12: =O8/O10 -> 21.526576
A13: Product type
A14: TIS | B14: KTon | C14: =C10 -> 30 | D14: =D10 -> 30 | E14: =E10 -> 40 | F14: =F10 -> 45 | G14: =G10 -> 50 | H14: =H10 -> 50 | I14: =I10 -> 60 | J14: =J10 -> 60 | ... N14: =N10 -> 60 | O14: =SUM(C14:N14) -> 590
A15: CV (ADB) | B15: Kcal/kg | C15: 7190.3485 | D15: 7200.3485 | E15: 7180.3485 | F15: 7181.199 | G15: 7192.7045 | H15: 7244.7561 | I15: 7393.4564 | J15: 7312.7855 | K15: 7299.2735 | L15: 7232.9742 | M15: 7341.3072 | N15: 7323.6173 | O15: =IFERROR(SUMPRODUCT(C15:N15,$C$14:$N$14)/$O$14,0) -> 7269.1507
A16: CV (GAR) | B16: Kcal/kg | C16: =C15*(100-C20)/(100-C19) -> 6824.4902 | D16: =D15*(100-D20)/(100-D19) -> 6820.347 | E16: =E15*(100-E20)/(100-E19) -> 6806.1231 | F16: =F15*(100-F20)/(100-F19) -> 6833.9324 | G16: =G15*(100-G20)/(100-G19) -> 6994.3648 | H16: =H15*(100-H20)/(100-H19) -> 7027.769 | I16: =I15*(100-I20)/(100-I19) -> 7159.1562 | J16: =J15*(100-J20)/(100-J19) -> 7071.2557 | ... N16: =N15*(100-N20)/(100-N19) -> 6909.6969 | O16: =IFERROR(SUMPRODUCT(C16:N16,$C$14:$N$14)/$O$14,0) -> 6937.7795
A17: TS | B17: % | C17: 1.4307861 | D17: 1.5139922 | E17: 1.5555952 | F17: 1.5555952 | G17: 1.5555952 | H17: 1.2555952 | I17: 1.2555952 | J17: 1.2955952 | K17: 1.1555952 | L17: 1.2555952 | M17: 1.182556 | N17: 1.2555952 | O17: =IFERROR(SUMPRODUCT(C17:N17,$C$14:$N$14)/$O$14,0) -> 1.3342231
A18: Ash | B18: % | C18: 2.9538162 | D18: 3.1341807 | E18: 3.1951671 | F18: 3.3934831 | G18: 3.2981007 | H18: 2.8070271 | I18: 2.8034331 | J18: 3.0056476 | K18: 2.6376748 | L18: 2.8830807 | M18: 2.5934831 | N18: 2.6436862 | O18: =IFERROR(SUMPRODUCT(C18:N18,$C$14:$N$14)/$O$14,0) -> 2.9184048
A19: IM | B19: % | C19: 4.432777 | D19: 4.5234545 | E19: 4.5521376 | F19: 4.557654 | G19: 4.7566334 | H19: 4.5532702 | I19: 4.6037048 | J19: 4.8185719 | K19: 4.5690437 | L19: 4.9641888 | M19: 4.6397494 | N19: 4.7276789 | O19: =IFERROR(SUMPRODUCT(C19:N19,$C$14:$N$14)/$O$14,0) -> 4.6608024
A20: TM | B20: % | C20: 9.2954142 | D20: 9.5622703 | E20: 9.5266895 | F20: 9.1730303 | G20: 7.3829808 | H20: 7.4119873 | I20: 7.6268328 | J20: 7.9622651 | K20: 9.8485977 | L20: 10.628141 | M20: 9.9458142 | N20: 10.112335 | O20: =IFERROR(SUMPRODUCT(C20:N20,$C$14:$N$14)/$O$14,0) -> 9.0078971

Sheet NPR 2025
A1: NPR 2025 Production Plan - 2nd Draft
A3: Draft file | B3: Draft NPR Production Plan 2025 - 450 Kton ROM
A4: Draft date | B4: 45613
C5: 2025
A6: Mine | B6: Unit | C6: Jan | D6: Feb | E6: Mar | F6: Apr | G6: May | H6: Jun | I6: Jul | J6: Aug | K6: Sep | L6: Oct | M6: Nov | N6: Dec | O6: Total
A7: NPR
A8: OB removal | B8: KBCM | C8: 0 | D8: 0 | E8: 129 | F8: 535 | G8: 542 | H8: 543 | I8: 586 | J8: 594 | K8: 578 | L8: 752 | M8: 682 | N8: 742.5 | O8: =SUM(C8:N8) -> 5683.5
A9: ROM production | B9: KTon | C9: 0 | D9: 0 | E9: 0 | F9: 0 | G9: 25 | H9: 55 | I9: 60 | J9: 60 | K9: 55 | L9: 65 | M9: 65 | N9: 65 | O9: =SUM(C9:N9) -> 450
A10: FC production | B10: KTon | C10: =C14+C21 -> 0 | D10: =D14+D21 -> 0 | E10: =E14+E21 -> 0 | F10: =F14+F21 -> 0 | G10: =G14+G21 -> 17 | H10: =H14+H21 -> 37 | I10: =I14+I21 -> 40 | J10: =J14+J21 -> 40 | ... O10: =O14+O21 -> 300
