Workbook
Name _1A1_Z1...A10_Z10: #REF!
Name _1A1_Z1...A10_Z10: #REF!
Name _Apr: [1]Validation!$A$33
Name _Aug: [1]Validation!$A$37
Name _Chubu1: [1]Validation!$A$5
Name _Chubu2: [1]Validation!$A$6
Name _Chubu3: [1]Validation!$A$7
Name _ChubuP1: [1]Chubu!$V$203
Name _ChubuP2: [1]Chubu!$V$204
Name _CLP: [1]Validation!$A$17
Name _CLPP1: [1]CLP!$V$203
Name _CLPP2: [1]CLP!$V$204
Name _DATE: #REF!
Name _DATE: #REF!
Name _Dec: [1]Validation!$A$41
Name _ENEL1: [1]Validation!$A$11
Name _ENELP1: '[1]Enel '!$V$264
Name _ENELP2: '[1]Enel '!$V$265
Name _EPDC: [1]Validation!$A$8
Name _EPDCP1: [1]EPDC!$V$203
Name _EPDCP2: [1]EPDC!$V$204
Name _Feb: [1]Validation!$A$31
Name _ffggggg: #REF!
Name _ffggggg: #REF!
Name _Formosa1: [1]Validation!$A$15
Name _Formosa2: [1]Validation!$A$16
Name _FORMOSAP1: [1]Formosa!$V$264
Name _FORMOSAP2: [1]Formosa!$V$265
Name _fs1: #REF!
Name _fs1: #REF!
Name _HEK1: [1]Validation!$A$20
Name _HEK2: [1]Validation!$A$21
Name _HEKP1: [1]HEK!$V$203
Name _HEKP2: [1]HEK!$V$204
Name _Huaneng1: [1]Validation!$A$18
Name _Huaneng2: [1]Validation!$A$19
Name _HUANP1: [1]Huaneng!$V$394
Name _HUANP2: [1]Huaneng!$V$395
Name _Jan: [1]Validation!$A$30
Name _Jul: [1]Validation!$A$36
Name _Jun: [1]Validation!$A$35
Name _Kobe: [1]Validation!$A$9
Name _KOBEP1: '[1]Kobe Steel'!$V$264
Name _KOBEP2: '[1]Kobe Steel'!$V$265
Name _Kospo: [1]Validation!$A$13
Name _KOSPOP1: [1]Kospo!$V$203
Name _KOSPOP2: [1]Kospo!$V$204
Name _Kowepo: [1]Validation!$A$14
Name _KOWEPOP1: [1]Kowepo!$V$264
Name _KOWEPOP2: [1]Kowepo!$V$265
Name _Mar: [1]Validation!$A$32
Name _May: [1]Validation!$A$34
Name _Nov: [1]Validation!$A$40
Name _Oct: [1]Validation!$A$39
Name _Sep: [1]Validation!$A$38
Name _SHIKOKUP1: [1]Shikoku!$V$203
Name _SHIKOKUP2: [1]Shikoku!$V$204
Name _Tirreno: [1]Validation!$A$12
Name _TIRRENOP1: [1]Tirreno!$V$264
Name _TIRRENOP2: [1]Tirreno!$V$265

Sheet Budget 2025
A1: ITM plan year 2024
A2: As of 18 Nov'24
A4: IMM | B4: Jan | C4: Feb | D4: Mar | E4: Apr | F4: May | G4: Jun | H4: Jul | I4: Aug | J4: Sep | K4: Oct | L4: Nov | M4: Dec | N4: Total
A5: OB Removal (KBcm) | B5: =SUM(B6:B7) -> 7619.4483 | C5: =SUM(C6:C7) -> 7224.3023 | D5: =SUM(D6:D7) -> 6870.0231 | E5: =SUM(E6:E7) -> 7815.9147 | F5: =SUM(F6:F7) -> 8233.4755 | G5: =SUM(G6:G7) -> 7596.8792 | H5: =SUM(H6:H7) -> 8769.11 | I5: =SUM(I6:I7) -> 8498.0492 | ... M5: =SUM(M6:M7) -> 7566.691 | N5: =SUM(B5:M5) -> 94714.478 | P5: Done
A6: PAMA (WB) | B6: 2904.786 | C6: 2754.4503 | D6: 2424.321 | E6: 2767.1447 | F6: 2927.6178 | G6: 2460.4194 | H6: 3157.9028 | I6: 3107.2173 | J6: 2899.6426 | K6: 2829.8233 | L6: 2690.1553 | M6: 2609.1784 | N6: =SUM(B6:M6) -> 33532.659
A7: PAMA (EB) | B7: 4714.6622 | C7: 4469.852 | D7: 4445.7021 | E7: 5048.77 | F7: 5305.8577 | G7: 5136.4598 | H7: 5611.2072 | I7: 5390.8319 | J7: 5542.5331 | K7: 5412.2853 | L7: 5146.1452 | M7: 4957.5126 | N7: =SUM(B7:M7) -> 61181.819
A8: ROM Production (Kton) | B8: =SUM(B9:B11) -> 537.5 | C8: =SUM(C9:C11) -> 532.5 | D8: =SUM(D9:D11) -> 537.5 | E8: =SUM(E9:E11) -> 537.5 | F8: =SUM(F9:F11) -> 537.5 | G8: =SUM(G9:G11) -> 537.5 | H8: =SUM(H9:H11) -> 610 | I8: =SUM(I9:I11) -> 625 | ... M8: =SUM(M9:M11) -> 620 | N8: =SUM(B8:M8) -> 6950
A9: PAMA (WB) | B9: 192.5 | C9: 187.5 | D9: 192.5 | E9: 190 | F9: 185 | G9: 155 | H9: 130 | I9: 135 | J9: 145 | K9: 110 | L9: 120 | M9: 120 | N9: =SUM(B9:M9) -> 1862.5
A10: PAMA (EB) | B10: 345 | C10: 345 | D10: 345 | E10: 347.5 | F10: 352.5 | G10: 382.5 | H10: 480 | I10: 490 | J10: 480 | K10: 515 | L10: 505 | M10: 500 | N10: =SUM(B10:M10) -> 5087.5
A11: Fine Coal | B11: 0 | C11: 0 | D11: 0 | E11: 0 | F11: 0 | G11: 0 | H11: 0 | I11: 0 | J11: 0 | K11: 0 | L11: 0 | M11: 0 | N11: =SUM(B11:M11) -> 0
A12: SR ROM Total | B12: =B5/B8 -> 14.175718 | C12: =C5/C8 -> 13.566765 | D12: =D5/D8 -> 12.781438 | E12: =E5/E8 -> 14.541237 | F12: =F5/F8 -> 15.318094 | G12: =G5/G8 -> 14.133729 | H12: =H5/H8 -> 14.37559 | I12: =I5/I8 -> 13.596879 | ... N12: =N5/N8 -> 13.627982
A13: FC Product (Kton) | B13: =SUM(B14:B16) -> 541.75 | C13: =SUM(C14:C16) -> 536.75 | D13: =SUM(D14:D16) -> 541.75 | E13: =SUM(E14:E16) -> 551.75 | F13: =SUM(F14:F16) -> 551.75 | G13: =SUM(G14:G16) -> 551.75 | H13: =SUM(H14:H16) -> 635.75 | I13: =SUM(I14:I16) -> 637.75 | ... M13: =SUM(M14:M16) -> 637.75 | N13: =SUM(B13:M13) -> 7100
A14: PAMA (WB) | B14: 192.5 | C14: 187.5 | D14: 192.5 | E14: 190 | F14: 185 | G14: 155 | H14: 130 | I14: 135 | J14: 145 | K14: 110 | L14: 120 | M14: 120 | N14: =SUM(B14:M14) -> 1862.5
A15: PAMA (EB) | B15: 345 | C15: 345 | D15: 345 | E15: 349 | F15: 354 | G15: 384 | H15: 493 | I15: 490 | J15: 480 | K15: 515 | L15: 505 | M15: 505 | N15: =SUM(B15:M15) -> 5110
A16: Fine Coal | B16: 4.25 | C16: 4.25 | D16: 4.25 | E16: 12.75 | F16: 12.75 | G16: 12.75 | H16: 12.75 | I16: 12.75 | J16: 12.75 | K16: 12.75 | L16: 12.75 | M16: 12.75 | N16: =SUM(B16:M16) -> 127.5
A17: SR FC Total | B17: =B5/B13 -> 14.06451 | C17: =C5/C13 -> 13.459343 | D17: =D5/D13 -> 12.681169 | E17: =E5/E13 -> 14.165681 | F17: =F5/F13 -> 14.922475 | G17: =G5/G13 -> 13.768698 | H17: =H5/H13 -> 13.793331 | I17: =I5/I13 -> 13.325048 | ... N17: =N5/N13 -> 13.340067
A18: IMM-WB.HCV.LS | B18: 154.9822 | C18: 150.19218 | D18: 153.44456 | E18: 142.73183 | F18: 131.89202 | G18: 90.256716 | H18: 45.052829 | I18: 60.104109 | J18: 62.623268 | K18: 73.637876 | L18: 78.465632 | M18: 85.419934 | N18: =SUM(B18:M18) -> 1228.8032
A19: CV(GAR) | B19: 6066.6995 | C19: 6061.099 | D19: 6072.9614 | E19: 6113.1737 | F19: 6106.3251 | G19: 6216.0563 | H19: 6397.4706 | I19: 6374.5335 | J19: 6369.463 | K19: 6395.7374 | L19: 6207.9868 | M19: 6224.9984 | N19: =SUMPRODUCT(B19:M19,$B$18:$M$18)/SUM($B$18:$M$18) -> 6169.7769
A20: TS | B20: 0.79938883 | C20: 0.79960479 | D20: 0.80630914 | E20: 0.80238321 | F20: 0.79513307 | G20: 0.79813522 | H20: 0.8000568 | I20: 0.80071014 | J20: 0.80424058 | K20: 0.87778388 | L20: 0.89103139 | M20: 0.79704817 | N20: =SUMPRODUCT(B20:M20,$B$18:$M$18)/SUM($B$18:$M$18) -> 0.81080181
A21: Ash | B21: 8.5931913 | C21: 8.5723462 | D21: 8.4652505 | E21: 8.3496537 | F21: 8.4544991 | G21: 8.0611616 | H21: 8.0877488 | I21: 8.0139288 | J21: 8.093906 | K21: 8.3113445 | L21: 8.6583469 | M21: 8.1211956 | N21: =SUMPRODUCT(B21:M21,$B$18:$M$18)/SUM($B$18:$M$18) -> 8.3745645
A22: Moist | B22: 8.4967581 | C22: 8.6035878 | D22: 8.5701167 | E22: 8.295887 | F22: 8.4360236 | G22: 8.1042227 | H22: 7.1124623 | I22: 7.0457455 | J22: 7.1276119 | K22: 7.1603037 | L22: 7.2146756 | M22: 7.5402791 | N22: =SUMPRODUCT(B22:M22,$B$18:$M$18)/SUM($B$18:$M$18) -> 8.0403443
A23: TM | B23: 13.52212 | C23: 13.62895 | D23: 13.595479 | E23: 13.321249 | F23: 13.461386 | G23: 13.129585 | H23: 12.137825 | I23: 12.071108 | J23: 12.152974 | K23: 12.185666 | L23: 12.240038 | M23: 12.565641 | N23: =SUMPRODUCT(B23:M23,$B$18:$M$18)/SUM($B$18:$M$18) -> 13.065707
A24: IMM-WB.HCV.HS | B24: 37.517805 | C24: 37.307818 | D24: 39.055444 | E24: 47.268165 | F24: 53.10798 | G24: 64.743284 | H24: 84.947171 | I24: 74.895891 | J24: 82.376732 | K24: 36.362124 | L24: 41.534368 | M24: 34.580066 | N24: =SUM(B24:M24) -> 633.69685
A25: CV(GAR) | B25: 5995.4058 | C25: 6102.8668 | D25: 6012.8803 | E25: 5956.2491 | F25: 5900.982 | G25: 5903.8514 | H25: 5953.1501 | I25: 5935.2903 | J25: 5994.0694 | K25: 5972.607 | L25: 5974.5067 | M25: 5973.0938 | N25: =SUMPRODUCT(B25:M25,$B$24:$M$24)/SUM($B$24:$M$24) -> 5965.7827
A26: TS | B26: 2.4295613 | C26: 2.4050655 | D26: 2.5318666 | E26: 2.5966145 | F26: 2.6452674 | G26: 2.7646957 | H26: 2.7577905 | I26: 2.7055365 | J26: 2.6431822 | K26: 2.4886633 | L26: 2.3842149 | M26: 1.9721835 | N26: =SUMPRODUCT(B26:M26,$B$24:$M$24)/SUM($B$24:$M$24) -> 2.5790489
A27: Ash | B27: 13.650338 | C27: 13.07266 | D27: 13.53618 | E27: 14.197739 | F27: 14.74821 | G27: 14.555829 | H27: 13.682949 | I27: 14.42353 | J27: 13.830267 | K27: 13.802136 | L27: 13.963262 | M27: 13.239605 | N27: =SUMPRODUCT(B27:M27,$B$24:$M$24)/SUM($B$24:$M$24) -> 13.960595
A28: Moist | B28: 6.0446714 | C28: 6.0271092 | D28: 6.0381378 | E28: 6.0670306 | F28: 6.0650682 | G28: 7.0545207 | H28: 6.8576285 | I28: 6.9141156 | J28: 7.151348 | K28: 7.5030578 | L28: 7.5101273 | M28: 7.1237139 | N28: =SUMPRODUCT(B28:M28,$B$24:$M$24)/SUM($B$24:$M$24) -> 6.7439986
A29: TM | B29: 11.070034 | C29: 11.052472 | D29: 11.0635 | E29: 11.092393 | F29: 11.090431 | G29: 12.079883 | H29: 11.882991 | I29: 11.939478 | J29: 12.17671 | K29: 12.52842 | L29: 12.53549 | M29: 12.149076 | N29: =SUMPRODUCT(B29:M29,$B$24:$M$24)/SUM($B$24:$M$24) -> 11.769361
A30: IMM-EB.MCV.LS | B30: 3.3845713 | C30: 2.1986171 | D30: 2.3031178 | E30: 2.767207 | F30: 1.8758652 | G30: 1.1105575 | H30: 0 | I30: 0 | J30: 0 | K30: 0 | L30: 0 | M30: 0 | N30: =SUM(B30:M30) -> 13.639936
A31: CV(GAR) | B31: 5821.883 | C31: 5816.4871 | D31: 5824.2204 | E31: 5826.2223 | F31: 5821.6228 | G31: 5824.0809 | H31: 0 | I31: 0 | J31: 0 | K31: 0 | L31: 0 | M31: 0 | N31: =SUMPRODUCT(B31:M31,$B$30:$M$30)/SUM($B$30:$M$30) -> 5822.4314
A32: TS | B32: 0.89812632 | C32: 0.89994494 | D32: 0.90129647 | E32: 0.90153154 | F32: 0.90292127 | G32: 0.90325732 | H32: 0 | I32: 0 | J32: 0 | K32: 0 | L32: 0 | M32: 0 | N32: =SUMPRODUCT(B32:M32,$B$30:$M$30)/SUM($B$30:$M$30) -> 0.90072278
A33: Ash | B33: 8.6642459 | C33: 8.6537904 | D33: 8.6423873 | E33: 8.5289327 | F33: 8.5159535 | G33: 8.5014972 | H33: 0 | I33: 0 | J33: 0 | K33: 0 | L33: 0 | M33: 0 | N33: =SUMPRODUCT(B33:M33,$B$30:$M$30)/SUM($B$30:$M$30) -> 8.5977728
A34: Moist | B34: 11.332981 | C34: 11.336869 | D34: 11.369268 | E34: 11.350128 | F34: 11.399581 | G34: 11.357707 | H34: 0 | I34: 0 | J34: 0 | K34: 0 | L34: 0 | M34: 0 | N34: =SUMPRODUCT(B34:M34,$B$30:$M$30)/SUM($B$30:$M$30) -> 11.354386
A35: TM | B35: 16.332981 | C35: 16.336869 | D35: 16.369268 | E35: 16.350128 | F35: 16.399581 | G35: 16.357707 | H35: 0 | I35: 0 | J35: 0 | K35: 0 | L35: 0 | M35: 0 | N35: =SUMPRODUCT(B35:M35,$B$30:$M$30)/SUM($B$30:$M$30) -> 16.354386
A36: IMM-EB.MCV.MS | B36: 2.5218825 | C36: 7.2154786 | D36: 26.720101 | E36: 6.3272233 | F36: 12.630174 | G36: 4.8087851 | H36: 12.094951 | I36: 14.998053 | J36: 83.697273 | K36: 94.400599 | L36: 71.33532 | M36: 85.965624 | N36: =SUM(B36:M36) -> 422.71546
A37: CV(GAR) | B37: 6013.744 | C37: 5958.5719 | D37: 6011.5142 | E37: 6033.7912 | F37: 5987.1311 | G37: 6002.8141 | H37: 6036.2059 | I37: 6005.6296 | J37: 5996.4183 | K37: 6012.5832 | L37: 6026.6617 | M37: 6027.4417 | N37: =SUMPRODUCT(B37:M37,$B$36:$M$36)/SUM($N$36) -> 6013.6725
A38: TS | B38: 1.5719259 | C38: 1.5704928 | D38: 1.5645055 | E38: 1.5541281 | F38: 1.5514426 | G38: 1.5490809 | H38: 1.5706205 | I38: 1.5667221 | J38: 1.5492652 | K38: 1.553251 | L38: 1.5598162 | M38: 1.5724278 | N38: =SUMPRODUCT(B38:M38,$B$36:$M$36)/SUM($N$36) -> 1.5594733
A39: Ash | B39: 6.0748082 | C39: 6.153097 | D39: 6.1792076 | E39: 5.197632 | F39: 5.2945573 | G39: 5.236934 | H39: 5.1052577 | I39: 5.3674075 | J39: 5.3569251 | K39: 5.169691 | L39: 5.1649103 | M39: 5.3009891 | N39: =SUMPRODUCT(B39:M39,$B$36:$M$36)/SUM($N$36) -> 5.3287414
A40: Moist | B40: 10.127325 | C40: 10.233784 | D40: 10.532647 | E40: 10.3526 | F40: 10.781854 | G40: 10.481305 | H40: 10.365903 | I40: 10.468448 | J40: 10.443604 | K40: 10.274018 | L40: 10.240397 | M40: 9.9507726 | N40: =SUMPRODUCT(B40:M40,$B$36:$M$36)/SUM($N$36) -> 10.279207
A41: TM | B41: 15.127325 | C41: 15.233784 | D41: 15.532647 | E41: 15.3526 | F41: 15.781854 | G41: 15.481305 | H41: 15.365903 | I41: 15.468448 | J41: 15.443604 | K41: 15.274018 | L41: 15.240397 | M41: 14.950773 | N41: =SUMPRODUCT(B41:M41,$B$36:$M$36)/SUM($N$36) -> 15.279207
...

Sheet Outlook 4+8
A1: ITM outlook 2025 (4+8)
B3: Act. | C3: Act. | D3: Act. | E3: Act. | F3: Out. | G3: Out. | H3: Out. | I3: Out. | J3: Out. | K3: Out. | L3: Out. | M3: Out. | N3: Out.
A4: IMM | B4: Jan | C4: Feb | D4: Mar | E4: Apr | F4: May | G4: Jun | H4: Jul | I4: Aug | J4: Sep | K4: Oct | L4: Nov | M4: Dec | N4: Total | P4: Budget 2025
A5: OB Removal (KBcm) | B5: =SUM(B6:B7) -> 6763.0376 | C5: =SUM(C6:C7) -> 7421.6153 | D5: =SUM(D6:D7) -> 6667.0223 | E5: =SUM(E6:E7) -> 6380.9103 | F5: =SUM(F6:F7) -> 8427.9132 | G5: =SUM(G6:G7) -> 7640.614 | H5: =SUM(H6:H7) -> 8789.2468 | I5: =SUM(I6:I7) -> 8512.679 | ... M5: =SUM(M6:M7) -> 8533.4634 | N5: =SUM(B5:M5) -> 95198.037 | P5: ='Budget 2025'!N5 -> 94714.478 | Q5: =N5/P5 -> 1.0051054
A6: PAMA (WB) | B6: 2244.6941 | C6: 2827.069 | D6: 2295.7418 | E6: 1946.6079 | F6: 2953.7157 | G6: 2717.2507 | H6: 3223.0037 | I6: 3121.8471 | J6: 2945.2593 | K6: 3171.8912 | L6: 3162.2305 | M6: 3070.0459 | N6: =SUM(B6:M6) -> 33679.357 | P6: ='Budget 2025'!N6 -> 33532.659
A7: PAMA (EB) | B7: 4518.3435 | C7: 4594.5463 | D7: 4371.2805 | E7: 4434.3024 | F7: 5474.1975 | G7: 4923.3633 | H7: 5566.2431 | I7: 5390.8319 | J7: 5542.5331 | K7: 5587.5705 | L7: 5652.0501 | M7: 5463.4174 | N7: =SUM(B7:M7) -> 61518.68 | P7: ='Budget 2025'!N7 -> 61181.819
A8: ROM Production (Kton) | B8: =SUM(B9:B11) -> 542.83357 | C8: =SUM(C9:C11) -> 554.11951 | D8: =SUM(D9:D11) -> 482.78672 | E8: =SUM(E9:E11) -> 444.51201 | F8: =SUM(F9:F11) -> 570.02058 | G8: =SUM(G9:G11) -> 582.5 | H8: =SUM(H9:H11) -> 610 | I8: =SUM(I9:I11) -> 660 | ... N8: =SUM(N9:N11) -> 7047.5 | P8: ='Budget 2025'!N8 -> 6950 | Q8: =N8/P8 -> 1.0140288
A9: PAMA (WB) | B9: 158.42587 | C9: 192.58567 | D9: 141.12357 | E9: 88.560644 | F9: 165.15203 | G9: 140 | H9: 165 | I9: 165 | J9: 130 | K9: 130 | L9: 130 | M9: 126.65221 | N9: =SUM(B9:M9) -> 1732.5 | P9: ='Budget 2025'!N9 -> 1862.5
A10: PAMA (EB) | B10: 384.4077 | C10: 361.53383 | D10: 341.66315 | E10: 355.95136 | F10: 404.86854 | G10: 442.5 | H10: 445 | I10: 495 | J10: 530 | K10: 530 | L10: 530 | M10: 494.07541 | N10: =SUM(B10:M10) -> 5315 | P10: ='Budget 2025'!N10 -> 5087.5
A11: Fine Coal (WB) | B11: 0 | C11: 0 | D11: 0 | E11: 0 | F11: 0 | G11: 0 | H11: 0 | I11: 0 | J11: 0 | K11: 0 | L11: 0 | M11: 0 | N11: =SUM(B11:M11) -> 0 | P11: ='Budget 2025'!N11 -> 0
A12: SR ROM Total | B12: =B5/B8 -> 12.458768 | C12: =C5/C8 -> 13.393528 | D12: =D5/D8 -> 13.809457 | E12: =E5/E8 -> 14.354866 | F12: =F5/F8 -> 14.785279 | G12: =G5/G8 -> 13.116934 | H12: =H5/H8 -> 14.408601 | I12: =I5/I8 -> 12.897998 | ... N12: =N5/N8 -> 13.508058 | P12: ='Budget 2025'!N12 -> 13.627982
A13: FC Product (Kton) | B13: =SUM(B14:B16) -> 612.68293 | C13: =SUM(C14:C16) -> 584.91494 | D13: =SUM(D14:D16) -> 501.01074 | E13: =SUM(E14:E16) -> 479.30495 | F13: =SUM(F14:F16) -> 584.25 | G13: =SUM(G14:G16) -> 584.25 | H13: =SUM(H14:H16) -> 625.75 | I13: =SUM(I14:I16) -> 672.75 | ... M13: =SUM(M14:M16) -> 533.33645 | N13: =SUM(B13:M13) -> 7135 | P13: ='Budget 2025'!N13 -> 7100
A14: PAMA (WB) | B14: 203.84233 | C14: 213.15935 | D14: 151.07621 | E14: 100.53441 | F14: 165 | G14: 148.5 | H14: 175 | I14: 165 | J14: 130 | K14: 115 | L14: 115 | M14: 47.887695 | N14: =SUM(B14:M14) -> 1730 | P14: ='Budget 2025'!N14 -> 1862.5
A15: PAMA (EB) | B15: 408.8406 | C15: 371.75559 | D15: 349.93453 | E15: 378.57866 | F15: 415 | G15: 431.5 | H15: 446.5 | I15: 495 | J15: 530 | K15: 514.25 | L15: 514.25 | M15: 472.69875 | N15: =SUM(B15:M15) -> 5328.3081 | P15: ='Budget 2025'!N15 -> 5110
A16: Fine Coal | B16: 0 | C16: 0 | D16: 0 | E16: 0.19186901 | F16: 4.25 | G16: 4.25 | H16: 4.25 | I16: 12.75 | J16: 12.75 | K16: 12.75 | L16: 12.75 | M16: 12.75 | N16: =SUM(B16:M16) -> 76.691869 | P16: ='Budget 2025'!N48 -> 127.5
A17: SR FC Total | B17: =B5/B13 -> 11.038397 | C17: =C5/C13 -> 12.688367 | D17: =D5/D13 -> 13.307145 | E17: =E5/E13 -> 13.31284 | F17: =F5/F13 -> 14.425183 | G17: =G5/G13 -> 13.077645 | H17: =H5/H13 -> 14.04594 | I17: =I5/I13 -> 12.653555 | ... N17: =N5/N13 -> 13.342402 | P17: ='Budget 2025'!N17 -> 13.340067
A18: IMM-WB.HCV.LS | B18: 146.18254 | C18: 147.46076 | D18: 104.99952 | E18: 70.128194 | F18: 130 | G18: 71.061876 | H18: 103.46868 | I18: 88.954305 | J18: 60.50972 | K18: 66.095478 | L18: 66.452916 | M18: 47.887695 | N18: =SUM(B18:M18) -> 1103.2017 | P18: ='Budget 2025'!N18 -> 1228.8032
A19: CV(GAR) | B19: 6193.9879 | C19: 6105.8162 | D19: 6211.2744 | E19: 6152.0829 | F19: 6008.2957 | G19: 6195.4139 | H19: 6259.4326 | I19: 6230.9729 | J19: 6374.9065 | K19: 6400.56 | L19: 6233.1866 | M19: 6244.1353 | N19: =SUMPRODUCT(B19:M19,$B$18:$M$18)/SUM($B$18:$M$18) -> 6195.3516 | P19: ='Budget 2025'!N19 -> 6169.7769
A20: TS | B20: 0.61677597 | C20: 0.68122223 | D20: 0.59905828 | E20: 0.64019198 | F20: 0.8860665 | G20: 0.79806691 | H20: 0.80275322 | I20: 0.80158132 | J20: 0.79960709 | K20: 0.84666532 | L20: 0.86800879 | M20: 0.75911701 | N20: =SUMPRODUCT(B20:M20,$B$18:$M$18)/SUM($B$18:$M$18) -> 0.74606059 | P20: ='Budget 2025'!N20 -> 0.81080181
A21: Ash | B21: 8.41834 | C21: 8.393601 | D21: 8.4815141 | E21: 7.9869977 | F21: 8.967472 | G21: 8.274516 | H21: 8.4062057 | I21: 8.2506424 | J21: 7.9678796 | K21: 8.2594088 | L21: 8.3090156 | M21: 7.7956903 | N21: =SUMPRODUCT(B21:M21,$B$18:$M$18)/SUM($B$18:$M$18) -> 8.3665686 | P21: ='Budget 2025'!N21 -> 8.3745645
A22: Moist | B22: 8.6372078 | C22: 9.4241924 | D22: 8.714191 | E22: 9.2338941 | F22: 8.8974814 | G22: 8.4669603 | H22: 8.1639926 | I22: 7.8478728 | J22: 7.1238159 | K22: 7.1464323 | L22: 7.0760958 | M22: 7.6334264 | N22: =SUMPRODUCT(B22:M22,$B$18:$M$18)/SUM($B$18:$M$18) -> 8.3894011 | P22: ='Budget 2025'!N22 -> 8.0403443
A23: TM | B23: 11.489526 | C23: 12.325215 | D23: 11.133918 | E23: 12.344042 | F23: 13.79115 | G23: 13.492323 | H23: 13.189355 | I23: 12.873235 | J23: 12.149178 | K23: 12.171795 | L23: 12.101458 | M23: 12.658789 | N23: =SUMPRODUCT(B23:M23,$B$18:$M$18)/SUM($B$18:$M$18) -> 12.457605 | P23: ='Budget 2025'!N23 -> 13.065707
A24: IMM-WB.HCV.HS | B24: 57.659789 | C24: 65.698593 | D24: 46.076686 | E24: 30.406221 | F24: 35 | G24: 77.438124 | H24: 71.531318 | I24: 76.045695 | J24: 69.49028 | K24: 48.904522 | L24: 48.547084 | M24: 0 | N24: =SUM(B24:M24) -> 626.79831 | P24: ='Budget 2025'!N24 -> 633.69685
A25: CV(GAR) | B25: 5947.3932 | C25: 5939.4465 | D25: 6026.7648 | E25: 5928.2234 | F25: 5964.604 | G25: 5905.9183 | H25: 5962.1308 | I25: 5928.4411 | J25: 6005.5198 | K25: 5894.1649 | L25: 5910.574 | M25: 0 | N25: =SUMPRODUCT(B25:M25,$B$24:$M$24)/SUM($B$24:$M$24) -> 5946.124 | P25: ='Budget 2025'!N25 -> 5965.7827
A26: TS | B26: 1.9789488 | C26: 2.2887477 | D26: 2.1709775 | E26: 1.9301202 | F26: 2.5411798 | G26: 2.7715287 | H26: 2.7609279 | I26: 2.697927 | J26: 2.6091248 | K26: 2.6713147 | L26: 2.6349423 | M26: 0 | N26: =SUMPRODUCT(B26:M26,$B$24:$M$24)/SUM($B$24:$M$24) -> 2.5036461 | P26: ='Budget 2025'!N26 -> 2.5790489
A27: Ash | B27: 12.398872 | C27: 11.628956 | D27: 11.380259 | E27: 12.152459 | F27: 13.234938 | G27: 14.510182 | H27: 13.50972 | I27: 14.370514 | J27: 13.324647 | K27: 14.771804 | L27: 14.891748 | M27: 0 | N27: =SUMPRODUCT(B27:M27,$B$24:$M$24)/SUM($B$24:$M$24) -> 13.385706 | P27: ='Budget 2025'!N27 -> 13.960595
A28: Moist | B28: 7.8249272 | C28: 7.5595294 | D28: 6.9977463 | E28: 7.2613478 | F28: 6.2776773 | G28: 7.0494548 | H28: 6.8342267 | I28: 6.842531 | J28: 6.8309987 | K28: 7.4057237 | L28: 7.4333415 | M28: 0 | N28: =SUMPRODUCT(B28:M28,$B$24:$M$24)/SUM($B$24:$M$24) -> 7.1212814 | P28: ='Budget 2025'!N28 -> 6.7439986
A29: TM | B29: 10.911081 | C29: 11.826969 | D29: 11.261991 | E29: 11.642346 | F29: 10.785568 | G29: 12.074817 | H29: 11.859589 | I29: 11.867893 | J29: 11.856361 | K29: 12.431086 | L29: 12.458704 | M29: 0 | N29: =SUMPRODUCT(B29:M29,$B$24:$M$24)/SUM($B$24:$M$24) -> 11.772707 | P29: ='Budget 2025'!N29 -> 11.769361
A30: IMM-EB.MCV.LS | B30: 4.1511632 | C30: 4.8753097 | D30: 8.972062 | E30: 7.4826072 | F30: 10 | G30: 1.9294767 | H30: 0 | I30: 0 | J30: 0 | K30: 0 | L30: 0 | M30: 0 | N30: =SUM(B30:M30) -> 37.410619 | P30: ='Budget 2025'!N30 -> 13.639936
A31: CV(GAR) | B31: 5768.2424 | C31: 5970.6107 | D31: 5842.9196 | E31: 6060.3315 | F31: 5833.2311 | G31: 5811.3441 | H31: 0 | I31: 0 | J31: 0 | K31: 0 | L31: 0 | M31: 0 | N31: =SUMPRODUCT(B31:M31,$B$30:$M$30)/SUM($B$30:$M$30) -> 5890.5407 | P31: ='Budget 2025'!N31 -> 5822.4314
A32: TS | B32: 0.90470615 | C32: 0.97326494 | D32: 0.89969842 | E32: 0.91618026 | F32: 0.9511492 | G32: 0.86029826 | H32: 0 | I32: 0 | J32: 0 | K32: 0 | L32: 0 | M32: 0 | N32: =SUMPRODUCT(B32:M32,$B$30:$M$30)/SUM($B$30:$M$30) -> 0.92485868 | P32: ='Budget 2025'!N32 -> 0.90072278
A33: Ash | B33: 8.4980056 | C33: 6.454713 | D33: 6.9734339 | E33: 5.5176512 | F33: 8.819985 | G33: 8.7157061 | H33: 0 | I33: 0 | J33: 0 | K33: 0 | L33: 0 | M33: 0 | N33: =SUMPRODUCT(B33:M33,$B$30:$M$30)/SUM($B$30:$M$30) -> 7.3672781 | P33: ='Budget 2025'!N33 -> 8.5977728
A34: Moist | B34: 10.861527 | C34: 11.334285 | D34: 10.91524 | E34: 11.119528 | F34: 12.2149 | G34: 11.423063 | H34: 0 | I34: 0 | J34: 0 | K34: 0 | L34: 0 | M34: 0 | N34: =SUMPRODUCT(B34:M34,$B$30:$M$30)/SUM($B$30:$M$30) -> 11.378345 | P34: ='Budget 2025'!N34 -> 11.354386
A35: TM | B35: 14.308473 | C35: 13.960815 | D35: 14.885351 | E35: 13.934471 | F35: 16.7849 | G35: 16.423063 | H35: 0 | I35: 0 | J35: 0 | K35: 0 | L35: 0 | M35: 0 | N35: =SUMPRODUCT(B35:M35,$B$30:$M$30)/SUM($B$30:$M$30) -> 15.097732 | P35: ='Budget 2025'!N35 -> 16.354386
A36: IMM-EB.MCV.MS | B36: 16.385665 | C36: 4.2318727 | D36: 27.481461 | E36: 41.321236 | F36: 25 | G36: 7.8203168 | H36: 35.332551 | I36: 27.662426 | J36: 80.262722 | K36: 89.777098 | L36: 74.169949 | M36: 71.808994 | N36: =SUM(B36:M36) -> 501.25429 | P36: ='Budget 2025'!N36 -> 422.71546
A37: CV(GAR) | B37: 6095.6967 | C37: 5702.0802 | D37: 5950.0061 | E37: 5974.4204 | F37: 5852.0766 | G37: 5991.2837 | H37: 6020.8684 | I37: 6013.3215 | J37: 6007.8378 | K37: 5999.9701 | L37: 6040.3584 | M37: 6028.6326 | N37: =SUMPRODUCT(B37:M37,$B$36:$M$36)/SUM($B$36:$M$36) -> 6001.7792 | P37: ='Budget 2025'!N37 -> 6013.6725
A38: TS | B38: 1.5214168 | C38: 1.2568182 | D38: 1.4097729 | E38: 1.483995 | F38: 1.5987736 | G38: 1.5415472 | H38: 1.5694494 | I38: 1.5853859 | J38: 1.5745159 | K38: 1.5672109 | L38: 1.5887592 | M38: 1.573939 | N38: =SUMPRODUCT(B38:M38,$B$36:$M$36)/SUM($B$36:$M$36) -> 1.5552585 | P38: ='Budget 2025'!N38 -> 1.5594733
A39: Ash | B39: 5.147646 | C39: 7.9572727 | D39: 6.2814993 | E39: 5.8970893 | F39: 6.9774206 | G39: 5.2091521 | H39: 5.1963486 | I39: 5.239347 | J39: 5.4473366 | K39: 5.466429 | L39: 5.2138936 | M39: 5.2948455 | N39: =SUMPRODUCT(B39:M39,$B$36:$M$36)/SUM($B$36:$M$36) -> 5.5319976 | P39: ='Budget 2025'!N39 -> 5.3287414
A40: Moist | B40: 11.52539 | C40: 13.017273 | D40: 11.444174 | E40: 12.148882 | F40: 10.910863 | G40: 10.574814 | H40: 10.507448 | I40: 10.48465 | J40: 10.349522 | K40: 10.246272 | L40: 10.128781 | M40: 9.9377827 | N40: =SUMPRODUCT(B40:M40,$B$36:$M$36)/SUM($B$36:$M$36) -> 10.55879 | P40: ='Budget 2025'!N40 -> 10.279207
A41: TM | B41: 13.645355 | C41: 15.082727 | D41: 14.292213 | E41: 14.144596 | F41: 15.814649 | G41: 15.574814 | H41: 15.507448 | I41: 15.48465 | J41: 15.349522 | K41: 15.246272 | L41: 15.128781 | M41: 14.937783 | N41: =SUMPRODUCT(B41:M41,$B$36:$M$36)/SUM($B$36:$M$36) -> 15.069427 | P41: ='Budget 2025'!N41 -> 15.279207
...

Sheet Outlook Quarterly 4+8
A1: ITM outlook 2025 (4+8)
B3: Act. | C3: Out. | D3: Out. | E3: Out. | F3: Out.
A4: IMM | B4: Q1 | C4: Q2 | D4: Q3 | E4: Q4 | F4: Total | H4: Budget 2025
A5: OB Removal (KBcm) | B5: =SUM(B6:B7) -> 20851.675 | C5: =SUM(C6:C7) -> 22449.437 | D5: =SUM(D6:D7) -> 25789.718 | E5: =SUM(E6:E7) -> 26107.206 | F5: =SUM(B5:E5) -> 95198.037 | H5: ='Budget 2025'!N5 -> 94714.478 | I5: =F5/H5 -> 1.0051054
A6: PAMA (WB) | B6: =SUMIFS('Outlook 4+8'!$B6:$M6,'Outlook 4+8'!$B$185:$M$185,'Outlook Quarterly 4+8'!B$4) -> 7367.5048 | C6: =SUMIFS('Outlook 4+8'!$B6:$M6,'Outlook 4+8'!$B$185:$M$185,'Outlook Quarterly 4+8'!C$4) -> 7617.5744 | D6: =SUMIFS('Outlook 4+8'!$B6:$M6,'Outlook 4+8'!$B$185:$M$185,'Outlook Quarterly 4+8'!D$4) -> 9290.1101 | E6: =SUMIFS('Outlook 4+8'!$B6:$M6,'Outlook 4+8'!$B$185:$M$185,'Outlook Quarterly 4+8'!E$4) -> 9404.1677 | F6: =SUM(B6:E6) -> 33679.357 | H6: ='Budget 2025'!N6 -> 33532.659
A7: PAMA (EB) | B7: =SUMIFS('Outlook 4+8'!$B7:$M7,'Outlook 4+8'!$B$185:$M$185,'Outlook Quarterly 4+8'!B$4) -> 13484.17 | C7: =SUMIFS('Outlook 4+8'!$B7:$M7,'Outlook 4+8'!$B$185:$M$185,'Outlook Quarterly 4+8'!C$4) -> 14831.863 | D7: =SUMIFS('Outlook 4+8'!$B7:$M7,'Outlook 4+8'!$B$185:$M$185,'Outlook Quarterly 4+8'!D$4) -> 16499.608 | E7: =SUMIFS('Outlook 4+8'!$B7:$M7,'Outlook 4+8'!$B$185:$M$185,'Outlook Quarterly 4+8'!E$4) -> 16703.038 | F7: =SUM(B7:E7) -> 61518.68 | H7: ='Budget 2025'!N7 -> 61181.819
A8: ROM Production (Kton) | B8: =SUM(B9:B11) -> 1579.7398 | C8: =SUM(C9:C11) -> 1597.0326 | D8: =SUM(D9:D11) -> 1930 | E8: =SUM(E9:E11) -> 1940.7276 | F8: =SUM(F9:F11) -> 7047.5 | H8: ='Budget 2025'!N8 -> 6950 | I8: =F8/H8 -> 1.0140288
A9: PAMA (WB) | B9: =SUMIFS('Outlook 4+8'!$B9:$M9,'Outlook 4+8'!$B$185:$M$185,'Outlook Quarterly 4+8'!B$4) -> 492.13512 | C9: =SUMIFS('Outlook 4+8'!$B9:$M9,'Outlook 4+8'!$B$185:$M$185,'Outlook Quarterly 4+8'!C$4) -> 393.71268 | D9: =SUMIFS('Outlook 4+8'!$B9:$M9,'Outlook 4+8'!$B$185:$M$185,'Outlook Quarterly 4+8'!D$4) -> 460 | E9: =SUMIFS('Outlook 4+8'!$B9:$M9,'Outlook 4+8'!$B$185:$M$185,'Outlook Quarterly 4+8'!E$4) -> 386.65221 | F9: =SUM(B9:E9) -> 1732.5 | H9: ='Budget 2025'!N9 -> 1862.5
A10: PAMA (EB) | B10: =SUMIFS('Outlook 4+8'!$B10:$M10,'Outlook 4+8'!$B$185:$M$185,'Outlook Quarterly 4+8'!B$4) -> 1087.6047 | C10: =SUMIFS('Outlook 4+8'!$B10:$M10,'Outlook 4+8'!$B$185:$M$185,'Outlook Quarterly 4+8'!C$4) -> 1203.3199 | D10: =SUMIFS('Outlook 4+8'!$B10:$M10,'Outlook 4+8'!$B$185:$M$185,'Outlook Quarterly 4+8'!D$4) -> 1470 | E10: =SUMIFS('Outlook 4+8'!$B10:$M10,'Outlook 4+8'!$B$185:$M$185,'Outlook Quarterly 4+8'!E$4) -> 1554.0754 | F10: =SUM(B10:E10) -> 5315 | H10: ='Budget 2025'!N10 -> 5087.5
A11: Fine Coal (WB) | B11: =SUMIFS('Outlook 4+8'!$B11:$M11,'Outlook 4+8'!$B$185:$M$185,'Outlook Quarterly 4+8'!B$4) -> 0 | C11: =SUMIFS('Outlook 4+8'!$B11:$M11,'Outlook 4+8'!$B$185:$M$185,'Outlook Quarterly 4+8'!C$4) -> 0 | D11: =SUMIFS('Outlook 4+8'!$B11:$M11,'Outlook 4+8'!$B$185:$M$185,'Outlook Quarterly 4+8'!D$4) -> 0 | E11: =SUMIFS('Outlook 4+8'!$B11:$M11,'Outlook 4+8'!$B$185:$M$185,'Outlook Quarterly 4+8'!E$4) -> 0 | F11: =SUM(B11:E11) -> 0 | H11: ='Budget 2025'!N11 -> 0
A12: SR ROM Total | B12: =B5/B8 -> 13.199437 | C12: =C5/C8 -> 14.056969 | D12: =D5/D8 -> 13.362548 | E12: =E5/E8 -> 13.452277 | F12: =F5/F8 -> 13.508058 | H12: ='Budget 2025'!N12 -> 13.627982
A13: FC Product (Kton) | B13: =SUM(B14:B16) -> 1698.6086 | C13: =SUM(C14:C16) -> 1647.8049 | D13: =SUM(D14:D16) -> 1971.25 | E13: =SUM(E14:E16) -> 1817.3364 | F13: =SUM(B13:E13) -> 7135 | H13: ='Budget 2025'!N13 -> 7100
A14: PAMA (WB) | B14: =SUMIFS('Outlook 4+8'!$B14:$M14,'Outlook 4+8'!$B$185:$M$185,'Outlook Quarterly 4+8'!B$4) -> 568.07789 | C14: =SUMIFS('Outlook 4+8'!$B14:$M14,'Outlook 4+8'!$B$185:$M$185,'Outlook Quarterly 4+8'!C$4) -> 414.03441 | D14: =SUMIFS('Outlook 4+8'!$B14:$M14,'Outlook 4+8'!$B$185:$M$185,'Outlook Quarterly 4+8'!D$4) -> 470 | E14: =SUMIFS('Outlook 4+8'!$B14:$M14,'Outlook 4+8'!$B$185:$M$185,'Outlook Quarterly 4+8'!E$4) -> 277.8877 | F14: =SUM(B14:E14) -> 1730 | H14: ='Budget 2025'!N14 -> 1862.5
A15: PAMA (EB) | B15: =SUMIFS('Outlook 4+8'!$B15:$M15,'Outlook 4+8'!$B$185:$M$185,'Outlook Quarterly 4+8'!B$4) -> 1130.5307 | C15: =SUMIFS('Outlook 4+8'!$B15:$M15,'Outlook 4+8'!$B$185:$M$185,'Outlook Quarterly 4+8'!C$4) -> 1225.0787 | D15: =SUMIFS('Outlook 4+8'!$B15:$M15,'Outlook 4+8'!$B$185:$M$185,'Outlook Quarterly 4+8'!D$4) -> 1471.5 | E15: =SUMIFS('Outlook 4+8'!$B15:$M15,'Outlook 4+8'!$B$185:$M$185,'Outlook Quarterly 4+8'!E$4) -> 1501.1988 | F15: =SUM(B15:E15) -> 5328.3081 | H15: ='Budget 2025'!N15 -> 5110
A16: Fine Coal | B16: =SUMIFS('Outlook 4+8'!$B16:$M16,'Outlook 4+8'!$B$185:$M$185,'Outlook Quarterly 4+8'!B$4) -> 0 | C16: =SUMIFS('Outlook 4+8'!$B16:$M16,'Outlook 4+8'!$B$185:$M$185,'Outlook Quarterly 4+8'!C$4) -> 8.691869 | D16: =SUMIFS('Outlook 4+8'!$B16:$M16,'Outlook 4+8'!$B$185:$M$185,'Outlook Quarterly 4+8'!D$4) -> 29.75 | E16: =SUMIFS('Outlook 4+8'!$B16:$M16,'Outlook 4+8'!$B$185:$M$185,'Outlook Quarterly 4+8'!E$4) -> 38.25 | F16: =SUM(B16:E16) -> 76.691869 | H16: ='Budget 2025'!N48 -> 127.5
A17: SR FC Total | B17: =B5/B13 -> 12.275739 | C17: =C5/C13 -> 13.623844 | D17: =D5/D13 -> 13.082926 | E17: =E5/E13 -> 14.365643 | F17: =F5/F13 -> 13.342402 | H17: ='Budget 2025'!N17 -> 13.340067
A18: IMM-WB.HCV.LS | B18: =SUMIFS('Outlook 4+8'!$B18:$M18,'Outlook 4+8'!$B$185:$M$185,'Outlook Quarterly 4+8'!B$4) -> 398.64282 | C18: =SUMIFS('Outlook 4+8'!$B18:$M18,'Outlook 4+8'!$B$185:$M$185,'Outlook Quarterly 4+8'!C$4) -> 271.19007 | D18: =SUMIFS('Outlook 4+8'!$B18:$M18,'Outlook 4+8'!$B$185:$M$185,'Outlook Quarterly 4+8'!D$4) -> 252.93271 | E18: =SUMIFS('Outlook 4+8'!$B18:$M18,'Outlook 4+8'!$B$185:$M$185,'Outlook Quarterly 4+8'!E$4) -> 180.43609 | F18: =SUM(B18:E18) -> 1103.2017 | H18: ='Budget 2025'!N18 -> 1228.8032
A19: CV(GAR) | B19: =SUMPRODUCT('Outlook 4+8'!$B19:$D19,'Outlook 4+8'!$B$18:$D$18)/SUM('Outlook 4+8'!$B$18:$D$18) -> 6165.9257 | C19: =SUMPRODUCT('Outlook 4+8'!$E19:$G19,'Outlook 4+8'!$E$18:$G$18)/SUM('Outlook 4+8'!$E$18:$G$18) -> 6094.5101 | D19: =SUMPRODUCT('Outlook 4+8'!$H19:$J19,'Outlook 4+8'!$H$18:$J$18)/SUM('Outlook 4+8'!$H$18:$J$18) -> 6277.0487 | E19: =SUMPRODUCT('Outlook 4+8'!$K19:$M19,'Outlook 4+8'!$K$18:$M$18)/SUM('Outlook 4+8'!$K$18:$M$18) -> 6297.4028 | F19: =SUMPRODUCT(B19:E19,$B$18:$E$18)/SUM($B$18:$E$18) -> 6195.3516 | H19: ='Budget 2025'!N19 -> 6169.7769
A20: TS | B20: =SUMPRODUCT('Outlook 4+8'!$B20:$D20,'Outlook 4+8'!$B$18:$D$18)/SUM('Outlook 4+8'!$B$18:$D$18) -> 0.63594838 | C20: =SUMPRODUCT('Outlook 4+8'!$E20:$G20,'Outlook 4+8'!$E$18:$G$18)/SUM('Outlook 4+8'!$E$18:$G$18) -> 0.7994256 | D20: =SUMPRODUCT('Outlook 4+8'!$H20:$J20,'Outlook 4+8'!$H$18:$J$18)/SUM('Outlook 4+8'!$H$18:$J$18) -> 0.80158842 | E20: =SUMPRODUCT('Outlook 4+8'!$K20:$M20,'Outlook 4+8'!$K$18:$M$18)/SUM('Outlook 4+8'!$K$18:$M$18) -> 0.83129062 | F20: =SUMPRODUCT(B20:E20,$B$18:$E$18)/SUM($B$18:$E$18) -> 0.74606059 | H20: ='Budget 2025'!N20 -> 0.81080181
A21: Ash | B21: =SUMPRODUCT('Outlook 4+8'!$B21:$D21,'Outlook 4+8'!$B$18:$D$18)/SUM('Outlook 4+8'!$B$18:$D$18) -> 8.4258284 | C21: =SUMPRODUCT('Outlook 4+8'!$E21:$G21,'Outlook 4+8'!$E$18:$G$18)/SUM('Outlook 4+8'!$E$18:$G$18) -> 8.5323468 | D21: =SUMPRODUCT('Outlook 4+8'!$H21:$J21,'Outlook 4+8'!$H$18:$J$18)/SUM('Outlook 4+8'!$H$18:$J$18) -> 8.2466336 | E21: =SUMPRODUCT('Outlook 4+8'!$K21:$M21,'Outlook 4+8'!$K$18:$M$18)/SUM('Outlook 4+8'!$K$18:$M$18) -> 8.1546078 | F21: =SUMPRODUCT(B21:E21,$B$18:$E$18)/SUM($B$18:$E$18) -> 8.3665686 | H21: ='Budget 2025'!N21 -> 8.3745645
A22: Moist | B22: =SUMPRODUCT('Outlook 4+8'!$B22:$D22,'Outlook 4+8'!$B$18:$D$18)/SUM('Outlook 4+8'!$B$18:$D$18) -> 8.9485957 | C22: =SUMPRODUCT('Outlook 4+8'!$E22:$G22,'Outlook 4+8'!$E$18:$G$18)/SUM('Outlook 4+8'!$E$18:$G$18) -> 8.8716633 | D22: =SUMPRODUCT('Outlook 4+8'!$H22:$J22,'Outlook 4+8'!$H$18:$J$18)/SUM('Outlook 4+8'!$H$18:$J$18) -> 7.8039719 | E22: =SUMPRODUCT('Outlook 4+8'!$K22:$M22,'Outlook 4+8'!$K$18:$M$18)/SUM('Outlook 4+8'!$K$18:$M$18) -> 7.2497761 | F22: =SUMPRODUCT(B22:E22,$B$18:$E$18)/SUM($B$18:$E$18) -> 8.3894011 | H22: ='Budget 2025'!N22 -> 8.0403443
A23: TM | B23: =SUMPRODUCT('Outlook 4+8'!$B23:$D23,'Outlook 4+8'!$B$18:$D$18)/SUM('Outlook 4+8'!$B$18:$D$18) -> 11.704989 | C23: =SUMPRODUCT('Outlook 4+8'!$E23:$G23,'Outlook 4+8'!$E$18:$G$18)/SUM('Outlook 4+8'!$E$18:$G$18) -> 13.338633 | D23: =SUMPRODUCT('Outlook 4+8'!$H23:$J23,'Outlook 4+8'!$H$18:$J$18)/SUM('Outlook 4+8'!$H$18:$J$18) -> 12.829334 | E23: =SUMPRODUCT('Outlook 4+8'!$K23:$M23,'Outlook 4+8'!$K$18:$M$18)/SUM('Outlook 4+8'!$K$18:$M$18) -> 12.275138 | F23: =SUMPRODUCT(B23:E23,$B$18:$E$18)/SUM($B$18:$E$18) -> 12.457605 | H23: ='Budget 2025'!N23 -> 13.065707
A24: IMM-WB.HCV.HS | B24: =SUMIFS('Outlook 4+8'!$B24:$M24,'Outlook 4+8'!$B$185:$M$185,'Outlook Quarterly 4+8'!B$4) -> 169.43507 | C24: =SUMIFS('Outlook 4+8'!$B24:$M24,'Outlook 4+8'!$B$185:$M$185,'Outlook Quarterly 4+8'!C$4) -> 142.84434 | D24: =SUMIFS('Outlook 4+8'!$B24:$M24,'Outlook 4+8'!$B$185:$M$185,'Outlook Quarterly 4+8'!D$4) -> 217.06729 | E24: =SUMIFS('Outlook 4+8'!$B24:$M24,'Outlook 4+8'!$B$185:$M$185,'Outlook Quarterly 4+8'!E$4) -> 97.451605 | F24: =SUM(B24:E24) -> 626.79831 | H24: ='Budget 2025'!N24 -> 633.69685
A25: CV(GAR) | B25: =SUMPRODUCT('Outlook 4+8'!$B25:$D25,'Outlook 4+8'!$B$24:$D$24)/SUM('Outlook 4+8'!$B$24:$D$24) -> 5965.8964 | C25: =SUMPRODUCT('Outlook 4+8'!$E25:$G25,'Outlook 4+8'!$E$24:$G$24)/SUM('Outlook 4+8'!$E$24:$G$24) -> 5925.0455 | D25: =SUMPRODUCT('Outlook 4+8'!$H25:$J25,'Outlook 4+8'!$H$24:$J$24)/SUM('Outlook 4+8'!$H$24:$J$24) -> 5964.2184 | E25: =SUMPRODUCT('Outlook 4+8'!$K25:$M25,'Outlook 4+8'!$K$24:$M$24)/SUM('Outlook 4+8'!$K$24:$M$24) -> 5902.3394 | F25: =SUMPRODUCT(B25:E25,$B$24:$E$24)/SUM($B$24:$E$24) -> 5946.124 | H25: ='Budget 2025'!N25 -> 5965.7827
A26: TS | B26: =SUMPRODUCT('Outlook 4+8'!$B26:$D26,'Outlook 4+8'!$B$24:$D$24)/SUM('Outlook 4+8'!$B$24:$D$24) -> 2.1512944 | C26: =SUMPRODUCT('Outlook 4+8'!$E26:$G26,'Outlook 4+8'!$E$24:$G$24)/SUM('Outlook 4+8'!$E$24:$G$24) -> 2.5359838 | D26: =SUMPRODUCT('Outlook 4+8'!$H26:$J26,'Outlook 4+8'!$H$24:$J$24)/SUM('Outlook 4+8'!$H$24:$J$24) -> 2.6902595 | E26: =SUMPRODUCT('Outlook 4+8'!$K26:$M26,'Outlook 4+8'!$K$24:$M$24)/SUM('Outlook 4+8'!$K$24:$M$24) -> 2.6531952 | F26: =SUMPRODUCT(B26:E26,$B$24:$E$24)/SUM($B$24:$E$24) -> 2.5036461 | H26: ='Budget 2025'!N26 -> 2.5790489
A27: Ash | B27: =SUMPRODUCT('Outlook 4+8'!$B27:$D27,'Outlook 4+8'!$B$24:$D$24)/SUM('Outlook 4+8'!$B$24:$D$24) -> 11.823332 | C27: =SUMPRODUCT('Outlook 4+8'!$E27:$G27,'Outlook 4+8'!$E$24:$G$24)/SUM('Outlook 4+8'!$E$24:$G$24) -> 13.695848 | D27: =SUMPRODUCT('Outlook 4+8'!$H27:$J27,'Outlook 4+8'!$H$24:$J$24)/SUM('Outlook 4+8'!$H$24:$J$24) -> 13.752036 | E27: =SUMPRODUCT('Outlook 4+8'!$K27:$M27,'Outlook 4+8'!$K$24:$M$24)/SUM('Outlook 4+8'!$K$24:$M$24) -> 14.831556 | F27: =SUMPRODUCT(B27:E27,$B$24:$E$24)/SUM($B$24:$E$24) -> 13.385706 | H27: ='Budget 2025'!N27 -> 13.960595
A28: Moist | B28: =SUMPRODUCT('Outlook 4+8'!$B28:$D28,'Outlook 4+8'!$B$24:$D$24)/SUM('Outlook 4+8'!$B$24:$D$24) -> 7.4970729 | C28: =SUMPRODUCT('Outlook 4+8'!$E28:$G28,'Outlook 4+8'!$E$24:$G$24)/SUM('Outlook 4+8'!$E$24:$G$24) -> 6.9054565 | D28: =SUMPRODUCT('Outlook 4+8'!$H28:$J28,'Outlook 4+8'!$H$24:$J$24)/SUM('Outlook 4+8'!$H$24:$J$24) -> 6.8361026 | E28: =SUMPRODUCT('Outlook 4+8'!$K28:$M28,'Outlook 4+8'!$K$24:$M$24)/SUM('Outlook 4+8'!$K$24:$M$24) -> 7.419482 | F28: =SUMPRODUCT(B28:E28,$B$24:$E$24)/SUM($B$24:$E$24) -> 7.1212814 | H28: ='Budget 2025'!N28 -> 6.7439986
A29: TM | B29: =SUMPRODUCT('Outlook 4+8'!$B29:$D29,'Outlook 4+8'!$B$24:$D$24)/SUM('Outlook 4+8'!$B$24:$D$24) -> 11.361645 | C29: =SUMPRODUCT('Outlook 4+8'!$E29:$G29,'Outlook 4+8'!$E$24:$G$24)/SUM('Outlook 4+8'!$E$24:$G$24) -> 11.666866 | D29: =SUMPRODUCT('Outlook 4+8'!$H29:$J29,'Outlook 4+8'!$H$24:$J$24)/SUM('Outlook 4+8'!$H$24:$J$24) -> 11.861465 | E29: =SUMPRODUCT('Outlook 4+8'!$K29:$M29,'Outlook 4+8'!$K$24:$M$24)/SUM('Outlook 4+8'!$K$24:$M$24) -> 12.444844 | F29: =SUMPRODUCT(B29:E29,$B$24:$E$24)/SUM($B$24:$E$24) -> 11.772707 | H29: ='Budget 2025'!N29 -> 11.769361
A30: IMM-EB.MCV.LS | B30: =SUMIFS('Outlook 4+8'!$B30:$M30,'Outlook 4+8'!$B$185:$M$185,'Outlook Quarterly 4+8'!B$4) -> 17.998535 | C30: =SUMIFS('Outlook 4+8'!$B30:$M30,'Outlook 4+8'!$B$185:$M$185,'Outlook Quarterly 4+8'!C$4) -> 19.412084 | D30: =SUMIFS('Outlook 4+8'!$B30:$M30,'Outlook 4+8'!$B$185:$M$185,'Outlook Quarterly 4+8'!D$4) -> 0 | E30: =SUMIFS('Outlook 4+8'!$B30:$M30,'Outlook 4+8'!$B$185:$M$185,'Outlook Quarterly 4+8'!E$4) -> 0 | F30: =SUM(B30:E30) -> 37.410619 | H30: ='Budget 2025'!N30 -> 13.639936
A31: CV(GAR) | B31: =SUMPRODUCT('Outlook 4+8'!$B31:$D31,'Outlook 4+8'!$B$30:$D$30)/SUM('Outlook 4+8'!$B$30:$D$30) -> 5860.2842 | C31: =SUMPRODUCT('Outlook 4+8'!$E31:$G31,'Outlook 4+8'!$E$30:$G$30)/SUM('Outlook 4+8'!$E$30:$G$30) -> 5918.594 | D31: =IFERROR(SUMPRODUCT('Outlook 4+8'!$H31:$J31,'Outlook 4+8'!$H$30:$J$30)/SUM('Outlook 4+8'!$H$30:$J$30),0) -> 0 | E31: =IFERROR(SUMPRODUCT('Outlook 4+8'!$K31:$M31,'Outlook 4+8'!$K$30:$M$30)/SUM('Outlook 4+8'!$K$30:$M$30),0) -> 0 | F31: =SUMPRODUCT(B31:E31,$B$30:$E$30)/SUM($B$30:$E$30) -> 5890.5407 | H31: ='Budget 2025'!N31 -> 5822.4314
A32: TS | B32: =SUMPRODUCT('Outlook 4+8'!$B32:$D32,'Outlook 4+8'!$B$30:$D$30)/SUM('Outlook 4+8'!$B$30:$D$30) -> 0.92078055 | C32: =SUMPRODUCT('Outlook 4+8'!$E32:$G32,'Outlook 4+8'!$E$30:$G$30)/SUM('Outlook 4+8'!$E$30:$G$30) -> 0.92863984 | D32: =IFERROR(SUMPRODUCT('Outlook 4+8'!$H32:$J32,'Outlook 4+8'!$H$30:$J$30)/SUM('Outlook 4+8'!$H$30:$J$30),0) -> 0 | E32: =IFERROR(SUMPRODUCT('Outlook 4+8'!$K32:$M32,'Outlook 4+8'!$K$30:$M$30)/SUM('Outlook 4+8'!$K$30:$M$30),0) -> 0 | F32: =SUMPRODUCT(B32:E32,$B$30:$E$30)/SUM($B$30:$E$30) -> 0.92485868 | H32: ='Budget 2025'!N32 -> 0.90072278
A33: Ash | B33: =SUMPRODUCT('Outlook 4+8'!$B33:$D33,'Outlook 4+8'!$B$30:$D$30)/SUM('Outlook 4+8'!$B$30:$D$30) -> 7.1845522 | C33: =SUMPRODUCT('Outlook 4+8'!$E33:$G33,'Outlook 4+8'!$E$30:$G$30)/SUM('Outlook 4+8'!$E$30:$G$30) -> 7.5366982 | D33: =IFERROR(SUMPRODUCT('Outlook 4+8'!$H33:$J33,'Outlook 4+8'!$H$30:$J$30)/SUM('Outlook 4+8'!$H$30:$J$30),0) -> 0 | E33: =IFERROR(SUMPRODUCT('Outlook 4+8'!$K33:$M33,'Outlook 4+8'!$K$30:$M$30)/SUM('Outlook 4+8'!$K$30:$M$30),0) -> 0 | F33: =SUMPRODUCT(B33:E33,$B$30:$E$30)/SUM($B$30:$E$30) -> 7.3672781 | H33: ='Budget 2025'!N33 -> 8.5977728
A34: Moist | B34: =SUMPRODUCT('Outlook 4+8'!$B34:$D34,'Outlook 4+8'!$B$30:$D$30)/SUM('Outlook 4+8'!$B$30:$D$30) -> 11.01636 | C34: =SUMPRODUCT('Outlook 4+8'!$E34:$G34,'Outlook 4+8'!$E$30:$G$30)/SUM('Outlook 4+8'!$E$30:$G$30) -> 11.713971 | D34: =IFERROR(SUMPRODUCT('Outlook 4+8'!$H34:$J34,'Outlook 4+8'!$H$30:$J$30)/SUM('Outlook 4+8'!$H$30:$J$30),0) -> 0 | E34: =IFERROR(SUMPRODUCT('Outlook 4+8'!$K34:$M34,'Outlook 4+8'!$K$30:$M$30)/SUM('Outlook 4+8'!$K$30:$M$30),0) -> 0 | F34: =SUMPRODUCT(B34:E34,$B$30:$E$30)/SUM($B$30:$E$30) -> 11.378345 | H34: ='Budget 2025'!N34 -> 11.354386
A35: TM | B35: =SUMPRODUCT('Outlook 4+8'!$B35:$D35,'Outlook 4+8'!$B$30:$D$30)/SUM('Outlook 4+8'!$B$30:$D$30) -> 14.501869 | C35: =SUMPRODUCT('Outlook 4+8'!$E35:$G35,'Outlook 4+8'!$E$30:$G$30)/SUM('Outlook 4+8'!$E$30:$G$30) -> 15.650205 | D35: =IFERROR(SUMPRODUCT('Outlook 4+8'!$H35:$J35,'Outlook 4+8'!$H$30:$J$30)/SUM('Outlook 4+8'!$H$30:$J$30),0) -> 0 | E35: =IFERROR(SUMPRODUCT('Outlook 4+8'!$K35:$M35,'Outlook 4+8'!$K$30:$M$30)/SUM('Outlook 4+8'!$K$30:$M$30),0) -> 0 | F35: =SUMPRODUCT(B35:E35,$B$30:$E$30)/SUM($B$30:$E$30) -> 15.097732 | H35: ='Budget 2025'!N35 -> 16.354386
A36: IMM-EB.MCV.MS | B36: =SUMIFS('Outlook 4+8'!$B36:$M36,'Outlook 4+8'!$B$185:$M$185,'Outlook Quarterly 4+8'!B$4) -> 48.098999 | C36: =SUMIFS('Outlook 4+8'!$B36:$M36,'Outlook 4+8'!$B$185:$M$185,'Outlook Quarterly 4+8'!C$4) -> 74.141553 | D36: =SUMIFS('Outlook 4+8'!$B36:$M36,'Outlook 4+8'!$B$185:$M$185,'Outlook Quarterly 4+8'!D$4) -> 143.2577 | E36: =SUMIFS('Outlook 4+8'!$B36:$M36,'Outlook 4+8'!$B$185:$M$185,'Outlook Quarterly 4+8'!E$4) -> 235.75604 | F36: =SUM(B36:E36) -> 501.25429 | H36: ='Budget 2025'!N36 -> 422.71546
A37: CV(GAR) | B37: =SUMPRODUCT('Outlook 4+8'!$B37:$D37,'Outlook 4+8'!$B$36:$D$36)/SUM('Outlook 4+8'!$B$36:$D$36) -> 5977.8247 | C37: =SUMPRODUCT('Outlook 4+8'!$E37:$G37,'Outlook 4+8'!$E$36:$G$36)/SUM('Outlook 4+8'!$E$36:$G$36) -> 5934.9456 | D37: =IFERROR(SUMPRODUCT('Outlook 4+8'!$H37:$J37,'Outlook 4+8'!$H$36:$J$36)/SUM('Outlook 4+8'!$H$36:$J$36),0) -> 6012.1105 | E37: =IFERROR(SUMPRODUCT('Outlook 4+8'!$K37:$M37,'Outlook 4+8'!$K$36:$M$36)/SUM('Outlook 4+8'!$K$36:$M$36),0) -> 6021.4067 | F37: =SUMPRODUCT(B37:E37,$B$36:$E$36)/SUM($B$36:$E$36) -> 6001.7792 | H37: ='Budget 2025'!N37 -> 6013.6725
A38: TS | B38: =SUMPRODUCT('Outlook 4+8'!$B38:$D38,'Outlook 4+8'!$B$36:$D$36)/SUM('Outlook 4+8'!$B$36:$D$36) -> 1.4343487 | C38: =SUMPRODUCT('Outlook 4+8'!$E38:$G38,'Outlook 4+8'!$E$36:$G$36)/SUM('Outlook 4+8'!$E$36:$G$36) -> 1.528768 | D38: =IFERROR(SUMPRODUCT('Outlook 4+8'!$H38:$J38,'Outlook 4+8'!$H$36:$J$36)/SUM('Outlook 4+8'!$H$36:$J$36),0) -> 1.5753653 | E38: =IFERROR(SUMPRODUCT('Outlook 4+8'!$K38:$M38,'Outlook 4+8'!$K$36:$M$36)/SUM('Outlook 4+8'!$K$36:$M$36),0) -> 1.5760394 | F38: =SUMPRODUCT(B38:E38,$B$36:$E$36)/SUM($B$36:$E$36) -> 1.5552585 | H38: ='Budget 2025'!N38 -> 1.5594733
A39: Ash | B39: =SUMPRODUCT('Outlook 4+8'!$B39:$D39,'Outlook 4+8'!$B$36:$D$36)/SUM('Outlook 4+8'!$B$36:$D$36) -> 6.0426735 | C39: =SUMPRODUCT('Outlook 4+8'!$E39:$G39,'Outlook 4+8'!$E$36:$G$36)/SUM('Outlook 4+8'!$E$36:$G$36) -> 6.1888069 | D39: =IFERROR(SUMPRODUCT('Outlook 4+8'!$H39:$J39,'Outlook 4+8'!$H$36:$J$36)/SUM('Outlook 4+8'!$H$36:$J$36),0) -> 5.3452719 | E39: =IFERROR(SUMPRODUCT('Outlook 4+8'!$K39:$M39,'Outlook 4+8'!$K$36:$M$36)/SUM('Outlook 4+8'!$K$36:$M$36),0) -> 5.3347175 | F39: =SUMPRODUCT(B39:E39,$B$36:$E$36)/SUM($B$36:$E$36) -> 5.5319976 | H39: ='Budget 2025'!N39 -> 5.3287414
A40: Moist | B40: =SUMPRODUCT('Outlook 4+8'!$B40:$D40,'Outlook 4+8'!$B$36:$D$36)/SUM('Outlook 4+8'!$B$36:$D$36) -> 11.610247 | C40: =SUMPRODUCT('Outlook 4+8'!$E40:$G40,'Outlook 4+8'!$E$36:$G$36)/SUM('Outlook 4+8'!$E$36:$G$36) -> 11.565401 | D40: =IFERROR(SUMPRODUCT('Outlook 4+8'!$H40:$J40,'Outlook 4+8'!$H$36:$J$36)/SUM('Outlook 4+8'!$H$36:$J$36),0) -> 10.414565 | E40: =IFERROR(SUMPRODUCT('Outlook 4+8'!$K40:$M40,'Outlook 4+8'!$K$36:$M$36)/SUM('Outlook 4+8'!$K$36:$M$36),0) -> 10.115346 | F40: =SUMPRODUCT(B40:E40,$B$36:$E$36)/SUM($B$36:$E$36) -> 10.55879 | H40: ='Budget 2025'!N40 -> 10.279207
A41: TM | B41: =SUMPRODUCT('Outlook 4+8'!$B41:$D41,'Outlook 4+8'!$B$36:$D$36)/SUM('Outlook 4+8'!$B$36:$D$36) -> 14.141402 | C41: =SUMPRODUCT('Outlook 4+8'!$E41:$G41,'Outlook 4+8'!$E$36:$G$36)/SUM('Outlook 4+8'!$E$36:$G$36) -> 14.858583 | D41: =IFERROR(SUMPRODUCT('Outlook 4+8'!$H41:$J41,'Outlook 4+8'!$H$36:$J$36)/SUM('Outlook 4+8'!$H$36:$J$36),0) -> 15.414565 | E41: =IFERROR(SUMPRODUCT('Outlook 4+8'!$K41:$M41,'Outlook 4+8'!$K$36:$M$36)/SUM('Outlook 4+8'!$K$36:$M$36),0) -> 15.115346 | F41: =SUMPRODUCT(B41:E41,$B$36:$E$36)/SUM($B$36:$E$36) -> 15.069427 | H41: ='Budget 2025'!N41 -> 15.279207
...

Sheet BudgVSact. June
B2: SITES | C2: OB | E2: ROM | G2: FC | I2: SR (OB/ROM) | K2: Diff. (Act.%)
C3: Budget | D3: Actual | E3: Budget | F3: Actual | G3: Budget | H3: Actual | I3: Budget | J3: Actual | K3: OB | L3: ROM
B4: IMM | C4: =SUM('Budget 2025'!B5:G5) -> 45360.043 | D4: =SUM('Outlook 4+8'!B5:G5) -> 43301.113 | E4: =SUM('Budget 2025'!B8:G8) -> 3220 | F4: =SUM('Outlook 4+8'!B8:G8) -> 3176.7724 | G4: =SUM('Budget 2025'!B13:G13) -> 3275.5 | H4: =SUM('Outlook 4+8'!B13:G13) -> 3346.4136 | I4: =C4/E4 -> 14.08697 | J4: =D4/F4 -> 13.630537 | K4: =D4/C4 -> 0.95460916 | L4: =F4/E4 -> 0.98657527
B5: TCM | C5: =SUM('Budget 2025'!B56:G56) -> 25550 | D5: =SUM('Outlook 4+8'!B56:G56) -> 21049.987 | E5: =SUM('Budget 2025'!B60:G60) -> 1487 | F5: =SUM('Outlook 4+8'!B60:G60) -> 1389.7788 | G5: =SUM('Budget 2025'!B65:G65) -> 1562 | H5: =SUM('Outlook 4+8'!B66:G66) -> 1448.2282 | I5: =C5/E5 -> 17.182246 | J5: =D5/F5 -> 15.146286 | K5: =D5/C5 -> 0.82387426 | L5: =F5/E5 -> 0.93461921
B6: BEK | C6: =SUM('Budget 2025'!B105:G105) -> 45094 | D6: =SUM('Outlook 4+8'!B100:G100) -> 45842.741 | E6: =SUM('Budget 2025'!B109:G109) -> 3966.5 | F6: =SUM('Outlook 4+8'!B104:G104) -> 4469.687 | G6: =SUM('Budget 2025'!B115:G115) -> 4050 | H6: =SUM('Outlook 4+8'!B110:G110) -> 4248.2213 | I6: =C6/E6 -> 11.368713 | J6: =D6/F6 -> 10.256365 | K6: =D6/C6 -> 1.016604 | L6: =F6/E6 -> 1.1268592
B7: JBG | C7: =SUM('Budget 2025'!B130:G130) -> 1603.028 | D7: =SUM('Outlook 4+8'!B125:G125) -> 160 | E7: =SUM('Budget 2025'!B132:G132) -> 57 | F7: =SUM('Outlook 4+8'!B127:G127) -> 0 | G7: =SUM('Budget 2025'!B137:G137) -> 53 | H7: =SUM('Outlook 4+8'!B132:G132) -> 0 | I7: =C7/E7 -> 28.123298 | J7: =D7/F7 -> #DIV/0! | K7: =D7/C7 -> 0.099811107 | L7: =F7/E7 -> 0
B8: GPK | C8: =SUM('Budget 2025'!B145:G145) -> 3825 | D8: =SUM('Outlook 4+8'!B140:G140) -> 3692.6779 | E8: =SUM('Budget 2025'!B147:G147) -> 1062 | F8: =SUM('Outlook 4+8'!B142:G142) -> 1210.1154 | G8: =SUM('Budget 2025'!B152:G152) -> 1100 | H8: =SUM('Outlook 4+8'!B148:G148) -> 1223.3729 | I8: =C8/E8 -> 3.6016949 | J8: =D8/F8 -> 3.0515089 | K8: =D8/C8 -> 0.965406 | L8: =F8/E8 -> 1.1394684
B9: TIS | C9: =SUM('Budget 2025'!B160:G160) -> 4924.429 | D9: =SUM('Outlook 4+8'!B156:G156) -> 4754.59 | E9: =SUM('Budget 2025'!B162:G162) -> 270.88602 | F9: =SUM('Outlook 4+8'!B158:G158) -> 270.48932 | G9: =SUM('Budget 2025'!B166:G166) -> 245 | H9: =SUM('Outlook 4+8'!B163:G163) -> 144.71555 | I9: =C9/E9 -> 18.178971 | J9: =D9/F9 -> 17.577737 | K9: =D9/C9 -> 0.96551093 | L9: =F9/E9 -> 0.99853554
B10: TOTAL | C10: =SUM(C4:C9) -> 126356.5 | D10: =SUM(D4:D9) -> 118801.11 | E10: =SUM(E4:E9) -> 10063.386 | F10: =SUM(F4:F9) -> 10516.843 | G10: =SUM(G4:G9) -> 10285.5 | H10: =SUM(H4:H9) -> 10410.952 | I10: =C10/E10 -> 12.556062 | J10: =D10/F10 -> 11.296271 | K10: =D10/C10 -> 0.94020576 | L10: =F10/E10 -> 1.0450601
F11: =F10/E10 -> 1.0450601 | H11: =H10/G10 -> 1.0121969
