Workbook
Name _1A1_Z1...A10_Z10: #REF!
Name _1A1_Z1...A10_Z10: #REF!
Name _Apr: [1]Validation!$A$33
Name _Aug: [1]Validation!$A$37
Name _Chubu1: [1]Validation!$A$5
Name _Chubu2: [1]Validation!$A$6
Name _Chubu3: [1]Validation!$A$7
Name _ChubuP1: [1]Chubu!$V$203
Name _ChubuP2: [1]Chubu!$V$204
Name _CLP: [1]Validation!$A$17
Name _CLPP1: [1]CLP!$V$203
Name _CLPP2: [1]CLP!$V$204
Name _DATE: #REF!
Name _DATE: #REF!
Name _Dec: [1]Validation!$A$41
Name _ENEL1: [1]Validation!$A$11
Name _ENELP1: '[1]Enel '!$V$264
Name _ENELP2: '[1]Enel '!$V$265
Name _EPDC: [1]Validation!$A$8
Name _EPDCP1: [1]EPDC!$V$203
Name _EPDCP2: [1]EPDC!$V$204
Name _Feb: [1]Validation!$A$31
Name _ffggggg: #REF!
Name _ffggggg: #REF!
Name _Formosa1: [1]Validation!$A$15
Name _Formosa2: [1]Validation!$A$16
Name _FORMOSAP1: [1]Formosa!$V$264
Name _FORMOSAP2: [1]Formosa!$V$265
Name _fs1: #REF!
Name _fs1: #REF!
Name _HEK1: [1]Validation!$A$20
Name _HEK2: [1]Validation!$A$21
Name _HEKP1: [1]HEK!$V$203
Name _HEKP2: [1]HEK!$V$204
Name _Huaneng1: [1]Validation!$A$18
Name _Huaneng2: [1]Validation!$A$19
Name _HUANP1: [1]Huaneng!$V$394
Name _HUANP2: [1]Huaneng!$V$395
Name _Jan: [1]Validation!$A$30
Name _Jul: [1]Validation!$A$36
Name _Jun: [1]Validation!$A$35
Name _Kobe: [1]Validation!$A$9
Name _KOBEP1: '[1]Kobe Steel'!$V$264
Name _KOBEP2: '[1]Kobe Steel'!$V$265
Name _Kospo: [1]Validation!$A$13
Name _KOSPOP1: [1]Kospo!$V$203
Name _KOSPOP2: [1]Kospo!$V$204
Name _Kowepo: [1]Validation!$A$14
Name _KOWEPOP1: [1]Kowepo!$V$264
Name _KOWEPOP2: [1]Kowepo!$V$265
Name _Mar: [1]Validation!$A$32
Name _May: [1]Validation!$A$34
Name _Nov: [1]Validation!$A$40
Name _Oct: [1]Validation!$A$39
Name _Sep: [1]Validation!$A$38
Name _SHIKOKUP1: [1]Shikoku!$V$203
Name _SHIKOKUP2: [1]Shikoku!$V$204
Name _Tirreno: [1]Validation!$A$12
Name _TIRRENOP1: [1]Tirreno!$V$264
Name _TIRRENOP2: [1]Tirreno!$V$265

Sheet Budget 2025
A1: ITM plan year 2024 | B1: 1000
A2: As of 18 Nov'24
A4: IMM | B4: Jan | C4: Feb | D4: Mar | E4: Apr | F4: May | G4: Jun | H4: Jul | I4: Aug | J4: Sep | K4: Oct | L4: Nov | M4: Dec | N4: Total
A5: OB Removal (KBcm) | B5: =SUM(B6:B7) -> 7619.4483 | C5: =SUM(C6:C7) -> 7224.3023 | D5: =SUM(D6:D7) -> 6870.0231 | E5: =SUM(E6:E7) -> 7815.9147 | F5: =SUM(F6:F7) -> 8233.4755 | G5: =SUM(G6:G7) -> 7596.8792 | H5: =SUM(H6:H7) -> 8769.11 | I5: =SUM(I6:I7) -> 8498.0492 | ... M5: =SUM(M6:M7) -> 7566.691 | N5: =SUM(B5:M5) -> 94714.478 | P5: Done
A6: PAMA (WB) | B6: 2904.786 | C6: 2754.4503 | D6: 2424.321 | E6: 2767.1447 | F6: 2927.6178 | G6: 2460.4194 | H6: 3157.9028 | I6: 3107.2173 | J6: 2899.6426 | K6: 2829.8233 | L6: 2690.1553 | M6: 2609.1784 | N6: =SUM(B6:M6) -> 33532.659
A7: PAMA (EB) | B7: 4714.6622 | C7: 4469.852 | D7: 4445.7021 | E7: 5048.77 | F7: 5305.8577 | G7: 5136.4598 | H7: 5611.2072 | I7: 5390.8319 | J7: 5542.5331 | K7: 5412.2853 | L7: 5146.1452 | M7: 4957.5126 | N7: =SUM(B7:M7) -> 61181.819
A8: ROM Production (Kton) | B8: =SUM(B9:B11) -> 550 | C8: =SUM(C9:C11) -> 545 | D8: =SUM(D9:D11) -> 550 | E8: =SUM(E9:E11) -> 550 | F8: =SUM(F9:F11) -> 550 | G8: =SUM(G9:G11) -> 550 | H8: =SUM(H9:H11) -> 622.5 | I8: =SUM(I9:I11) -> 637.5 | ... M8: =SUM(M9:M11) -> 632.5 | N8: =SUM(B8:M8) -> 7100
A9: PAMA (WB) | B9: 192.5 | C9: 187.5 | D9: 192.5 | E9: 190 | F9: 185 | G9: 155 | H9: 130 | I9: 135 | J9: 145 | K9: 110 | L9: 120 | M9: 120 | N9: =SUM(B9:M9) -> 1862.5
A10: PAMA (EB) | B10: 345 | C10: 345 | D10: 345 | E10: 347.5 | F10: 352.5 | G10: 382.5 | H10: 480 | I10: 490 | J10: 480 | K10: 515 | L10: 505 | M10: 500 | N10: =SUM(B10:M10) -> 5087.5
A11: Fine Coal | B11: 12.5 | C11: 12.5 | D11: 12.5 | E11: 12.5 | F11: 12.5 | G11: 12.5 | H11: 12.5 | I11: 12.5 | J11: 12.5 | K11: 12.5 | L11: 12.5 | M11: 12.5 | N11: =SUM(B11:M11) -> 150
A12: SR ROM Total | B12: =B5/B8 -> 13.853542 | C12: =C5/C8 -> 13.255601 | D12: =D5/D8 -> 12.490951 | E12: =E5/E8 -> 14.210754 | F12: =F5/F8 -> 14.969956 | G12: =G5/G8 -> 13.812508 | H12: =H5/H8 -> 14.086924 | I12: =I5/I8 -> 13.330273 | ... N12: =N5/N8 -> 13.340067
A13: FC Product (Kton) | B13: =SUM(B14:B16) -> 541.75 | C13: =SUM(C14:C16) -> 536.75 | D13: =SUM(D14:D16) -> 541.75 | E13: =SUM(E14:E16) -> 551.75 | F13: =SUM(F14:F16) -> 551.75 | G13: =SUM(G14:G16) -> 551.75 | H13: =SUM(H14:H16) -> 635.75 | I13: =SUM(I14:I16) -> 637.75 | ... M13: =SUM(M14:M16) -> 637.75 | N13: =SUM(B13:M13) -> 7100
A14: PAMA (WB) | B14: 192.5 | C14: 187.5 | D14: 192.5 | E14: 190 | F14: 185 | G14: 155 | H14: 130 | I14: 135 | J14: 145 | K14: 110 | L14: 120 | M14: 120 | N14: =SUM(B14:M14) -> 1862.5
A15: PAMA (EB) | B15: 345 | C15: 345 | D15: 345 | E15: 349 | F15: 354 | G15: 384 | H15: 493 | I15: 490 | J15: 480 | K15: 515 | L15: 505 | M15: 505 | N15: =SUM(B15:M15) -> 5110
A16: Fine Coal | B16: 4.25 | C16: 4.25 | D16: 4.25 | E16: 12.75 | F16: 12.75 | G16: 12.75 | H16: 12.75 | I16: 12.75 | J16: 12.75 | K16: 12.75 | L16: 12.75 | M16: 12.75 | N16: =SUM(B16:M16) -> 127.5
A17: SR FC Total | B17: =B5/B13 -> 14.06451 | C17: =C5/C13 -> 13.459343 | D17: =D5/D13 -> 12.681169 | E17: =E5/E13 -> 14.165681 | F17: =F5/F13 -> 14.922475 | G17: =G5/G13 -> 13.768698 | H17: =H5/H13 -> 13.793331 | I17: =I5/I13 -> 13.325048 | ... N17: =N5/N13 -> 13.340067
A18: IMM-WB.HCV.LS | B18: 154.9822 | C18: 150.19218 | D18: 153.44456 | E18: 142.73183 | F18: 131.89202 | G18: 90.256716 | H18: 45.052829 | I18: 60.104109 | J18: 62.623268 | K18: 73.637876 | L18: 78.465632 | M18: 85.419934 | N18: =SUM(B18:M18) -> 1228.8032
A19: CV(GAR) | B19: 6066.6995 | C19: 6061.099 | D19: 6072.9614 | E19: 6113.1737 | F19: 6106.3251 | G19: 6216.0563 | H19: 6397.4706 | I19: 6374.5335 | J19: 6369.463 | K19: 6395.7374 | L19: 6207.9868 | M19: 6224.9984 | N19: =SUMPRODUCT(B19:M19,$B$18:$M$18)/SUM($B$18:$M$18) -> 6169.7769
A20: TS | B20: 0.79938883 | C20: 0.79960479 | D20: 0.80630914 | E20: 0.80238321 | F20: 0.79513307 | G20: 0.79813522 | H20: 0.8000568 | I20: 0.80071014 | J20: 0.80424058 | K20: 0.87778388 | L20: 0.89103139 | M20: 0.79704817 | N20: =SUMPRODUCT(B20:M20,$B$18:$M$18)/SUM($B$18:$M$18) -> 0.81080181
A21: Ash | B21: 8.5931913 | C21: 8.5723462 | D21: 8.4652505 | E21: 8.3496537 | F21: 8.4544991 | G21: 8.0611616 | H21: 8.0877488 | I21: 8.0139288 | J21: 8.093906 | K21: 8.3113445 | L21: 8.6583469 | M21: 8.1211956 | N21: =SUMPRODUCT(B21:M21,$B$18:$M$18)/SUM($B$18:$M$18) -> 8.3745645
A22: Moist | B22: 8.4967581 | C22: 8.6035878 | D22: 8.5701167 | E22: 8.295887 | F22: 8.4360236 | G22: 8.1042227 | H22: 7.1124623 | I22: 7.0457455 | J22: 7.1276119 | K22: 7.1603037 | L22: 7.2146756 | M22: 7.5402791 | N22: =SUMPRODUCT(B22:M22,$B$18:$M$18)/SUM($B$18:$M$18) -> 8.0403443
A23: TM | B23: 13.52212 | C23: 13.62895 | D23: 13.595479 | E23: 13.321249 | F23: 13.461386 | G23: 13.129585 | H23: 12.137825 | I23: 12.071108 | J23: 12.152974 | K23: 12.185666 | L23: 12.240038 | M23: 12.565641 | N23: =SUMPRODUCT(B23:M23,$B$18:$M$18)/SUM($B$18:$M$18) -> 13.065707
A24: IMM-WB.HCV.HS | B24: 37.517805 | C24: 37.307818 | D24: 39.055444 | E24: 47.268165 | F24: 53.10798 | G24: 64.743284 | H24: 84.947171 | I24: 74.895891 | J24: 82.376732 | K24: 36.362124 | L24: 41.534368 | M24: 34.580066 | N24: =SUM(B24:M24) -> 633.69685
A25: CV(GAR) | B25: 5995.4058 | C25: 6102.8668 | D25: 6012.8803 | E25: 5956.2491 | F25: 5900.982 | G25: 5903.8514 | H25: 5953.1501 | I25: 5935.2903 | J25: 5994.0694 | K25: 5972.607 | L25: 5974.5067 | M25: 5973.0938 | N25: =SUMPRODUCT(B25:M25,$B$24:$M$24)/SUM($B$24:$M$24) -> 5965.7827
A26: TS | B26: 2.4295613 | C26: 2.4050655 | D26: 2.5318666 | E26: 2.5966145 | F26: 2.6452674 | G26: 2.7646957 | H26: 2.7577905 | I26: 2.7055365 | J26: 2.6431822 | K26: 2.4886633 | L26: 2.3842149 | M26: 1.9721835 | N26: =SUMPRODUCT(B26:M26,$B$24:$M$24)/SUM($B$24:$M$24) -> 2.5790489
A27: Ash | B27: 13.650338 | C27: 13.07266 | D27: 13.53618 | E27: 14.197739 | F27: 14.74821 | G27: 14.555829 | H27: 13.682949 | I27: 14.42353 | J27: 13.830267 | K27: 13.802136 | L27: 13.963262 | M27: 13.239605 | N27: =SUMPRODUCT(B27:M27,$B$24:$M$24)/SUM($B$24:$M$24) -> 13.960595
A28: Moist | B28: 6.0446714 | C28: 6.0271092 | D28: 6.0381378 | E28: 6.0670306 | F28: 6.0650682 | G28: 7.0545207 | H28: 6.8576285 | I28: 6.9141156 | J28: 7.151348 | K28: 7.5030578 | L28: 7.5101273 | M28: 7.1237139 | N28: =SUMPRODUCT(B28:M28,$B$24:$M$24)/SUM($B$24:$M$24) -> 6.7439986
A29: TM | B29: 11.070034 | C29: 11.052472 | D29: 11.0635 | E29: 11.092393 | F29: 11.090431 | G29: 12.079883 | H29: 11.882991 | I29: 11.939478 | J29: 12.17671 | K29: 12.52842 | L29: 12.53549 | M29: 12.149076 | N29: =SUMPRODUCT(B29:M29,$B$24:$M$24)/SUM($B$24:$M$24) -> 11.769361
A30: IMM-EB.MCV.LS | B30: 3.3845713 | C30: 2.1986171 | D30: 2.3031178 | E30: 2.767207 | F30: 1.8758652 | G30: 1.1105575 | H30: 0 | I30: 0 | J30: 0 | K30: 0 | L30: 0 | M30: 0 | N30: =SUM(B30:M30) -> 13.639936
A31: CV(GAR) | B31: 5821.883 | C31: 5816.4871 | D31: 5824.2204 | E31: 5826.2223 | F31: 5821.6228 | G31: 5824.0809 | H31: 0 | I31: 0 | J31: 0 | K31: 0 | L31: 0 | M31: 0 | N31: =SUMPRODUCT(B31:M31,$B$30:$M$30)/SUM($B$30:$M$30) -> 5822.4314
A32: TS | B32: 0.89812632 | C32: 0.89994494 | D32: 0.90129647 | E32: 0.90153154 | F32: 0.90292127 | G32: 0.90325732 | H32: 0 | I32: 0 | J32: 0 | K32: 0 | L32: 0 | M32: 0 | N32: =SUMPRODUCT(B32:M32,$B$30:$M$30)/SUM($B$30:$M$30) -> 0.90072278
A33: Ash | B33: 8.6642459 | C33: 8.6537904 | D33: 8.6423873 | E33: 8.5289327 | F33: 8.5159535 | G33: 8.5014972 | H33: 0 | I33: 0 | J33: 0 | K33: 0 | L33: 0 | M33: 0 | N33: =SUMPRODUCT(B33:M33,$B$30:$M$30)/SUM($B$30:$M$30) -> 8.5977728
A34: Moist | B34: 11.332981 | C34: 11.336869 | D34: 11.369268 | E34: 11.350128 | F34: 11.399581 | G34: 11.357707 | H34: 0 | I34: 0 | J34: 0 | K34: 0 | L34: 0 | M34: 0 | N34: =SUMPRODUCT(B34:M34,$B$30:$M$30)/SUM($B$30:$M$30) -> 11.354386
A35: TM | B35: 16.332981 | C35: 16.336869 | D35: 16.369268 | E35: 16.350128 | F35: 16.399581 | G35: 16.357707 | H35: 0 | I35: 0 | J35: 0 | K35: 0 | L35: 0 | M35: 0 | N35: =SUMPRODUCT(B35:M35,$B$30:$M$30)/SUM($B$30:$M$30) -> 16.354386
A36: IMM-EB.MCV.MS | B36: 2.5218825 | C36: 7.2154786 | D36: 26.720101 | E36: 6.3272233 | F36: 12.630174 | G36: 4.8087851 | H36: 12.094951 | I36: 14.998053 | J36: 83.697273 | K36: 94.400599 | L36: 71.33532 | M36: 85.965624 | N36: =SUM(B36:M36) -> 422.71546
A37: CV(GAR) | B37: 6013.744 | C37: 5958.5719 | D37: 6011.5142 | E37: 6033.7912 | F37: 5987.1311 | G37: 6002.8141 | H37: 6036.2059 | I37: 6005.6296 | J37: 5996.4183 | K37: 6012.5832 | L37: 6026.6617 | M37: 6027.4417 | N37: =SUMPRODUCT(B37:M37,$B$36:$M$36)/SUM($N$36) -> 6013.6725
A38: TS | B38: 1.5719259 | C38: 1.5704928 | D38: 1.5645055 | E38: 1.5541281 | F38: 1.5514426 | G38: 1.5490809 | H38: 1.5706205 | I38: 1.5667221 | J38: 1.5492652 | K38: 1.553251 | L38: 1.5598162 | M38: 1.5724278 | N38: =SUMPRODUCT(B38:M38,$B$36:$M$36)/SUM($N$36) -> 1.5594733
A39: Ash | B39: 6.0748082 | C39: 6.153097 | D39: 6.1792076 | E39: 5.197632 | F39: 5.2945573 | G39: 5.236934 | H39: 5.1052577 | I39: 5.3674075 | J39: 5.3569251 | K39: 5.169691 | L39: 5.1649103 | M39: 5.3009891 | N39: =SUMPRODUCT(B39:M39,$B$36:$M$36)/SUM($N$36) -> 5.3287414
A40: Moist | B40: 10.127325 | C40: 10.233784 | D40: 10.532647 | E40: 10.3526 | F40: 10.781854 | G40: 10.481305 | H40: 10.365903 | I40: 10.468448 | J40: 10.443604 | K40: 10.274018 | L40: 10.240397 | M40: 9.9507726 | N40: =SUMPRODUCT(B40:M40,$B$36:$M$36)/SUM($N$36) -> 10.279207
A41: TM | B41: 15.127325 | C41: 15.233784 | D41: 15.532647 | E41: 15.3526 | F41: 15.781854 | G41: 15.481305 | H41: 15.365903 | I41: 15.468448 | J41: 15.443604 | K41: 15.274018 | L41: 15.240397 | M41: 14.950773 | N41: =SUMPRODUCT(B41:M41,$B$36:$M$36)/SUM($N$36) -> 15.279207
...

Sheet Outlook 0+12
A1: ITM outlook 2025 (0+12) | B1: 1000
B3: Out. | C3: Out. | D3: Out. | E3: Out. | F3: Out. | G3: Out. | H3: Out. | I3: Out. | J3: Out. | K3: Out. | L3: Out. | M3: Out. | N3: Out.
A4: IMM | B4: Jan | C4: Feb | D4: Mar | E4: Apr | F4: May | G4: Jun | H4: Jul | I4: Aug | J4: Sep | K4: Oct | L4: Nov | M4: Dec | N4: Total | P4: Budget 2025
A5: OB Removal (KBcm) | B5: =SUM(B6:B7) -> 7628.0103 | C5: =SUM(C6:C7) -> 7275.0402 | D5: =SUM(D6:D7) -> 6917.9241 | E5: =SUM(E6:E7) -> 7858.7341 | F5: =SUM(F6:F7) -> 8278.4905 | G5: =SUM(G6:G7) -> 7640.614 | H5: =SUM(H6:H7) -> 8789.2468 | I5: =SUM(I6:I7) -> 8512.679 | ... M5: =SUM(M6:M7) -> 7651.8218 | N5: =SUM(B5:M5) -> 95205.55 | P5: ='Budget 2025'!N5 -> 94714.478 | Q5: =N5/P5 -> 1.0051848
A6: PAMA (WB) | B6: 2766.4135 | C6: 2778.6096 | D6: 2447.1295 | E6: 2781.4178 | F6: 2942.6228 | G6: 2548.7015 | H6: 3112.9386 | I6: 3121.8471 | J6: 2945.2593 | K6: 2874.3188 | L6: 2732.4476 | M6: 2649.3725 | N6: =SUM(B6:M6) -> 33701.079 | P6: ='Budget 2025'!N6 -> 33532.659
A7: PAMA (EB) | B7: 4861.5967 | C7: 4496.4306 | D7: 4470.7946 | E7: 5077.3162 | F7: 5335.8677 | G7: 5091.9125 | H7: 5676.3082 | I7: 5390.8319 | J7: 5542.5331 | K7: 5412.2853 | L7: 5146.1452 | M7: 5002.4492 | N7: =SUM(B7:M7) -> 61504.471 | P7: ='Budget 2025'!N7 -> 61181.819
A8: ROM Production (Kton) | B8: =SUM(B9:B11) -> 554.06482 | C8: =SUM(C9:C11) -> 552.5 | D8: =SUM(D9:D11) -> 552.5 | E8: =SUM(E9:E11) -> 557.5 | F8: =SUM(F9:F11) -> 557.5 | G8: =SUM(G9:G11) -> 557.5 | H8: =SUM(H9:H11) -> 622.5 | I8: =SUM(I9:I11) -> 637.5 | ... N8: =SUM(N9:N11) -> 7135 | P8: ='Budget 2025'!N8 -> 7100 | Q8: =N8/P8 -> 1.0049296
A9: PAMA (WB) | B9: 188.78323 | C9: 170 | D9: 170 | E9: 160 | F9: 175 | G9: 150 | H9: 140 | I9: 130.27368 | J9: 130 | K9: 115 | L9: 110 | M9: 85.942654 | N9: =SUM(B9:M9) -> 1724.9996 | P9: ='Budget 2025'!N9 -> 1862.5
A10: PAMA (EB) | B10: 365.28158 | C10: 370 | D10: 370 | E10: 385 | F10: 370 | G10: 395 | H10: 470 | I10: 494.72632 | J10: 495 | K10: 510 | L10: 515 | M10: 532.49253 | N10: =SUM(B10:M10) -> 5272.5004 | P10: ='Budget 2025'!N10 -> 5087.5
A11: Fine Coal (WB) | B11: 0 | C11: 12.5 | D11: 12.5 | E11: 12.5 | F11: 12.5 | G11: 12.5 | H11: 12.5 | I11: 12.5 | J11: 12.5 | K11: 12.5 | L11: 12.5 | M11: 12.5 | N11: =SUM(B11:M11) -> 137.5 | P11: ='Budget 2025'!N11 -> 150
A12: SR ROM Total | B12: =B5/B8 -> 13.767361 | C12: =C5/C8 -> 13.167494 | D12: =D5/D8 -> 12.52113 | E12: =E5/E8 -> 14.096384 | F12: =F5/F8 -> 14.84931 | G12: =G5/G8 -> 13.705137 | H12: =H5/H8 -> 14.119272 | I12: =I5/I8 -> 13.353222 | ... N12: =N5/N8 -> 13.343455 | P12: ='Budget 2025'!N12 -> 13.340067
A13: FC Product (Kton) | B13: =SUM(B14:B16) -> 575 | C13: =SUM(C14:C16) -> 575 | D13: =SUM(D14:D16) -> 575 | E13: =SUM(E14:E16) -> 554.25 | F13: =SUM(F14:F16) -> 559.25 | G13: =SUM(G14:G16) -> 559.25 | H13: =SUM(H14:H16) -> 625.75 | I13: =SUM(I14:I16) -> 637.75 | ... M13: =SUM(M14:M16) -> 622 | N13: =SUM(B13:M13) -> 7135 | P13: ='Budget 2025'!N13 -> 7100
A14: PAMA (WB) | B14: 185 | C14: 185 | D14: 185 | E14: 165 | F14: 175 | G14: 150 | H14: 150 | I14: 130.27368 | J14: 130 | K14: 100 | L14: 95 | M14: 74.726316 | N14: =SUM(B14:M14) -> 1725 | P14: ='Budget 2025'!N14 -> 1862.5
A15: PAMA (EB) | B15: 390 | C15: 385.75 | D15: 385.75 | E15: 385 | F15: 371.5 | G15: 396.5 | H15: 463 | I15: 494.72632 | J15: 495 | K15: 494.25 | L15: 499.25 | M15: 534.52368 | N15: =SUM(B15:M15) -> 5295.25 | P15: ='Budget 2025'!N15 -> 5110
A16: Fine Coal | B16: 0 | C16: 4.25 | D16: 4.25 | E16: 4.25 | F16: 12.75 | G16: 12.75 | H16: 12.75 | I16: 12.75 | J16: 12.75 | K16: 12.75 | L16: 12.75 | M16: 12.75 | N16: =N48 -> 114.75 | P16: ='Budget 2025'!N48 -> 127.5
A17: SR FC Total | B17: =B5/B13 -> 13.266105 | C17: =C5/C13 -> 12.652244 | D17: =D5/D13 -> 12.031172 | E17: =E5/E13 -> 14.179042 | F17: =F5/F13 -> 14.802844 | G17: =G5/G13 -> 13.662251 | H17: =H5/H13 -> 14.04594 | I17: =I5/I13 -> 13.347987 | ... N17: =N5/N13 -> 13.343455 | P17: ='Budget 2025'!N17 -> 13.340067
A18: IMM-WB.HCV.LS | B18: 128 | C18: 127.89722 | D18: 125.948 | E18: 123.72368 | F18: 121.28495 | G18: 72.693323 | H18: 51.776511 | I18: 63.569437 | J18: 60.50972 | K18: 63.634133 | L18: 63.954928 | M18: 73.789156 | N18: =SUM(B18:M18) -> 1076.781 | P18: ='Budget 2025'!N18 -> 1228.8032 | R18: HCV.LS
A19: CV(GAR) | B19: 6056.5044 | C19: 6054.4664 | D19: 6060.4292 | E19: 6107.8098 | F19: 6113.6029 | G19: 6164.2166 | H19: 6395.8697 | I19: 6385.8035 | J19: 6374.9065 | K19: 6403.0078 | L19: 6240.9311 | M19: 6210.111 | N19: =SUMPRODUCT(B19:M19,$B$18:$M$18)/SUM($B$18:$M$18) -> 6171.9284 | P19: ='Budget 2025'!N19 -> 6169.7769
A20: TS | B20: 0.80255179 | C20: 0.79953187 | D20: 0.80438711 | E20: 0.79980649 | F20: 0.79531019 | G20: 0.79962966 | H20: 0.79864937 | I20: 0.80332935 | J20: 0.79960709 | K20: 0.8394863 | L20: 0.84973273 | M20: 0.83517755 | N20: =SUMPRODUCT(B20:M20,$B$18:$M$18)/SUM($B$18:$M$18) -> 0.80799292 | P20: ='Budget 2025'!N20 -> 0.81080181
A21: Ash | B21: 8.9639585 | C21: 8.6165952 | D21: 8.5485529 | E21: 8.4230847 | F21: 8.4692567 | G21: 8.3241764 | H21: 8.2711426 | I21: 8.0000283 | J21: 7.9678796 | K21: 8.1901515 | L21: 8.1985325 | M21: 8.2053863 | N21: =SUMPRODUCT(B21:M21,$B$18:$M$18)/SUM($B$18:$M$18) -> 8.4236804 | P21: ='Budget 2025'!N21 -> 8.3745645
A22: Moist | B22: 8.4747045 | C22: 8.6985088 | D22: 8.8456574 | E22: 8.5394601 | F22: 8.6055963 | G22: 8.607102 | H22: 7.2977721 | I22: 7.0138128 | J22: 7.1238159 | K22: 7.1299379 | L22: 7.0581129 | M22: 7.7179069 | N22: =SUMPRODUCT(B22:M22,$B$18:$M$18)/SUM($B$18:$M$18) -> 8.1415766 | P22: ='Budget 2025'!N22 -> 8.0403443
A23: TM | B23: 13.324127 | C23: 13.723871 | D23: 13.87102 | E23: 13.564822 | F23: 13.630959 | G23: 13.632464 | H23: 12.323134 | I23: 12.039175 | J23: 12.149178 | K23: 12.1553 | L23: 12.083475 | M23: 12.743269 | N23: =SUMPRODUCT(B23:M23,$B$18:$M$18)/SUM($B$18:$M$18) -> 13.146025 | P23: ='Budget 2025'!N23 -> 13.065707
A24: IMM-WB.HCV.HS | B24: 57 | C24: 57.102782 | D24: 59.052005 | E24: 41.27632 | F24: 53.715053 | G24: 77.306677 | H24: 98.223489 | I24: 66.704247 | J24: 69.49028 | K24: 36.365867 | L24: 31.045072 | M24: 0.93715959 | N24: =SUM(B24:M24) -> 648.21895 | P24: ='Budget 2025'!N24 -> 633.69685 | R24: MCV.HS
A25: CV(GAR) | B25: 5986.1578 | C25: 6173.5681 | D25: 6011.4535 | E25: 5973.6523 | F25: 5924.8145 | G25: 5894.6697 | H25: 5962.1308 | I25: 5930.0109 | J25: 6005.5198 | K25: 5934.0912 | L25: 5986.2386 | M25: 5823.7307 | N25: =SUMPRODUCT(B25:M25,$B$24:$M$24)/SUM($B$24:$M$24) -> 5977.6863 | P25: ='Budget 2025'!N25 -> 5965.7827
A26: TS | B26: 2.1574907 | C26: 2.5143984 | D26: 2.4830267 | E26: 2.603231 | F26: 2.6338335 | G26: 2.7440282 | H26: 2.7636454 | I26: 2.6980912 | J26: 2.6091248 | K26: 2.5875289 | L26: 2.4796141 | M26: 2.3813068 | N26: =SUMPRODUCT(B26:M26,$B$24:$M$24)/SUM($B$24:$M$24) -> 2.5921656 | P26: ='Budget 2025'!N26 -> 2.5790489
A27: Ash | B27: 12.442691 | C27: 13.060034 | D27: 13.000774 | E27: 13.872121 | F27: 14.397391 | G27: 14.758611 | H27: 13.50972 | I27: 14.254774 | J27: 13.324647 | K27: 13.975011 | L27: 13.727192 | M27: 14.885054 | N27: =SUMPRODUCT(B27:M27,$B$24:$M$24)/SUM($B$24:$M$24) -> 13.670827 | P27: ='Budget 2025'!N27 -> 13.960595
A28: Moist | B28: 6.4100452 | C28: 5.5947438 | D28: 6.0024919 | E28: 6.0768151 | F28: 6.0586598 | G28: 7.0770251 | H28: 6.8342267 | I28: 6.7892256 | J28: 6.8309987 | K28: 7.2711603 | L28: 7.2743126 | M28: 7.8622495 | N28: =SUMPRODUCT(B28:M28,$B$24:$M$24)/SUM($B$24:$M$24) -> 6.5705266 | P28: ='Budget 2025'!N28 -> 6.7439986
A29: TM | B29: 11.810707 | C29: 10.620106 | D29: 11.027854 | E29: 11.102177 | F29: 11.084022 | G29: 12.102387 | H29: 11.859589 | I29: 11.814588 | J29: 11.856361 | K29: 12.296523 | L29: 12.299675 | M29: 12.887612 | N29: =SUMPRODUCT(B29:M29,$B$24:$M$24)/SUM($B$24:$M$24) -> 11.62889 | P29: ='Budget 2025'!N29 -> 11.769361
A30: IMM-EB.MCV.LS | B30: 3.5 | C30: 2.2366315 | D30: 2.4266531 | E30: 2.767207 | F30: 1.8758652 | G30: 1.0397384 | H30: 0 | I30: 0 | J30: 0 | K30: 0 | L30: 0 | M30: 0 | N30: =SUM(B30:M30) -> 13.846095 | P30: ='Budget 2025'!N30 -> 13.639936 | R30: MCV.LS
A31: CV(GAR) | B31: 5856.5504 | C31: 5817.4439 | D31: 5826.7921 | E31: 5826.0545 | F31: 5822.6987 | G31: 5826.1463 | H31: 0 | I31: 0 | J31: 0 | K31: 0 | L31: 0 | M31: 0 | N31: =SUMPRODUCT(B31:M31,$B$30:$M$30)/SUM($B$30:$M$30) -> 5832.0538 | P31: ='Budget 2025'!N31 -> 5822.4314
A32: TS | B32: 0.9005 | C32: 0.90545161 | D32: 0.90943015 | E32: 0.90187879 | F32: 0.90556766 | G32: 0.91112484 | H32: 0 | I32: 0 | J32: 0 | K32: 0 | L32: 0 | M32: 0 | N32: =SUMPRODUCT(B32:M32,$B$30:$M$30)/SUM($B$30:$M$30) -> 0.90462492 | P32: ='Budget 2025'!N32 -> 0.90072278
A33: Ash | B33: 7.7055 | C33: 8.6308234 | D33: 8.6015019 | E33: 8.5322006 | F33: 8.5297282 | G33: 8.467009 | H33: 0 | I33: 0 | J33: 0 | K33: 0 | L33: 0 | M33: 0 | N33: =SUMPRODUCT(B33:M33,$B$30:$M$30)/SUM($B$30:$M$30) -> 8.3460745 | P33: ='Budget 2025'!N33 -> 8.5977728
A34: Moist | B34: 12.0415 | C34: 11.326661 | D34: 11.355842 | E34: 11.349639 | F34: 11.387471 | G34: 11.34698 | H34: 0 | I34: 0 | J34: 0 | K34: 0 | L34: 0 | M34: 0 | N34: =SUMPRODUCT(B34:M34,$B$30:$M$30)/SUM($B$30:$M$30) -> 11.526828 | P34: ='Budget 2025'!N34 -> 11.354386
A35: TM | B35: 16.475466 | C35: 16.326661 | D35: 16.355842 | E35: 16.349639 | F35: 16.387471 | G35: 16.34698 | H35: 0 | I35: 0 | J35: 0 | K35: 0 | L35: 0 | M35: 0 | N35: =SUMPRODUCT(B35:M35,$B$30:$M$30)/SUM($B$30:$M$30) -> 16.383747 | P35: ='Budget 2025'!N35 -> 16.354386
A36: IMM-EB.MCV.MS | B36: 15 | C36: 6.97183 | D36: 21.377741 | E36: 3.401339 | F36: 22.090583 | G36: 4.5999106 | H36: 41.570342 | I36: 40.772909 | J36: 79.848192 | K36: 87.001224 | L36: 77.797774 | M36: 75.957949 | N36: =SUM(B36:M36) -> 476.38979 | P36: ='Budget 2025'!N36 -> 422.71546 | R36: HCV.MS
A37: CV(GAR) | B37: 5918.5614 | C37: 5954.7474 | D37: 6008.4875 | E37: 6032.4641 | F37: 5995.2123 | G37: 6003.9591 | H37: 6003.0099 | I37: 6001.1416 | J37: 6011.5797 | K37: 5999.8733 | L37: 6040.1578 | M37: 6028.7914 | N37: =SUMPRODUCT(B37:M37,$B$36:$M$36)/SUM($B$36:$M$36) -> 6010.6292 | P37: ='Budget 2025'!N37 -> 6013.6725
A38: TS | B38: 1.5875425 | C38: 1.5558183 | D38: 1.5456704 | E38: 1.5544982 | F38: 1.5749652 | G38: 1.5506644 | H38: 1.5529204 | I38: 1.5597752 | J38: 1.5742938 | K38: 1.5665537 | L38: 1.5909634 | M38: 1.57364 | N38: =SUMPRODUCT(B38:M38,$B$36:$M$36)/SUM($B$36:$M$36) -> 1.5709145 | P38: ='Budget 2025'!N38 -> 1.5594733
A39: Ash | B39: 5.1835735 | C39: 6.1747501 | D39: 6.1701138 | E39: 5.2234687 | F39: 5.3979157 | G39: 5.238563 | H39: 5.1541212 | I39: 5.2235177 | J39: 5.4136753 | K39: 5.4676453 | L39: 5.2189677 | M39: 5.3018353 | N39: =SUMPRODUCT(B39:M39,$B$36:$M$36)/SUM($B$36:$M$36) -> 5.3690362 | P39: ='Budget 2025'!N39 -> 5.3287414
A40: Moist | B40: 11.923023 | C40: 10.24276 | D40: 10.532753 | E40: 10.348733 | F40: 10.690989 | G40: 10.471563 | H40: 10.621766 | I40: 10.572755 | J40: 10.350091 | K40: 10.245067 | L40: 10.128284 | M40: 9.9459134 | N40: =SUMPRODUCT(B40:M40,$B$36:$M$36)/SUM($B$36:$M$36) -> 10.346132 | P40: ='Budget 2025'!N40 -> 10.279207
A41: TM | B41: 16.695714 | C41: 15.24276 | D41: 15.532753 | E41: 15.348733 | F41: 15.690989 | G41: 15.471563 | H41: 15.621766 | I41: 15.572755 | J41: 15.350091 | K41: 15.245067 | L41: 15.128284 | M41: 14.945913 | N41: =SUMPRODUCT(B41:M41,$B$36:$M$36)/SUM($B$36:$M$36) -> 15.338975 | P41: ='Budget 2025'!N41 -> 15.279207
...

Sheet BudgVSact. June
B2: SITES | C2: OB | E2: ROM | G2: FC | I2: SR (OB/ROM) | K2: Diff. (Act.%)
C3: Budget | D3: Actual | E3: Budget | F3: Actual | G3: Budget | H3: Actual | I3: Budget | J3: Actual | K3: OB | L3: ROM
B4: IMM | C4: =SUM('Budget 2025'!B5:G5) -> 45360.043 | D4: =SUM('Outlook 0+12'!B5:G5) -> 45598.813 | E4: =SUM('Budget 2025'!B8:G8) -> 3295 | F4: =SUM('Outlook 0+12'!B8:G8) -> 3331.5648 | G4: =SUM('Budget 2025'!B13:G13) -> 3275.5 | H4: =SUM('Outlook 0+12'!B13:G13) -> 3397.75 | I4: =C4/E4 -> 13.766326 | J4: =D4/F4 -> 13.686906 | K4: =D4/C4 -> 1.0052639 | L4: =F4/E4 -> 1.0110971
B5: TCM | C5: =SUM('Budget 2025'!B56:G56) -> 25550 | D5: =SUM('Outlook 0+12'!B56:G56) -> 23685 | E5: =SUM('Budget 2025'!B60:G60) -> 1487 | F5: =SUM('Outlook 0+12'!B60:G60) -> 1504 | G5: =SUM('Budget 2025'!B65:G65) -> 1562 | H5: =SUM('Outlook 0+12'!B66:G66) -> 1582 | I5: =C5/E5 -> 17.182246 | J5: =D5/F5 -> 15.748005 | K5: =D5/C5 -> 0.92700587 | L5: =F5/E5 -> 1.0114324
B6: BEK | C6: =SUM('Budget 2025'!B105:G105) -> 45094 | D6: =SUM('Outlook 0+12'!B100:G100) -> 46285 | E6: =SUM('Budget 2025'!B109:G109) -> 3966.5 | F6: =SUM('Outlook 0+12'!B104:G104) -> 4250 | G6: =SUM('Budget 2025'!B115:G115) -> 4050 | H6: =SUM('Outlook 0+12'!B110:G110) -> 4245 | I6: =C6/E6 -> 11.368713 | J6: =D6/F6 -> 10.890588 | K6: =D6/C6 -> 1.0264115 | L6: =F6/E6 -> 1.0714736
B7: JBG | C7: =SUM('Budget 2025'!B130:G130) -> 1603.028 | D7: =SUM('Outlook 0+12'!B125:G125) -> 294.136 | E7: =SUM('Budget 2025'!B132:G132) -> 57 | F7: =SUM('Outlook 0+12'!B127:G127) -> 0 | G7: =SUM('Budget 2025'!B137:G137) -> 53 | H7: =SUM('Outlook 0+12'!B132:G132) -> 0 | I7: =C7/E7 -> 28.123298 | J7: =D7/F7 -> #DIV/0! | K7: =D7/C7 -> 0.18348775 | L7: =F7/E7 -> 0
B8: GPK | C8: =SUM('Budget 2025'!B145:G145) -> 3825 | D8: =SUM('Outlook 0+12'!B140:G140) -> 3825 | E8: =SUM('Budget 2025'!B147:G147) -> 1062 | F8: =SUM('Outlook 0+12'!B142:G142) -> 1175 | G8: =SUM('Budget 2025'!B152:G152) -> 1100 | H8: =SUM('Outlook 0+12'!B148:G148) -> 1230 | I8: =C8/E8 -> 3.6016949 | J8: =D8/F8 -> 3.2553191 | K8: =D8/C8 -> 1 | L8: =F8/E8 -> 1.106403
B9: TIS | C9: =SUM('Budget 2025'!B160:G160) -> 5910.67 | D9: =SUM('Outlook 0+12'!B156:G156) -> 5029.9767 | E9: =SUM('Budget 2025'!B162:G162) -> 265 | F9: =SUM('Outlook 0+12'!B158:G158) -> 284.39484 | G9: =SUM('Budget 2025'!B166:G166) -> 245 | H9: =SUM('Outlook 0+12'!B162:G162) -> 275 | I9: =C9/E9 -> 22.304415 | J9: =D9/F9 -> 17.686596 | K9: =D9/C9 -> 0.85099942 | L9: =F9/E9 -> 1.0731881
B10: TOTAL | C10: =SUM(C4:C9) -> 127342.74 | D10: =SUM(D4:D9) -> 124717.93 | E10: =SUM(E4:E9) -> 10132.5 | F10: =SUM(F4:F9) -> 10544.96 | G10: =SUM(G4:G9) -> 10285.5 | H10: =SUM(H4:H9) -> 10729.75 | I10: =C10/E10 -> 12.567751 | J10: =D10/F10 -> 11.827255 | K10: =D10/C10 -> 0.97938779 | L10: =F10/E10 -> 1.0407066
F11: =F10/E10 -> 1.0407066 | H11: =H10/G10 -> 1.0431919
